Workbook

Sheet SẢN LƯỢNG
A2: CỘNG HÒA DÂN CHỦ NHÂN DÂN LÀO
A3: Hòa Bình -Độc Lập - Dân Chủ - thống Nhất - Thịnh Vượng
A4: -----o0o-----
B6: CÔNG TY TNHH MTV QUASA - GERUCO LÀO
B7: ĐỘI SẢN XUẤT SỐ 04
A9: BẢNG THEO DÕI SẢN LƯỢNG MỦ TẠP THÁNG 10 NĂM 2025
A10: (Từ ngày 01 đến 31/10/2025)
A13: Stt | C13: MSNV | D13: Họ và tên | E13: Kí tên | F13: Ngày | AK13: Tổng mủ tạp | AL13: DRC bình quân | AM13: Quy khô | AN13: Tổng mủ tạp T08 | AO13: DRC bình quân T8 | AP13: Quy khô truy lỉnh T08 | AQ13: Tổng trả lương | AR13: Xếp hạng kỹ thuật
F14: 1 | G14: 2 | H14: 3 | I14: 4 | J14: 5 | K14: 6 | L14: 7 | M14: 8 | N14: 9 | O14: 10 | P14: 11 | Q14: 12 | R14: 13 | S14: 14 | T14: 15 | U14: 16 | V14: 17 | W14: 18 | X14: 19 | Y14: 20 | Z14: 21 | AA14: 22 | AB14: 23 | AC14: 24 | AD14: 25 | AE14: 26 | AF14: 27 | AG14: 28 | AH14: 29 | AI14: 30 | AJ14: 31 | AT14: DRC bình quân
A15: Lát bốc | F15: A | G15: B | H15: C | I15: D | J15: A | K15: B | L15: C | M15: D | N15: A | O15: B | P15: C | Q15: D | R15: A | S15: BC | T15: D | U15: A | V15: B | W15: C | X15: D | Y15: A | Z15: BC | AA15: D | AB15: A | AC15: B | AD15: C | AE15: D | AF15: A | AG15: B | AH15: C | AI15: D
A16: Trạm 1 | F16: =SUM(F17:F97) -> 835 | G16: =SUM(G17:G97) -> 6713 | H16: =SUM(H17:H97) -> 5962 | I16: =SUM(I17:I97) -> 6519 | J16: =SUM(J17:J97) -> 13879 | K16: =SUM(K17:K97) -> 8647 | L16: =SUM(L17:L97) -> 6851 | M16: =SUM(M17:M97) -> 13028 | ... AN16: =SUM(AN17:AN97) -> 299923 | AP16: =SUM(AP17:AP97) -> 10180 | AQ16: =SUM(AQ17:AQ97) -> 139316.23
A17: 1 | B17: 1 | C17: ='Chấm công KT'!C13 -> 0 | D17: ='Chấm công KT'!D13 -> T. Lăm | F17: 0 | G17: 127 | H17: 84 | I17: 94 | J17: 146 | K17: 101 | L17: 108 | M17: 188 | N17: 148 | O17: 100 | P17: 168 | Q17: 179 | R17: 186 | S17: 116 | T17: 127 | U17: 107 | V17: 141 | W17: 99 | X17: 117 | Y17: 136 | Z17: 161 | AA17: 104 | AB17: 125 | AC17: 121 | AD17: 162 | AE17: 92 | AF17: 121 | AG17: 170 | AH17: 182 | AI17: 123 | AJ17: 281 | AK17: =SUM(F17:AJ17) -> 4114 | AL17: 44.143706 | AM17: =AK17*AL17/100 -> 1816.0721 | AN17: 3874 | AO17: 3.3942045 | AP17: =AN17*AO17/100 -> 131.49148 | AQ17: =AM17+AP17 -> 1947.5635 | AR17: B | AW17: =AQ16/15*100 -> 928774.87
A18: 2 | B18: 2 | C18: ='Chấm công KT'!C14 -> 04052 | D18: ='Chấm công KT'!D14 -> T. Feng | F18: 0 | G18: 113 | H18: 69 | I18: 89 | J18: 191 | K18: 95 | L18: 74 | M18: 169 | N18: 139 | O18: 163 | P18: 131 | Q18: 163 | R18: 192 | S18: 146 | T18: 144 | U18: 160 | V18: 178 | W18: 109 | X18: 109 | Y18: 120 | Z18: 191 | AA18: 115 | AB18: 94 | AC18: 132 | AD18: 206 | AE18: 169 | AF18: 108 | AG18: 162 | AH18: 182 | AI18: 149 | AJ18: 140 | AK18: =SUM(F18:AJ18) -> 4202 | AL18: 44.143706 | AM18: =AK18*AL18/100 -> 1854.9185 | AN18: 3883 | AO18: 3.3942045 | AP18: =AN18*AO18/100 -> 131.79696 | AQ18: =AM18+AP18 -> 1986.7155 | AR18: B | AW18: =10180/AN16*100 -> 3.3942045
A19: 3 | B19: 3 | C19: ='Chấm công KT'!C15 -> 02725 | D19: ='Chấm công KT'!D15 -> T. Sa Văn | F19: 212 | G19: 0 | H19: 0 | I19: 141 | J19: 172 | K19: 183 | L19: 110 | M19: 200 | N19: 122 | O19: 170 | P19: 143 | Q19: 169 | R19: 170 | S19: 128 | T19: 142 | U19: 160 | V19: 166 | W19: 124 | X19: 124 | Y19: 157 | Z19: 124 | AA19: 104 | AB19: 110 | AC19: 140 | AD19: 153 | AE19: 137 | AF19: 152 | AG19: 180 | AH19: 216 | AI19: 122 | AJ19: 173 | AK19: =SUM(F19:AJ19) -> 4404 | AL19: 44.143706 | AM19: =AK19*AL19/100 -> 1944.0888 | AN19: 5035 | AO19: 3.3942045 | AP19: =AN19*AO19/100 -> 170.8982 | AQ19: =AM19+AP19 -> 2114.987 | AR19: B
A20: 4 | B20: 4 | C20: ='Chấm công KT'!C16 -> 04053 | D20: ='Chấm công KT'!D16 -> Lăm Ma Thu | F20: 0 | G20: 0 | H20: 0 | I20: 76 | J20: 228 | K20: 170 | L20: 83 | M20: 145 | N20: 0 | O20: 122 | P20: 89 | Q20: 128 | R20: 221 | S20: 0 | T20: 0 | U20: 104 | V20: 0 | W20: 123 | X20: 161 | Y20: 119 | Z20: 199 | AA20: 129 | AB20: 101 | AC20: 100 | AD20: 203 | AE20: 60 | AF20: 91 | AG20: 155 | AH20: 175 | AI20: 87 | AJ20: 144 | AK20: =SUM(F20:AJ20) -> 3213 | AL20: 44.143706 | AM20: =AK20*AL20/100 -> 1418.3373 | AN20: 3912 | AO20: 3.3942045 | AP20: =AN20*AO20/100 -> 132.78128 | AQ20: =AM20+AP20 -> 1551.1185 | AR20: B
A21: 5 | B21: 5 | C21: ='Chấm công KT'!C17 -> 03459 | D21: ='Chấm công KT'!D17 -> N. Vạt | F21: 0 | G21: 63 | H21: 129 | I21: 60 | J21: 153 | K21: 90 | L21: 92 | M21: 154 | N21: 114 | O21: 80 | P21: 174 | Q21: 127 | R21: 0 | S21: 160 | T21: 167 | U21: 0 | V21: 141 | W21: 133 | X21: 207 | Y21: 198 | Z21: 0 | AA21: 112 | AB21: 155 | AC21: 156 | AD21: 180 | AE21: 0 | AF21: 118 | AG21: 156 | AH21: 162 | AI21: 169 | AJ21: 210 | AK21: =SUM(F21:AJ21) -> 3660 | AL21: 44.143706 | AM21: =AK21*AL21/100 -> 1615.6596 | AN21: 3471 | AO21: 3.3942045 | AP21: =AN21*AO21/100 -> 117.81284 | AQ21: =AM21+AP21 -> 1733.4725 | AR21: B
A22: 6 | B22: 6 | C22: ='Chấm công KT'!C18 -> 04054 | D22: ='Chấm công KT'!D18 -> N. Kay Son | F22: 0 | G22: 0 | H22: 100 | I22: 79 | J22: 148 | K22: 147 | L22: 117 | M22: 207 | N22: 150 | O22: 150 | P22: 166 | Q22: 198 | R22: 177 | S22: 141 | T22: 125 | U22: 161 | V22: 203 | W22: 106 | X22: 140 | Y22: 160 | Z22: 194 | AA22: 121 | AB22: 133 | AC22: 151 | AD22: 198 | AE22: 158 | AF22: 141 | AG22: 170 | AH22: 226 | AI22: 122 | AJ22: 160 | AK22: =SUM(F22:AJ22) -> 4449 | AL22: 44.143706 | AM22: =AK22*AL22/100 -> 1963.9535 | AN22: 4292 | AO22: 3.3942045 | AP22: =AN22*AO22/100 -> 145.67926 | AQ22: =AM22+AP22 -> 2109.6327 | AR22: B
A23: 7 | B23: 7 | C23: ='Chấm công KT'!C19 -> 04055 | D23: ='Chấm công KT'!D19 -> T. Đèng 1 | F23: 0 | G23: 0 | H23: 135 | I23: 157 | J23: 195 | K23: 123 | L23: 143 | M23: 162 | N23: 115 | O23: 104 | P23: 136 | Q23: 159 | R23: 179 | S23: 164 | T23: 131 | U23: 176 | V23: 141 | W23: 161 | X23: 119 | Y23: 138 | Z23: 152 | AA23: 101 | AB23: 0 | AC23: 145 | AD23: 95 | AE23: 146 | AF23: 144 | AG23: 170 | AH23: 141 | AI23: 115 | AJ23: 106 | AK23: =SUM(F23:AJ23) -> 3953 | AL23: 44.143706 | AM23: =AK23*AL23/100 -> 1745.0007 | AN23: 3779 | AO23: 3.3942045 | AP23: =AN23*AO23/100 -> 128.26699 | AQ23: =AM23+AP23 -> 1873.2677 | AR23: A
A24: 8 | B24: 8 | C24: ='Chấm công KT'!C20 -> 03462 | D24: ='Chấm công KT'!D20 -> T . Bua Ngân | F24: 0 | G24: 126 | H24: 110 | I24: 131 | J24: 194 | K24: 117 | L24: 102 | M24: 158 | N24: 83 | O24: 159 | P24: 126 | Q24: 154 | R24: 114 | S24: 123 | T24: 0 | U24: 0 | V24: 137 | W24: 114 | X24: 154 | Y24: 222 | Z24: 151 | AA24: 118 | AB24: 115 | AC24: 131 | AD24: 116 | AE24: 0 | AF24: 111 | AG24: 158 | AH24: 95 | AI24: 178 | AJ24: 122 | AK24: =SUM(F24:AJ24) -> 3619 | AL24: 44.143706 | AM24: =AK24*AL24/100 -> 1597.5607 | AN24: 3373 | AO24: 3.3942045 | AP24: =AN24*AO24/100 -> 114.48652 | AQ24: =AM24+AP24 -> 1712.0472 | AR24: A
A25: 9 | B25: 9 | C25: ='Chấm công KT'!C21 -> 03463 | D25: ='Chấm công KT'!D21 -> T Căng | F25: 0 | G25: 130 | H25: 141 | I25: 77 | J25: 204 | K25: 91 | L25: 101 | M25: 172 | N25: 106 | O25: 94 | P25: 253 | Q25: 158 | R25: 143 | S25: 176 | T25: 182 | U25: 0 | V25: 160 | W25: 153 | X25: 237 | Y25: 322 | Z25: 145 | AA25: 162 | AB25: 138 | AC25: 171 | AD25: 181 | AE25: 125 | AF25: 131 | AG25: 171 | AH25: 143 | AI25: 151 | AJ25: 235 | AK25: =SUM(F25:AJ25) -> 4653 | AL25: 44.143706 | AM25: =AK25*AL25/100 -> 2054.0066 | AN25: 4784 | AO25: 3.3942045 | AP25: =AN25*AO25/100 -> 162.37874 | AQ25: =AM25+AP25 -> 2216.3854 | AR25: A
A26: 10 | B26: 10 | C26: ='Chấm công KT'!C22 -> 03464 | D26: ='Chấm công KT'!D22 -> N. Phôn 1 | F26: 0 | G26: 136 | H26: 122 | I26: 84 | J26: 214 | K26: 100 | L26: 124 | M26: 191 | N26: 104 | O26: 94 | P26: 251 | Q26: 179 | R26: 141 | S26: 181 | T26: 180 | U26: 0 | V26: 120 | W26: 160 | X26: 240 | Y26: 312 | Z26: 150 | AA26: 161 | AB26: 160 | AC26: 186 | AD26: 175 | AE26: 120 | AF26: 158 | AG26: 184 | AH26: 147 | AI26: 161 | AJ26: 250 | AK26: =SUM(F26:AJ26) -> 4785 | AL26: 44.143706 | AM26: =AK26*AL26/100 -> 2112.2763 | AN26: 4831 | AO26: 3.3942045 | AP26: =AN26*AO26/100 -> 163.97402 | AQ26: =AM26+AP26 -> 2276.2503 | AR26: A
A27: 11 | B27: 11 | C27: ='Chấm công KT'!C23 -> 03465 | D27: ='Chấm công KT'!D23 -> T. In Păn | F27: 0 | G27: 106 | H27: 138 | I27: 0 | J27: 203 | K27: 90 | L27: 135 | M27: 213 | N27: 0 | O27: 56 | P27: 194 | Q27: 170 | R27: 192 | S27: 107 | T27: 194 | U27: 164 | V27: 148 | W27: 110 | X27: 186 | Y27: 154 | Z27: 202 | AA27: 0 | AB27: 150 | AC27: 132 | AD27: 140 | AE27: 140 | AF27: 207 | AG27: 216 | AH27: 174 | AI27: 0 | AJ27: 176 | AK27: =SUM(F27:AJ27) -> 4097 | AL27: 44.143706 | AM27: =AK27*AL27/100 -> 1808.5676 | AN27: 3949 | AO27: 3.3942045 | AP27: =AN27*AO27/100 -> 134.03714 | AQ27: =AM27+AP27 -> 1942.6048 | AR27: A
A28: 12 | B28: 12 | C28: ='Chấm công KT'!C24 -> 03466 | D28: ='Chấm công KT'!D24 -> N. Keo | F28: 0 | G28: 106 | H28: 110 | I28: 90 | J28: 211 | K28: 88 | L28: 96 | M28: 162 | N28: 92 | O28: 180 | P28: 228 | Q28: 142 | R28: 186 | S28: 158 | T28: 178 | U28: 116 | V28: 156 | W28: 120 | X28: 154 | Y28: 0 | Z28: 188 | AA28: 138 | AB28: 164 | AC28: 146 | AD28: 180 | AE28: 156 | AF28: 205 | AG28: 160 | AH28: 213 | AI28: 124 | AJ28: 263 | AK28: =SUM(F28:AJ28) -> 4510 | AL28: 44.143706 | AM28: =AK28*AL28/100 -> 1990.8811 | AN28: 4330 | AO28: 3.3942045 | AP28: =AN28*AO28/100 -> 146.96906 | AQ28: =AM28+AP28 -> 2137.8502 | AR28: A
A29: 13 | B29: 13 | C29: ='Chấm công KT'!C25 -> 02727 | D29: ='Chấm công KT'!D25 -> T. Thong Đon | F29: 0 | G29: 170 | H29: 146 | I29: 81 | J29: 191 | K29: 105 | L29: 100 | M29: 213 | N29: 93 | O29: 104 | P29: 222 | Q29: 133 | R29: 163 | S29: 186 | T29: 173 | U29: 120 | V29: 128 | W29: 207 | X29: 201 | Y29: 162 | Z29: 141 | AA29: 121 | AB29: 189 | AC29: 109 | AD29: 108 | AE29: 110 | AF29: 169 | AG29: 182 | AH29: 188 | AI29: 161 | AJ29: 274 | AK29: =SUM(F29:AJ29) -> 4650 | AL29: 44.143706 | AM29: =AK29*AL29/100 -> 2052.6823 | AN29: 4257 | AO29: 3.3942045 | AP29: =AN29*AO29/100 -> 144.49129 | AQ29: =AM29+AP29 -> 2197.1736 | AR29: B
A30: 14 | B30: 14 | C30: ='Chấm công KT'!C26 -> 03467 | D30: ='Chấm công KT'!D26 -> T. Hin | F30: 0 | G30: 128 | H30: 81 | I30: 71 | J30: 145 | K30: 111 | L30: 0 | M30: 200 | N30: 76 | O30: 120 | P30: 222 | Q30: 112 | R30: 113 | S30: 147 | T30: 130 | U30: 0 | V30: 142 | W30: 200 | X30: 109 | Y30: 158 | Z30: 119 | AA30: 152 | AB30: 110 | AC30: 97 | AD30: 134 | AE30: 178 | AF30: 112 | AG30: 91 | AH30: 144 | AI30: 146 | AJ30: 172 | AK30: =SUM(F30:AJ30) -> 3720 | AL30: 44.143706 | AM30: =AK30*AL30/100 -> 1642.1459 | AN30: 3486 | AO30: 3.3942045 | AP30: =AN30*AO30/100 -> 118.32197 | AQ30: =AM30+AP30 -> 1760.4678 | AR30: A
... A89: 73 | B89: 73 | C89: ='Chấm công KT'!C85 -> 04071 | D89: ='Chấm công KT'!D85 -> T. Ne | F89: 0 | G89: 131 | H89: 0 | I89: 122 | J89: 0 | K89: 0 | L89: 0 | M89: 146 | N89: 0 | O89: 0 | P89: 0 | Q89: 0 | R89: 165 | S89: 0 | T89: 110 | U89: 122 | V89: 58 | W89: 52 | X89: 78 | Y89: 73 | Z89: 73 | AA89: 76 | AB89: 77 | AC89: 77 | AD89: 70 | AE89: 70 | AF89: 75 | AG89: 75 | AH89: 120 | AI89: 143 | AJ89: 150 | AK89: =SUM(F89:AJ89) -> 2063 | AL89: 44.143706 | AM89: =AK89*AL89/100 -> 910.68465 | AN89: 2721 | AO89: 3.3942045 | AP89: =AN89*AO89/100 -> 92.356305 | AQ89: =AM89+AP89 -> 1003.041 | AR89: A
A90: 74 | B90: 74 | D90: ='Chấm công KT'!D86 -> N. Khăn | F90: 0 | G90: 87 | H90: 12 | I90: 0 | J90: 0 | K90: 0 | L90: 0 | M90: 0 | N90: 0 | O90: 93 | P90: 56 | Q90: 0 | R90: 0 | S90: 0 | T90: 0 | U90: 0 | V90: 0 | W90: 59 | X90: 59 | Y90: 0 | Z90: 0 | AA90: 0 | AB90: 0 | AC90: 0 | AD90: 0 | AE90: 105 | AF90: 93 | AG90: 0 | AH90: 0 | AI90: 0 | AJ90: 0 | AK90: =SUM(F90:AJ90) -> 564 | AL90: 44.143706 | AM90: =AK90*AL90/100 -> 248.9705 | AN90: 2466 | AO90: 3.3942045 | AP90: =AN90*AO90/100 -> 83.701083 | AQ90: =AM90+AP90 -> 332.67158 | AR90: C.
A91: 75 | B91: 75 | D91: ='Chấm công KT'!D87 -> T. Lã | F91: 0 | G91: 0 | H91: 0 | I91: 0 | J91: 161 | K91: 184 | L91: 80 | M91: 0 | N91: 0 | O91: 151 | P91: 0 | Q91: 126 | R91: 0 | S91: 128 | T91: 121 | U91: 229 | V91: 0 | W91: 70 | X91: 0 | Y91: 70 | Z91: 0 | AA91: 67 | AB91: 150 | AC91: 140 | AD91: 138 | AE91: 155 | AF91: 163 | AG91: 110 | AH91: 132 | AI91: 72 | AJ91: 0 | AK91: =SUM(F91:AJ91) -> 2447 | AL91: 44.143706 | AM91: =AK91*AL91/100 -> 1080.1965 | AN91: 1079 | AO91: 3.3942045 | AP91: =AN91*AO91/100 -> 36.623467 | AQ91: =AM91+AP91 -> 1116.8199 | AR91: C.
A92: 76 | B92: 76 | D92: ='Chấm công KT'!D88 -> N. Veo | F92: 0 | G92: 0 | H92: 0 | I92: 0 | J92: 161 | K92: 184 | L92: 73 | M92: 0 | N92: 0 | O92: 0 | P92: 0 | Q92: 0 | R92: 0 | S92: 134 | T92: 117 | U92: 80 | V92: 0 | W92: 68 | X92: 0 | Y92: 102 | Z92: 0 | AA92: 63 | AB92: 156 | AC92: 154 | AD92: 129 | AE92: 102 | AF92: 180 | AG92: 108 | AH92: 133 | AI92: 78 | AJ92: 0 | AK92: =SUM(F92:AJ92) -> 2022 | AL92: 44.143706 | AM92: =AK92*AL92/100 -> 892.58573 | AN92: 456 | AO92: 3.3942045 | AP92: =AN92*AO92/100 -> 15.477573 | AQ92: =AM92+AP92 -> 908.0633 | AR92: C.
A93: 77 | B93: 77 | D93: ='Chấm công KT'!D89 -> T. Pu | F93: 0 | G93: 0 | H93: 0 | I93: 0 | J93: 0 | K93: 0 | L93: 70 | M93: 0 | N93: 0 | O93: 0 | P93: 0 | Q93: 0 | R93: 0 | S93: 132 | T93: 122 | U93: 0 | V93: 0 | W93: 66 | X93: 0 | Y93: 125 | Z93: 0 | AA93: 98 | AB93: 105 | AC93: 141 | AD93: 0 | AE93: 112 | AF93: 126 | AG93: 0 | AH93: 0 | AI93: 78 | AJ93: 109 | AK93: =SUM(F93:AJ93) -> 1284 | AL93: 44.143706 | AM93: =AK93*AL93/100 -> 566.80518 | AN93: 397 | AO93: 3.3942045 | AP93: =AN93*AO93/100 -> 13.474992 | AQ93: =AM93+AP93 -> 580.28017 | AR93: C.
A94: 78 | B94: 78 | D94: ='Chấm công KT'!D90 -> T. Ta. | F94: 0 | G94: 0 | H94: 0 | I94: 0 | J94: 0 | K94: 0 | L94: 0 | M94: 0 | N94: 0 | O94: 0 | P94: 0 | Q94: 0 | R94: 0 | S94: 0 | T94: 0 | U94: 0 | V94: 0 | W94: 0 | X94: 0 | Y94: 103 | Z94: 0 | AA94: 102 | AB94: 102 | AC94: 0 | AD94: 0 | AE94: 0 | AF94: 128 | AG94: 0 | AH94: 0 | AI94: 75 | AJ94: 127 | AK94: =SUM(F94:AJ94) -> 637 | AL94: 44.143706 | AM94: =AK94*AL94/100 -> 281.19541 | AN94: 325 | AO94: 3.3942045 | AP94: =AN94*AO94/100 -> 11.031165 | AQ94: =AM94+AP94 -> 292.22657 | AR94: C.
A95: 79 | B95: 79 | D95: ='Chấm công KT'!D91 -> N. Nang | F95: 0 | G95: 0 | H95: 0 | I95: 0 | J95: 0 | K95: 0 | L95: 0 | M95: 0 | N95: 0 | O95: 0 | P95: 0 | Q95: 0 | R95: 0 | S95: 0 | T95: 0 | U95: 0 | V95: 0 | W95: 0 | X95: 0 | Y95: 0 | Z95: 101 | AA95: 104 | AB95: 0 | AC95: 0 | AD95: 0 | AE95: 0 | AF95: 112 | AG95: 0 | AH95: 0 | AI95: 0 | AJ95: 110 | AK95: =SUM(F95:AJ95) -> 427 | AL95: 44.143706 | AM95: =AK95*AL95/100 -> 188.49362 | AQ95: =AM95+AP95 -> 188.49362 | AR95: C.
A96: 80 | B96: 80 | D96: ='Chấm công KT'!D92 -> T. Tan | F96: 0 | G96: 0 | H96: 0 | I96: 0 | J96: 0 | K96: 0 | L96: 0 | M96: 0 | N96: 0 | O96: 0 | P96: 0 | Q96: 0 | R96: 0 | S96: 0 | T96: 0 | U96: 0 | V96: 0 | W96: 0 | X96: 0 | Y96: 0 | Z96: 104 | AA96: 0 | AB96: 0 | AC96: 0 | AD96: 0 | AE96: 0 | AF96: 109 | AG96: 0 | AH96: 0 | AI96: 0 | AJ96: 118 | AK96: =SUM(F96:AJ96) -> 331 | AL96: 44.143706 | AM96: =AK96*AL96/100 -> 146.11567 | AQ96: =AM96+AP96 -> 146.11567 | AR96: C.
A97: 81 | B97: 81 | D97: ='Chấm công KT'!D93 -> 0 | AI97: 0 | AK97: =SUM(F97:AJ97) -> 0 | AQ97: =AK97*AL97/100 -> 0 | AR97: C.
A98: Tram 2 | F98: =SUM(F99:F160) -> 3877 | G98: =SUM(G99:G160) -> 7788 | H98: =SUM(H99:H160) -> 3635 | I98: =SUM(I99:I160) -> 12542 | J98: =SUM(J99:J160) -> 8504 | K98: =SUM(K99:K160) -> 5220 | L98: =SUM(L99:L160) -> 6372 | M98: =SUM(M99:M160) -> 7388 | ... AN98: =SUM(AN99:AN160) -> 237754 | AP98: =SUM(AP99:AP160) -> 8081 | AQ98: =SUM(AQ99:AQ160) -> 109452.58
A99: 81 | B99: 1 | C99: ='Chấm công KT'!C95 -> 04072 | D99: ='Chấm công KT'!D95 -> T. Lun | F99: 105 | G99: 160 | H99: 123 | I99: 139 | J99: 107 | K99: 142 | L99: 156 | M99: 79 | N99: 102 | O99: 160 | P99: 273 | Q99: 0 | R99: 118 | S99: 104 | T99: 146 | U99: 164 | V99: 99 | W99: 192 | X99: 128 | Y99: 116 | Z99: 60 | AA99: 82 | AB99: 103 | AC99: 135 | AD99: 82 | AE99: 85 | AF99: 119 | AG99: 142 | AH99: 135 | AI99: 70 | AJ99: 116 | AK99: =SUM(F99:AJ99) -> 3742 | AL99: 43.742536 | AM99: =AK99*AL99/100 -> 1636.8457 | AN99: 4099 | AO99: 3.3988913 | AP99: =AN99*AO99/100 -> 139.32055 | AQ99: =AM99+AP99 -> 1776.1662 | AR99: A
A100: 82 | B100: 2 | C100: ='Chấm công KT'!C96 -> 03466 | D100: ='Chấm công KT'!D96 -> N. Keo | F100: 376 | G100: 0 | H100: 43 | I100: 242 | J100: 173 | K100: 71 | L100: 198 | M100: 103 | N100: 88 | O100: 0 | P100: 377 | Q100: 184 | R100: 81 | S100: 179 | T100: 181 | U100: 0 | V100: 119 | W100: 124 | X100: 131 | Y100: 0 | Z100: 0 | AA100: 0 | AB100: 0 | AC100: 72 | AD100: 125 | AE100: 281 | AF100: 177 | AG100: 55 | AH100: 112 | AI100: 0 | AJ100: 88 | AK100: =SUM(F100:AJ100) -> 3580 | AL100: 43.742536 | AM100: =AK100*AL100/100 -> 1565.9828 | AN100: 4332 | AO100: 3.3988913 | AP100: =AN100*AO100/100 -> 147.23997 | AQ100: =AM100+AP100 -> 1713.2228 | AR100: A | AW100: =8081/AN98*100 -> 3.3988913
A101: 83 | B101: 3 | C101: ='Chấm công KT'!C97 -> 03590 | D101: ='Chấm công KT'!D97 -> T .Nhum | F101: 93 | G101: 139 | H101: 106 | I101: 177 | J101: 169 | K101: 92 | L101: 0 | M101: 95 | N101: 168 | O101: 105 | P101: 324 | Q101: 236 | R101: 86 | S101: 78 | T101: 101 | U101: 206 | V101: 70 | W101: 173 | X101: 224 | Y101: 85 | Z101: 94 | AA101: 75 | AB101: 0 | AC101: 73 | AD101: 92 | AE101: 80 | AF101: 188 | AG101: 84 | AH101: 68 | AI101: 83 | AJ101: 174 | AK101: =SUM(F101:AJ101) -> 3738 | AL101: 43.742536 | AM101: =AK101*AL101/100 -> 1635.096 | AN101: 3851 | AO101: 3.3988913 | AP101: =AN101*AO101/100 -> 130.8913 | AQ101: =AM101+AP101 -> 1765.9873 | AR101: A
A102: 84 | B102: 4 | C102: ='Chấm công KT'!C98 -> 03591 | D102: ='Chấm công KT'!D98 -> N.Vông Ma Ni | F102: 0 | G102: 125 | H102: 140 | I102: 252 | J102: 119 | K102: 130 | L102: 0 | M102: 103 | N102: 113 | O102: 137 | P102: 465 | Q102: 223 | R102: 0 | S102: 124 | T102: 113 | U102: 143 | V102: 199 | W102: 167 | X102: 127 | Y102: 0 | Z102: 96 | AA102: 0 | AB102: 0 | AC102: 218 | AD102: 61 | AE102: 140 | AF102: 191 | AG102: 131 | AH102: 105 | AI102: 113 | AJ102: 114 | AK102: =SUM(F102:AJ102) -> 3849 | AL102: 43.742536 | AM102: =AK102*AL102/100 -> 1683.6502 | AN102: 3696 | AO102: 3.3988913 | AP102: =AN102*AO102/100 -> 125.62302 | AQ102: =AM102+AP102 -> 1809.2732 | AR102: A
A103: 85 | B103: 5 | C103: ='Chấm công KT'!C99 -> 03592 | D103: ='Chấm công KT'!D99 -> Đao Hương | F103: 0 | G103: 129 | H103: 117 | I103: 259 | J103: 107 | K103: 112 | L103: 0 | M103: 94 | N103: 110 | O103: 133 | P103: 416 | Q103: 179 | R103: 0 | S103: 100 | T103: 128 | U103: 161 | V103: 159 | W103: 198 | X103: 147 | Y103: 0 | Z103: 90 | AA103: 0 | AB103: 0 | AC103: 197 | AD103: 81 | AE103: 135 | AF103: 170 | AG103: 118 | AH103: 87 | AI103: 108 | AJ103: 119 | AK103: =SUM(F103:AJ103) -> 3654 | AL103: 43.742536 | AM103: =AK103*AL103/100 -> 1598.3523 | AN103: 3659 | AO103: 3.3988913 | AP103: =AN103*AO103/100 -> 124.36543 | AQ103: =AM103+AP103 -> 1722.7177 | AR103: A
...

Sheet MỦ SERUM
A1: CỘNG HÒA DÂN CHỦ NHÂN DÂN LÀO
A2: Hòa Bình -Độc Lập - Dân Chủ - thống Nhất - Thịnh Vượng
A3: -----o0o-----
A5: CÔNG TY TNHH MTV QUASA - GERUCO LÀO
A6: ĐỘI SẢN XUẤT SỐ 4
A12: BẢNG THEO DÕI SẢN LƯỢNG MỦ SERUM THÁNG 10 NĂM 2025
AK13: DRC
A14: Stt | B14: Họ và tên | C14: Ngày | AH14: Tổng mủ Xirum | AI14: DRC bình quân | AJ14: Quy khô | AK14: Xếp hạng kỹ thuật | AL14: Kí tên
C15: 1 | D15: 2 | E15: 3 | F15: 4 | G15: 5 | H15: 6 | I15: 7 | J15: 8 | K15: 9 | L15: 10 | M15: 11 | N15: 12 | O15: 13 | P15: 14 | Q15: 15 | R15: 16 | S15: 17 | T15: 18 | U15: 19 | V15: 20 | W15: 21 | X15: 22 | Y15: 23 | Z15: 24 | AA15: 25 | AB15: 26 | AC15: 27 | AD15: 28 | AE15: 29 | AF15: 30 | AG15: 31
A16: Trạm 1 | C16: =C17 -> 0 | D16: =D17 -> 0 | E16: =E17 -> 0 | F16: =F17 -> 0 | G16: =G17 -> 0 | H16: =H17 -> 0 | I16: =I17 -> 0 | J16: =J17 -> 0 | ... AH16: =AH17 -> 300 | AJ16: =AJ17 -> 164.97 | AK16: =AK17 -> 0
A17: 1 | B17: Mủ Xirum | V17: 300 | AH17: =SUM(C17:AG17) -> 300 | AI17: 54.99 | AJ17: =AH17*AI17/100 -> 164.97
A18: Trạm 2 | C18: =C19 -> 0 | D18: =D19 -> 0 | E18: =E19 -> 0 | F18: =F19 -> 0 | G18: =G19 -> 0 | H18: =H19 -> 0 | I18: =I19 -> 0 | J18: =J19 -> 0 | ... AH18: =AH19 -> 485 | AJ18: =AJ19 -> 259.182
A19: 1 | B19: Mủ Xirum | X19: 280 | AG19: 205 | AH19: =SUM(C19:AG19) -> 485 | AI19: 53.439588 | AJ19: =AH19*AI19/100 -> 259.182
A20: Tổng cộng | V20: =V16+V18 -> 300 | X20: =X16+X18 -> 280 | AG20: =AG16+AG18 -> 205 | AH20: =AH16+AH18 -> 785 | AJ20: =AJ16+AJ18 -> 424.152 | AK20: =AK16+AK18+#REF!+#REF! -> #REF!
Y22: Mường phìn, ngày 02 tháng 11 năm 2025
A23: TỔNG GIÁM ĐỐC PHÒNG QL - KT P. PHÒNG PHỤ TRÁCH ĐỘI TRƯỞNG NGƯỜI LẬP | AS23: MỦ

Sheet Chấm công KT
B1: CỘNG HÒA DÂN CHỦ NHÂN DÂN LÀO
B2: Hòa Bình -Độc Lập - Dân Chủ - thống Nhất - Thịnh Vượng
B3: -----o0o-----
B5: CÔNG TY TNHH MTV QUASA - GERUCO LÀO
B6: ĐỘI SẢN XUẤT SỐ 04
B7: BẢNG CHẤM CÔNG PHỤ CẤP CHO CÔNG NHÂN KHAI THÁC THÁNG 10 NĂM 2025
A8: (Từ ngày 01/10 đến 31/10/2025)
A10: STT | C10: MSNV | D10: HỌ VÀ TÊN | E10: Kí tên | F10: Phụ cấp ngày cạo, ngày chủ nhật | AK10: Ngày công đi cạo thường | AL10: Ngày CN thường | AM10: Ngày công đi cạo 2 lát (đ) | AN10: Ngày công chủ nhật cạo 2 lát (đc) | AO10: Ngày công cạo gia tăng 2 miêng (gt) | AP10: Ngày chủ nhật cạo gia tăng 2 miệng (ct) | AQ10: Tổng công | AU10: Ngày công đi cạo thường (x) | AV10: Ngày CN thường (cn) | AW10: Ngày công đi cạo 2 lát (đ) | AX10: Ngày công chủ nhật cạo 2 lát (đc) | AY10: Ngày công cạo gia tăng 2 miêng (gt) | AZ10: Ngày chủ nhật cạo gia tăng 2 miệng (ct)
F11: 1 | G11: 2 | H11: 3 | I11: 4 | J11: 5 | K11: 6 | L11: 7 | M11: 8 | N11: 9 | O11: 10 | P11: 11 | Q11: 12 | R11: 13 | S11: 14 | T11: 15 | U11: 16 | V11: 17 | W11: 18 | X11: 19 | Y11: 20 | Z11: 21 | AA11: 22 | AB11: 23 | AC11: 24 | AD11: 25 | AE11: 26 | AF11: 27 | AG11: 28 | AH11: 29 | AI11: 30 | AJ11: 31
A12: Trạm 1 | F12: =SUM(COUNTIF(F13:F93,"x"))+(COUNTIF(F13:F93,"cn"))+(COUNTIF(F13:F93,"gt"))+(COUNTIF(F13:F93,"ct"))+(COUNTIF(F13:F93,"đ"))+(COUNTIF(F13:F93,"đc")) -> 73 | G12: =SUM(COUNTIF(G13:G93,"x"))+(COUNTIF(G13:G93,"cn"))+(COUNTIF(G13:G93,"gt"))+(COUNTIF(G13:G93,"ct"))+(COUNTIF(G13:G93,"đ"))+(COUNTIF(G13:G93,"đc")) -> 73 | H12: =SUM(COUNTIF(H13:H93,"x"))+(COUNTIF(H13:H93,"cn"))+(COUNTIF(H13:H93,"gt"))+(COUNTIF(H13:H93,"ct"))+(COUNTIF(H13:H93,"đ"))+(COUNTIF(H13:H93,"đc")) -> 74 | I12: =SUM(COUNTIF(I13:I93,"x"))+(COUNTIF(I13:I93,"cn"))+(COUNTIF(I13:I93,"gt"))+(COUNTIF(I13:I93,"ct"))+(COUNTIF(I13:I93,"đ"))+(COUNTIF(I13:I93,"đc")) -> 74 | J12: =SUM(COUNTIF(J13:J93,"x"))+(COUNTIF(J13:J93,"cn"))+(COUNTIF(J13:J93,"gt"))+(COUNTIF(J13:J93,"ct"))+(COUNTIF(J13:J93,"đ"))+(COUNTIF(J13:J93,"đc")) -> 73 | K12: =SUM(COUNTIF(K13:K93,"x"))+(COUNTIF(K13:K93,"cn"))+(COUNTIF(K13:K93,"gt"))+(COUNTIF(K13:K93,"ct"))+(COUNTIF(K13:K93,"đ"))+(COUNTIF(K13:K93,"đc")) -> 73 | L12: =SUM(COUNTIF(L13:L93,"x"))+(COUNTIF(L13:L93,"cn"))+(COUNTIF(L13:L93,"gt"))+(COUNTIF(L13:L93,"ct"))+(COUNTIF(L13:L93,"đ"))+(COUNTIF(L13:L93,"đc")) -> 74 | M12: =SUM(COUNTIF(M13:M93,"x"))+(COUNTIF(M13:M93,"cn"))+(COUNTIF(M13:M93,"gt"))+(COUNTIF(M13:M93,"ct"))+(COUNTIF(M13:M93,"đ"))+(COUNTIF(M13:M93,"đc")) -> 74 | ... AJ12: =SUM(COUNTIF(AJ13:AJ93,"x"))+(COUNTIF(AJ13:AJ93,"cn"))+(COUNTIF(AJ13:AJ93,"gt"))+(COUNTIF(AJ13:AJ93,"ct"))+(COUNTIF(AJ13:AJ93,"đ"))+(COUNTIF(AJ13:AJ93,"đc")) -> 74 | AK12: =SUM(AK13:AK93) -> 1974 | AL12: =SUM(AL13:AL93) -> 294 | AM12: =SUM(AM13:AM93) -> 0 | AN12: =SUM(AN13:AN93) -> 0 | AO12: =SUM(AO13:AO93) -> 0 | AP12: =SUM(AP13:AP93) -> 0 | AQ12: =SUM(AQ13:AQ93) -> 2268 | AS12: =VLOOKUP(D13,'Mã số nhân viên'!B3:I74,8,0) -> #N/A | AT12: =C13-AS12 -> #N/A
A13: 1 | B13: 1 | D13: T. Lăm | F13: x | G13: x | H13: x | I13: x | J13: cn | K13: x | L13: x | M13: x | N13: x | O13: x | P13: x | Q13: cn | R13: x | S13: x | T13: x | U13: x | V13: x | W13: x | X13: cn | Y13: x | Z13: x | AA13: x | AB13: x | AC13: x | AD13: x | AE13: cn | AF13: x | AG13: x | AH13: x | AI13: x | AJ13: x | AK13: =SUM(COUNTIF(F13:AJ13,"x")) -> 27 | AL13: =SUM(COUNTIF(F13:AJ13,"cn")) -> 4 | AM13: =SUM(COUNTIF(F13:AJ13,"đ")) -> 0 | AN13: =SUM(COUNTIF(F13:AJ13,"đc")) -> 0 | AO13: =SUM(COUNTIF(F13:AJ13,"gt")) -> 0 | AP13: =SUM(COUNTIF(F13:AJ13,"ct")) -> 0 | AQ13: =AK13+AL13+AM13+AN13+AO13+AP13 -> 31 | AS13: =VLOOKUP(D13,'Mã số nhân viên'!B3:I75,8,0) -> #N/A | AT13: =C14-AS13 -> #N/A
A14: 2 | B14: 2 | C14: =VLOOKUP(D14,'Mã số nhân viên'!B4:I135,8,0) -> 04052 | D14: T. Feng | F14: x | G14: x | H14: x | I14: x | J14: cn | K14: x | L14: x | M14: x | N14: x | O14: x | P14: x | Q14: cn | R14: x | S14: x | T14: x | U14: x | V14: x | W14: x | X14: cn | Y14: x | Z14: x | AA14: x | AB14: x | AC14: x | AD14: x | AE14: cn | AF14: x | AG14: x | AH14: x | AI14: x | AJ14: x | AK14: =SUM(COUNTIF(F14:AJ14,"x")) -> 27 | AL14: =SUM(COUNTIF(F14:AJ14,"cn")) -> 4 | AM14: =SUM(COUNTIF(F14:AJ14,"đ")) -> 0 | AN14: =SUM(COUNTIF(F14:AJ14,"đc")) -> 0 | AO14: =SUM(COUNTIF(F14:AJ14,"gt")) -> 0 | AP14: =SUM(COUNTIF(F14:AJ14,"ct")) -> 0 | AQ14: =AK14+AL14+AM14+AN14+AO14+AP14 -> 31 | AS14: =VLOOKUP(D14,'Mã số nhân viên'!B4:I76,8,0) -> 04052 | AT14: =C14-AS14 -> 0
A15: 3 | B15: 3 | C15: =VLOOKUP(D15,'Mã số nhân viên'!B5:I136,8,0) -> 02725 | D15: T. Sa Văn | F15: x | G15: x | H15: x | I15: x | J15: cn | K15: x | L15: x | M15: x | N15: x | O15: x | P15: x | Q15: cn | R15: x | S15: x | T15: x | U15: x | V15: x | W15: x | X15: cn | Y15: x | Z15: x | AA15: x | AB15: x | AC15: x | AD15: tt | AE15: cn | AF15: x | AG15: x | AH15: x | AI15: x | AJ15: x | AK15: =SUM(COUNTIF(F15:AJ15,"x")) -> 26 | AL15: =SUM(COUNTIF(F15:AJ15,"cn")) -> 4 | AM15: =SUM(COUNTIF(F15:AJ15,"đ")) -> 0 | AN15: =SUM(COUNTIF(F15:AJ15,"đc")) -> 0 | AO15: =SUM(COUNTIF(F15:AJ15,"gt")) -> 0 | AP15: =SUM(COUNTIF(F15:AJ15,"ct")) -> 0 | AQ15: =AK15+AL15+AM15+AN15+AO15+AP15 -> 30 | AS15: =VLOOKUP(D15,'Mã số nhân viên'!B5:I77,8,0) -> 02725 | AT15: =C15-AS15 -> 0
A16: 4 | B16: 4 | C16: =VLOOKUP(D16,'Mã số nhân viên'!B6:I137,8,0) -> 04053 | D16: Lăm Ma Thu | F16: x | G16: x | H16: x | I16: x | J16: cn | K16: x | L16: x | M16: x | N16: x | O16: x | P16: x | Q16: cn | R16: x | S16: tt | U16: x | V16: x | W16: x | X16: cn | Y16: x | Z16: x | AA16: x | AB16: x | AC16: x | AD16: x | AE16: cn | AF16: x | AG16: x | AH16: x | AI16: x | AJ16: x | AK16: =SUM(COUNTIF(F16:AJ16,"x")) -> 25 | AL16: =SUM(COUNTIF(F16:AJ16,"cn")) -> 4 | AM16: =SUM(COUNTIF(F16:AJ16,"đ")) -> 0 | AN16: =SUM(COUNTIF(F16:AJ16,"đc")) -> 0 | AO16: =SUM(COUNTIF(F16:AJ16,"gt")) -> 0 | AP16: =SUM(COUNTIF(F16:AJ16,"ct")) -> 0 | AQ16: =AK16+AL16+AM16+AN16+AO16+AP16 -> 29 | AS16: =VLOOKUP(D16,'Mã số nhân viên'!B6:I78,8,0) -> 04053 | AT16: =C16-AS16 -> 0
A17: 5 | B17: 5 | C17: =VLOOKUP(D17,'Mã số nhân viên'!B7:I138,8,0) -> 03459 | D17: N. Vạt | F17: x | G17: x | H17: x | I17: x | J17: cn | K17: x | L17: x | M17: x | N17: x | O17: x | P17: x | Q17: cn | R17: x | S17: tt | T17: x | U17: x | V17: x | W17: x | X17: cn | Y17: x | Z17: x | AA17: x | AB17: x | AC17: x | AD17: x | AE17: tt | AF17: x | AG17: x | AH17: x | AI17: x | AJ17: x | AK17: =SUM(COUNTIF(F17:AJ17,"x")) -> 26 | AL17: =SUM(COUNTIF(F17:AJ17,"cn")) -> 3 | AM17: =SUM(COUNTIF(F17:AJ17,"đ")) -> 0 | AN17: =SUM(COUNTIF(F17:AJ17,"đc")) -> 0 | AO17: =SUM(COUNTIF(F17:AJ17,"gt")) -> 0 | AP17: =SUM(COUNTIF(F17:AJ17,"ct")) -> 0 | AQ17: =AK17+AL17+AM17+AN17+AO17+AP17 -> 29 | AS17: =VLOOKUP(D17,'Mã số nhân viên'!B7:I79,8,0) -> 03459 | AT17: =C17-AS17 -> 0
A18: 6 | B18: 6 | C18: =VLOOKUP(D18,'Mã số nhân viên'!B8:I139,8,0) -> 04054 | D18: N. Kay Son | F18: x | G18: x | H18: x | I18: x | J18: cn | K18: x | L18: x | M18: x | N18: x | O18: x | P18: x | Q18: cn | R18: x | S18: x | T18: x | U18: x | V18: x | W18: x | X18: cn | Y18: x | Z18: x | AA18: x | AB18: x | AC18: x | AD18: x | AE18: cn | AF18: x | AG18: x | AH18: x | AI18: x | AJ18: x | AK18: =SUM(COUNTIF(F18:AJ18,"x")) -> 27 | AL18: =SUM(COUNTIF(F18:AJ18,"cn")) -> 4 | AM18: =SUM(COUNTIF(F18:AJ18,"đ")) -> 0 | AN18: =SUM(COUNTIF(F18:AJ18,"đc")) -> 0 | AO18: =SUM(COUNTIF(F18:AJ18,"gt")) -> 0 | AP18: =SUM(COUNTIF(F18:AJ18,"ct")) -> 0 | AQ18: =AK18+AL18+AM18+AN18+AO18+AP18 -> 31 | AS18: =VLOOKUP(D18,'Mã số nhân viên'!B8:I80,8,0) -> 04054 | AT18: =C18-AS18 -> 0
A19: 7 | B19: 7 | C19: =VLOOKUP(D19,'Mã số nhân viên'!B9:I140,8,0) -> 04055 | D19: T. Đèng 1 | F19: x | G19: x | H19: x | I19: x | J19: cn | K19: x | L19: x | M19: x | N19: x | O19: x | P19: x | Q19: cn | R19: x | S19: x | T19: x | U19: x | V19: x | W19: x | X19: cn | Y19: tt | Z19: x | AA19: x | AB19: x | AC19: x | AD19: x | AE19: cn | AF19: x | AG19: x | AH19: x | AI19: x | AJ19: x | AK19: =SUM(COUNTIF(F19:AJ19,"x")) -> 26 | AL19: =SUM(COUNTIF(F19:AJ19,"cn")) -> 4 | AM19: =SUM(COUNTIF(F19:AJ19,"đ")) -> 0 | AN19: =SUM(COUNTIF(F19:AJ19,"đc")) -> 0 | AO19: =SUM(COUNTIF(F19:AJ19,"gt")) -> 0 | AP19: =SUM(COUNTIF(F19:AJ19,"ct")) -> 0 | AQ19: =AK19+AL19+AM19+AN19+AO19+AP19 -> 30 | AS19: =VLOOKUP(D19,'Mã số nhân viên'!B9:I81,8,0) -> 04055 | AT19: =C19-AS19 -> 0
A20: 8 | B20: 8 | C20: =VLOOKUP(D20,'Mã số nhân viên'!B10:I141,8,0) -> 03462 | D20: T . Bua Ngân | F20: x | G20: x | H20: x | I20: x | J20: cn | K20: x | L20: x | M20: x | N20: x | O20: x | P20: x | Q20: cn | R20: x | S20: x | T20: x | U20: x | V20: x | W20: x | X20: cn | Y20: x | Z20: x | AA20: x | AB20: x | AC20: x | AD20: x | AE20: cn | AF20: x | AG20: x | AH20: x | AI20: x | AJ20: x | AK20: =SUM(COUNTIF(F20:AJ20,"x")) -> 27 | AL20: =SUM(COUNTIF(F20:AJ20,"cn")) -> 4 | AM20: =SUM(COUNTIF(F20:AJ20,"đ")) -> 0 | AN20: =SUM(COUNTIF(F20:AJ20,"đc")) -> 0 | AO20: =SUM(COUNTIF(F20:AJ20,"gt")) -> 0 | AP20: =SUM(COUNTIF(F20:AJ20,"ct")) -> 0 | AQ20: =AK20+AL20+AM20+AN20+AO20+AP20 -> 31 | AS20: =VLOOKUP(D20,'Mã số nhân viên'!B10:I82,8,0) -> 03462 | AT20: =C20-AS20 -> 0
A21: 9 | B21: 9 | C21: =VLOOKUP(D21,'Mã số nhân viên'!B11:I142,8,0) -> 03463 | D21: T Căng | F21: x | G21: x | H21: x | I21: x | J21: cn | K21: x | L21: x | M21: x | N21: x | O21: x | P21: x | Q21: cn | R21: x | S21: x | T21: x | U21: x | V21: x | W21: x | X21: cn | Y21: x | Z21: x | AA21: x | AB21: x | AC21: x | AD21: x | AE21: cn | AF21: x | AG21: x | AH21: x | AI21: x | AJ21: x | AK21: =SUM(COUNTIF(F21:AJ21,"x")) -> 27 | AL21: =SUM(COUNTIF(F21:AJ21,"cn")) -> 4 | AM21: =SUM(COUNTIF(F21:AJ21,"đ")) -> 0 | AN21: =SUM(COUNTIF(F21:AJ21,"đc")) -> 0 | AO21: =SUM(COUNTIF(F21:AJ21,"gt")) -> 0 | AP21: =SUM(COUNTIF(F21:AJ21,"ct")) -> 0 | AQ21: =AK21+AL21+AM21+AN21+AO21+AP21 -> 31 | AS21: =VLOOKUP(D21,'Mã số nhân viên'!B11:I83,8,0) -> 03463 | AT21: =C21-AS21 -> 0
A22: 10 | B22: 10 | C22: =VLOOKUP(D22,'Mã số nhân viên'!B12:I143,8,0) -> 03464 | D22: N. Phôn 1 | F22: x | G22: x | H22: x | I22: x | J22: cn | K22: x | L22: x | M22: x | N22: x | O22: x | P22: x | Q22: cn | R22: x | S22: x | T22: x | U22: x | V22: x | W22: x | X22: cn | Y22: x | Z22: x | AA22: x | AB22: x | AC22: x | AD22: x | AE22: cn | AF22: x | AG22: x | AH22: x | AI22: x | AJ22: x | AK22: =SUM(COUNTIF(F22:AJ22,"x")) -> 27 | AL22: =SUM(COUNTIF(F22:AJ22,"cn")) -> 4 | AM22: =SUM(COUNTIF(F22:AJ22,"đ")) -> 0 | AN22: =SUM(COUNTIF(F22:AJ22,"đc")) -> 0 | AO22: =SUM(COUNTIF(F22:AJ22,"gt")) -> 0 | AP22: =SUM(COUNTIF(F22:AJ22,"ct")) -> 0 | AQ22: =AK22+AL22+AM22+AN22+AO22+AP22 -> 31 | AS22: =VLOOKUP(D22,'Mã số nhân viên'!B12:I84,8,0) -> 03464 | AT22: =C22-AS22 -> 0
A23: 11 | B23: 11 | C23: =VLOOKUP(D23,'Mã số nhân viên'!B13:I144,8,0) -> 03465 | D23: T. In Păn | F23: x | G23: x | H23: x | I23: x | J23: cn | K23: x | L23: x | M23: x | N23: x | O23: x | P23: x | Q23: cn | R23: x | S23: x | T23: x | U23: x | V23: x | W23: x | X23: cn | Y23: x | Z23: x | AA23: x | AB23: x | AC23: x | AD23: x | AE23: cn | AF23: tt | AG23: x | AH23: x | AI23: x | AJ23: x | AK23: =SUM(COUNTIF(F23:AJ23,"x")) -> 26 | AL23: =SUM(COUNTIF(F23:AJ23,"cn")) -> 4 | AM23: =SUM(COUNTIF(F23:AJ23,"đ")) -> 0 | AN23: =SUM(COUNTIF(F23:AJ23,"đc")) -> 0 | AO23: =SUM(COUNTIF(F23:AJ23,"gt")) -> 0 | AP23: =SUM(COUNTIF(F23:AJ23,"ct")) -> 0 | AQ23: =AK23+AL23+AM23+AN23+AO23+AP23 -> 30 | AS23: =VLOOKUP(D23,'Mã số nhân viên'!B13:I85,8,0) -> 03465 | AT23: =C23-AS23 -> 0
A24: 12 | B24: 12 | C24: =VLOOKUP(D24,'Mã số nhân viên'!B14:I145,8,0) -> 03466 | D24: N. Keo | F24: x | G24: x | H24: x | I24: x | J24: cn | K24: x | L24: x | M24: x | N24: x | O24: x | P24: x | Q24: cn | R24: x | S24: x | T24: x | U24: x | V24: x | W24: x | X24: cn | Y24: x | Z24: x | AA24: x | AB24: x | AC24: x | AD24: x | AE24: cn | AF24: x | AG24: x | AH24: x | AI24: x | AJ24: x | AK24: =SUM(COUNTIF(F24:AJ24,"x")) -> 27 | AL24: =SUM(COUNTIF(F24:AJ24,"cn")) -> 4 | AM24: =SUM(COUNTIF(F24:AJ24,"đ")) -> 0 | AN24: =SUM(COUNTIF(F24:AJ24,"đc")) -> 0 | AO24: =SUM(COUNTIF(F24:AJ24,"gt")) -> 0 | AP24: =SUM(COUNTIF(F24:AJ24,"ct")) -> 0 | AQ24: =AK24+AL24+AM24+AN24+AO24+AP24 -> 31 | AS24: =VLOOKUP(D24,'Mã số nhân viên'!B14:I86,8,0) -> 03466 | AT24: =C24-AS24 -> 0
A25: 13 | B25: 13 | C25: =VLOOKUP(D25,'Mã số nhân viên'!B15:I146,8,0) -> 02727 | D25: T. Thong Đon | F25: x | G25: x | H25: x | I25: x | J25: cn | K25: x | L25: x | M25: x | N25: x | O25: x | P25: x | Q25: cn | R25: x | S25: x | T25: x | U25: x | V25: x | W25: x | X25: cn | Y25: x | Z25: x | AA25: x | AB25: x | AC25: x | AD25: x | AE25: cn | AF25: x | AG25: x | AH25: x | AI25: x | AJ25: x | AK25: =SUM(COUNTIF(F25:AJ25,"x")) -> 27 | AL25: =SUM(COUNTIF(F25:AJ25,"cn")) -> 4 | AM25: =SUM(COUNTIF(F25:AJ25,"đ")) -> 0 | AN25: =SUM(COUNTIF(F25:AJ25,"đc")) -> 0 | AO25: =SUM(COUNTIF(F25:AJ25,"gt")) -> 0 | AP25: =SUM(COUNTIF(F25:AJ25,"ct")) -> 0 | AQ25: =AK25+AL25+AM25+AN25+AO25+AP25 -> 31 | AS25: =VLOOKUP(D25,'Mã số nhân viên'!B15:I87,8,0) -> 02727 | AT25: =C25-AS25 -> 0
A26: 14 | B26: 14 | C26: =VLOOKUP(D26,'Mã số nhân viên'!B16:I147,8,0) -> 03467 | D26: T. Hin | F26: x | G26: x | H26: x | I26: x | J26: cn | K26: x | L26: x | M26: x | N26: x | O26: x | P26: x | Q26: cn | R26: x | S26: x | T26: x | U26: x | V26: x | W26: x | X26: cn | Y26: x | Z26: x | AA26: x | AB26: x | AC26: x | AD26: x | AE26: cn | AF26: x | AG26: x | AH26: x | AI26: x | AJ26: x | AK26: =SUM(COUNTIF(F26:AJ26,"x")) -> 27 | AL26: =SUM(COUNTIF(F26:AJ26,"cn")) -> 4 | AM26: =SUM(COUNTIF(F26:AJ26,"đ")) -> 0 | AN26: =SUM(COUNTIF(F26:AJ26,"đc")) -> 0 | AO26: =SUM(COUNTIF(F26:AJ26,"gt")) -> 0 | AP26: =SUM(COUNTIF(F26:AJ26,"ct")) -> 0 | AQ26: =AK26+AL26+AM26+AN26+AO26+AP26 -> 31 | AS26: =VLOOKUP(D26,'Mã số nhân viên'!B16:I88,8,0) -> 03467 | AT26: =C26-AS26 -> 0
A27: 15 | B27: 15 | C27: =VLOOKUP(D27,'Mã số nhân viên'!B17:I148,8,0) -> 04056 | D27: N. Ly Phon | F27: x | G27: x | H27: x | I27: x | J27: cn | K27: x | L27: x | M27: x | N27: x | O27: x | P27: x | Q27: cn | R27: x | S27: x | T27: x | U27: x | V27: x | W27: x | X27: cn | Y27: x | Z27: x | AA27: x | AB27: x | AC27: x | AD27: x | AE27: cn | AF27: x | AG27: x | AH27: x | AI27: x | AJ27: x | AK27: =SUM(COUNTIF(F27:AJ27,"x")) -> 27 | AL27: =SUM(COUNTIF(F27:AJ27,"cn")) -> 4 | AM27: =SUM(COUNTIF(F27:AJ27,"đ")) -> 0 | AN27: =SUM(COUNTIF(F27:AJ27,"đc")) -> 0 | AO27: =SUM(COUNTIF(F27:AJ27,"gt")) -> 0 | AP27: =SUM(COUNTIF(F27:AJ27,"ct")) -> 0 | AQ27: =AK27+AL27+AM27+AN27+AO27+AP27 -> 31 | AS27: =VLOOKUP(D27,'Mã số nhân viên'!B17:I89,8,0) -> 04056 | AT27: =C27-AS27 -> 0
A28: 16 | B28: 16 | C28: =VLOOKUP(D28,'Mã số nhân viên'!B18:I149,8,0) -> 03469 | D28: T. Xôm Va Nít | F28: x | G28: x | H28: x | I28: x | J28: cn | K28: x | L28: x | M28: x | N28: x | O28: x | P28: x | Q28: cn | R28: x | S28: x | T28: x | U28: x | V28: tt | W28: x | X28: cn | Y28: x | Z28: x | AA28: x | AB28: x | AC28: x | AD28: x | AE28: cn | AF28: x | AG28: x | AH28: x | AI28: x | AJ28: x | AK28: =SUM(COUNTIF(F28:AJ28,"x")) -> 26 | AL28: =SUM(COUNTIF(F28:AJ28,"cn")) -> 4 | AM28: =SUM(COUNTIF(F28:AJ28,"đ")) -> 0 | AN28: =SUM(COUNTIF(F28:AJ28,"đc")) -> 0 | AO28: =SUM(COUNTIF(F28:AJ28,"gt")) -> 0 | AP28: =SUM(COUNTIF(F28:AJ28,"ct")) -> 0 | AQ28: =AK28+AL28+AM28+AN28+AO28+AP28 -> 30 | AS28: =VLOOKUP(D28,'Mã số nhân viên'!B18:I90,8,0) -> 03469 | AT28: =C28-AS28 -> 0
... A33: 21 | B33: 21 | C33: =VLOOKUP(D33,'Mã số nhân viên'!B23:I154,8,0) -> 03474 | D33: N. Mon Khăm | F33: x | G33: x | H33: x | I33: x | J33: cn | K33: x | L33: x | M33: x | N33: x | O33: x | P33: x | Q33: cn | R33: x | S33: x | T33: x | U33: x | V33: x | W33: x | X33: cn | Y33: x | Z33: x | AA33: x | AB33: x | AC33: tt | AD33: x | AE33: cn | AF33: tt | AG33: tt | AH33: x | AI33: x | AJ33: x | AK33: =SUM(COUNTIF(F33:AJ33,"x")) -> 24 | AL33: =SUM(COUNTIF(F33:AJ33,"cn")) -> 4 | AM33: =SUM(COUNTIF(F33:AJ33,"đ")) -> 0 | AN33: =SUM(COUNTIF(F33:AJ33,"đc")) -> 0 | AO33: =SUM(COUNTIF(F33:AJ33,"gt")) -> 0 | AP33: =SUM(COUNTIF(F33:AJ33,"ct")) -> 0 | AQ33: =AK33+AL33+AM33+AN33+AO33+AP33 -> 28 | AS33: =VLOOKUP(D33,'Mã số nhân viên'!B23:I95,8,0) -> 03474 | AT33: =C33-AS33 -> 0
A34: 22 | B34: 22 | D34: N.Choi | F34: x | G34: x | H34: x | I34: x | J34: cn | K34: x | L34: x | M34: x | N34: x | O34: x | P34: x | Q34: cn | R34: x | S34: x | T34: x | U34: tt | V34: x | W34: x | X34: cn | Y34: x | Z34: x | AA34: x | AB34: x | AC34: x | AD34: x | AE34: cn | AF34: x | AG34: x | AH34: x | AI34: x | AJ34: x | AK34: =SUM(COUNTIF(F34:AJ34,"x")) -> 26 | AL34: =SUM(COUNTIF(F34:AJ34,"cn")) -> 4 | AM34: =SUM(COUNTIF(F34:AJ34,"đ")) -> 0 | AN34: =SUM(COUNTIF(F34:AJ34,"đc")) -> 0 | AO34: =SUM(COUNTIF(F34:AJ34,"gt")) -> 0 | AP34: =SUM(COUNTIF(F34:AJ34,"ct")) -> 0 | AQ34: =AK34+AL34+AM34+AN34+AO34+AP34 -> 30 | AS34: =VLOOKUP(D34,'Mã số nhân viên'!B24:I96,8,0) -> #N/A | AT34: =C34-AS34 -> #N/A
A35: 23 | B35: 23 | C35: =VLOOKUP(D35,'Mã số nhân viên'!B25:I156,8,0) -> 03476 | D35: T. Bin Ly. | F35: x | G35: x | H35: x | I35: x | J35: cn | K35: x | L35: x | M35: x | N35: x | O35: x | P35: x | Q35: cn | R35: x | S35: x | T35: x | U35: x | V35: x | W35: x | X35: cn | Y35: x | Z35: x | AA35: x | AB35: x | AC35: x | AD35: x | AE35: cn | AF35: x | AG35: x | AH35: x | AI35: x | AJ35: x | AK35: =SUM(COUNTIF(F35:AJ35,"x")) -> 27 | AL35: =SUM(COUNTIF(F35:AJ35,"cn")) -> 4 | AM35: =SUM(COUNTIF(F35:AJ35,"đ")) -> 0 | AN35: =SUM(COUNTIF(F35:AJ35,"đc")) -> 0 | AO35: =SUM(COUNTIF(F35:AJ35,"gt")) -> 0 | AP35: =SUM(COUNTIF(F35:AJ35,"ct")) -> 0 | AQ35: =AK35+AL35+AM35+AN35+AO35+AP35 -> 31 | AS35: =VLOOKUP(D35,'Mã số nhân viên'!B25:I97,8,0) -> 03476 | AT35: =C35-AS35 -> 0
A36: 24 | B36: 24 | D36: N. Tinh | F36: x | G36: x | H36: x | I36: x | J36: cn | K36: x | L36: x | M36: x | N36: x | O36: x | P36: x | Q36: cn | R36: x | S36: x | T36: x | U36: x | V36: x | W36: x | X36: cn | Y36: x | Z36: x | AA36: x | AB36: x | AC36: x | AD36: x | AE36: cn | AF36: x | AG36: x | AH36: x | AI36: x | AJ36: x | AK36: =SUM(COUNTIF(F36:AJ36,"x")) -> 27 | AL36: =SUM(COUNTIF(F36:AJ36,"cn")) -> 4 | AM36: =SUM(COUNTIF(F36:AJ36,"đ")) -> 0 | AN36: =SUM(COUNTIF(F36:AJ36,"đc")) -> 0 | AO36: =SUM(COUNTIF(F36:AJ36,"gt")) -> 0 | AP36: =SUM(COUNTIF(F36:AJ36,"ct")) -> 0 | AQ36: =AK36+AL36+AM36+AN36+AO36+AP36 -> 31 | AS36: =VLOOKUP(D36,'Mã số nhân viên'!B26:I98,8,0) -> #N/A | AT36: =C36-AS36 -> #N/A
A37: 25 | B37: 25 | C37: =VLOOKUP(D37,'Mã số nhân viên'!B27:I158,8,0) -> 03478 | D37: N. Nong | F37: x | G37: x | H37: x | I37: x | J37: cn | K37: x | L37: x | M37: x | N37: x | O37: x | P37: x | Q37: cn | R37: x | S37: x | T37: x | U37: x | V37: x | W37: x | X37: cn | Y37: x | Z37: x | AA37: x | AB37: x | AC37: x | AD37: x | AE37: cn | AF37: x | AG37: x | AH37: x | AI37: x | AJ37: x | AK37: =SUM(COUNTIF(F37:AJ37,"x")) -> 27 | AL37: =SUM(COUNTIF(F37:AJ37,"cn")) -> 4 | AM37: =SUM(COUNTIF(F37:AJ37,"đ")) -> 0 | AN37: =SUM(COUNTIF(F37:AJ37,"đc")) -> 0 | AO37: =SUM(COUNTIF(F37:AJ37,"gt")) -> 0 | AP37: =SUM(COUNTIF(F37:AJ37,"ct")) -> 0 | AQ37: =AK37+AL37+AM37+AN37+AO37+AP37 -> 31 | AS37: =VLOOKUP(D37,'Mã số nhân viên'!B27:I99,8,0) -> 03478 | AT37: =C37-AS37 -> 0
A38: 26 | B38: 26 | C38: =VLOOKUP(D38,'Mã số nhân viên'!B28:I159,8,0) -> 03479 | D38: N. Tun 1 | F38: x | G38: x | H38: x | I38: x | J38: cn | K38: x | L38: x | M38: x | N38: x | O38: x | P38: x | Q38: cn | R38: x | S38: x | T38: tt | U38: x | V38: x | W38: x | X38: cn | Y38: x | Z38: x | AA38: x | AB38: x | AC38: tt | AD38: x | AE38: cn | AF38: x | AG38: x | AH38: x | AI38: x | AJ38: x | AK38: =SUM(COUNTIF(F38:AJ38,"x")) -> 25 | AL38: =SUM(COUNTIF(F38:AJ38,"cn")) -> 4 | AM38: =SUM(COUNTIF(F38:AJ38,"đ")) -> 0 | AN38: =SUM(COUNTIF(F38:AJ38,"đc")) -> 0 | AO38: =SUM(COUNTIF(F38:AJ38,"gt")) -> 0 | AP38: =SUM(COUNTIF(F38:AJ38,"ct")) -> 0 | AQ38: =AK38+AL38+AM38+AN38+AO38+AP38 -> 29 | AS38: =VLOOKUP(D38,'Mã số nhân viên'!B28:I100,8,0) -> 03479 | AT38: =C38-AS38 -> 0
A39: 27 | B39: 27 | C39: =VLOOKUP(D39,'Mã số nhân viên'!B29:I160,8,0) -> 03480 | D39: T . Lốc | F39: x | G39: x | H39: x | I39: x | J39: cn | K39: x | L39: x | M39: x | N39: x | O39: x | P39: x | Q39: cn | R39: x | S39: x | T39: tt | U39: x | V39: x | W39: x | X39: cn | Y39: x | Z39: x | AA39: x | AB39: x | AC39: tt | AD39: x | AE39: cn | AF39: x | AG39: x | AH39: x | AI39: x | AJ39: x | AK39: =SUM(COUNTIF(F39:AJ39,"x")) -> 25 | AL39: =SUM(COUNTIF(F39:AJ39,"cn")) -> 4 | AM39: =SUM(COUNTIF(F39:AJ39,"đ")) -> 0 | AN39: =SUM(COUNTIF(F39:AJ39,"đc")) -> 0 | AO39: =SUM(COUNTIF(F39:AJ39,"gt")) -> 0 | AP39: =SUM(COUNTIF(F39:AJ39,"ct")) -> 0 | AQ39: =AK39+AL39+AM39+AN39+AO39+AP39 -> 29 | AS39: =VLOOKUP(D39,'Mã số nhân viên'!B29:I101,8,0) -> 03480 | AT39: =C39-AS39 -> 0
A40: 28 | B40: 28 | C40: =VLOOKUP(D40,'Mã số nhân viên'!B30:I161,8,0) -> 03481 | D40: N . Khâm (1) | F40: x | G40: x | H40: x | I40: x | J40: cn | K40: x | L40: x | M40: x | N40: x | O40: x | P40: x | Q40: cn | R40: x | S40: x | U40: x | V40: tt | W40: tt | X40: tt | Y40: x | Z40: x | AA40: x | AB40: x | AC40: x | AD40: x | AE40: cn | AF40: x | AG40: x | AH40: x | AI40: x | AJ40: x | AK40: =SUM(COUNTIF(F40:AJ40,"x")) -> 24 | AL40: =SUM(COUNTIF(F40:AJ40,"cn")) -> 3 | AM40: =SUM(COUNTIF(F40:AJ40,"đ")) -> 0 | AN40: =SUM(COUNTIF(F40:AJ40,"đc")) -> 0 | AO40: =SUM(COUNTIF(F40:AJ40,"gt")) -> 0 | AP40: =SUM(COUNTIF(F40:AJ40,"ct")) -> 0 | AQ40: =AK40+AL40+AM40+AN40+AO40+AP40 -> 27 | AS40: =VLOOKUP(D40,'Mã số nhân viên'!B30:I102,8,0) -> 03481 | AT40: =C40-AS40 -> 0
A41: 29 | B41: 29 | C41: =VLOOKUP(D41,'Mã số nhân viên'!B31:I162,8,0) -> 03482 | D41: T . Phết | F41: x | G41: x | H41: x | I41: x | J41: cn | K41: x | L41: x | M41: x | N41: x | O41: x | P41: x | Q41: cn | R41: x | S41: x | U41: x | V41: tt | W41: tt | X41: tt | Y41: x | Z41: x | AA41: x | AB41: x | AC41: x | AD41: x | AE41: cn | AF41: x | AG41: x | AH41: x | AI41: x | AJ41: x | AK41: =SUM(COUNTIF(F41:AJ41,"x")) -> 24 | AL41: =SUM(COUNTIF(F41:AJ41,"cn")) -> 3 | AM41: =SUM(COUNTIF(F41:AJ41,"đ")) -> 0 | AN41: =SUM(COUNTIF(F41:AJ41,"đc")) -> 0 | AO41: =SUM(COUNTIF(F41:AJ41,"gt")) -> 0 | AP41: =SUM(COUNTIF(F41:AJ41,"ct")) -> 0 | AQ41: =AK41+AL41+AM41+AN41+AO41+AP41 -> 27 | AS41: =VLOOKUP(D41,'Mã số nhân viên'!B31:I103,8,0) -> 03482 | AT41: =C41-AS41 -> 0
A42: 30 | B42: 30 | C42: =VLOOKUP(D42,'Mã số nhân viên'!B32:I163,8,0) -> 03483 | D42: T. Viêng Sa Văn | F42: x | G42: x | H42: x | I42: tt | J42: cn | K42: x | L42: x | M42: x | N42: x | O42: x | P42: x | Q42: cn | R42: x | S42: x | T42: x | U42: x | V42: x | W42: x | X42: cn | Y42: x | Z42: x | AA42: x | AB42: x | AC42: tt | AD42: x | AE42: cn | AF42: x | AG42: x | AH42: x | AI42: x | AJ42: x | AK42: =SUM(COUNTIF(F42:AJ42,"x")) -> 25 | AL42: =SUM(COUNTIF(F42:AJ42,"cn")) -> 4 | AM42: =SUM(COUNTIF(F42:AJ42,"đ")) -> 0 | AN42: =SUM(COUNTIF(F42:AJ42,"đc")) -> 0 | AO42: =SUM(COUNTIF(F42:AJ42,"gt")) -> 0 | AP42: =SUM(COUNTIF(F42:AJ42,"ct")) -> 0 | AQ42: =AK42+AL42+AM42+AN42+AO42+AP42 -> 29 | AS42: =VLOOKUP(D42,'Mã số nhân viên'!B32:I104,8,0) -> 03483 | AT42: =C42-AS42 -> 0
A43: 31 | B43: 31 | C43: =VLOOKUP(D43,'Mã số nhân viên'!B33:I164,8,0) -> 03484 | D43: T. Ca Te | F43: x | G43: x | H43: x | I43: x | J43: cn | K43: x | L43: x | M43: x | N43: x | O43: x | P43: x | Q43: cn | R43: x | S43: x | T43: x | U43: x | V43: x | W43: x | X43: cn | Y43: x | Z43: x | AA43: x | AB43: x | AC43: x | AD43: x | AE43: cn | AF43: x | AG43: x | AH43: x | AI43: x | AJ43: x | AK43: =SUM(COUNTIF(F43:AJ43,"x")) -> 27 | AL43: =SUM(COUNTIF(F43:AJ43,"cn")) -> 4 | AM43: =SUM(COUNTIF(F43:AJ43,"đ")) -> 0 | AN43: =SUM(COUNTIF(F43:AJ43,"đc")) -> 0 | AO43: =SUM(COUNTIF(F43:AJ43,"gt")) -> 0 | AP43: =SUM(COUNTIF(F43:AJ43,"ct")) -> 0 | AQ43: =AK43+AL43+AM43+AN43+AO43+AP43 -> 31 | AS43: =VLOOKUP(D43,'Mã số nhân viên'!B33:I105,8,0) -> 03484 | AT43: =C43-AS43 -> 0
A44: 32 | B44: 32 | C44: =VLOOKUP(D44,'Mã số nhân viên'!B34:I165,8,0) -> 03485 | D44: T. Lâm Phon | F44: x | G44: x | H44: x | I44: x | J44: cn | K44: x | L44: x | M44: x | N44: x | O44: x | P44: x | Q44: cn | R44: x | S44: x | T44: x | U44: x | V44: x | W44: x | X44: cn | Y44: x | Z44: x | AA44: x | AB44: x | AC44: x | AD44: x | AE44: cn | AF44: x | AG44: x | AH44: x | AI44: x | AJ44: x | AK44: =SUM(COUNTIF(F44:AJ44,"x")) -> 27 | AL44: =SUM(COUNTIF(F44:AJ44,"cn")) -> 4 | AM44: =SUM(COUNTIF(F44:AJ44,"đ")) -> 0 | AN44: =SUM(COUNTIF(F44:AJ44,"đc")) -> 0 | AO44: =SUM(COUNTIF(F44:AJ44,"gt")) -> 0 | AP44: =SUM(COUNTIF(F44:AJ44,"ct")) -> 0 | AQ44: =AK44+AL44+AM44+AN44+AO44+AP44 -> 31 | AS44: =VLOOKUP(D44,'Mã số nhân viên'!B34:I106,8,0) -> 03485 | AT44: =C44-AS44 -> 0
A45: 33 | B45: 33 | C45: =VLOOKUP(D45,'Mã số nhân viên'!B35:I166,8,0) -> 02712 | D45: T. Sô Đa | F45: x | G45: x | H45: x | I45: x | J45: cn | K45: x | L45: x | M45: x | N45: x | O45: x | P45: x | Q45: cn | R45: x | S45: x | T45: x | U45: x | V45: x | W45: x | X45: cn | Y45: x | Z45: x | AA45: x | AC45: x | AD45: x | AE45: cn | AF45: x | AG45: x | AH45: x | AI45: x | AJ45: x | AK45: =SUM(COUNTIF(F45:AJ45,"x")) -> 26 | AL45: =SUM(COUNTIF(F45:AJ45,"cn")) -> 4 | AM45: =SUM(COUNTIF(F45:AJ45,"đ")) -> 0 | AN45: =SUM(COUNTIF(F45:AJ45,"đc")) -> 0 | AO45: =SUM(COUNTIF(F45:AJ45,"gt")) -> 0 | AP45: =SUM(COUNTIF(F45:AJ45,"ct")) -> 0 | AQ45: =AK45+AL45+AM45+AN45+AO45+AP45 -> 30 | AS45: =VLOOKUP(D45,'Mã số nhân viên'!B35:I107,8,0) -> 02712 | AT45: =C45-AS45 -> 0
A46: 34 | B46: 34 | D46: N. Pheng Mi | F46: x | G46: x | H46: x | I46: x | J46: cn | K46: x | L46: x | M46: x | N46: x | O46: x | P46: x | Q46: cn | R46: x | S46: x | U46: x | V46: x | W46: x | X46: cn | Y46: x | Z46: x | AA46: x | AB46: x | AC46: x | AD46: x | AE46: cn | AF46: x | AG46: x | AH46: x | AI46: x | AJ46: x | AK46: =SUM(COUNTIF(F46:AJ46,"x")) -> 26 | AL46: =SUM(COUNTIF(F46:AJ46,"cn")) -> 4 | AM46: =SUM(COUNTIF(F46:AJ46,"đ")) -> 0 | AN46: =SUM(COUNTIF(F46:AJ46,"đc")) -> 0 | AO46: =SUM(COUNTIF(F46:AJ46,"gt")) -> 0 | AP46: =SUM(COUNTIF(F46:AJ46,"ct")) -> 0 | AQ46: =AK46+AL46+AM46+AN46+AO46+AP46 -> 30 | AS46: =VLOOKUP(D46,'Mã số nhân viên'!B36:I108,8,0) -> #N/A | AT46: =C46-AS46 -> #N/A
...

Sheet TONGHOPCONGDOI
A2: CÔNG TY TNHH CỔ PHẦN QUASA - GERUCO | R2: CỘNG HÒA DÂN CHỦ NHÂN DÂN LÀO
A3: NÔNG TRƯỜNG 2 | N3: =144/0.67 -> 214.92537 | R3: Hòa Bình - Độc Lập - Dân Chủ - Thống Nhất - Thịnh Vượng
A4: Đội: 1.2.3.4 | J4: =F11*25000 -> 0 | K4: =G11*25000 -> 0 | T4: =Q9-19035.02 -> -14883.12
A5: BẢNG TỔNG HỢP CÔNG THỰC HIỆN THÁNG 07 NĂM 2025
A6: STT | B6: Mã số nhân viên | C6: Họ và Tên Lào | D6: Chức vụ
E7: Bôi thuốc kích thích | F7: Bôi thuốc loét sọc | G7: Phun cỏ đại trà | H7: Phát chồi đại trà | I7: Thiết kế miệng cạo ngữa | J7: Bón Phân | K7: Phun Potry | L7: Xả miệng cạo ngữa | M7: Phun cỏ bao lô chống cháy | N7: Gom chén | P7: Thổi lá hàng 3m | Q7: Tổng công | R7: Sản lượng mủ | V7: Các khoản PC | AC7: Tổng cộng | AD7: Xếp loại KT tính lương | AE7: Xác Nhận
R8: Mủ tạp | S8: Mủ Xirum | T8: Quy khô DRC=50 | U8: Tổng sản lượng mủ tạp+mủ dây quy khô | V8: Ngày công đi cạo thường (x) | W8: Ngày CN thường (cn) | X8: Ngày công đi cạo 2 lát (đ) | Y8: Ngày công chủ nhật cạo 2 lát (đc) | Z8: Ngày công cạo gia tăng 2 miêng (gt) | AA8: Ngày chủ nhật cạo gia tăng 2 miệng (ct) | AB8: Phụ cấp nhỏ a xít | AI8: =5308.01-Q9 -> 1156.11
A9: I | B9: VC KINH DOANH NĂM | E9: =E10+E95 -> 1051.2 | F9: =F10+F95 -> 0 | G9: =G10+G95 -> 379.54 | H9: =H10+H95 -> 2127.8 | I9: =I10+I95 -> 0 | J9: =J10+J95 -> 0 | K9: =K10+K95 -> 0 | L9: =L10+L95 -> 0 | ... AC9: =AC10+AC95 -> 4151.9 | AF9: 6716.8 | AG9: =6716.8-Q9 -> 2564.9
A10: A | B10: Đội I | E10: =SUM(E11:E94) -> 587.2 | F10: =SUM(F11:F94) -> 0 | G10: =SUM(G11:G94) -> 379.54 | H10: =SUM(H11:H94) -> 1417.6 | I10: =SUM(I11:I94) -> 0 | J10: =SUM(J11:J94) -> 0 | K10: =SUM(K11:K94) -> 0 | L10: =SUM(L11:L94) -> 0 | ... AC10: =SUM(AC11:AC94) -> 2535.03 | AF10: 1618 | AG10: 194
A11: 1 | B11: ='Chấm công KT'!C13 -> 0 | C11: ='Chấm công KT'!D13 -> T. Lăm | D11: CN-KT | E11: =10/1.25 -> 8 | Q11: =SUM(E11:P11) -> 8 | R11: =VLOOKUP(C11,'SẢN LƯỢNG'!D17:AK97,34,0) -> 4114 | T11: =S11*50/100 -> 0 | U11: =R11 -> 4114 | V11: =VLOOKUP(C11,'Chấm công KT'!D13:AK93,34,0) -> 27 | W11: =VLOOKUP(C11,'Chấm công KT'!D13:AL93,35,0) -> 4 | Y11: =VLOOKUP(C11,'Chấm công KT'!D13:AN93,37,0) -> 0 | Z11: =VLOOKUP(C11,'Chấm công KT'!$D$13:$AO$92,38,0) -> 0 | AA11: =VLOOKUP(C11,'Chấm công KT'!$D$13:$AP$92,39,0) -> 0 | AC11: =Q11 -> 8 | AD11: =VLOOKUP(C11,'SẢN LƯỢNG'!$D$17:$AR$160,37,0) -> 3874
A12: 2 | B12: ='Chấm công KT'!C14 -> 04052 | C12: ='Chấm công KT'!D14 -> T. Feng | D12: CN-KT | E12: =10/1.25 -> 8 | Q12: =SUM(E12:P12) -> 8 | R12: =VLOOKUP(C12,'SẢN LƯỢNG'!D18:AK98,34,0) -> 4202 | T12: =S12*50/100 -> 0 | U12: =R12 -> 4202 | V12: =VLOOKUP(C12,'Chấm công KT'!D14:AK94,34,0) -> 27 | W12: =VLOOKUP(C12,'Chấm công KT'!D14:AL94,35,0) -> 4 | Y12: =VLOOKUP(C12,'Chấm công KT'!D14:AN94,37,0) -> 0 | Z12: =VLOOKUP(C12,'Chấm công KT'!$D$13:$AO$92,38,0) -> 0 | AA12: =VLOOKUP(C12,'Chấm công KT'!$D$13:$AP$92,39,0) -> 0 | AC12: =Q12 -> 8 | AD12: =VLOOKUP(C12,'SẢN LƯỢNG'!$D$17:$AR$160,37,0) -> 3883
A13: 3 | B13: ='Chấm công KT'!C15 -> 02725 | C13: ='Chấm công KT'!D15 -> T. Sa Văn | D13: CN-KT | E13: =10/1.25 -> 8 | Q13: =SUM(E13:P13) -> 8 | R13: =VLOOKUP(C13,'SẢN LƯỢNG'!D19:AK99,34,0) -> 4404 | T13: =S13*50/100 -> 0 | U13: =R13 -> 4404 | V13: =VLOOKUP(C13,'Chấm công KT'!D15:AK95,34,0) -> 26 | W13: =VLOOKUP(C13,'Chấm công KT'!D15:AL95,35,0) -> 4 | Y13: =VLOOKUP(C13,'Chấm công KT'!D15:AN95,37,0) -> 0 | Z13: =VLOOKUP(C13,'Chấm công KT'!$D$13:$AO$92,38,0) -> 0 | AA13: =VLOOKUP(C13,'Chấm công KT'!$D$13:$AP$92,39,0) -> 0 | AC13: =Q13 -> 8 | AD13: =VLOOKUP(C13,'SẢN LƯỢNG'!$D$17:$AR$160,37,0) -> 5035 | AG13: 119657 | AH13: 197
A14: 4 | B14: ='Chấm công KT'!C16 -> 04053 | C14: ='Chấm công KT'!D16 -> Lăm Ma Thu | D14: CN-KT | E14: =10/1.25 -> 8 | Q14: =SUM(E14:P14) -> 8 | R14: =VLOOKUP(C14,'SẢN LƯỢNG'!D20:AK100,34,0) -> 3213 | T14: =S14*50/100 -> 0 | U14: =R14 -> 3213 | V14: =VLOOKUP(C14,'Chấm công KT'!D16:AK96,34,0) -> 25 | W14: =VLOOKUP(C14,'Chấm công KT'!D16:AL96,35,0) -> 4 | Y14: =VLOOKUP(C14,'Chấm công KT'!D16:AN96,37,0) -> 0 | Z14: =VLOOKUP(C14,'Chấm công KT'!$D$13:$AO$92,38,0) -> 0 | AA14: =VLOOKUP(C14,'Chấm công KT'!$D$13:$AP$92,39,0) -> 0 | AC14: =Q14 -> 8 | AD14: =VLOOKUP(C14,'SẢN LƯỢNG'!$D$17:$AR$160,37,0) -> 3912 | AG14: 125408 | AH14: 554
A15: 5 | B15: ='Chấm công KT'!C17 -> 03459 | C15: ='Chấm công KT'!D17 -> N. Vạt | D15: CN-KT | E15: =10/1.25 -> 8 | Q15: =SUM(E15:P15) -> 8 | R15: =VLOOKUP(C15,'SẢN LƯỢNG'!D21:AK101,34,0) -> 3660 | T15: =S15*50/100 -> 0 | U15: =R15 -> 3660 | V15: =VLOOKUP(C15,'Chấm công KT'!D17:AK97,34,0) -> 26 | W15: =VLOOKUP(C15,'Chấm công KT'!D17:AL97,35,0) -> 3 | Y15: =VLOOKUP(C15,'Chấm công KT'!D17:AN97,37,0) -> 0 | Z15: =VLOOKUP(C15,'Chấm công KT'!$D$13:$AO$92,38,0) -> 0 | AA15: =VLOOKUP(C15,'Chấm công KT'!$D$13:$AP$92,39,0) -> 0 | AC15: =Q15 -> 8 | AD15: =VLOOKUP(C15,'SẢN LƯỢNG'!$D$17:$AR$160,37,0) -> 3471 | AG15: 97048 | AH15: 92
A16: 6 | B16: ='Chấm công KT'!C18 -> 04054 | C16: ='Chấm công KT'!D18 -> N. Kay Son | D16: CN-KT | E16: =10/1.25 -> 8 | Q16: =SUM(E16:P16) -> 8 | R16: =VLOOKUP(C16,'SẢN LƯỢNG'!D22:AK102,34,0) -> 4449 | T16: =S16*50/100 -> 0 | U16: =R16 -> 4449 | V16: =VLOOKUP(C16,'Chấm công KT'!D18:AK98,34,0) -> 27 | W16: =VLOOKUP(C16,'Chấm công KT'!D18:AL98,35,0) -> 4 | Y16: =VLOOKUP(C16,'Chấm công KT'!D18:AN98,37,0) -> 0 | Z16: =VLOOKUP(C16,'Chấm công KT'!$D$13:$AO$92,38,0) -> 0 | AA16: =VLOOKUP(C16,'Chấm công KT'!$D$13:$AP$92,39,0) -> 0 | AC16: =Q16 -> 8 | AD16: =VLOOKUP(C16,'SẢN LƯỢNG'!$D$17:$AR$160,37,0) -> 4292 | AG16: 46179
A17: 7 | B17: ='Chấm công KT'!C19 -> 04055 | C17: ='Chấm công KT'!D19 -> T. Đèng 1 | D17: CN-KT | E17: =10/1.25 -> 8 | Q17: =SUM(E17:P17) -> 8 | R17: =VLOOKUP(C17,'SẢN LƯỢNG'!D23:AK103,34,0) -> 3953 | T17: =S17*50/100 -> 0 | U17: =R17 -> 3953 | V17: =VLOOKUP(C17,'Chấm công KT'!D19:AK99,34,0) -> 26 | W17: =VLOOKUP(C17,'Chấm công KT'!D19:AL99,35,0) -> 4 | Y17: =VLOOKUP(C17,'Chấm công KT'!D19:AN99,37,0) -> 0 | Z17: =VLOOKUP(C17,'Chấm công KT'!$D$13:$AO$92,38,0) -> 0 | AA17: =VLOOKUP(C17,'Chấm công KT'!$D$13:$AP$92,39,0) -> 0 | AC17: =Q17 -> 8 | AD17: =VLOOKUP(C17,'SẢN LƯỢNG'!$D$17:$AR$160,37,0) -> 3779
A18: 8 | B18: ='Chấm công KT'!C20 -> 03462 | C18: ='Chấm công KT'!D20 -> T . Bua Ngân | D18: CN-KT | E18: =10/1.25 -> 8 | Q18: =SUM(E18:P18) -> 8 | R18: =VLOOKUP(C18,'SẢN LƯỢNG'!D24:AK104,34,0) -> 3619 | T18: =S18*50/100 -> 0 | U18: =R18 -> 3619 | V18: =VLOOKUP(C18,'Chấm công KT'!D20:AK100,34,0) -> 27 | W18: =VLOOKUP(C18,'Chấm công KT'!D20:AL100,35,0) -> 4 | Y18: =VLOOKUP(C18,'Chấm công KT'!D20:AN100,37,0) -> 0 | Z18: =VLOOKUP(C18,'Chấm công KT'!$D$13:$AO$92,38,0) -> 0 | AA18: =VLOOKUP(C18,'Chấm công KT'!$D$13:$AP$92,39,0) -> 0 | AC18: =Q18 -> 8 | AD18: =VLOOKUP(C18,'SẢN LƯỢNG'!$D$17:$AR$160,37,0) -> 3373 | AI18: =1155.43-Q9 -> -2996.47
A19: 9 | B19: ='Chấm công KT'!C21 -> 03463 | C19: ='Chấm công KT'!D21 -> T Căng | D19: CN-KT | E19: =10/1.25 -> 8 | Q19: =SUM(E19:P19) -> 8 | R19: =VLOOKUP(C19,'SẢN LƯỢNG'!D25:AK105,34,0) -> 4653 | T19: =S19*50/100 -> 0 | U19: =R19 -> 4653 | V19: =VLOOKUP(C19,'Chấm công KT'!D21:AK101,34,0) -> 27 | W19: =VLOOKUP(C19,'Chấm công KT'!D21:AL101,35,0) -> 4 | Y19: =VLOOKUP(C19,'Chấm công KT'!D21:AN101,37,0) -> 0 | Z19: =VLOOKUP(C19,'Chấm công KT'!$D$13:$AO$92,38,0) -> 0 | AA19: =VLOOKUP(C19,'Chấm công KT'!$D$13:$AP$92,39,0) -> 0 | AC19: =Q19 -> 8 | AD19: =VLOOKUP(C19,'SẢN LƯỢNG'!$D$17:$AR$160,37,0) -> 4784
A20: 10 | B20: ='Chấm công KT'!C22 -> 03464 | C20: ='Chấm công KT'!D22 -> N. Phôn 1 | D20: CN-KT | E20: =10/1.25 -> 8 | Q20: =SUM(E20:P20) -> 8 | R20: =VLOOKUP(C20,'SẢN LƯỢNG'!D26:AK106,34,0) -> 4785 | T20: =S20*50/100 -> 0 | U20: =R20 -> 4785 | V20: =VLOOKUP(C20,'Chấm công KT'!D22:AK102,34,0) -> 27 | W20: =VLOOKUP(C20,'Chấm công KT'!D22:AL102,35,0) -> 4 | Y20: =VLOOKUP(C20,'Chấm công KT'!D22:AN102,37,0) -> 0 | Z20: =VLOOKUP(C20,'Chấm công KT'!$D$13:$AO$92,38,0) -> 0 | AA20: =VLOOKUP(C20,'Chấm công KT'!$D$13:$AP$92,39,0) -> 0 | AC20: =Q20 -> 8 | AD20: =VLOOKUP(C20,'SẢN LƯỢNG'!$D$17:$AR$160,37,0) -> 4831 | AG20: =Q9 -> 4151.9
A21: 11 | B21: ='Chấm công KT'!C23 -> 03465 | C21: ='Chấm công KT'!D23 -> T. In Păn | D21: CN-KT | E21: =10/1.25 -> 8 | Q21: =SUM(E21:P21) -> 8 | R21: =VLOOKUP(C21,'SẢN LƯỢNG'!D27:AK107,34,0) -> 4097 | T21: =S21*50/100 -> 0 | U21: =R21 -> 4097 | V21: =VLOOKUP(C21,'Chấm công KT'!D23:AK103,34,0) -> 26 | W21: =VLOOKUP(C21,'Chấm công KT'!D23:AL103,35,0) -> 4 | Y21: =VLOOKUP(C21,'Chấm công KT'!D23:AN103,37,0) -> 0 | Z21: =VLOOKUP(C21,'Chấm công KT'!$D$13:$AO$92,38,0) -> 0 | AA21: =VLOOKUP(C21,'Chấm công KT'!$D$13:$AP$92,39,0) -> 0 | AC21: =Q21 -> 8 | AD21: =VLOOKUP(C21,'SẢN LƯỢNG'!$D$17:$AR$160,37,0) -> 3949 | AG21: =AG20-2544.38 -> 1607.52
A22: 12 | B22: ='Chấm công KT'!C24 -> 03466 | C22: ='Chấm công KT'!D24 -> N. Keo | D22: CN-KT | E22: =10/1.25 -> 8 | Q22: =SUM(E22:P22) -> 8 | R22: =VLOOKUP(C22,'SẢN LƯỢNG'!D28:AK108,34,0) -> 4510 | T22: =S22*50/100 -> 0 | U22: =R22 -> 4510 | V22: =VLOOKUP(C22,'Chấm công KT'!D24:AK104,34,0) -> 27 | W22: =VLOOKUP(C22,'Chấm công KT'!D24:AL104,35,0) -> 4 | Y22: =VLOOKUP(C22,'Chấm công KT'!D24:AN104,37,0) -> 0 | Z22: =VLOOKUP(C22,'Chấm công KT'!$D$13:$AO$92,38,0) -> 0 | AA22: =VLOOKUP(C22,'Chấm công KT'!$D$13:$AP$92,39,0) -> 0 | AC22: =Q22 -> 8 | AD22: =VLOOKUP(C22,'SẢN LƯỢNG'!$D$17:$AR$160,37,0) -> 4330 | AG22: =AG21-6.33 -> 1601.19
A23: 13 | B23: ='Chấm công KT'!C25 -> 02727 | C23: ='Chấm công KT'!D25 -> T. Thong Đon | D23: CN-KT | E23: =10/1.25 -> 8 | Q23: =SUM(E23:P23) -> 8 | R23: =VLOOKUP(C23,'SẢN LƯỢNG'!D29:AK109,34,0) -> 4650 | T23: =S23*50/100 -> 0 | U23: =R23 -> 4650 | V23: =VLOOKUP(C23,'Chấm công KT'!D25:AK105,34,0) -> 27 | W23: =VLOOKUP(C23,'Chấm công KT'!D25:AL105,35,0) -> 4 | Y23: =VLOOKUP(C23,'Chấm công KT'!D25:AN105,37,0) -> 0 | Z23: =VLOOKUP(C23,'Chấm công KT'!$D$13:$AO$92,38,0) -> 0 | AA23: =VLOOKUP(C23,'Chấm công KT'!$D$13:$AP$92,39,0) -> 0 | AC23: =Q23 -> 8 | AD23: =VLOOKUP(C23,'SẢN LƯỢNG'!$D$17:$AR$160,37,0) -> 4257
A24: 14 | B24: ='Chấm công KT'!C26 -> 03467 | C24: ='Chấm công KT'!D26 -> T. Hin | D24: CN-KT | E24: =10/1.25 -> 8 | Q24: =SUM(E24:P24) -> 8 | R24: =VLOOKUP(C24,'SẢN LƯỢNG'!D30:AK110,34,0) -> 3720 | T24: =S24*50/100 -> 0 | U24: =R24 -> 3720 | V24: =VLOOKUP(C24,'Chấm công KT'!D26:AK106,34,0) -> 27 | W24: =VLOOKUP(C24,'Chấm công KT'!D26:AL106,35,0) -> 4 | Y24: =VLOOKUP(C24,'Chấm công KT'!D26:AN106,37,0) -> 0 | Z24: =VLOOKUP(C24,'Chấm công KT'!$D$13:$AO$92,38,0) -> 0 | AA24: =VLOOKUP(C24,'Chấm công KT'!$D$13:$AP$92,39,0) -> 0 | AC24: =Q24 -> 8 | AD24: =VLOOKUP(C24,'SẢN LƯỢNG'!$D$17:$AR$160,37,0) -> 3486
A25: 15 | B25: ='Chấm công KT'!C27 -> 04056 | C25: ='Chấm công KT'!D27 -> N. Ly Phon | D25: CN-KT | E25: =10/1.25 -> 8 | Q25: =SUM(E25:P25) -> 8 | R25: =VLOOKUP(C25,'SẢN LƯỢNG'!D31:AK111,34,0) -> 3893 | T25: =S25*50/100 -> 0 | U25: =R25 -> 3893 | V25: =VLOOKUP(C25,'Chấm công KT'!D27:AK107,34,0) -> 27 | W25: =VLOOKUP(C25,'Chấm công KT'!D27:AL107,35,0) -> 4 | Y25: =VLOOKUP(C25,'Chấm công KT'!D27:AN107,37,0) -> 0 | Z25: =VLOOKUP(C25,'Chấm công KT'!$D$13:$AO$92,38,0) -> 0 | AA25: =VLOOKUP(C25,'Chấm công KT'!$D$13:$AP$92,39,0) -> 0 | AC25: =Q25 -> 8 | AD25: =VLOOKUP(C25,'SẢN LƯỢNG'!$D$17:$AR$160,37,0) -> 3436
A26: 16 | B26: ='Chấm công KT'!C28 -> 03469 | C26: ='Chấm công KT'!D28 -> T. Xôm Va Nít | D26: CN-KT | E26: =10/1.25 -> 8 | Q26: =SUM(E26:P26) -> 8 | R26: =VLOOKUP(C26,'SẢN LƯỢNG'!D32:AK112,34,0) -> 4412 | T26: =S26*50/100 -> 0 | U26: =R26 -> 4412 | V26: =VLOOKUP(C26,'Chấm công KT'!D28:AK108,34,0) -> 26 | W26: =VLOOKUP(C26,'Chấm công KT'!D28:AL108,35,0) -> 4 | Y26: =VLOOKUP(C26,'Chấm công KT'!D28:AN108,37,0) -> 0 | Z26: =VLOOKUP(C26,'Chấm công KT'!$D$13:$AO$92,38,0) -> 0 | AA26: =VLOOKUP(C26,'Chấm công KT'!$D$13:$AP$92,39,0) -> 0 | AC26: =Q26 -> 8 | AD26: =VLOOKUP(C26,'SẢN LƯỢNG'!$D$17:$AR$160,37,0) -> 4353
A27: 17 | B27: ='Chấm công KT'!C29 -> 03470 | C27: ='Chấm công KT'!D29 -> T. Lọi | D27: CN-KT | E27: =10/1.25 -> 8 | Q27: =SUM(E27:P27) -> 8 | R27: =VLOOKUP(C27,'SẢN LƯỢNG'!D33:AK113,34,0) -> 3677 | T27: =S27*50/100 -> 0 | U27: =R27 -> 3677 | V27: =VLOOKUP(C27,'Chấm công KT'!D29:AK109,34,0) -> 26 | W27: =VLOOKUP(C27,'Chấm công KT'!D29:AL109,35,0) -> 3 | Y27: =VLOOKUP(C27,'Chấm công KT'!D29:AN109,37,0) -> 0 | Z27: =VLOOKUP(C27,'Chấm công KT'!$D$13:$AO$92,38,0) -> 0 | AA27: =VLOOKUP(C27,'Chấm công KT'!$D$13:$AP$92,39,0) -> 0 | AC27: =Q27 -> 8 | AD27: =VLOOKUP(C27,'SẢN LƯỢNG'!$D$17:$AR$160,37,0) -> 3463
A28: 18 | B28: ='Chấm công KT'!C30 -> 03471 | C28: ='Chấm công KT'!D30 -> T. Phô Thong | D28: CN-KT | E28: =10/1.25 -> 8 | Q28: =SUM(E28:P28) -> 8 | R28: =VLOOKUP(C28,'SẢN LƯỢNG'!D34:AK114,34,0) -> 5164 | T28: =S28*50/100 -> 0 | U28: =R28 -> 5164 | V28: =VLOOKUP(C28,'Chấm công KT'!D30:AK110,34,0) -> 27 | W28: =VLOOKUP(C28,'Chấm công KT'!D30:AL110,35,0) -> 4 | Y28: =VLOOKUP(C28,'Chấm công KT'!D30:AN110,37,0) -> 0 | Z28: =VLOOKUP(C28,'Chấm công KT'!$D$13:$AO$92,38,0) -> 0 | AA28: =VLOOKUP(C28,'Chấm công KT'!$D$13:$AP$92,39,0) -> 0 | AC28: =Q28 -> 8 | AD28: =VLOOKUP(C28,'SẢN LƯỢNG'!$D$17:$AR$160,37,0) -> 4404 | AF28: =Q9-3223.96 -> 927.94
A29: 19 | B29: ='Chấm công KT'!C31 -> 03472 | C29: ='Chấm công KT'!D31 -> N. Soi | D29: CN-KT | E29: =10/1.25 -> 8 | Q29: =SUM(E29:P29) -> 8 | R29: =VLOOKUP(C29,'SẢN LƯỢNG'!D35:AK115,34,0) -> 3965 | T29: =S29*50/100 -> 0 | U29: =R29 -> 3965 | V29: =VLOOKUP(C29,'Chấm công KT'!D31:AK111,34,0) -> 26 | W29: =VLOOKUP(C29,'Chấm công KT'!D31:AL111,35,0) -> 4 | Y29: =VLOOKUP(C29,'Chấm công KT'!D31:AN111,37,0) -> 0 | Z29: =VLOOKUP(C29,'Chấm công KT'!$D$13:$AO$92,38,0) -> 0 | AA29: =VLOOKUP(C29,'Chấm công KT'!$D$13:$AP$92,39,0) -> 0 | AC29: =Q29 -> 8 | AD29: =VLOOKUP(C29,'SẢN LƯỢNG'!$D$17:$AR$160,37,0) -> 3333
