Workbook
Name a: #REF!
Name aí6: #REF!
Name So_XN: [1]PHATSINH!$B$6:$B$2093

Sheet thưởng 300
A1: CỘNG HÒA DÂN CHỦ NHÂN DÂN LÀO
A2: Hòa Bình - Độc Lập - Dân Chủ - Thống Nhất - Thịnh Vượng
A3: -----oOo-----
A5: CÔNG TY TNHH CỔ PHẦN QUASA - GERUCO LÀO
A6: ĐƠN VỊ: NÔNG TRƯỜNG 1
A8: BẢNG THANH TOÁN PHỤ CẤP TRANG BỊ VẬT TƯ - XÃ MIỆNG CẠO CHO CÔNG NHÂN KHAI THÁC
A10: STT | C10: Mã số nhân viên | E10: Tên công nhân | F10: Chức vụ | G10: Thành tiền(kíp) | H10: Kí Nhận | I10: Ghi chú
A11: ĐỘI 1 | G11: =SUM(G12:G54) -> 21500000
A12: 1 | B12: 1 | E12: Bôn | F12: CNKT | G12: 500000 | I12: =E12 -> Bôn
A13: 2 | B13: 2 | E13: E | F13: CNKT | G13: 500000 | I13: =E13 -> E
A14: 3 | B14: 3 | E14: Khương (3) | F14: CNKT | G14: 500000 | I14: =E14 -> Khương (3)
A15: 4 | B15: 4 | E15: Nít Ni Lanh | F15: CNKT | G15: 500000 | I15: =E15 -> Nít Ni Lanh
A16: 5 | B16: 5 | E16: Khăm Đeng | F16: CNKT | G16: 500000 | I16: =E16 -> Khăm Đeng
A17: 6 | B17: 6 | E17: Nàng Năt | F17: CNKT | G17: 500000 | I17: =E17 -> Nàng Năt
A18: 7 | B18: 7 | E18: Xay (3) | F18: CNKT | G18: 500000 | I18: =E18 -> Xay (3)
A19: 8 | B19: 8 | E19: Xôn | F19: CNKT | G19: 500000 | I19: =E19 -> Xôn
A20: 9 | B20: 9 | E20: Phum Hom | F20: CNKT | G20: 500000 | I20: =E20 -> Phum Hom
A21: 10 | B21: 10 | E21: Pa Lay | F21: CNKT | G21: 500000 | I21: =E21 -> Pa Lay
A22: 11 | B22: 11 | E22: Măm | F22: CNKT | G22: 500000 | I22: =E22 -> Măm
A23: 12 | B23: 12 | E23: Muôi | F23: CNKT | G23: 500000 | I23: =E23 -> Muôi
... A54: 43 | B54: 43 | E54: Me Son | F54: CNKT | G54: 500000 | I54: =E54 -> Me Son
A55: ĐỘI 2 | G55: =SUM(G56:G112) -> 28500000
A56: 44 | B56: 1 | E56: Bôn | F56: CNKT | G56: 500000 | I56: =E56 -> Bôn
A57: 45 | B57: 2 | E57: E | F57: CNKT | G57: 500000 | I57: =E57 -> E
A58: 46 | B58: 3 | E58: Khương (3) | F58: CNKT | G58: 500000 | I58: =E58 -> Khương (3)
A59: 47 | B59: 4 | E59: Nít Ni Lanh | F59: CNKT | G59: 500000 | I59: =E59 -> Nít Ni Lanh
A60: 48 | B60: 5 | E60: Khăm Đeng | F60: CNKT | G60: 500000 | I60: =E60 -> Khăm Đeng
A61: 49 | B61: 6 | E61: Nàng Năt | F61: CNKT | G61: 500000 | I61: =E61 -> Nàng Năt
A62: 50 | B62: 7 | E62: Xay (3) | F62: CNKT | G62: 500000 | I62: =E62 -> Xay (3)
A63: 51 | B63: 8 | E63: Xôn | F63: CNKT | G63: 500000 | I63: =E63 -> Xôn
A64: 52 | B64: 9 | E64: Phum Hom | F64: CNKT | G64: 500000 | I64: =E64 -> Phum Hom
A65: 53 | B65: 10 | E65: Pa Lay | F65: CNKT | G65: 500000 | I65: =E65 -> Pa Lay
A66: 54 | B66: 11 | E66: Măm | F66: CNKT | G66: 500000 | I66: =E66 -> Măm
A67: 55 | B67: 12 | E67: Muôi | F67: CNKT | G67: 500000 | I67: =E67 -> Muôi
... A99: 87 | B99: 44 | E99: Nít | F99: CNKT | G99: 500000 | I99: =E99 -> Nít
A100: 88 | B100: 45 | E100: Nui | F100: CNKT | G100: 500000 | I100: =E100 -> Nui | Q100: =760.5-48.5 -> 712
A101: 89 | B101: 46 | E101: Đuông Chăn | F101: CNKT | G101: 500000 | I101: =E101 -> Đuông Chăn | Q101: =+Q100*30 -> 21360
A102: 90 | B102: 47 | E102: Đăm (3) | F102: CNKT | G102: 500000 | I102: =E102 -> Đăm (3)
A103: 91 | B103: 48 | E103: Hăm Nọi A | F103: CNKT | G103: 500000 | I103: =E103 -> Hăm Nọi A
A104: 92 | B104: 49 | E104: Hip | F104: CNKT | G104: 500000 | I104: =E104 -> Hip
...

Sheet PLC   (2)
A1: ĐỘI 1
A2: =$K$2 -> THÁNG 09/2024 | G2: =$K$2 -> THÁNG 09/2024 | K2: THÁNG 09/2024
A3: Họ và tên | B3: Thô | G3: Họ và tên | H3: Mè Ta Van | L3: 680.47
A4: Công sản phẩm | B4: ²½ìò©ªະພັນ | C4: =VLOOKUP(B3,'LƯƠNG KT'!$D$15:$U$94,3,0) -> #N/A | D4: =+C4*25000 -> #N/A | G4: Công sản phẩm | H4: ²½ìò©ªະພັນ | I4: =VLOOKUP(H3,'LƯƠNG KT'!$D$15:$U$94,3,0) -> #N/A | J4: =+I4*25000 -> #N/A | K4: Công đi cạo | L4: =46.1*L3 -> 31369.667
A5: Công đi cạo | B5: ໝວດໄປຂີດ | C5: =VLOOKUP(B3,'LƯƠNG KT'!$D$15:$U$94,14,0) -> #N/A | D5: =C5*$L$4 -> #N/A | G5: Công đi cạo | H5: ໝວດໄປຂີດ | I5: =VLOOKUP(H3,'LƯƠNG KT'!$D$15:$U$94,14,0) -> #N/A | J5: =I5*$L$4 -> #N/A | K5: Công chủ nhật | L5: =76.9*L3 -> 52328.143
A6: Công làm ngày chủ nhật | B6: ໝວດເຮັດວຽກວັນທິດ | C6: =VLOOKUP(B3,'LƯƠNG KT'!$D$15:$U$94,15,0) -> #N/A | D6: =C6*$L$5 -> #N/A | G6: Công làm ngày chủ nhật | H6: ໝວດເຮັດວຽກວັນທິດ | I6: =VLOOKUP(H3,'LƯƠNG KT'!$D$15:$U$94,15,0) -> #N/A | J6: =I6*$L$5 -> #N/A | K6: PC đánh axit | L6: 10000
A7: Công nhỏ axit đánh đông | C7: =VLOOKUP(B3,'LƯƠNG KT'!$D$15:$U$94,16,0) -> #N/A | D7: =+C7*$L$6 -> #N/A | G7: Công nhỏ axit đánh đông | I7: =VLOOKUP(H3,'LƯƠNG KT'!$D$15:$U$94,16,0) -> #N/A | J7: =+I7*$L$6 -> #N/A | K7: PC cây non | L7: =30.7*L3 -> 20890.429
A8: Phụ cấp cạo 2 lát | C8: =VLOOKUP(B4,'LƯƠNG KT'!$D$15:$U$94,16,0) -> #N/A | D8: =+C8*$L$6 -> #N/A | G8: Công nhỏ axit đánh đông | I8: =VLOOKUP(H4,'LƯƠNG KT'!$D$15:$U$94,16,0) -> #N/A | J8: =+I8*$L$6 -> #N/A | K8: PC cây non | L8: =30.7*L4 -> 963048.78
A9: Phụ cấp tiền lương | C9: =VLOOKUP(B5,'LƯƠNG KT'!$D$15:$U$94,16,0) -> #N/A | D9: =+C9*$L$6 -> #N/A | G9: Công nhỏ axit đánh đông | I9: =VLOOKUP(H5,'LƯƠNG KT'!$D$15:$U$94,16,0) -> #N/A | J9: =+I9*$L$6 -> #N/A | K9: PC cây non | L9: =30.7*L5 -> 1606474
A10: Mủ dây | B10: ຢ່າງເສັ້ນ | C10: =VLOOKUP(B3,'LƯƠNG KT'!$D$15:$U$94,9,0)*$L$10 -> #N/A | D10: =+C10*0.5*3000 -> #N/A | G10: Mủ dây | H10: ຢ່າງເສັ້ນ | I10: =VLOOKUP(H3,'LƯƠNG KT'!$D$15:$U$94,9,0)*$L$10 -> #N/A | J10: =+I10*0.5*3000 -> #N/A | K10: DRC mủ dây | L10: 0.5
A11: Sản lượng mủ | B11: ໝວດຂີດທັບເກັບຢາງ | C11: =VLOOKUP(B3,'LƯƠNG KT'!$D$15:$U$94,8,0)*$L$11 -> #N/A | D11: =VLOOKUP(B3,'LƯƠNG KT'!$D$15:$U$94,13,0)-D10 -> #N/A | G11: Sản lượng mủ | H11: ໝວດຂີດທັບເກັບຢາງ | I11: =VLOOKUP(H3,'LƯƠNG KT'!$D$15:$U$94,8,0)*$L$11 -> #N/A | J11: =VLOOKUP(H3,'LƯƠNG KT'!$D$15:$U$94,13,0)-J10 -> #N/A | K11: DRC mủ tạp | L11: 0.42315994
A12: Các khoản trừ | B12: ການຫັກລົບ | G12: Các khoản trừ | H12: ການຫັກລົບ
A13: Tạm ứng | B13: ຄວາມກ້າວໜ້າ | D13: =56*25000 -> 1400000 | G13: Tạm ứng | H13: ຄວາມກ້າວໜ້າ | J13: =56*25000 -> 1400000
A14: Tổng trừ: | B14: ລວມທັງໝົດ | D14: =D13 -> 1400000 | G14: Tổng trừ: | H14: ລວມທັງໝົດ | J14: =J13 -> 1400000
A15: Còn lãnh | B15: ຍັງເຫລືອ | D15: =SUM(D4:D11)-D14 -> #N/A | G15: Còn lãnh | H15: ຍັງເຫລືອ | J15: =SUM(J4:J11)-J14 -> #N/A
L16: Phụ cấp cạo 2 lát | M16: Phụ cấp tiền lương
A18: =$K$2 -> THÁNG 09/2024 | G18: =$K$2 -> THÁNG 09/2024
A19: Họ và tên | B19: Ka Tho | G19: Họ và tên | H19: Xay
A20: Công sản phẩm | B20: ²½ìò©ªະພັນ | C20: =VLOOKUP(B19,'LƯƠNG KT'!$D$15:$U$94,3,0) -> #N/A | D20: =+C20*25000 -> #N/A | G20: Công sản phẩm | H20: ²½ìò©ªະພັນ | I20: =VLOOKUP(H19,'LƯƠNG KT'!$D$15:$U$94,3,0) -> #N/A | J20: =+I20*25000 -> #N/A
A21: Công đi cạo | B21: ໝວດໄປຂີດ | C21: =VLOOKUP(B19,'LƯƠNG KT'!$D$15:$U$94,14,0) -> #N/A | D21: =C21*$L$4 -> #N/A | G21: Công đi cạo | H21: ໝວດໄປຂີດ | I21: =VLOOKUP(H19,'LƯƠNG KT'!$D$15:$U$94,14,0) -> #N/A | J21: =I21*$L$4 -> #N/A
A22: Công làm ngày chủ nhật | B22: ໝວດເຮັດວຽກວັນທິດ | C22: =VLOOKUP(B19,'LƯƠNG KT'!$D$15:$U$94,15,0) -> #N/A | D22: =C22*$L$5 -> #N/A | G22: Công làm ngày chủ nhật | H22: ໝວດເຮັດວຽກວັນທິດ | I22: =VLOOKUP(H19,'LƯƠNG KT'!$D$15:$U$94,15,0) -> #N/A | J22: =I22*$L$5 -> #N/A
A23: Công nhỏ axit đánh đông | C23: =VLOOKUP(B19,'LƯƠNG KT'!$D$15:$U$94,16,0) -> #N/A | D23: =+C23*$L$6 -> #N/A | G23: Công nhỏ axit đánh đông | I23: =VLOOKUP(H19,'LƯƠNG KT'!$D$15:$U$94,16,0) -> #N/A | J23: =+I23*$L$6 -> #N/A | M23: =425*50 -> 21250
A24: Công nhỏ axit đánh đông | C24: =VLOOKUP(B20,'LƯƠNG KT'!$D$15:$U$94,16,0) -> #N/A | D24: =+C24*$L$6 -> #N/A | G24: Công nhỏ axit đánh đông | I24: =VLOOKUP(H20,'LƯƠNG KT'!$D$15:$U$94,16,0) -> #N/A | J24: =+I24*$L$6 -> #N/A | M24: =425*50 -> 21250
A25: Công nhỏ axit đánh đông | C25: =VLOOKUP(B21,'LƯƠNG KT'!$D$15:$U$94,16,0) -> #N/A | D25: =+C25*$L$6 -> #N/A | G25: Công nhỏ axit đánh đông | I25: =VLOOKUP(H21,'LƯƠNG KT'!$D$15:$U$94,16,0) -> #N/A | J25: =+I25*$L$6 -> #N/A | M25: =425*50 -> 21250
A26: Mủ dây | B26: ຢ່າງເສັ້ນ | C26: =VLOOKUP(B19,'LƯƠNG KT'!$D$15:$U$94,9,0)*$L$10 -> #N/A | D26: =+C26*0.5*3000 -> #N/A | G26: Mủ dây | H26: ຢ່າງເສັ້ນ | I26: =VLOOKUP(H19,'LƯƠNG KT'!$D$15:$U$94,9,0)*$L$10 -> #N/A | J26: =+I26*0.5*3000 -> #N/A
A27: Sản lượng mủ | B27: ໝວດຂີດທັບເກັບຢາງ | C27: =VLOOKUP(B19,'LƯƠNG KT'!$D$15:$U$94,8,0)*$L$11 -> #N/A | D27: =VLOOKUP(B19,'LƯƠNG KT'!$D$15:$U$94,13,0)-D26 -> #N/A | G27: Sản lượng mủ | H27: ໝວດຂີດທັບເກັບຢາງ | I27: =VLOOKUP(H19,'LƯƠNG KT'!$D$15:$U$94,8,0)*$L$11 -> #N/A | J27: =VLOOKUP(H19,'LƯƠNG KT'!$D$15:$U$94,13,0)-J26+I21*20000+I22*20000 -> #N/A
A28: Các khoản trừ | B28: ການຫັກລົບ | G28: Các khoản trừ | H28: ການຫັກລົບ
A29: Tạm ứng | B29: ຄວາມກ້າວໜ້າ | D29: =56*25000 -> 1400000 | G29: Tạm ứng | H29: ຄວາມກ້າວໜ້າ | J29: =56*25000 -> 1400000 | M29: =425+9 -> 434 | N29: =+M29*20 -> 8680
A30: Tổng trừ: | B30: ລວມທັງໝົດ | D30: =D29 -> 1400000 | G30: Tổng trừ: | H30: ລວມທັງໝົດ | J30: =J29 -> 1400000 | M30: =+M29*50 -> 21700
A31: Còn lãnh | B31: ຍັງເຫລືອ | D31: =SUM(D20:D27)-D30 -> #N/A | G31: Còn lãnh | H31: ຍັງເຫລືອ | J31: =SUM(J20:J27)-J30 -> #N/A
A34: =$K$2 -> THÁNG 09/2024 | G34: =$K$2 -> THÁNG 09/2024
A35: Họ và tên | B35: Thảo In | G35: Họ và tên | H35: Cha La
A36: Công sản phẩm | B36: ²½ìò©ªະພັນ | C36: =VLOOKUP(B35,'LƯƠNG KT'!$D$15:$U$94,3,0) -> #N/A | D36: =+C36*25000 -> #N/A | G36: Công sản phẩm | H36: ²½ìò©ªະພັນ | I36: =VLOOKUP(H35,'LƯƠNG KT'!$D$15:$U$94,3,0) -> #N/A | J36: =+I36*25000 -> #N/A
A37: Công đi cạo | B37: ໝວດໄປຂີດ | C37: =VLOOKUP(B35,'LƯƠNG KT'!$D$15:$U$94,14,0) -> #N/A | D37: =C37*$L$4 -> #N/A | G37: Công đi cạo | H37: ໝວດໄປຂີດ | I37: =VLOOKUP(H35,'LƯƠNG KT'!$D$15:$U$94,14,0) -> #N/A | J37: =I37*$L$4 -> #N/A
A38: Công làm ngày chủ nhật | B38: ໝວດເຮັດວຽກວັນທິດ | C38: =VLOOKUP(B35,'LƯƠNG KT'!$D$15:$U$94,15,0) -> #N/A | D38: =C38*$L$5 -> #N/A | G38: Công làm ngày chủ nhật | H38: ໝວດເຮັດວຽກວັນທິດ | I38: =VLOOKUP(H35,'LƯƠNG KT'!$D$15:$U$94,15,0) -> #N/A | J38: =I38*$L$5 -> #N/A
A39: Công nhỏ axit đánh đông | C39: =VLOOKUP(B35,'LƯƠNG KT'!$D$15:$U$94,16,0) -> #N/A | D39: =+C39*$L$6 -> #N/A | G39: Công nhỏ axit đánh đông | I39: =VLOOKUP(H35,'LƯƠNG KT'!$D$15:$U$94,16,0) -> #N/A | J39: =+I39*$L$6 -> #N/A
A42: Mủ dây | B42: ຢ່າງເສັ້ນ | C42: =VLOOKUP(B35,'LƯƠNG KT'!$D$15:$U$94,9,0)*$L$10 -> #N/A | D42: =+C42*0.5*3000 -> #N/A | G42: Mủ dây | H42: ຢ່າງເສັ້ນ | I42: =VLOOKUP(H35,'LƯƠNG KT'!$D$15:$U$94,9,0)*$L$10 -> #N/A | J42: =+I42*0.5*3000 -> #N/A
A43: Sản lượng mủ | B43: ໝວດຂີດທັບເກັບຢາງ | C43: =VLOOKUP(B35,'LƯƠNG KT'!$D$15:$U$94,8,0)*$L$11 -> #N/A | D43: =VLOOKUP(B35,'LƯƠNG KT'!$D$15:$U$94,13,0)-D42+C37*20000+C38*20000 -> #N/A | G43: Sản lượng mủ | H43: ໝວດຂີດທັບເກັບຢາງ | I43: =VLOOKUP(H35,'LƯƠNG KT'!$D$15:$U$94,8,0)*$L$11 -> #N/A | J43: =VLOOKUP(H35,'LƯƠNG KT'!$D$15:$U$94,13,0)-J42 -> #N/A
A44: Các khoản trừ | B44: ການຫັກລົບ | G44: Các khoản trừ | H44: ການຫັກລົບ
A45: Tạm ứng | B45: ຄວາມກ້າວໜ້າ | D45: =56*25000 -> 1400000 | G45: Tạm ứng | H45: ຄວາມກ້າວໜ້າ | J45: =56*25000 -> 1400000
...

Sheet PCNC BUN 
A1: CỘNG HÒA DÂN CHỦ NHÂN DÂN LÀO
A2: Hòa Bình - Độc Lập - Dân Chủ - Thống Nhất - Thịnh Vượng
A3: -----oOo-----
A5: CÔNG TY TNHH CỔ PHẦN QUASA - GERUCO LÀO
A6: ĐƠN VỊ: NÔNG TRƯỜNG 1
A8: BẢNG THANH TOÁN PHỤ CẤP NGÀY CÔNG CHO CÔNG NHÂN TRỰC TIẾP THÁNG 11 NĂM 2024
A10: STT | C10: Mã số nhân viên | E10: Tên công nhân | F10: Chức vụ | G10: Ngày công | K10: Tổng công | L10: Thành tiền(kíp) | M10: Ký nhận
G11: 2/11 | H11: 3/11 | I11: 4/11 | J11: 5/11
A12: ĐỘI 1 | G12: =COUNTIF(G13:G55,"X") -> 43 | H12: =COUNTIF(H13:H55,"X") -> 43 | I12: =COUNTIF(I13:I55,"X") -> 42 | J12: =COUNTIF(J13:J55,"X") -> 40 | K12: =SUM(K13:K55) -> 168 | L12: =SUM(L13:L55) -> 16800000
A13: 1 | B13: 1 | E13: Thô | F13: CNKT | G13: X | H13: X | I13: X | J13: X | K13: =COUNTIF(G13:J13,"X") -> 4 | L13: =K13*100000 -> 400000
A14: 2 | B14: 2 | E14: Mè Ta Van | F14: CNKT | G14: X | H14: X | I14: X | K14: =COUNTIF(G14:J14,"X") -> 3 | L14: =K14*100000 -> 300000
A15: 3 | B15: 3 | E15: Ka Tho | F15: CNKT | G15: X | H15: X | I15: X | J15: X | K15: =COUNTIF(G15:J15,"X") -> 4 | L15: =K15*100000 -> 400000
A16: 4 | B16: 4 | E16: Xay | F16: CNKT | G16: X | H16: X | I16: X | K16: =COUNTIF(G16:J16,"X") -> 3 | L16: =K16*100000 -> 300000
A17: 5 | B17: 5 | E17: Thảo In | F17: CNKT | G17: X | H17: X | K17: =COUNTIF(G17:J17,"X") -> 2 | L17: =K17*100000 -> 200000
A18: 6 | B18: 6 | E18: Cha La | F18: CNKT | G18: X | H18: X | I18: X | J18: X | K18: =COUNTIF(G18:J18,"X") -> 4 | L18: =K18*100000 -> 400000
A19: 7 | B19: 7 | E19: Nang Nga | F19: CNKT | G19: X | H19: X | I19: X | J19: X | K19: =COUNTIF(G19:J19,"X") -> 4 | L19: =K19*100000 -> 400000
A20: 8 | B20: 8 | E20: Khăm Đi | F20: CNKT | G20: X | H20: X | I20: X | J20: X | K20: =COUNTIF(G20:J20,"X") -> 4 | L20: =K20*100000 -> 400000
A21: 9 | B21: 9 | E21: Me Đuông | F21: CNKT | G21: X | H21: X | I21: X | J21: X | K21: =COUNTIF(G21:J21,"X") -> 4 | L21: =K21*100000 -> 400000
A22: 10 | B22: 10 | E22: Nang Môn | F22: CNKT | G22: X | H22: X | I22: X | J22: X | K22: =COUNTIF(G22:J22,"X") -> 4 | L22: =K22*100000 -> 400000
A23: 11 | B23: 11 | E23: Ziên | F23: CNKT | G23: X | H23: X | I23: X | J23: X | K23: =COUNTIF(G23:J23,"X") -> 4 | L23: =K23*100000 -> 400000
A24: 12 | B24: 12 | E24: Me Pê | F24: CNKT | G24: X | H24: X | I24: X | J24: X | K24: =COUNTIF(G24:J24,"X") -> 4 | L24: =K24*100000 -> 400000
A25: 13 | B25: 13 | E25: Thảo chòi | F25: CNKT | G25: X | H25: X | I25: X | J25: X | K25: =COUNTIF(G25:J25,"X") -> 4 | L25: =K25*100000 -> 400000
A26: 14 | B26: 14 | E26: Tìng A | F26: CNKT | G26: X | H26: X | I26: X | J26: X | K26: =COUNTIF(G26:J26,"X") -> 4 | L26: =K26*100000 -> 400000
A27: 15 | B27: 15 | E27: Phò Set Tha | F27: CNKT | G27: X | H27: X | I27: X | J27: X | K27: =COUNTIF(G27:J27,"X") -> 4 | L27: =K27*100000 -> 400000
A28: 16 | B28: 16 | E28: Sắt | F28: CNKT | G28: X | H28: X | I28: X | J28: X | K28: =COUNTIF(G28:J28,"X") -> 4 | L28: =K28*100000 -> 400000
A29: 17 | B29: 17 | E29: Khăm | F29: CNKT | G29: X | H29: X | I29: X | J29: X | K29: =COUNTIF(G29:J29,"X") -> 4 | L29: =K29*100000 -> 400000
... A55: 43 | B55: 43 | E55: Nang Hỏm | F55: CNKT | G55: X | H55: X | I55: X | J55: X | K55: =COUNTIF(G55:J55,"X") -> 4 | L55: =K55*100000 -> 400000
A56: ĐỘI 2 | G56: =COUNTIF(G57:G111,"X") -> 50 | H56: =COUNTIF(H57:H111,"X") -> 53 | I56: =COUNTIF(I57:I111,"X") -> 52 | J56: =COUNTIF(J57:J111,"X") -> 49 | K56: =SUM(K57:K111) -> 204 | L56: =SUM(L57:L111) -> 20400000
A57: 44 | B57: 1 | E57: Lếc | F57: CNKT | I57: X | K57: =COUNTIF(G57:J57,"X") -> 1 | L57: =K57*100000 -> 100000
A58: 45 | B58: 2 | E58: Hăm Lẹ | F58: CNKT | G58: X | H58: X | I58: X | J58: X | K58: =COUNTIF(G58:J58,"X") -> 4 | L58: =K58*100000 -> 400000
A59: 46 | B59: 3 | E59: Vông | F59: CNKT | G59: X | H59: X | I59: X | J59: X | K59: =COUNTIF(G59:J59,"X") -> 4 | L59: =K59*100000 -> 400000
A60: 47 | B60: 4 | E60: Ma Ni Son | F60: CNKT | G60: X | H60: X | I60: X | J60: X | K60: =COUNTIF(G60:J60,"X") -> 4 | L60: =K60*100000 -> 400000
A61: 48 | B61: 5 | E61: Cong Ma | F61: CNKT | G61: X | H61: X | I61: X | J61: X | K61: =COUNTIF(G61:J61,"X") -> 4 | L61: =K61*100000 -> 400000 | P61: =5+2+3+6 -> 16
A62: 49 | B62: 6 | E62: Kệt | F62: CNKT | H62: X | I62: X | J62: X | K62: =COUNTIF(G62:J62,"X") -> 3 | L62: =K62*100000 -> 300000 | P62: =55*4 -> 220
A63: 50 | B63: 7 | E63: Măn | F63: CNKT | G63: X | H63: X | I63: X | J63: X | K63: =COUNTIF(G63:J63,"X") -> 4 | L63: =K63*100000 -> 400000 | P63: =+P62-P61 -> 204
A64: 51 | B64: 8 | E64: Soi | F64: CNKT | G64: X | H64: X | J64: X | K64: =COUNTIF(G64:J64,"X") -> 3 | L64: =K64*100000 -> 300000
A65: 52 | B65: 9 | E65: Phò Mom | F65: CNKT | G65: X | H65: X | I65: X | J65: X | K65: =COUNTIF(G65:J65,"X") -> 4 | L65: =K65*100000 -> 400000
A66: 53 | B66: 10 | E66: Pệt | F66: CNKT | G66: X | H66: X | I66: X | K66: =COUNTIF(G66:J66,"X") -> 3 | L66: =K66*100000 -> 300000
A67: 54 | B67: 11 | E67: Khay Khăm | F67: CNKT | G67: X | H67: X | I67: X | J67: X | K67: =COUNTIF(G67:J67,"X") -> 4 | L67: =K67*100000 -> 400000
A68: 55 | B68: 12 | E68: Ô Lích | F68: CNKT | G68: X | H68: X | I68: X | J68: X | K68: =COUNTIF(G68:J68,"X") -> 4 | L68: =K68*100000 -> 400000
...

Sheet LƯƠNG GIA THUỘC THÁNG 11
A1: CỘNG HOÀ DÂN CHỦ NHÂN DÂN LÀO
A2: Hoà bình - Độc lập - Dân chủ - Thống nhất - Thịnh vượng
A3: ----oOo----
A4: CÔNG TY TNHH CỔ PHẦN QUASA - GERUCO LÀO
A5: NÔNG TRƯỜNG CAO SU SỐ 1
A6: BẢNG LƯƠNG CB QUẢN LÝ & CN TRỰC TIẾP NGƯỜI LÀO THÁNG 11 NĂM 2024
D8: Tỷ giá Bath qua Kip | F8: 660
A10: Stt | B10: Mã nhân viên | C10: Lào | D10: Việt Nam | E10: Chức vụ | F10: Ký tên | G10: Lương | J10: Tổng tiền lương | K10: Thưởng hoàn thanh nước rút | L10: Thuế TNCN | M10: Tiền lương còn lại | N10: Ghi chú
G11: Lương chăm sóc | H11: Lương sản lượng | I11: Lương phụ cấp
A12: ì© | C12: §ˆ²¾¦¾ì¾¸ | D12: §ˆ²¾¦¾¹¸¼© | E12: ª¿ÁÎÈ¤ | G12: ¸ñ­¤¾­ | H12: À¤ò­À©õº­ª¾ ´°½ìò©ª½²ñ­ | I12: º÷©Îø­¡ó©µ¾¤* | J12: ລວມເປັນເເງິນ | K12: ì¸´À¤ò­»ñ® | L12: º¾¡º­ì¾¨ Ä©É | M12: À¤ò­»ñ ®ªö¸¥ò¤
A13: 1 | C13: ອ່ວນ | D13: Sủng | E13: CNKT | G13: 40000 | H13: 614840.62 | I13: 118679 | J13: =SUM(G13:I13) -> 773519.62 | M13: =J13-L13 -> 773519.62 | O13: =1300000-M13 -> 526480.38
A14: 2 | C14: ຕອງ | D14: Thảo Mút | E14: CNKT | G14: 40000 | H14: 554373.1 | I14: 107985.27 | J14: =SUM(G14:I14) -> 702358.37 | M14: =J14-L14 -> 702358.37 | O14: =MIN(M14:M193,M195:M524,M526:M1097,M1099:M1141,M1143:M1183,M1185:M1694,M1696:M2162,M2164:M2552) -> 544338.9
A15: 3 | B15: =VLOOKUP(D15,'[2]DS CN MOI UP'!$B$11:$C$447,2,0) -> 02429 | C15: ຄຳບຸນ | D15: Nang Thôn | E15: CNKT | G15: 40000 | H15: 554373.1 | I15: 106506.79 | J15: =SUM(G15:I15) -> 700879.89 | M15: =J15-L15 -> 700879.89
A16: 4 | B16: =VLOOKUP(D16,'[2]DS CN MOI UP'!$B$11:$C$447,2,0) -> #N/A | C16: ນ ວັນ | D16: Khai Thong | E16: CNKT | G16: 40000 | H16: 554373.1 | I16: 75304.754 | J16: =SUM(G16:I16) -> 669677.85 | M16: =J16-L16 -> 669677.85
A17: 5 | B17: =VLOOKUP(D17,'[2]DS CN MOI UP'!$B$11:$C$447,2,0) -> 02431 | C17: ນ ວັນ | D17: Xăm Phon | E17: CNKT | G17: 40000 | H17: 635040.19 | I17: 150609.51 | J17: =SUM(G17:I17) -> 825649.7 | M17: =J17-L17 -> 825649.7
A18: 6 | B18: =VLOOKUP(D18,'[2]DS CN MOI UP'!$B$11:$C$447,2,0) -> #N/A | C18: ນ ວັນ | D18: Nang Tìng | E18: CNKT | G18: 40000 | H18: 544338.9 | I18: 146532.6 | J18: =SUM(G18:I18) -> 730871.5 | M18: =J18-L18 -> 730871.5
A19: 7 | B19: =VLOOKUP(D19,'[2]DS CN MOI UP'!$B$11:$C$447,2,0) -> 02433 | C19: ນ ວັນ | D19: Me Đuông | E19: CNKT | G19: 40000 | H19: 574572.66 | I19: 107519.12 | J19: =SUM(G19:I19) -> 722091.79 | M19: =J19-L19 -> 722091.79
A20: 8 | B20: =VLOOKUP(D20,'[2]DS CN MOI UP'!$B$11:$C$447,2,0) -> #N/A | C20: ນ ວັນ | D20: Xơi | E20: CNKT | G20: 40000 | H20: 604806.43 | I20: 109019.12 | J20: =SUM(G20:I20) -> 753825.55 | M20: =J20-L20 -> 753825.55
A21: 9 | B21: =VLOOKUP(D21,'[2]DS CN MOI UP'!$B$11:$C$447,2,0) -> 03436 | C21: ນ ວັນ | D21: Sắt | E21: CNKT | G21: 40000 | H21: 584606.86 | I21: 229728.84 | J21: =SUM(G21:I21) -> 854335.7 | M21: =J21-L21 -> 854335.7
A22: 10 | B22: =VLOOKUP(D22,'[2]DS CN MOI UP'!$B$11:$C$447,2,0) -> 02638 | C22: ນ ວັນ | D22: Đăm | E22: CNKT | G22: 40000 | H22: 635040.19 | I22: 193212.23 | J22: =SUM(G22:I22) -> 868252.41 | M22: =J22-L22 -> 868252.41
A23: 11 | B23: =VLOOKUP(D23,'[2]DS CN MOI UP'!$B$11:$C$447,2,0) -> 02437 | C23: ນ ວັນ | D23: Bun Nác | E23: CNKT | G23: 40000 | H23: 524139.34 | I23: 524139.34 | J23: =SUM(G23:I23) -> 1088278.7 | M23: =J23-L23 -> 1088278.7
A24: 12 | B24: =VLOOKUP(D24,'[2]DS CN MOI UP'!$B$11:$C$447,2,0) -> 02438 | C24: ນ ວັນ | D24: Nàng Chăn A | E24: CNKT | G24: 40000 | H24: 635040.19 | I24: 524139.34 | J24: =SUM(G24:I24) -> 1199179.5 | M24: =J24-L24 -> 1199179.5
A25: 13 | B25: =VLOOKUP(D25,'[2]DS CN MOI UP'!$B$11:$C$447,2,0) -> 02440 | C25: ນ ວັນ | D25: Thô | E25: CNKT | G25: 40000 | H25: 635040.19 | I25: 524139.34 | J25: =SUM(G25:I25) -> 1199179.5 | M25: =J25-L25 -> 1199179.5
A26: 14 | B26: =VLOOKUP(D26,'[2]DS CN MOI UP'!$B$11:$C$447,2,0) -> 02442 | C26: ນ ວັນ | D26: Nang Thong | E26: CNKT | G26: 40000 | H26: 554373.1 | I26: 524139.34 | J26: =SUM(G26:I26) -> 1118512.4 | M26: =J26-L26 -> 1118512.4
... A33: 21 | B33: =VLOOKUP(D33,'[2]DS CN MOI UP'!$B$11:$C$447,2,0) -> #N/A | C33: ແຕງ | D33: Thảo Nọi | E33: CNKT | G33: 40000 | H33: 554373.1 | I33: 554373.1 | J33: =SUM(G33:I33) -> 1148746.2 | M33: =J33-L33 -> 1148746.2
A34: 22 | B34: =VLOOKUP(D34,'[2]DS CN MOI UP'!$B$11:$C$447,2,0) -> #N/A | C34: ແຕງ | D34: Phò Thiêm | E34: CNKT | H34: 635040.19 | I34: 635040.19 | J34: =SUM(G34:I34) -> 1270080.4 | M34: =J34-L34 -> 1270080.4
A35: 23 | B35: =VLOOKUP(D35,'[2]DS CN MOI UP'!$B$11:$C$447,2,0) -> #N/A | C35: ແຕງ | D35: Nàng Nun | E35: CNKT | G35: 40000 | H35: 544338.9 | I35: 544338.9 | J35: =SUM(G35:I35) -> 1128677.8 | M35: =J35-L35 -> 1128677.8
A36: 24 | B36: =VLOOKUP(D36,'[2]DS CN MOI UP'!$B$11:$C$447,2,0) -> #N/A | C36: ແຕງ | D36: Thảo Bổ | E36: CNKT | G36: 40000 | H36: 574572.66 | I36: 574572.66 | J36: =SUM(G36:I36) -> 1189145.3 | M36: =J36-L36 -> 1189145.3
A37: 25 | B37: =VLOOKUP(D37,'[2]DS CN MOI UP'!$B$11:$C$447,2,0) -> #N/A | C37: ແຕງ | D37: Nàng Tủi | E37: CNKT | G37: 40000 | H37: 604806.43 | I37: 604806.43 | J37: =SUM(G37:I37) -> 1249612.9 | M37: =J37-L37 -> 1249612.9
A38: 26 | B38: =VLOOKUP(D38,'[2]DS CN MOI UP'!$B$11:$C$447,2,0) -> #N/A | C38: ແຕງ | D38: Nang Miu | E38: CNKT | G38: 40000 | H38: 584606.86 | I38: 584606.86 | J38: =SUM(G38:I38) -> 1209213.7 | M38: =J38-L38 -> 1209213.7
A39: 27 | B39: =VLOOKUP(D39,'[2]DS CN MOI UP'!$B$11:$C$447,2,0) -> 03442 | C39: ແຕງ | D39: Lec | E39: CNKT | H39: 635040.19 | I39: 635040.19 | J39: =SUM(G39:I39) -> 1270080.4 | M39: =J39-L39 -> 1270080.4
A40: 28 | B40: =VLOOKUP(D40,'[2]DS CN MOI UP'!$B$11:$C$447,2,0) -> 03439 | C40: ແຕງ | D40: Khu | E40: CNKT | G40: 40000 | H40: 524139.34 | I40: 524139.34 | J40: =SUM(G40:I40) -> 1088278.7 | M40: =J40-L40 -> 1088278.7
A41: 29 | B41: =VLOOKUP(D41,'[2]DS CN MOI UP'!$B$11:$C$447,2,0) -> #N/A | C41: ແຕງ | D41: Hài | E41: CNKT | G41: 40000 | H41: 554373.1 | I41: 554373.1 | J41: =SUM(G41:I41) -> 1148746.2 | M41: =J41-L41 -> 1148746.2
A42: 30 | B42: =VLOOKUP(D42,'[2]DS CN MOI UP'!$B$11:$C$447,2,0) -> 03443 | C42: ແຕງ | D42: Chun | E42: CNKT | G42: 40000 | H42: 554373.1 | I42: 265581.23 | J42: =SUM(G42:I42) -> 859954.33 | M42: =J42-L42 -> 859954.33
A43: 31 | B43: =VLOOKUP(D43,'[2]DS CN MOI UP'!$B$11:$C$447,2,0) -> #N/A | C43: ແຕງ | D43: Phò Đon | E43: CNKT | G43: 40000 | H43: 614840.62 | I43: 118679 | J43: =SUM(G43:I43) -> 773519.62 | M43: =J43-L43 -> 773519.62
A44: 32 | B44: =VLOOKUP(D44,'[2]DS CN MOI UP'!$B$11:$C$447,2,0) -> 03446 | C44: ແຕງ | D44: Thảo Công | E44: CNKT | G44: 40000 | H44: 554373.1 | I44: 107985.27 | J44: =SUM(G44:I44) -> 702358.37 | M44: =J44-L44 -> 702358.37
A45: 33 | B45: =VLOOKUP(D45,'[2]DS CN MOI UP'!$B$11:$C$447,2,0) -> 03440 | C45: ແຕງ | D45: Xeng | E45: CNKT | G45: 40000 | H45: 554373.1 | I45: 106506.79 | J45: =SUM(G45:I45) -> 700879.89 | M45: =J45-L45 -> 700879.89
A46: 34 | B46: =VLOOKUP(D46,'[2]DS CN MOI UP'!$B$11:$C$447,2,0) -> 03852 | C46: ແຕງ | D46: Na Ly | E46: CNKT | G46: 40000 | H46: 554373.1 | I46: 75304.754 | J46: =SUM(G46:I46) -> 669677.85 | M46: =J46-L46 -> 669677.85
A47: 35 | B47: =VLOOKUP(D47,'[2]DS CN MOI UP'!$B$11:$C$447,2,0) -> #N/A | C47: ແຕງ | D47: Ngui | E47: CNKT | G47: 40000 | H47: 635040.19 | I47: 150609.51 | J47: =SUM(G47:I47) -> 825649.7 | M47: =J47-L47 -> 825649.7
A48: 36 | B48: =VLOOKUP(D48,'[2]DS CN MOI UP'!$B$11:$C$447,2,0) -> #N/A | C48: ແຕງ | D48: Ca Lo | E48: CNKT | G48: 40000 | H48: 544338.9 | I48: 146532.6 | J48: =SUM(G48:I48) -> 730871.5 | M48: =J48-L48 -> 730871.5
...

Sheet CHẤM CÔNG Axit
A1: CÔNG TY TNHH CP QUASA-GERUCO | R1: CỘNG HÒA DÂN CHỦ NHÂN DÂN LÀO
A2: NÔNG TRƯỜNG 1 | R2: Hòa Bình - Độc Lập - Dân Chủ - Thống Nhất - Thịnh Vượng
R3: ----oOo----
A4: BẢNG CHẤM CÔNG THEO DÕI CHẤM CÔNG SỬ DỤNG AXIT ĐÁNH ĐÔNG THÁNG 06 NĂM 2024
A5: (Từ ngày 01 đến 30/06/2024)
A6: Stt | B6: MSNV | C6: Họ và tên | D6: Ngày công | AI6: Tổng số ngày làm việc | AJ6: Ký tên CN
D7: 1 | E7: 2 | F7: 3 | G7: 4 | H7: 5 | I7: 6 | J7: 7 | K7: 8 | L7: 9 | M7: 10 | N7: 11 | O7: 12 | P7: 13 | Q7: 14 | R7: 15 | S7: 16 | T7: 17 | U7: 18 | V7: 19 | W7: 20 | X7: 21 | Y7: 22 | Z7: 23 | AA7: 24 | AB7: 25 | AC7: 26 | AD7: 27 | AE7: 28 | AF7: 29 | AG7: 30 | AH7: 31
C8: Tên Việt
A9: Đội 1 | D9: =COUNTIF(D10:D52,"X")+COUNTIF(D10:D52,"CN") -> 0 | E9: =COUNTIF(E10:E52,"X")+COUNTIF(E10:E52,"CN") -> 0 | F9: =COUNTIF(F10:F52,"X")+COUNTIF(F10:F52,"CN") -> 0 | G9: =COUNTIF(G10:G52,"X")+COUNTIF(G10:G52,"CN") -> 0 | H9: =COUNTIF(H10:H52,"X")+COUNTIF(H10:H52,"CN") -> 0 | I9: =COUNTIF(I10:I52,"X")+COUNTIF(I10:I52,"CN") -> 0 | J9: =COUNTIF(J10:J52,"X")+COUNTIF(J10:J52,"CN") -> 0 | K9: =COUNTIF(K10:K52,"X")+COUNTIF(K10:K52,"CN") -> 0 | ... AH9: =COUNTIF(AH10:AH52,"X")+COUNTIF(AH10:AH52,"CN") -> 0 | AI9: =SUM(AI10:AI52) -> 0
A10: 1 | B10: =VLOOKUP(C10,'DS CN MOI UP'!$B$10:$C$347,2,0) -> #N/A | C10: Thô | AI10: =COUNTIF(D10:AH10,"X") -> 0
A11: 2 | B11: =VLOOKUP(C11,'DS CN MOI UP'!$B$10:$C$347,2,0) -> #N/A | C11: Mè Ta Van | AI11: =COUNTIF(D11:AH11,"X") -> 0
A12: 3 | B12: =VLOOKUP(C12,'DS CN MOI UP'!$B$10:$C$347,2,0) -> #N/A | C12: Ka Tho | AI12: =COUNTIF(D12:AH12,"X") -> 0
A13: 4 | B13: =VLOOKUP(C13,'DS CN MOI UP'!$B$10:$C$347,2,0) -> #N/A | C13: Tô Tộ | AI13: =COUNTIF(D13:AH13,"X") -> 0
A14: 5 | B14: =VLOOKUP(C14,'DS CN MOI UP'!$B$10:$C$347,2,0) -> #N/A | C14: Thảo In | AI14: =COUNTIF(D14:AH14,"X") -> 0
A15: 6 | B15: =VLOOKUP(C15,'DS CN MOI UP'!$B$10:$C$347,2,0) -> #N/A | C15: Cha La | AI15: =COUNTIF(D15:AH15,"X") -> 0
A16: 7 | B16: =VLOOKUP(C16,'DS CN MOI UP'!$B$10:$C$347,2,0) -> #N/A | C16: Nang Nga | AI16: =COUNTIF(D16:AH16,"X") -> 0
A17: 8 | B17: =VLOOKUP(C17,'DS CN MOI UP'!$B$10:$C$347,2,0) -> #N/A | C17: Viêng (1) | AI17: =COUNTIF(D17:AH17,"X") -> 0
A18: 9 | B18: =VLOOKUP(C18,'DS CN MOI UP'!$B$10:$C$347,2,0) -> #N/A | C18: Me Đuông | AI18: =COUNTIF(D18:AH18,"X") -> 0
A19: 10 | B19: =VLOOKUP(C19,'DS CN MOI UP'!$B$10:$C$347,2,0) -> #N/A | C19: Nang Môn | AI19: =COUNTIF(D19:AH19,"X") -> 0
A20: 11 | B20: =VLOOKUP(C20,'DS CN MOI UP'!$B$10:$C$347,2,0) -> #N/A | C20: Ziên | AI20: =COUNTIF(D20:AH20,"X") -> 0
A21: 12 | B21: =VLOOKUP(C21,'DS CN MOI UP'!$B$10:$C$347,2,0) -> #N/A | C21: Me Pê | AI21: =COUNTIF(D21:AH21,"X") -> 0
... A52: 43 | B52: =VLOOKUP(C52,'DS CN MOI UP'!$B$10:$C$347,2,0) -> #N/A | C52: Nang Hỏm | AI52: =COUNTIF(D52:AH52,"X") -> 0
A53: Đội 2 | B53: =VLOOKUP(C53,'DS CN MOI UP'!$B$10:$C$347,2,0) -> #N/A | D53: =COUNTIF(D54:D108,"X")+COUNTIF(D54:D108,"CN") -> 0 | E53: =COUNTIF(E54:E108,"X")+COUNTIF(E54:E108,"CN") -> 0 | F53: =COUNTIF(F54:F108,"X")+COUNTIF(F54:F108,"CN") -> 12 | G53: =COUNTIF(G54:G108,"X")+COUNTIF(G54:G108,"CN") -> 0 | H53: =COUNTIF(H54:H108,"X")+COUNTIF(H54:H108,"CN") -> 15 | I53: =COUNTIF(I54:I108,"X")+COUNTIF(I54:I108,"CN") -> 16 | J53: =COUNTIF(J54:J108,"X")+COUNTIF(J54:J108,"CN") -> 12 | K53: =COUNTIF(K54:K108,"X")+COUNTIF(K54:K108,"CN") -> 21 | ... AH53: =COUNTIF(AH54:AH108,"X")+COUNTIF(AH54:AH108,"CN") -> 0 | AI53: =SUM(AI54:AI108) -> 173
A54: 1 | B54: =VLOOKUP(C54,'DS CN MOI UP'!$B$10:$C$347,2,0) -> #N/A | C54: Lếc | AI54: =COUNTIF(D54:AH54,"X") -> 0
A55: 2 | B55: =VLOOKUP(C55,'DS CN MOI UP'!$B$10:$C$347,2,0) -> #N/A | C55: Hăm Lẹ | R55: X | T55: X | AI55: =COUNTIF(D55:AH55,"X") -> 2
A56: 3 | B56: =VLOOKUP(C56,'DS CN MOI UP'!$B$10:$C$347,2,0) -> #N/A | C56: Vông | F56: X | H56: X | O56: X | T56: X | AI56: =COUNTIF(D56:AH56,"X") -> 4
A57: 4 | B57: =VLOOKUP(C57,'DS CN MOI UP'!$B$10:$C$347,2,0) -> #N/A | C57: Ma Ni Son | H57: X | K57: X | Q57: X | R57: X | AI57: =COUNTIF(D57:AH57,"X") -> 4
A58: 5 | B58: =VLOOKUP(C58,'DS CN MOI UP'!$B$10:$C$347,2,0) -> #N/A | C58: Cong Ma | H58: X | Q58: X | U58: X | AI58: =COUNTIF(D58:AH58,"X") -> 3
A59: 6 | B59: =VLOOKUP(C59,'DS CN MOI UP'!$B$10:$C$347,2,0) -> #N/A | C59: Két | H59: X | K59: X | AI59: =COUNTIF(D59:AH59,"X") -> 2
A60: 7 | B60: =VLOOKUP(C60,'DS CN MOI UP'!$B$10:$C$347,2,0) -> #N/A | C60: Măn | AI60: =COUNTIF(D60:AH60,"X") -> 0
A61: 8 | B61: =VLOOKUP(C61,'DS CN MOI UP'!$B$10:$C$347,2,0) -> #N/A | C61: Soi | I61: X | K61: X | O61: X | AI61: =COUNTIF(D61:AH61,"X") -> 3
A62: 9 | B62: =VLOOKUP(C62,'DS CN MOI UP'!$B$10:$C$347,2,0) -> #N/A | C62: Pò Mòm | F62: X | I62: X | K62: X | O62: X | P62: X | Q62: X | T62: X | U62: X | AI62: =COUNTIF(D62:AH62,"X") -> 8
A63: 10 | B63: =VLOOKUP(C63,'DS CN MOI UP'!$B$10:$C$347,2,0) -> #N/A | C63: Pệt | AI63: =COUNTIF(D63:AH63,"X") -> 0
A64: 11 | B64: =VLOOKUP(C64,'DS CN MOI UP'!$B$10:$C$347,2,0) -> #N/A | C64: Khay Khăm | H64: X | O64: X | AI64: =COUNTIF(D64:AH64,"X") -> 2
A65: 12 | B65: =VLOOKUP(C65,'DS CN MOI UP'!$B$10:$C$347,2,0) -> #N/A | C65: Ô Lích | I65: X | K65: X | P65: X | R65: X | T65: X | U65: X | AI65: =COUNTIF(D65:AH65,"X") -> 6
A66: 13 | B66: =VLOOKUP(C66,'DS CN MOI UP'!$B$10:$C$347,2,0) -> #N/A | C66: Va Khăm | I66: X | K66: X | Q66: X | AI66: =COUNTIF(D66:AH66,"X") -> 3
A67: 14 | B67: =VLOOKUP(C67,'DS CN MOI UP'!$B$10:$C$347,2,0) -> #N/A | C67: Căn Nha | I67: X | R67: X | AI67: =COUNTIF(D67:AH67,"X") -> 2
A68: 15 | B68: =VLOOKUP(C68,'DS CN MOI UP'!$B$10:$C$347,2,0) -> #N/A | C68: Nọi (2) | P68: X | AI68: =COUNTIF(D68:AH68,"X") -> 1
A69: 16 | B69: =VLOOKUP(C69,'DS CN MOI UP'!$B$10:$C$347,2,0) -> #N/A | C69: Lợt | H69: X | K69: X | Q69: X | T69: X | AI69: =COUNTIF(D69:AH69,"X") -> 4
A70: 17 | B70: =VLOOKUP(C70,'DS CN MOI UP'!$B$10:$C$347,2,0) -> #N/A | C70: Ếch | H70: X | K70: X | O70: X | Q70: X | T70: X | AI70: =COUNTIF(D70:AH70,"X") -> 5
...

Sheet MỦ XIRUM
A1: CÔNG TY TNHH CP QUASA-GERUCO LÀO | S1: CỘNG HÒA DÂN CHỦ NHÂN DÂN LÀO
A2: NÔNG TRƯỜNG 1 | S2: Hòa Bình - Độc Lập - Dân Chủ - Thống Nhất - Thịnh Vượng
S3: ----oOo----
A4: BẢNG THEO DÕI SẢN LƯỢNG MỦ TẠP THÁNG 09 NĂM 2024
A5: (Từ ngày 01 đến 31/07/2024) | AK5: DRC | AL5: 0.4986
A6: Stt | B6: Stt | C6: MSNV | D6: Họ và tên | E6: Ngày | AL6: Ký tên
E7: 1 | F7: 2 | G7: 3 | H7: 4 | I7: 5 | J7: 6 | K7: 7 | L7: 8 | M7: 9 | N7: 10 | O7: 11 | P7: 12 | Q7: 13 | R7: 14 | S7: 15 | T7: 16 | U7: 17 | V7: 18 | W7: 19 | X7: 20 | Y7: 21 | Z7: 22 | AA7: 23 | AB7: 24 | AC7: 25 | AD7: 26 | AE7: 27 | AF7: 28 | AG7: 29 | AH7: 30 | AI7: 31 | AJ7: Tổng mủ Xirum | AK7: Quy khô
A8: Lát bốc | E8: B | F8: C | G8: A | H8: B | I8: C | J8: A | K8: B | L8: C | M8: A | N8: B | O8: C | P8: A | Q8: B | R8: C | S8: A | T8: B | U8: C | V8: A | W8: B | X8: C | Y8: A | Z8: B | AA8: C | AB8: A | AC8: B | AD8: C | AE8: A | AF8: B | AG8: C | AH8: A | AI8: B | AM8: DRC | AN8: 0.42315994
A9: Đội 1 | E9: =SUM(E10:E10) -> 0 | F9: =SUM(F10:F10) -> 0 | G9: =SUM(G10:G10) -> 0 | H9: =SUM(H10:H10) -> 0 | I9: =SUM(I10:I10) -> 0 | J9: =SUM(J10:J10) -> 0 | K9: =SUM(K10:K10) -> 0 | L9: =SUM(L10:L10) -> 0 | ... AI9: =SUM(AI10:AI10) -> 0 | AJ9: =AJ10 -> 0 | AK9: =AK10 -> 0
A10: 1 | B10: 1 | C10: Mủ xirum | D10: Mủ xirum 1 | AJ10: =SUM(E10:AI10) -> 0 | AK10: =+AJ10*$AL$5 -> 0 | AM10: =SUM(E10:AI10) -> 0 | AN10: Mủ serum Đội 3 | AO10: 0.17504745
A11: Đội 2 | E11: =SUM(E12:E12) -> 0 | F11: =SUM(F12:F12) -> 0 | G11: =SUM(G12:G12) -> 0 | H11: =SUM(H12:H12) -> 0 | I11: =SUM(I12:I12) -> 0 | J11: =SUM(J12:J12) -> 0 | K11: =SUM(K12:K12) -> 0 | L11: =SUM(L12:L12) -> 0 | ... AI11: =SUM(AI12:AI12) -> 0 | AJ11: =AJ12 -> 290 | AK11: =AK12 -> 144.594 | AN11: Mủ serum Đội 4 | AO11: 0.31672615
A12: 1 | B12: 1 | C12: Mủ xirum | D12: Mủ xirum 2 | AH12: 290 | AJ12: =SUM(E12:AI12) -> 290 | AK12: =+AJ12*$AL$5 -> 144.594 | AM12: =SUM(E12:AI12) -> 290 | AN12: Mủ serum Đội 5 | AO12: 0.4986
A13: Đội 3 | E13: =SUM(E14:E14) -> 0 | F13: =SUM(F14:F14) -> 0 | G13: =SUM(G14:G14) -> 0 | H13: =SUM(H14:H14) -> 0 | I13: =SUM(I14:I14) -> 0 | J13: =SUM(J14:J14) -> 0 | K13: =SUM(K14:K14) -> 0 | L13: =SUM(L14:L14) -> 0 | ... AI13: =SUM(AI14:AI14) -> 0 | AJ13: =AJ14 -> 0 | AK13: =AK14 -> 0
A14: 2 | B14: 1 | C14: Phong | D14: Mủ xirum 3 | AJ14: =SUM(E14:AI14) -> 0 | AK14: =+AJ14*$AO$10 -> 0
A15: Đội 4 | E15: =SUM(E16:E16) -> 0 | F15: =SUM(F16:F16) -> 0 | G15: =SUM(G16:G16) -> 0 | H15: =SUM(H16:H16) -> 0 | I15: =SUM(I16:I16) -> 0 | J15: =SUM(J16:J16) -> 0 | K15: =SUM(K16:K16) -> 0 | L15: =SUM(L16:L16) -> 0 | ... AI15: =SUM(AI16:AI16) -> 0 | AJ15: =AJ16 -> 0 | AK15: =AK16 -> 0 | AM15: =SUM(AK9,AK11,AK13,AK15) -> 144.594
A16: 2 | B16: 1 | C16: Phong | D16: Mủ xirum 4 | AJ16: =SUM(E16:AI16) -> 0 | AK16: =+AJ16*$AO$11 -> 0
A17: Đội 5 | E17: =SUM(E18:E18) -> 0 | F17: =SUM(F18:F18) -> 0 | G17: =SUM(G18:G18) -> 0 | H17: =SUM(H18:H18) -> 0 | I17: =SUM(I18:I18) -> 0 | J17: =SUM(J18:J18) -> 0 | K17: =SUM(K18:K18) -> 0 | L17: =SUM(L18:L18) -> 0 | ... AI17: =SUM(AI18:AI18) -> 0 | AJ17: =SUM(E17:AI17) -> 0 | AK17: =SUM(AK18:AK18) -> 0
A18: 3 | B18: 1 | C18: Nàng Mon | D18: Mủ xirum 5 | AJ18: =SUM(E18:AI18) -> 0 | AK18: =+AJ18*$AO$12 -> 0
A19: Tổng | E19: =E11+E13+E15 -> 0 | F19: =F11+F13+F15 -> 0 | G19: =G11+G13+G15 -> 0 | H19: =H11+H13+H15 -> 0 | I19: =I11+I13+I15 -> 0 | J19: =J11+J13+J15 -> 0 | K19: =K11+K13+K15 -> 0 | L19: =L11+L13+L15 -> 0 | ... AI19: =AI11+AI13+AI15 -> 0 | AJ19: =AJ11+AJ13+AJ15+AJ9+AJ18 -> 290 | AK19: =AK11+AK13+AK15+AK9+AK18 -> 144.594 | AM19: =+AK19+'sản lượng'!AL90 -> 64092.594
A22: TỔNG GIÁM ĐỐC | J22: PHÒNG KT - NN | Q22: GĐ. NÔNG TRƯỜNG | Z22: TL. TC - KT | AG22: TL. KH - NN | AJ22: NGƯỜI LẬP BIỂU

Sheet MỦ DÂY
A1: CÔNG TY TNHH CP QUASA-GERUCO LÀO | S1: CỘNG HÒA DÂN CHỦ NHÂN DÂN LÀO
A2: NÔNG TRƯỜNG 1 | S2: Hòa Bình - Độc Lập - Dân Chủ - Thống Nhất - Thịnh Vượng
S3: ----oOo----
A4: BẢNG THEO DÕI SẢN LƯỢNG MỦ TẠP THÁNG 07 NĂM 2024
A5: (Từ ngày 01 đến 31/07/2024)
A6: Stt | B6: Stt | C6: MSNV | D6: Họ và tên | E6: Ngày | AJ6: Tổng mủ dây | AK6: Quy khô | AL6: Ký tên | AM6: DRC | AN6: 0.5
E7: 1 | F7: 2 | G7: 3 | H7: 4 | I7: 5 | J7: 6 | K7: 7 | L7: 8 | M7: 9 | N7: 10 | O7: 11 | P7: 12 | Q7: 13 | R7: 14 | S7: 15 | T7: 16 | U7: 17 | V7: 18 | W7: 19 | X7: 20 | Y7: 21 | Z7: 22 | AA7: 23 | AB7: 24 | AC7: 25 | AD7: 26 | AE7: 27 | AF7: 28 | AG7: 29 | AH7: 30 | AI7: 31
A8: Lát bốc | E8: B | F8: C | G8: A | H8: B | I8: C | J8: A | K8: B | L8: C | M8: A | N8: B | O8: C | P8: A | Q8: B | R8: C | S8: A | T8: B | U8: C | V8: A | W8: B | X8: C | Y8: A | Z8: B | AA8: C | AB8: A | AC8: B | AD8: C | AE8: A | AF8: B | AG8: C | AH8: A | AI8: B
A9: Đội 1 | E9: =SUM(E10:E52) -> 0 | F9: =SUM(F10:F52) -> 0 | G9: =SUM(G10:G52) -> 0 | H9: =SUM(H10:H52) -> 0 | I9: =SUM(I10:I52) -> 0 | J9: =SUM(J10:J52) -> 0 | K9: =SUM(K10:K52) -> 0 | L9: =SUM(L10:L52) -> 0 | ... AK9: =SUM(AK10:AK52) -> 0
A10: 1 | B10: 1 | C10: =VLOOKUP(D10,'DS CN MOI UP'!$B$10:$C$347,2,0) -> #N/A | D10: Thô | AJ10: =SUM(E10:AI10) -> 0 | AK10: =AJ10*$AN$6 -> 0
A11: 2 | B11: 2 | C11: =VLOOKUP(D11,'DS CN MOI UP'!$B$10:$C$347,2,0) -> #N/A | D11: Mè Ta Van | AJ11: =SUM(E11:AI11) -> 0 | AK11: =AJ11*$AN$6 -> 0
A12: 3 | B12: 3 | C12: =VLOOKUP(D12,'DS CN MOI UP'!$B$10:$C$347,2,0) -> #N/A | D12: Ka Tho | AJ12: =SUM(E12:AI12) -> 0 | AK12: =AJ12*$AN$6 -> 0
A13: 4 | B13: 4 | C13: =VLOOKUP(D13,'DS CN MOI UP'!$B$10:$C$347,2,0) -> #N/A | D13: Tô Tộ | AJ13: =SUM(E13:AI13) -> 0 | AK13: =AJ13*$AN$6 -> 0
A14: 5 | B14: 5 | C14: =VLOOKUP(D14,'DS CN MOI UP'!$B$10:$C$347,2,0) -> #N/A | D14: Thảo In | AJ14: =SUM(E14:AI14) -> 0 | AK14: =AJ14*$AN$6 -> 0
A15: 6 | B15: 6 | C15: =VLOOKUP(D15,'DS CN MOI UP'!$B$10:$C$347,2,0) -> #N/A | D15: Cha La | AJ15: =SUM(E15:AI15) -> 0 | AK15: =AJ15*$AN$6 -> 0
A16: 7 | B16: 7 | C16: =VLOOKUP(D16,'DS CN MOI UP'!$B$10:$C$347,2,0) -> #N/A | D16: Nang Nga | AJ16: =SUM(E16:AI16) -> 0 | AK16: =AJ16*$AN$6 -> 0
A17: 8 | B17: 8 | C17: =VLOOKUP(D17,'DS CN MOI UP'!$B$10:$C$347,2,0) -> #N/A | D17: Viêng (1) | AJ17: =SUM(E17:AI17) -> 0 | AK17: =AJ17*$AN$6 -> 0
A18: 9 | B18: 9 | C18: =VLOOKUP(D18,'DS CN MOI UP'!$B$10:$C$347,2,0) -> #N/A | D18: Me Đuông | AJ18: =SUM(E18:AI18) -> 0 | AK18: =AJ18*$AN$6 -> 0
A19: 10 | B19: 10 | C19: =VLOOKUP(D19,'DS CN MOI UP'!$B$10:$C$347,2,0) -> #N/A | D19: Nang Môn | AJ19: =SUM(E19:AI19) -> 0 | AK19: =AJ19*$AN$6 -> 0
A20: 11 | B20: 11 | C20: =VLOOKUP(D20,'DS CN MOI UP'!$B$10:$C$347,2,0) -> #N/A | D20: Ziên | AJ20: =SUM(E20:AI20) -> 0 | AK20: =AJ20*$AN$6 -> 0
A21: 12 | B21: 12 | C21: =VLOOKUP(D21,'DS CN MOI UP'!$B$10:$C$347,2,0) -> #N/A | D21: Me Pê | AJ21: =SUM(E21:AI21) -> 0 | AK21: =AJ21*$AN$6 -> 0
... A52: 43 | B52: 43 | C52: =VLOOKUP(D52,'DS CN MOI UP'!$B$10:$C$347,2,0) -> #N/A | D52: Nang Hỏm | AJ52: =SUM(E52:AI52) -> 0 | AK52: =AJ52*$AN$6 -> 0
A53: Đội 2 | C53: =VLOOKUP(D53,'DS CN MOI UP'!$B$10:$C$347,2,0) -> #N/A | AJ53: =SUM(AJ54:AJ109) -> 0 | AK53: =SUM(AK54:AK109) -> 0
A54: 44 | B54: 1 | C54: =VLOOKUP(D54,'DS CN MOI UP'!$B$10:$C$347,2,0) -> #N/A | D54: Lếc | AJ54: =SUM(E54:AI54) -> 0 | AK54: =AJ54*$AN$6 -> 0 | AM54: =SUM(E54:AI54) -> 0 | AN54: =+#REF!-AM54 -> #REF!
A55: 45 | B55: 2 | C55: =VLOOKUP(D55,'DS CN MOI UP'!$B$10:$C$347,2,0) -> #N/A | D55: Hăm Lẹ | AJ55: =SUM(E55:AI55) -> 0 | AK55: =AJ55*$AN$6 -> 0 | AM55: =SUM(E55:AI55) -> 0 | AN55: =+#REF!-AM55 -> #REF!
A56: 46 | B56: 3 | C56: =VLOOKUP(D56,'DS CN MOI UP'!$B$10:$C$347,2,0) -> #N/A | D56: Vông | AJ56: =SUM(E56:AI56) -> 0 | AK56: =AJ56*$AN$6 -> 0 | AM56: =SUM(E56:AI56) -> 0 | AN56: =+#REF!-AM56 -> #REF!
A57: 47 | B57: 4 | C57: =VLOOKUP(D57,'DS CN MOI UP'!$B$10:$C$347,2,0) -> #N/A | D57: Ma Ni Son | AJ57: =SUM(E57:AI57) -> 0 | AK57: =AJ57*$AN$6 -> 0 | AM57: =SUM(E57:AI57) -> 0 | AN57: =+#REF!-AM57 -> #REF!
A58: 48 | B58: 5 | C58: =VLOOKUP(D58,'DS CN MOI UP'!$B$10:$C$347,2,0) -> #N/A | D58: Cong Ma | AJ58: =SUM(E58:AI58) -> 0 | AK58: =AJ58*$AN$6 -> 0 | AM58: =SUM(E58:AI58) -> 0 | AN58: =+#REF!-AM58 -> #REF!
A59: 49 | B59: 6 | C59: =VLOOKUP(D59,'DS CN MOI UP'!$B$10:$C$347,2,0) -> #N/A | D59: Két | AJ59: =SUM(E59:AI59) -> 0 | AK59: =AJ59*$AN$6 -> 0 | AM59: =SUM(E59:AI59) -> 0 | AN59: =+#REF!-AM59 -> #REF!
A60: 50 | B60: 7 | C60: =VLOOKUP(D60,'DS CN MOI UP'!$B$10:$C$347,2,0) -> #N/A | D60: Măn | AJ60: =SUM(E60:AI60) -> 0 | AK60: =AJ60*$AN$6 -> 0 | AM60: =SUM(E60:AI60) -> 0 | AN60: =+#REF!-AM60 -> #REF!
A61: 51 | B61: 8 | C61: =VLOOKUP(D61,'DS CN MOI UP'!$B$10:$C$347,2,0) -> #N/A | D61: Soi | AJ61: =SUM(E61:AI61) -> 0 | AK61: =AJ61*$AN$6 -> 0 | AM61: =SUM(E61:AI61) -> 0 | AN61: =+#REF!-AM61 -> #REF!
A62: 52 | B62: 9 | C62: =VLOOKUP(D62,'DS CN MOI UP'!$B$10:$C$347,2,0) -> #N/A | D62: Pò Mòm | AJ62: =SUM(E62:AI62) -> 0 | AK62: =AJ62*$AN$6 -> 0 | AM62: =SUM(E62:AI62) -> 0 | AN62: =+#REF!-AM62 -> #REF!
A63: 53 | B63: 10 | C63: =VLOOKUP(D63,'DS CN MOI UP'!$B$10:$C$347,2,0) -> #N/A | D63: Pệt | AJ63: =SUM(E63:AI63) -> 0 | AK63: =AJ63*$AN$6 -> 0 | AM63: =SUM(E63:AI63) -> 0 | AN63: =+#REF!-AM63 -> #REF!
A64: 54 | B64: 11 | C64: =VLOOKUP(D64,'DS CN MOI UP'!$B$10:$C$347,2,0) -> #N/A | D64: Khay Khăm | AJ64: =SUM(E64:AI64) -> 0 | AK64: =AJ64*$AN$6 -> 0 | AM64: =SUM(E64:AI64) -> 0 | AN64: =+#REF!-AM64 -> #REF!
A65: 55 | B65: 12 | C65: =VLOOKUP(D65,'DS CN MOI UP'!$B$10:$C$347,2,0) -> #N/A | D65: Ô Lích | AJ65: =SUM(E65:AI65) -> 0 | AK65: =AJ65*$AN$6 -> 0 | AM65: =SUM(E65:AI65) -> 0 | AN65: =+#REF!-AM65 -> #REF!
... A109: 99 | B109: 55 | C109: =VLOOKUP(D109,'DS CN MOI UP'!$B$10:$C$347,2,0) -> #N/A | D109: Mủ xirum | AJ109: =SUM(E109:AI109) -> 0 | AK109: =AJ109*$AN$6 -> 0 | AM109: =SUM(E109:AI109) -> 0 | AN109: =+#REF!-AM109 -> #REF!
A110: Đội 3 | C110: =VLOOKUP(D110,'DS CN MOI UP'!$B$10:$C$347,2,0) -> #N/A | AJ110: =SUM(AJ111:AJ204) -> 0 | AK110: =SUM(AK111:AK204) -> 0
A111: 100 | B111: 1 | C111: =VLOOKUP(D111,'DS CN MOI UP'!$B$10:$C$347,2,0) -> 03319 | D111: Bôn | AJ111: =SUM(E111:AI111) -> 0 | AK111: =AJ111*$AN$6 -> 0
A112: 101 | B112: 2 | C112: =VLOOKUP(D112,'DS CN MOI UP'!$B$10:$C$347,2,0) -> 03320 | D112: E | AJ112: =SUM(E112:AI112) -> 0 | AK112: =AJ112*$AN$6 -> 0
A113: 102 | B113: 3 | C113: =VLOOKUP(D113,'DS CN MOI UP'!$B$10:$C$347,2,0) -> 02453 | D113: Khương (3) | AJ113: =SUM(E113:AI113) -> 0 | AK113: =AJ113*$AN$6 -> 0
...

Sheet DS CN MOI UP
A1: CÔNG TY TNHH CP QUASA-GERUCO LÀO | D1: CỘNG HÒA DÂN CHỦ NHÂN DÂN LÀO
A2: NÔNG TRƯỜNG 1 | D2: Hòa bình - Độc lập - Dân chủ - Thống nhất - Thịnh vượng
A4: DANH SÁCH CÔNG NHÂN KHAI THÁC + BẢO VỆ
A7: Stt | B7: Họ và tên | C7: MSNV | D7: Giới tính | E7: Ngày tháng năm sinh | F7: Nơi ở | G7: Ghi chú
A8: A | B8: CÔNG NHÂN KHAI THÁC
A10: Đội 3
A11: 1 | B11: Bôn | C11: 03319 | D11: Nam | F11: Non Say
A12: 2 | B12: E | C12: 03320 | D12: Nam | F12: Non Say
A13: 3 | B13: Khương (3) | C13: 02453 | D13: Nam | F13: Non Say
A14: 4 | B14: Nít Ni Lanh | C14: 02471 | D14: Nam | F14: Non Say
A15: 5 | B15: Khăm Đeng | C15: 02465 | D15: Nam | F15: Non Say
A16: 6 | B16: Nàng Năt | C16: 03321 | D16: Nữ | F16: Non Say
A17: 7 | B17: Xay (3) | C17: 03322 | D17: Nam | F17: Non Say
A18: 8 | B18: Xôn | C18: 02452 | D18: Nam | F18: Non Say
A19: 9 | B19: Phum Hom | C19: 02508 | D19: Nam | F19: Non Say
A20: 10 | B20: Pa Lay | C20: 03323 | D20: Nam | F20: Non Say
A21: 11 | B21: Măm | C21: 02466 | D21: Nam | F21: Non Say
A22: 12 | B22: Muôi | C22: 02493 | D22: Nữ | F22: Non Say
... A103: 93 | B103: Chinh | C103: 02480 | D103: Nữ | F103: Non Say
A104: XC
A105: 1 | B105: Pho Thông | C105: 03346 | D105: Nam | E105: 26696 | F105: Non Say
A106: 2 | B106: Ka Púc | C106: 02472 | D106: Nam | E106: 32579 | F106: Non Say
A107: 3 | B107: Chay Đi | C107: 02477 | D107: Nữ | E107: 34889 | F107: Non Say
A108: 4 | B108: Lăng B | C108: 02495 | D108: Nam | E108: 25486 | F108: Non Say
A109: 5 | B109: Vi Say | C109: 02505 | D109: Nam | E109: 26183 | F109: Non Say
A110: 6 | B110: On | C110: 02516 | D110: Nữ | E110: 35013 | F110: Non Say
A111: 7 | B111: Tuc | C111: 03347 | D111: Nữ | E111: 26671 | F111: Non Say
A112: TC
A113: 1 | B113: Thon | C113: 03343 | D113: Nam | E113: 38400 | F113: Non Say
A114: 2 | B114: Nhon | C114: 02444 | D114: Nữ | E114: 29503 | F114: Non Say
A115: 3 | B115: Hăm (3) | C115: 02447 | D115: Nam | E115: 32960 | F115: Xay Xăm Bun
A116: 4 | B116: Nang (3) | C116: 03344 | D116: Nữ | E116: 36203 | F116: Xay Xăm Bun
A117: 5 | B117: Khăm | C117: 02449 | D117: Nam | E117: 28619 | F117: Non Say
A118: 6 | B118: Nàng Bát | C118: 02445 | D118: Nữ | E118: 29405 | F118: Non Say
A119: 7 | B119: Dộc | C119: 02446 | D119: Nam | E119: 29803 | F119: Non Say
A120: 8 | B120: Chăn (3) | C120: 03345 | D120: Nam | E120: 32762 | F120: Xi Bun Hương
A121: 9 | B121: Hát | C121: 03854 | D121: Nam | E121: =2024-1982 -> 42 | F121: Xay Xăm Bun | G121: Chưa có HĐ
A122: 10 | B122: Bun (3) | C122: 03855 | D122: Nam | E122: =2024-1975 -> 49 | F122: Bản Cang | G122: Chưa có HĐ
A123: 11 | B123: My | C123: 03856 | D123: Nữ | E123: =2024-1986 -> 38 | F123: Xay Xăm Bun | G123: Chưa có HĐ
A124: Đội 4
...

Sheet BCSX T6 CHỈNH SỬA
A1: CỘNG HÒA DÂN CHỦ NHÂN DÂN LÀO
A2: Hoà Bình - Độc Lập - Dân Chủ - Thống Nhất - Thịnh Vượng
A3: -----oOo-----
A4: CÔNG TY TNHH MTV QUASA- GERUCO LÀO
A5: Đội sản xuất số 8
A7: BÁO CÁO SẢN XUẤT THÁNG 06 NĂM 2025
A8: ( Từ ngày 01 tháng 06 năm 2025 đến ngày 30 tháng 6 năm 2025 )
A10: STT | B10: DANH MỤC | C10: ĐVT | D10: Định mức | E10: Địa điểm và khối lương thực hiện | M10: Tổng khối lượng | N10: Số lần | O10: Tổng công | P10: Ghi chú
E11: Tên lô | F11: KL | G11: Tên lô | H11: KL | I11: Tên lô | J11: KL | K11: Tên lô | L11: KL | O11: 25.000 kíp
A12: A | B12: VƯỜN CÂY KINH DOANH | O12: =O17+O21 -> 2134.48
A13: I | B13: SẢN LƯỢNG | C13: Kg
A14: 1.1 | B14: Mủ tạp (Quy khô) | C14: kg | Q14: =97+52+23 -> 172
A15: 1.2 | B15: Mủ dây ( Quy khô ) | C15: kg | Q15: =Q14/4 -> 43
A16: 1.3 | B16: Mủ Sirum ( Quy khô) | C16: kg
A17: II | B17: PHỤ CẤP CẠO MỦ | C17: Công | O17: =SUM(O18:O20) -> 0
A18: 2.1 | B18: Phụ cấp ngày công đi cạo | C18: công | O18: =ROUND(M18*30/25,2) -> 0 | R18: 59
A19: 2.2 | B19: Phụ cấp đi cạo ngày chủ nhật | C19: công | O19: =ROUND(M19*50/25,2) -> 0 | Q19: 78 | R19: 25
A20: 2.3 | B20: Phu cấp ngày công cho công nhân vùng khó khăn | C20: công | O20: =ROUND(M20*20/25,2) -> 0 | R20: 12
A21: III | B21: CHĂM SÓC | O21: =SUBTOTAL(9,O22:O46) -> 2134.48 | Q21: =SUM(Q18:Q20) -> 78 | R21: =SUM(R18:R20) -> 96
A22: 1 | B22: Vườn cây kinh doanh năm 1 | O22: =SUBTOTAL(9,O23:O27) -> 379.68
A23: 1.1 | B23: Bôi thuốc kích thích | C23: phần | D23: 1.25 | M23: 24 | O23: =M23/D23 -> 19.2 | Q23: =1/D23 -> 0.8
A24: 1.2 | B24: Bôi thuốc phòng bệnh loét sọc miệng cạo | C24: phần | D24: 1.25 | M24: 24 | O24: =M24/D24 -> 19.2
A25: 1.3 | B25: Phun thuốc diệt cỏ đại trà
B26: Trạm 2 | C26: ha | D26: =1/4.8 -> 0.20833333 | E26: 20A | F26: 13.56 | G26: 22A | H26: 5.62 | I26: 14A | J26: 2.6 | K26: 21A | L26: 17.53 | M26: =SUM(E26:L27) -> 71.1 | O26: =M26/D26 -> 341.28 | Q26: =[3]KHSXT7!M31 -> 11.84 | R26: =M26+Q26 -> 82.94
E27: 15A | F27: 2.5 | G27: 16A | H27: 6.5 | I27: 20C | J27: 5.04 | K27: 17A | L27: 17.75
A28: 2 | B28: Vườn cây kinh doanh năm 6 | O28: =SUBTOTAL(9,O29:O32) -> 27.6
A29: 2.1 | B29: Bôi thuốc kích thích | C29: phần | D29: 1.25 | M29: 12 | O29: =M29/D29 -> 9.6
A30: 2.2 | B30: Bôi thuốc phòng bệnh loét sọc miệng cạo | C30: phần | D30: 1.25 | M30: 12 | O30: =M30/D30 -> 9.6
A31: 2.3 | B31: Phun thuốc diệt cỏ đại trà
B32: Trạm 1 | C32: ha | D32: =1/4.8 -> 0.20833333 | E32: 13I | F32: 1.75 | M32: =F32 -> 1.75 | O32: =M32/D32 -> 8.4 | Q32: =M32 -> 1.75
A33: 3 | B33: Vườn cây kinh doanh năm 8 | O33: =SUBTOTAL(9,O34:O41) -> 1230.08 | Q33: =[3]KHSXT7!M45 -> 15.26
A34: 3.1 | B34: Bôi thuốc kích thích | C34: phần | D34: 1.25 | M34: 180 | O34: =M34/D34 -> 144
A35: 3.2 | B35: Bôi thuốc phòng bệnh loét sọc miệng cạo | C35: phần | D35: 1.25 | M35: =180-101 -> 79 | O35: =M35/D35 -> 63.2
A36: 3.3 | B36: Phát chồi đại trà | C36: ha | D36: =1/16 -> 0.0625 | E36: 18E | F36: =11.6+4 -> 15.6 | G36: 19K | H36: 6.1 | I36: 13J | J36: 11.45 | M36: =SUM(E36:L36) -> 33.15 | O36: =M36/D36 -> 530.4 | Q36: =M36-F36 -> 17.55
A37: 3.4 | B37: Phun thuốc diệt cỏ đại trà
B38: Trạm 1 | C38: ha | D38: =1/4.8 -> 0.20833333 | E38: 15I | F38: 9.16 | G38: 16I | H38: 4.52 | I38: 15K | J38: 3.77 | K38: 14J | L38: 7.1 | M38: =SUM(E38:L39) -> 32.4 | O38: =M38/D38 -> 155.52
E39: 14K | F39: 7.85
B41: Trạm 2 | C41: ha | D41: =1/4.8 -> 0.20833333 | E41: 16E | F41: 14.42 | G41: 17E | H41: 19.89 | I41: 18F | J41: 31.95 | K41: 18A | L41: 3.94 | M41: =SUM(E41:L41) -> 70.2 | O41: =M41/D41 -> 336.96
A42: 4 | B42: Vườn cây tận thu | O42: =SUBTOTAL(9,O43:O46) -> 497.12
A43: 4.1 | B43: Phát chồi đại trà | C43: ha | D43: =1/16 -> 0.0625 | E43: 18E | F43: =15.79+2.82 -> 18.61 | G43: 19K | H43: 6 | I43: 13J | J43: 3.1 | M43: =SUM(E43:L43) -> 27.71 | O43: =M43/D43 -> 443.36 | Q43: =M46 -> 11.2
...

Sheet CÔNG CHĂM SÓC
A2: BẢNG TỔNG HỢP CÁC CÔNG CHĂM SÓC
A4: STT | B4: Tên CN | C4: Tên công việc | M4: Tổng
C5: Bôi kích thích | D5: bôi loét sọc | E5: Phun cỏ | F5: Phát chồi | O5: Bấm mái chắn mưa | P5: Bấm mái chắn mưa HO4 | Q5: Bấm màng phủ chén | R5: Bôi thuốc kích thích
A7: Trạm 1 | C7: =SUM(C8:C33) -> 76.8 | D7: =SUM(D8:D33) -> 29.6 | E7: =SUM(E8:E33) -> 217.68 | F7: =SUM(F8:F33) -> 530.4 | G7: =SUM(G8:G33) -> 0 | H7: =SUM(H8:H33) -> 0 | I7: =SUM(I8:I33) -> 0 | J7: =SUM(J8:J33) -> 0 | ... M7: =SUM(M8:M33) -> 854.48
A8: 1 | B8: Phương | C8: 3.2 | M8: =SUM(C8:L8) -> 3.2 | O8: 2 | P8: 1 | Q8: 3 | R8: 3
A9: 2 | B9: Nhung | C9: 3.2 | D9: 0.8 | M9: =SUM(C9:L9) -> 4 | O9: 1 | P9: 2 | Q9: 3 | R9: 3
A10: 3 | B10: Xăm Chết | C10: 3.2 | D10: 0.8 | M10: =SUM(C10:L10) -> 4 | O10: 1 | P10: 2 | Q10: 3 | R10: 3
A11: 4 | B11: Thảo Po Mua | C11: 3.2 | D11: 0.8 | M11: =SUM(C11:L11) -> 4 | O11: 1 | P11: 2 | Q11: 3 | R11: 3
A12: 5 | B12: Thảo Từn Vàng | C12: 3.2 | M12: =SUM(C12:L12) -> 3.2 | O12: 1 | P12: 2 | Q12: 3 | R12: 3
A13: 6 | B13: Thảo Cua Vư | C13: 3.2 | M13: =SUM(C13:L13) -> 3.2 | O13: 1 | P13: 2 | Q13: 3 | R13: 3
A14: 7 | B14: Mèo | C14: 3.2 | D14: 0.8 | M14: =SUM(C14:L14) -> 4 | O14: 1 | P14: 2 | Q14: 3 | R14: 3
A15: 8 | B15: A Pan | C15: 3.2 | D15: 0.8 | M15: =SUM(C15:L15) -> 4 | O15: 1 | P15: 2 | Q15: 3 | R15: 3
A16: 9 | B16: A Thay | C16: 3.2 | D16: 0.8 | M16: =SUM(C16:L16) -> 4 | O16: 1 | P16: 2 | Q16: 3 | R16: 3
A17: 10 | B17: Cha | C17: 3.2 | D17: 0.8 | M17: =SUM(C17:L17) -> 4 | O17: 1 | P17: 2 | Q17: 3 | R17: 3
A18: 11 | B18: Thọ Tinh | C18: 3.2 | D18: 1.6 | M18: =SUM(C18:L18) -> 4.8 | O18: 1 | P18: 2 | Q18: 3 | R18: 3
A19: 12 | B19: Sinh Thoong | C19: 3.2 | D19: 1.6 | M19: =SUM(C19:L19) -> 4.8 | O19: 1 | P19: 2 | Q19: 3 | R19: 3
A20: 13 | B20: Bố Nọi | C20: 3.2 | D20: 0.8 | M20: =SUM(C20:L20) -> 4 | O20: 1 | P20: 2 | Q20: 3 | R20: 3
A21: 14 | B21: A Thưng | C21: 3.2 | D21: 0.8 | M21: =SUM(C21:L21) -> 4 | O21: 1 | P21: 2 | Q21: 3 | R21: 3
A22: 15 | B22: Xì xung | C22: 3.2 | D22: 1.6 | M22: =SUM(C22:L22) -> 4.8 | O22: 1 | P22: 2 | Q22: 3 | R22: 3
A23: 16 | B23: Cha Chiệp | C23: 3.2 | D23: 1.6 | M23: =SUM(C23:L23) -> 4.8 | O23: 1 | P23: 2 | Q23: 3 | R23: 3
A24: 17 | B24: Cha Măn | C24: 3.2 | D24: 1.6 | M24: =SUM(C24:L24) -> 4.8 | O24: 1 | P24: 2 | Q24: 3 | R24: 3
A25: 18 | B25: A Nem | C25: 3.2 | D25: 1.6 | M25: =SUM(C25:L25) -> 4.8 | O25: 1 | P25: 2 | Q25: 3 | R25: 3
A26: 19 | B26: Muôi | M26: =SUM(C26:L26) -> 0 | O26: 1 | P26: 2 | Q26: 3 | R26: 3
A27: 20 | B27: A Hông | C27: 3.2 | D27: 1.6 | M27: =SUM(C27:L27) -> 4.8 | O27: 1 | P27: 2 | Q27: 3 | R27: 3
A28: 21 | B28: Ka Văng | M28: =SUM(C28:L28) -> 0 | O28: 1 | P28: 2 | Q28: 3 | R28: 3
A29: 22 | B29: Xăm Mái | C29: 3.2 | D29: 0.8 | M29: =SUM(C29:L29) -> 4 | O29: 1 | P29: 2 | Q29: 3 | R29: 3
A30: 23 | B30: Ly | C30: 3.2 | D30: 0.8 | M30: =SUM(C30:L30) -> 4 | O30: 1 | P30: 2 | Q30: 3 | R30: 3
A31: 24 | B31: A Tè | C31: 3.2 | D31: 1.6 | M31: =SUM(C31:L31) -> 4.8 | O31: 1 | P31: 2 | Q31: 3 | R31: 3
B32: A Pót | C32: 3.2 | D32: =3.2+1.6 -> 4.8 | E32: 217.68 | M32: =SUM(C32:L32) -> 225.68
B33: Sún | C33: 3.2 | D33: 3.2 | F33: 530.4 | M33: =SUM(C33:L33) -> 536.8
A34: Trạm 2 | C34: =SUM(C35:C66) -> 96 | D34: =SUM(D35:D66) -> 62.4 | E34: =SUM(E35:E66) -> 678.24 | F34: =SUM(F35:F66) -> 443.36 | G34: =SUM(G35:G66) -> 0 | H34: =SUM(H35:H66) -> 0 | I34: =SUM(I35:I66) -> 0 | J34: =SUM(J35:J66) -> 0 | ... M34: =SUM(M35:M66) -> 1280 | O34: Bấm mái chắn mưa | Q34: Bấm màng phủ chén | R34: Bôi thuốc kích thích | S34: Gia cố mái chắn mưa
A35: 1 | B35: Thông Đăm | C35: 3.2 | D35: 2.4 | M35: =SUM(C35:L35) -> 5.6 | O35: 4 | Q35: 4 | R35: 4
A36: 2 | B36: A Bươi | C36: 3.2 | D36: 2.4 | M36: =SUM(C36:L36) -> 5.6 | O36: 4 | Q36: 4 | R36: 4
A37: 3 | B37: Lun | C37: 3.2 | D37: 2.4 | M37: =SUM(C37:L37) -> 5.6 | O37: 4 | Q37: 4 | R37: 4
A38: 4 | B38: A Phay | C38: 3.2 | D38: 2.4 | M38: =SUM(C38:L38) -> 5.6 | O38: 4 | Q38: 4 | R38: 4
A39: 5 | B39: A Pon | C39: 3.2 | D39: 2.4 | M39: =SUM(C39:L39) -> 5.6 | O39: 4 | Q39: 4 | R39: 4
A40: 6 | B40: Ta Lốt | C40: 3.2 | D40: 2.4 | M40: =SUM(C40:L40) -> 5.6 | O40: 4 | Q40: 4 | R40: 4
A41: 7 | B41: Phò Lăng | C41: 3.2 | D41: 1.6 | M41: =SUM(C41:L41) -> 4.8 | O41: 4 | Q41: 4 | R41: 4
A42: 8 | B42: A Têng | C42: 3.2 | D42: 1.6 | M42: =SUM(C42:L42) -> 4.8 | O42: 4 | Q42: 4 | R42: 4
A43: 9 | B43: Ói | C43: 3.2 | D43: 1.6 | M43: =SUM(C43:L43) -> 4.8 | O43: 4 | Q43: 4 | R43: 4
...

Sheet BCSX T6
A1: CỘNG HÒA DÂN CHỦ NHÂN DÂN LÀO
A2: Hoà Bình - Độc Lập - Dân Chủ - Thống Nhất - Thịnh Vượng
A3: -----oOo-----
A4: CÔNG TY TNHH MTV QUASA- GERUCO LÀO
A5: ĐỘI SẢN XUẤT SỐ 6
A7: BÁO CÁO SẢN XUẤT THÁNG 06 NĂM 2025
A8: ( Từ ngày 01 tháng 06 đến ngày 30 tháng 6 năm 2025 )
A10: STT | B10: DANH MỤC | C10: ĐVT | D10: Định mức | E10: Địa điểm và khối lương thực hiện | M10: Tổng khối lượng | N10: Tổng công | O10: Ghi chú
E11: Tên lô | F11: KL | G11: Tên lô | H11: KL | I11: Tên lô | J11: KL | K11: Tên lô | L11: KL | N11: 25.000 kíp
A12: A | B12: VƯỜN CÂY KINH DOANH | N12: =SUBTOTAL(9,N13:N56) -> 1536.8019
A13: I | B13: SẢN LƯỢNG | C13: Kg
A14: 1.1 | B14: Mủ tạp (Quy khô) | C14: kg | P14: =31/0.4 -> 77.5
A15: 1.2 | B15: Mủ dây ( Quy khô ) | C15: Kg
A16: 1.3 | B16: Mủ Sirum ( Quy khô) | C16: Kg
A17: II | B17: PHỤ CẤP CẠO MỦ | C17: Công | N17: =+SUBTOTAL(9,N18:N21) -> 0
A18: 2.1 | B18: Phụ cấp ngày công đi cạo | C18: Công
A19: 2.2 | B19: Phụ cấp đi cạo ngày chủ nhật | C19: Công
A20: 2.3 | B20: Phu cấp ngày công cho công nhân vùng khó khăn | C20: Công
A21: 2.4 | B21: Phu cấp cạo cây non | C21: Công
A22: III | B22: CHĂM SÓC | N22: =SUBTOTAL(9,N23:N56) -> 1536.8019
A23: 1 | B23: Vườn cây kinh doanh năm 1 | N23: =+SUBTOTAL(9,N24:N31) -> 399.10286
A24: 1.1 | B24: Bôi thuốc kích thích mủ | C24: Phần | D24: =25/20 -> 1.25 | M24: 23 | N24: =+M24/D24 -> 18.4
A25: 1.2 | B25: Bôi thuốc loét sọc miệng cạo | C25: Phần | D25: =25/20 -> 1.25 | M25: 23 | N25: =+M25/D25 -> 18.4
A26: 1.3 | B26: Dọn cành nhánh trên lô | C26: Phần | D26: 0.5 | M26: =+SUM(E27:L27) -> 22 | N26: =+M26/D26 -> 44
E27: X1 | F27: 6 | G27: X2 | H27: 10 | I27: X33 | J27: 5 | K27: X25 | L27: 1 | Q27: =+#REF!+#REF!+#REF!+#REF! -> #REF! | R27: 94.57
A28: 1.4 | B28: Phun thuốc diệt cỏ đại trà | C28: ha | D28: 0.21 | M28: =+SUM(E29:L29) -> 1.29 | N28: =+M28/D28 -> 6.1428571
B29: Trạm 2 | E29: X25 | F29: 1.29 | Q29: =+M28+M40+M49 -> 61.69 | R29: =+M59+M62 -> 114.68
A30: 1.5 | B30: Phát chồi đại trà | C30: Ha | D30: =1/16 -> 0.0625 | M30: =+SUM(E31:L31) -> 19.51 | N30: =+M30/D30 -> 312.16 | Q30: =+Q29+R29 -> 176.37 | R30: phun
B31: Trạm 2 | E31: X22 | F31: 10.75 | G31: X33 | H31: 8.76
A32: 2 | B32: Vườn cây kinh doanh năm 2 | N32: =+SUBTOTAL(9,N33:N36) -> 164.16
A33: 2.1 | B33: Bôi thuốc kích thích mủ | C33: Phần | D33: =25/20 -> 1.25 | M33: 33 | N33: =+M33/D33 -> 26.4
A34: 2.2 | B34: Bôi thuốc loét sọc miệng cạo | C34: Phần | D34: =25/20 -> 1.25 | M34: 33 | N34: =+M34/D34 -> 26.4
A35: 2.4 | B35: Phát chồi đại trà | C35: Ha | D35: =1/16 -> 0.0625 | M35: =+SUM(E36:J36) -> 6.96 | N35: =+M35/D35 -> 111.36
B36: Trạm 2 | E36: X29 | F36: 6.96
A37: 3 | B37: Vườn cây kinh doanh năm 4 | N37: =+SUBTOTAL(9,N38:N45) -> 402.8019 | Q37: 50
A38: 3.1 | B38: Bôi thuốc kích thích mủ | C38: Phần | D38: =25/20 -> 1.25 | M38: 64 | N38: =+M38/D38 -> 51.2
A39: 3.2 | B39: Bôi thuốc loét sọc miệng cạo | C39: Phần | D39: =25/20 -> 1.25 | M39: 64 | N39: =+M39/D39 -> 51.2
A40: 3.5 | B40: Phun thuốc diệt cỏ đại trà | C40: ha | D40: 0.21 | M40: =SUM(E41:L41) -> 34.81 | N40: =+M40/D40 -> 165.7619
B41: Trạm 2 | E41: X25 | F41: 16.31 | G41: X20a | H41: 5.9 | I41: X20b | J41: 12.6
A42: 3.6 | B42: Phát chồi đại trà | C42: Ha | D42: =1/16 -> 0.0625 | M42: =+SUM(E43:L43) -> 4.59 | N42: =+M42/D42 -> 73.44
...

Sheet TTTX
B1: CỘNG HOÀ DÂN CHỦ NHÂN DÂN LÀO
B2: Hoà bình - Độc Lập - Dân chủ - Thống nhất - Thịnh vượng
B3: ----oOo----
B4: CÔNG TY TNHH CỔ PHẦN QUASA - GERUCO LÀO
B5: ĐỘI SẢN XUẤT SỐ 06
B7: BẢNG THANH TOÁN TIỀN PHỤ CẤP TIỀN XĂNG CB.CNV THÁNG 05 NĂM 2025
A9: STT | B9: Họ và tên | C9: Số ngày | D9: Đơn giá ( Kíp) | E9: Thành tiền ( Kíp) | F9: Ký nhận | G9: Ghi chú
A10: 1 | B10: Trần Quang Thiện | C10: =+VLOOKUP(B10,'[4]CHẤM CÔNG XĂNG'!$C$12:$AM$17,37,0) -> 15 | D10: 20000 | E10: =+C10*D10 -> 300000
A11: 2 | B11: Trần Thanh Hải | C11: =+VLOOKUP(B11,'[4]CHẤM CÔNG XĂNG'!$C$12:$AM$17,37,0) -> 7 | D11: 20000 | E11: =+C11*D11 -> 140000
A12: 3 | B12: Vương Thành Long | C12: =+VLOOKUP(B12,'[4]CHẤM CÔNG XĂNG'!$C$12:$AM$17,37,0) -> 15 | D12: 20000 | E12: =+C12*D12 -> 300000
A13: 4 | B13: Hồ Dũng Cảm | C13: =+VLOOKUP(B13,'[4]CHẤM CÔNG XĂNG'!$C$12:$AM$17,37,0) -> 15 | D13: 20000 | E13: =+C13*D13 -> 300000
A14: 5 | B14: Nguyễn Tất Châu | C14: =+VLOOKUP(B14,'[4]CHẤM CÔNG XĂNG'!$C$12:$AM$17,37,0) -> 15 | D14: 20000 | E14: =+C14*D14 -> 300000
A15: 6 | B15: Nguyễn Phúc Hào | C15: =+VLOOKUP(B15,'[4]CHẤM CÔNG XĂNG'!$C$12:$AM$17,37,0) -> 15 | D15: 20000 | E15: =+C15*D15 -> 300000
A16: Tộng cộng | C16: =SUM(C10:C15) -> 82 | E16: =SUM(E10:E15) -> 1640000
A17: Bằng chữ: Ba triệu bảy trăm hai mươi nghìn kíp
D18: Huyện Nong, ngày 03 tháng 06 năm 2025
A19: P.PHÒNG PHỤ TRÁCH | C19: ĐỘI TRƯỞNG | F19: NGƯỜI LẬP
A27: PHÒNG TC - KT | D27: PHÒNG TC - HC

Sheet CHẤM CÔNG XĂNG
A1: CỘNG HÒA DÂN CHỦ NHÂN DÂN LÀO
A2: Hòa bình - Độc lập - Dân chủ - Thống nhất - Thịnh vượng
A3: -----oOo-----
A4: CÔNG TY TNHH CP QUASA - GERUCO LÀO | AN4: 1 | AO4: 2 | AP4: 3 | AQ4: 4 | AR4: 5 | AS4: 6 | AT4: 7
A5: ĐỘI SẢN XUẤT SỐ 6 | AN5: CN | AO5: Hai | AP5: Ba | AQ5: Tư | AR5: Năm | AS5: Sáu | AT5: Bảy
A7: BẢNG CHẤM CÔNG PHỤ CẤP TIỀN XĂNG THÁNG 05 NĂM 2025
B8: NĂM | C8: 2025
B9: THÁNG | C9: 05
A10: STT | B10: Mã NV | C10: Ngày/thứ Họ và tên | D10: Chức vụ | E10: 1 | F10: 2 | G10: 3 | H10: 4 | I10: 5 | J10: 6 | K10: 7 | L10: 8 | M10: 9 | N10: 10 | O10: 11 | P10: 12 | Q10: 13 | R10: 14 | S10: 15 | T10: 16 | U10: 17 | V10: 18 | W10: 19 | X10: 20 | Y10: 21 | Z10: 22 | AA10: 23 | AB10: 24 | AC10: 25 | AD10: 26 | AE10: 27 | AF10: 28 | AG10: =IF(DAY(DATE(C8,C9+1,1)-1)<29,"",29) -> 29 | AH10: 30 | AI10: 31 | AJ10: Ngày công đi làm | AK10: Ngày nghĩ phép | AL10: Ngày công trực tết | AM10: Tổng cộng | AN10: Ghi chú
E11: =IF(E10="","",HLOOKUP(WEEKDAY(DATE($C$8,$C$9,E10)),$AN$4:$AT$5,2,0)) -> Năm | F11: =IF(F10="","",HLOOKUP(WEEKDAY(DATE($C$8,$C$9,F10)),$AN$4:$AT$5,2,0)) -> Sáu | G11: =IF(G10="","",HLOOKUP(WEEKDAY(DATE($C$8,$C$9,G10)),$AN$4:$AT$5,2,0)) -> Bảy | H11: =IF(H10="","",HLOOKUP(WEEKDAY(DATE($C$8,$C$9,H10)),$AN$4:$AT$5,2,0)) -> CN | I11: =IF(I10="","",HLOOKUP(WEEKDAY(DATE($C$8,$C$9,I10)),$AN$4:$AT$5,2,0)) -> Hai | J11: =IF(J10="","",HLOOKUP(WEEKDAY(DATE($C$8,$C$9,J10)),$AN$4:$AT$5,2,0)) -> Ba | K11: =IF(K10="","",HLOOKUP(WEEKDAY(DATE($C$8,$C$9,K10)),$AN$4:$AT$5,2,0)) -> Tư | L11: =IF(L10="","",HLOOKUP(WEEKDAY(DATE($C$8,$C$9,L10)),$AN$4:$AT$5,2,0)) -> Năm | ... AG11: =IF(AG10="","",HLOOKUP(WEEKDAY(DATE($C$8,$C$9,AG10)),$AN$4:$AT$5,2,0)) -> Năm | AH11: Năm | AI11: =IF(AI10="","",HLOOKUP(WEEKDAY(DATE($C$8,$C$9,AI10)),$AN$4:$AT$5,2,0)) -> Bảy
A12: 1 | C12: Trần Quang Thiện | D12: Đội trưởng | E12: X | F12: X | G12: X | H12: X | I12: X | J12: X | K12: X | L12: X | M12: X | N12: X | O12: X | P12: X | Q12: X | R12: X | S12: X | AJ12: =COUNTIF(E12:AI12,"X") -> 15 | AK12: =COUNTIF(E12:AJ12,"P") -> 0 | AL12: =COUNTIF(E12:AJ12,"TT") -> 0 | AM12: =+AJ12+AL12+AK12 -> 15
A13: 2 | C13: Trần Thanh Hải | D13: Đội Phó | E13: X | F13: X | G13: X | H13: X | I13: X | J13: X | S13: X | AJ13: =COUNTIF(E13:AI13,"X") -> 7 | AK13: =COUNTIF(E13:AJ13,"P") -> 0 | AM13: =+AJ13+AL13+AK13 -> 7
A14: 3 | C14: Vương Thành Long | D14: Đội Phó | E14: X | F14: X | G14: X | H14: X | I14: X | J14: X | K14: X | L14: X | M14: X | N14: X | O14: X | P14: X | Q14: X | R14: X | S14: X | AJ14: =COUNTIF(E14:AI14,"X") -> 15 | AK14: =COUNTIF(E14:AJ14,"P") -> 0 | AL14: =COUNTIF(E14:AJ14,"TT") -> 0 | AM14: =+AJ14+AL14+AK14 -> 15
A15: 4 | C15: Hồ Dũng Cảm | D15: Thống kê - tổng hợp | E15: X | F15: X | G15: X | H15: X | I15: X | J15: X | K15: X | L15: X | M15: X | N15: X | O15: X | P15: X | Q15: X | R15: X | S15: X | AJ15: =COUNTIF(E15:AI15,"X") -> 15 | AK15: =COUNTIF(E15:AJ15,"P") -> 0 | AL15: =COUNTIF(E15:AJ15,"TT") -> 0 | AM15: =+AJ15+AL15+AK15 -> 15
A16: 5 | C16: Nguyễn Tất Châu | D16: Nhân viên kỷ thuật | E16: X | F16: X | G16: X | H16: X | I16: X | J16: X | K16: X | L16: X | M16: X | N16: X | O16: X | P16: X | Q16: X | R16: X | S16: X | AJ16: =COUNTIF(E16:AI16,"X") -> 15 | AM16: =+AJ16+AL16+AK16 -> 15
A17: 6 | C17: Nguyễn Phúc Hào | D17: Nhân viên kỷ thuật | E17: X | F17: X | G17: X | H17: X | I17: X | J17: X | K17: X | L17: X | M17: X | N17: X | O17: X | P17: X | Q17: X | R17: X | S17: X | AJ17: =COUNTIF(E17:AI17,"X") -> 15 | AK17: =COUNTIF(E17:AJ17,"P") -> 0 | AM17: =+AJ17+AL17+AK17 -> 15
A18: TỔNG CỘNG | S18: =COUNTIF(S12:S17,"X") -> 6 | T18: =COUNTIF(T12:T17,"X") -> 0 | U18: =COUNTIF(U12:U17,"X") -> 0 | V18: =COUNTIF(V12:V17,"X") -> 0 | W18: =COUNTIF(W12:W17,"X") -> 0 | X18: =COUNTIF(X12:X17,"X") -> 0 | Y18: =COUNTIF(Y12:Y17,"X") -> 0 | Z18: =COUNTIF(Z12:Z17,"X") -> 0 | ... AI18: =COUNTIF(AI12:AI17,"X") -> 0 | AJ18: =SUM(AJ12:AJ17) -> 82 | AK18: =SUM(AK12:AK15) -> 0 | AL18: =SUM(AL12:AL15) -> 0 | AM18: =SUM(AM12:AM17) -> 82
A19: Ghi chú: | AA19: Huyện Noong, ngày 01 tháng 06 năm 2025
A20: x | B20: Ghi chú: | C20: Ngày công đi làm | D20: P .TC - HC | I20: P.PHÒNG KTNN PHỤ TRÁCH | S20: ĐỘI TRƯỞNG | AB20: NGƯỜI LẬP

Sheet Thanh toán mủ dây
A1: CỘNG HÒA DÂN CHỦ NHÂN DÂN LÀO
A2: Hòa Bình -Độc Lập - Dân Chủ - thống Nhất - Thịnh Vượng
A3: -----oOo-----
A4: CÔNG TY TNHH CP QUASA - GERUCO LÀO
A5: ĐỘI SẢN XUẤT SỐ 6
A7: BẢNG THANH TOÁN TIỀN LƯƠNG MỦ DÂY THÁNG 06 NĂM 2025
A8: (Từ ngày 01 tháng 06 đến ngày 30 tháng 06 năm 2025)
A11: Stt | B11: Họ và tên | C11: Ngày | AG11: Sản lượng mủ dây | AH11: Đơn giá ( Kíp) | AI11: Thành tiền | AJ11: Ký tên
C12: 1 | D12: 2 | E12: 3 | F12: 4 | G12: 5 | H12: 6 | I12: 7 | J12: 8 | K12: 9 | L12: 10 | M12: 11 | N12: 12 | O12: 13 | P12: 14 | Q12: 15 | R12: 16 | S12: 17 | T12: 18 | U12: 19 | V12: 20 | W12: 21 | X12: 22 | Y12: 23 | Z12: 24 | AA12: 25 | AB12: 26 | AC12: 27 | AD12: 28 | AE12: 29 | AF12: 30
A13: 1 | B13: Tà Lọt | T13: 20 | AG13: =+VLOOKUP(B13,'Biểu 2 TH MỦ dây'!$C$11:$AI$87,33,0) -> 27 | AH13: 8000 | AI13: =+AG13*AH13 -> 216000
