Workbook
Name ten_hang_muc_KD: '[1]Ten hang muc (2)'!$B$1:$C$31

Sheet SL KHOÁNG T10 NT
G1: Qui khô 44% | I1: tổ 2 | K1: tổ 3 | M1: tổ 4 | O1: tổ 5
A2: Tổ | B2: Tổng cây | C2: Sản lượng (kg) | D2: Quy khô 44% (kg) | G2: 1567.3 | H2: 3562 | I2: 1666.3 | J2: 3787 | K2: 1681.7 | L2: 3822 | M2: 1031.8 | N2: 2345 | O2: 1204.7 | P2: 2738
A3: 1 | B3: 123836 | C3: 173374 | D3: =ROUND(C3*0.44,0) -> 76285 | G3: 1557.2 | H3: 3539 | I3: 1640.3 | J3: 3728 | K3: 1662.8 | L3: 3779 | M3: 1100.4 | N3: 2501 | O3: 1196.8 | P3: 2720
A4: 2 | B4: 118640 | C4: 166096 | D4: =ROUND(C4*0.44,0) -> 73082 | G4: 1582.7 | H4: 3597 | I4: 1632.4 | J4: 3710 | K4: 1584.4 | L4: 3601 | M4: 1087.7 | N4: 2472 | O4: 1136.1 | P4: 2582
A5: 3 | B5: 115450 | C5: 161633 | D5: =ROUND(C5*0.44,0) -> 71119 | G5: 1617 | H5: 3675 | I5: 1590.6 | J5: 3615 | K5: 1584.9 | L5: 3602 | M5: 1057.3 | N5: 2403 | O5: 1173 | P5: 2666
A6: 4 | B6: 80347 | C6: 80347 | D6: =ROUND(C6*0.44,0) -> 35353 | G6: 1651.3 | H6: 3753 | I6: 1584.4 | J6: 3601 | K6: 1607.8 | L6: 3654 | M6: 1043.7 | N6: 2372 | O6: 1195.9 | P6: 2718
A7: 5 | B7: 79366 | C7: 87306 | D7: =ROUND(C7*0.44,0) -> 38415 | G7: 1662.8 | H7: 3779 | I7: 1564.2 | J7: 3555 | K7: 1599 | L7: 3634 | M7: 1035.3 | N7: 2353 | O7: 1253.6 | P7: 2849
G8: 1671.1 | H8: 3798 | I8: 1639.9 | J8: 3727 | K8: 1618.8 | L8: 3679 | M8: 1000.1 | N8: 2273 | O8: 1238.2 | P8: 2814
A9: TỔNG CỘNG | B9: =SUM(B3:B8) -> 517639 | C9: =SUM(C3:C8) -> 668756 | D9: =SUM(D3:D8) -> 294254 | G9: 1619.6 | H9: 3681 | I9: 1604.7 | J9: 3647 | K9: 1602 | L9: 3641 | M9: 985.2 | N9: 2239 | O9: 1243.9 | P9: 2827
G10: 1669.4 | H10: 3794 | I10: 1586.6 | J10: 3606 | K10: 1588.8 | L10: 3611 | M10: 963.2 | N10: 2189 | O10: 1222.8 | P10: 2779
G11: 1613.9 | H11: 3668 | I11: 1654.4 | J11: 3760 | K11: 1604.7 | L11: 3647 | M11: 1007.2 | N11: 2289 | O11: 1194.2 | P11: 2714
G12: 1635.5 | H12: 3717 | I12: 1654 | J12: 3759 | K12: 1585.8 | L12: 3604 | M12: 969.8 | N12: 2204 | O12: 1173.9 | P12: 2668
G13: 1614.4 | H13: 3669 | I13: 1641.2 | J13: 3730 | K13: 1564.2 | L13: 3555 | M13: 1018.2 | N13: 2314 | O13: 1169.5 | P13: 2658
G14: 1656.6 | H14: 3765 | I14: 1592.8 | J14: 3620 | K14: 1522.8 | L14: 3461 | M14: 1002.8 | N14: 2279 | O14: 1185.8 | P14: 2695
G15: 1561.1 | H15: 3548 | I15: 1610.4 | J15: 3660 | K15: 1527.2 | L15: 3471 | M15: 981.6 | N15: 2231 | O15: 1123.8 | P15: 2554
G16: 1601.6 | H16: 3640 | I16: 1620.1 | J16: 3682 | K16: 1570.4 | L16: 3569 | M16: 990.4 | N16: 2251 | O16: 1141.8 | P16: 2595
G17: 1676.8 | H17: 3811 | I17: 1687.4 | J17: 3835 | K17: 1594.1 | L17: 3623 | M17: 1024.8 | N17: 2329 | O17: 1111.4 | P17: 2526
G18: 1677.3 | H18: 3812 | I18: 1606 | J18: 3650 | K18: 1579.6 | L18: 3590 | M18: 1002.3 | N18: 2278 | O18: 1118.5 | P18: 2542
G19: 1676.8 | H19: 3811 | I19: 1634.2 | J19: 3714 | K19: 1575.2 | L19: 3580 | M19: 1013.8 | N19: 2304 | O19: 1107 | P19: 2516
G20: 1662.8 | H20: 3779 | I20: 1605.1 | J20: 3648 | K20: 1625.8 | L20: 3695 | M20: 1058.6 | N20: 2406 | O20: 1054.2 | P20: 2396
G21: 1672 | H21: 3800 | I21: 1567.3 | J21: 3562 | K21: 1692.2 | L21: 3846 | M21: 1079.3 | N21: 2453 | O21: 1085.9 | P21: 2468
... G35: 1656.6 | H35: 3765 | I35: 1630.6 | J35: 3706 | K35: 1578.7 | L35: 3588 | M35: 1114.1 | N35: 2532 | O35: 1035.8 | P35: 2354
G36: 1607.8 | H36: 3654 | I36: 1666.7 | J36: 3788 | K36: 1651.3 | L36: 3753
G37: 1669.8 | H37: 3795 | I37: 1641.2 | J37: 3730 | K37: 1638.1 | L37: 3723
G38: 1619.6 | H38: 3681 | I38: 1632.4 | J38: 3710 | K38: 1743.3 | L38: 3962
G39: 1647.4 | H39: 3744 | I39: 1657.5 | J39: 3767 | K39: 1743.3 | L39: 3962
G40: 1650.4 | H40: 3751 | I40: 1660.1 | J40: 3773 | K40: 1601.2 | L40: 3639
G41: 1551.9 | H41: 3527 | I41: 1649.1 | J41: 3748 | K41: 1651.3 | L41: 3753
G42: 1574.3 | H42: 3578 | I42: 1652.6 | J42: 3756 | K42: 1649.6 | L42: 3749
G43: 1607.3 | H43: 3653 | I43: 1659.7 | J43: 3772 | K43: 1656.6 | L43: 3765
G44: 1591.9 | H44: 3618 | I44: 1620.5 | J44: 3683 | K44: 1664.5 | L44: 3783
G45: 1589.3 | H45: 3612 | I45: 1612.6 | J45: 3665 | K45: 1659.7 | L45: 3772
G46: 1598.5 | H46: 3633 | I46: 1613.9 | J46: 3668
G47: 1592.8 | H47: 3620
G48: 1543.1 | H48: 3507

Sheet ct thuc te
A2: CHI TIẾT SẢN XUẤT NÔNG TRƯỜNG 1 KD THÁNG 06/2022
A3: S T T | B3: Tên lô | C3: Năm trồng | D3: Diện tích | E3: phát chổi | F3: bón phân | H3: t 4 | I3: t 5
D4: 2369.1
A5: KD 5 | B5: 0 | D5: =SUM(D6:D25) -> 474.2 | E5: =SUM(E6:E25) -> 0 | F5: =SUM(F6:F25) -> 218.3 | G5: 0
A6: 1 | B6: W 15 | C6: 2011 | D6: 24.3 | F6: =D6 -> 24.3
A7: 2 | B7: X 15 | C7: 2011 | D7: 24.3 | F7: =D7 -> 24.3
A8: 3 | B8: X 16 | C8: 2011 | D8: 24.3 | F8: =D8 -> 24.3
A9: 4 | B9: X 17 | C9: 2011 | D9: 24.3 | F9: =D9 -> 24.3
A10: 5 | B10: X 19 | C10: 2011 | D10: 24.3 | F10: =D10 -> 24.3
A11: 6 | B11: Y 12 | C11: 2011 | D11: 24.3 | H11: 24.3
A12: 7 | B12: Y 13 | C12: 2011 | D12: 23.8 | I12: 23.8
A13: 8 | B13: Y 15 | C13: 2011 | D13: 24.3 | I13: 24.3
A14: 9 | B14: Y 16 | C14: 2011 | D14: 24.3 | F14: =D14 -> 24.3
A15: 10 | B15: Y 19 | C15: 2011 | D15: 24.1 | F15: =D15 -> 24.1
A16: 11 | B16: Y 20 | C16: 2011 | D16: 24.1 | F16: =D16 -> 24.1
A17: 12 | B17: Y 21 | C17: 2011 | D17: 24.3 | F17: =D17 -> 24.3
A18: 13 | B18: Z 14 | C18: 2011 | D18: 22.9 | H18: 22.9
A19: 14 | B19: Z 15 | C19: 2011 | D19: 23.2 | H19: 23.2
A20: 15 | B20: Z 16 | C20: 2011 | D20: 23.2 | H20: 23.2
A21: 16 | B21: Z 17 | C21: 2011 | D21: 23.2 | H21: 23.2
A22: 17 | B22: Z 18 | C22: 2011 | D22: 23.3 | H22: 23.3
A23: 18 | B23: Z 19 | C23: 2011 | D23: 23.4 | H23: 23.4
A24: 19 | B24: Z 20 | C24: 2011 | D24: 22.3 | H24: 22.3
A25: 20 | B25: Z 21 | C25: 2011 | D25: 22 | H25: 22
A26: KD 4 | B26: 0 | D26: =SUM(D27:D58) -> 676.4 | E26: =SUM(E27:E58) -> 0 | F26: =SUM(F27:F58) -> 365.7 | G26: 0
A27: 1 | B27: X 20 | C27: 2011 | D27: 24.3 | F27: =D27 -> 24.3
A28: 2 | B28: X 18 | C28: 2011 | D28: 24.3 | F28: =D28 -> 24.3
A29: 3 | B29: Z 23 | C29: 2011 | D29: 11.6 | H29: 11.6
A30: 4 | B30: Z 22 | C30: 2011 | D30: 23.5 | H30: 23.5
A31: 5 | B31: Y 18 | C31: 2011 | D31: 24.3 | F31: =D31 -> 24.3
A32: 6 | B32: Y 17 | C32: 2011 | D32: 24.3 | F32: =D32 -> 24.3
A33: 7 | B33: V 15 | C33: 2011 | D33: 23 | F33: =D33 -> 23
A34: 8 | B34: Z 12 | C34: 2012 | D34: 8.9 | H34: 8.9
A35: 9 | B35: Z 11 | C35: 2012 | D35: 14.8 | H35: 14.8
A36: 10 | B36: Y 22 | C36: 2012 | D36: 15.9 | F36: =D36 -> 15.9
A37: 11 | B37: Y 14 | C37: 2012 | D37: 21.6 | I37: 21.6
A38: 12 | B38: Y 10+11 | C38: 2012 | D38: 27.3 | H38: 27.3
A39: 13 | B39: X 14 | C39: 2012 | D39: 24.3 | I39: 24.3
A40: 14 | B40: X 13 | C40: 2012 | D40: 24.3 | I40: 24.3
A41: 15 | B41: X 12 | C41: 2012 | D41: 24.3 | H41: 24.3
...

Sheet TÊN HÀNG MỤC
A1: A | B1: CHĂM SÓC | C1: ការថែទាំ
A2: 1 | B2: Phát cỏ luồng | C2: ជម្រះស្មៅចន្លោះរង
A3: 2 | B3: Bón phân | C3: ដាក់ជី
A4: 3 | B4: Phòng trị bệnh | C4: បង្ការព្យាបាលជម្ងឺ
A5: 4 | B5: Làm giàn mủ tạp | C5: ធ្វើរានដាក់ជ័រចម្រុះ
A6: 5 | B6: Phòng chống cháy + gác lửa | C6: ការពារភ្លើងឆេះ + យាមភ្លើង
A7: B | B7: THU HOẠCH | C7: ប្រមូលផល
A8: 1 | B8: Kiểm kê cây cao su đầu vụ cạo | C8: ជំរឿនដើមកៅស៊ូនៅដើមរដូវចៀរ
A9: 2 | B9: Thiết kế mặt cạo | C9: បែងចែកផ្ទាំងចៀរ
A10: 3 | B10: Đánh dấu hao dăm quý, năm | C10: គូសសញ្ញាចំណាយអាចម៍ពន្លាក់ប្រចាំត្រីមាស​និងឆ្នាំ
A11: 4 | B11: Chia, đánh số phần cạo | C11: បែងចែកនិងគូសលេខរានចៀរ
A12: 5 | B12: Trang bị vật tư (Kiềng, chén) | C12: បំពាក់ឧបករណ៍ (កង, ចាន)
A13: 6 | B13: Cạo xả miệng, đóng máng, gắn mái che chén | C13: បើកមុខចៀរជ័រដំបូង ដោតស្លាបព្រា​និងទគម្របចាន
A14: 7 | B14: Gắn máng chắn mưa | C14: ការបំពាក់ក្បាំងទឹកភ្លៀង
A15: 8 | B15: Vệ sinh cây cạo | C15: សំអាតដើមចៀរ
A16: 9 | B16: Bôi thuốc kích thích | C16: លាបថ្នាំរំញោច
A17: 10 | B17: Thu dọn cuối vụ cạo | C17: ប្រមូលសម្ភារៈចុងរដូវចៀរ
A18: 11 | B18: Cạo, trút và giao nộp mủ | C18: ចៀរ សារនិងប្រគូលជ័រ
A19: 12 | B19: Công nhật (25.500 KHR) | C19: កម្លាំងចៀរ
A20: 13 | B20: Công trả sản lượng mủ | C20: កម្លាំងចំណាយទៅលើផលិតផលជ័រ
A21: C | B21: Bảo vệ vườn cây | C21: សន្តិសុខការពារចំការ
B22: Kinh doanh nhóm 1 | C22: អាជីវកម្មក្រុមទី​១
B23: Kinh doanh năm 4 | C23: អាជីវកម្មឆ្នាំទី​៤
B24: Kinh doanh năm 3 | C24: អាជីវកម្មឆ្នាំទី​៣
B25: Kinh doanh năm 2 | C25: អាជីវកម្មឆ្នាំទី​២
B26: Mở cạo 2021 | C26: បើកមុខចៀរជ័រឆ្នាំ​២០២១
B27: Công/ha | C27: កម្លាំង/ហិតា
B28: Đợt 1 | C28: វគ្គទី​១
B29: Đợt 2 | C29: វគ្គទី​២
B30: Tổng 2 đợt | C30: សរុបទាំង​២វគ្គ
B31: Công/ngày | C31: កម្លាំង/ថ្ងៃ
A32: Hạng mục KTCB | C32: មុខងាររយៈមុនពេលប្រមូលផល
B33: Phun thuốc cỏ hàng | C33: បាញ់ថ្នាំរង
B34: Phát cỏ luồng | C34: ជម្រះស្មៅចន្លោះរង
B35: Phát dọn, phòng chống cháy | C35: ជម្រះការពារភ្លើងឆេះ
B36: Phòng trị bệnh | C36: បង្ការព្យាបាលជម្ងឺ
B37: Bảo vệ thường xuyên | C37: ការពារជាប្រចាំ
B38: Kiểm kê cuối năm | C38: ជំរឿនដើមកៅស៊ូនៅចុងរដូវចៀរ

Sheet Tên Tháng 1
P1: SỐ NĂM
A2: STT | B2: ប្រុល់ | C2: ស្រី | D2: CMNN | F2: TÊN | G2: Tổ | H2: Số phần cây
A4: 1 | B4: 33030 | C4: ស្រី | D4: 150429518 | E4: ឆែម ហុង | F4: CHHEM HONG | G4: 1 | H4: 1 | I4: GA 1 | O4: =YEAR(NOW())-YEAR(B4) -> 36 | P4: =IF(O4<=59,O4,IF(O4=60,1)) -> 36 | U4: 33030 | V4: NỮ
A5: 2 | B5: 35982 | C5: ប្រុស | D5: 220140698 | E5: សុទ្ធ សីថា | F5: SOT SEYTHA | G5: 1 | H5: 2 | I5: GA 1 | O5: =YEAR(NOW())-YEAR(B5) -> 28 | P5: =IF(O5<=59,O5,IF(O5=60,1)) -> 28 | U5: 35982 | V5: NAM
A6: 3 | B6: 38457 | C6: ប្រុស | D6: 151027370 | E6: រ៉ន ចាន់រាជ | F6: RORN CHANREACH | G6: 1 | H6: 3 | I6: GA 1 | O6: =YEAR(NOW())-YEAR(B6) -> 21 | P6: =IF(O6<=59,O6,IF(O6=60,1)) -> 21 | U6: 38457 | V6: NAM
A7: 4 | B7: 36175 | C7: ស្រី | D7: 150815265 | E7: ណំ ធីងធីង | F7: NON THING THING | G7: 1 | H7: 4 | I7: GA 1 | O7: =YEAR(NOW())-YEAR(B7) -> 27 | P7: =IF(O7<=59,O7,IF(O7=60,1)) -> 27 | U7: 36175 | V7: NỮ
A8: 5 | B8: 33615 | C8: ប្រុស | D8: 150523483 | E8: វ៉ាន់ បូរ៉ុង | F8: VANN BORONG | G8: 1 | H8: 5 | I8: GA 1 | O8: =YEAR(NOW())-YEAR(B8) -> 34 | P8: =IF(O8<=59,O8,IF(O8=60,1)) -> 34 | U8: 33615 | V8: NAM
A9: 6 | B9: 35986 | C9: ប្រុស | D9: 220152906 | E9: យឿង សុខជា | F9: YOEUNG SOKCHEA | G9: 1 | H9: 6 | I9: GA 1 | O9: =YEAR(NOW())-YEAR(B9) -> 28 | P9: =IF(O9<=59,O9,IF(O9=60,1)) -> 28 | U9: 35986 | V9: NAM
A10: 7 | B10: 36651 | C10: ប្រុស | D10: 220175364 | E10: អួន សុភាព | F10: OURN SOPHEAP | G10: 1 | H10: 7 | I10: GA 1 | O10: =YEAR(NOW())-YEAR(B10) -> 26 | P10: =IF(O10<=59,O10,IF(O10=60,1)) -> 26 | U10: 36651 | V10: NAM
A11: 8 | B11: 35950 | C11: ប្រុស | D11: 220209900 | E11: ភួន ភី | F11: PHUON PHY | G11: 1 | H11: 8 | I11: GA 1 | O11: =YEAR(NOW())-YEAR(B11) -> 28 | P11: =IF(O11<=59,O11,IF(O11=60,1)) -> 28 | U11: 35950 | V11: NAM
A12: 9 | B12: 36447 | C12: ប្រុស | D12: 150789799 | E12: ទូ គុលា | F12: TO TOKLA | G12: 1 | H12: 9 | I12: GA 1 | O12: =YEAR(NOW())-YEAR(B12) -> 27 | P12: =IF(O12<=59,O12,IF(O12=60,1)) -> 27 | U12: 36447 | V12: NAM
A13: 10 | B13: 38244 | C13: ស្រី | D13: 150983095 | E13: ណំ សិទ្ធិ | F13: NOM SITH | G13: 1 | H13: 10 | I13: GA 1 | O13: =YEAR(NOW())-YEAR(B13) -> 22 | P13: =IF(O13<=59,O13,IF(O13=60,1)) -> 22 | U13: 38244 | V13: NỮ
A14: 11 | B14: 29073 | C14: ស្រី | D14: 150814730 | E14: ធ្លក រាន់ | F14: THLOK ROIN | G14: 1 | H14: 11 | I14: GA 1 | O14: =YEAR(NOW())-YEAR(B14) -> 47 | P14: =IF(O14<=59,O14,IF(O14=60,1)) -> 47 | U14: 29073 | V14: NỮ
A15: 12 | B15: 29082 | C15: ស្រី | D15: 150427542 | E15: យ៉ែម ឃឿន | F15: YEM KHOEUN | G15: 1 | H15: 12 | I15: GA 1 | O15: =YEAR(NOW())-YEAR(B15) -> 47 | P15: =IF(O15<=59,O15,IF(O15=60,1)) -> 47 | U15: 29082 | V15: NỮ
A16: 13 | B16: 37848 | C16: ប្រុស | D16: 220234084 | E16: យឿង រ៉ាឌី | F16: YOEUNG RADIN | G16: 1 | H16: 13 | I16: GA 1 | O16: =YEAR(NOW())-YEAR(B16) -> 23 | P16: =IF(O16<=59,O16,IF(O16=60,1)) -> 23 | U16: 37848 | V16: NAM
A17: 14 | B17: 34127 | C17: ប្រុស | D17: 150468345 | E17: វ៉ាន់ បូរិទ្ធ | F17: VANN BORITH | G17: 1 | H17: 14 | I17: GA 1 | O17: =YEAR(NOW())-YEAR(B17) -> 33 | P17: =IF(O17<=59,O17,IF(O17=60,1)) -> 33 | U17: 34127 | V17: NAM
A18: 15 | B18: 30477 | C18: ស្រី | D18: 250230683 | E18: ឆែម ហ៊ាច | F18: CHHEM HEACH | G18: 1 | H18: 15 | I18: GA 1 | O18: =YEAR(NOW())-YEAR(B18) -> 43 | P18: =IF(O18<=59,O18,IF(O18=60,1)) -> 43 | U18: 30477 | V18: NỮ
A19: 16 | B19: 34095 | C19: ប្រុស | D19: 150523533 | E19: ឆែម ឆុន | F19: CHHEN CHHON | G19: 1 | H19: 16 | I19: GA 1 | O19: =YEAR(NOW())-YEAR(B19) -> 33 | P19: =IF(O19<=59,O19,IF(O19=60,1)) -> 33 | U19: 34095 | V19: NAM
... A27: 24 | B27: 35189 | C27: ប្រុស | D27: 220208788 | E27: សុទ្ធ សុខជា | F27: SOTH SOKCHEA | G27: 1 | H27: 24 | I27: GA 1 | O27: =YEAR(NOW())-YEAR(B27) -> 30 | P27: =IF(O27<=59,O27,IF(O27=60,1)) -> 30 | U27: 35189 | V27: NAM
A28: 25 | B28: 31200 | C28: ស្រី | D28: 060541171 | E28: ពិន ឆេន | F28: PIN CHHEN | G28: 1 | H28: 25 | I28: GA 1 | O28: =YEAR(NOW())-YEAR(B28) -> 41 | P28: =IF(O28<=59,O28,IF(O28=60,1)) -> 41 | U28: 31200 | V28: NỮ
A29: 26 | B29: 30904 | C29: ប្រុស | D29: 060540793 | E29: កេត នី | F29: KET NY | G29: 1 | H29: 26 | I29: GA 1 | O29: =YEAR(NOW())-YEAR(B29) -> 42 | P29: =IF(O29<=59,O29,IF(O29=60,1)) -> 42 | U29: 30904 | V29: NAM
A30: 27 | B30: 38861 | C30: ប្រុស | D30: 250373915 | E30: គៀវ និ | F30: KIEV NIK | G30: 1 | H30: 27 | I30: GA 1 | O30: =YEAR(NOW())-YEAR(B30) -> 20 | P30: =IF(O30<=59,O30,IF(O30=60,1)) -> 20 | U30: 38861 | V30: NAM
A31: 28 | B31: 39434 | C31: ប្រុស | D31: 151065238 | E31: ដួត ដែន | F31: DOUT DEN | G31: 1 | H31: 28 | I31: GA 1 | O31: =YEAR(NOW())-YEAR(B31) -> 19 | P31: =IF(O31<=59,O31,IF(O31=60,1)) -> 19 | U31: 39434 | V31: NAM
A32: 29 | B32: 39615 | C32: ស្រី | D32: 151057212 | E32: ចាយ ពន្លក | F32: CHAY PONLOK | G32: 1 | H32: 29 | I32: GA 1 | O32: =YEAR(NOW())-YEAR(B32) -> 18 | P32: =IF(O32<=59,O32,IF(O32=60,1)) -> 18 | U32: 39615 | V32: NỮ
A33: 30 | B33: 28982 | C33: ប្រុស | D33: 150978869 | E33: សំ ផុន | F33: SOM PHON | G33: 1 | H33: 30 | I33: GA 1 | O33: =YEAR(NOW())-YEAR(B33) -> 47 | P33: =IF(O33<=59,O33,IF(O33=60,1)) -> 47 | U33: 28982 | V33: NAM
A34: 31 | B34: 38595 | C34: ស្រី | D34: 150983094 | E34: អ៊ុន ឆវ័ន | F34: UN CHORVON | G34: 1 | H34: 31 | I34: GA 1 | O34: =YEAR(NOW())-YEAR(B34) -> 21 | P34: =IF(O34<=59,O34,IF(O34=60,1)) -> 21 | U34: 38595 | V34: NỮ
A35: 32 | B35: 30503 | C35: ប្រុស | D35: 220175216 | E35: ប៉ិល ថា | F35: PEL THA | G35: 1 | H35: 32 | I35: GA 1 | O35: =YEAR(NOW())-YEAR(B35) -> 43 | P35: =IF(O35<=59,O35,IF(O35=60,1)) -> 43 | U35: 30503 | V35: NAM
A36: 33 | B36: 31663 | C36: ប្រុស | D36: 220175443 | E36: ប៉ិល ផល្លា | F36: PEL PHALLA | G36: 1 | H36: 33 | I36: GA 1 | O36: =YEAR(NOW())-YEAR(B36) -> 40 | P36: =IF(O36<=59,O36,IF(O36=60,1)) -> 40 | U36: 31663 | V36: NAM
A37: 34 | B37: 37412 | C37: ប្រុស | D37: 220208812 | E37: យៀត ឌី | F37: YIEN DY | G37: 1 | H37: 34 | I37: GA 1 | O37: =YEAR(NOW())-YEAR(B37) -> 24 | P37: =IF(O37<=59,O37,IF(O37=60,1)) -> 24 | U37: 37412 | V37: NAM
A38: 35 | B38: 30868 | C38: ស្រី | D38: 220175374 | E38: រឿន ចាន់រ៉ា | F38: ROEUN CHANRA | G38: 1 | H38: 35 | I38: GA 1 | O38: =YEAR(NOW())-YEAR(B38) -> 42 | P38: =IF(O38<=59,O38,IF(O38=60,1)) -> 42 | U38: 30868 | V38: NỮ
A39: 36 | B39: 38777 | C39: ស្រី | D39: 220234356 | E39: អៀវ សុភ័ណ្ឌ | F39: IEV SOPHORN | G39: 1 | H39: 36 | I39: GA 1 | O39: =YEAR(NOW())-YEAR(B39) -> 20 | P39: =IF(O39<=59,O39,IF(O39=60,1)) -> 20 | U39: 38777 | V39: NỮ
A40: 37 | B40: 30835 | C40: ប្រុស | D40: 160485580 | E40: គុយ សឿន | F40: KUY SOEUN | G40: 1 | H40: 37 | I40: GA 1 | O40: =YEAR(NOW())-YEAR(B40) -> 42 | P40: =IF(O40<=59,O40,IF(O40=60,1)) -> 42 | U40: 30835 | V40: NAM
A41: 38 | B41: 35066 | C41: ស្រី | D41: 150523513 | E41: សាំ សុរីសា | F41: SAM SORYSA | G41: 1 | H41: 38 | I41: GA 1 | O41: =YEAR(NOW())-YEAR(B41) -> 30 | P41: =IF(O41<=59,O41,IF(O41=60,1)) -> 30 | U41: 35066 | V41: NỮ
... A60: 57 | B60: 38127 | C60: ស្រី | D60: 150949342 | E60: ម៉ួន ហ៊ាង | F60: MUON HEANG | G60: 4 | H60: 146 | I60: GA 1 | O60: =YEAR(NOW())-YEAR(B60) -> 22 | P60: =IF(O60<=59,O60,IF(O60=60,1)) -> 22 | U60: 38127 | V60: NỮ
A61: 58 | B61: 37818 | C61: ប្រុស | D61: 051669732 | E61: យ៉េន ហៃ | F61: YEN HAI | G61: 4 | H61: 147 | I61: GA 1 | O61: =YEAR(NOW())-YEAR(B61) -> 23 | P61: =IF(O61<=59,O61,IF(O61=60,1)) -> 23 | U61: 37818 | V61: NAM
A62: 59 | B62: 24275 | C62: ប្រុស | D62: 150360039 | E62: ស្រី អ៊ឹម | F62: SREY OEM | G62: 4 | H62: 148 | I62: GA 1 | O62: =YEAR(NOW())-YEAR(B62) -> 60 | P62: =IF(O62<=59,O62,IF(O62=60,1)) -> 1 | U62: 24275 | V62: NAM
A63: 60 | B63: 33636 | C63: ប្រុស | D63: 150523030 | E63: ណេ សារ៉ាត់ | F63: NE SARATH | G63: 4 | H63: 149 | I63: GA 1 | O63: =YEAR(NOW())-YEAR(B63) -> 34 | P63: =IF(O63<=59,O63,IF(O63=60,1)) -> 34 | U63: 33636 | V63: NAM
A64: 61 | B64: 30757 | C64: ស្រី | D64: 150236408 | E64: សន ធីន | F64: SORN THIN | G64: 4 | H64: 150 | I64: GA 1 | O64: =YEAR(NOW())-YEAR(B64) -> 42 | P64: =IF(O64<=59,O64,IF(O64=60,1)) -> 42 | U64: 30757 | V64: NỮ
A65: 62 | B65: 28445 | C65: ប្រុស | D65: 150523289 | E65: ម៉ន ម៉ៃ | F65: MORN MAY | G65: 4 | H65: 151 | I65: GA 1 | O65: =YEAR(NOW())-YEAR(B65) -> 49 | P65: =IF(O65<=59,O65,IF(O65=60,1)) -> 49 | U65: 28445 | V65: NAM
A66: 63 | B66: 28158 | C66: ស្រី | D66: 150523290 | E66: ជន សាមាក់ | F66: CHORN SAMAK | G66: 4 | H66: 152 | I66: GA 1 | O66: =YEAR(NOW())-YEAR(B66) -> 49 | P66: =IF(O66<=59,O66,IF(O66=60,1)) -> 49 | U66: 28158 | V66: NỮ
...

Sheet CHAM CONG
BI1: Tổ 1 | BJ1: =SUM(AQ8:AQ174) -> 2195 | BK1: =SUM(AR8:AR174) -> 91
A2: BẢNG CHẤM CÔNG CẠO MỦ THÁNG 01 /2026 | BF2: 2011 | BG2: =SUM(BA8:BC265) -> 0 | BI2: Tổ 2 | BJ2: =SUM(AQ177:AQ221) -> 513 | BK2: =SUM(AR177:AR221) -> 11
AQ3: =SUBTOTAL(9,AQ8:AQ314) -> 5479 | AR3: =SUBTOTAL(9,AR8:AR314) -> 293 | AV3: tổng 25.500 tháng 4,5 | AX3: =AX175+#REF!+#REF! -> #REF! | AY3: GHI CHÚ : NGÀY 1,4,5,6,7 THÁNG 11/2025 CHO NGƯƠNG CẠO | BF3: 2012 | BG3: =SUM(BD8:BD265)+SUM(#REF!) -> #REF! | BI3: Tổ 3 | BJ3: =SUM(AQ222:AQ265) -> 519 | BK3: =SUM(AR222:AR265) -> 26
A4: Stt | B4: Tổ | C4: Mã số CN | D4: Họ và tên | F4: Tổ khai thác | G4: Các ngày trong tháng | V4: D2 | AA4: cạo úp | AQ4: Tổng công | BF4: 2013 | BG4: =SUM(BA266:BD314) -> #N/A | BI4: Tổ 4 | BJ4: =SUM(#REF!) -> #REF! | BK4: =SUM(#REF!) -> #REF!
D5: Khmer | E5: Latinh | G5: 1 | H5: 2 | I5: 3 | J5: 4 | K5: 5 | L5: 6 | M5: 7 | N5: 8 | O5: 9 | P5: 10 | Q5: 11 | R5: 12 | S5: 13 | T5: 14 | U5: 15 | V5: 2 | W5: 3 | X5: 14 | Y5: 15 | AA5: 1 | AB5: 2 | AC5: 3 | AD5: 4 | AE5: 5 | AF5: 6 | AG5: 7 | AH5: 8 | AI5: 9 | AJ5: 10 | AK5: 11 | AL5: 12 | AM5: 13 | AN5: 14 | AO5: 15 | AP5: 31 | AQ5: 1-15 | AR5: D2 | AS5: Tổng | AT5: tháng 04/2025 | AU5: 25500 | AW5: 16000 | AX5: D | AY5: cạo choàn | AZ5: + | BA5: Cộng phiên A | BB5: Cộng phiên B | BC5: Cộng phiên C | BD5: Cộng phiên D | BE5: Tổng cộng | BF5: CC | BG5: =SUM(BG2:BG4) -> #REF! | BI5: Tổ 5 | BJ5: =SUM(#REF!) -> #REF! | BK5: =SUM(#REF!) -> #REF!
F6: Phiên cạo | AP6: A | AZ6: - | BF6: =SUM(BF8:BF265) -> 2492 | BG6: =SUM(BJ1:BJ9)-BG5 -> #REF! | BI6: Tổ 6 | BJ6: =SUM(AQ266:AQ313) -> 610 | BK6: =SUM(AR266:AR313) -> 64
B7: GA 1
A8: 1 | B8: 1 | C8: 1 | G8: 0 | H8: 0 | I8: x | K8: 0 | L8: 0 | M8: x | N8: x | O8: x | P8: x | Q8: x | R8: x | S8: x | T8: x | U8: x | AQ8: =COUNTIF(G8:U8,"X") -> 10 | AR8: =COUNTIF(V8:AA8,"X") -> 0 | AS8: =ROUND(COUNTIF(G8:AO8,"x"),0)+ROUND(COUNTIF(AA8:AP8,">0"),0) -> 10 | AT8: 9 | AZ8: =AY8*25000 -> 0 | BA8: =COUNTIFS($G8:$AP8,"x",$G$6:$AP$6,"A")+COUNTIFS($G8:$AP8,"xx",$G$6:$AP$6,"A") -> 0 | BB8: =COUNTIFS($G8:$AP8,"x",$G$6:$AP$6,"B")+COUNTIFS($G8:$AP8,"xx",$G$6:$AP$6,"B") -> 0 | BC8: =COUNTIFS($G8:$AP8,"x",$G$6:$AP$6,"C")+COUNTIFS($G8:$AP8,"xx",$G$6:$AP$6,"C") -> 0 | BD8: =COUNTIFS($G8:$AP8,"x",$G$6:$AP$6,"D")+COUNTIFS($G8:$AP8,"xx",$G$6:$AP$6,"D") -> 0 | BE8: =SUM(BA8:BD8) -> 0 | BF8: =IF(AS8>=13,AS8,0) -> 0 | BI8: Tổ 7 | BJ8: =SUM(#REF!) -> #REF! | BK8: =SUM(#REF!) -> #REF!
A9: 2 | B9: 1 | C9: 2 | G9: 0 | H9: x | I9: x | K9: x | L9: x | M9: x | N9: x | O9: x | P9: x | Q9: x | R9: x | S9: x | T9: x | U9: x | AQ9: =COUNTIF(G9:U9,"X") -> 13 | AR9: =COUNTIF(V9:AA9,"X") -> 0 | AS9: =ROUND(COUNTIF(G9:AO9,"x"),0)+ROUND(COUNTIF(AA9:AP9,">0"),0) -> 13 | AT9: 9 | AZ9: =AY9*25000 -> 0 | BA9: =COUNTIFS($G9:$AP9,"x",$G$6:$AP$6,"A")+COUNTIFS($G9:$AP9,"xx",$G$6:$AP$6,"A") -> 0 | BB9: =COUNTIFS($G9:$AP9,"x",$G$6:$AP$6,"B")+COUNTIFS($G9:$AP9,"xx",$G$6:$AP$6,"B") -> 0 | BC9: =COUNTIFS($G9:$AP9,"x",$G$6:$AP$6,"C")+COUNTIFS($G9:$AP9,"xx",$G$6:$AP$6,"C") -> 0 | BD9: =COUNTIFS($G9:$AP9,"x",$G$6:$AP$6,"D")+COUNTIFS($G9:$AP9,"xx",$G$6:$AP$6,"D") -> 0 | BE9: =SUM(BA9:BD9) -> 0 | BF9: =IF(AS9>=13,AS9,0) -> 13 | BI9: Tổ 8 | BJ9: =SUM(#REF!) -> #REF! | BK9: =SUM(#REF!) -> #REF!
A10: 3 | B10: 1 | C10: 3 | G10: x | H10: x | I10: x | K10: x | L10: x | M10: x | N10: x | O10: x | P10: x | Q10: x | R10: x | S10: x | T10: x | U10: x | V10: x | AQ10: =COUNTIF(G10:U10,"X") -> 14 | AR10: =COUNTIF(V10:AA10,"X") -> 1 | AS10: =ROUND(COUNTIF(G10:AO10,"x"),0)+ROUND(COUNTIF(AA10:AP10,">0"),0) -> 15 | AT10: 9 | AZ10: =AY10*25000 -> 0 | BA10: =COUNTIFS($G10:$AP10,"x",$G$6:$AP$6,"A")+COUNTIFS($G10:$AP10,"xx",$G$6:$AP$6,"A") -> 0 | BB10: =COUNTIFS($G10:$AP10,"x",$G$6:$AP$6,"B")+COUNTIFS($G10:$AP10,"xx",$G$6:$AP$6,"B") -> 0 | BC10: =COUNTIFS($G10:$AP10,"x",$G$6:$AP$6,"C")+COUNTIFS($G10:$AP10,"xx",$G$6:$AP$6,"C") -> 0 | BD10: =COUNTIFS($G10:$AP10,"x",$G$6:$AP$6,"D")+COUNTIFS($G10:$AP10,"xx",$G$6:$AP$6,"D") -> 0 | BE10: =SUM(BA10:BD10) -> 0 | BF10: =IF(AS10>=13,AS10,0) -> 15
A11: 4 | B11: 1 | C11: 4 | G11: 0 | H11: x | I11: x | K11: x | L11: x | M11: x | N11: x | O11: x | P11: x | Q11: x | R11: x | S11: x | T11: x | U11: x | AQ11: =COUNTIF(G11:U11,"X") -> 13 | AR11: =COUNTIF(V11:AA11,"X") -> 0 | AS11: =ROUND(COUNTIF(G11:AO11,"x"),0)+ROUND(COUNTIF(AA11:AP11,">0"),0) -> 13 | AT11: 9 | AZ11: =AY11*25000 -> 0 | BA11: =COUNTIFS($G11:$AP11,"x",$G$6:$AP$6,"A")+COUNTIFS($G11:$AP11,"xx",$G$6:$AP$6,"A") -> 0 | BB11: =COUNTIFS($G11:$AP11,"x",$G$6:$AP$6,"B")+COUNTIFS($G11:$AP11,"xx",$G$6:$AP$6,"B") -> 0 | BC11: =COUNTIFS($G11:$AP11,"x",$G$6:$AP$6,"C")+COUNTIFS($G11:$AP11,"xx",$G$6:$AP$6,"C") -> 0 | BD11: =COUNTIFS($G11:$AP11,"x",$G$6:$AP$6,"D")+COUNTIFS($G11:$AP11,"xx",$G$6:$AP$6,"D") -> 0 | BE11: =SUM(BA11:BD11) -> 0 | BF11: =IF(AS11>=13,AS11,0) -> 13
A12: 5 | B12: 1 | C12: 5 | G12: x | H12: x | I12: x | K12: x | L12: x | M12: x | N12: x | O12: x | P12: x | Q12: x | R12: x | S12: x | T12: x | U12: x | X12: x | AQ12: =COUNTIF(G12:U12,"X") -> 14 | AR12: =COUNTIF(V12:AA12,"X") -> 1 | AS12: =ROUND(COUNTIF(G12:AO12,"x"),0)+ROUND(COUNTIF(AA12:AP12,">0"),0) -> 15 | AT12: 9 | AZ12: =AY12*25000 -> 0 | BA12: =COUNTIFS($G12:$AP12,"x",$G$6:$AP$6,"A")+COUNTIFS($G12:$AP12,"xx",$G$6:$AP$6,"A") -> 0 | BB12: =COUNTIFS($G12:$AP12,"x",$G$6:$AP$6,"B")+COUNTIFS($G12:$AP12,"xx",$G$6:$AP$6,"B") -> 0 | BC12: =COUNTIFS($G12:$AP12,"x",$G$6:$AP$6,"C")+COUNTIFS($G12:$AP12,"xx",$G$6:$AP$6,"C") -> 0 | BD12: =COUNTIFS($G12:$AP12,"x",$G$6:$AP$6,"D")+COUNTIFS($G12:$AP12,"xx",$G$6:$AP$6,"D") -> 0 | BE12: =SUM(BA12:BD12) -> 0 | BF12: =IF(AS12>=13,AS12,0) -> 15
A13: 6 | B13: 1 | C13: 6 | G13: x | H13: x | I13: x | K13: 0 | L13: x | M13: x | N13: x | O13: x | P13: x | Q13: x | R13: x | S13: x | T13: x | U13: x | AQ13: =COUNTIF(G13:U13,"X") -> 13 | AR13: =COUNTIF(V13:AA13,"X") -> 0 | AS13: =ROUND(COUNTIF(G13:AO13,"x"),0)+ROUND(COUNTIF(AA13:AP13,">0"),0) -> 13 | AT13: 9 | AZ13: =AY13*25000 -> 0 | BA13: =COUNTIFS($G13:$AP13,"x",$G$6:$AP$6,"A")+COUNTIFS($G13:$AP13,"xx",$G$6:$AP$6,"A") -> 0 | BB13: =COUNTIFS($G13:$AP13,"x",$G$6:$AP$6,"B")+COUNTIFS($G13:$AP13,"xx",$G$6:$AP$6,"B") -> 0 | BC13: =COUNTIFS($G13:$AP13,"x",$G$6:$AP$6,"C")+COUNTIFS($G13:$AP13,"xx",$G$6:$AP$6,"C") -> 0 | BD13: =COUNTIFS($G13:$AP13,"x",$G$6:$AP$6,"D")+COUNTIFS($G13:$AP13,"xx",$G$6:$AP$6,"D") -> 0 | BE13: =SUM(BA13:BD13) -> 0 | BF13: =IF(AS13>=13,AS13,0) -> 13
A14: 7 | B14: 1 | C14: 7 | G14: 0 | H14: x | I14: x | K14: x | L14: 0 | M14: x | N14: x | O14: x | P14: x | Q14: x | R14: x | S14: x | T14: x | U14: x | V14: x | AQ14: =COUNTIF(G14:U14,"X") -> 12 | AR14: =COUNTIF(V14:AA14,"X") -> 1 | AS14: =ROUND(COUNTIF(G14:AO14,"x"),0)+ROUND(COUNTIF(AA14:AP14,">0"),0) -> 13 | AT14: 9 | AZ14: =AY14*25000 -> 0 | BA14: =COUNTIFS($G14:$AP14,"x",$G$6:$AP$6,"A")+COUNTIFS($G14:$AP14,"xx",$G$6:$AP$6,"A") -> 0 | BB14: =COUNTIFS($G14:$AP14,"x",$G$6:$AP$6,"B")+COUNTIFS($G14:$AP14,"xx",$G$6:$AP$6,"B") -> 0 | BC14: =COUNTIFS($G14:$AP14,"x",$G$6:$AP$6,"C")+COUNTIFS($G14:$AP14,"xx",$G$6:$AP$6,"C") -> 0 | BD14: =COUNTIFS($G14:$AP14,"x",$G$6:$AP$6,"D")+COUNTIFS($G14:$AP14,"xx",$G$6:$AP$6,"D") -> 0 | BE14: =SUM(BA14:BD14) -> 0 | BF14: =IF(AS14>=13,AS14,0) -> 13
A15: 8 | B15: 1 | C15: 8 | G15: x | H15: x | I15: x | K15: x | L15: x | M15: x | N15: x | O15: x | P15: x | Q15: x | R15: x | S15: x | T15: 0 | U15: x | AQ15: =COUNTIF(G15:U15,"X") -> 13 | AR15: =COUNTIF(V15:AA15,"X") -> 0 | AS15: =ROUND(COUNTIF(G15:AO15,"x"),0)+ROUND(COUNTIF(AA15:AP15,">0"),0) -> 13 | AT15: 9 | AZ15: =AY15*25000 -> 0 | BA15: =COUNTIFS($G15:$AP15,"x",$G$6:$AP$6,"A")+COUNTIFS($G15:$AP15,"xx",$G$6:$AP$6,"A") -> 0 | BB15: =COUNTIFS($G15:$AP15,"x",$G$6:$AP$6,"B")+COUNTIFS($G15:$AP15,"xx",$G$6:$AP$6,"B") -> 0 | BC15: =COUNTIFS($G15:$AP15,"x",$G$6:$AP$6,"C")+COUNTIFS($G15:$AP15,"xx",$G$6:$AP$6,"C") -> 0 | BD15: =COUNTIFS($G15:$AP15,"x",$G$6:$AP$6,"D")+COUNTIFS($G15:$AP15,"xx",$G$6:$AP$6,"D") -> 0 | BE15: =SUM(BA15:BD15) -> 0 | BF15: =IF(AS15>=13,AS15,0) -> 13
A16: 9 | B16: 1 | C16: 9 | G16: x | H16: x | I16: x | K16: x | L16: x | M16: x | N16: 0 | O16: x | P16: x | Q16: 0 | R16: x | S16: x | T16: x | U16: x | AQ16: =COUNTIF(G16:U16,"X") -> 12 | AR16: =COUNTIF(V16:AA16,"X") -> 0 | AS16: =ROUND(COUNTIF(G16:AO16,"x"),0)+ROUND(COUNTIF(AA16:AP16,">0"),0) -> 12 | AT16: 9 | AZ16: =AY16*25000 -> 0 | BA16: =COUNTIFS($G16:$AP16,"x",$G$6:$AP$6,"A")+COUNTIFS($G16:$AP16,"xx",$G$6:$AP$6,"A") -> 0 | BB16: =COUNTIFS($G16:$AP16,"x",$G$6:$AP$6,"B")+COUNTIFS($G16:$AP16,"xx",$G$6:$AP$6,"B") -> 0 | BC16: =COUNTIFS($G16:$AP16,"x",$G$6:$AP$6,"C")+COUNTIFS($G16:$AP16,"xx",$G$6:$AP$6,"C") -> 0 | BD16: =COUNTIFS($G16:$AP16,"x",$G$6:$AP$6,"D")+COUNTIFS($G16:$AP16,"xx",$G$6:$AP$6,"D") -> 0 | BE16: =SUM(BA16:BD16) -> 0 | BF16: =IF(AS16>=13,AS16,0) -> 0
A17: 10 | B17: 1 | C17: 10 | G17: x | H17: x | I17: x | K17: 0 | L17: x | M17: x | N17: x | O17: x | P17: x | Q17: x | R17: x | S17: x | T17: x | U17: x | AQ17: =COUNTIF(G17:U17,"X") -> 13 | AR17: =COUNTIF(V17:AA17,"X") -> 0 | AS17: =ROUND(COUNTIF(G17:AO17,"x"),0)+ROUND(COUNTIF(AA17:AP17,">0"),0) -> 13 | AT17: 9 | AZ17: =AY17*25000 -> 0 | BA17: =COUNTIFS($G17:$AP17,"x",$G$6:$AP$6,"A")+COUNTIFS($G17:$AP17,"xx",$G$6:$AP$6,"A") -> 0 | BB17: =COUNTIFS($G17:$AP17,"x",$G$6:$AP$6,"B")+COUNTIFS($G17:$AP17,"xx",$G$6:$AP$6,"B") -> 0 | BC17: =COUNTIFS($G17:$AP17,"x",$G$6:$AP$6,"C")+COUNTIFS($G17:$AP17,"xx",$G$6:$AP$6,"C") -> 0 | BD17: =COUNTIFS($G17:$AP17,"x",$G$6:$AP$6,"D")+COUNTIFS($G17:$AP17,"xx",$G$6:$AP$6,"D") -> 0 | BE17: =SUM(BA17:BD17) -> 0 | BF17: =IF(AS17>=13,AS17,0) -> 13
A18: 11 | B18: 1 | C18: 11 | G18: x | H18: x | I18: 0 | K18: 0 | L18: x | M18: x | N18: x | O18: x | P18: x | Q18: x | R18: x | S18: x | T18: x | U18: x | AQ18: =COUNTIF(G18:U18,"X") -> 12 | AR18: =COUNTIF(V18:AA18,"X") -> 0 | AS18: =ROUND(COUNTIF(G18:AO18,"x"),0)+ROUND(COUNTIF(AA18:AP18,">0"),0) -> 12 | AT18: 9 | AZ18: =AY18*25000 -> 0 | BA18: =COUNTIFS($G18:$AP18,"x",$G$6:$AP$6,"A")+COUNTIFS($G18:$AP18,"xx",$G$6:$AP$6,"A") -> 0 | BB18: =COUNTIFS($G18:$AP18,"x",$G$6:$AP$6,"B")+COUNTIFS($G18:$AP18,"xx",$G$6:$AP$6,"B") -> 0 | BC18: =COUNTIFS($G18:$AP18,"x",$G$6:$AP$6,"C")+COUNTIFS($G18:$AP18,"xx",$G$6:$AP$6,"C") -> 0 | BD18: =COUNTIFS($G18:$AP18,"x",$G$6:$AP$6,"D")+COUNTIFS($G18:$AP18,"xx",$G$6:$AP$6,"D") -> 0 | BE18: =SUM(BA18:BD18) -> 0 | BF18: =IF(AS18>=13,AS18,0) -> 0
A19: 12 | B19: 1 | C19: 12 | G19: x | H19: x | I19: x | K19: x | L19: x | M19: 0 | N19: x | O19: 0 | P19: x | Q19: x | R19: x | S19: x | T19: x | U19: x | AQ19: =COUNTIF(G19:U19,"X") -> 12 | AR19: =COUNTIF(V19:AA19,"X") -> 0 | AS19: =ROUND(COUNTIF(G19:AO19,"x"),0)+ROUND(COUNTIF(AA19:AP19,">0"),0) -> 12 | AT19: 9 | AZ19: =AY19*25000 -> 0 | BA19: =COUNTIFS($G19:$AP19,"x",$G$6:$AP$6,"A")+COUNTIFS($G19:$AP19,"xx",$G$6:$AP$6,"A") -> 0 | BB19: =COUNTIFS($G19:$AP19,"x",$G$6:$AP$6,"B")+COUNTIFS($G19:$AP19,"xx",$G$6:$AP$6,"B") -> 0 | BC19: =COUNTIFS($G19:$AP19,"x",$G$6:$AP$6,"C")+COUNTIFS($G19:$AP19,"xx",$G$6:$AP$6,"C") -> 0 | BD19: =COUNTIFS($G19:$AP19,"x",$G$6:$AP$6,"D")+COUNTIFS($G19:$AP19,"xx",$G$6:$AP$6,"D") -> 0 | BE19: =SUM(BA19:BD19) -> 0 | BF19: =IF(AS19>=13,AS19,0) -> 0
A20: 13 | B20: 1 | C20: 13 | G20: 0 | H20: x | I20: x | K20: 0 | L20: x | M20: 0 | N20: x | O20: x | P20: x | Q20: x | R20: x | S20: x | T20: x | U20: x | AQ20: =COUNTIF(G20:U20,"X") -> 11 | AR20: =COUNTIF(V20:AA20,"X") -> 0 | AS20: =ROUND(COUNTIF(G20:AO20,"x"),0)+ROUND(COUNTIF(AA20:AP20,">0"),0) -> 11 | AT20: 9 | AZ20: =AY20*25000 -> 0 | BA20: =COUNTIFS($G20:$AP20,"x",$G$6:$AP$6,"A")+COUNTIFS($G20:$AP20,"xx",$G$6:$AP$6,"A") -> 0 | BB20: =COUNTIFS($G20:$AP20,"x",$G$6:$AP$6,"B")+COUNTIFS($G20:$AP20,"xx",$G$6:$AP$6,"B") -> 0 | BC20: =COUNTIFS($G20:$AP20,"x",$G$6:$AP$6,"C")+COUNTIFS($G20:$AP20,"xx",$G$6:$AP$6,"C") -> 0 | BD20: =COUNTIFS($G20:$AP20,"x",$G$6:$AP$6,"D")+COUNTIFS($G20:$AP20,"xx",$G$6:$AP$6,"D") -> 0 | BE20: =SUM(BA20:BD20) -> 0 | BF20: =IF(AS20>=13,AS20,0) -> 0
A21: 14 | B21: 1 | C21: 14 | G21: 0 | H21: 0 | I21: x | K21: 0 | L21: 0 | M21: x | N21: x | O21: x | P21: x | Q21: x | R21: x | S21: x | T21: x | U21: x | AQ21: =COUNTIF(G21:U21,"X") -> 10 | AR21: =COUNTIF(V21:AA21,"X") -> 0 | AS21: =ROUND(COUNTIF(G21:AO21,"x"),0)+ROUND(COUNTIF(AA21:AP21,">0"),0) -> 10 | AT21: 9 | AZ21: =AY21*25000 -> 0 | BA21: =COUNTIFS($G21:$AP21,"x",$G$6:$AP$6,"A")+COUNTIFS($G21:$AP21,"xx",$G$6:$AP$6,"A") -> 0 | BB21: =COUNTIFS($G21:$AP21,"x",$G$6:$AP$6,"B")+COUNTIFS($G21:$AP21,"xx",$G$6:$AP$6,"B") -> 0 | BC21: =COUNTIFS($G21:$AP21,"x",$G$6:$AP$6,"C")+COUNTIFS($G21:$AP21,"xx",$G$6:$AP$6,"C") -> 0 | BD21: =COUNTIFS($G21:$AP21,"x",$G$6:$AP$6,"D")+COUNTIFS($G21:$AP21,"xx",$G$6:$AP$6,"D") -> 0 | BE21: =SUM(BA21:BD21) -> 0 | BF21: =IF(AS21>=13,AS21,0) -> 0
A22: 15 | B22: 1 | C22: 15 | G22: 0 | H22: 0 | I22: x | K22: x | L22: x | M22: x | N22: x | O22: x | P22: x | Q22: x | R22: x | S22: x | T22: x | U22: x | AQ22: =COUNTIF(G22:U22,"X") -> 12 | AR22: =COUNTIF(V22:AA22,"X") -> 0 | AS22: =ROUND(COUNTIF(G22:AO22,"x"),0)+ROUND(COUNTIF(AA22:AP22,">0"),0) -> 12 | AT22: 9 | AZ22: =AY22*25000 -> 0 | BA22: =COUNTIFS($G22:$AP22,"x",$G$6:$AP$6,"A")+COUNTIFS($G22:$AP22,"xx",$G$6:$AP$6,"A") -> 0 | BB22: =COUNTIFS($G22:$AP22,"x",$G$6:$AP$6,"B")+COUNTIFS($G22:$AP22,"xx",$G$6:$AP$6,"B") -> 0 | BC22: =COUNTIFS($G22:$AP22,"x",$G$6:$AP$6,"C")+COUNTIFS($G22:$AP22,"xx",$G$6:$AP$6,"C") -> 0 | BD22: =COUNTIFS($G22:$AP22,"x",$G$6:$AP$6,"D")+COUNTIFS($G22:$AP22,"xx",$G$6:$AP$6,"D") -> 0 | BE22: =SUM(BA22:BD22) -> 0 | BF22: =IF(AS22>=13,AS22,0) -> 0
A23: 16 | B23: 1 | C23: 16 | G23: 0 | H23: 0 | I23: x | K23: x | L23: x | M23: x | N23: x | O23: x | P23: x | Q23: x | R23: x | S23: x | T23: x | U23: x | X23: x | AQ23: =COUNTIF(G23:U23,"X") -> 12 | AR23: =COUNTIF(V23:AA23,"X") -> 1 | AS23: =ROUND(COUNTIF(G23:AO23,"x"),0)+ROUND(COUNTIF(AA23:AP23,">0"),0) -> 13 | AT23: 9 | AZ23: =AY23*25000 -> 0 | BA23: =COUNTIFS($G23:$AP23,"x",$G$6:$AP$6,"A")+COUNTIFS($G23:$AP23,"xx",$G$6:$AP$6,"A") -> 0 | BB23: =COUNTIFS($G23:$AP23,"x",$G$6:$AP$6,"B")+COUNTIFS($G23:$AP23,"xx",$G$6:$AP$6,"B") -> 0 | BC23: =COUNTIFS($G23:$AP23,"x",$G$6:$AP$6,"C")+COUNTIFS($G23:$AP23,"xx",$G$6:$AP$6,"C") -> 0 | BD23: =COUNTIFS($G23:$AP23,"x",$G$6:$AP$6,"D")+COUNTIFS($G23:$AP23,"xx",$G$6:$AP$6,"D") -> 0 | BE23: =SUM(BA23:BD23) -> 0 | BF23: =IF(AS23>=13,AS23,0) -> 13
A24: 17 | B24: 1 | C24: 17 | G24: 0 | H24: x | I24: x | K24: x | L24: x | M24: 0 | N24: x | O24: x | P24: x | Q24: x | R24: x | S24: x | T24: x | U24: 0 | AQ24: =COUNTIF(G24:U24,"X") -> 11 | AR24: =COUNTIF(V24:AA24,"X") -> 0 | AS24: =ROUND(COUNTIF(G24:AO24,"x"),0)+ROUND(COUNTIF(AA24:AP24,">0"),0) -> 11 | AT24: 9 | AZ24: =AY24*25000 -> 0 | BA24: =COUNTIFS($G24:$AP24,"x",$G$6:$AP$6,"A")+COUNTIFS($G24:$AP24,"xx",$G$6:$AP$6,"A") -> 0 | BB24: =COUNTIFS($G24:$AP24,"x",$G$6:$AP$6,"B")+COUNTIFS($G24:$AP24,"xx",$G$6:$AP$6,"B") -> 0 | BC24: =COUNTIFS($G24:$AP24,"x",$G$6:$AP$6,"C")+COUNTIFS($G24:$AP24,"xx",$G$6:$AP$6,"C") -> 0 | BD24: =COUNTIFS($G24:$AP24,"x",$G$6:$AP$6,"D")+COUNTIFS($G24:$AP24,"xx",$G$6:$AP$6,"D") -> 0 | BE24: =SUM(BA24:BD24) -> 0 | BF24: =IF(AS24>=13,AS24,0) -> 0
A25: 18 | B25: 1 | C25: 18 | G25: 0 | H25: x | I25: x | K25: 0 | L25: x | M25: x | N25: 0 | O25: x | P25: x | Q25: x | R25: x | S25: x | T25: x | U25: x | AQ25: =COUNTIF(G25:U25,"X") -> 11 | AR25: =COUNTIF(V25:AA25,"X") -> 0 | AS25: =ROUND(COUNTIF(G25:AO25,"x"),0)+ROUND(COUNTIF(AA25:AP25,">0"),0) -> 11 | AT25: 8 | AZ25: =AY25*25000 -> 0 | BA25: =COUNTIFS($G25:$AP25,"x",$G$6:$AP$6,"A")+COUNTIFS($G25:$AP25,"xx",$G$6:$AP$6,"A") -> 0 | BB25: =COUNTIFS($G25:$AP25,"x",$G$6:$AP$6,"B")+COUNTIFS($G25:$AP25,"xx",$G$6:$AP$6,"B") -> 0 | BC25: =COUNTIFS($G25:$AP25,"x",$G$6:$AP$6,"C")+COUNTIFS($G25:$AP25,"xx",$G$6:$AP$6,"C") -> 0 | BD25: =COUNTIFS($G25:$AP25,"x",$G$6:$AP$6,"D")+COUNTIFS($G25:$AP25,"xx",$G$6:$AP$6,"D") -> 0 | BE25: =SUM(BA25:BD25) -> 0 | BF25: =IF(AS25>=13,AS25,0) -> 0
A26: 19 | B26: 1 | C26: 19 | G26: 0 | H26: 0 | I26: x | K26: x | L26: x | M26: x | N26: x | O26: x | P26: x | Q26: x | R26: x | S26: x | T26: x | U26: x | AQ26: =COUNTIF(G26:U26,"X") -> 12 | AR26: =COUNTIF(V26:AA26,"X") -> 0 | AS26: =ROUND(COUNTIF(G26:AO26,"x"),0)+ROUND(COUNTIF(AA26:AP26,">0"),0) -> 12 | AT26: 9 | AZ26: =AY26*25000 -> 0 | BA26: =COUNTIFS($G26:$AP26,"x",$G$6:$AP$6,"A")+COUNTIFS($G26:$AP26,"xx",$G$6:$AP$6,"A") -> 0 | BB26: =COUNTIFS($G26:$AP26,"x",$G$6:$AP$6,"B")+COUNTIFS($G26:$AP26,"xx",$G$6:$AP$6,"B") -> 0 | BC26: =COUNTIFS($G26:$AP26,"x",$G$6:$AP$6,"C")+COUNTIFS($G26:$AP26,"xx",$G$6:$AP$6,"C") -> 0 | BD26: =COUNTIFS($G26:$AP26,"x",$G$6:$AP$6,"D")+COUNTIFS($G26:$AP26,"xx",$G$6:$AP$6,"D") -> 0 | BE26: =SUM(BA26:BD26) -> 0 | BF26: =IF(AS26>=13,AS26,0) -> 0
A27: 20 | B27: 1 | C27: 20 | G27: x | H27: x | I27: x | J27: x | K27: 0 | L27: x | M27: x | N27: x | O27: x | P27: x | Q27: x | R27: x | S27: 0 | T27: x | U27: x | AQ27: =COUNTIF(G27:U27,"X") -> 13 | AR27: =COUNTIF(V27:AA27,"X") -> 0 | AS27: =ROUND(COUNTIF(G27:AO27,"x"),0)+ROUND(COUNTIF(AA27:AP27,">0"),0) -> 13 | AT27: 9 | AZ27: =AY27*25000 -> 0 | BA27: =COUNTIFS($G27:$AP27,"x",$G$6:$AP$6,"A")+COUNTIFS($G27:$AP27,"xx",$G$6:$AP$6,"A") -> 0 | BB27: =COUNTIFS($G27:$AP27,"x",$G$6:$AP$6,"B")+COUNTIFS($G27:$AP27,"xx",$G$6:$AP$6,"B") -> 0 | BC27: =COUNTIFS($G27:$AP27,"x",$G$6:$AP$6,"C")+COUNTIFS($G27:$AP27,"xx",$G$6:$AP$6,"C") -> 0 | BD27: =COUNTIFS($G27:$AP27,"x",$G$6:$AP$6,"D")+COUNTIFS($G27:$AP27,"xx",$G$6:$AP$6,"D") -> 0 | BE27: =SUM(BA27:BD27) -> 0 | BF27: =IF(AS27>=13,AS27,0) -> 13
A28: 21 | B28: 1 | C28: 21 | G28: x | H28: 0 | I28: x | K28: x | L28: x | M28: x | N28: x | O28: x | P28: x | Q28: x | R28: x | S28: x | T28: x | U28: x | AQ28: =COUNTIF(G28:U28,"X") -> 13 | AR28: =COUNTIF(V28:AA28,"X") -> 0 | AS28: =ROUND(COUNTIF(G28:AO28,"x"),0)+ROUND(COUNTIF(AA28:AP28,">0"),0) -> 13 | AT28: 9 | AZ28: =AY28*25000 -> 0 | BA28: =COUNTIFS($G28:$AP28,"x",$G$6:$AP$6,"A")+COUNTIFS($G28:$AP28,"xx",$G$6:$AP$6,"A") -> 0 | BB28: =COUNTIFS($G28:$AP28,"x",$G$6:$AP$6,"B")+COUNTIFS($G28:$AP28,"xx",$G$6:$AP$6,"B") -> 0 | BC28: =COUNTIFS($G28:$AP28,"x",$G$6:$AP$6,"C")+COUNTIFS($G28:$AP28,"xx",$G$6:$AP$6,"C") -> 0 | BD28: =COUNTIFS($G28:$AP28,"x",$G$6:$AP$6,"D")+COUNTIFS($G28:$AP28,"xx",$G$6:$AP$6,"D") -> 0 | BE28: =SUM(BA28:BD28) -> 0 | BF28: =IF(AS28>=13,AS28,0) -> 13
A29: 22 | B29: 1 | C29: 22 | G29: 0 | H29: x | I29: x | K29: x | L29: 0 | M29: x | N29: x | O29: 0 | P29: 0 | Q29: 0 | R29: 0 | S29: 0 | T29: 0 | U29: 0 | AQ29: =COUNTIF(G29:U29,"X") -> 5 | AR29: =COUNTIF(V29:AA29,"X") -> 0 | AS29: =ROUND(COUNTIF(G29:AO29,"x"),0)+ROUND(COUNTIF(AA29:AP29,">0"),0) -> 5 | AT29: 9 | AZ29: =AY29*25000 -> 0 | BA29: =COUNTIFS($G29:$AP29,"x",$G$6:$AP$6,"A")+COUNTIFS($G29:$AP29,"xx",$G$6:$AP$6,"A") -> 0 | BB29: =COUNTIFS($G29:$AP29,"x",$G$6:$AP$6,"B")+COUNTIFS($G29:$AP29,"xx",$G$6:$AP$6,"B") -> 0 | BC29: =COUNTIFS($G29:$AP29,"x",$G$6:$AP$6,"C")+COUNTIFS($G29:$AP29,"xx",$G$6:$AP$6,"C") -> 0 | BD29: =COUNTIFS($G29:$AP29,"x",$G$6:$AP$6,"D")+COUNTIFS($G29:$AP29,"xx",$G$6:$AP$6,"D") -> 0 | BE29: =SUM(BA29:BD29) -> 0 | BF29: =IF(AS29>=13,AS29,0) -> 0
A30: 23 | B30: 1 | C30: 23 | G30: 0 | H30: x | I30: x | K30: x | L30: x | M30: x | N30: x | O30: x | P30: x | Q30: x | R30: x | S30: x | T30: x | U30: x | AQ30: =COUNTIF(G30:U30,"X") -> 13 | AR30: =COUNTIF(V30:AA30,"X") -> 0 | AS30: =ROUND(COUNTIF(G30:AO30,"x"),0)+ROUND(COUNTIF(AA30:AP30,">0"),0) -> 13 | AT30: 9 | AZ30: =AY30*25000 -> 0 | BA30: =COUNTIFS($G30:$AP30,"x",$G$6:$AP$6,"A")+COUNTIFS($G30:$AP30,"xx",$G$6:$AP$6,"A") -> 0 | BB30: =COUNTIFS($G30:$AP30,"x",$G$6:$AP$6,"B")+COUNTIFS($G30:$AP30,"xx",$G$6:$AP$6,"B") -> 0 | BC30: =COUNTIFS($G30:$AP30,"x",$G$6:$AP$6,"C")+COUNTIFS($G30:$AP30,"xx",$G$6:$AP$6,"C") -> 0 | BD30: =COUNTIFS($G30:$AP30,"x",$G$6:$AP$6,"D")+COUNTIFS($G30:$AP30,"xx",$G$6:$AP$6,"D") -> 0 | BE30: =SUM(BA30:BD30) -> 0 | BF30: =IF(AS30>=13,AS30,0) -> 13
A31: 24 | B31: 1 | C31: 24 | G31: x | H31: x | I31: x | K31: x | L31: x | M31: x | N31: x | O31: x | P31: x | Q31: x | R31: x | S31: x | T31: x | U31: x | V31: x | X31: x | AQ31: =COUNTIF(G31:U31,"X") -> 14 | AR31: =COUNTIF(V31:AA31,"X") -> 2 | AS31: =ROUND(COUNTIF(G31:AO31,"x"),0)+ROUND(COUNTIF(AA31:AP31,">0"),0) -> 16 | AT31: 9 | AZ31: =AY31*25000 -> 0 | BA31: =COUNTIFS($G31:$AP31,"x",$G$6:$AP$6,"A")+COUNTIFS($G31:$AP31,"xx",$G$6:$AP$6,"A") -> 0 | BB31: =COUNTIFS($G31:$AP31,"x",$G$6:$AP$6,"B")+COUNTIFS($G31:$AP31,"xx",$G$6:$AP$6,"B") -> 0 | BC31: =COUNTIFS($G31:$AP31,"x",$G$6:$AP$6,"C")+COUNTIFS($G31:$AP31,"xx",$G$6:$AP$6,"C") -> 0 | BD31: =COUNTIFS($G31:$AP31,"x",$G$6:$AP$6,"D")+COUNTIFS($G31:$AP31,"xx",$G$6:$AP$6,"D") -> 0 | BE31: =SUM(BA31:BD31) -> 0 | BF31: =IF(AS31>=13,AS31,0) -> 16
A32: 25 | B32: 1 | C32: 25 | G32: 0 | H32: x | I32: x | K32: x | L32: x | M32: x | N32: x | O32: x | P32: x | Q32: x | R32: x | S32: x | T32: x | U32: x | V32: x | AQ32: =COUNTIF(G32:U32,"X") -> 13 | AR32: =COUNTIF(V32:AA32,"X") -> 1 | AS32: =ROUND(COUNTIF(G32:AO32,"x"),0)+ROUND(COUNTIF(AA32:AP32,">0"),0) -> 14 | AT32: 9 | AZ32: =AY32*25000 -> 0 | BA32: =COUNTIFS($G32:$AP32,"x",$G$6:$AP$6,"A")+COUNTIFS($G32:$AP32,"xx",$G$6:$AP$6,"A") -> 0 | BB32: =COUNTIFS($G32:$AP32,"x",$G$6:$AP$6,"B")+COUNTIFS($G32:$AP32,"xx",$G$6:$AP$6,"B") -> 0 | BC32: =COUNTIFS($G32:$AP32,"x",$G$6:$AP$6,"C")+COUNTIFS($G32:$AP32,"xx",$G$6:$AP$6,"C") -> 0 | BD32: =COUNTIFS($G32:$AP32,"x",$G$6:$AP$6,"D")+COUNTIFS($G32:$AP32,"xx",$G$6:$AP$6,"D") -> 0 | BE32: =SUM(BA32:BD32) -> 0 | BF32: =IF(AS32>=13,AS32,0) -> 14
A33: 26 | B33: 1 | C33: 26 | G33: 0 | H33: x | I33: x | K33: x | L33: x | M33: x | N33: x | O33: x | P33: x | Q33: x | R33: x | S33: x | T33: x | U33: x | V33: x | AQ33: =COUNTIF(G33:U33,"X") -> 13 | AR33: =COUNTIF(V33:AA33,"X") -> 1 | AS33: =ROUND(COUNTIF(G33:AO33,"x"),0)+ROUND(COUNTIF(AA33:AP33,">0"),0) -> 14 | AT33: 9 | AZ33: =AY33*25000 -> 0 | BA33: =COUNTIFS($G33:$AP33,"x",$G$6:$AP$6,"A")+COUNTIFS($G33:$AP33,"xx",$G$6:$AP$6,"A") -> 0 | BB33: =COUNTIFS($G33:$AP33,"x",$G$6:$AP$6,"B")+COUNTIFS($G33:$AP33,"xx",$G$6:$AP$6,"B") -> 0 | BC33: =COUNTIFS($G33:$AP33,"x",$G$6:$AP$6,"C")+COUNTIFS($G33:$AP33,"xx",$G$6:$AP$6,"C") -> 0 | BD33: =COUNTIFS($G33:$AP33,"x",$G$6:$AP$6,"D")+COUNTIFS($G33:$AP33,"xx",$G$6:$AP$6,"D") -> 0 | BE33: =SUM(BA33:BD33) -> 0 | BF33: =IF(AS33>=13,AS33,0) -> 14
A34: 27 | B34: 1 | C34: 27 | G34: 0 | H34: x | I34: x | K34: x | L34: x | M34: x | N34: 0 | O34: x | P34: x | Q34: x | R34: x | S34: x | T34: x | U34: x | V34: x | AQ34: =COUNTIF(G34:U34,"X") -> 12 | AR34: =COUNTIF(V34:AA34,"X") -> 1 | AS34: =ROUND(COUNTIF(G34:AO34,"x"),0)+ROUND(COUNTIF(AA34:AP34,">0"),0) -> 13 | AT34: 9 | AZ34: =AY34*25000 -> 0 | BA34: =COUNTIFS($G34:$AP34,"x",$G$6:$AP$6,"A")+COUNTIFS($G34:$AP34,"xx",$G$6:$AP$6,"A") -> 0 | BB34: =COUNTIFS($G34:$AP34,"x",$G$6:$AP$6,"B")+COUNTIFS($G34:$AP34,"xx",$G$6:$AP$6,"B") -> 0 | BC34: =COUNTIFS($G34:$AP34,"x",$G$6:$AP$6,"C")+COUNTIFS($G34:$AP34,"xx",$G$6:$AP$6,"C") -> 0 | BD34: =COUNTIFS($G34:$AP34,"x",$G$6:$AP$6,"D")+COUNTIFS($G34:$AP34,"xx",$G$6:$AP$6,"D") -> 0 | BE34: =SUM(BA34:BD34) -> 0 | BF34: =IF(AS34>=13,AS34,0) -> 13
A35: 28 | B35: 1 | C35: 28 | G35: x | H35: x | I35: x | K35: x | L35: x | M35: 0 | N35: x | O35: x | P35: x | Q35: x | R35: x | S35: x | T35: x | U35: x | AQ35: =COUNTIF(G35:U35,"X") -> 13 | AR35: =COUNTIF(V35:AA35,"X") -> 0 | AS35: =ROUND(COUNTIF(G35:AO35,"x"),0)+ROUND(COUNTIF(AA35:AP35,">0"),0) -> 13 | AT35: 9 | AZ35: =AY35*25000 -> 0 | BA35: =COUNTIFS($G35:$AP35,"x",$G$6:$AP$6,"A")+COUNTIFS($G35:$AP35,"xx",$G$6:$AP$6,"A") -> 0 | BB35: =COUNTIFS($G35:$AP35,"x",$G$6:$AP$6,"B")+COUNTIFS($G35:$AP35,"xx",$G$6:$AP$6,"B") -> 0 | BC35: =COUNTIFS($G35:$AP35,"x",$G$6:$AP$6,"C")+COUNTIFS($G35:$AP35,"xx",$G$6:$AP$6,"C") -> 0 | BD35: =COUNTIFS($G35:$AP35,"x",$G$6:$AP$6,"D")+COUNTIFS($G35:$AP35,"xx",$G$6:$AP$6,"D") -> 0 | BE35: =SUM(BA35:BD35) -> 0 | BF35: =IF(AS35>=13,AS35,0) -> 13
A36: 29 | B36: 1 | C36: 29 | G36: x | H36: x | I36: 0 | K36: x | L36: 0 | M36: x | N36: x | O36: x | P36: x | Q36: x | R36: x | S36: x | T36: 0 | U36: x | AQ36: =COUNTIF(G36:U36,"X") -> 11 | AR36: =COUNTIF(V36:AA36,"X") -> 0 | AS36: =ROUND(COUNTIF(G36:AO36,"x"),0)+ROUND(COUNTIF(AA36:AP36,">0"),0) -> 11 | AT36: 9 | AZ36: =AY36*25000 -> 0 | BA36: =COUNTIFS($G36:$AP36,"x",$G$6:$AP$6,"A")+COUNTIFS($G36:$AP36,"xx",$G$6:$AP$6,"A") -> 0 | BB36: =COUNTIFS($G36:$AP36,"x",$G$6:$AP$6,"B")+COUNTIFS($G36:$AP36,"xx",$G$6:$AP$6,"B") -> 0 | BC36: =COUNTIFS($G36:$AP36,"x",$G$6:$AP$6,"C")+COUNTIFS($G36:$AP36,"xx",$G$6:$AP$6,"C") -> 0 | BD36: =COUNTIFS($G36:$AP36,"x",$G$6:$AP$6,"D")+COUNTIFS($G36:$AP36,"xx",$G$6:$AP$6,"D") -> 0 | BE36: =SUM(BA36:BD36) -> 0 | BF36: =IF(AS36>=13,AS36,0) -> 0
A37: 30 | B37: 1 | C37: 30 | G37: x | H37: x | I37: x | K37: x | L37: x | M37: x | N37: x | O37: x | P37: x | Q37: x | R37: x | S37: x | T37: x | U37: x | AQ37: =COUNTIF(G37:U37,"X") -> 14 | AR37: =COUNTIF(V37:AA37,"X") -> 0 | AS37: =ROUND(COUNTIF(G37:AO37,"x"),0)+ROUND(COUNTIF(AA37:AP37,">0"),0) -> 14 | AT37: 9 | AZ37: =AY37*25000 -> 0 | BA37: =COUNTIFS($G37:$AP37,"x",$G$6:$AP$6,"A")+COUNTIFS($G37:$AP37,"xx",$G$6:$AP$6,"A") -> 0 | BB37: =COUNTIFS($G37:$AP37,"x",$G$6:$AP$6,"B")+COUNTIFS($G37:$AP37,"xx",$G$6:$AP$6,"B") -> 0 | BC37: =COUNTIFS($G37:$AP37,"x",$G$6:$AP$6,"C")+COUNTIFS($G37:$AP37,"xx",$G$6:$AP$6,"C") -> 0 | BD37: =COUNTIFS($G37:$AP37,"x",$G$6:$AP$6,"D")+COUNTIFS($G37:$AP37,"xx",$G$6:$AP$6,"D") -> 0 | BE37: =SUM(BA37:BD37) -> 0 | BF37: =IF(AS37>=13,AS37,0) -> 14
A38: 31 | B38: 1 | C38: 31 | G38: x | H38: 0 | I38: x | K38: x | L38: x | M38: x | N38: x | O38: x | P38: x | Q38: x | R38: x | S38: x | T38: x | U38: x | AQ38: =COUNTIF(G38:U38,"X") -> 13 | AR38: =COUNTIF(V38:AA38,"X") -> 0 | AS38: =ROUND(COUNTIF(G38:AO38,"x"),0)+ROUND(COUNTIF(AA38:AP38,">0"),0) -> 13 | AT38: 9 | AZ38: =AY38*25000 -> 0 | BA38: =COUNTIFS($G38:$AP38,"x",$G$6:$AP$6,"A")+COUNTIFS($G38:$AP38,"xx",$G$6:$AP$6,"A") -> 0 | BB38: =COUNTIFS($G38:$AP38,"x",$G$6:$AP$6,"B")+COUNTIFS($G38:$AP38,"xx",$G$6:$AP$6,"B") -> 0 | BC38: =COUNTIFS($G38:$AP38,"x",$G$6:$AP$6,"C")+COUNTIFS($G38:$AP38,"xx",$G$6:$AP$6,"C") -> 0 | BD38: =COUNTIFS($G38:$AP38,"x",$G$6:$AP$6,"D")+COUNTIFS($G38:$AP38,"xx",$G$6:$AP$6,"D") -> 0 | BE38: =SUM(BA38:BD38) -> 0 | BF38: =IF(AS38>=13,AS38,0) -> 13
A39: 32 | B39: 1 | C39: 32 | G39: x | H39: x | I39: x | K39: x | L39: x | M39: x | N39: x | O39: x | P39: x | Q39: x | R39: x | S39: x | T39: x | U39: x | AQ39: =COUNTIF(G39:U39,"X") -> 14 | AR39: =COUNTIF(V39:AA39,"X") -> 0 | AS39: =ROUND(COUNTIF(G39:AO39,"x"),0)+ROUND(COUNTIF(AA39:AP39,">0"),0) -> 14 | AT39: 9 | AZ39: =AY39*25000 -> 0 | BA39: =COUNTIFS($G39:$AP39,"x",$G$6:$AP$6,"A")+COUNTIFS($G39:$AP39,"xx",$G$6:$AP$6,"A") -> 0 | BB39: =COUNTIFS($G39:$AP39,"x",$G$6:$AP$6,"B")+COUNTIFS($G39:$AP39,"xx",$G$6:$AP$6,"B") -> 0 | BC39: =COUNTIFS($G39:$AP39,"x",$G$6:$AP$6,"C")+COUNTIFS($G39:$AP39,"xx",$G$6:$AP$6,"C") -> 0 | BD39: =COUNTIFS($G39:$AP39,"x",$G$6:$AP$6,"D")+COUNTIFS($G39:$AP39,"xx",$G$6:$AP$6,"D") -> 0 | BE39: =SUM(BA39:BD39) -> 0 | BF39: =IF(AS39>=13,AS39,0) -> 14
A40: 33 | B40: 1 | C40: 33 | G40: x | H40: x | I40: x | K40: x | L40: x | M40: x | N40: x | O40: x | P40: x | Q40: x | R40: x | S40: x | T40: x | U40: x | AQ40: =COUNTIF(G40:U40,"X") -> 14 | AR40: =COUNTIF(V40:AA40,"X") -> 0 | AS40: =ROUND(COUNTIF(G40:AO40,"x"),0)+ROUND(COUNTIF(AA40:AP40,">0"),0) -> 14 | AT40: 9 | AZ40: =AY40*25000 -> 0 | BA40: =COUNTIFS($G40:$AP40,"x",$G$6:$AP$6,"A")+COUNTIFS($G40:$AP40,"xx",$G$6:$AP$6,"A") -> 0 | BB40: =COUNTIFS($G40:$AP40,"x",$G$6:$AP$6,"B")+COUNTIFS($G40:$AP40,"xx",$G$6:$AP$6,"B") -> 0 | BC40: =COUNTIFS($G40:$AP40,"x",$G$6:$AP$6,"C")+COUNTIFS($G40:$AP40,"xx",$G$6:$AP$6,"C") -> 0 | BD40: =COUNTIFS($G40:$AP40,"x",$G$6:$AP$6,"D")+COUNTIFS($G40:$AP40,"xx",$G$6:$AP$6,"D") -> 0 | BE40: =SUM(BA40:BD40) -> 0 | BF40: =IF(AS40>=13,AS40,0) -> 14
...

Sheet SAN LUONG
AE1: CẠO ÚP | AF1: 555 | AI1: 2011 | AJ1: =SUM(AQ2:AQ4) -> 0 | AM1: A | AN1: B | AO1: C | AP1: D | AQ1: TỔNG CỘNG
G2: A | H2: B | I2: C | M2: A | N2: B | O2: C | AE2: CẠO NGỮA | AF2: 455 | AI2: 2012 | AJ2: =SUM(AQ5:AQ6)+AQ9 -> 0 | AL2: Tổ 1 | AQ2: =SUM(AM2:AP2) -> 0
G3: TỔ 1 | P3: TỔ 1 | AE3: CẠO THẤP | AF3: 505 | AI3: 2013 | AJ3: =SUM(AQ7:AQ8) -> 455 | AL3: Tổ 2 | AQ3: =SUM(AM3:AP3) -> 0
AJ4: =SUM(AJ1:AJ3) -> 455 | AL4: Tổ 3 | AQ4: =SUM(AM4:AP4) -> 0
A5: SẢN LƯỢNG THÁNG 01/2026 đợt 1 | AL5: Tổ 4 | AQ5: =SUM(AM5:AP5) -> 0
C6: 1 | D6: 2 | E6: 3 | F6: 4 | G6: 5 | H6: 6 | I6: 7 | J6: 8 | K6: 9 | L6: 10 | M6: 11 | N6: 12 | O6: 13 | P6: 14 | Q6: 15 | R6: 30 | S6: 17 | T6: 18 | U6: 19 | V6: 20 | W6: =W499/2 -> 288490.5 | X6: 100 | Y6: 480 | AA6: Công đợt I | AE6: quy khô | AF6: Sản lượng đợt I | AJ6: =AJ8+AJ177+#REF!+#REF!+#REF!+#REF!+#REF!+#REF! -> #REF! | AL6: Tổ 5 | AQ6: =SUM(AM6:AP6) -> 0
A7: STT | H7: B-D | I7: C-A | J7: D-B | K7: A-C | P7: B-D | Q7: C-A | W7: TỔNG CỘNG | AA7: A | AB7: B | AC7: C | AD7: D | AF7: A | AG7: B | AH7: C | AI7: D | AL7: Tổ 6 | AQ7: =SUM(AM7:AP7) -> 0
B8: GA 1 | C8: =SUM(C9:C175) -> 0 | D8: =SUM(D9:D175) -> 0 | E8: =SUM(E9:E175) -> 0 | F8: =SUM(F9:F175) -> 0 | G8: =SUM(G9:G175) -> 6771 | H8: =SUM(H9:H175) -> 29941 | I8: =SUM(I9:I175) -> 21584 | J8: =SUM(J9:J175) -> 23636 | ... AJ8: =SUM(AJ9:AJ175) -> 182708 | AK8: TỔ 1 | AL8: Tổ 7 | AQ8: 455 | AU8: =SUM(AU9:AU175) -> 0
A9: 1 | B9: 1 | G9: 0 | H9: 171 | I9: 98 | M9: 67 | N9: 204 | O9: 177 | W9: =SUM(C9:V9) -> 717 | Y9: =W9-X9 -> 717 | AA9: =K9 -> 0 | AB9: =L9 -> 0 | AC9: ='CHAM CONG'!BC8 -> 0 | AD9: ='CHAM CONG'!BD8 -> 0 | AE9: =ROUND(W9*0.44,2) -> 315.48 | AF9: =G9+M9 -> 67 | AG9: =H9+N9 -> 375 | AH9: =I9+O9 -> 275 | AJ9: =SUM(AF9:AI9) -> 717 | AK9: =SUM(AJ9:AJ55) -> 48462 | AL9: Tổ 8 | AQ9: =SUM(AM9:AP9) -> 0 | AU9: =SUM(AS9:AT9)/10 -> 0
A10: 2 | B10: 1 | G10: 64 | H10: 206 | I10: 161 | M10: 172 | N10: 229 | O10: 203 | W10: =SUM(C10:V10) -> 1035 | Y10: =W10-X10 -> 1035 | AA10: ='CHAM CONG'!BA9 -> 0 | AB10: ='CHAM CONG'!BB9 -> 0 | AC10: ='CHAM CONG'!BC9 -> 0 | AD10: ='CHAM CONG'!BD9 -> 0 | AE10: =ROUND(W10*0.44,2) -> 455.4 | AF10: =G10+M10 -> 236 | AG10: =H10+N10 -> 435 | AH10: =I10+O10 -> 364 | AJ10: =SUM(AF10:AI10) -> 1035 | AL10: Tổ 9 | AQ10: =SUM(AM10:AP10) -> 0 | AU10: =SUM(AS10:AT10)/10 -> 0
A11: 3 | B11: 1 | G11: 170 | H11: 211 | I11: 258 | M11: 171 | N11: 252 | O11: 211 | W11: =SUM(C11:V11) -> 1273 | Y11: =W11-X11 -> 1273 | AA11: ='CHAM CONG'!BA10 -> 0 | AB11: ='CHAM CONG'!BB10 -> 0 | AC11: ='CHAM CONG'!BC10 -> 0 | AD11: ='CHAM CONG'!BD10 -> 0 | AE11: =ROUND(W11*0.44,2) -> 560.12 | AF11: =G11+M11 -> 341 | AG11: =H11+N11 -> 463 | AH11: =I11+O11 -> 469 | AJ11: =SUM(AF11:AI11) -> 1273 | AL11: Tổ 10 | AQ11: =SUM(AM11:AP11) -> 0 | AU11: =SUM(AS11:AT11)/10 -> 0
A12: 4 | B12: 1 | G12: 72 | H12: 168 | I12: 182 | M12: 167 | N12: 209 | O12: 172 | W12: =SUM(C12:V12) -> 970 | Y12: =W12-X12 -> 970 | AA12: ='CHAM CONG'!BA11 -> 0 | AB12: ='CHAM CONG'!BB11 -> 0 | AC12: ='CHAM CONG'!BC11 -> 0 | AD12: ='CHAM CONG'!BD11 -> 0 | AE12: =ROUND(W12*0.44,2) -> 426.8 | AF12: =G12+M12 -> 239 | AG12: =H12+N12 -> 377 | AH12: =I12+O12 -> 354 | AJ12: =SUM(AF12:AI12) -> 970 | AL12: Tổ 11 | AQ12: =SUM(AM12:AP12) -> 0 | AU12: =SUM(AS12:AT12)/10 -> 0
A13: 5 | B13: 1 | G13: 177 | H13: 203 | I13: 206 | M13: 176 | N13: 196 | O13: 227 | W13: =SUM(C13:V13) -> 1185 | Y13: =W13-X13 -> 1185 | AA13: ='CHAM CONG'!BA12 -> 0 | AB13: ='CHAM CONG'!BB12 -> 0 | AC13: ='CHAM CONG'!BC12 -> 0 | AD13: ='CHAM CONG'!BD12 -> 0 | AE13: =ROUND(W13*0.44,2) -> 521.4 | AF13: =G13+M13 -> 353 | AG13: =H13+N13 -> 399 | AH13: =I13+O13 -> 433 | AJ13: =SUM(AF13:AI13) -> 1185 | AQ13: =SUM(AQ2:AQ12) -> 455 | AU13: =SUM(AS13:AT13)/10 -> 0
A14: 6 | B14: 1 | G14: 173 | H14: 223 | I14: 95 | M14: 171 | N14: 251 | O14: 223 | W14: =SUM(C14:V14) -> 1136 | Y14: =W14-X14 -> 1136 | AA14: ='CHAM CONG'!BA13 -> 0 | AB14: ='CHAM CONG'!BB13 -> 0 | AC14: ='CHAM CONG'!BC13 -> 0 | AD14: ='CHAM CONG'!BD13 -> 0 | AE14: =ROUND(W14*0.44,2) -> 499.84 | AF14: =G14+M14 -> 344 | AG14: =H14+N14 -> 474 | AH14: =I14+O14 -> 318 | AJ14: =SUM(AF14:AI14) -> 1136 | AU14: =SUM(AS14:AT14)/10 -> 0
A15: 7 | B15: 1 | G15: 81 | H15: 174 | I15: 191 | M15: 82 | N15: 214 | O15: 143 | W15: =SUM(C15:V15) -> 885 | Y15: =W15-X15 -> 885 | AA15: ='CHAM CONG'!BA14 -> 0 | AB15: ='CHAM CONG'!BB14 -> 0 | AC15: ='CHAM CONG'!BC14 -> 0 | AD15: ='CHAM CONG'!BD14 -> 0 | AE15: =ROUND(W15*0.44,2) -> 389.4 | AF15: =G15+M15 -> 163 | AG15: =H15+N15 -> 388 | AH15: =I15+O15 -> 334 | AJ15: =SUM(AF15:AI15) -> 885 | AU15: =SUM(AS15:AT15)/10 -> 0
A16: 8 | B16: 1 | G16: 150 | H16: 177 | I16: 165 | M16: 154 | N16: 224 | O16: 204 | W16: =SUM(C16:V16) -> 1074 | Y16: =W16-X16 -> 1074 | AA16: ='CHAM CONG'!BA15 -> 0 | AB16: ='CHAM CONG'!BB15 -> 0 | AC16: ='CHAM CONG'!BC15 -> 0 | AD16: ='CHAM CONG'!BD15 -> 0 | AE16: =ROUND(W16*0.44,2) -> 472.56 | AF16: =G16+M16 -> 304 | AG16: =H16+N16 -> 401 | AH16: =I16+O16 -> 369 | AJ16: =SUM(AF16:AI16) -> 1074 | AU16: =SUM(AS16:AT16)/10 -> 0
A17: 9 | B17: 1 | G17: 120 | H17: 82 | I17: 78 | M17: 0 | N17: 282 | O17: 0 | W17: =SUM(C17:V17) -> 562 | Y17: =W17-X17 -> 562 | AA17: ='CHAM CONG'!BA16 -> 0 | AB17: ='CHAM CONG'!BB16 -> 0 | AC17: ='CHAM CONG'!BC16 -> 0 | AD17: ='CHAM CONG'!BD16 -> 0 | AE17: =ROUND(W17*0.44,2) -> 247.28 | AF17: =G17+M17 -> 120 | AG17: =H17+N17 -> 364 | AH17: =I17+O17 -> 78 | AJ17: =SUM(AF17:AI17) -> 562 | AU17: =SUM(AS17:AT17)/10 -> 0
A18: 10 | B18: 1 | G18: 0 | H18: 361 | I18: 90 | M18: 205 | N18: 242 | O18: 278 | W18: =SUM(C18:V18) -> 1176 | Y18: =W18-X18 -> 1176 | AA18: ='CHAM CONG'!BA17 -> 0 | AB18: ='CHAM CONG'!BB17 -> 0 | AC18: ='CHAM CONG'!BC17 -> 0 | AD18: ='CHAM CONG'!BD17 -> 0 | AE18: =ROUND(W18*0.44,2) -> 517.44 | AF18: =G18+M18 -> 205 | AG18: =H18+N18 -> 603 | AH18: =I18+O18 -> 368 | AJ18: =SUM(AF18:AI18) -> 1176 | AU18: =SUM(AS18:AT18)/10 -> 0
A19: 11 | B19: 1 | G19: 0 | H19: 227 | I19: 80 | M19: 124 | N19: 191 | O19: 108 | W19: =SUM(C19:V19) -> 730 | Y19: =W19-X19 -> 730 | AA19: ='CHAM CONG'!BA18 -> 0 | AB19: ='CHAM CONG'!BB18 -> 0 | AC19: ='CHAM CONG'!BC18 -> 0 | AD19: ='CHAM CONG'!BD18 -> 0 | AE19: =ROUND(W19*0.44,2) -> 321.2 | AF19: =G19+M19 -> 124 | AG19: =H19+N19 -> 418 | AH19: =I19+O19 -> 188 | AJ19: =SUM(AF19:AI19) -> 730 | AU19: =SUM(AS19:AT19)/10 -> 0
A20: 12 | B20: 1 | G20: 100 | H20: 118 | I20: 96 | M20: 50 | N20: 64 | O20: 115 | W20: =SUM(C20:V20) -> 543 | Y20: =W20-X20 -> 543 | AA20: ='CHAM CONG'!BA19 -> 0 | AB20: ='CHAM CONG'!BB19 -> 0 | AC20: ='CHAM CONG'!BC19 -> 0 | AD20: ='CHAM CONG'!BD19 -> 0 | AE20: =ROUND(W20*0.44,2) -> 238.92 | AF20: =G20+M20 -> 150 | AG20: =H20+N20 -> 182 | AH20: =I20+O20 -> 211 | AJ20: =SUM(AF20:AI20) -> 543 | AU20: =SUM(AS20:AT20)/10 -> 0
A21: 13 | B21: 1 | G21: 105 | H21: 209 | I21: 97 | M21: 194 | N21: 146 | O21: 214 | W21: =SUM(C21:V21) -> 965 | Y21: =W21-X21 -> 965 | AA21: ='CHAM CONG'!BA20 -> 0 | AB21: ='CHAM CONG'!BB20 -> 0 | AC21: ='CHAM CONG'!BC20 -> 0 | AD21: ='CHAM CONG'!BD20 -> 0 | AE21: =ROUND(W21*0.44,2) -> 424.6 | AF21: =G21+M21 -> 299 | AG21: =H21+N21 -> 355 | AH21: =I21+O21 -> 311 | AJ21: =SUM(AF21:AI21) -> 965 | AU21: =SUM(AS21:AT21)/10 -> 0
A22: 14 | B22: 1 | G22: 0 | H22: 199 | I22: 100 | M22: 77 | N22: 205 | O22: 185 | W22: =SUM(C22:V22) -> 766 | Y22: =W22-X22 -> 766 | AA22: ='CHAM CONG'!BA21 -> 0 | AB22: ='CHAM CONG'!BB21 -> 0 | AC22: ='CHAM CONG'!BC21 -> 0 | AD22: ='CHAM CONG'!BD21 -> 0 | AE22: =ROUND(W22*0.44,2) -> 337.04 | AF22: =G22+M22 -> 77 | AG22: =H22+N22 -> 404 | AH22: =I22+O22 -> 285 | AJ22: =SUM(AF22:AI22) -> 766 | AU22: =SUM(AS22:AT22)/10 -> 0
A23: 15 | B23: 1 | G23: 108 | H23: 114 | I23: 222 | M23: 177 | N23: 258 | O23: 242 | W23: =SUM(C23:V23) -> 1121 | Y23: =W23-X23 -> 1121 | AA23: ='CHAM CONG'!BA22 -> 0 | AB23: ='CHAM CONG'!BB22 -> 0 | AC23: ='CHAM CONG'!BC22 -> 0 | AD23: ='CHAM CONG'!BD22 -> 0 | AE23: =ROUND(W23*0.44,2) -> 493.24 | AF23: =G23+M23 -> 285 | AG23: =H23+N23 -> 372 | AH23: =I23+O23 -> 464 | AJ23: =SUM(AF23:AI23) -> 1121 | AU23: =SUM(AS23:AT23)/10 -> 0
A24: 16 | B24: 1 | G24: 104 | H24: 120 | I24: 155 | M24: 210 | N24: 276 | O24: 210 | W24: =SUM(C24:V24) -> 1075 | Y24: =W24-X24 -> 1075 | AA24: ='CHAM CONG'!BA23 -> 0 | AB24: ='CHAM CONG'!BB23 -> 0 | AC24: ='CHAM CONG'!BC23 -> 0 | AD24: ='CHAM CONG'!BD23 -> 0 | AE24: =ROUND(W24*0.44,2) -> 473 | AF24: =G24+M24 -> 314 | AG24: =H24+N24 -> 396 | AH24: =I24+O24 -> 365 | AJ24: =SUM(AF24:AI24) -> 1075 | AU24: =SUM(AS24:AT24)/10 -> 0
A25: 17 | B25: 1 | G25: 101 | H25: 215 | I25: 178 | M25: 172 | N25: 95 | O25: 179 | W25: =SUM(C25:V25) -> 940 | Y25: =W25-X25 -> 940 | AA25: ='CHAM CONG'!BA24 -> 0 | AB25: ='CHAM CONG'!BB24 -> 0 | AC25: ='CHAM CONG'!BC24 -> 0 | AD25: ='CHAM CONG'!BD24 -> 0 | AE25: =ROUND(W25*0.44,2) -> 413.6 | AF25: =G25+M25 -> 273 | AG25: =H25+N25 -> 310 | AH25: =I25+O25 -> 357 | AJ25: =SUM(AF25:AI25) -> 940 | AU25: =SUM(AS25:AT25)/10 -> 0
... A54: 46 | B54: 1 | G54: 133 | H54: 211 | I54: 344 | M54: 224 | N54: 230 | O54: 129 | W54: =SUM(C54:V54) -> 1271 | Y54: =W54-X54 -> 1271 | AA54: ='CHAM CONG'!BA53 -> 0 | AB54: ='CHAM CONG'!BB53 -> 0 | AC54: ='CHAM CONG'!BC53 -> 0 | AD54: ='CHAM CONG'!BD53 -> 0 | AE54: =ROUND(W54*0.44,2) -> 559.24 | AF54: =G54+M54 -> 357 | AG54: =H54+N54 -> 441 | AH54: =I54+O54 -> 473 | AJ54: =SUM(AF54:AI54) -> 1271 | AU54: =SUM(AS54:AT54)/10 -> 0
A55: 47 | B55: 1 | G55: 108 | H55: 106 | I55: 53 | M55: 111 | N55: 123 | O55: 92 | W55: =SUM(C55:V55) -> 593 | Y55: =W55-X55 -> 593 | AA55: ='CHAM CONG'!#REF! -> #REF! | AB55: ='CHAM CONG'!#REF! -> #REF! | AC55: ='CHAM CONG'!#REF! -> #REF! | AD55: ='CHAM CONG'!#REF! -> #REF! | AE55: =ROUND(W55*0.44,2) -> 260.92 | AF55: =G55+M55 -> 219 | AG55: =H55+N55 -> 229 | AH55: =I55+O55 -> 145 | AJ55: =SUM(AF55:AI55) -> 593 | AK55: TỔ 4
A56: 137 | B56: 4 | H56: 191 | I56: 149 | J56: 206 | K56: 200 | P56: 177 | Q56: 208 | W56: =SUM(C56:V56) -> 1131 | Y56: =W56-X56 -> 1131 | AA56: ='CHAM CONG'!BA175 -> 0 | AB56: ='CHAM CONG'!BB175 -> 0 | AC56: ='CHAM CONG'!BC175 -> 0 | AD56: ='CHAM CONG'!BD175 -> 0 | AE56: =ROUND(W56*0.44,2) -> 497.64 | AF56: =K56 -> 200 | AG56: =H56+P56 -> 368 | AH56: =I56+Q56 -> 357 | AI56: =J56 -> 206 | AJ56: =SUM(AF56:AI56) -> 1131 | AK56: =SUM(AJ56:AJ94) -> 48749
A57: 138 | B57: 4 | H57: 173 | I57: 154 | J57: 394 | K57: 292 | P57: 165 | Q57: 187 | W57: =SUM(C57:V57) -> 1365 | Y57: =W57-X57 -> 1365 | AA57: ='CHAM CONG'!BA176 -> 0 | AB57: ='CHAM CONG'!BB176 -> 0 | AC57: ='CHAM CONG'!BC176 -> 0 | AD57: ='CHAM CONG'!BD176 -> 0 | AE57: =ROUND(W57*0.44,2) -> 600.6 | AF57: =K57 -> 292 | AG57: =H57+P57 -> 338 | AH57: =I57+Q57 -> 341 | AI57: =J57 -> 394 | AJ57: =SUM(AF57:AI57) -> 1365
A58: 139 | B58: 4 | H58: 221 | I58: 130 | J58: 388 | K58: 216 | P58: 244 | Q58: 196 | W58: =SUM(C58:V58) -> 1395 | Y58: =W58-X58 -> 1395 | AA58: ='CHAM CONG'!BA177 -> 0 | AB58: ='CHAM CONG'!BB177 -> 0 | AC58: ='CHAM CONG'!BC177 -> 0 | AD58: ='CHAM CONG'!BD177 -> 0 | AE58: =ROUND(W58*0.44,2) -> 613.8 | AF58: =K58 -> 216 | AG58: =H58+P58 -> 465 | AH58: =I58+Q58 -> 326 | AI58: =J58 -> 388 | AJ58: =SUM(AF58:AI58) -> 1395
A59: 140 | B59: 4 | H59: 171 | I59: 60 | J59: 351 | K59: 194 | P59: 87 | Q59: 162 | W59: =SUM(C59:V59) -> 1025 | Y59: =W59-X59 -> 1025 | AA59: ='CHAM CONG'!BA178 -> 0 | AB59: ='CHAM CONG'!BB178 -> 0 | AC59: ='CHAM CONG'!BC178 -> 0 | AD59: ='CHAM CONG'!BD178 -> 0 | AE59: =ROUND(W59*0.44,2) -> 451 | AF59: =K59 -> 194 | AG59: =H59+P59 -> 258 | AH59: =I59+Q59 -> 222 | AI59: =J59 -> 351 | AJ59: =SUM(AF59:AI59) -> 1025
A60: 141 | B60: 4 | H60: 130 | I60: 58 | J60: 362 | K60: 210 | P60: 133 | Q60: 72 | W60: =SUM(C60:V60) -> 965 | Y60: =W60-X60 -> 965 | AA60: ='CHAM CONG'!BA179 -> 0 | AB60: ='CHAM CONG'!BB179 -> 0 | AC60: ='CHAM CONG'!BC179 -> 0 | AD60: ='CHAM CONG'!BD179 -> 0 | AE60: =ROUND(W60*0.44,2) -> 424.6 | AF60: =K60 -> 210 | AG60: =H60+P60 -> 263 | AH60: =I60+Q60 -> 130 | AI60: =J60 -> 362 | AJ60: =SUM(AF60:AI60) -> 965
A61: 142 | B61: 4 | H61: 196 | I61: 58 | J61: 381 | K61: 229 | P61: 157 | Q61: 107 | W61: =SUM(C61:V61) -> 1128 | Y61: =W61-X61 -> 1128 | AA61: ='CHAM CONG'!BA180 -> 0 | AB61: ='CHAM CONG'!BB180 -> 0 | AC61: ='CHAM CONG'!BC180 -> 0 | AD61: ='CHAM CONG'!BD180 -> 0 | AE61: =ROUND(W61*0.44,2) -> 496.32 | AF61: =K61 -> 229 | AG61: =H61+P61 -> 353 | AH61: =I61+Q61 -> 165 | AI61: =J61 -> 381 | AJ61: =SUM(AF61:AI61) -> 1128
A62: 143 | B62: 4 | H62: 154 | I62: 215 | J62: 279 | K62: 164 | P62: 155 | Q62: 73 | W62: =SUM(C62:V62) -> 1040 | Y62: =W62-X62 -> 1040 | AA62: ='CHAM CONG'!BA181 -> 0 | AB62: ='CHAM CONG'!BB181 -> 0 | AC62: ='CHAM CONG'!BC181 -> 0 | AD62: ='CHAM CONG'!BD181 -> 0 | AE62: =ROUND(W62*0.44,2) -> 457.6 | AF62: =K62 -> 164 | AG62: =H62+P62 -> 309 | AH62: =I62+Q62 -> 288 | AI62: =J62 -> 279 | AJ62: =SUM(AF62:AI62) -> 1040
A63: 144 | B63: 4 | H63: 224 | I63: 74 | J63: 309 | K63: 293 | P63: 184 | Q63: 255 | W63: =SUM(C63:V63) -> 1339 | Y63: =W63-X63 -> 1339 | AA63: ='CHAM CONG'!BA182 -> 0 | AB63: ='CHAM CONG'!BB182 -> 0 | AC63: ='CHAM CONG'!BC182 -> 0 | AD63: ='CHAM CONG'!BD182 -> 0 | AE63: =ROUND(W63*0.44,2) -> 589.16 | AF63: =K63 -> 293 | AG63: =H63+P63 -> 408 | AH63: =I63+Q63 -> 329 | AI63: =J63 -> 309 | AJ63: =SUM(AF63:AI63) -> 1339
A64: 145 | B64: 4 | H64: 148 | I64: 110 | J64: 255 | K64: 290 | P64: 142 | Q64: 138 | W64: =SUM(C64:V64) -> 1083 | Y64: =W64-X64 -> 1083 | AA64: ='CHAM CONG'!BA183 -> 0 | AB64: ='CHAM CONG'!BB183 -> 0 | AC64: ='CHAM CONG'!BC183 -> 0 | AD64: ='CHAM CONG'!BD183 -> 0 | AE64: =ROUND(W64*0.44,2) -> 476.52 | AF64: =K64 -> 290 | AG64: =H64+P64 -> 290 | AH64: =I64+Q64 -> 248 | AI64: =J64 -> 255 | AJ64: =SUM(AF64:AI64) -> 1083
A65: 146 | B65: 4 | H65: 178 | I65: 140 | J65: 349 | K65: 265 | P65: 151 | Q65: 193 | W65: =SUM(C65:V65) -> 1276 | Y65: =W65-X65 -> 1276 | AA65: ='CHAM CONG'!BA184 -> 0 | AB65: ='CHAM CONG'!BB184 -> 0 | AC65: ='CHAM CONG'!BC184 -> 0 | AD65: ='CHAM CONG'!BD184 -> 0 | AE65: =ROUND(W65*0.44,2) -> 561.44 | AF65: =K65 -> 265 | AG65: =H65+P65 -> 329 | AH65: =I65+Q65 -> 333 | AI65: =J65 -> 349 | AJ65: =SUM(AF65:AI65) -> 1276
A66: 147 | B66: 4 | H66: 241 | I66: 107 | J66: 374 | K66: 246 | P66: 258 | Q66: 232 | W66: =SUM(C66:V66) -> 1458 | Y66: =W66-X66 -> 1458 | AA66: ='CHAM CONG'!BA185 -> 0 | AB66: ='CHAM CONG'!BB185 -> 0 | AC66: ='CHAM CONG'!BC185 -> 0 | AD66: ='CHAM CONG'!BD185 -> 0 | AE66: =ROUND(W66*0.44,2) -> 641.52 | AF66: =K66 -> 246 | AG66: =H66+P66 -> 499 | AH66: =I66+Q66 -> 339 | AI66: =J66 -> 374 | AJ66: =SUM(AF66:AI66) -> 1458
A67: 148 | B67: 4 | H67: 233 | I67: 192 | J67: 342 | K67: 229 | P67: 237 | Q67: 279 | W67: =SUM(C67:V67) -> 1512 | Y67: =W67-X67 -> 1512 | AA67: ='CHAM CONG'!BA186 -> 0 | AB67: ='CHAM CONG'!BB186 -> 0 | AC67: ='CHAM CONG'!BC186 -> 0 | AD67: ='CHAM CONG'!BD186 -> 0 | AE67: =ROUND(W67*0.44,2) -> 665.28 | AF67: =K67 -> 229 | AG67: =H67+P67 -> 470 | AH67: =I67+Q67 -> 471 | AI67: =J67 -> 342 | AJ67: =SUM(AF67:AI67) -> 1512
A68: 149 | B68: 4 | H68: 197 | I68: 88 | J68: 369 | K68: 171 | P68: 205 | Q68: 196 | W68: =SUM(C68:V68) -> 1226 | Y68: =W68-X68 -> 1226 | AA68: ='CHAM CONG'!BA187 -> 0 | AB68: ='CHAM CONG'!BB187 -> 0 | AC68: ='CHAM CONG'!BC187 -> 0 | AD68: ='CHAM CONG'!BD187 -> 0 | AE68: =ROUND(W68*0.44,2) -> 539.44 | AF68: =K68 -> 171 | AG68: =H68+P68 -> 402 | AH68: =I68+Q68 -> 284 | AI68: =J68 -> 369 | AJ68: =SUM(AF68:AI68) -> 1226
...

Sheet GA 1
A1: CÔNG TY TNHH CAO SU MEKONG
A2: ĐƠN VỊ: ĐỘI SẢN XUẤT 1
A3: _________________
A4: BẢNG CHẤM CÔNG CÔNG NHÂN KHAI THÁC
A5: THÁNG 01 NĂM 2026
