Workbook
Name ten_hang_muc_KD: '[1]Ten hang muc (2)'!$B$1:$C$31

Sheet Tên thang 01-26
AC1: TUỔI | AE1: TUỔI
A2: STT | B2: ប្រុល់ | C2: ស្រី | D2: CMNN | E2: TÊN | G2: GA | H2: Tổ | I2: Số phần cây
AC3: NAM | AD3: NỮ | AE3: NAM | AF3: NỮ
A4: 1 | B4: 33030 | C4: ស្រី | D4: 150429518 | E4: ឆែម ហុង | F4: CHHEM HONG | G4: 1 | H4: I | I4: 1 | W4: SAO PHEAROM | AC4: =YEAR(NOW())-YEAR(B4) -> 36 | AD4: =YEAR(NOW())-YEAR(C4) -> #VALUE! | AE4: =IF(AC4<=69,AC4,IF(AC4=70,1)) -> 36 | AF4: =IF(AD4<=69,AD4,IF(AD4=70,1)) -> #VALUE!
A5: 2 | B5: 35982 | C5: ប្រុស | D5: 220140698 | E5: សុទ្ធ សីថា | F5: SOT SEYTHA | G5: 1 | H5: I | I5: 2 | W5: PECH CHAN | AC5: =YEAR(NOW())-YEAR(B5) -> 28 | AD5: =YEAR(NOW())-YEAR(C5) -> #VALUE! | AE5: =IF(AC5<=69,AC5,IF(AC5=70,1)) -> 28 | AF5: =IF(AD5<=69,AD5,IF(AD5=70,1)) -> #VALUE!
A6: 3 | B6: 38457 | C6: ប្រុស | D6: 151027370 | E6: រ៉ន ចាន់រាជ | F6: RORN CHANREACH | G6: 1 | H6: I | I6: 3 | W6: NUON SAROEUN | AC6: =YEAR(NOW())-YEAR(B6) -> 21 | AD6: =YEAR(NOW())-YEAR(C6) -> #VALUE! | AE6: =IF(AC6<=69,AC6,IF(AC6=70,1)) -> 21 | AF6: =IF(AD6<=69,AD6,IF(AD6=70,1)) -> #VALUE!
A7: 4 | B7: 36175 | C7: ស្រី | D7: 150815265 | E7: ណំ ធីងធីង | F7: NON THING THING | G7: 1 | H7: I | I7: 4 | W7: HEAN CHANROTH | AC7: =YEAR(NOW())-YEAR(B7) -> 27 | AD7: =YEAR(NOW())-YEAR(C7) -> #VALUE! | AE7: =IF(AC7<=69,AC7,IF(AC7=70,1)) -> 27 | AF7: =IF(AD7<=69,AD7,IF(AD7=70,1)) -> #VALUE!
A8: 5 | B8: 33615 | C8: ប្រុស | D8: 150523483 | E8: វ៉ាន់ បូរ៉ុង | F8: VANN BORONG | G8: 1 | H8: I | I8: 5 | W8: CHOUN SAMUN | AC8: =YEAR(NOW())-YEAR(B8) -> 34 | AD8: =YEAR(NOW())-YEAR(C8) -> #VALUE! | AE8: =IF(AC8<=69,AC8,IF(AC8=70,1)) -> 34 | AF8: =IF(AD8<=69,AD8,IF(AD8=70,1)) -> #VALUE!
A9: 6 | B9: 35986 | C9: ប្រុស | D9: 220152906 | E9: យឿង សុខជា | F9: YOEUNG SOKCHEA | G9: 1 | H9: I | I9: 6 | W9: MORN POV | AC9: =YEAR(NOW())-YEAR(B9) -> 28 | AD9: =YEAR(NOW())-YEAR(C9) -> #VALUE! | AE9: =IF(AC9<=69,AC9,IF(AC9=70,1)) -> 28 | AF9: =IF(AD9<=69,AD9,IF(AD9=70,1)) -> #VALUE!
A10: 7 | B10: 36651 | C10: ប្រុស | D10: 220175364 | E10: អួន សុភាព | F10: OURN SOPHEAP | G10: 1 | H10: I | I10: 7 | W10: TRI MAK | AC10: =YEAR(NOW())-YEAR(B10) -> 26 | AD10: =YEAR(NOW())-YEAR(C10) -> #VALUE! | AE10: =IF(AC10<=69,AC10,IF(AC10=70,1)) -> 26 | AF10: =IF(AD10<=69,AD10,IF(AD10=70,1)) -> #VALUE!
A11: 8 | B11: 35950 | C11: ប្រុស | D11: 220209900 | E11: ភួន ភី | F11: PHUON PHY | G11: 1 | H11: I | I11: 8 | W11: YET YEN | AC11: =YEAR(NOW())-YEAR(B11) -> 28 | AD11: =YEAR(NOW())-YEAR(C11) -> #VALUE! | AE11: =IF(AC11<=69,AC11,IF(AC11=70,1)) -> 28 | AF11: =IF(AD11<=69,AD11,IF(AD11=70,1)) -> #VALUE!
A12: 9 | B12: 36447 | C12: ប្រុស | D12: 150789799 | E12: ទូ គុលា | F12: TO TOKLA | G12: 1 | H12: I | I12: 9 | W12: TANN NAVEN | AC12: =YEAR(NOW())-YEAR(B12) -> 27 | AD12: =YEAR(NOW())-YEAR(C12) -> #VALUE! | AE12: =IF(AC12<=69,AC12,IF(AC12=70,1)) -> 27 | AF12: =IF(AD12<=69,AD12,IF(AD12=70,1)) -> #VALUE!
A13: 10 | B13: 38244 | C13: ស្រី | D13: 150983095 | E13: ណំ សិទ្ធិ | F13: NOM SITH | G13: 1 | H13: I | I13: 10 | W13: NON THING THING | AC13: =YEAR(NOW())-YEAR(B13) -> 22 | AD13: =YEAR(NOW())-YEAR(C13) -> #VALUE! | AE13: =IF(AC13<=69,AC13,IF(AC13=70,1)) -> 22 | AF13: =IF(AD13<=69,AD13,IF(AD13=70,1)) -> #VALUE!
A14: 11 | B14: 29073 | C14: ស្រី | D14: 150814730 | E14: ធ្លក រាន់ | F14: THLOK ROIN | G14: 1 | H14: I | I14: 11 | W14: SOT SEYTHA | AC14: =YEAR(NOW())-YEAR(B14) -> 47 | AD14: =YEAR(NOW())-YEAR(C14) -> #VALUE! | AE14: =IF(AC14<=69,AC14,IF(AC14=70,1)) -> 47 | AF14: =IF(AD14<=69,AD14,IF(AD14=70,1)) -> #VALUE!
A15: 12 | B15: 29082 | C15: ស្រី | D15: 150427542 | E15: យ៉ែម ឃឿន | F15: YEM KHOEUN | G15: 1 | H15: I | I15: 12 | W15: CHHON YIN | AC15: =YEAR(NOW())-YEAR(B15) -> 47 | AD15: =YEAR(NOW())-YEAR(C15) -> #VALUE! | AE15: =IF(AC15<=69,AC15,IF(AC15=70,1)) -> 47 | AF15: =IF(AD15<=69,AD15,IF(AD15=70,1)) -> #VALUE!
A16: 13 | B16: 37848 | C16: ប្រុស | D16: 220234084 | E16: យឿង រ៉ាឌី | F16: YOEUNG RADIN | G16: 1 | H16: I | I16: 13 | W16: PHORN SAMBIEN | AC16: =YEAR(NOW())-YEAR(B16) -> 23 | AD16: =YEAR(NOW())-YEAR(C16) -> #VALUE! | AE16: =IF(AC16<=69,AC16,IF(AC16=70,1)) -> 23 | AF16: =IF(AD16<=69,AD16,IF(AD16=70,1)) -> #VALUE!
A17: 14 | B17: 34127 | C17: ប្រុស | D17: 150468345 | E17: វ៉ាន់ បូរិទ្ធ | F17: VANN BORITH | G17: 1 | H17: I | I17: 14 | W17: HAUY VEASNA | AC17: =YEAR(NOW())-YEAR(B17) -> 33 | AD17: =YEAR(NOW())-YEAR(C17) -> #VALUE! | AE17: =IF(AC17<=69,AC17,IF(AC17=70,1)) -> 33 | AF17: =IF(AD17<=69,AD17,IF(AD17=70,1)) -> #VALUE!
A18: 15 | B18: 30477 | C18: ស្រី | D18: 250230683 | E18: ឆែម ហ៊ាច | F18: CHHEM HEACH | G18: 1 | H18: I | I18: 15 | W18: SRENG NARIN | AC18: =YEAR(NOW())-YEAR(B18) -> 43 | AD18: =YEAR(NOW())-YEAR(C18) -> #VALUE! | AE18: =IF(AC18<=69,AC18,IF(AC18=70,1)) -> 43 | AF18: =IF(AD18<=69,AD18,IF(AD18=70,1)) -> #VALUE!
A19: 16 | B19: 34095 | C19: ប្រុស | D19: 150523533 | E19: ឆែម ឆុន | F19: CHHEN CHHON | G19: 1 | H19: I | I19: 16 | W19: SEK SAMON | AC19: =YEAR(NOW())-YEAR(B19) -> 33 | AD19: =YEAR(NOW())-YEAR(C19) -> #VALUE! | AE19: =IF(AC19<=69,AC19,IF(AC19=70,1)) -> 33 | AF19: =IF(AD19<=69,AD19,IF(AD19=70,1)) -> #VALUE!
... A27: 24 | B27: 35189 | C27: ប្រុស | D27: 220208788 | E27: សុទ្ធ សុខជា | F27: SOTH SOKCHEA | G27: 1 | H27: I | I27: 24 | W27: SOT LAYHORN | AC27: =YEAR(NOW())-YEAR(B27) -> 30 | AD27: =YEAR(NOW())-YEAR(C27) -> #VALUE! | AE27: =IF(AC27<=69,AC27,IF(AC27=70,1)) -> 30 | AF27: =IF(AD27<=69,AD27,IF(AD27=70,1)) -> #VALUE!
A28: 25 | B28: 31200 | C28: ស្រី | D28: 060541171 | E28: ពិន ឆេន | F28: PIN CHHEN | G28: 1 | H28: I | I28: 25 | W28: KHOURN HOUY | AC28: =YEAR(NOW())-YEAR(B28) -> 41 | AD28: =YEAR(NOW())-YEAR(C28) -> #VALUE! | AE28: =IF(AC28<=69,AC28,IF(AC28=70,1)) -> 41 | AF28: =IF(AD28<=69,AD28,IF(AD28=70,1)) -> #VALUE!
A29: 26 | B29: 30904 | C29: ប្រុស | D29: 060540793 | E29: កេត នី | F29: KET NY | G29: 1 | H29: I | I29: 26 | W29: LAY NHOENG | AC29: =YEAR(NOW())-YEAR(B29) -> 42 | AD29: =YEAR(NOW())-YEAR(C29) -> #VALUE! | AE29: =IF(AC29<=69,AC29,IF(AC29=70,1)) -> 42 | AF29: =IF(AD29<=69,AD29,IF(AD29=70,1)) -> #VALUE!
A30: 27 | B30: 38861 | C30: ប្រុស | D30: 250373915 | E30: គៀវ និ | F30: KIEV NIK | G30: 1 | H30: I | I30: 27 | W30: CHHENG CHAMRAEUN | AC30: =YEAR(NOW())-YEAR(B30) -> 20 | AD30: =YEAR(NOW())-YEAR(C30) -> #VALUE! | AE30: =IF(AC30<=69,AC30,IF(AC30=70,1)) -> 20 | AF30: =IF(AD30<=69,AD30,IF(AD30=70,1)) -> #VALUE!
A31: 28 | B31: 39434 | C31: ប្រុស | D31: 151065238 | E31: ដួត ដែន | F31: DOUT DEN | G31: 1 | H31: I | I31: 28 | W31: KHOEUN KHEN | AC31: =YEAR(NOW())-YEAR(B31) -> 19 | AD31: =YEAR(NOW())-YEAR(C31) -> #VALUE! | AE31: =IF(AC31<=69,AC31,IF(AC31=70,1)) -> 19 | AF31: =IF(AD31<=69,AD31,IF(AD31=70,1)) -> #VALUE!
A32: 29 | B32: 39615 | C32: ស្រី | D32: 151057212 | E32: ចាយ ពន្លក | F32: CHAY PONLOK | G32: 1 | H32: I | I32: 29 | W32: TAN VOT | AC32: =YEAR(NOW())-YEAR(B32) -> 18 | AD32: =YEAR(NOW())-YEAR(C32) -> #VALUE! | AE32: =IF(AC32<=69,AC32,IF(AC32=70,1)) -> 18 | AF32: =IF(AD32<=69,AD32,IF(AD32=70,1)) -> #VALUE!
A33: 30 | B33: 28982 | C33: ប្រុស | D33: 150978869 | E33: សំ ផុន | F33: SOM PHON | G33: 1 | H33: I | I33: 30 | W33: POV CHHONG | AC33: =YEAR(NOW())-YEAR(B33) -> 47 | AD33: =YEAR(NOW())-YEAR(C33) -> #VALUE! | AE33: =IF(AC33<=69,AC33,IF(AC33=70,1)) -> 47 | AF33: =IF(AD33<=69,AD33,IF(AD33=70,1)) -> #VALUE!
A34: 31 | B34: 38595 | C34: ស្រី | D34: 150983094 | E34: អ៊ុន ឆវ័ន | F34: UN CHORVON | G34: 1 | H34: I | I34: 31 | W34: SIEK SOM | AC34: =YEAR(NOW())-YEAR(B34) -> 21 | AD34: =YEAR(NOW())-YEAR(C34) -> #VALUE! | AE34: =IF(AC34<=69,AC34,IF(AC34=70,1)) -> 21 | AF34: =IF(AD34<=69,AD34,IF(AD34=70,1)) -> #VALUE!
A35: 32 | B35: 30503 | C35: ប្រុស | D35: 220175216 | E35: ប៉ិល ថា | F35: PEL THA | G35: 1 | H35: I | I35: 32 | W35: CHHIV PHALL | AC35: =YEAR(NOW())-YEAR(B35) -> 43 | AD35: =YEAR(NOW())-YEAR(C35) -> #VALUE! | AE35: =IF(AC35<=69,AC35,IF(AC35=70,1)) -> 43 | AF35: =IF(AD35<=69,AD35,IF(AD35=70,1)) -> #VALUE!
A36: 33 | B36: 31663 | C36: ប្រុស | D36: 220175443 | E36: ប៉ិល ផល្លា | F36: PEL PHALLA | G36: 1 | H36: I | I36: 33 | W36: VEAT TY | AC36: =YEAR(NOW())-YEAR(B36) -> 40 | AD36: =YEAR(NOW())-YEAR(C36) -> #VALUE! | AE36: =IF(AC36<=69,AC36,IF(AC36=70,1)) -> 40 | AF36: =IF(AD36<=69,AD36,IF(AD36=70,1)) -> #VALUE!
A37: 34 | B37: 37412 | C37: ប្រុស | D37: 220208812 | E37: យៀត ឌី | F37: YIEN DY | G37: 1 | H37: I | I37: 34 | J37: 37309 | L37: 150935164 | M37: ណំ វ៉ាន់​ស៊ីង | N37: NOM VANSING | W37: SIE RITH | AC37: =YEAR(NOW())-YEAR(B37) -> 24 | AD37: =YEAR(NOW())-YEAR(C37) -> #VALUE! | AE37: =IF(AC37<=69,AC37,IF(AC37=70,1)) -> 24 | AF37: =IF(AD37<=69,AD37,IF(AD37=70,1)) -> #VALUE!
A38: 35 | B38: 30868 | C38: ស្រី | D38: 220175374 | E38: រឿន ចាន់រ៉ា | F38: ROEUN CHANRA | G38: 1 | H38: I | I38: 35 | W38: TOCH CHANTHA | AC38: =YEAR(NOW())-YEAR(B38) -> 42 | AD38: =YEAR(NOW())-YEAR(C38) -> #VALUE! | AE38: =IF(AC38<=69,AC38,IF(AC38=70,1)) -> 42 | AF38: =IF(AD38<=69,AD38,IF(AD38=70,1)) -> #VALUE!
A39: 36 | B39: 38777 | C39: ស្រី | D39: 220234356 | E39: អៀវ សុភ័ណ្ឌ | F39: IEV SOPHORN | G39: 1 | H39: I | I39: 36 | W39: ROEUN SARANN | AC39: =YEAR(NOW())-YEAR(B39) -> 20 | AD39: =YEAR(NOW())-YEAR(C39) -> #VALUE! | AE39: =IF(AC39<=69,AC39,IF(AC39=70,1)) -> 20 | AF39: =IF(AD39<=69,AD39,IF(AD39=70,1)) -> #VALUE!
A40: 37 | B40: 30835 | C40: ប្រុស | D40: 160485580 | E40: គុយ សឿន | F40: KUY SOEUN | G40: 1 | H40: I | I40: 37 | W40: MEN MOEUN | AC40: =YEAR(NOW())-YEAR(B40) -> 42 | AD40: =YEAR(NOW())-YEAR(C40) -> #VALUE! | AE40: =IF(AC40<=69,AC40,IF(AC40=70,1)) -> 42 | AF40: =IF(AD40<=69,AD40,IF(AD40=70,1)) -> #VALUE!
A41: 38 | B41: 35066 | C41: ស្រី | D41: 150523513 | E41: សាំ សុរីសា | F41: SAM SORYSA | G41: 1 | H41: I | I41: 38 | J41: 35351 | L41: 150650748 | M41: លឿន ឡែម | N41: LOEUN LEM | W41: SAL SOPHORN | AC41: =YEAR(NOW())-YEAR(B41) -> 30 | AD41: =YEAR(NOW())-YEAR(C41) -> #VALUE! | AE41: =IF(AC41<=69,AC41,IF(AC41=70,1)) -> 30 | AF41: =IF(AD41<=69,AD41,IF(AD41=70,1)) -> #VALUE!
A42: 39 | B42: 33401 | C42: ប្រុស | D42: 150648033 | E42: មាស សំបាន | F42: MEAS SOM BAN | G42: 1 | H42: I | I42: 39 | W42: PHAN SOPHY | AC42: =YEAR(NOW())-YEAR(B42) -> 35 | AD42: =YEAR(NOW())-YEAR(C42) -> #VALUE! | AE42: =IF(AC42<=69,AC42,IF(AC42=70,1)) -> 35 | AF42: =IF(AD42<=69,AD42,IF(AD42=70,1)) -> #VALUE!
A43: 40 | B43: 38363 | C43: ស្រី | D43: 220220033 | E43: សុទ្ធ ឡៃហ័ន | F43: SOT LAYHORN | G43: 1 | H43: I | I43: 40 | W43: CHORN SOCHEAT | AC43: =YEAR(NOW())-YEAR(B43) -> 21 | AD43: =YEAR(NOW())-YEAR(C43) -> #VALUE! | AE43: =IF(AC43<=69,AC43,IF(AC43=70,1)) -> 21 | AF43: =IF(AD43<=69,AD43,IF(AD43=70,1)) -> #VALUE!
A44: 41 | B44: 37441 | C44: ប្រុស | D44: 150935343 | E44: អឿង សំអុល | F44: OENG SAMOL | G44: 1 | H44: I | I44: 41 | W44: SAL SOPHY | AC44: =YEAR(NOW())-YEAR(B44) -> 24 | AD44: =YEAR(NOW())-YEAR(C44) -> #VALUE! | AE44: =IF(AC44<=69,AC44,IF(AC44=70,1)) -> 24 | AF44: =IF(AD44<=69,AD44,IF(AD44=70,1)) -> #VALUE!
A45: 42 | B45: 33796 | C45: ប្រុស | D45: 150468460 | E45: ឡា​ឡច | F45: LA LOCH | G45: 1 | H45: I | I45: 42 | W45: HON HIM | AC45: =YEAR(NOW())-YEAR(B45) -> 34 | AD45: =YEAR(NOW())-YEAR(C45) -> #VALUE! | AE45: =IF(AC45<=69,AC45,IF(AC45=70,1)) -> 34 | AF45: =IF(AD45<=69,AD45,IF(AD45=70,1)) -> #VALUE! | AH45: 30201 | AI45: 250121370 | AJ45: ពិន ឈាន | AK45: PIN CHHEAN
A46: 43 | B46: 32968 | C46: ប្រុស | D46: 220175299 | E46: សៀក សំ | F46: SIEK SOM | G46: 1 | H46: I | I46: 43 | K46: 37162 | L46: 220217470 | M46: សៀក ពេញ | N46: SEAK PENH | W46: SEAK PENH | AC46: =YEAR(NOW())-YEAR(B46) -> 36 | AD46: =YEAR(NOW())-YEAR(C46) -> #VALUE! | AE46: =IF(AC46<=69,AC46,IF(AC46=70,1)) -> 36 | AF46: =IF(AD46<=69,AD46,IF(AD46=70,1)) -> #VALUE! | AG46: 30796 | AI46: 250121371 | AJ46: ហ៊ីម ហៀក | AK46: HIM HIEK
A47: 44 | B47: 36783 | C47: ស្រី | D47: 150982919 | E47: អ៊ីម សារ៉ាន | F47: IM SARAN | G47: 1 | H47: I | I47: 44 | J47: 37316 | K47: 220210781 | L47: ស្រេង ស្រីអូន | M47: SRENG SREY OUN | W47: PHANN PHANNY | AC47: =YEAR(NOW())-YEAR(B47) -> 26 | AD47: =YEAR(NOW())-YEAR(C47) -> #VALUE! | AE47: =IF(AC47<=69,AC47,IF(AC47=70,1)) -> 26 | AF47: =IF(AD47<=69,AD47,IF(AD47=70,1)) -> #VALUE! | AG47: 38971 | AI47: 250373914 | AJ47: ហៀក ហ៊ា | AK47: HIEK HEA
...

Sheet tên hang mục
A1: A | B1: CHĂM SÓC | C1: ការថែទាំ
A2: 1 | B2: Phát cỏ luồng | C2: ជម្រះស្មៅចន្លោះរង
A3: 2 | B3: Bón phân | C3: ដាក់ជី
A4: 3 | B4: Phòng trị bệnh | C4: បង្ការព្យាបាលជម្ងឺ
A5: 4 | B5: Làm giàn mủ tạp | C5: ធ្វើរានដាក់ជ័រចម្រុះ
A6: 5 | B6: Phòng chống cháy + gác lửa | C6: ការពារភ្លើងឆេះ + យាមភ្លើង
A7: B | B7: THU HOẠCH | C7: ប្រមូលផល
A8: 1 | B8: Kiểm kê cây cao su đầu vụ cạo | C8: ជំរឿនដើមកៅស៊ូនៅដើមរដូវចៀរ
A9: 2 | B9: Thiết kế mặt cạo | C9: បែងចែកផ្ទាំងចៀរ
A10: 3 | B10: Đánh dấu hao dăm quý, năm | C10: គូសសញ្ញាចំណាយអាចម៍ពន្លាក់ប្រចាំត្រីមាស​និងឆ្នាំ
A11: 4 | B11: Chia, đánh số phần cạo | C11: បែងចែកនិងគូសលេខរានចៀរ
A12: 5 | B12: Trang bị vật tư (Kiềng, chén) | C12: បំពាក់ឧបករណ៍ (កង, ចាន)
A13: 6 | B13: Cạo xả miệng, đóng máng, gắn mái che chén | C13: បើកមុខចៀរជ័រដំបូង ដោតស្លាបព្រា​និងទគម្របចាន
A14: 7 | B14: Gắn máng chắn mưa | C14: ការបំពាក់ក្បាំងទឹកភ្លៀង
A15: 8 | B15: Vệ sinh cây cạo | C15: សំអាតដើមចៀរ
A16: 9 | B16: Bôi thuốc kích thích | C16: លាបថ្នាំរំញោច
A17: 10 | B17: Thu dọn cuối vụ cạo | C17: ប្រមូលសម្ភារៈចុងរដូវចៀរ
A18: 11 | B18: Cạo, trút và giao nộp mủ | C18: ចៀរ សារនិងប្រគូលជ័រ
A19: 12 | B19: Công nhật (16.000 KHR) | C19: កម្លាំងចៀរ
A20: 13 | B20: Công trả sản lượng mủ | C20: កម្លាំងចំណាយទៅលើផលិតផលជ័រ
A21: C | B21: Bảo vệ vườn cây | C21: សន្តិសុខការពារចំការ
B22: Kinh doanh nhóm 1 | C22: អាជីវកម្មក្រុមទី​១
B23: Kinh doanh năm 4 | C23: អាជីវកម្មឆ្នាំទី​៤
B24: Kinh doanh năm 3 | C24: អាជីវកម្មឆ្នាំទី​៣
B25: Kinh doanh năm 2 | C25: អាជីវកម្មឆ្នាំទី​២
B26: Mở cạo 2021 | C26: បើកមុខចៀរជ័រឆ្នាំ​២០២១
B27: Công/ha | C27: កម្លាំង/ហិតា
B28: Đợt 1 | C28: វគ្គទី​១
B29: Đợt 2 | C29: វគ្គទី​២
B30: Tổng 2 đợt | C30: សរុបទាំង​២វគ្គ
B31: Công/ngày | C31: កម្លាំង/ថ្ងៃ
A32: Hạng mục KTCB | C32: មុខងាររយៈមុនពេលប្រមូលផល
B33: Phun thuốc cỏ hàng | C33: បាញ់ថ្នាំរង
B34: Phát cỏ luồng | C34: ជម្រះស្មៅចន្លោះរង
B35: Phát dọn, phòng chống cháy | C35: ជម្រះការពារភ្លើងឆេះ
B36: Phòng trị bệnh | C36: បង្ការព្យាបាលជម្ងឺ
B37: Bảo vệ thường xuyên | C37: ការពារជាប្រចាំ
B38: Kiểm kê cuối năm | C38: ជំរឿនដើមកៅស៊ូនៅចុងរដូវចៀរ

Sheet SAN LUONG
BD1: A | BE1: B | BF1: C | BG1: D | BH1: TỔNG CỘNG | CU1: A | CV1: B | CW1: C | CX1: D | CY1: TỔNG CỘNG | DG1: =DG8+DG177+#REF!+#REF!+#REF!+#REF!+#REF! -> #REF! | DH1: =BA6 -> #REF! | DI1: đợt 1 | DK1: =#REF! -> #REF! | DM1: =#REF! -> #REF! | EC1: Tiền điện | ED1: Tạm ứng | EE1: Tiền dao | EF1: Mủ dây
BC2: Tổ 1 | BD2: =AW8 -> 35596 | BE2: =AX8 -> 0 | BF2: =AY8 -> 23294 | BG2: =AZ8 -> 0 | BH2: =SUM(BD2:BG2) -> 58890 | CT2: Tổ 1 | CU2: =CM8 -> 0 | CV2: =CN8 -> 0 | CW2: =CO8 -> 0 | CX2: =CP8 -> 0 | CY2: =SUM(CU2:CX2) -> 0 | DG2: =DG1-SUM(DH1:DH2) -> #REF! | DH2: =CE6 -> #REF! | DI2: đợt 2 | DK2: =#REF! -> #REF! | DM2: =#REF! -> #REF! | EC2: =SUM(EC3:EC10) -> #REF! | ED2: =SUM(ED3:ED10) -> #REF! | EE2: =SUM(EE3:EE10) -> #REF! | EF2: =SUM(EF3:EF10) -> #REF! | EH2: =SUM(EH3:EH10) -> #REF!
BC3: Tổ 2 | BD3: =AW177 -> 29095 | BE3: =AX177 -> 0 | BF3: =AY177 -> 0 | BG3: =AZ177 -> 0 | BH3: =SUM(BD3:BG3) -> 29095 | CT3: Tổ 2 | CU3: =CM177 -> 0 | CV3: =CN177 -> 0 | CW3: =CO177 -> 0 | CX3: =CP177 -> 0 | CY3: =SUM(CU3:CX3) -> 0 | DK3: =#REF! -> #REF! | DM3: =#REF! -> #REF! | EB3: 1 | EC3: =DR8 -> 0 | ED3: =DT8 -> 0 | EE3: =DV8 -> 0 | EF3: =DW8 -> 3608.1 | EH3: =DY8 -> 1218
T4: B | U4: C | V4: A | Z4: C | AA4: A | AB4: B | AF4: A | AG4: B | AH4: C | AM4: 8659.5 | AP4: 3 | AV4: 6 | AW4: 3100 | AX4: 8 | AY4: 3080 | AZ4: 10 | BA4: 2340 | BC4: Tổ 3 | BD4: =#REF! -> #REF! | BE4: =#REF! -> #REF! | BF4: =#REF! -> #REF! | BG4: =#REF! -> #REF! | BH4: =SUM(BD4:BG4) -> #REF! | CT4: Tổ 3 | CU4: =#REF! -> #REF! | CV4: =#REF! -> #REF! | CW4: =#REF! -> #REF! | CX4: =#REF! -> #REF! | CY4: =SUM(CU4:CX4) -> #REF! | DK4: =#REF! -> #REF! | EB4: 2 | EC4: =DR177 -> 0 | ED4: =DT177 -> 0 | EE4: =DV177 -> 0 | EF4: =DW177 -> 3022.5 | EH4: =DY177 -> 1217
A5: SẢN LƯỢNG THÁNG 01/2026 đ2 | AN5: 4 | AP5: 2 | AV5: 5 | AW5: 2880 | AX5: 7 | AY5: 2700 | AZ5: 9 | BA5: 2720 | BC5: Tổ 4 | BD5: =#REF! -> #REF! | BE5: =#REF! -> #REF! | BF5: =#REF! -> #REF! | BG5: =#REF! -> #REF! | BH5: =SUM(BD5:BG5) -> #REF! | BK5: =A5 -> SẢN LƯỢNG THÁNG 01/2026 đ2 | CT5: Tổ 4 | CU5: =#REF! -> #REF! | CV5: =#REF! -> #REF! | CW5: =#REF! -> #REF! | CX5: =#REF! -> #REF! | CY5: =SUM(CU5:CX5) -> #REF! | DK5: =#REF! -> #REF! | EB5: 3 | EC5: =#REF! -> #REF! | ED5: =#REF! -> #REF! | EE5: =#REF! -> #REF! | EF5: =#REF! -> #REF! | EH5: =#REF! -> #REF!
C6: 1 | D6: 2 | E6: 3 | F6: 4 | G6: 5 | H6: 6 | I6: 7 | J6: 8 | K6: 9 | L6: 10 | M6: 11 | N6: 12 | O6: 13 | P6: 14 | Q6: 15 | R6: tổng đ1 | S6: 16 | T6: 17 | U6: 18 | V6: 19 | W6: 20 | X6: 21 | Y6: 22 | Z6: 23 | AA6: 24 | AB6: 25 | AC6: 26 | AD6: 27 | AE6: 28 | AF6: 29 | AG6: 30 | AH6: 31 | AM6: =AM500/2 -> 402704.5 | AN6: tổng 2 đợt | AP6: 1 | AR6: Công đợt I | AW6: Sản lượng đợt I | BA6: =BA8+BA177+#REF!+#REF!+#REF!+#REF!+#REF!+#REF! -> #REF! | BC6: Tổ 5 | BD6: =#REF! -> #REF! | BE6: =#REF! -> #REF! | BF6: =#REF! -> #REF! | BG6: =#REF! -> #REF! | BH6: =SUM(BD6:BG6) -> #REF! | CE6: =CE8+CE177+#REF!+#REF!+#REF!+#REF!+#REF!+#REF! -> #REF! | CG6: Công đợt II | CM6: Sản lượng đợt II | CQ6: =CQ8+CQ177+#REF!+#REF!+#REF!+#REF!+#REF!+#REF! -> #REF! | CS6: =CS8+CS177+#REF!+#REF!+#REF!+#REF!+#REF!+#REF! -> #REF! | CT6: Tổ 5 | CU6: =#REF! -> #REF! | CV6: =#REF! -> #REF! | CW6: =#REF! -> #REF! | CX6: =#REF! -> #REF! | CY6: =SUM(CU6:CX6) -> #REF! | DC6: Sản lượng 2 đợt | DR6: tháng 04 | DS6: điện tháng 03 | DW6: 1 | EB6: 4 | EC6: =#REF! -> #REF! | ED6: =#REF! -> #REF! | EE6: =#REF! -> #REF! | EF6: =#REF! -> #REF! | EH6: =#REF! -> #REF!
A7: STT | H7: A | I7: B | J7: C | S7: D-B | T7: A-C | Y7: D | Z7: A | AA7: B | AB7: C | AG7: B-D | AH7: C-A | AO7: 505 | AP7: 455 | AQ7: đạt sản lượng | AR7: A | AS7: B | AT7: C | AU7: D | AV7: 555 | AW7: A | AX7: B | AY7: C | AZ7: D | BC7: Tổ 6 | BD7: =#REF! -> #REF! | BE7: =#REF! -> #REF! | BF7: =#REF! -> #REF! | BG7: =#REF! -> #REF! | BH7: =SUM(BD7:BG7) -> #REF! | BK7: A | BL7: B | BM7: C | BN7: D | BO7: A | BP7: B | BQ7: C | BR7: D | BS7: A | BT7: B | BU7: C | BV7: D | BW7: A | BX7: B | BY7: C | BZ7: D | CA7: A | CE7: TỔNG CỘNG | CG7: A | CH7: B | CI7: C | CJ7: D | CM7: A | CN7: B | CO7: C | CP7: D | CS7: Mủ dây | CT7: Tổ 6 | CU7: =#REF! -> #REF! | CV7: =#REF! -> #REF! | CW7: =#REF! -> #REF! | CX7: =#REF! -> #REF! | CY7: =SUM(CU7:CX7) -> #REF! | DC7: A | DD7: B | DE7: C | DF7: D | DH7: KH GIAO KHOÁN | DL7: Tổng SL 2 đợt | DM7: Bôi KT | DN7: Bôi Phòng | DP7: LỄ (PCHUM BANH) | DQ7: tiền nước | DR7: Tiền điện | DS7: Tiền điện | DT7: Tạm ứng | DU7: Đá mài | DV7: Tiền dao | DW7: Mủ dây | EB7: 5 | EC7: =#REF! -> #REF! | ED7: =#REF! -> #REF! | EE7: =#REF! -> #REF! | EF7: =#REF! -> #REF! | EH7: =#REF! -> #REF!
A8: GA 1 | C8: =SUM(C9:C175) -> 0 | D8: =SUM(D9:D175) -> 0 | E8: =SUM(E9:E175) -> 0 | F8: =SUM(F9:F175) -> 0 | G8: =SUM(G9:G175) -> 0 | H8: =SUM(H9:H175) -> 0 | I8: =SUM(I9:I175) -> 0 | J8: =SUM(J9:J175) -> 0 | ... DW8: =SUM(DW9:DW175) -> 3608.1 | DX8: tổ1 | DY8: =SUM(DW9:DW55) -> 1218 | EB8: 6 | EC8: =#REF! -> #REF! | ED8: =#REF! -> #REF! | EE8: =#REF! -> #REF! | EF8: =#REF! -> #REF! | EH8: =#REF! -> #REF!
A9: 1 | B9: 1 | R9: =SUM(C9:Q9) -> 0 | T9: 187 | U9: 177 | V9: 126 | Z9: 85 | AA9: 120 | AB9: 256 | AF9: 54 | AG9: 130 | AH9: 108 | AM9: =SUM(S9:AL9) -> 1243 | AN9: =R9+AM9 -> 1243 | AV9: =AN9 -> 1243 | AW9: =T9+AC9 -> 187 | AX9: =AD9 -> 0 | AY9: =S9+AE9 -> 0 | DM9: 3 | DW9: 20 | EB9: 7 | EC9: =#REF! -> #REF! | ED9: =#REF! -> #REF! | EE9: =#REF! -> #REF! | EF9: =#REF! -> #REF! | EH9: =#REF! -> #REF!
A10: 2 | B10: 1 | R10: =SUM(C10:Q10) -> 0 | T10: 172 | U10: 155 | V10: 174 | Z10: 80 | AA10: 72 | AB10: 158 | AF10: 74 | AG10: 145 | AH10: 129 | AM10: =SUM(S10:AL10) -> 1159 | AN10: =R10+AM10 -> 1159 | AQ10: =#N/A -> #N/A | AV10: =AN10 -> 1159 | AW10: =T10+AC10 -> 172 | AX10: =AD10 -> 0 | AY10: =S10+AE10 -> 0 | DM10: 3 | DW10: 15 | EB10: 8 | EC10: =#REF! -> #REF! | ED10: =#REF! -> #REF! | EE10: =#REF! -> #REF! | EF10: =#REF! -> #REF! | EH10: =#REF! -> #REF!
A11: 3 | B11: 1 | R11: =SUM(C11:Q11) -> 0 | T11: 223 | U11: 188 | V11: 181 | Z11: 0 | AA11: 164 | AB11: 286 | AF11: 81 | AG11: 167 | AH11: 113 | AM11: =SUM(S11:AL11) -> 1403 | AN11: =R11+AM11 -> 1403 | AQ11: =#N/A -> #N/A | AV11: =AN11 -> 1403 | AW11: =T11+AC11 -> 223 | AX11: =AD11 -> 0 | AY11: =S11+AE11 -> 0 | DM11: 3 | DW11: 36
A12: 4 | B12: 1 | R12: =SUM(C12:Q12) -> 0 | T12: 173 | U12: 158 | V12: 170 | Z12: 75 | AA12: 66 | AB12: 154 | AF12: 92 | AG12: 145 | AH12: 130 | AM12: =SUM(S12:AL12) -> 1163 | AN12: =R12+AM12 -> 1163 | AQ12: =#N/A -> #N/A | AV12: =AN12 -> 1163 | AW12: =T12+AC12 -> 173 | AX12: =AD12 -> 0 | AY12: =S12+AE12 -> 0 | DM12: 3 | DW12: 14
A13: 5 | B13: 1 | R13: =SUM(C13:Q13) -> 0 | T13: 196 | U13: 214 | V13: 256 | Z13: 124 | AA13: 172 | AB13: 266 | AF13: 91 | AG13: 158 | AH13: 216 | AM13: =SUM(S13:AL13) -> 1693 | AN13: =R13+AM13 -> 1693 | AQ13: =#N/A -> #N/A | AV13: =AN13 -> 1693 | AW13: =T13+AC13 -> 196 | AX13: =AD13 -> 0 | AY13: =S13+AE13 -> 0 | DM13: 3 | DW13: 58
A14: 6 | B14: 1 | R14: =SUM(C14:Q14) -> 0 | T14: 227 | U14: 209 | V14: 195 | Z14: 69 | AA14: 91 | AB14: 223 | AF14: 90 | AG14: 186 | AH14: 196 | AM14: =SUM(S14:AL14) -> 1486 | AN14: =R14+AM14 -> 1486 | AQ14: =#N/A -> #N/A | AV14: =AN14 -> 1486 | AW14: =T14+AC14 -> 227 | AX14: =AD14 -> 0 | AY14: =S14+AE14 -> 0 | DM14: 3 | DW14: 27
A15: 7 | B15: 1 | R15: =SUM(C15:Q15) -> 0 | T15: 187 | U15: 129 | V15: 199 | Z15: 62 | AA15: 172 | AB15: 217 | AF15: 94 | AG15: 80 | AH15: 86 | AM15: =SUM(S15:AL15) -> 1226 | AN15: =R15+AM15 -> 1226 | AQ15: =#N/A -> #N/A | AV15: =AN15 -> 1226 | AW15: =T15+AC15 -> 187 | AX15: =AD15 -> 0 | AY15: =S15+AE15 -> 0 | DM15: 3 | DW15: 15
A16: 8 | B16: 1 | R16: =SUM(C16:Q16) -> 0 | T16: 175 | U16: 83 | V16: 169 | Z16: 91 | AA16: 166 | AB16: 190 | AF16: 82 | AG16: 144 | AH16: 176 | AM16: =SUM(S16:AL16) -> 1276 | AN16: =R16+AM16 -> 1276 | AQ16: =#N/A -> #N/A | AV16: =AN16 -> 1276 | AW16: =T16+AC16 -> 175 | AX16: =AD16 -> 0 | AY16: =S16+AE16 -> 0 | DM16: 3 | DW16: 18
A17: 9 | B17: 1 | R17: =SUM(C17:Q17) -> 0 | T17: 0 | U17: 252 | V17: 68 | Z17: 51 | AA17: 85 | AB17: 207 | AF17: 49 | AG17: 114 | AH17: 72 | AM17: =SUM(S17:AL17) -> 898 | AN17: =R17+AM17 -> 898 | AQ17: =#N/A -> #N/A | AV17: =AN17 -> 898 | AW17: =T17+AC17 -> 0 | AX17: =AD17 -> 0 | AY17: =S17+AE17 -> 0 | DM17: 2 | DW17: 42
A18: 10 | B18: 1 | R18: =SUM(C18:Q18) -> 0 | T18: 218 | U18: 101 | V18: 212 | Z18: 103 | AA18: 144 | AB18: 274 | AF18: 42 | AG18: 50 | AH18: 150 | AM18: =SUM(S18:AL18) -> 1294 | AN18: =R18+AM18 -> 1294 | AQ18: =#N/A -> #N/A | AV18: =AN18 -> 1294 | AW18: =T18+AC18 -> 218 | AX18: =AD18 -> 0 | AY18: =S18+AE18 -> 0 | DM18: 3 | DW18: 20
A19: 11 | B19: 1 | R19: =SUM(C19:Q19) -> 0 | T19: 180 | U19: 124 | V19: 183 | Z19: 100 | AA19: 166 | AB19: 132 | AF19: 100 | AG19: 178 | AH19: 139 | AM19: =SUM(S19:AL19) -> 1302 | AN19: =R19+AM19 -> 1302 | AQ19: =#N/A -> #N/A | AV19: =AN19 -> 1302 | AW19: =T19+AC19 -> 180 | AX19: =AD19 -> 0 | AY19: =S19+AE19 -> 0 | DM19: 3 | DW19: 18
A20: 12 | B20: 1 | R20: =SUM(C20:Q20) -> 0 | T20: 59 | U20: 110 | V20: 121 | Z20: 46 | AA20: 57 | AB20: 140 | AF20: 58 | AG20: 90 | AH20: 86 | AM20: =SUM(S20:AL20) -> 767 | AN20: =R20+AM20 -> 767 | AQ20: =#N/A -> #N/A | AV20: =AN20 -> 767 | AW20: =T20+AC20 -> 59 | AX20: =AD20 -> 0 | AY20: =S20+AE20 -> 0 | DM20: 3 | DW20: 25
A21: 13 | B21: 1 | R21: =SUM(C21:Q21) -> 0 | T21: 213 | U21: 203 | V21: 230 | Z21: 90 | AA21: 180 | AB21: 247 | AF21: 73 | AG21: 94 | AH21: 164 | AM21: =SUM(S21:AL21) -> 1494 | AN21: =R21+AM21 -> 1494 | AQ21: =#N/A -> #N/A | AV21: =AN21 -> 1494 | AW21: =T21+AC21 -> 213 | AX21: =AD21 -> 0 | AY21: =S21+AE21 -> 0 | DM21: 3 | DW21: 17
A22: 14 | B22: 1 | R22: =SUM(C22:Q22) -> 0 | T22: 176 | U22: 167 | V22: 160 | Z22: 82 | AA22: 134 | AB22: 225 | AF22: 62 | AG22: 128 | AH22: 107 | AM22: =SUM(S22:AL22) -> 1241 | AN22: =R22+AM22 -> 1241 | AQ22: =#N/A -> #N/A | AV22: =AN22 -> 1241 | AW22: =T22+AC22 -> 176 | AX22: =AD22 -> 0 | AY22: =S22+AE22 -> 0 | DM22: 3 | DW22: 21
... A39: 31 | B39: 1 | R39: =SUM(C39:Q39) -> 0 | T39: 175 | U39: 211 | V39: 265 | Z39: 91 | AA39: 121 | AB39: 203 | AF39: 128 | AG39: 72 | AH39: 245 | AM39: =SUM(S39:AL39) -> 1511 | AN39: =R39+AM39 -> 1511 | AQ39: =#N/A -> #N/A | AV39: =AN39 -> 1511 | AW39: =T39+AC39 -> 175 | AX39: =AD39 -> 0 | AY39: =S39+AE39 -> 0 | DM39: 3 | DW39: 15
A40: 32 | B40: 1 | R40: =SUM(C40:Q40) -> 0 | T40: 206 | U40: 133 | V40: 226 | Z40: 75 | AA40: 185 | AB40: 230 | AF40: 0 | AG40: 144 | AH40: 174 | AM40: =SUM(S40:AL40) -> 1373 | AN40: =R40+AM40 -> 1373 | AQ40: =IF(AN40>=$AQ$6,1,0) -> 1 | AV40: =AN40 -> 1373 | AW40: =T40+AC40 -> 206 | AX40: =AD40 -> 0 | AY40: =S40+AE40 -> 0 | DM40: 3 | DW40: 31
A41: 33 | B41: 1 | R41: =SUM(C41:Q41) -> 0 | T41: 228 | U41: 173 | V41: 277 | Z41: 83 | AA41: 132 | AB41: 299 | AF41: 139 | AG41: 170 | AH41: 150 | AM41: =SUM(S41:AL41) -> 1651 | AN41: =R41+AM41 -> 1651 | AQ41: =IF(AN41>=$AQ$6,1,0) -> 1 | AV41: =AN41 -> 1651 | AW41: =T41+AC41 -> 228 | AX41: =AD41 -> 0 | AY41: =S41+AE41 -> 0 | DM41: 3 | DW41: 31
A42: 34 | B42: 1 | R42: =SUM(C42:Q42) -> 0 | T42: 182 | U42: 168 | V42: 234 | Z42: 83 | AA42: 212 | AB42: 227 | AF42: 110 | AG42: 150 | AH42: 180 | AM42: =SUM(S42:AL42) -> 1546 | AN42: =R42+AM42 -> 1546 | AQ42: =IF(AN42>=$AQ$6,1,0) -> 1 | AV42: =AN42 -> 1546 | AW42: =T42+AC42 -> 182 | AX42: =AD42 -> 0 | AY42: =S42+AE42 -> 0 | DM42: 3 | DW42: 38
A43: 35 | B43: 1 | R43: =SUM(C43:Q43) -> 0 | T43: 198 | U43: 139 | V43: 246 | Z43: 53 | AA43: 185 | AB43: 225 | AF43: 0 | AG43: 135 | AH43: 112 | AM43: =SUM(S43:AL43) -> 1293 | AN43: =R43+AM43 -> 1293 | AQ43: =IF(AN43>=$AQ$6,1,0) -> 1 | AV43: =AN43 -> 1293 | AW43: =T43+AC43 -> 198 | AX43: =AD43 -> 0 | AY43: =S43+AE43 -> 0 | DM43: 3 | DW43: 39
A44: 36 | B44: 1 | R44: =SUM(C44:Q44) -> 0 | T44: 185 | U44: 147 | V44: 267 | Z44: 72 | AA44: 130 | AB44: 218 | AF44: 122 | AG44: 129 | AH44: 169 | AM44: =SUM(S44:AL44) -> 1439 | AN44: =R44+AM44 -> 1439 | AQ44: =IF(AN44>=$AQ$6,1,0) -> 1 | AV44: =AN44 -> 1439 | AW44: =T44+AC44 -> 185 | AX44: =AD44 -> 0 | AY44: =S44+AE44 -> 0 | DM44: 3 | DW44: 24
A45: 37 | B45: 1 | R45: =SUM(C45:Q45) -> 0 | T45: 182 | U45: 154 | V45: 247 | Z45: 70 | AA45: 204 | AB45: 232 | AF45: 99 | AG45: 132 | AH45: 155 | AM45: =SUM(S45:AL45) -> 1475 | AN45: =R45+AM45 -> 1475 | AQ45: =IF(AN45>=$AQ$6,1,0) -> 1 | AV45: =AN45 -> 1475 | AW45: =T45+AC45 -> 182 | AX45: =AD45 -> 0 | AY45: =S45+AE45 -> 0 | DM45: 3 | DW45: 26
A46: 38 | B46: 1 | R46: =SUM(C46:Q46) -> 0 | T46: 180 | U46: 152 | V46: 241 | Z46: 71 | AA46: 236 | AB46: 218 | AF46: 119 | AG46: 99 | AH46: 162 | AM46: =SUM(S46:AL46) -> 1478 | AN46: =R46+AM46 -> 1478 | AQ46: =IF(AN46>=$AQ$6,1,0) -> 1 | AV46: =AN46 -> 1478 | AW46: =T46+AC46 -> 180 | AX46: =AD46 -> 0 | AY46: =S46+AE46 -> 0 | DM46: 3 | DW46: 28
A47: 39 | B47: 1 | R47: =SUM(C47:Q47) -> 0 | T47: 178 | U47: 188 | V47: 247 | Z47: 0 | AA47: 0 | AB47: 0 | AF47: 112 | AG47: 121 | AH47: 107 | AM47: =SUM(S47:AL47) -> 953 | AN47: =R47+AM47 -> 953 | AQ47: =IF(AN47>=$AQ$6,1,0) -> 1 | AV47: =AN47 -> 953 | AW47: =T47+AC47 -> 178 | AX47: =AD47 -> 0 | AY47: =S47+AE47 -> 0 | DM47: 3 | DW47: 32
A48: 40 | B48: 1 | R48: =SUM(C48:Q48) -> 0 | T48: 182 | U48: 166 | V48: 320 | Z48: 83 | AA48: 107 | AB48: 208 | AF48: 162 | AG48: 125 | AH48: 149 | AM48: =SUM(S48:AL48) -> 1502 | AN48: =R48+AM48 -> 1502 | AQ48: =IF(AN48>=$AQ$6,1,0) -> 1 | AV48: =AN48 -> 1502 | AW48: =T48+AC48 -> 182 | AX48: =AD48 -> 0 | AY48: =S48+AE48 -> 0 | DM48: 3 | DW48: 15
A49: 41 | B49: 1 | R49: =SUM(C49:Q49) -> 0 | T49: 179 | U49: 184 | V49: 247 | Z49: 81 | AA49: 87 | AB49: 217 | AF49: 147 | AG49: 116 | AH49: 160 | AM49: =SUM(S49:AL49) -> 1418 | AN49: =R49+AM49 -> 1418 | AQ49: =IF(AN49>=$AQ$6,1,0) -> 1 | AV49: =AN49 -> 1418 | AW49: =T49+AC49 -> 179 | AX49: =AD49 -> 0 | AY49: =S49+AE49 -> 0 | DM49: 3 | DW49: 15
A50: 42 | B50: 1 | R50: =SUM(C50:Q50) -> 0 | T50: 232 | U50: 124 | V50: 360 | Z50: 235 | AA50: 232 | AB50: 303 | AF50: 113 | AG50: 187 | AH50: 253 | AM50: =SUM(S50:AL50) -> 2039 | AN50: =R50+AM50 -> 2039 | AQ50: =IF(AN50>=$AQ$6,1,0) -> 1 | AV50: =AN50 -> 2039 | AW50: =T50+AC50 -> 232 | AX50: =AD50 -> 0 | AY50: =S50+AE50 -> 0 | DM50: 3 | DW50: 33
A51: 43 | B51: 1 | R51: =SUM(C51:Q51) -> 0 | T51: 202 | U51: 102 | V51: 187 | Z51: 97 | AA51: 89 | AB51: 259 | AF51: 80 | AG51: 151 | AH51: 204 | AM51: =SUM(S51:AL51) -> 1371 | AN51: =R51+AM51 -> 1371 | AQ51: =IF(AN51>=$AQ$6,1,0) -> 1 | AV51: =AN51 -> 1371 | AW51: =T51+AC51 -> 202 | AX51: =AD51 -> 0 | AY51: =S51+AE51 -> 0 | DM51: 3 | DW51: 32
... A54: 46 | B54: 1 | R54: =SUM(C54:Q54) -> 0 | T54: 187 | U54: 240 | V54: 242 | Z54: 108 | AA54: 234 | AB54: 112 | AF54: 114 | AG54: 88 | AH54: 214 | AM54: =SUM(S54:AL54) -> 1539 | AN54: =R54+AM54 -> 1539 | AQ54: =IF(AN54>=$AQ$6,1,0) -> 1 | AV54: =AN54 -> 1539 | AW54: =T54+AC54 -> 187 | AX54: =AD54 -> 0 | AY54: =S54+AE54 -> 0 | DM54: 3 | DW54: 32
A55: 47 | B55: 1 | T55: 144 | U55: 103 | V55: 112 | Z55: 50 | AA55: 50 | AB55: 237 | AF55: 44 | AG55: 81 | AH55: 77 | AM55: =SUM(S55:AL55) -> 898 | AN55: =R55+AM55 -> 898 | AQ55: =IF(AN55>=$AQ$6,1,0) -> 1 | AV55: =AN55 -> 898 | AW55: =T55+AC55 -> 144 | AX55: =AD55 -> 0 | AY55: =S55+AE55 -> 0 | DM55: 3 | DW55: 24 | DX55: tổ 4 | DY55: =SUM(DW56:DW94) -> 717.3
A56: 137 | B56: 4 | S56: 204 | T56: 186 | Y56: 220 | Z56: 184 | AA56: 281 | AB56: 324 | AG56: 184 | AH56: 175 | AM56: =SUM(S56:AL56) -> 1758 | AN56: =R56+AM56 -> 1758 | AP56: =AM56 -> 1758 | AQ56: =IF(AN56>=$AQ$6,1,0) -> 1 | AW56: =T56+AC56 -> 186 | AX56: =AD56 -> 0 | AY56: =S56+AE56 -> 204 | DM56: 4 | DW56: 11.2
A57: 138 | B57: 4 | S57: 331 | T57: 250 | Y57: 328 | Z57: 240 | AA57: 335 | AB57: 338 | AG57: 183 | AH57: 193 | AM57: =SUM(S57:AL57) -> 2198 | AN57: =R57+AM57 -> 2198 | AP57: =AM57 -> 2198 | AQ57: =IF(AN57>=$AQ$6,1,0) -> 1 | AW57: =T57+AC57 -> 250 | AX57: =AD57 -> 0 | AY57: =S57+AE57 -> 331 | DM57: 4 | DW57: 12
A58: 139 | B58: 4 | S58: 291 | T58: 152 | Y58: 236 | Z58: 192 | AA58: 282 | AB58: 344 | AG58: 237 | AH58: 145 | AM58: =SUM(S58:AL58) -> 1879 | AN58: =R58+AM58 -> 1879 | AP58: =AM58 -> 1879 | AQ58: =IF(AN58>=$AQ$6,1,0) -> 1 | AW58: =T58+AC58 -> 152 | AX58: =AD58 -> 0 | AY58: =S58+AE58 -> 291 | DM58: 4 | DW58: 20
...

Sheet CHAM CONG
BY1: ĐỢT I | CF1: 31 | CG1: 47 | CH1: Tổ 1 | CI1: =SUM(BB7:BB173) -> 2195 | CJ1: =SUM(BC7:BC173) -> 2482 | CK1: =ROUND((SUM(CI1:CJ1)/CG1/$CF$1)*100,1) -> 321 | CL1: ĐỢT II | CT1: Tổ 1 | CU1: =SUM(BC7:BC173) -> 2482
A2: BẢNG CHẤM CÔNG CẠO MỦ THÁNG 01/2026 | BR2: D | CD2: 2011 | CF2: =SUM(BY7:CA311) -> #N/A | CG2: 45 | CH2: Tổ 2 | CI2: =SUM(BB175:BB311) -> 1642 | CJ2: =SUM(BC175:BC311) -> 1946 | CK2: =ROUND((SUM(CI2:CJ2)/CG2/$CF$1)*100,1) -> 257.2 | CL2: =CK1 -> 321 | CQ2: 2011 | CR2: =SUM(CL7:CN311) -> #N/A | CT2: Tổ 2 | CU2: =SUM(BC175:BC311) -> 1946
AL3: D2 | BB3: =SUM(BB7:BB355)/2 -> 4113 | BC3: =SUM(BC7:BC355)/2 -> 4741.5 | BE3: D2 | BO3: =BO498 -> 12192 | BP3: 16000 | BQ3: 25500 | BT3: =BT498 -> 432 | CD3: 2012 | CF3: =SUM(CB7:CB311)+SUM(#REF!)+SUM(#REF!) -> #N/A | CG3: 44 | CH3: Tổ 3 | CI3: =SUM(#REF!) -> #REF! | CJ3: =SUM(#REF!) -> #REF! | CK3: =ROUND((SUM(CI3:CJ3)/CG3/$CF$1)*100,1) -> #REF! | CQ3: 2012 | CR3: =SUM(CO7:CO311)+SUM(#REF!) -> #N/A | CT3: Tổ 3 | CU3: =SUM(#REF!) -> #REF!
A4: Stt | B4: TỔ | C4: Mã số CN | D4: Họ và tên | F4: Tổ khai thác | G4: Các ngày trong tháng | AL4: D2 | AV4: CẠO ÚP | AY4: 29 | AZ4: 30 | BA4: CẠO XẢ | BB4: Tổng công | BK4: MÌ (D2) | BL4: CCAN | BR4: Lễ chol chnam thmay | BS4: chuyển cần đã tách | BT4: mì | BU4: KIỂM TRA KỸ THUẬT | CD4: 2013 | CF4: =SUM(#REF!) -> #REF! | CG4: 52 | CH4: Tổ 4 | CI4: =SUM(#REF!) -> #REF! | CJ4: =SUM(#REF!) -> #REF! | CK4: =ROUND((SUM(CI4:CJ4)/CG4/$CF$1)*100,1) -> #REF! | CQ4: 2013 | CR4: =SUM(#REF!) -> #REF! | CT4: Tổ 4 | CU4: =SUM(#REF!) -> #REF!
D5: Khmer | E5: Latinh | G5: 1 | H5: 2 | I5: 3 | J5: 4 | K5: 5 | L5: 6 | M5: 7 | N5: 8 | O5: 9 | P5: 10 | Q5: 11 | R5: 12 | S5: 13 | T5: 14 | U5: 15 | V5: 16 | W5: 17 | X5: 18 | Y5: 19 | Z5: 20 | AA5: 21 | AB5: 22 | AC5: 23 | AD5: 24 | AE5: 25 | AF5: 26 | AG5: 27 | AH5: 28 | AI5: 29 | AJ5: 30 | AK5: 31 | AL5: 16 | AM5: 18 | AN5: 19 | AO5: 20 | AP5: 21 | AQ5: 23 | AR5: 24 | AS5: 27 | AT5: 28 | AU5: 31 | BB5: 1-15 | BC5: 16-30 | BD5: D2 | BE5: HỌC CẠO | BF5: Tổng | BG5: tháng 05+ t6 đ1 | BH5: tháng 05+06 | BI5: 255000 | BJ5: 16000 | BM5: 19000 (4/6 -6/6) | BN5: 16000 (4/6 -6/6) | BO5: chuyên cần | BP5: cạo choàn | BU5: HS NT | BW5: CTY | BY5: Cộng phiên A | BZ5: Cộng phiên B | CA5: Cộng phiên C | CB5: Cộng phiên D | CC5: Tổng cộng | CF5: =SUM(CF2:CF4) -> #N/A | CG5: 52 | CH5: Tổ 5 | CI5: =SUM(#REF!) -> #REF! | CJ5: =SUM(#REF!) -> #REF! | CK5: =ROUND((SUM(CI5:CJ5)/CG5/$CF$1)*100,1) -> #REF! | CL5: Cộng phiên A | CM5: Cộng phiên B | CN5: Cộng phiên C | CO5: Cộng phiên D | CP5: Tổng cộng | CR5: =SUM(CR2:CR4) -> #N/A | CT5: Tổ 5 | CU5: =SUM(#REF!) -> #REF!
A6: GA 1 | F6: Phiên cạo | BD6: Đ1 | BE6: D 2 | BP6: CÔNG | BQ6: TIỀN | CE6: công cao nhất | CG6: 48 | CH6: Tổ 6 | CI6: =SUM(#REF!) -> #REF! | CJ6: =SUM(#REF!) -> #REF! | CK6: =ROUND((SUM(CI6:CJ6)/CG6/$CF$1)*100,1) -> #REF! | CR6: =SUM(CU1:CU7)-CR5 -> #REF! | CT6: Tổ 6 | CU6: =SUM(#REF!) -> #REF! | DD6: =DD8+DD177+#REF!+#REF!+#REF!+#REF!+#REF!+#REF! -> #REF!
A7: 1 | B7: 1 | C7: 1 | G7: 0 | H7: 0 | I7: x | K7: 0 | L7: 0 | M7: x | N7: x | O7: x | P7: x | Q7: x | R7: x | S7: x | T7: x | U7: x | V7: x | W7: x | X7: x | Y7: x | Z7: x | AA7: x | AB7: x | AC7: x | AD7: x | AE7: x | AF7: x | AG7: 0 | AH7: x | AI7: x | AJ7: x | AK7: x | AP7: x | BB7: =COUNTIF(G7:U7,"X") -> 10 | BC7: =COUNTIF(V7:AK7,"X") -> 15 | BD7: =COUNTIF(AL7:BA7,"X") -> 1 | BE7: =COUNTIF(AU7:BA7,"x") -> 0 | BF7: =BB7+BC7 -> 25 | BK7: =IF(BO7>=26,1,0) -> 0 | BL7: =(BB7+BC7) -> 25 | BO7: =IF(BT7>0,BF7,0) -> 0 | BT7: =IF(BF7>=26,1,0) -> 0 | BV7: =IF(AND(BU7>0,BU7<=1),50000,IF(AND(BU7>1,BU7<=3),40000,IF(AND(BU7>3,BU7<=5),20000,IF(AND(BU7>5,BU7<=9),0,IF(AND(BU7>9,BU7<=11),-20000,IF(AND(BU7>11,BU7<=13),-40000,IF(BU7>13,-50000,0))))))) -> 0 | BX7: =IF(AND(BW7>0,BW7<=1),1.15,IF(AND(BW7>1,BW7<=3),1.1,IF(AND(BW7>3,BW7<=5),1.05,IF(AND(BW7>5,BW7<=9),1,IF(AND(BW7>9,BW7<=11),-0.05,IF(AND(BW7>11,BW7<=13),-0.1,IF(BW7>13,-0.15,0))))))) -> 0 | BY7: =#N/A -> #N/A | BZ7: =#N/A -> #N/A | CA7: =#N/A -> #N/A | CB7: =#N/A -> #N/A | CC7: =SUM(BY7:CB7) -> #N/A | CD7: =CC7-BB7 -> #N/A | CE7: =IF(CF7>0,BF7,0) -> 0 | CF7: =IF(BF7>=26,1,0) -> 0 | CG7: 56 | CH7: Tổ 7 | CI7: =SUM(#REF!) -> #REF! | CJ7: =SUM(#REF!) -> #REF! | CK7: =ROUND((SUM(CI7:CJ7)/CG7/$CF$1)*100,1) -> #REF! | CL7: =#N/A -> #N/A | CM7: =#N/A -> #N/A | CN7: =#N/A -> #N/A | CO7: =#N/A -> #N/A | CP7: =SUM(CL7:CO7) -> #N/A | CQ7: =CP7-BC7 -> #N/A | CT7: Tổ 7 | CU7: =SUM(#REF!) -> #REF! | CW7: =BU7 -> 0 | CX7: =BW7 -> 0 | CY7: =IF(COUNT(CW7:CX7)=2,ROUND((CW7+CX7)/2,2),CW7) -> 0
A8: 2 | B8: 1 | C8: 2 | G8: 0 | H8: x | I8: x | K8: x | L8: x | M8: x | N8: x | O8: x | P8: x | Q8: x | R8: x | S8: x | T8: x | U8: x | V8: x | W8: x | X8: x | Y8: x | Z8: x | AA8: x | AB8: 0 | AC8: 0 | AD8: x | AE8: x | AF8: x | AG8: x | AH8: x | AI8: x | AJ8: x | AK8: x | AP8: x | BB8: =COUNTIF(G8:U8,"X") -> 13 | BC8: =COUNTIF(V8:AK8,"X") -> 14 | BD8: =COUNTIF(AL8:BA8,"X") -> 1 | BE8: =COUNTIF(AU8:BA8,"x") -> 0 | BF8: =BB8+BC8 -> 27 | BK8: =IF(BO8>=26,1,0) -> 1 | BL8: =(BB8+BC8) -> 27 | BO8: =IF(BT8>0,BF8,0) -> 27 | BT8: =IF(BF8>=26,1,0) -> 1 | BV8: =IF(AND(BU8>0,BU8<=1),50000,IF(AND(BU8>1,BU8<=3),40000,IF(AND(BU8>3,BU8<=5),20000,IF(AND(BU8>5,BU8<=9),0,IF(AND(BU8>9,BU8<=11),-20000,IF(AND(BU8>11,BU8<=13),-40000,IF(BU8>13,-50000,0))))))) -> 0 | BX8: =IF(AND(BW8>0,BW8<=1),1.15,IF(AND(BW8>1,BW8<=3),1.1,IF(AND(BW8>3,BW8<=5),1.05,IF(AND(BW8>5,BW8<=9),1,IF(AND(BW8>9,BW8<=11),-0.05,IF(AND(BW8>11,BW8<=13),-0.1,IF(BW8>13,-0.15,0))))))) -> 0 | BY8: =#N/A -> #N/A | BZ8: =#N/A -> #N/A | CA8: =#N/A -> #N/A | CB8: =#N/A -> #N/A | CC8: =SUM(BY8:CB8) -> #N/A | CD8: =CC8-BB8 -> #N/A | CE8: =IF(CF8>0,BF8,0) -> 27 | CF8: =IF(BF8>=26,1,0) -> 1 | CG8: 51 | CH8: Tổ 8 | CI8: =BB313 -> 1642 | CJ8: =BC313 -> 1946 | CK8: =ROUND((SUM(CI8:CJ8)/CG8/$CF$1)*100,1) -> 226.9 | CL8: =#N/A -> #N/A | CM8: =#N/A -> #N/A | CN8: =#N/A -> #N/A | CO8: =#N/A -> #N/A | CP8: =SUM(CL8:CO8) -> #N/A | CQ8: =CP8-BC8 -> #N/A | CT8: Tổ 8 | CU8: =SUM(#REF!) -> #REF! | CW8: =BU8 -> 0 | CX8: =BW8 -> 0 | CY8: =IF(COUNT(CW8:CX8)=2,ROUND((CW8+CX8)/2,2),CW8) -> 0 | DD8: =SUM(DD9:DD175) -> 0
A9: 3 | B9: 1 | C9: 3 | G9: x | H9: x | I9: x | K9: x | L9: x | M9: x | N9: x | O9: x | P9: x | Q9: x | R9: x | S9: x | T9: x | U9: x | V9: x | W9: x | X9: x | Y9: 0 | Z9: x | AA9: x | AB9: x | AC9: x | AD9: 0 | AE9: x | AF9: x | AG9: x | AH9: x | AI9: x | AJ9: x | AK9: x | AP9: x | BB9: =COUNTIF(G9:U9,"X") -> 14 | BC9: =COUNTIF(V9:AK9,"X") -> 14 | BD9: =COUNTIF(AL9:BA9,"X") -> 1 | BE9: =COUNTIF(AU9:BA9,"x") -> 0 | BF9: =BB9+BC9 -> 28 | BK9: =IF(BO9>=26,1,0) -> 1 | BL9: =(BB9+BC9) -> 28 | BO9: =IF(BT9>0,BF9,0) -> 28 | BT9: =IF(BF9>=26,1,0) -> 1 | BV9: =IF(AND(BU9>0,BU9<=1),50000,IF(AND(BU9>1,BU9<=3),40000,IF(AND(BU9>3,BU9<=5),20000,IF(AND(BU9>5,BU9<=9),0,IF(AND(BU9>9,BU9<=11),-20000,IF(AND(BU9>11,BU9<=13),-40000,IF(BU9>13,-50000,0))))))) -> 0 | BX9: =IF(AND(BW9>0,BW9<=1),1.15,IF(AND(BW9>1,BW9<=3),1.1,IF(AND(BW9>3,BW9<=5),1.05,IF(AND(BW9>5,BW9<=9),1,IF(AND(BW9>9,BW9<=11),-0.05,IF(AND(BW9>11,BW9<=13),-0.1,IF(BW9>13,-0.15,0))))))) -> 0 | BY9: =#N/A -> #N/A | BZ9: =#N/A -> #N/A | CA9: =#N/A -> #N/A | CB9: =#N/A -> #N/A | CC9: =SUM(BY9:CB9) -> #N/A | CD9: =CC9-BB9 -> #N/A | CE9: =IF(CF9>0,BF9,0) -> 28 | CF9: =IF(BF9>=26,1,0) -> 1 | CH9: Thưởng ngày công | CL9: =#N/A -> #N/A | CM9: =#N/A -> #N/A | CN9: =#N/A -> #N/A | CO9: =#N/A -> #N/A | CP9: =SUM(CL9:CO9) -> #N/A | CQ9: =CP9-BC9 -> #N/A | CT9: Tổ 9 | CW9: =BU9 -> 0 | CX9: =BW9 -> 0 | CY9: =IF(COUNT(CW9:CX9)=2,ROUND((CW9+CX9)/2,2),CW9) -> 0
A10: 4 | B10: 1 | C10: 4 | G10: 0 | H10: x | I10: x | K10: x | L10: x | M10: x | N10: x | O10: x | P10: x | Q10: x | R10: x | S10: x | T10: x | U10: x | V10: x | W10: x | X10: x | Y10: x | Z10: x | AA10: x | AB10: 0 | AC10: 0 | AD10: x | AE10: x | AF10: x | AG10: x | AH10: x | AI10: x | AJ10: x | AK10: x | AP10: x | BB10: =COUNTIF(G10:U10,"X") -> 13 | BC10: =COUNTIF(V10:AK10,"X") -> 14 | BD10: =COUNTIF(AL10:BA10,"X") -> 1 | BE10: =COUNTIF(AU10:BA10,"x") -> 0 | BF10: =BB10+BC10 -> 27 | BK10: =IF(BO10>=26,1,0) -> 1 | BL10: =(BB10+BC10) -> 27 | BO10: =IF(BT10>0,BF10,0) -> 27 | BT10: =IF(BF10>=26,1,0) -> 1 | BV10: =IF(AND(BU10>0,BU10<=1),50000,IF(AND(BU10>1,BU10<=3),40000,IF(AND(BU10>3,BU10<=5),20000,IF(AND(BU10>5,BU10<=9),0,IF(AND(BU10>9,BU10<=11),-20000,IF(AND(BU10>11,BU10<=13),-40000,IF(BU10>13,-50000,0))))))) -> 0 | BX10: =IF(AND(BW10>0,BW10<=1),1.15,IF(AND(BW10>1,BW10<=3),1.1,IF(AND(BW10>3,BW10<=5),1.05,IF(AND(BW10>5,BW10<=9),1,IF(AND(BW10>9,BW10<=11),-0.05,IF(AND(BW10>11,BW10<=13),-0.1,IF(BW10>13,-0.15,0))))))) -> 0 | BY10: =#N/A -> #N/A | BZ10: =#N/A -> #N/A | CA10: =#N/A -> #N/A | CB10: =#N/A -> #N/A | CC10: =SUM(BY10:CB10) -> #N/A | CD10: =CC10-BB10 -> #N/A | CE10: =IF(CF10>0,BF10,0) -> 27 | CF10: =IF(BF10>=26,1,0) -> 1 | CH10: Tổ 1 | CI10: =IF(CK1>=98,60000,IF(CK1>95,40000,0)) -> 60000 | CJ10: =SUM(CI10:CI12) -> #REF! | CL10: =#N/A -> #N/A | CM10: =#N/A -> #N/A | CN10: =#N/A -> #N/A | CO10: =#N/A -> #N/A | CP10: =SUM(CL10:CO10) -> #N/A | CQ10: =CP10-BC10 -> #N/A | CW10: =BU10 -> 0 | CX10: =BW10 -> 0 | CY10: =IF(COUNT(CW10:CX10)=2,ROUND((CW10+CX10)/2,2),CW10) -> 0
A11: 5 | B11: 1 | C11: 5 | G11: x | H11: x | I11: x | K11: x | L11: x | M11: x | N11: x | O11: x | P11: x | Q11: x | R11: x | S11: x | T11: x | U11: x | V11: x | W11: x | X11: x | Y11: x | Z11: x | AA11: x | AB11: x | AC11: x | AD11: x | AE11: x | AF11: x | AG11: x | AH11: x | AI11: x | AJ11: x | AK11: x | AP11: x | BB11: =COUNTIF(G11:U11,"X") -> 14 | BC11: =COUNTIF(V11:AK11,"X") -> 16 | BD11: =COUNTIF(AL11:BA11,"X") -> 1 | BE11: =COUNTIF(AU11:BA11,"x") -> 0 | BF11: =BB11+BC11 -> 30 | BK11: =IF(BO11>=26,1,0) -> 1 | BL11: =(BB11+BC11) -> 30 | BO11: =IF(BT11>0,BF11,0) -> 30 | BT11: =IF(BF11>=26,1,0) -> 1 | BV11: =IF(AND(BU11>0,BU11<=1),50000,IF(AND(BU11>1,BU11<=3),40000,IF(AND(BU11>3,BU11<=5),20000,IF(AND(BU11>5,BU11<=9),0,IF(AND(BU11>9,BU11<=11),-20000,IF(AND(BU11>11,BU11<=13),-40000,IF(BU11>13,-50000,0))))))) -> 0 | BX11: =IF(AND(BW11>0,BW11<=1),1.15,IF(AND(BW11>1,BW11<=3),1.1,IF(AND(BW11>3,BW11<=5),1.05,IF(AND(BW11>5,BW11<=9),1,IF(AND(BW11>9,BW11<=11),-0.05,IF(AND(BW11>11,BW11<=13),-0.1,IF(BW11>13,-0.15,0))))))) -> 0 | BY11: =#N/A -> #N/A | BZ11: =#N/A -> #N/A | CA11: =#N/A -> #N/A | CB11: =#N/A -> #N/A | CC11: =SUM(BY11:CB11) -> #N/A | CD11: =CC11-BB11 -> #N/A | CE11: =IF(CF11>0,BF11,0) -> 30 | CF11: =IF(BF11>=26,1,0) -> 1 | CH11: Tổ 2 | CI11: =IF(CK2>=98,60000,IF(CK2>95,40000,0)) -> 60000 | CL11: =#N/A -> #N/A | CM11: =#N/A -> #N/A | CN11: =#N/A -> #N/A | CO11: =#N/A -> #N/A | CP11: =SUM(CL11:CO11) -> #N/A | CQ11: =CP11-BC11 -> #N/A | CW11: =BU11 -> 0 | CX11: =BW11 -> 0 | CY11: =IF(COUNT(CW11:CX11)=2,ROUND((CW11+CX11)/2,2),CW11) -> 0
A12: 6 | B12: 1 | C12: 6 | G12: x | H12: x | I12: x | K12: 0 | L12: x | M12: x | N12: x | O12: x | P12: x | Q12: x | R12: x | S12: x | T12: x | U12: x | V12: x | W12: x | X12: 0 | Y12: x | Z12: x | AA12: x | AB12: 0 | AC12: x | AD12: x | AE12: x | AF12: x | AG12: x | AH12: x | AI12: x | AJ12: x | AK12: x | AP12: x | BB12: =COUNTIF(G12:U12,"X") -> 13 | BC12: =COUNTIF(V12:AK12,"X") -> 14 | BD12: =COUNTIF(AL12:BA12,"X") -> 1 | BE12: =COUNTIF(AU12:BA12,"x") -> 0 | BF12: =BB12+BC12 -> 27 | BK12: =IF(BO12>=26,1,0) -> 1 | BL12: =(BB12+BC12) -> 27 | BO12: =IF(BT12>0,BF12,0) -> 27 | BT12: =IF(BF12>=26,1,0) -> 1 | BV12: =IF(AND(BU12>0,BU12<=1),50000,IF(AND(BU12>1,BU12<=3),40000,IF(AND(BU12>3,BU12<=5),20000,IF(AND(BU12>5,BU12<=9),0,IF(AND(BU12>9,BU12<=11),-20000,IF(AND(BU12>11,BU12<=13),-40000,IF(BU12>13,-50000,0))))))) -> 0 | BX12: =IF(AND(BW12>0,BW12<=1),1.15,IF(AND(BW12>1,BW12<=3),1.1,IF(AND(BW12>3,BW12<=5),1.05,IF(AND(BW12>5,BW12<=9),1,IF(AND(BW12>9,BW12<=11),-0.05,IF(AND(BW12>11,BW12<=13),-0.1,IF(BW12>13,-0.15,0))))))) -> 0 | BY12: =#N/A -> #N/A | BZ12: =#N/A -> #N/A | CA12: =#N/A -> #N/A | CB12: =#N/A -> #N/A | CC12: =SUM(BY12:CB12) -> #N/A | CD12: =CC12-BB12 -> #N/A | CE12: =IF(CF12>0,BF12,0) -> 27 | CF12: =IF(BF12>=26,1,0) -> 1 | CH12: Tổ 3 | CI12: =IF(CK3>=98,60000,IF(CK3>95,40000,0)) -> #REF! | CL12: =#N/A -> #N/A | CM12: =#N/A -> #N/A | CN12: =#N/A -> #N/A | CO12: =#N/A -> #N/A | CP12: =SUM(CL12:CO12) -> #N/A | CQ12: =CP12-BC12 -> #N/A | CW12: =BU12 -> 0 | CX12: =BW12 -> 0 | CY12: =IF(COUNT(CW12:CX12)=2,ROUND((CW12+CX12)/2,2),CW12) -> 0
A13: 7 | B13: 1 | C13: 7 | G13: 0 | H13: x | I13: x | K13: x | L13: 0 | M13: x | N13: x | O13: x | P13: x | Q13: x | R13: x | S13: x | T13: x | U13: x | V13: x | W13: x | X13: x | Y13: x | Z13: x | AA13: x | AB13: x | AC13: x | AD13: 0 | AE13: x | AF13: x | AG13: x | AH13: 0 | AI13: x | AJ13: x | AK13: x | AP13: x | BB13: =COUNTIF(G13:U13,"X") -> 12 | BC13: =COUNTIF(V13:AK13,"X") -> 14 | BD13: =COUNTIF(AL13:BA13,"X") -> 1 | BE13: =COUNTIF(AU13:BA13,"x") -> 0 | BF13: =BB13+BC13 -> 26 | BK13: =IF(BO13>=26,1,0) -> 1 | BL13: =(BB13+BC13) -> 26 | BO13: =IF(BT13>0,BF13,0) -> 26 | BT13: =IF(BF13>=26,1,0) -> 1 | BV13: =IF(AND(BU13>0,BU13<=1),50000,IF(AND(BU13>1,BU13<=3),40000,IF(AND(BU13>3,BU13<=5),20000,IF(AND(BU13>5,BU13<=9),0,IF(AND(BU13>9,BU13<=11),-20000,IF(AND(BU13>11,BU13<=13),-40000,IF(BU13>13,-50000,0))))))) -> 0 | BX13: =IF(AND(BW13>0,BW13<=1),1.15,IF(AND(BW13>1,BW13<=3),1.1,IF(AND(BW13>3,BW13<=5),1.05,IF(AND(BW13>5,BW13<=9),1,IF(AND(BW13>9,BW13<=11),-0.05,IF(AND(BW13>11,BW13<=13),-0.1,IF(BW13>13,-0.15,0))))))) -> 0 | BY13: =#N/A -> #N/A | BZ13: =#N/A -> #N/A | CA13: =#N/A -> #N/A | CB13: =#N/A -> #N/A | CC13: =SUM(BY13:CB13) -> #N/A | CD13: =CC13-BB13 -> #N/A | CE13: =IF(CF13>0,BF13,0) -> 26 | CF13: =IF(BF13>=26,1,0) -> 1 | CH13: Tổ 4 | CI13: =IF(CK4>=98,60000,IF(CK4>95,40000,0)) -> #REF! | CL13: =#N/A -> #N/A | CM13: =#N/A -> #N/A | CN13: =#N/A -> #N/A | CO13: =#N/A -> #N/A | CP13: =SUM(CL13:CO13) -> #N/A | CQ13: =CP13-BC13 -> #N/A | CW13: =BU13 -> 0 | CX13: =BW13 -> 0 | CY13: =IF(COUNT(CW13:CX13)=2,ROUND((CW13+CX13)/2,2),CW13) -> 0
A14: 8 | B14: 1 | C14: 8 | G14: x | H14: x | I14: x | K14: x | L14: x | M14: x | N14: x | O14: x | P14: x | Q14: x | R14: x | S14: x | T14: 0 | U14: x | V14: x | W14: x | X14: 0 | Y14: x | Z14: x | AA14: x | AB14: x | AC14: x | AD14: x | AE14: x | AF14: x | AG14: x | AH14: x | AI14: x | AJ14: x | AK14: x | AP14: x | BB14: =COUNTIF(G14:U14,"X") -> 13 | BC14: =COUNTIF(V14:AK14,"X") -> 15 | BD14: =COUNTIF(AL14:BA14,"X") -> 1 | BE14: =COUNTIF(AU14:BA14,"x") -> 0 | BF14: =BB14+BC14 -> 28 | BK14: =IF(BO14>=26,1,0) -> 1 | BL14: =(BB14+BC14) -> 28 | BO14: =IF(BT14>0,BF14,0) -> 28 | BT14: =IF(BF14>=26,1,0) -> 1 | BV14: =IF(AND(BU14>0,BU14<=1),50000,IF(AND(BU14>1,BU14<=3),40000,IF(AND(BU14>3,BU14<=5),20000,IF(AND(BU14>5,BU14<=9),0,IF(AND(BU14>9,BU14<=11),-20000,IF(AND(BU14>11,BU14<=13),-40000,IF(BU14>13,-50000,0))))))) -> 0 | BX14: =IF(AND(BW14>0,BW14<=1),1.15,IF(AND(BW14>1,BW14<=3),1.1,IF(AND(BW14>3,BW14<=5),1.05,IF(AND(BW14>5,BW14<=9),1,IF(AND(BW14>9,BW14<=11),-0.05,IF(AND(BW14>11,BW14<=13),-0.1,IF(BW14>13,-0.15,0))))))) -> 0 | BY14: =#N/A -> #N/A | BZ14: =#N/A -> #N/A | CA14: =#N/A -> #N/A | CB14: =#N/A -> #N/A | CC14: =SUM(BY14:CB14) -> #N/A | CD14: =CC14-BB14 -> #N/A | CE14: =IF(CF14>0,BF14,0) -> 28 | CF14: =IF(BF14>=26,1,0) -> 1 | CH14: Tổ 5 | CI14: =IF(CK5>=98,60000,IF(CK5>95,40000,0)) -> #REF! | CL14: =#N/A -> #N/A | CM14: =#N/A -> #N/A | CN14: =#N/A -> #N/A | CO14: =#N/A -> #N/A | CP14: =SUM(CL14:CO14) -> #N/A | CQ14: =CP14-BC14 -> #N/A | CW14: =BU14 -> 0 | CX14: =BW14 -> 0 | CY14: =IF(COUNT(CW14:CX14)=2,ROUND((CW14+CX14)/2,2),CW14) -> 0
A15: 9 | B15: 1 | C15: 9 | G15: x | H15: x | I15: x | K15: x | L15: x | M15: x | N15: 0 | O15: x | P15: x | Q15: 0 | R15: x | S15: x | T15: x | U15: x | V15: x | W15: 0 | X15: x | Y15: x | Z15: x | AA15: x | AB15: 0 | AC15: x | AD15: x | AE15: x | AF15: x | AG15: x | AH15: x | AI15: x | AJ15: 0 | AK15: x | AP15: x | BB15: =COUNTIF(G15:U15,"X") -> 12 | BC15: =COUNTIF(V15:AK15,"X") -> 13 | BD15: =COUNTIF(AL15:BA15,"X") -> 1 | BE15: =COUNTIF(AU15:BA15,"x") -> 0 | BF15: =BB15+BC15 -> 25 | BK15: =IF(BO15>=26,1,0) -> 0 | BL15: =(BB15+BC15) -> 25 | BO15: =IF(BT15>0,BF15,0) -> 0 | BT15: =IF(BF15>=26,1,0) -> 0 | BV15: =IF(AND(BU15>0,BU15<=1),50000,IF(AND(BU15>1,BU15<=3),40000,IF(AND(BU15>3,BU15<=5),20000,IF(AND(BU15>5,BU15<=9),0,IF(AND(BU15>9,BU15<=11),-20000,IF(AND(BU15>11,BU15<=13),-40000,IF(BU15>13,-50000,0))))))) -> 0 | BX15: =IF(AND(BW15>0,BW15<=1),1.15,IF(AND(BW15>1,BW15<=3),1.1,IF(AND(BW15>3,BW15<=5),1.05,IF(AND(BW15>5,BW15<=9),1,IF(AND(BW15>9,BW15<=11),-0.05,IF(AND(BW15>11,BW15<=13),-0.1,IF(BW15>13,-0.15,0))))))) -> 0 | BY15: =#N/A -> #N/A | BZ15: =#N/A -> #N/A | CA15: =#N/A -> #N/A | CB15: =#N/A -> #N/A | CC15: =SUM(BY15:CB15) -> #N/A | CD15: =CC15-BB15 -> #N/A | CE15: =IF(CF15>0,BF15,0) -> 0 | CF15: =IF(BF15>=26,1,0) -> 0 | CH15: Tổ 6 | CI15: =IF(CK6>=98,60000,IF(CK6>95,40000,0)) -> #REF! | CJ15: =SUM(CI15:CI16) -> #REF! | CL15: =#N/A -> #N/A | CM15: =#N/A -> #N/A | CN15: =#N/A -> #N/A | CO15: =#N/A -> #N/A | CP15: =SUM(CL15:CO15) -> #N/A | CQ15: =CP15-BC15 -> #N/A | CW15: =BU15 -> 0 | CX15: =BW15 -> 0 | CY15: =IF(COUNT(CW15:CX15)=2,ROUND((CW15+CX15)/2,2),CW15) -> 0
A16: 10 | B16: 1 | C16: 10 | G16: x | H16: x | I16: x | K16: 0 | L16: x | M16: x | N16: x | O16: x | P16: x | Q16: x | R16: x | S16: x | T16: x | U16: x | V16: 0 | W16: x | X16: x | Y16: x | Z16: x | AA16: x | AB16: x | AC16: x | AD16: x | AE16: x | AF16: x | AG16: x | AH16: 0 | AI16: x | AJ16: x | AK16: x | AP16: x | BB16: =COUNTIF(G16:U16,"X") -> 13 | BC16: =COUNTIF(V16:AK16,"X") -> 14 | BD16: =COUNTIF(AL16:BA16,"X") -> 1 | BE16: =COUNTIF(AU16:BA16,"x") -> 0 | BF16: =BB16+BC16 -> 27 | BK16: =IF(BO16>=26,1,0) -> 1 | BL16: =(BB16+BC16) -> 27 | BO16: =IF(BT16>0,BF16,0) -> 27 | BT16: =IF(BF16>=26,1,0) -> 1 | BV16: =IF(AND(BU16>0,BU16<=1),50000,IF(AND(BU16>1,BU16<=3),40000,IF(AND(BU16>3,BU16<=5),20000,IF(AND(BU16>5,BU16<=9),0,IF(AND(BU16>9,BU16<=11),-20000,IF(AND(BU16>11,BU16<=13),-40000,IF(BU16>13,-50000,0))))))) -> 0 | BX16: =IF(AND(BW16>0,BW16<=1),1.15,IF(AND(BW16>1,BW16<=3),1.1,IF(AND(BW16>3,BW16<=5),1.05,IF(AND(BW16>5,BW16<=9),1,IF(AND(BW16>9,BW16<=11),-0.05,IF(AND(BW16>11,BW16<=13),-0.1,IF(BW16>13,-0.15,0))))))) -> 0 | BY16: =#N/A -> #N/A | BZ16: =#N/A -> #N/A | CA16: =#N/A -> #N/A | CB16: =#N/A -> #N/A | CC16: =SUM(BY16:CB16) -> #N/A | CD16: =CC16-BB16 -> #N/A | CE16: =IF(CF16>0,BF16,0) -> 27 | CF16: =IF(BF16>=26,1,0) -> 1 | CH16: Tổ 7 | CI16: =IF(CK7>=98,60000,IF(CK7>95,40000,0)) -> #REF! | CL16: =#N/A -> #N/A | CM16: =#N/A -> #N/A | CN16: =#N/A -> #N/A | CO16: =#N/A -> #N/A | CP16: =SUM(CL16:CO16) -> #N/A | CQ16: =CP16-BC16 -> #N/A | CW16: =BU16 -> 0 | CX16: =BW16 -> 0 | CY16: =IF(COUNT(CW16:CX16)=2,ROUND((CW16+CX16)/2,2),CW16) -> 0
A17: 11 | B17: 1 | C17: 11 | G17: x | H17: x | I17: 0 | K17: 0 | L17: x | M17: x | N17: x | O17: x | P17: x | Q17: x | R17: x | S17: x | T17: x | U17: x | V17: x | W17: x | X17: x | Y17: x | Z17: x | AA17: x | AB17: x | AC17: 0 | AD17: x | AE17: x | AF17: x | AG17: x | AH17: x | AI17: x | AJ17: x | AK17: x | AP17: x | BB17: =COUNTIF(G17:U17,"X") -> 12 | BC17: =COUNTIF(V17:AK17,"X") -> 15 | BD17: =COUNTIF(AL17:BA17,"X") -> 1 | BE17: =COUNTIF(AU17:BA17,"x") -> 0 | BF17: =BB17+BC17 -> 27 | BK17: =IF(BO17>=26,1,0) -> 1 | BL17: =(BB17+BC17) -> 27 | BO17: =IF(BT17>0,BF17,0) -> 27 | BT17: =IF(BF17>=26,1,0) -> 1 | BV17: =IF(AND(BU17>0,BU17<=1),50000,IF(AND(BU17>1,BU17<=3),40000,IF(AND(BU17>3,BU17<=5),20000,IF(AND(BU17>5,BU17<=9),0,IF(AND(BU17>9,BU17<=11),-20000,IF(AND(BU17>11,BU17<=13),-40000,IF(BU17>13,-50000,0))))))) -> 0 | BX17: =IF(AND(BW17>0,BW17<=1),1.15,IF(AND(BW17>1,BW17<=3),1.1,IF(AND(BW17>3,BW17<=5),1.05,IF(AND(BW17>5,BW17<=9),1,IF(AND(BW17>9,BW17<=11),-0.05,IF(AND(BW17>11,BW17<=13),-0.1,IF(BW17>13,-0.15,0))))))) -> 0 | BY17: =#N/A -> #N/A | BZ17: =#N/A -> #N/A | CA17: =#N/A -> #N/A | CB17: =#N/A -> #N/A | CC17: =SUM(BY17:CB17) -> #N/A | CD17: =CC17-BB17 -> #N/A | CE17: =IF(CF17>0,BF17,0) -> 27 | CF17: =IF(BF17>=26,1,0) -> 1 | CH17: Tổ 8 | CI17: =IF(CK8>=98,60000,IF(CK8>95,40000,0)) -> 60000 | CJ17: =SUM(CI13:CI14,CI17) -> #REF! | CL17: =#N/A -> #N/A | CM17: =#N/A -> #N/A | CN17: =#N/A -> #N/A | CO17: =#N/A -> #N/A | CP17: =SUM(CL17:CO17) -> #N/A | CQ17: =CP17-BC17 -> #N/A | CW17: =BU17 -> 0 | CX17: =BW17 -> 0 | CY17: =IF(COUNT(CW17:CX17)=2,ROUND((CW17+CX17)/2,2),CW17) -> 0
A18: 12 | B18: 1 | C18: 12 | G18: x | H18: x | I18: x | K18: x | L18: x | M18: 0 | N18: x | O18: 0 | P18: x | Q18: x | R18: x | S18: x | T18: x | U18: x | V18: x | W18: x | X18: x | Y18: x | Z18: x | AA18: x | AB18: 0 | AC18: x | AD18: x | AE18: x | AF18: x | AG18: 0 | AH18: x | AI18: x | AJ18: 0 | AK18: x | AP18: x | BB18: =COUNTIF(G18:U18,"X") -> 12 | BC18: =COUNTIF(V18:AK18,"X") -> 13 | BD18: =COUNTIF(AL18:BA18,"X") -> 1 | BE18: =COUNTIF(AU18:BA18,"x") -> 0 | BF18: =BB18+BC18 -> 25 | BK18: =IF(BO18>=26,1,0) -> 0 | BL18: =(BB18+BC18) -> 25 | BO18: =IF(BT18>0,BF18,0) -> 0 | BT18: =IF(BF18>=26,1,0) -> 0 | BV18: =IF(AND(BU18>0,BU18<=1),50000,IF(AND(BU18>1,BU18<=3),40000,IF(AND(BU18>3,BU18<=5),20000,IF(AND(BU18>5,BU18<=9),0,IF(AND(BU18>9,BU18<=11),-20000,IF(AND(BU18>11,BU18<=13),-40000,IF(BU18>13,-50000,0))))))) -> 0 | BX18: =IF(AND(BW18>0,BW18<=1),1.15,IF(AND(BW18>1,BW18<=3),1.1,IF(AND(BW18>3,BW18<=5),1.05,IF(AND(BW18>5,BW18<=9),1,IF(AND(BW18>9,BW18<=11),-0.05,IF(AND(BW18>11,BW18<=13),-0.1,IF(BW18>13,-0.15,0))))))) -> 0 | BY18: =#N/A -> #N/A | BZ18: =#N/A -> #N/A | CA18: =#N/A -> #N/A | CB18: =#N/A -> #N/A | CC18: =SUM(BY18:CB18) -> #N/A | CD18: =CC18-BB18 -> #N/A | CE18: =IF(CF18>0,BF18,0) -> 0 | CF18: =IF(BF18>=26,1,0) -> 0 | CG18: 42 | CH18: Tổ 9 | CI18: =IF(CK18>=98,60000,IF(CK18>95,40000,0)) -> #REF! | CJ18: =#REF! -> #REF! | CK18: =ROUND((SUM(CJ18)/CG18/$CF$1)*100,1) -> #REF! | CL18: =#N/A -> #N/A | CM18: =#N/A -> #N/A | CN18: =#N/A -> #N/A | CO18: =#N/A -> #N/A | CP18: =SUM(CL18:CO18) -> #N/A | CQ18: =CP18-BC18 -> #N/A | CW18: =BU18 -> 0 | CX18: =BW18 -> 0 | CY18: =IF(COUNT(CW18:CX18)=2,ROUND((CW18+CX18)/2,2),CW18) -> 0
A19: 13 | B19: 1 | C19: 13 | G19: 0 | H19: x | I19: x | K19: 0 | L19: x | M19: 0 | N19: x | O19: x | P19: x | Q19: x | R19: x | S19: x | T19: x | U19: x | V19: x | W19: x | X19: x | Y19: x | Z19: x | AA19: x | AB19: x | AC19: x | AD19: x | AE19: x | AF19: 0 | AG19: x | AH19: x | AI19: x | AJ19: x | AK19: x | AP19: x | BB19: =COUNTIF(G19:U19,"X") -> 11 | BC19: =COUNTIF(V19:AK19,"X") -> 15 | BD19: =COUNTIF(AL19:BA19,"X") -> 1 | BE19: =COUNTIF(AU19:BA19,"x") -> 0 | BF19: =BB19+BC19 -> 26 | BK19: =IF(BO19>=26,1,0) -> 1 | BL19: =(BB19+BC19) -> 26 | BO19: =IF(BT19>0,BF19,0) -> 26 | BT19: =IF(BF19>=26,1,0) -> 1 | BV19: =IF(AND(BU19>0,BU19<=1),50000,IF(AND(BU19>1,BU19<=3),40000,IF(AND(BU19>3,BU19<=5),20000,IF(AND(BU19>5,BU19<=9),0,IF(AND(BU19>9,BU19<=11),-20000,IF(AND(BU19>11,BU19<=13),-40000,IF(BU19>13,-50000,0))))))) -> 0 | BX19: =IF(AND(BW19>0,BW19<=1),1.15,IF(AND(BW19>1,BW19<=3),1.1,IF(AND(BW19>3,BW19<=5),1.05,IF(AND(BW19>5,BW19<=9),1,IF(AND(BW19>9,BW19<=11),-0.05,IF(AND(BW19>11,BW19<=13),-0.1,IF(BW19>13,-0.15,0))))))) -> 0 | BY19: =#N/A -> #N/A | BZ19: =#N/A -> #N/A | CA19: =#N/A -> #N/A | CB19: =#N/A -> #N/A | CC19: =SUM(BY19:CB19) -> #N/A | CD19: =CC19-BB19 -> #N/A | CE19: =IF(CF19>0,BF19,0) -> 26 | CF19: =IF(BF19>=26,1,0) -> 1 | CG19: 42 | CH19: Tổ 10 | CI19: =IF(CK19>=98,60000,IF(CK19>95,40000,0)) -> 60000 | CJ19: =BF399 -> 2394 | CK19: =ROUND((SUM(CJ19)/CG19/$CF$1)*100,1) -> 183.9 | CL19: =#N/A -> #N/A | CM19: =#N/A -> #N/A | CN19: =#N/A -> #N/A | CO19: =#N/A -> #N/A | CP19: =SUM(CL19:CO19) -> #N/A | CQ19: =CP19-BC19 -> #N/A | CW19: =BU19 -> 0 | CX19: =BW19 -> 0 | CY19: =IF(COUNT(CW19:CX19)=2,ROUND((CW19+CX19)/2,2),CW19) -> 0
A20: 14 | B20: 1 | C20: 14 | G20: 0 | H20: 0 | I20: x | K20: 0 | L20: 0 | M20: x | N20: x | O20: x | P20: x | Q20: x | R20: x | S20: x | T20: x | U20: x | V20: x | W20: x | X20: x | Y20: x | Z20: x | AA20: x | AB20: x | AC20: x | AD20: x | AE20: x | AF20: x | AG20: 0 | AH20: x | AI20: x | AJ20: x | AK20: x | AP20: x | BB20: =COUNTIF(G20:U20,"X") -> 10 | BC20: =COUNTIF(V20:AK20,"X") -> 15 | BD20: =COUNTIF(AL20:BA20,"X") -> 1 | BE20: =COUNTIF(AU20:BA20,"x") -> 0 | BF20: =BB20+BC20 -> 25 | BK20: =IF(BO20>=26,1,0) -> 0 | BL20: =(BB20+BC20) -> 25 | BO20: =IF(BT20>0,BF20,0) -> 0 | BT20: =IF(BF20>=26,1,0) -> 0 | BV20: =IF(AND(BU20>0,BU20<=1),50000,IF(AND(BU20>1,BU20<=3),40000,IF(AND(BU20>3,BU20<=5),20000,IF(AND(BU20>5,BU20<=9),0,IF(AND(BU20>9,BU20<=11),-20000,IF(AND(BU20>11,BU20<=13),-40000,IF(BU20>13,-50000,0))))))) -> 0 | BX20: =IF(AND(BW20>0,BW20<=1),1.15,IF(AND(BW20>1,BW20<=3),1.1,IF(AND(BW20>3,BW20<=5),1.05,IF(AND(BW20>5,BW20<=9),1,IF(AND(BW20>9,BW20<=11),-0.05,IF(AND(BW20>11,BW20<=13),-0.1,IF(BW20>13,-0.15,0))))))) -> 0 | BY20: =#N/A -> #N/A | BZ20: =#N/A -> #N/A | CA20: =#N/A -> #N/A | CB20: =#N/A -> #N/A | CC20: =SUM(BY20:CB20) -> #N/A | CD20: =CC20-BB20 -> #N/A | CE20: =IF(CF20>0,BF20,0) -> 0 | CF20: =IF(BF20>=26,1,0) -> 0 | CG20: 45 | CH20: Tổ 11 | CI20: =IF(CK20>=98,60000,IF(CK20>95,40000,0)) -> 60000 | CJ20: =BF497 -> 2669 | CK20: =ROUND((SUM(CJ20)/CG20/$CF$1)*100,1) -> 191.3 | CL20: =#N/A -> #N/A | CM20: =#N/A -> #N/A | CN20: =#N/A -> #N/A | CO20: =#N/A -> #N/A | CP20: =SUM(CL20:CO20) -> #N/A | CQ20: =CP20-BC20 -> #N/A | CW20: =BU20 -> 0 | CX20: =BW20 -> 0 | CY20: =IF(COUNT(CW20:CX20)=2,ROUND((CW20+CX20)/2,2),CW20) -> 0
A21: 15 | B21: 1 | C21: 15 | G21: 0 | H21: 0 | I21: x | K21: x | L21: x | M21: x | N21: x | O21: x | P21: x | Q21: x | R21: x | S21: x | T21: x | U21: x | V21: x | W21: x | X21: x | Y21: x | Z21: x | AA21: x | AB21: x | AC21: x | AD21: x | AE21: x | AF21: x | AG21: 0 | AH21: x | AI21: x | AJ21: x | AK21: x | AP21: x | BB21: =COUNTIF(G21:U21,"X") -> 12 | BC21: =COUNTIF(V21:AK21,"X") -> 15 | BD21: =COUNTIF(AL21:BA21,"X") -> 1 | BE21: =COUNTIF(AU21:BA21,"x") -> 0 | BF21: =BB21+BC21 -> 27 | BK21: =IF(BO21>=26,1,0) -> 1 | BL21: =(BB21+BC21) -> 27 | BO21: =IF(BT21>0,BF21,0) -> 27 | BT21: =IF(BF21>=26,1,0) -> 1 | BV21: =IF(AND(BU21>0,BU21<=1),50000,IF(AND(BU21>1,BU21<=3),40000,IF(AND(BU21>3,BU21<=5),20000,IF(AND(BU21>5,BU21<=9),0,IF(AND(BU21>9,BU21<=11),-20000,IF(AND(BU21>11,BU21<=13),-40000,IF(BU21>13,-50000,0))))))) -> 0 | BX21: =IF(AND(BW21>0,BW21<=1),1.15,IF(AND(BW21>1,BW21<=3),1.1,IF(AND(BW21>3,BW21<=5),1.05,IF(AND(BW21>5,BW21<=9),1,IF(AND(BW21>9,BW21<=11),-0.05,IF(AND(BW21>11,BW21<=13),-0.1,IF(BW21>13,-0.15,0))))))) -> 0 | BY21: =#N/A -> #N/A | BZ21: =#N/A -> #N/A | CA21: =#N/A -> #N/A | CB21: =#N/A -> #N/A | CC21: =SUM(BY21:CB21) -> #N/A | CD21: =CC21-BB21 -> #N/A | CE21: =IF(CF21>0,BF21,0) -> 27 | CF21: =IF(BF21>=26,1,0) -> 1 | CH21: t 1.2.3 | CI21: 420 | CL21: =#N/A -> #N/A | CM21: =#N/A -> #N/A | CN21: =#N/A -> #N/A | CO21: =#N/A -> #N/A | CP21: =SUM(CL21:CO21) -> #N/A | CQ21: =CP21-BC21 -> #N/A | CW21: =BU21 -> 0 | CX21: =BW21 -> 0 | CY21: =IF(COUNT(CW21:CX21)=2,ROUND((CW21+CX21)/2,2),CW21) -> 0
A22: 16 | B22: 1 | C22: 16 | G22: 0 | H22: 0 | I22: x | K22: x | L22: x | M22: x | N22: x | O22: x | P22: x | Q22: x | R22: x | S22: x | T22: x | U22: x | V22: x | W22: x | X22: x | Y22: x | Z22: x | AA22: x | AB22: x | AC22: x | AD22: x | AE22: x | AF22: x | AG22: x | AH22: x | AI22: x | AJ22: x | AK22: x | AP22: 0 | AS22: x | BB22: =COUNTIF(G22:U22,"X") -> 12 | BC22: =COUNTIF(V22:AK22,"X") -> 16 | BD22: =COUNTIF(AL22:BA22,"X") -> 1 | BE22: =COUNTIF(AU22:BA22,"x") -> 0 | BF22: =BB22+BC22 -> 28 | BK22: =IF(BO22>=26,1,0) -> 1 | BL22: =(BB22+BC22) -> 28 | BO22: =IF(BT22>0,BF22,0) -> 28 | BT22: =IF(BF22>=26,1,0) -> 1 | BV22: =IF(AND(BU22>0,BU22<=1),50000,IF(AND(BU22>1,BU22<=3),40000,IF(AND(BU22>3,BU22<=5),20000,IF(AND(BU22>5,BU22<=9),0,IF(AND(BU22>9,BU22<=11),-20000,IF(AND(BU22>11,BU22<=13),-40000,IF(BU22>13,-50000,0))))))) -> 0 | BX22: =IF(AND(BW22>0,BW22<=1),1.15,IF(AND(BW22>1,BW22<=3),1.1,IF(AND(BW22>3,BW22<=5),1.05,IF(AND(BW22>5,BW22<=9),1,IF(AND(BW22>9,BW22<=11),-0.05,IF(AND(BW22>11,BW22<=13),-0.1,IF(BW22>13,-0.15,0))))))) -> 0 | BY22: =#N/A -> #N/A | BZ22: =#N/A -> #N/A | CA22: =#N/A -> #N/A | CB22: =#N/A -> #N/A | CC22: =SUM(BY22:CB22) -> #N/A | CD22: =CC22-BB22 -> #N/A | CE22: =IF(CF22>0,BF22,0) -> 28 | CF22: =IF(BF22>=26,1,0) -> 1 | CH22: T 4.5.8 | CI22: 440 | CL22: =#N/A -> #N/A | CM22: =#N/A -> #N/A | CN22: =#N/A -> #N/A | CO22: =#N/A -> #N/A | CP22: =SUM(CL22:CO22) -> #N/A | CQ22: =CP22-BC22 -> #N/A | CW22: =BU22 -> 0 | CX22: =BW22 -> 0 | CY22: =IF(COUNT(CW22:CX22)=2,ROUND((CW22+CX22)/2,2),CW22) -> 0
A23: 17 | B23: 1 | C23: 17 | G23: 0 | H23: x | I23: x | K23: x | L23: x | M23: 0 | N23: x | O23: x | P23: x | Q23: x | R23: x | S23: x | T23: x | U23: 0 | V23: x | W23: x | X23: x | Y23: x | Z23: x | AA23: x | AB23: x | AC23: x | AD23: x | AE23: x | AF23: x | AG23: x | AH23: x | AI23: 0 | AJ23: x | AK23: x | AP23: x | BB23: =COUNTIF(G23:U23,"X") -> 11 | BC23: =COUNTIF(V23:AK23,"X") -> 15 | BD23: =COUNTIF(AL23:BA23,"X") -> 1 | BE23: =COUNTIF(AU23:BA23,"x") -> 0 | BF23: =BB23+BC23 -> 26 | BK23: =IF(BO23>=26,1,0) -> 1 | BL23: =(BB23+BC23) -> 26 | BO23: =IF(BT23>0,BF23,0) -> 26 | BT23: =IF(BF23>=26,1,0) -> 1 | BV23: =IF(AND(BU23>0,BU23<=1),50000,IF(AND(BU23>1,BU23<=3),40000,IF(AND(BU23>3,BU23<=5),20000,IF(AND(BU23>5,BU23<=9),0,IF(AND(BU23>9,BU23<=11),-20000,IF(AND(BU23>11,BU23<=13),-40000,IF(BU23>13,-50000,0))))))) -> 0 | BX23: =IF(AND(BW23>0,BW23<=1),1.15,IF(AND(BW23>1,BW23<=3),1.1,IF(AND(BW23>3,BW23<=5),1.05,IF(AND(BW23>5,BW23<=9),1,IF(AND(BW23>9,BW23<=11),-0.05,IF(AND(BW23>11,BW23<=13),-0.1,IF(BW23>13,-0.15,0))))))) -> 0 | BY23: =#N/A -> #N/A | BZ23: =#N/A -> #N/A | CA23: =#N/A -> #N/A | CB23: =#N/A -> #N/A | CC23: =SUM(BY23:CB23) -> #N/A | CD23: =CC23-BB23 -> #N/A | CE23: =IF(CF23>0,BF23,0) -> 26 | CF23: =IF(BF23>=26,1,0) -> 1 | CH23: T 6.7 | CI23: 505 | CL23: =#N/A -> #N/A | CM23: =#N/A -> #N/A | CN23: =#N/A -> #N/A | CO23: =#N/A -> #N/A | CP23: =SUM(CL23:CO23) -> #N/A | CQ23: =CP23-BC23 -> #N/A | CW23: =BU23 -> 0 | CX23: =BW23 -> 0 | CY23: =IF(COUNT(CW23:CX23)=2,ROUND((CW23+CX23)/2,2),CW23) -> 0
