Workbook

Sheet BCD D1T1
A1: ក្រុមហ៊ុន កៅស៊ូ មេគង្គ ខូ អិលធីឌី | G1: ព្រះរាជាណាចក្រ កម្ពុជា
A2: CÔNG TY TNHH CAO SU MEKONG | G2: VƯƠNG QUỐC CAMPUCHIA
A3: រោងចក្រកែច្នៃ | G3: ជាតិ សាសនា ព្រះមហាក្សត្រ
A4: XƯỞNG CHẾ BIẾN | G4: Dân tộc - Tôn giáo - Quốc vương
A6: តារាងតុល្យភាពបំណុល
A7: បៀវត្សកម្មកររោងចក្រកែច្នៃជ័រកៅស៊ូ ខែ ០១ ឆ្នាំ​ ២០២៦ (វគ្គទី២)
A8: BẢNG CÂN ĐỐI CÔNG NỢ
A9: LƯƠNG CÔNG NHÂN XƯỞNG CHẾ BIẾN THÁNG 01 NĂM 2026 (ĐỢT 2)
B11: I/ សរុបបៀវត្សខែ ០១/២០២៦ (Tổng lương tháng 01/2026): | G11: =G12+G13 -> 94283904 | H11: Riel | J11: ='TTL dot​2 (31947)'!K84 -> 94283904
B12: 1/ ប្រាក់បៀវត្សទី ១ (Tiền lương đợt 1) ៖ | G12: ='TTL dot​2 (31947)'!G84 -> 45775579 | H12: Riel | J12: =#REF! -> #REF!
B13: 2/ ប្រាក់បៀវត្សទី ២ (Tiền lương đợt 2) ៖ | G13: ='TTL dot​2 (31947)'!I84 -> 48508325 | H13: Riel | J13: ='[1]TTL dot 1 (31948)'!I84 -> 0
B14: II/ ប្រាក់បានទទួល (Các khoản đã nhận): | G14: =SUM(G15:G16) -> 45775579 | H14: Riel | J14: =G14+G17 -> 47266149
B15: 1/ទូទាត់ប្រាក់បៀវត្សលើកទី ១ (Thanh toán lương đợt 1) ៖ | G15: ='TTL dot​2 (31947)'!L84 -> 44843116 | H15: Riel
B16: 2/ ភាគទានប្រាក់សោធនវគ្គទី១​​​/ BHXH Đợt 1 | G16: ='TTL dot​2 (31947)'!M84 -> 932463 | H16: Riel
B17: III/ ប្រាក់ត្រូវប្រមូល (Các khoản phải thu): | G17: =SUM(G18:G21) -> 1490570 | H17: Riel | J17: ='TTL dot​2 (31947)'!Q84 -> 47266149
B18: 1/ ពន្ធលើប្រាក់បៀវត្ស (Thuế TNCN): | G18: ='TTL dot​2 (31947)'!P84 -> 1011620 | H18: Riel
B19: 2/ ភាគទានប្រាក់សោធនវគ្គទី១​​​/ BHXH Đợt 1 | G19: 0 | H19: Riel
B20: 2/ ភាគទានប្រាក់សោធនវគ្គទី២​​​/ BHXH Đợt 2 | G20: ='TTL dot​2 (31947)'!O84 -> 478950 | H20: Riel
B21: 3/ បុរេប្រទានផ្ទាល់ខ្លួន (Tạm ứng cá nhân): | G21: 0 | H21: Riel
B22: IV/ ប្រាក់ត្រូវទទួល (Thực nhận): | G22: =G23 -> 47017755 | H22: Riel | M22: សាមសិបប្រាំបួនលាន ប្រាំម៉ឺន ប្រាំពីរពាន់ ប្រាំរយ ហាសិបបួន រៀល
B23: 1/ ប្រាក់បៀវត្សត្រូវទទួល (Tiền lương thực nhận): | G23: =ROUND(G11-G14-G17,0) -> 47017755 | H23: Riel | J23: ='TTL dot​2 (31947)'!R84 -> 47017755 | M23: ( Bằng chữ: Ba mươi chín triệu không trăm năm mươi bảy nghìn năm trăm năm mươi bốn riel)
A25: សែសិបប្រាំពីរលាន សូន្យរយដប់ប្រាំពីរពាន់ ប្រាំពីររយហាសិបប្រាំរៀលគត។
A26: ( Bằng chữ: Bốn mươi bảy triệu không trăm mươi bảy nghìn bảy trăm năm mươi lăm riel)
F28: កំពង់ធំ, ថ្ងៃ (ngày) 31 ខែ (tháng) 01 ឆ្នាំ (năm) 2026
A29: ផ.ហិរ.គណនេយ្យ | E29: រោងចក្រកែច្នៃ | G29: អ្នករៀបចំ
A30: PHÒNG TCKT | E30: XƯỞNG CHẾ BIẾN | G30: Lập biểu
G34: Bùi Ngọc Triệu
A35: អនុម័តនាយកក្រុមហ៊ុន/DUYỆT GIÁM ĐỐC

Sheet BPTL D1T1
A2: ក្រុមហ៊ុន កៅស៊ូ មេគង្គ ខូ អិលធីឌី | G2: ព្រះរាជាណាចក្រ កម្ពុជា
A3: CÔNG TY TNHH CAO SU MEKONG | G3: VƯƠNG QUỐC CAMPUCHIA
A4: រោងចក្រកែច្នៃ | G4: ជាតិ សាសនា ព្រះមហាក្សត្រ
A5: XƯỞNG CHẾ BIẾN | G5: Dân tộc - Tôn giáo - Quốc vương
A7: តារាងបែងចែកប្រាក់បៀវត្សកម្មករ​រោងចក្រកែច្នៃជ័រកៅស៊ូខែ ០១ ឆ្នាំ​ ២០២៦(វគ្គទី ២)
A8: BẢNG PHÂN TOÁN LƯƠNG CÔNG NHÂN XƯỞNG CHẾ BIẾN THÁNG 01 NĂM 2026​​​ ( ĐỢT 2)
H10: ឯកតា/ | I10: ĐVT៖ Riel
A11: ល.រ | B11: រាយនាមការងារ | C11: តម្លៃ | D11: កម្លាំងថ្ងៃធម្មតា Công ngày | F11: កម្លាំងថែមម៉ោង Công làm thêm giờ | H11: សរុប | I11: កំណត់ចំណាំ
A12: STT | B12: Hạng mục công việc | C12: Đơn​ giá | D12: កម្លាំង Công | E12: ជាប្រាក់ Thành tiền | F12: កម្លាំង Công | G12: ជាប្រាក់ Thành tiền | H12: Tổng cộng | I12: Ghi chú
A13: A | B13: B | C13: 1 | D13: 2 | E13: 3=1x2 | F13: 4 | G13: 5=4x1 | H13: 6=3+5 | I13: 7
A14: I/ សរុបបៀវត្សខែ ០១/២០២៦ (Tổng lương tháng 01/2026): | E14: =SUM(E15:E22) -> 48508325 | H14: =SUM(H15:H22) -> 48508325
A15: 1 | B15: ជ័រកិន /Mủ cán vắt ( Gồm phụ cấp phụ trợ trực tiếp 10%) | C15: 31947 | D15: ='BTHKL D1 T1 (26)'!F12 -> 680.41 | E15: =ROUND(D15*C15,0) -> 21737058 | H15: =G15+E15 -> 21737058
A16: =+A15+1 -> 2 | B16: ជ័រសម្រេច/Mủ Thành phẩm (Gồm phụ cấp phụ trợ trực tiếp 15%) | C16: 31947 | D16: ='BTHKL D1 T1 (26)'!F13 -> 398.63 | E16: =ROUND(D16*C16,0) -> 12735033 | H16: =G16+E16 -> 12735033
A17: =+A16+1 -> 3 | B17: សន្ដិសុខការពារ​​​​​ (Bảo vệ) | C17: 31947 | D17: ='BTHKL D1 T1 (26)'!F14 -> 28.55 | E17: =ROUND(D17*C17,0) -> 912087 | H17: =G17+E17 -> 912087 | K17: =1*0.9391*C17 -> 30001.428 | L17: =SUM(#REF!)-K17 -> #REF! | M17: =H17-L17 -> #REF!
A18: =+A17+1 -> 4 | B18: កម្មករ មេកានិច (Công nhân cơ khí) | C18: 31947 | D18: ='BTHKL D1 T1 (26)'!F17 -> 57.6 | E18: =ROUND(D18*C18,0) -> 1840147 | H18: =G18+E18 -> 1840147 | K18: =33.17*C17 -> 1059682 | L18: =SUM(H18:H19) -> 5120145 | M18: =SUM(#REF!) -> #REF!
A19: =+A18+1 -> 5 | B19: អ្នកបើកឡាន (Tài xế) | C19: 31947 | D19: ='BTHKL D1 T1 (26)'!F18 -> 102.67 | E19: =ROUND(D19*C19,0) -> 3279998 | H19: =G19+E19 -> 3279998 | K19: =24.42*C22 -> 780145.74 | L19: =L18+K18+K19 -> 6959972.7
A20: =+A19+1 -> 6 | B20: សម្អាត (Vệ sinh) | C20: 31947 | D20: ='BTHKL D1 T1 (26)'!F19 -> 26.2 | E20: =ROUND(D20*C20,0) -> 837011 | H20: =G20+E20 -> 837011
A21: =+A20+1 -> 7 | B21: អ្នកធ្វើការមិនរើសមុខ (Tạp vụ) | C21: 31947 | D21: ='BTHKL D1 T1 (26)'!F20 -> 14.68 | E21: =ROUND(D21*C21,0) -> 468982 | H21: =G21+E21 -> 468982 | L21: =ROUND(D23*C22,0) -> 48508325
A22: =+A21+1 -> 8 | B22: កម្លាំងផ្សេង (Công Khác) | C22: 31947 | D22: ='BTHKL D1 T1 (26)'!F21 -> 209.66 | E22: =ROUND(D22*C22,0)+1 -> 6698009 | H22: =G22+E22 -> 6698009 | L22: ='TTL dot​2 (31947)'!I84 -> 48508325
B23: សរុប (Tổng cộng) | D23: =SUM(D15:D22) -> 1518.4 | E23: =SUM(E15:E22) -> 48508325 | H23: =G23+E23 -> 48508325 | L23: =L22-L21 -> 0
A25: សែសិបប្រាំបីលាន ប្រាំរយប្រាំបីពាន់ បីរយម្ភៃប្រាំ រៀលគត់។ | L25: =A25=[2]Sheet1!$N$9 -> FALSE
A26: ( Bằng chữ: Bốn mươi tám triệu, năm trăm lẻ tám nghìn ba trăm hai mươi lăm riel)
E28: កំពង់ធំ, ថ្ងៃ (ngày) 31 ខែ (tháng) 01 ឆ្នាំ (năm) 2026 | L28: សរុបបៀវត្សខែ ០៤/២០២៥ (Tổng lương tháng 04/2025)
A29: រោងចក្រកែច្នៃ/ XƯỞNG CHẾ BIẾN | E29: អ្នករៀបចំ/ LẬP BIỂU
E32: Bùi Ngọc Triệu
A33: ផ្នែក ចាត់តាំង រដ្ឋបាល/ PHÒNG TCHC | E33: ផ.ហិរ.គណនេយ្យ / PHÒNG TCKT
A38: អនុម័តនាយកក្រុមហ៊ុន/ DUYỆT GIÁM ĐỐC

Sheet BCC D1(26)
A1: ក្រុមហ៊ុន កៅស៊ូ មេគង្គ ខូ អិលធីឌី | P1: ព្រះរាជាណាចក្រ កម្ពុជា
A2: CÔNG TY TNHH CAO SU MEKONG | P2: VƯƠNG QUỐC CAMPUCHIA
A3: រោងចក្រកែច្នៃ | P3: ជាតិ សាសនា ព្រះមហាក្សត្រ
A4: XƯỞNG CHẾ BIẾN | P4: Dân tộc - Tôn giáo - Quốc vương
A6: តារាងវត្តមានកម្មកររោងចក្រកែច្នៃជ័រកៅស៊ូ
A7: ថ្ងៃ ១៦ ដល់ ៣១ ខែ ០១ ឆ្នាំ ២០២៦ (វគ្គទី ២)
A8: BẢNG CHẤM CÔNG CÔNG NHÂN XƯỞNG CHẾ BIẾN
A9: NGÀY 16 ĐẾN ​31 THÁNG 01 NĂM 2026 (ĐỢT 2) | Z9: =COUNTIF(F9:T9,"-") -> 0
A11: ល.រ STT | B11: ត្រកូលនិងឈ្មោះ | C11: HỌ VÀ TÊN | D11: លេខអត្តសញ្ញាណ​បណ្ណ Số CMND | E11: ថ្ងៃខែឆ្នាំកំណើត Năm sinh | F11: 16 | G11: =F11+1 -> 17 | H11: =G11+1 -> 18 | I11: =H11+1 -> 19 | J11: =I11+1 -> 20 | K11: =J11+1 -> 21 | L11: =K11+1 -> 22 | M11: =L11+1 -> 23 | N11: =M11+1 -> 24 | ... U11: =T11+1 -> 31 | V11: ប្រាក់ថ្ងៃបុណ្យភ្ជុំបិណ្ឌ (Tiền lễ dương lịch 1/1/2026) | W11: មី និងប្រេងឆាឲ្យកម្មករ (Mì, dầu ăn cho CN) | X11: សរុប TỔNG CỘNG | Y11: សម្គាល់ GHI CHÚ | Z11: Vắng Đ 1 | AA11: Vắng Đ 2
A12: 1 | B12: រិន ច្រិប | C12: RIN CHRIB | D12: 150952531 | E12: 32274 | F12: X | G12: X | I12: X | J12: X | K12: X | L12: X | M12: X | N12: X | P12: - | Q12: - | R12: X | S12: X | T12: X | U12: X | V12: 1 | W12: =IF(SUM(Z12:AA12)<=2,1,0) -> 0 | X12: =COUNTIF(F12:U12,"X")+0.5*COUNTIF(F12:U12,"/")+COUNTIF(F12:U12,"R1")+COUNTIF(F12:U12,"R")+COUNTIF(F12:U12,"R")+COUNTIF(F12:U12,"Xcv") -> 12 | Z12: 1 | AA12: =COUNTIF(F12:U12,"-") -> 2 | AB12: =ROUND(AD12/AC12,4) -> 0.0909 | AC12: 11 | AD12: =V12 -> 1 | AE12: =ROUND(AD12*31947,0) -> 31947
A13: =+A12+1 -> 2 | B13: កែវ សម្បត្តិ | C13: KEO SAMBATH | D13: 110471355 | E13: 27485 | F13: X | G13: X | I13: X | J13: X | K13: X | L13: X | M13: X | N13: X | P13: X | Q13: X | R13: X | S13: X | T13: X | U13: X | V13: 1 | W13: =IF(SUM(Z13:AA13)<=2,1,0) -> 1 | X13: =COUNTIF(F13:U13,"X")+0.5*COUNTIF(F13:U13,"/")+COUNTIF(F13:U13,"R1")+COUNTIF(F13:U13,"R")+COUNTIF(F13:U13,"R")+COUNTIF(F13:U13,"Xcv") -> 14 | Z13: 0 | AA13: =COUNTIF(F13:U13,"-") -> 0 | AB13: =ROUND(AD13/AC13,4) -> 0.0909 | AC13: 11 | AD13: =V13 -> 1 | AE13: =ROUND(AD13*31947,0) -> 31947
A14: =+A13+1 -> 3 | B14: ផន ឃី | C14: PHORN KHY | D14: 150981478 | E14: 28166 | F14: - | G14: X | I14: X | J14: X | K14: X | L14: X | M14: X | N14: X | P14: X | Q14: X | R14: X | S14: X | T14: X | U14: X | V14: 1 | W14: =IF(SUM(Z14:AA14)<=2,1,0) -> 1 | X14: =COUNTIF(F14:U14,"X")+0.5*COUNTIF(F14:U14,"/")+COUNTIF(F14:U14,"R1")+COUNTIF(F14:U14,"R")+COUNTIF(F14:U14,"R")+COUNTIF(F14:U14,"Xcv") -> 13 | Z14: 0 | AA14: =COUNTIF(F14:U14,"-") -> 1 | AB14: =ROUND(AD14/AC14,4) -> 0.0845 | AC14: 10 | AD14: =V14*0.8451 -> 0.8451 | AE14: =ROUND(AD14*31947,0) -> 26998
A15: =+A14+1 -> 4 | B15: ថន ម៉ន | C15: THORN MORN | D15: 150644309 | E15: 30376 | F15: X | G15: X | I15: X | J15: X | K15: X | L15: X | M15: X | N15: X | P15: X | Q15: X | R15: X | S15: X | T15: X | U15: X | V15: 1 | W15: =IF(SUM(Z15:AA15)<=2,1,0) -> 1 | X15: =COUNTIF(F15:U15,"X")+0.5*COUNTIF(F15:U15,"/")+COUNTIF(F15:U15,"R1")+COUNTIF(F15:U15,"R")+COUNTIF(F15:U15,"R")+COUNTIF(F15:U15,"Xcv") -> 14 | Z15: 0 | AA15: =COUNTIF(F15:T15,"-") -> 0 | AB15: =ROUND(AD15/AC15,4) -> 0.1138 | AC15: 11 | AD15: =V15*1.2521 -> 1.2521 | AE15: =ROUND(AD15*31947,0) -> 40001
B16: ថន ម៉ន | C16: THORN MORN | D16: Làm thêm giờ | F16: / | I16: / | J16: / | K16: / | L16: / | M16: / | N16: / | P16: / | Q16: / | R16: / | S16: / | T16: / | U16: / | X16: =COUNTIF(F16:U16,"X")+0.5*COUNTIF(F16:U16,"/")+COUNTIF(F16:U16,"R1")+COUNTIF(F16:U16,"R")+COUNTIF(F16:U16,"R")+COUNTIF(F16:U16,"Xcv") -> 6.5 | AB16: =V16 -> 0 | AE16: =AB16*5000 -> 0
A17: 5 | B17: សៃ រិទ្ធី | C17: SAI RITHY | D17: 220195668 | E17: 37000 | F17: X | G17: X | I17: X | J17: X | K17: X | L17: X | M17: X | N17: X | P17: X | Q17: X | R17: X | T17: / | U17: X | V17: 1 | W17: =IF(SUM(Z17:AA17)<=2,1,0) -> 1 | X17: =COUNTIF(F17:U17,"X")+0.5*COUNTIF(F17:U17,"/")+COUNTIF(F17:U17,"R1")+COUNTIF(F17:U17,"R")+COUNTIF(F17:U17,"R")+COUNTIF(F17:U17,"Xcv") -> 12.5 | Z17: 0 | AA17: =COUNTIF(F17:T17,"-") -> 0 | AB17: =ROUND(AD17/AC17,4) -> 0.1138 | AC17: 11 | AD17: =V17*1.2521 -> 1.2521 | AE17: =ROUND(AD17*31947,0) -> 40001
B18: សៃ រិទ្ធី | C18: SAI RITHY | D18: Làm thêm giờ | F18: / | J18: / | K18: / | L18: / | M18: / | N18: / | Q18: / | R18: / | X18: =COUNTIF(F18:U18,"X")+0.5*COUNTIF(F18:U18,"/")+COUNTIF(F18:U18,"R1")+COUNTIF(F18:U18,"R")+COUNTIF(F18:U18,"R")+COUNTIF(F18:U18,"Xcv") -> 4 | AB18: =V18 -> 0 | AE18: =AB18*5000 -> 0
A19: 6 | B19: សាត រិទ្ធិសាក់ | C19: SAT RITHYSAK | D19: 220208913 | E19: 36814 | F19: X | G19: X | I19: X | J19: X | K19: X | L19: X | M19: X | N19: X | P19: X | Q19: X | R19: X | S19: X | T19: X | U19: X | V19: 1 | W19: =IF(SUM(Z19:AA19)<=2,1,0) -> 1 | X19: =COUNTIF(F19:U19,"X")+0.5*COUNTIF(F19:U19,"/")+COUNTIF(F19:U19,"R1")+COUNTIF(F19:U19,"R")+COUNTIF(F19:U19,"R")+COUNTIF(F19:U19,"Xcv") -> 14 | Z19: 0 | AA19: =COUNTIF(F19:T19,"-") -> 0 | AB19: =V19*1.2521 -> 1.2521 | AC19: =ROUND(V19*31947,0) -> 31947
B20: សាត រិទ្ធិសាក់ | C20: SAT RITHYSAK | D20: Làm thêm giờ | F20: / | I20: / | J20: / | K20: / | L20: / | M20: / | N20: / | P20: / | Q20: / | R20: / | S20: / | T20: / | U20: / | X20: =COUNTIF(F20:U20,"X")+0.5*COUNTIF(F20:U20,"/")+COUNTIF(F20:U20,"R1")+COUNTIF(F20:U20,"R")+COUNTIF(F20:U20,"R")+COUNTIF(F20:U20,"Xcv") -> 6.5 | AB20: =V20 -> 0 | AC20: =V20*5000 -> 0
A21: =+A19+1 -> 7 | B21: ហឿង សុជឿន | C21: HOEUNG SOCHOEUN | D21: 150911076 | E21: 37169 | J21: X | K21: X | L21: X | M21: X | N21: X | V21: 1 | W21: =IF(SUM(Z21:AA21)<=2,1,0) -> 1 | X21: =COUNTIF(F21:U21,"X")+0.5*COUNTIF(F21:U21,"/")+COUNTIF(F21:U21,"R1")+COUNTIF(F21:U21,"R")+COUNTIF(F21:U21,"R")+COUNTIF(F21:U21,"Xcv") -> 5 | Z21: 0 | AA21: =COUNTIF(F21:T21,"-") -> 0
A22: =A21+1 -> 8 | B22: ថន សំណាង | C22: THAN SAMNANG | D22: 220102094 | E22: 34977 | J22: X | K22: X | L22: X | M22: X | N22: X | V22: 1 | W22: =IF(SUM(Z22:AA22)<=2,1,0) -> 1 | X22: =COUNTIF(F22:U22,"X")+0.5*COUNTIF(F22:U22,"/")+COUNTIF(F22:U22,"R1")+COUNTIF(F22:U22,"R")+COUNTIF(F22:U22,"R")+COUNTIF(F22:U22,"Xcv") -> 5 | Z22: 1 | AA22: =COUNTIF(F22:T22,"-") -> 0
A23: =A22+1 -> 9 | B23: ថូរ សុភ័ណ្ឌ | C23: THO SOPHORN | D23: 210050404 | E23: 35370 | J23: X | K23: X | L23: X | M23: X | N23: - | V23: 1 | W23: =IF(SUM(Z23:AA23)<=2,1,0) -> 1 | X23: =COUNTIF(F23:U23,"X")+0.5*COUNTIF(F23:U23,"/")+COUNTIF(F23:U23,"R1")+COUNTIF(F23:U23,"R")+COUNTIF(F23:U23,"R")+COUNTIF(F23:U23,"Xcv") -> 4 | Z23: 0 | AA23: =COUNTIF(F23:T23,"-") -> 1
A24: =A23+1 -> 10 | B24: ធៀម សំនាង | C24: THEAM SAMNEANG | D24: 151006137 | E24: 38944 | J24: X | K24: X | L24: X | M24: X | N24: X | V24: 1 | W24: =IF(SUM(Z24:AA24)<=2,1,0) -> 1 | X24: =COUNTIF(F24:U24,"X")+0.5*COUNTIF(F24:U24,"/")+COUNTIF(F24:U24,"R1")+COUNTIF(F24:U24,"R")+COUNTIF(F24:U24,"R")+COUNTIF(F24:U24,"Xcv") -> 5 | Z24: 1 | AA24: =COUNTIF(F24:T24,"-") -> 0
A25: =A24+1 -> 11 | B25: អែល សាន់ | C25: EL SANN | D25: 040322767 | E25: 34973 | J25: X | K25: - | L25: X | M25: X | N25: X | V25: 1 | W25: =IF(SUM(Z25:AA25)<=2,1,0) -> 1 | X25: =COUNTIF(F25:U25,"X")+0.5*COUNTIF(F25:U25,"/")+COUNTIF(F25:U25,"R1")+COUNTIF(F25:U25,"R")+COUNTIF(F25:U25,"R")+COUNTIF(F25:U25,"Xcv") -> 4 | Z25: 1 | AA25: =COUNTIF(F25:T25,"-") -> 1
A26: =A25+1 -> 12 | B26: អ៊ាវ ខាត់ | C26: EAV KHATH | D26: 150469697 | E26: 33704 | J26: X | K26: - | L26: X | M26: X | N26: X | V26: 1 | W26: =IF(SUM(Z26:AA26)<=2,1,0) -> 1 | X26: =COUNTIF(F26:U26,"X")+0.5*COUNTIF(F26:U26,"/")+COUNTIF(F26:U26,"R1")+COUNTIF(F26:U26,"R")+COUNTIF(F26:U26,"R")+COUNTIF(F26:U26,"Xcv") -> 4 | Z26: 1 | AA26: =COUNTIF(F26:T26,"-") -> 1
A27: =A26+1 -> 13 | B27: ភី ផូ | C27: PHI PHO | D27: 150927708 | E27: 37085 | J27: X | K27: X | L27: X | M27: X | N27: X | V27: 1 | W27: =IF(SUM(Z27:AA27)<=2,1,0) -> 0 | X27: =COUNTIF(F27:U27,"X")+0.5*COUNTIF(F27:U27,"/")+COUNTIF(F27:U27,"R1")+COUNTIF(F27:U27,"R")+COUNTIF(F27:U27,"R")+COUNTIF(F27:U27,"Xcv") -> 5 | Z27: 4 | AA27: =COUNTIF(F27:T27,"-") -> 0
A28: =A27+1 -> 14 | B28: វុន វណ្ណនី | C28: VON VANNY | D28: 151034061 | E28: 39153 | J28: - | K28: - | L28: X | M28: - | N28: - | V28: 1 | W28: =IF(SUM(Z28:AA28)<=2,1,0) -> 0 | X28: =COUNTIF(F28:U28,"X")+0.5*COUNTIF(F28:U28,"/")+COUNTIF(F28:U28,"R1")+COUNTIF(F28:U28,"R")+COUNTIF(F28:U28,"R")+COUNTIF(F28:U28,"Xcv") -> 1 | Z28: 0 | AA28: =COUNTIF(F28:T28,"-") -> 4
A29: =A28+1 -> 15 | B29: លឿន ឆាលី | C29: LOEUN CHALY | D29: 150911069 | E29: 37366 | J29: X | K29: X | L29: - | M29: X | N29: X | V29: 1 | W29: =IF(SUM(Z29:AA29)<=2,1,0) -> 0 | X29: =COUNTIF(F29:U29,"X")+0.5*COUNTIF(F29:U29,"/")+COUNTIF(F29:U29,"R1")+COUNTIF(F29:U29,"R")+COUNTIF(F29:U29,"R")+COUNTIF(F29:U29,"Xcv") -> 4 | Z29: 3 | AA29: =COUNTIF(F29:T29,"-") -> 1
A30: =A29+1 -> 16 | B30: ហឿន សាវុធ | C30: HOEURN SAVUTH | D30: 020520213 | E30: 31484 | J30: X | K30: - | L30: X | M30: X | N30: X | V30: 1 | W30: =IF(SUM(Z30:AA30)<=2,1,0) -> 1 | X30: =COUNTIF(F30:U30,"X")+0.5*COUNTIF(F30:U30,"/")+COUNTIF(F30:U30,"R1")+COUNTIF(F30:U30,"R")+COUNTIF(F30:U30,"R")+COUNTIF(F30:U30,"Xcv") -> 4 | Z30: 1 | AA30: =COUNTIF(F30:T30,"-") -> 1
A31: =A30+1 -> 17 | B31: រឿន សារី | C31: ROEUN SARY | D31: 220175393 | E31: 31413 | J31: X | K31: X | L31: X | M31: X | N31: X | V31: 1 | W31: =IF(SUM(Z31:AA31)<=2,1,0) -> 1 | X31: =COUNTIF(F31:U31,"X")+0.5*COUNTIF(F31:U31,"/")+COUNTIF(F31:U31,"R1")+COUNTIF(F31:U31,"R")+COUNTIF(F31:U31,"R")+COUNTIF(F31:U31,"Xcv") -> 5 | Z31: 0 | AA31: =COUNTIF(F31:T31,"-") -> 0
A32: =A31+1 -> 18 | B32: ហ៊ុច សំណាង | C32: HOCH SOMNANG | D32: 150936257 | E32: 37356 | J32: X | K32: X | L32: - | M32: X | N32: X | V32: 1 | W32: =IF(SUM(Z32:AA32)<=2,1,0) -> 1 | X32: =COUNTIF(F32:U32,"X")+0.5*COUNTIF(F32:U32,"/")+COUNTIF(F32:U32,"R1")+COUNTIF(F32:U32,"R")+COUNTIF(F32:U32,"R")+COUNTIF(F32:U32,"Xcv") -> 4 | Z32: 1 | AA32: =COUNTIF(F32:T32,"-") -> 1
A33: =A32+1 -> 19 | B33: បាន ចន្ថា | C33: BAN CHANTHA | D33: 220137301 | E33: 30074 | J33: X | K33: - | L33: X | M33: X | N33: X | V33: 1 | W33: =IF(SUM(Z33:AA33)<=2,1,0) -> 1 | X33: =COUNTIF(F33:U33,"X")+0.5*COUNTIF(F33:U33,"/")+COUNTIF(F33:U33,"R1")+COUNTIF(F33:U33,"R")+COUNTIF(F33:U33,"R")+COUNTIF(F33:U33,"Xcv") -> 4 | Z33: 1 | AA33: =COUNTIF(F33:T33,"-") -> 1
A34: =A33+1 -> 20 | B34: សាន់ យូស័រ | C34: SAN YUSOR | D34: 150940509 | E34: 37662 | J34: X | K34: X | L34: X | M34: X | N34: X | V34: 1 | W34: =IF(SUM(Z34:AA34)<=2,1,0) -> 0 | X34: =COUNTIF(F34:U34,"X")+0.5*COUNTIF(F34:U34,"/")+COUNTIF(F34:U34,"R1")+COUNTIF(F34:U34,"R")+COUNTIF(F34:U34,"R")+COUNTIF(F34:U34,"Xcv") -> 5 | Z34: 4 | AA34: =COUNTIF(F34:T34,"-") -> 0
A35: =A34+1 -> 21 | B35: វុន វណ្ណា | C35: VUN VANNA | D35: 150657948 | E35: 36192 | J35: - | K35: - | L35: X | M35: / | N35: X | V35: 1 | W35: =IF(SUM(Z35:AA35)<=2,1,0) -> 1 | X35: =COUNTIF(F35:U35,"X")+0.5*COUNTIF(F35:U35,"/")+COUNTIF(F35:U35,"R1")+COUNTIF(F35:U35,"R")+COUNTIF(F35:U35,"R")+COUNTIF(F35:U35,"Xcv") -> 2.5 | Z35: 0 | AA35: =COUNTIF(F35:T35,"-") -> 2
A36: =A35+1 -> 22 | B36: ជឿន នីន | C36: CHOEUN NIN | D36: 150952503 | E36: 38207 | J36: X | K36: X | L36: X | M36: X | N36: X | V36: 1 | W36: =IF(SUM(Z36:AA36)<=2,1,0) -> 1 | X36: =COUNTIF(F36:U36,"X")+0.5*COUNTIF(F36:U36,"/")+COUNTIF(F36:U36,"R1")+COUNTIF(F36:U36,"R")+COUNTIF(F36:U36,"R")+COUNTIF(F36:U36,"Xcv") -> 5 | Z36: 0 | AA36: =COUNTIF(F36:T36,"-") -> 0
A37: =A36+1 -> 23 | B37: ហឿង ហេង | C37: HOEUNG HENG | D37: 220248893 | E37: 33855 | J37: - | K37: X | L37: X | M37: X | N37: X | V37: 1 | W37: =IF(SUM(Z37:AA37)<=2,1,0) -> 0 | X37: =COUNTIF(F37:U37,"X")+0.5*COUNTIF(F37:U37,"/")+COUNTIF(F37:U37,"R1")+COUNTIF(F37:U37,"R")+COUNTIF(F37:U37,"R")+COUNTIF(F37:U37,"Xcv") -> 4 | Z37: 3 | AA37: =COUNTIF(F37:T37,"-") -> 1
A38: =A37+1 -> 24 | B38: គង់ ចាន់ទ្រឿន | C38: KONG CHANTROEUN | D38: 220105697 | E38: 35623 | J38: - | K38: X | L38: X | M38: X | N38: X | V38: 1 | W38: =IF(SUM(Z38:AA38)<=2,1,0) -> 0 | X38: =COUNTIF(F38:U38,"X")+0.5*COUNTIF(F38:U38,"/")+COUNTIF(F38:U38,"R1")+COUNTIF(F38:U38,"R")+COUNTIF(F38:U38,"R")+COUNTIF(F38:U38,"Xcv") -> 4 | Z38: 3 | AA38: =COUNTIF(F38:T38,"-") -> 1
A39: =A38+1 -> 25 | B39: ទៀង ឡៃស៊ីម | C39: TIENG LAISIM | D39: 220216744 | E39: 37994 | J39: X | K39: X | L39: X | M39: X | N39: X | V39: 1 | W39: =IF(SUM(Z39:AA39)<=2,1,0) -> 1 | X39: =COUNTIF(F39:U39,"X")+0.5*COUNTIF(F39:U39,"/")+COUNTIF(F39:U39,"R1")+COUNTIF(F39:U39,"R")+COUNTIF(F39:U39,"R")+COUNTIF(F39:U39,"Xcv") -> 5 | Z39: 1 | AA39: =COUNTIF(F39:T39,"-") -> 0
A40: =A39+1 -> 26 | B40: ម៉ុន ម៉ោល | C40: MON MORL | D40: 220211460 | E40: 37970 | J40: X | K40: X | L40: X | M40: X | N40: X | V40: 1 | W40: =IF(SUM(Z40:AA40)<=2,1,0) -> 1 | X40: =COUNTIF(F40:U40,"X")+0.5*COUNTIF(F40:U40,"/")+COUNTIF(F40:U40,"R1")+COUNTIF(F40:U40,"R")+COUNTIF(F40:U40,"R")+COUNTIF(F40:U40,"Xcv") -> 5 | Z40: 1 | AA40: =COUNTIF(F40:T40,"-") -> 0
A41: =A40+1 -> 27 | B41: កែវ ប្រុសសុទ្ធ | C41: KEO BROSSOTH | D41: 151056059 | E41: 38810 | J41: X | K41: X | L41: X | M41: - | N41: X | V41: 1 | W41: =IF(SUM(Z41:AA41)<=2,1,0) -> 1 | X41: =COUNTIF(F41:U41,"X")+0.5*COUNTIF(F41:U41,"/")+COUNTIF(F41:U41,"R1")+COUNTIF(F41:U41,"R")+COUNTIF(F41:U41,"R")+COUNTIF(F41:U41,"Xcv") -> 4 | Z41: 1 | AA41: =COUNTIF(F41:T41,"-") -> 1
A42: =A41+1 -> 28 | B42: ម៉ុក សុធា | C42: MOK SOTHEA | D42: 150306182 (01) | E42: 31934 | J42: X | K42: - | L42: X | M42: X | N42: X | V42: 1 | W42: =IF(SUM(Z42:AA42)<=2,1,0) -> 0 | X42: =COUNTIF(F42:U42,"X")+0.5*COUNTIF(F42:U42,"/")+COUNTIF(F42:U42,"R1")+COUNTIF(F42:U42,"R")+COUNTIF(F42:U42,"R")+COUNTIF(F42:U42,"Xcv") -> 4 | Z42: 2 | AA42: =COUNTIF(F42:T42,"-") -> 1
...

Sheet BTHKL D1 T1 (26)
A1: ក្រុមហ៊ុន កៅស៊ូ មេគង្គ ខូ អិលធីឌី | E1: ព្រះរាជាណាចក្រ កម្ពុជា
A2: CÔNG TY TNHH CAO SU MEKONG | E2: VƯƠNG QUỐC CAMPUCHIA
A3: រោងចក្រកែច្នៃ | E3: ជាតិ សាសនា ព្រះមហាក្សត្រ
A4: XƯỞNG CHẾ BIẾN | E4: Dân tộc - Tôn giáo - Quốc vương
A6: តារាងបូកសរុបបរិមាណ​ ចាប់ពីថ្ងៃ ០១-១៥ ខែ ០១ ឆ្នាំ ២០២៦ (វគ្គទី ១)
A7: BẢNG TỔNG HỢP KHỐI LƯỢNG (ĐỢT 1)
A8: NGÀY​​​​ 01 ĐẾN 15 THÁNG 01 NĂM 2026
A10: ល.រ STT | B10: រាយនាមការងារ/ Hạng mục công việc | C10: ឯកតា ĐVT | D10: កម្រិត Định mức | E10: អនុវត្ត/THỰC HIỆN | G10: សម្គាល់/ Ghi chú | I10: Đợt 1
E11: បរិមាណ/ Khối lượng | F11: កម្លាំង / Công | K11: BC hàng ngày
A12: 1 | B12: ជ័រកិន /Mủ cán vắt ( Gồm phụ cấp phụ trợ trực tiếp 10%) | C12: តោន (Tấn) | D12: =ROUND(23000/31947,4) -> 0.7199 | E12: ='[3]BTHKL D1 T1'!E13 -> 945.15 | F12: =ROUND(E12*D12,2) -> 680.41
A13: =+A12+1 -> 2 | B13: ជ័រសម្រេច/Mủ Thành phẩm (Gồm phụ cấp phụ trợ trực tiếp 15%) | C13: តោន (Tấn) | D13: =ROUND(35000/31947,4) -> 1.0956 | E13: ='[3]BTHKL D1 T1'!E14 -> 363.85 | F13: =ROUND(E13*D13,2) -> 398.63
A14: =+A13+1 -> 3 | B14: សន្ដិសុខការពារ​​​​​ (Bảo vệ) | C14: កម្លាំង (Công) | F14: =SUM(F15:F16) -> 28.55
A15: + | B15: សន្ដិសុខការពារ​​​​​ (Bảo vệ) | C15: ថ្ងៃ (Ngày) | D15: 0.9657 | E15: ='[3]BCC D1 (26)'!X55 -> 14 | F15: =ROUND(D15*E15,2) -> 13.52 | G15: 1 người | I15: =ROUND(K15/J15,4) -> 1.5022 | J15: 9 | K15: =F15 -> 13.52 | L15: =ROUND(F15*31947,0) -> 431923
A16: + | B16: សន្ដិសុខការពារ​​​​​ (Bảo vệ biết TV) | C16: ថ្ងៃ (Ngày) | D16: 1.0736 | E16: ='[3]BCC D1 (26)'!X13 -> 14 | F16: =ROUND(D16*E16,2) -> 15.03 | G16: 1 người | I16: =ROUND(K16/J16,4) -> 1.1562 | J16: 13 | K16: =F16 -> 15.03 | L16: =F16*31947 -> 480163.41
A17: =+A14+1 -> 4 | B17: កម្មករ មេកានិច (Công nhân cơ khí) | C17: កម្លាំង (Công) | D17: 1.4222 | E17: ='[3]BTHKL D1 T1'!J18 -> 40.5 | F17: =ROUND(D17*E17,2) -> 57.6 | G17: 2 người | I17: =ROUND(K17/J17,4) -> 1.6457 | J17: 35 | K17: =F17 -> 57.6 | L17: =ROUND(F17*31947,0) -> 1840147 | M17: =K17*2 -> 115.2
A18: =+A17+1 -> 5 | B18: អ្នកបើកឡាន (Tài xế) | C18: ថ្ងៃ (Ngày) | D18: 1.426 | E18: =SUM('BCC D1(26)'!X54:X57,'BCC D1(26)'!X15:X18) -> 72 | F18: =ROUND(D18*E18,2) -> 102.67 | G18: 4 người | I18: =ROUND(K18/J18,4) -> 1.8667 | J18: 55 | K18: =F18 -> 102.67 | L18: =ROUND(F18*31947/4,0) -> 820000 | M18: =K18*4 -> 410.68
A19: =+A18+1 -> 6 | B19: សម្អាត (Vệ sinh) | C19: ថ្ងៃ (Ngày) | D19: 0.9704 | E19: ='[3]BTHKL D1 T1'!J20 -> 27 | F19: =ROUND(D19*E19,2) -> 26.2 | G19: 2 người | I19: =ROUND(K19/J19,4) -> 1.4556 | J19: 18 | K19: =F19 -> 26.2 | L19: =ROUND(F19*31947/2,0) -> 418506 | M19: =K19*2 -> 52.4
A20: =+A19+1 -> 7 | B20: អ្នកធ្វើការមិនរើសមុខ (Tạp vụ) | C20: ថ្ងៃ (Ngày) | D20: 1.2233 | E20: ='[3]BTHKL D1 T1'!J21 -> 12 | F20: =ROUND(D20*E20,2) -> 14.68 | I20: =ROUND(K20/J20,4) -> 1.835 | J20: 8 | K20: =F20 -> 14.68 | L20: =F20*31947 -> 468981.96
A21: =+A20+1 -> 8 | B21: កម្លាំងលើកជញ្ជូន (Công khác) | C21: កម្លាំង (Công) | F21: =SUM(F22:F26) -> 209.66 | I21: =ROUND(K21/J21,4) -> 19.06 | J21: 11 | K21: =F21 -> 209.66 | L21: =F21*31947 -> 6698008
A22: 8.1 | B22: លាងសម្អាតធុងសម្ងួតជ័រ/ vệ sinh thùng sấy mủ | C22: ថ្ងៃ (Ngày) | D22: 0.9391 | E22: ='[3]BCC D1 (26)'!X98 -> 15.5 | F22: =ROUND(D22*E22,2) -> 14.56 | I22: =ROUND(K22/J22,4) -> 1.12 | J22: 13 | K22: =F22 -> 14.56 | L22: =F22*31947 -> 465148.32
A23: 8.2 | B23: ប្ដូរតែម/Thay tem nhãn | C23: កម្លាំង (Công) | D23: 1.2501 | E23: ='[3]BCC D1 (26)'!X107 -> 64 | F23: =ROUNDDOWN(D23*E23,2) -> 80 | I23: =ROUND(K23/J23,4) -> 9.4118 | J23: 8.5 | K23: =F23 -> 80 | L23: =F23*31947 -> 2555760
A24: 8.3 | B24: កាត់ស្មៅ ពន្លត់អគ្គីភ័យ/Phát cỏ phòng chống cháy | C24: កម្លាំង (Công) | D24: 1.3147 | E24: ='[3]BCC D1 (26)'!X95 -> 10.5 | F24: =ROUND(D24*E24,2) -> 13.8
A25: 8.4 | B25: ប្រាក់ថ្ងៃបុណ្យចូលឆ្នាំសកល (Tiền lễ dương lịch 1/1/2026) | C25: ថ្ងៃ (Ngày) | D25: =ROUND(16000/31947,4) -> 0.5008 | E25: ='[3]BCC D1 (26)'!V121 -> 71 | F25: =ROUND(D25*E25,2) -> 35.56
A26: 8.5 | B26: មី និងប្រេងឆាឲ្យកម្មករ (Mì, dầu ăn cho CN) | C26: កេះ (Thùng) | D26: =ROUND(35000/31947,4) -> 1.0956 | E26: ='[3]BCC D1 (26)'!W121 -> 60 | F26: =ROUND(D26*E26,2) -> 65.74
A27: សរុប/Tổng cộng | F27: =ROUND(SUM(F12:F14,F17:F21),2) -> 1518.4 | I27: =F27*31947 -> 48508325
I29: =2290.11-627 -> 1663.11 | J29: =ROUND(F27*31947,0) -> 48508325 | K29: 1140.84
E30: កំពង់ធំ, ថ្ងៃ (ngày) 15 ខែ (tháng) 01 ឆ្នាំ (năm) 2026 | J30: =ROUND(K29*31947,0) -> 36446415
B31: អ្នករៀបចំ / Lập biểu | E31: អង្គភាពអនុវត្ត /ĐƠN VỊ THỰC HIỆN
B34: Bùi Ngọc Triệu
F38: ផ.ហិរ.គណនេយ្យ
F39: PHÒNG TCKT

Sheet BPHAN CHIA 
A1: ក្រុមហ៊ុន កៅស៊ូ មេគង្គ ខូ អិលធីឌី
A2: CÔNG TY TNHH CAO SU VRG MEKONG
A3: រោងចក្រកែច្នៃ
A4: XƯỞNG CHẾ BIẾN
A5: តារាងបែងចែកបរិមាណ កម្មករធើ្វជ័រកិនរមូរ ក្រុម ១
A6: ថ្ងៃ ១៦-៣១ ខែ ០១ ឆ្នាំ ២០២៦
A7: BẢNG PHÂN CHIA KHỐI LƯỢNG CÔNG NHÂN LÀM MỦ CÁN VẮT TỔ 1
A8: ='[3]BKECHITIET TO2'!A5:N5 -> NGÀY​​​​ 16 ĐẾN 31 THÁNG 01 NĂM 2026
A10: ល.រ STT | B10: ត្រកូលនិងឈ្មោះ HỌ VÀ TÊN | D10: ឯកតា ĐVT | E10: 16 | F10: =E10+1 -> 17 | G10: =F10+1 -> 18 | H10: =G10+1 -> 19 | I10: =H10+1 -> 20 | J10: =I10+1 -> 21 | K10: =J10+1 -> 22 | L10: =K10+1 -> 23 | M10: =L10+1 -> 24 | ... T10: =S10+1 -> 31 | U10: សរុប TỔNG CỘNG | V10: សម្គាល់ GHI CHÚ | W10: ហត្ថលេខាទទួល Ký nhận
A11: 1 | B11: ជឿន ថា | C11: CHOEUN THA | D11: តោន (Tấn) | E11: 4099 | G11: 3843 | H11: 5379 | J11: 4355 | K11: 3074 | L11: 4099 | M11: 4099 | N11: 4099 | O11: 4099 | P11: 4422 | Q11: 4099 | R11: 4355 | S11: 5123 | U11: =ROUND(V11/1000,3) -> 55.145 | V11: =SUM(E11:T11) -> 55145 | Y11: =U11+U64+U100+U136 -> 124.752 | Z11: =ROUND(U11*0.1,2) -> 5.51 | AA11: =Z11+U11 -> 60.655
A12: 2 | B12: ហ៊ុន ម៉ៅ | C12: HUN MAO | D12: តោន (Tấn) | E12: 4099 | G12: 3842 | H12: 5380 | J12: 4355 | K12: 3074 | L12: 4099 | M12: 4099 | N12: 4099 | O12: 4099 | P12: 4422 | Q12: 4099 | R12: 4355 | S12: 5123 | U12: =ROUND(V12/1000,3) -> 55.145 | V12: =SUM(E12:T12) -> 55145
A13: 3 | B13: ជឿន ថី | C13: CHOEUN THEY | D13: តោន (Tấn) | E13: 4099 | G13: 3842 | H13: 5380 | J13: 4355 | K13: 3074 | L13: 4099 | M13: 4099 | N13: 4099 | O13: 4099 | P13: 4422 | Q13: 4099 | R13: 4355 | S13: 5123 | U13: =ROUND(V13/1000,3) -> 55.145 | V13: =SUM(E13:T13) -> 55145
A14: 4 | B14: ឆឹម ខុន | C14: CHHEOM KHON | D14: តោន (Tấn) | E14: 4099 | G14: 3842 | H14: 5380 | J14: 4355 | K14: 3074 | L14: 4099 | M14: 4098 | N14: 4099 | O14: 4098 | P14: 4422 | Q14: 4099 | R14: 4355 | S14: 5123 | U14: =ROUND(V14/1000,3) -> 55.143 | V14: =SUM(E14:T14) -> 55143
A15: 5 | B15: ថន សុខធា | C15: THON SOKHTHEA | D15: តោន (Tấn) | E15: 4099 | G15: 3842 | H15: 5380 | J15: 4354 | K15: 3074 | L15: 4099 | M15: 4098 | N15: 4099 | O15: 4098 | P15: 4423 | Q15: 4099 | R15: 4355 | S15: 5123 | U15: =ROUND(V15/1000,3) -> 55.143 | V15: =SUM(E15:T15) -> 55143
A16: 6 | B16: នី គីន | C16: NY KIN | D16: តោន (Tấn) | E16: 4099 | G16: 3842 | H16: 5379 | J16: 4355 | K16: 3074 | L16: 4099 | M16: 4098 | N16: 4099 | O16: 4098 | P16: 4423 | Q16: 4099 | R16: 4354 | S16: 5124 | U16: =ROUND(V16/1000,3) -> 55.143 | V16: =SUM(E16:T16) -> 55143
A17: 7 | B17: វុន ហួន | C17: VUN HOUN | D17: តោន (Tấn) | E17: 4098 | G17: 3843 | H17: 5379 | J17: 4355 | K17: 3074 | L17: 4098 | M17: 4099 | N17: 4098 | O17: 4099 | P17: 4423 | Q17: 4098 | R17: 4355 | S17: 5124 | U17: =ROUND(V17/1000,3) -> 55.143 | V17: =SUM(E17:T17) -> 55143
A18: 8 | B18: លី​ ប៊ុនយ៉េន | C18: LY BUNYEN | D18: តោន (Tấn) | E18: 4098 | G18: 3843 | H18: 5379 | J18: 4355 | K18: 3074 | L18: 4098 | M18: 4099 | N18: 4098 | O18: 4099 | P18: 4423 | Q18: 4098 | R18: 4355 | S18: 5124 | U18: =ROUND(V18/1000,3) -> 55.143 | V18: =SUM(E18:T18) -> 55143
A19: 9 | B19: ធឿន​ វុឌ្ឍី | C19: THOEUN VUTHY | D19: តោន (Tấn) | E19: 4098 | G19: 3843 | H19: 5379 | J19: 4355 | K19: 3074 | L19: 4098 | M19: 4099 | N19: 4098 | O19: 4099 | P19: 4423 | Q19: 4098 | R19: 4355 | S19: 5123 | U19: =ROUND(V19/1000,3) -> 55.142 | V19: =SUM(E19:T19) -> 55142
B20: Cộng | E20: =SUM(E11:E19) -> 36888 | F20: =SUM(F11:F19) -> 0 | G20: =SUM(G11:G19) -> 34582 | H20: =SUM(H11:H19) -> 48415 | I20: =SUM(I11:I19) -> 0 | J20: =SUM(J11:J19) -> 39194 | K20: =SUM(K11:K19) -> 27666 | L20: =SUM(L11:L19) -> 36888 | ... V20: =SUM(V11:V19) -> 496292 | Y20: 143710 | Z20: =U20+U73 -> 934.34
E21: =VLOOKUP(E10,'[3]BKECHITIET TO1'!$A$11:$K$27,11) -> 36888 | F21: =VLOOKUP(F10,'[3]BKECHITIET TO1'!$A$11:$K$27,11) -> 0 | G21: =VLOOKUP(G10,'[3]BKECHITIET TO1'!$A$11:$K$27,11) -> 34582 | H21: =VLOOKUP(H10,'[3]BKECHITIET TO1'!$A$11:$K$27,11) -> 48415 | I21: =VLOOKUP(I10,'[3]BKECHITIET TO1'!$A$11:$K$27,11) -> 0 | J21: =VLOOKUP(J10,'[3]BKECHITIET TO1'!$A$11:$K$27,11) -> 39194 | K21: =VLOOKUP(K10,'[3]BKECHITIET TO1'!$A$11:$K$27,11) -> 27666 | L21: =VLOOKUP(L10,'[3]BKECHITIET TO1'!$A$11:$K$27,11) -> 36888 | ... O21: =VLOOKUP(O10,'[3]BKECHITIET TO1'!$A$11:$K$27,11) -> 36888 | P21: 39803 | Q21: =VLOOKUP(Q10,'[3]BKECHITIET TO1'!$A$11:$K$27,11) -> 36888 | R21: =VLOOKUP(R10,'[3]BKECHITIET TO1'!$A$11:$K$27,11) -> 39194 | S21: =VLOOKUP(S10,'[3]BKECHITIET TO1'!$A$11:$K$27,11) -> 46110 | T21: =VLOOKUP(T10,'[3]BKECHITIET TO1'!$A$11:$K$27,11) -> 0 | U21: =SUM(E21:T21) -> 496292
E22: =E21-E20 -> 0 | F22: =F21-F20 -> 0 | G22: =G21-G20 -> 0 | H22: =H21-H20 -> 0 | I22: =I21-I20 -> 0 | J22: =J21-J20 -> 0 | K22: =K21-K20 -> 0 | L22: =L21-L20 -> 0 | ... T22: =T21-T20 -> 0 | U22: =U21-V20 -> 0
E23: =COUNTIF(E11:E19,"X")+0.5*COUNTIF(E11:E19,"/") -> 0 | F23: =COUNTIF(F11:F19,"X")+0.5*COUNTIF(F11:F19,"/") -> 0 | G23: =COUNTIF(G11:G19,"X")+0.5*COUNTIF(G11:G19,"/") -> 0 | H23: =COUNTIF(H11:H19,"X")+0.5*COUNTIF(H11:H19,"/") -> 0 | I23: =COUNTIF(I11:I19,"X")+0.5*COUNTIF(I11:I19,"/") -> 0 | J23: =COUNTIF(J11:J19,"X")+0.5*COUNTIF(J11:J19,"/") -> 0 | K23: =COUNTIF(K11:K19,"X")+0.5*COUNTIF(K11:K19,"/") -> 0 | L23: =COUNTIF(L11:L19,"X")+0.5*COUNTIF(L11:L19,"/") -> 0 | ... R23: =COUNTIF(R11:R19,"X")+0.5*COUNTIF(R11:R19,"/") -> 0 | T23: =COUNTIF(T11:T19,"X")+0.5*COUNTIF(T11:T19,"/") -> 0
E24: 9 | F24: 0 | G24: 9 | H24: 9 | I24: 0 | J24: 9 | K24: 9 | L24: 9 | M24: 9 | N24: 9 | O24: 9 | P24: 9 | Q24: 9 | R24: 9 | S24: 9 | T24: 9
E25: =ROUND(E21/E24,1) -> 4098.7 | F25: =ROUND(F21/F24,1) -> #DIV/0! | G25: =ROUND(G21/G24,1) -> 3842.4 | H25: =ROUND(H21/H24,1) -> 5379.4 | I25: =ROUND(I21/I24,1) -> #DIV/0! | J25: =ROUND(J21/J24,1) -> 4354.9 | K25: =ROUND(K21/K24,1) -> 3074 | L25: =ROUND(L21/L24,1) -> 4098.7 | ... T25: =ROUND(T21/T24,1) -> 0
F26: =F25/2 -> #DIV/0! | G26: =G25/2 -> 1921.2 | H26: =H25/2 -> 2689.7 | I26: =I25/2 -> #DIV/0! | K26: =K25/2 -> 1537 | N26: =N25/2 -> 2049.35 | O26: =O25/2 -> 2049.35 | Q26: =Q25/2 -> 2049.35 | R26: =R25/2 -> 2177.45 | T26: =T25/2 -> 0
Z27: =10%*(U11+U64) -> 10.8172
C38: 26129
C39: 24592
C40: 15370
A52: ក្រុមហ៊ុន កៅស៊ូ មេគង្គ ខូ អិលធីឌី
A53: =A2 -> CÔNG TY TNHH CAO SU VRG MEKONG
A54: រោងចក្រកែច្នៃ
A55: XƯỞNG CHẾ BIẾN
A58: តារាងបែងចែកបរិមាណ កម្មករធើ្វជ័រកិនរមូរ ក្រុម ២
A59: =A6 -> ថ្ងៃ ១៦-៣១ ខែ ០១ ឆ្នាំ ២០២៦
A60: BẢNG PHÂN CHIA KHỐI LƯỢNG CÔNG NHÂN LÀM MỦ CÁN VẮT TỔ 2
A61: =A8 -> NGÀY​​​​ 16 ĐẾN 31 THÁNG 01 NĂM 2026
A63: ល.រ STT | B63: ត្រកូលនិងឈ្មោះ HỌ VÀ TÊN | D63: ឯកតា ĐVT | E63: =E10 -> 16 | F63: =E63+1 -> 17 | G63: =F63+1 -> 18 | H63: =G63+1 -> 19 | I63: =H63+1 -> 20 | J63: =I63+1 -> 21 | K63: =J63+1 -> 22 | L63: =K63+1 -> 23 | M63: =L63+1 -> 24 | ... T63: =S63+1 -> 31 | U63: សរុប TỔNG CỘNG | V63: សម្គាល់ GHI CHÚ | W63: Ký nhận
A64: 1 | B64: សន ម៉ាប់ | C64: SORN MAB | D64: តោន (Tấn) | E64: 4323 | F64: 2562 | G64: 3746 | H64: 4323 | K64: 4611 | L64: 4035 | M64: 4323 | N64: 3842 | O64: 4611 | P64: 4099 | Q64: 3843 | R64: 4098 | S64: 4611 | U64: =ROUND(V64/1000,3) -> 53.027 | V64: =SUM(E64:T64) -> 53027 | Y64: =U179+#REF! -> #REF! | Z64: =ROUND(U64*0.1,2) -> 5.3 | AA64: =Z64+U64 -> 58.327
A65: 2 | B65: ម៉ន ពឿយ | C65: MORN POEUY | D65: តោន (Tấn) | E65: - | F65: 2562 | G65: 3746 | H65: 4323 | K65: 4611 | L65: 4035 | M65: 4323 | N65: 3842 | O65: - | P65: 4099 | Q65: 3843 | R65: 4098 | S65: 4611 | U65: =ROUND(V65/1000,3) -> 44.093 | V65: =SUM(E65:T65) -> 44093
...

Sheet KLCN t1 dot 1
A1: ក្រុមហ៊ុន កៅស៊ូ មេគង្គ ខូ អិលធីឌី | M1: ព្រះរាជាណាចក្រ កម្ពុជា
A2: CÔNG TY TNHH CAO SU MEKONG | M2: VƯƠNG QUỐC CAMPUCHIA
A3: រោងចក្រកែច្នៃ | M3: ជាតិ សាសនា ព្រះមហាក្សត្រ
A4: XƯỞNG CHẾ BIẾN | M4: Dân tộc - Tôn giáo - Quốc vương
A6: តារាងបរិមាណកម្មករ រោងចក្រកែច្នៃជ័រកៅស៊ូ ខែ ១២ ឆ្នាំ ២០២៥
A7: ចាប់ពីថ្ងៃ ០១-១៥ ខែ ១ ឆ្នាំ ២០២៦ (វគ្គទី ២)
A8: BẢNG KHỐI LƯỢNG CÔNG NHÂN XƯỞNG CHẾ BIẾN THÁNG 1 NĂM 2026
A9: TỪ NGÀY 16-31 THÁNG 1 NĂM 2026 (ĐỢT 2)
A11: ល.រ STT | B11: ត្រកូលនិងឈ្មោះ Họ và tên | D11: ជ័រកិន (Làm mủ cán vắt) | F11: ជ័រសម្រេច (Làm mủ Thành phẩm) | H11: អ្នកធ្វើការមិនរើសមុខ (Tạp vụ) | J11: សន្ដិសុខការពារ​​​​​ (Bảo vệ) | L11: អ្នកបើកឡាន (Tài xế) | N11: សម្អាត (Vệ sinh) | P11: កម្មករ មេកានិច (Công nhân cơ khí) | R11: កម្លាំងកាត់ស្មៅបាញ់ថ្នាំស្មៅ ; ពេលនាំចេញជ័រទៅលក់/ (Công phát cỏ, xịt cỏ; xuất hàng) | T11: លាងសម្អាតធុងសម្ងួតជ័រ/ vệ sinh thùng sấy mủ | V11: ថ្លឹង កៅស៊ូ ប៉េអឺ ដើម្បីធើ្វសារពើភ័ណ្ឌ ថ្ងៃ ៣១/១២/២០២៥/ Cân thảm kiểm kê VT | X11: មី និងប្រេងឆាឲ្យកម្មករ (Mì, dầu ăn cho CN) | Z11: សរុប Tổng công | AA11: ហត្ថលេខា KÝ TÊN
B12: អក្សរខ្មែរ (Khmer) | C12: អក្សរ ឡាតាំង (La tinh) | D12: បរិមាណ Khối lượng | E12: កម្លាំង Công | F12: បរិមាណ Khối lượng | G12: កម្លាំង Công | H12: បរិមាណ Khối lượng | I12: កម្លាំង Công | J12: បរិមាណ Khối lượng | K12: កម្លាំង Công | L12: បរិមាណ Khối lượng | M12: កម្លាំង Công | N12: បរិមាណ Khối lượng | O12: កម្លាំង Công | P12: បរិមាណ Khối lượng | Q12: កម្លាំង Công | R12: បរិមាណ Khối lượng | S12: កម្លាំង Công | T12: បរិមាណ Khối lượng | U12: កម្លាំង Công | V12: បរិមាណ Khối lượng | W12: កម្លាំង Công | X12: បរិមាណ Khối lượng | Y12: កម្លាំង Công
A13: 1 | B13: រិន ច្រិប | C13: RIN CHRIB | H13: ='[5]BCC D1(26)'!V12 -> 10.5 | I13: =ROUND(H13*1.2486,2) -> 13.11 | Z13: =SUM(G13,E13,S13,Q13,O13,M13,K13,I13,U13,W13,Y13) -> 13.11
A14: =+A13+1 -> 2 | B14: កែវ សម្បត្តិ | C14: KEO SAMBATH | J14: ='[5]BCC D1(26)'!V13+'[5]BCC D1(26)'!V14 -> 16 | K14: =ROUND(J14*1.0563,2) -> 16.9 | R14: ='[5]BCC D1(26)'!V93 -> 3.5 | S14: =ROUND(R14*0.9391,2) -> 3.29 | Z14: =SUM(G14,E14,S14,Q14,O14,M14,K14,I14,U14,W14,Y14) -> 20.19 | AD14: គី គីន
A15: =+A14+1 -> 3 | B15: ផន ឃី | C15: PHORN KHY | N15: ='[5]BCC D1(26)'!V15 -> 12.5 | O15: =ROUND(N15*0.9776,2) -> 12.22 | Z15: =SUM(G15,E15,S15,Q15,O15,M15,K15,I15,U15,W15,Y15) -> 12.22
A16: =+A15+1 -> 4 | B16: ថន ម៉ន | C16: THORN MORN | L16: =SUM('[5]BCC D1(26)'!V16:V17) -> 17.5 | M16: =ROUND(L16*1.4667,2)-0.01 -> 25.66 | Z16: =SUM(G16,E16,S16,Q16,O16,M16,K16,I16,U16,W16,Y16) -> 25.66
A17: =+A16+1 -> 5 | B17: សៃ រិទ្ធី | C17: SAI RITHY | L17: =SUM('[5]BCC D1(26)'!V18:V19) -> 11 | M17: =ROUND(L17*1.4779,2) -> 16.26 | Z17: =SUM(G17,E17,S17,Q17,O17,M17,K17,I17,U17,W17,Y17) -> 16.26
A18: =+A17+1 -> 6 | B18: សាត រិទ្ធិសាក់ | C18: SAT RITHYSAK | P18: =SUM('[5]BCC D1(26)'!V20:V21) -> 17.5 | Q18: =ROUND(P18*1.4608,2) -> 25.56 | Z18: =SUM(G18,E18,S18,Q18,O18,M18,K18,I18,U18,W18,Y18) -> 25.56
A19: =+A18+1 -> 7 | B19: ហឿង សុជឿន | C19: HOEUNG SOCHOEUN | D19: =ROUND(VLOOKUP(B19,'[5]BPHAN CHIA '!$B$100:$T$110,19,0)*1.1,2) -> 9.82 | E19: =ROUND(0.7199*D19,2) -> 7.07 | F19: =ROUND(1.15*VLOOKUP(B19,'[5]BPHAN CHIA '!$B$179:$T$200,19,0),2) -> 13.75 | G19: =ROUND(F19*1.0956,2) -> 15.06 | U19: =ROUND(T19*0.9391,2) -> 0 | Z19: =SUM(G19,E19,S19,Q19,O19,M19,K19,I19,U19,W19,Y19) -> 22.13
A20: =+A19+1 -> 8 | B20: ថន សំណាង | C20: THAN SAMNANG | D20: =ROUND(VLOOKUP(B20,'[5]BPHAN CHIA '!$B$100:$T$110,19,0),2) -> 12.55 | E20: =ROUND(0.7199*D20,2) -> 9.03 | F20: =ROUND(VLOOKUP(B20,'[5]BPHAN CHIA '!$B$179:$T$200,19,0),2) -> 10.35 | G20: =ROUND(F20*1.0956,2) -> 11.34 | Z20: =SUM(G20,E20,S20,Q20,O20,M20,K20,I20,U20,W20,Y20) -> 20.37
A21: =+A20+1 -> 9 | B21: ថូរ សុភ័ណ្ឌ | C21: THO SOPHORN | F21: =ROUND(VLOOKUP(B21,'[5]BPHAN CHIA '!$B$179:$T$200,19,0),2) -> 11.95 | G21: =ROUND(F21*1.0956,2) -> 13.09 | Z21: =SUM(G21,E21,S21,Q21,O21,M21,K21,I21,U21,W21,Y21) -> 13.09
A22: =+A21+1 -> 10 | B22: ធៀម សំនាង | C22: THEAM SAMNEANG | F22: =ROUND(VLOOKUP(B22,'[5]BPHAN CHIA '!$B$179:$T$200,19,0),2) -> 9.96 | G22: =ROUND(F22*1.0956,2) -> 10.91 | Z22: =SUM(G22,E22,S22,Q22,O22,M22,K22,I22,U22,W22,Y22) -> 10.91
A23: =+A22+1 -> 11 | B23: អែល សាន់ | C23: EL SANN | D23: =ROUND(VLOOKUP(B23,'[5]BPHAN CHIA '!$B$100:$T$110,19,0),2) -> 12.55 | E23: =ROUND(0.7199*D23,2) -> 9.03 | F23: =ROUND(VLOOKUP(B23,'[5]BPHAN CHIA '!$B$179:$T$200,19,0),2) -> 11.95 | G23: =ROUND(F23*1.0956,2) -> 13.09 | Z23: =SUM(G23,E23,S23,Q23,O23,M23,K23,I23,U23,W23,Y23) -> 22.12
A24: =+A23+1 -> 12 | B24: អ៊ាវ ខាត់ | C24: EAV KHATH | D24: =ROUND(VLOOKUP(B24,'[5]BPHAN CHIA '!$B$100:$T$110,19,0),2) -> 3.62 | E24: =ROUND(0.7199*D24,2) -> 2.61 | F24: =ROUND(VLOOKUP(B24,'[5]BPHAN CHIA '!$B$179:$T$200,19,0),2) -> 11.95 | G24: =ROUND(F24*1.0956,2) -> 13.09 | Z24: =SUM(G24,E24,S24,Q24,O24,M24,K24,I24,U24,W24,Y24) -> 15.7
A25: =+A24+1 -> 13 | B25: ភី ផូ | C25: PHI PHO | F25: =ROUND(VLOOKUP(B25,'[5]BPHAN CHIA '!$B$179:$T$200,19,0),2) -> 11.95 | G25: =ROUND(F25*1.0956,2) -> 13.09 | Z25: =SUM(G25,E25,S25,Q25,O25,M25,K25,I25,U25,W25,Y25) -> 13.09
A26: =+A25+1 -> 14 | B26: វុន វណ្ណនី | C26: VON VANNY | F26: =ROUND(VLOOKUP(B26,'[5]BPHAN CHIA '!$B$179:$T$200,19,0),2) -> 8.99 | G26: =ROUND(F26*1.0956,2) -> 9.85 | Z26: =SUM(G26,E26,S26,Q26,O26,M26,K26,I26,U26,W26,Y26) -> 9.85
A27: =+A26+1 -> 15 | B27: លឿន ឆាលី | C27: LOEUN CHALY | F27: =ROUND(VLOOKUP(B27,'[5]BPHAN CHIA '!$B$179:$T$200,19,0),2) -> 10.35 | G27: =ROUND(F27*1.0956,2) -> 11.34 | Z27: =SUM(G27,E27,S27,Q27,O27,M27,K27,I27,U27,W27,Y27) -> 11.34
A28: =+A27+1 -> 16 | B28: ហឿន សាវុធ | C28: HOEURN SAVUTH | D28: =ROUND(VLOOKUP(B28,'[5]BPHAN CHIA '!$B$100:$T$110,19,0),2) -> 12.55 | E28: =ROUND(0.7199*D28,2) -> 9.03 | F28: =ROUND(VLOOKUP(B28,'[5]BPHAN CHIA '!$B$179:$T$200,19,0),2) -> 10.58 | G28: =ROUND(F28*1.0956,2) -> 11.59 | Z28: =SUM(G28,E28,S28,Q28,O28,M28,K28,I28,U28,W28,Y28) -> 20.62
A29: =+A28+1 -> 17 | B29: រឿន សារី | C29: ROEUN SARY | F29: =ROUND(VLOOKUP(B29,'[5]BPHAN CHIA '!$B$179:$T$200,19,0),2) -> 6.65 | G29: =ROUND(F29*1.0956,2) -> 7.29 | Z29: =SUM(G29,E29,S29,Q29,O29,M29,K29,I29,U29,W29,Y29) -> 7.29
A30: =+A29+1 -> 18 | B30: ហ៊ុច សំណាង | C30: HOCH SOMNANG | F30: =ROUND(VLOOKUP(B30,'[5]BPHAN CHIA '!$B$179:$T$200,19,0),2) -> 11.95 | G30: =ROUND(F30*1.0956,2) -> 13.09 | Z30: =SUM(G30,E30,S30,Q30,O30,M30,K30,I30,U30,W30,Y30) -> 13.09
A31: =+A30+1 -> 19 | B31: បាន ចន្ថា | C31: BAN CHANTHA | D31: =ROUND(VLOOKUP(B31,'[5]BPHAN CHIA '!$B$100:$T$110,19,0),2) -> 12.55 | E31: =ROUND(0.7199*D31,2) -> 9.03 | F31: =ROUND(VLOOKUP(B31,'[5]BPHAN CHIA '!$B$179:$T$200,19,0),2) -> 10.01 | G31: =ROUND(F31*1.0956,2) -> 10.97 | T31: ='[5]BCC D1(26)'!V95 -> 4 | U31: =ROUND(T31*0.9391,2) -> 3.76 | Z31: =SUM(G31,E31,S31,Q31,O31,M31,K31,I31,U31,W31,Y31) -> 23.76
A32: =+A31+1 -> 20 | B32: សាន់ យូស័រ | C32: SAN YUSOR | D32: =ROUND(VLOOKUP(B32,'[5]BPHAN CHIA '!$B$100:$T$110,19,0),2) -> 12.55 | E32: =ROUND(0.7199*D32,2) -> 9.03 | F32: =ROUND(VLOOKUP(B32,'[5]BPHAN CHIA '!$B$179:$T$200,19,0),2) -> 8.39 | G32: =ROUND(F32*1.0956,2) -> 9.19 | Z32: =SUM(G32,E32,S32,Q32,O32,M32,K32,I32,U32,W32,Y32) -> 18.22
A33: =+A32+1 -> 21 | B33: វុន វណ្ណា | C33: VUN VANNA | D33: =ROUND(VLOOKUP(B33,'[5]BPHAN CHIA '!$B$100:$T$110,19,0),2) -> 6.33 | E33: =ROUND(0.7199*D33,2) -> 4.56 | F33: =ROUND(VLOOKUP(B33,'[5]BPHAN CHIA '!$B$179:$T$200,19,0),2) -> 9.96 | G33: =ROUND(F33*1.0956,2) -> 10.91 | U33: =ROUND(T33*0.9391,2) -> 0 | Z33: =SUM(G33,E33,S33,Q33,O33,M33,K33,I33,U33,W33,Y33) -> 15.47
A34: =+A33+1 -> 22 | B34: ជឿន នីន | C34: CHOEUN NIN | F34: =ROUND(VLOOKUP(B34,'[5]BPHAN CHIA '!$B$179:$T$200,19,0),2) -> 11.95 | G34: =ROUND(F34*1.0956,2) -> 13.09 | Z34: =SUM(G34,E34,S34,Q34,O34,M34,K34,I34,U34,W34,Y34) -> 13.09
A35: =+A34+1 -> 23 | B35: ហឿង ហេង | C35: HOEUNG HENG | F35: =ROUND(VLOOKUP(B35,'[5]BPHAN CHIA '!$B$179:$T$200,19,0),2) -> 11.95 | G35: =ROUND(F35*1.0956,2) -> 13.09 | Z35: =SUM(G35,E35,S35,Q35,O35,M35,K35,I35,U35,W35,Y35) -> 13.09
A36: =+A35+1 -> 24 | B36: គង់ ចាន់ទ្រឿន | C36: KONG CHANTROEUN | F36: =ROUND(VLOOKUP(B36,'[5]BPHAN CHIA '!$B$179:$T$200,19,0),2) -> 11.95 | G36: =ROUND(F36*1.0956,2) -> 13.09 | Z36: =SUM(G36,E36,S36,Q36,O36,M36,K36,I36,U36,W36,Y36) -> 13.09
A37: =+A36+1 -> 25 | B37: ទៀង ឡៃស៊ីម | C37: TIENG LAISIM | F37: =ROUND(VLOOKUP(B37,'[5]BPHAN CHIA '!$B$179:$T$200,19,0),2) -> 11.95 | G37: =ROUND(F37*1.0956,2) -> 13.09 | Z37: =SUM(G37,E37,S37,Q37,O37,M37,K37,I37,U37,W37,Y37) -> 13.09
A38: =+A37+1 -> 26 | B38: ម៉ុន ម៉ោល | C38: MON MORL | D38: =ROUND(VLOOKUP(B38,'[5]BPHAN CHIA '!$B$100:$T$110,19,0),2) -> 12.54 | E38: =ROUND(0.7199*D38,2) -> 9.03 | F38: =ROUND(VLOOKUP(B38,'[5]BPHAN CHIA '!$B$179:$T$200,19,0),2) -> 5.22 | G38: =ROUND(F38*1.0956,2) -> 5.72 | T38: ='[5]BCC D1(26)'!V96 -> 4 | U38: =ROUND(T38*0.9391,2) -> 3.76 | Z38: =SUM(G38,E38,S38,Q38,O38,M38,K38,I38,U38,W38,Y38) -> 18.51
A39: =+A38+1 -> 27 | B39: កែវ ប្រុសសុទ្ធ | C39: KEO BROSSOTH | D39: =ROUND(VLOOKUP(B39,'[5]BPHAN CHIA '!$B$100:$T$110,19,0),2) -> 1.63 | E39: =ROUND(0.7199*D39,2) -> 1.17 | F39: =ROUND(VLOOKUP(B39,'[5]BPHAN CHIA '!$B$179:$T$200,19,0),2) -> 8.53 | G39: =ROUND(F39*1.0956,2) -> 9.35 | Z39: =SUM(G39,E39,S39,Q39,O39,M39,K39,I39,U39,W39,Y39) -> 10.52
A40: =+A39+1 -> 28 | B40: ម៉ុក សុធា | C40: MOK SOTHEA | D40: =ROUND(VLOOKUP(B40,'[5]BPHAN CHIA '!$B$100:$T$110,19,0),2) -> 5.67 | E40: =ROUND(0.7199*D40,2) -> 4.08 | F40: =ROUND(VLOOKUP(B40,'[5]BPHAN CHIA '!$B$179:$T$200,19,0),2) -> 11.95 | G40: =ROUND(F40*1.0956,2) -> 13.09 | Z40: =SUM(G40,E40,S40,Q40,O40,M40,K40,I40,U40,W40,Y40) -> 17.17
A41: =+A40+1 -> 29 | B41: ជឿន ថា | C41: CHOEUN THA | D41: =ROUND(VLOOKUP(B41,'[5]BPHAN CHIA '!$B$11:$T$19,19,0)*1.1,2) -> 52.34 | E41: =ROUND(0.7199*D41,2) -> 37.68 | Z41: =SUM(G41,E41,S41,Q41,O41,M41,K41,I41,U41,W41,Y41) -> 37.68
A42: =+A41+1 -> 30 | B42: ហ៊ុន ម៉ៅ | C42: HUN MAO | D42: =ROUND(VLOOKUP(B42,'[5]BPHAN CHIA '!$B$11:$T$19,19,0),2) -> 47.58 | E42: =ROUND(0.7199*D42,2) -> 34.25 | Z42: =SUM(G42,E42,S42,Q42,O42,M42,K42,I42,U42,W42,Y42) -> 34.25
...

Sheet KLCN t1 dot 2
A1: ក្រុមហ៊ុន កៅស៊ូ មេគង្គ ខូ អិលធីឌី | M1: ព្រះរាជាណាចក្រ កម្ពុជា
A2: CÔNG TY TNHH CAO SU MEKONG | M2: VƯƠNG QUỐC CAMPUCHIA
A3: រោងចក្រកែច្នៃ | M3: ជាតិ សាសនា ព្រះមហាក្សត្រ
A4: XƯỞNG CHẾ BIẾN | M4: Dân tộc - Tôn giáo - Quốc vương
A6: តារាងបរិមាណកម្មករ រោងចក្រកែច្នៃជ័រកៅស៊ូ ខែ ១២ ឆ្នាំ ២០២៥
A7: ចាប់ពីថ្ងៃ ១៦ឥ៣១ ខែ ០១ ឆ្នាំ ២០២៦ (វគ្គទី ២)
A8: BẢNG KHỐI LƯỢNG CÔNG NHÂN XƯỞNG CHẾ BIẾN THÁNG 01 NĂM 2026
A9: TỪ NGÀY 16-31 THÁNG 01 NĂM 2026 (ĐỢT 2)
A11: ល.រ STT | B11: ត្រកូលនិងឈ្មោះ Họ và tên | D11: ជ័រកិន (Làm mủ cán vắt) | F11: ជ័រសម្រេច (Làm mủ Thành phẩm) | H11: អ្នកធ្វើការមិនរើសមុខ (Tạp vụ) | J11: សន្ដិសុខការពារ​​​​​ (Bảo vệ) | L11: អ្នកបើកឡាន (Tài xế) | N11: សម្អាត (Vệ sinh) | P11: កម្មករ មេកានិច (Công nhân cơ khí) | R11: កាត់ស្មៅ ពន្លត់អគ្គីភ័យ/Phát cỏ phòng chống cháy | T11: លាងសម្អាតធុងសម្ងួតជ័រ/ vệ sinh thùng sấy mủ | V11: ប្ដូរតែម/Thay tem nhãn | X11: ប្រាក់ថ្ងៃបុណ្យចូលឆ្នាំសកល (Tiền lễ dương lịch 1/1/2026) | Z11: មី និងប្រេងឆាឲ្យកម្មករ (Mì, dầu ăn cho CN) | AB11: សរុប Tổng công | AC11: ហត្ថលេខា KÝ TÊN
B12: អក្សរខ្មែរ (Khmer) | C12: អក្សរ ឡាតាំង (La tinh) | D12: បរិមាណ Khối lượng | E12: កម្លាំង Công | F12: បរិមាណ Khối lượng | G12: កម្លាំង Công | H12: បរិមាណ Khối lượng | I12: កម្លាំង Công | J12: បរិមាណ Khối lượng | K12: កម្លាំង Công | L12: បរិមាណ Khối lượng | M12: កម្លាំង Công | N12: បរិមាណ Khối lượng | O12: កម្លាំង Công | P12: បរិមាណ Khối lượng | Q12: កម្លាំង Công | R12: បរិមាណ Khối lượng | S12: កម្លាំង Công | T12: បរិមាណ Khối lượng | U12: កម្លាំង Công | V12: បរិមាណ Khối lượng | W12: កម្លាំង Công | X12: បរិមាណ Khối lượng | Y12: កម្លាំង Công | Z12: បរិមាណ Khối lượng | AA12: កម្លាំង Công
A13: 1 | B13: រិន ច្រិប | C13: RIN CHRIB | H13: ='BCC D1(26)'!X12 -> 12 | I13: =ROUND(H13*1.2233,2) -> 14.68 | X13: =ROUND(VLOOKUP(B13,'BCC D1(26)'!$B$12:$V$79,21,0),0) -> 1 | Y13: =ROUND(X13*0.5008,2) -> 0.5 | Z13: =VLOOKUP(B13,'BCC D1(26)'!$B$12:$W$88,22,0) -> 0 | AA13: =ROUND(Z13*1.0956,2) -> 0 | AB13: =SUM(G13,E13,S13,Q13,O13,M13,K13,I13,U13,Y13,AA13,W13) -> 15.18
A14: =+A13+1 -> 2 | B14: កែវ សម្បត្តិ | C14: KEO SAMBATH | J14: ='BCC D1(26)'!X13 -> 14 | K14: =ROUND(J14*1.0736,2) -> 15.03 | R14: ='BCC D1(26)'!X91 -> 10 | S14: =ROUND(R14*1.3147,2) -> 13.15 | X14: =ROUND(VLOOKUP(B14,'BCC D1(26)'!$B$12:$V$79,21,0),0) -> 1 | Y14: =ROUND(X14*0.5008,2) -> 0.5 | Z14: =VLOOKUP(B14,'BCC D1(26)'!$B$12:$W$88,22,0) -> 1 | AA14: =ROUND(Z14*1.0956,2) -> 1.1 | AB14: =SUM(G14,E14,S14,Q14,O14,M14,K14,I14,U14,Y14,AA14,W14) -> 29.78 | AF14: គី គីន
A15: =+A14+1 -> 3 | B15: ផន ឃី | C15: PHORN KHY | N15: ='BCC D1(26)'!X14 -> 13 | O15: =ROUND(N15*0.9704,2) -> 12.62 | X15: =ROUND(VLOOKUP(B15,'BCC D1(26)'!$B$12:$V$79,21,0),0) -> 1 | Y15: =ROUND(X15*0.5008,2) -> 0.5 | Z15: =VLOOKUP(B15,'BCC D1(26)'!$B$12:$W$88,22,0) -> 1 | AA15: =ROUND(Z15*1.0956,2) -> 1.1 | AB15: =SUM(G15,E15,S15,Q15,O15,M15,K15,I15,U15,Y15,AA15,W15) -> 14.22
A16: =+A15+1 -> 4 | B16: ថន ម៉ន | C16: THORN MORN | L16: =SUM('BCC D1(26)'!X15:X16) -> 20.5 | M16: =ROUND(L16*1.426,2) -> 29.23 | X16: =ROUND(VLOOKUP(B16,'BCC D1(26)'!$B$12:$V$79,21,0),0) -> 1 | Y16: =ROUND(X16*0.5008,2) -> 0.5 | Z16: =VLOOKUP(B16,'BCC D1(26)'!$B$12:$W$88,22,0) -> 1 | AA16: =ROUND(Z16*1.0956,2) -> 1.1 | AB16: =SUM(G16,E16,S16,Q16,O16,M16,K16,I16,U16,Y16,AA16,W16) -> 30.83
A17: =+A16+1 -> 5 | B17: សៃ រិទ្ធី | C17: SAI RITHY | L17: =SUM('BCC D1(26)'!X17:X18) -> 16.5 | M17: =ROUND(L17*1.426,2) -> 23.53 | X17: =ROUND(VLOOKUP(B17,'BCC D1(26)'!$B$12:$V$79,21,0),0) -> 1 | Y17: =ROUND(X17*0.5008,2) -> 0.5 | Z17: =VLOOKUP(B17,'BCC D1(26)'!$B$12:$W$88,22,0) -> 1 | AA17: =ROUND(Z17*1.0956,2) -> 1.1 | AB17: =SUM(G17,E17,S17,Q17,O17,M17,K17,I17,U17,Y17,AA17,W17) -> 25.13
A18: =+A17+1 -> 6 | B18: សាត រិទ្ធិសាក់ | C18: SAT RITHYSAK | P18: =SUM('BCC D1(26)'!X19:X20) -> 20.5 | Q18: =ROUND(P18*1.4353,2) -> 29.42 | X18: =ROUND(VLOOKUP(B18,'BCC D1(26)'!$B$12:$V$79,21,0),0) -> 1 | Y18: =ROUND(X18*0.5008,2) -> 0.5 | Z18: =VLOOKUP(B18,'BCC D1(26)'!$B$12:$W$88,22,0) -> 1 | AA18: =ROUND(Z18*1.0956,2) -> 1.1 | AB18: =SUM(G18,E18,S18,Q18,O18,M18,K18,I18,U18,Y18,AA18,W18) -> 31.02
A19: =+A18+1 -> 7 | B19: ហឿង សុជឿន | C19: HOEUNG SOCHOEUN | F19: =ROUND(1.15*VLOOKUP(B19,'BPHAN CHIA '!$B$179:$U$200,20,0),2) -> 10.94 | G19: =ROUND(F19*1.0956,2) -> 11.99 | T19: =VLOOKUP(B19,'BCC D1(26)'!$B$93:$X$100,23,0) -> 1 | U19: =ROUND(T19*0.9391,2) -> 0.94 | V19: =ROUND(VLOOKUP(B19,'BCC D1(26)'!$B$102:$X$114,23,0),0) -> 5 | W19: =ROUND(V19*1.2501,2) -> 6.25 | X19: =ROUND(VLOOKUP(B19,'BCC D1(26)'!$B$12:$V$79,21,0),0) -> 1 | Y19: =ROUND(X19*0.5008,2) -> 0.5 | Z19: =VLOOKUP(B19,'BCC D1(26)'!$B$12:$W$88,22,0) -> 1 | AA19: =ROUND(Z19*1.0956,2) -> 1.1 | AB19: =SUM(G19,E19,S19,Q19,O19,M19,K19,I19,U19,Y19,AA19,W19) -> 20.78
A20: =+A19+1 -> 8 | B20: ថន សំណាង | C20: THAN SAMNANG | F20: =ROUND(VLOOKUP(B20,'BPHAN CHIA '!$B$179:$U$200,20,0),2) -> 9.51 | G20: =ROUND(F20*1.0956,2) -> 10.42 | X20: =ROUND(VLOOKUP(B20,'BCC D1(26)'!$B$12:$V$79,21,0),0) -> 1 | Y20: =ROUND(X20*0.5008,2) -> 0.5 | Z20: =VLOOKUP(B20,'BCC D1(26)'!$B$12:$W$88,22,0) -> 1 | AA20: =ROUND(Z20*1.0956,2) -> 1.1 | AB20: =SUM(G20,E20,S20,Q20,O20,M20,K20,I20,U20,Y20,AA20,W20) -> 12.02
A21: =+A20+1 -> 9 | B21: ថូរ សុភ័ណ្ឌ | C21: THO SOPHORN | F21: =ROUND(VLOOKUP(B21,'BPHAN CHIA '!$B$179:$U$200,20,0),2) -> 7.62 | G21: =ROUND(F21*1.0956,2) -> 8.35 | X21: =ROUND(VLOOKUP(B21,'BCC D1(26)'!$B$12:$V$79,21,0),0) -> 1 | Y21: =ROUND(X21*0.5008,2) -> 0.5 | Z21: =VLOOKUP(B21,'BCC D1(26)'!$B$12:$W$88,22,0) -> 1 | AA21: =ROUND(Z21*1.0956,2) -> 1.1 | AB21: =SUM(G21,E21,S21,Q21,O21,M21,K21,I21,U21,Y21,AA21,W21) -> 9.95
A22: =+A21+1 -> 10 | B22: ធៀម សំនាង | C22: THEAM SAMNEANG | F22: =ROUND(VLOOKUP(B22,'BPHAN CHIA '!$B$179:$U$200,20,0),2) -> 9.51 | G22: =ROUND(F22*1.0956,2) -> 10.42 | T22: =VLOOKUP(B22,'BCC D1(26)'!$B$93:$X$100,23,0) -> 1 | U22: =ROUND(T22*0.9391,2) -> 0.94 | X22: =ROUND(VLOOKUP(B22,'BCC D1(26)'!$B$12:$V$79,21,0),0) -> 1 | Y22: =ROUND(X22*0.5008,2) -> 0.5 | Z22: =VLOOKUP(B22,'BCC D1(26)'!$B$12:$W$88,22,0) -> 1 | AA22: =ROUND(Z22*1.0956,2) -> 1.1 | AB22: =SUM(G22,E22,S22,Q22,O22,M22,K22,I22,U22,Y22,AA22,W22) -> 12.96
A23: =+A22+1 -> 11 | B23: អែល សាន់ | C23: EL SANN | F23: =ROUND(VLOOKUP(B23,'BPHAN CHIA '!$B$179:$U$200,20,0),2) -> 7.27 | G23: =ROUND(F23*1.0956,2) -> 7.97 | X23: =ROUND(VLOOKUP(B23,'BCC D1(26)'!$B$12:$V$79,21,0),0) -> 1 | Y23: =ROUND(X23*0.5008,2) -> 0.5 | Z23: =VLOOKUP(B23,'BCC D1(26)'!$B$12:$W$88,22,0) -> 1 | AA23: =ROUND(Z23*1.0956,2) -> 1.1 | AB23: =SUM(G23,E23,S23,Q23,O23,M23,K23,I23,U23,Y23,AA23,W23) -> 9.57
A24: =+A23+1 -> 12 | B24: អ៊ាវ ខាត់ | C24: EAV KHATH | F24: =ROUND(VLOOKUP(B24,'BPHAN CHIA '!$B$179:$U$200,20,0),2) -> 7.27 | G24: =ROUND(F24*1.0956,2) -> 7.97 | X24: =ROUND(VLOOKUP(B24,'BCC D1(26)'!$B$12:$V$79,21,0),0) -> 1 | Y24: =ROUND(X24*0.5008,2) -> 0.5 | Z24: =VLOOKUP(B24,'BCC D1(26)'!$B$12:$W$88,22,0) -> 1 | AA24: =ROUND(Z24*1.0956,2) -> 1.1 | AB24: =SUM(G24,E24,S24,Q24,O24,M24,K24,I24,U24,Y24,AA24,W24) -> 9.57
A25: =+A24+1 -> 13 | B25: ភី ផូ | C25: PHI PHO | F25: =ROUND(VLOOKUP(B25,'BPHAN CHIA '!$B$179:$U$200,20,0),2) -> 9.51 | G25: =ROUND(F25*1.0956,2) -> 10.42 | X25: =ROUND(VLOOKUP(B25,'BCC D1(26)'!$B$12:$V$79,21,0),0) -> 1 | Y25: =ROUND(X25*0.5008,2) -> 0.5 | Z25: =VLOOKUP(B25,'BCC D1(26)'!$B$12:$W$88,22,0) -> 0 | AA25: =ROUND(Z25*1.0956,2) -> 0 | AB25: =SUM(G25,E25,S25,Q25,O25,M25,K25,I25,U25,Y25,AA25,W25) -> 10.92
A26: =+A25+1 -> 14 | B26: វុន វណ្ណនី | C26: VON VANNY | F26: =ROUND(VLOOKUP(B26,'BPHAN CHIA '!$B$179:$U$200,20,0),2) -> 1.86 | G26: =ROUND(F26*1.0956,2) -> 2.04 | X26: =ROUND(VLOOKUP(B26,'BCC D1(26)'!$B$12:$V$79,21,0),0) -> 1 | Y26: =ROUND(X26*0.5008,2) -> 0.5 | Z26: =VLOOKUP(B26,'BCC D1(26)'!$B$12:$W$88,22,0) -> 0 | AA26: =ROUND(Z26*1.0956,2) -> 0 | AB26: =SUM(G26,E26,S26,Q26,O26,M26,K26,I26,U26,Y26,AA26,W26) -> 2.54
A27: =+A26+1 -> 15 | B27: លឿន ឆាលី | C27: LOEUN CHALY | F27: =ROUND(VLOOKUP(B27,'BPHAN CHIA '!$B$179:$U$200,20,0),2) -> 7.66 | G27: =ROUND(F27*1.0956,2) -> 8.39 | X27: =ROUND(VLOOKUP(B27,'BCC D1(26)'!$B$12:$V$79,21,0),0) -> 1 | Y27: =ROUND(X27*0.5008,2) -> 0.5 | Z27: =VLOOKUP(B27,'BCC D1(26)'!$B$12:$W$88,22,0) -> 0 | AA27: =ROUND(Z27*1.0956,2) -> 0 | AB27: =SUM(G27,E27,S27,Q27,O27,M27,K27,I27,U27,Y27,AA27,W27) -> 8.89
A28: =+A27+1 -> 16 | B28: ហឿន សាវុធ | C28: HOEURN SAVUTH | F28: =ROUND(VLOOKUP(B28,'BPHAN CHIA '!$B$179:$U$200,20,0),2) -> 7.27 | G28: =ROUND(F28*1.0956,2) -> 7.97 | V28: =ROUND(VLOOKUP(B28,'BCC D1(26)'!$B$102:$X$114,23,0),0) -> 5 | W28: =ROUND(V28*1.2501,2) -> 6.25 | X28: =ROUND(VLOOKUP(B28,'BCC D1(26)'!$B$12:$V$79,21,0),0) -> 1 | Y28: =ROUND(X28*0.5008,2) -> 0.5 | Z28: =VLOOKUP(B28,'BCC D1(26)'!$B$12:$W$88,22,0) -> 1 | AA28: =ROUND(Z28*1.0956,2) -> 1.1 | AB28: =SUM(G28,E28,S28,Q28,O28,M28,K28,I28,U28,Y28,AA28,W28) -> 15.82
A29: =+A28+1 -> 17 | B29: រឿន សារី | C29: ROEUN SARY | F29: =ROUND(VLOOKUP(B29,'BPHAN CHIA '!$B$179:$U$200,20,0),2) -> 9.51 | G29: =ROUND(F29*1.0956,2) -> 10.42 | X29: =ROUND(VLOOKUP(B29,'BCC D1(26)'!$B$12:$V$79,21,0),0) -> 1 | Y29: =ROUND(X29*0.5008,2) -> 0.5 | Z29: =VLOOKUP(B29,'BCC D1(26)'!$B$12:$W$88,22,0) -> 1 | AA29: =ROUND(Z29*1.0956,2) -> 1.1 | AB29: =SUM(G29,E29,S29,Q29,O29,M29,K29,I29,U29,Y29,AA29,W29) -> 12.02
A30: =+A29+1 -> 18 | B30: ហ៊ុច សំណាង | C30: HOCH SOMNANG | F30: =ROUND(VLOOKUP(B30,'BPHAN CHIA '!$B$179:$U$200,20,0),2) -> 7.66 | G30: =ROUND(F30*1.0956,2) -> 8.39 | X30: =ROUND(VLOOKUP(B30,'BCC D1(26)'!$B$12:$V$79,21,0),0) -> 1 | Y30: =ROUND(X30*0.5008,2) -> 0.5 | Z30: =VLOOKUP(B30,'BCC D1(26)'!$B$12:$W$88,22,0) -> 1 | AA30: =ROUND(Z30*1.0956,2) -> 1.1 | AB30: =SUM(G30,E30,S30,Q30,O30,M30,K30,I30,U30,Y30,AA30,W30) -> 9.99
A31: =+A30+1 -> 19 | B31: បាន ចន្ថា | C31: BAN CHANTHA | F31: =ROUND(VLOOKUP(B31,'BPHAN CHIA '!$B$179:$U$200,20,0),2) -> 7.27 | G31: =ROUND(F31*1.0956,2) -> 7.97 | V31: =ROUND(VLOOKUP(B31,'BCC D1(26)'!$B$102:$X$114,23,0),0) -> 5 | W31: =ROUND(V31*1.2501,2) -> 6.25 | X31: =ROUND(VLOOKUP(B31,'BCC D1(26)'!$B$12:$V$79,21,0),0) -> 1 | Y31: =ROUND(X31*0.5008,2) -> 0.5 | Z31: =VLOOKUP(B31,'BCC D1(26)'!$B$12:$W$88,22,0) -> 1 | AA31: =ROUND(Z31*1.0956,2) -> 1.1 | AB31: =SUM(G31,E31,S31,Q31,O31,M31,K31,I31,U31,Y31,AA31,W31) -> 15.82
A32: =+A31+1 -> 20 | B32: សាន់ យូស័រ | C32: SAN YUSOR | F32: =ROUND(VLOOKUP(B32,'BPHAN CHIA '!$B$179:$U$200,20,0),2) -> 9.51 | G32: =ROUND(F32*1.0956,2) -> 10.42 | X32: =ROUND(VLOOKUP(B32,'BCC D1(26)'!$B$12:$V$79,21,0),0) -> 1 | Y32: =ROUND(X32*0.5008,2) -> 0.5 | Z32: =VLOOKUP(B32,'BCC D1(26)'!$B$12:$W$88,22,0) -> 0 | AA32: =ROUND(Z32*1.0956,2) -> 0 | AB32: =SUM(G32,E32,S32,Q32,O32,M32,K32,I32,U32,Y32,AA32,W32) -> 10.92
A33: =+A32+1 -> 21 | B33: វុន វណ្ណា | C33: VUN VANNA | F33: =ROUND(VLOOKUP(B33,'BPHAN CHIA '!$B$179:$U$200,20,0),2) -> 4.63 | G33: =ROUND(F33*1.0956,2) -> 5.07 | X33: =ROUND(VLOOKUP(B33,'BCC D1(26)'!$B$12:$V$79,21,0),0) -> 1 | Y33: =ROUND(X33*0.5008,2) -> 0.5 | Z33: =VLOOKUP(B33,'BCC D1(26)'!$B$12:$W$88,22,0) -> 1 | AA33: =ROUND(Z33*1.0956,2) -> 1.1 | AB33: =SUM(G33,E33,S33,Q33,O33,M33,K33,I33,U33,Y33,AA33,W33) -> 6.67
A34: =+A33+1 -> 22 | B34: ជឿន នីន | C34: CHOEUN NIN | F34: =ROUND(VLOOKUP(B34,'BPHAN CHIA '!$B$179:$U$200,20,0),2) -> 9.51 | G34: =ROUND(F34*1.0956,2) -> 10.42 | T34: =VLOOKUP(B34,'BCC D1(26)'!$B$93:$X$100,23,0) -> 1 | U34: =ROUND(T34*0.9391,2) -> 0.94 | X34: =ROUND(VLOOKUP(B34,'BCC D1(26)'!$B$12:$V$79,21,0),0) -> 1 | Y34: =ROUND(X34*0.5008,2) -> 0.5 | Z34: =VLOOKUP(B34,'BCC D1(26)'!$B$12:$W$88,22,0) -> 1 | AA34: =ROUND(Z34*1.0956,2) -> 1.1 | AB34: =SUM(G34,E34,S34,Q34,O34,M34,K34,I34,U34,Y34,AA34,W34) -> 12.96
A35: =+A34+1 -> 23 | B35: ហឿង ហេង | C35: HOEUNG HENG | F35: =ROUND(VLOOKUP(B35,'BPHAN CHIA '!$B$179:$U$200,20,0),2) -> 7.77 | G35: =ROUND(F35*1.0956,2) -> 8.51 | V35: =ROUND(VLOOKUP(B35,'BCC D1(26)'!$B$102:$X$114,23,0),0) -> 5 | W35: =ROUND(V35*1.2501,2) -> 6.25 | X35: =ROUND(VLOOKUP(B35,'BCC D1(26)'!$B$12:$V$79,21,0),0) -> 1 | Y35: =ROUND(X35*0.5008,2) -> 0.5 | Z35: =VLOOKUP(B35,'BCC D1(26)'!$B$12:$W$88,22,0) -> 0 | AA35: =ROUND(Z35*1.0956,2) -> 0 | AB35: =SUM(G35,E35,S35,Q35,O35,M35,K35,I35,U35,Y35,AA35,W35) -> 15.26
A36: =+A35+1 -> 24 | B36: គង់ ចាន់ទ្រឿន | C36: KONG CHANTROEUN | F36: =ROUND(VLOOKUP(B36,'BPHAN CHIA '!$B$179:$U$200,20,0),2) -> 7.77 | G36: =ROUND(F36*1.0956,2) -> 8.51 | X36: =ROUND(VLOOKUP(B36,'BCC D1(26)'!$B$12:$V$79,21,0),0) -> 1 | Y36: =ROUND(X36*0.5008,2) -> 0.5 | Z36: =VLOOKUP(B36,'BCC D1(26)'!$B$12:$W$88,22,0) -> 0 | AA36: =ROUND(Z36*1.0956,2) -> 0 | AB36: =SUM(G36,E36,S36,Q36,O36,M36,K36,I36,U36,Y36,AA36,W36) -> 9.01
A37: =+A36+1 -> 25 | B37: ទៀង ឡៃស៊ីម | C37: TIENG LAISIM | F37: =ROUND(VLOOKUP(B37,'BPHAN CHIA '!$B$179:$U$200,20,0),2)+0.01 -> 9.52 | G37: =ROUND(F37*1.0956,2) -> 10.43 | X37: =ROUND(VLOOKUP(B37,'BCC D1(26)'!$B$12:$V$79,21,0),0) -> 1 | Y37: =ROUND(X37*0.5008,2) -> 0.5 | Z37: =VLOOKUP(B37,'BCC D1(26)'!$B$12:$W$88,22,0) -> 1 | AA37: =ROUND(Z37*1.0956,2) -> 1.1 | AB37: =SUM(G37,E37,S37,Q37,O37,M37,K37,I37,U37,Y37,AA37,W37) -> 12.03
A38: =+A37+1 -> 26 | B38: ម៉ុន ម៉ោល | C38: MON MORL | F38: =ROUND(VLOOKUP(B38,'BPHAN CHIA '!$B$179:$U$200,20,0),2)+0.01 -> 9.52 | G38: =ROUND(F38*1.0956,2) -> 10.43 | V38: =ROUND(VLOOKUP(B38,'BCC D1(26)'!$B$102:$X$114,23,0),0) -> 5 | W38: =ROUND(V38*1.2501,2) -> 6.25 | X38: =ROUND(VLOOKUP(B38,'BCC D1(26)'!$B$12:$V$79,21,0),0) -> 1 | Y38: =ROUND(X38*0.5008,2) -> 0.5 | Z38: =VLOOKUP(B38,'BCC D1(26)'!$B$12:$W$88,22,0) -> 1 | AA38: =ROUND(Z38*1.0956,2) -> 1.1 | AB38: =SUM(G38,E38,S38,Q38,O38,M38,K38,I38,U38,Y38,AA38,W38) -> 18.28
A39: =+A38+1 -> 27 | B39: កែវ ប្រុសសុទ្ធ | C39: KEO BROSSOTH | F39: =ROUND(VLOOKUP(B39,'BPHAN CHIA '!$B$179:$U$200,20,0),2) -> 7.74 | G39: =ROUND(F39*1.0956,2)-0.01 -> 8.47 | V39: =ROUND(VLOOKUP(B39,'BCC D1(26)'!$B$102:$X$114,23,0),0) -> 4 | W39: =ROUND(V39*1.2501,2) -> 5 | X39: =ROUND(VLOOKUP(B39,'BCC D1(26)'!$B$12:$V$79,21,0),0) -> 1 | Y39: =ROUND(X39*0.5008,2) -> 0.5 | Z39: =VLOOKUP(B39,'BCC D1(26)'!$B$12:$W$88,22,0) -> 1 | AA39: =ROUND(Z39*1.0956,2) -> 1.1 | AB39: =SUM(G39,E39,S39,Q39,O39,M39,K39,I39,U39,Y39,AA39,W39) -> 15.07
A40: =+A39+1 -> 28 | B40: ម៉ុក សុធា | C40: MOK SOTHEA | F40: =ROUND(VLOOKUP(B40,'BPHAN CHIA '!$B$179:$U$200,20,0),2) -> 7.27 | G40: =ROUND(F40*1.0956,2)-0.01 -> 7.96 | V40: =ROUND(VLOOKUP(B40,'BCC D1(26)'!$B$102:$X$114,23,0),0) -> 5 | W40: =ROUND(V40*1.2501,2) -> 6.25 | X40: =ROUND(VLOOKUP(B40,'BCC D1(26)'!$B$12:$V$79,21,0),0) -> 1 | Y40: =ROUND(X40*0.5008,2) -> 0.5 | Z40: =VLOOKUP(B40,'BCC D1(26)'!$B$12:$W$88,22,0) -> 0 | AA40: =ROUND(Z40*1.0956,2) -> 0 | AB40: =SUM(G40,E40,S40,Q40,O40,M40,K40,I40,U40,Y40,AA40,W40) -> 14.71
A41: =+A40+1 -> 29 | B41: ជឿន ថា | C41: CHOEUN THA | D41: =ROUND(VLOOKUP(B41,'BPHAN CHIA '!$B$11:$U$19,20,0)*1.1,2)-0.01 -> 60.65 | E41: =ROUND(0.7199*D41,2) -> 43.66 | X41: =ROUND(VLOOKUP(B41,'BCC D1(26)'!$B$12:$V$79,21,0),0) -> 1 | Y41: =ROUND(X41*0.5008,2) -> 0.5 | Z41: =VLOOKUP(B41,'BCC D1(26)'!$B$12:$W$88,22,0) -> 1 | AA41: =ROUND(Z41*1.0956,2) -> 1.1 | AB41: =SUM(G41,E41,S41,Q41,O41,M41,K41,I41,U41,Y41,AA41,W41) -> 45.26
A42: =+A41+1 -> 30 | B42: ហ៊ុន ម៉ៅ | C42: HUN MAO | D42: =ROUND(VLOOKUP(B42,'BPHAN CHIA '!$B$11:$U$19,20,0),2) -> 55.15 | E42: =ROUND(0.7199*D42,2) -> 39.7 | X42: =ROUND(VLOOKUP(B42,'BCC D1(26)'!$B$12:$V$79,21,0),0) -> 1 | Y42: =ROUND(X42*0.5008,2) -> 0.5 | Z42: =VLOOKUP(B42,'BCC D1(26)'!$B$12:$W$88,22,0) -> 1 | AA42: =ROUND(Z42*1.0956,2) -> 1.1 | AB42: =SUM(G42,E42,S42,Q42,O42,M42,K42,I42,U42,Y42,AA42,W42) -> 41.3
...

Sheet TTL dot​2 (31947)
A1: ក្រុមហ៊ុន កៅស៊ូ មេគង្គ ខូ អិលធីឌី | P1: ព្រះរាជាណាចក្រ កម្ពុជា
A2: CÔNG TY TNHH CAO SU MEKONG | P2: VƯƠNG QUỐC CAMPUCHIA
A3: រោងចក្រកែច្នៃ | P3: ជាតិ សាសនា ព្រះមហាក្សត្រ
A4: XƯỞNG CHẾ BIẾN | P4: Dân tộc - Tôn giáo - Quốc vương
A5: តារាងទូទាត់បៀវត្សកម្មកររោងចក្រកែច្នៃជ័រកៅស៊ូ ខែ ០១ ឆ្នាំ ២០២៦
A6: ចាប់ពីថ្ងៃ ១៦-៣១ ខែ ០១ ឆ្នាំ ២០២៦ (វគ្គទី ២)
A7: BẢNG THANH TOÁN LƯƠNG CÔNG NHÂN XƯỞNG CHẾ BIẾN THÁNG 01 NĂM 2026​​ (ĐỢT 2)
A8: TỪ NGÀY 16-31 THÁNG​ 01 NĂM 2026
R9: ឯកតា/ | S9: ĐVT: Riel
A10: ល.រ STT | B10: ត្រកូល និង ឈ្មោះ / Họ và tên | D10: លេខអត្តសញ្ញាណ​បណ្ណ Số CMND | E10: បទដ្ឋាន Định mức 31.947 Riel/ công | F10: បៀវត្សថ្ងៃធម្មតា វគ្គទី១ Lương ngày | H10: បៀវត្សថ្ងៃធម្មតា វគ្គទី​​​២ Lương ngày | J10: បៀវត្សដាច់ឆ្នាំ (Lương thâm niên) | K10: សរុប Tổng lương | L10: បំណុល/ Công nợ | Q10: សរុបបំណុល Tổng nợ | R10: ត្រូវទទួល Thực nhận | S10: ហត្ថលេខាទទួល KÝ NHẬN | U10: Tạm ứng lương | V10: Thực lãnh
B11: អក្សរខ្មែរ (Khmer) | C11: អក្សរ ឡាតាំង (La tinh) | F11: កម្លាំង Công | G11: ជាប្រាក់ Thành Tiền | H11: កម្លាំង Công | I11: ជាប្រាក់ Thành Tiền | L11: បុរេប្រទាន បៀវត្ស T/ứ lương | M11: ភាគទានប្រាក់សោធនវគ្គទី១​​​/ BHXH đợt 1 | N11: ភាគទានប្រាក់សោធន​​​/ BHXH | O11: ភាគទានប្រាក់សោធនវគ្គទី២​​​/ BHXH đợt 2 | P11: ពន្ធលើប្រាក់បៀវត្ស/ TNCN | W11: Gia cảnh | Z11: STT | AA11: Công việc | AB11: Tổng lương trả trong tháng bao gồm phụ cấp (riel) | AC11: Mì gạo dầu ăn (riel)
A12: A | B12: B | C12: C | D12: D | E12: 1 | F12: 2 | G12: 3 | H12: 4 | I12: 5 | J12: 6 | K12: 6 | L12: 7 | M12: 8 | N12: 9 | O12: 10 | P12: 11 | Q12: 12 | R12: 13 | S12: 14
A13: 1 | B13: រិន ច្រិប | C13: RIN CHRIB | D13: 150952531 | E13: 31947 | F13: =VLOOKUP(B13,'KLCN t1 dot 1'!$B$13:$Z$83,25,0) -> 13.11 | G13: =ROUND(F13*E13,0) -> 418825 | H13: =VLOOKUP(B13,'KLCN t1 dot 2'!$B$13:$AB$83,27,0) -> 15.18 | I13: =ROUND(E13*H13,0) -> 484955 | K13: =I13+J13+G13 -> 903780 | L13: =VLOOKUP(B13,'[5]TTL dot​2 (31947)'!B$13:R$83,17,0) -> 410448 | M13: =IF(G13<=400000,400000*2%,IF(G13<=1200000,ROUND(G13*2%,0),ROUND(1200000*2%,0))) -> 8377 | N13: =IF(K13<=400000,400000*2%,IF(K13<=1200000,ROUND(K13*2%,0),ROUND(1200000*2%,0))) -> 18076 | O13: =N13-M13 -> 9699 | P13: =ROUND(IF((K13-J13-N13)<=1500000,0,IF(AND(((K13-J13-N13))>1500000,((K13-J13-N13))<=2000000),((K13-J13-N13))*5%-75000,IF(AND(((K13-J13-N13))>2000000,((K13-J13-N13))<=8500000),((K13-J13-N13))*10%-175000))),0) -> 0 | Q13: =L13+M13+O13+P13 -> 428524 | R13: =ROUND(K13-Q13,0) -> 475256 | U13: 50000 | V13: =+R13-U13 -> 425256 | W13: =#REF! -> #REF! | X13: 100000
A14: =+A13+1 -> 2 | B14: កែវ សម្បត្តិ | C14: KEO SAMBATH | D14: 110471355 | E14: 31947 | F14: =VLOOKUP(B14,'KLCN t1 dot 1'!$B$13:$Z$83,25,0) -> 20.19 | G14: =ROUND(F14*E14,0) -> 645010 | H14: =VLOOKUP(B14,'KLCN t1 dot 2'!$B$13:$AB$83,27,0) -> 29.78 | I14: =ROUND(E14*H14,0) -> 951382 | K14: =I14+J14+G14 -> 1596392 | L14: =VLOOKUP(B14,'[5]TTL dot​2 (31947)'!B$13:R$83,17,0) -> 632110 | M14: =IF(G14<=400000,400000*2%,IF(G14<=1200000,ROUND(G14*2%,0),ROUND(1200000*2%,0))) -> 12900 | N14: =IF(K14<=400000,400000*2%,IF(K14<=1200000,ROUND(K14*2%,0),ROUND(1200000*2%,0))) -> 24000 | O14: =N14-M14 -> 11100 | P14: =ROUND(IF((K14-J14-N14)<=1500000,0,IF(AND(((K14-J14-N14))>1500000,((K14-J14-N14))<=2000000),((K14-J14-N14))*5%-75000,IF(AND(((K14-J14-N14))>2000000,((K14-J14-N14))<=8500000),((K14-J14-N14))*10%-175000))),0) -> 3620 | Q14: =L14+M14+O14+P14 -> 659730 | R14: =ROUND(K14-Q14,0) -> 936662 | U14: 200000 | V14: =+R14-U14 -> 736662 | W14: =+#REF! -> #REF! | X14: 200000
