Workbook

Sheet BCD D1T1
A1: ក្រុមហ៊ុន កៅស៊ូ មេគង្គ ខូ អិលធីឌី | G1: ព្រះរាជាណាចក្រ កម្ពុជា
A2: CÔNG TY TNHH CAO SU MEKONG | G2: VƯƠNG QUỐC CAMPUCHIA
A3: រោងចក្រកែច្នៃ | G3: ជាតិ សាសនា ព្រះមហាក្សត្រ
A4: XƯỞNG CHẾ BIẾN | G4: Dân tộc - Tôn giáo - Quốc vương
A6: តារាងតុល្យភាពបំណុល
A7: បៀវត្សកម្មកររោងចក្រកែច្នៃជ័រកៅស៊ូ ខែ ០១ ឆ្នាំ​ ២០២៦ (វគ្គទី១)
A8: BẢNG CÂN ĐỐI CÔNG NỢ
A9: LƯƠNG CÔNG NHÂN XƯỞNG CHẾ BIẾN THÁNG 01 NĂM 2026 (ĐỢT 1)
B11: I/ សរុបបៀវត្សខែ ០១/២០២៦ (Tổng lương tháng 01/2026): | G11: =G12+G13 -> 45775579 | H11: Riel | J11: ='TTL dot​2 (31947)'!K84 -> 45775579
B12: 1/ ប្រាក់បៀវត្សទី ១ (Tiền lương đợt 1) ៖ | G12: ='TTL dot​2 (31947)'!G84 -> 45775579 | H12: Riel | J12: =#REF! -> #REF!
B13: 2/ ប្រាក់បៀវត្សទី ២ (Tiền lương đợt 2) ៖ | G13: ='TTL dot​2 (31947)'!I84 -> 0 | H13: Riel | J13: ='[1]TTL dot 1 (31948)'!I84 -> 0
B14: II/ ប្រាក់បានទទួល (Các khoản đã nhận): | G14: =SUM(G15:G16) -> 932463 | H14: Riel | J14: =G14+G17 -> 932463
B15: 1/ទូទាត់ប្រាក់បៀវត្សលើកទី ១ (Thanh toán lương đợt 1) ៖ | G15: ='TTL dot​2 (31947)'!L84 -> 0 | H15: Riel
B16: 2/ ភាគទានប្រាក់សោធនវគ្គទី១​​​/ BHXH Đợt 1 | G16: ='TTL dot​2 (31947)'!M84 -> 932463 | H16: Riel
B17: III/ ប្រាក់ត្រូវប្រមូល (Các khoản phải thu): | G17: =SUM(G18:G21) -> 0 | H17: Riel | J17: ='TTL dot​2 (31947)'!Q84 -> 932463
B18: 1/ ពន្ធលើប្រាក់បៀវត្ស (Thuế TNCN): | G18: ='TTL dot​2 (31947)'!P84 -> 0 | H18: Riel
B19: 2/ ភាគទានប្រាក់សោធនវគ្គទី១​​​/ BHXH Đợt 1 | G19: 0 | H19: Riel
B20: 2/ ភាគទានប្រាក់សោធនវគ្គទី២​​​/ BHXH Đợt 2 | G20: ='TTL dot​2 (31947)'!O84 -> 0 | H20: Riel
B21: 3/ បុរេប្រទានផ្ទាល់ខ្លួន (Tạm ứng cá nhân): | G21: 0 | H21: Riel
B22: IV/ ប្រាក់ត្រូវទទួល (Thực nhận): | G22: =G23 -> 44843116 | H22: Riel | M22: សាមសិបប្រាំបួនលាន ប្រាំម៉ឺន ប្រាំពីរពាន់ ប្រាំរយ ហាសិបបួន រៀល
B23: 1/ ប្រាក់បៀវត្សត្រូវទទួល (Tiền lương thực nhận): | G23: =ROUND(G11-G14-G17,0) -> 44843116 | H23: Riel | J23: ='TTL dot​2 (31947)'!R84 -> 44843116 | M23: ( Bằng chữ: Ba mươi chín triệu không trăm năm mươi bảy nghìn năm trăm năm mươi bốn riel)
A25: សែសិបបួនលាន ប្រាំបីរយសែសិបបីពាន់ មួយរយដប់ប្រាំមួយ រៀលគត់។
A26: ( Bằng chữ: Bốn mươi bốn triệu tám trăm bốn mươi ba nghìn một trăm mười sáu riel)
F28: កំពង់ធំ, ថ្ងៃ (ngày) 31 ខែ (tháng) 01 ឆ្នាំ (năm) 2026
A29: ផ.ហិរ.គណនេយ្យ | E29: រោងចក្រកែច្នៃ | G29: អ្នករៀបចំ
A30: PHÒNG TCKT | E30: XƯỞNG CHẾ BIẾN | G30: Lập biểu
G34: Bùi Ngọc Triệu
A35: អនុម័តនាយកក្រុមហ៊ុន/DUYỆT GIÁM ĐỐC

Sheet BPTL D1T1
A2: ក្រុមហ៊ុន កៅស៊ូ មេគង្គ ខូ អិលធីឌី | G2: ព្រះរាជាណាចក្រ កម្ពុជា
A3: CÔNG TY TNHH CAO SU MEKONG | G3: VƯƠNG QUỐC CAMPUCHIA
A4: រោងចក្រកែច្នៃ | G4: ជាតិ សាសនា ព្រះមហាក្សត្រ
A5: XƯỞNG CHẾ BIẾN | G5: Dân tộc - Tôn giáo - Quốc vương
A7: តារាងបែងចែកប្រាក់បៀវត្សកម្មករ​រោងចក្រកែច្នៃជ័រកៅស៊ូខែ ១២ ឆ្នាំ​ ២០២៥(វគ្គទី ២)
A8: BẢNG PHÂN TOÁN LƯƠNG CÔNG NHÂN XƯỞNG CHẾ BIẾN THÁNG 12 NĂM 2025​​​ ( ĐỢT 2)
H10: ឯកតា/ | I10: ĐVT៖ Riel
A11: ល.រ | B11: រាយនាមការងារ | C11: តម្លៃ | D11: កម្លាំងថ្ងៃធម្មតា Công ngày | F11: កម្លាំងថែមម៉ោង Công làm thêm giờ | H11: សរុប | I11: កំណត់ចំណាំ
A12: STT | B12: Hạng mục công việc | C12: Đơn​ giá | D12: កម្លាំង Công | E12: ជាប្រាក់ Thành tiền | F12: កម្លាំង Công | G12: ជាប្រាក់ Thành tiền | H12: Tổng cộng | I12: Ghi chú
A13: A | B13: B | C13: 1 | D13: 2 | E13: 3=1x2 | F13: 4 | G13: 5=4x1 | H13: 6=3+5 | I13: 7
A14: I/ សរុបបៀវត្សខែ ០១/២០២៦ (Tổng lương tháng 01/2026): | E14: =SUM(E15:E22) -> 45775579 | H14: =SUM(H15:H22) -> 45775579
A15: 1 | B15: ជ័រកិន /Mủ cán vắt ( Gồm phụ cấp phụ trợ trực tiếp 10%) | C15: 31947 | D15: ='BTHKL D1 T1 (26)'!F12 -> 725.03 | E15: =ROUND(D15*C15,0) -> 23162533 | H15: =G15+E15 -> 23162533
A16: =+A15+1 -> 2 | B16: ជ័រសម្រេច/Mủ Thành phẩm (Gồm phụ cấp phụ trợ trực tiếp 15%) | C16: 31947 | D16: ='BTHKL D1 T1 (26)'!F13 -> 479.8 | E16: =ROUND(D16*C16,0) -> 15328171 | H16: =G16+E16 -> 15328171
A17: =+A16+1 -> 3 | B17: សន្ដិសុខការពារ​​​​​ (Bảo vệ) | C17: 31947 | D17: ='BTHKL D1 T1 (26)'!F14 -> 27.04 | E17: =ROUND(D17*C17,0) -> 863847 | H17: =G17+E17 -> 863847 | K17: =1*0.9391*C17 -> 30001.428 | L17: =SUM(#REF!)-K17 -> #REF! | M17: =H17-L17 -> #REF!
A18: =+A17+1 -> 4 | B18: កម្មករ មេកានិច (Công nhân cơ khí) | C18: 31947 | D18: ='BTHKL D1 T1 (26)'!F17 -> 52.59 | E18: =ROUND(D18*C18,0) -> 1680093 | H18: =G18+E18 -> 1680093 | K18: =33.17*C17 -> 1059682 | L18: =SUM(H18:H19) -> 4560115 | M18: =SUM(#REF!) -> #REF!
A19: =+A18+1 -> 5 | B19: អ្នកបើកឡាន (Tài xế) | C19: 31947 | D19: ='BTHKL D1 T1 (26)'!F18 -> 90.15 | E19: =ROUND(D19*C19,0) -> 2880022 | H19: =G19+E19 -> 2880022 | K19: =24.42*C22 -> 780145.74 | L19: =L18+K18+K19 -> 6399942.7
A20: =+A19+1 -> 6 | B20: សម្អាត (Vệ sinh) | C20: 31947 | D20: ='BTHKL D1 T1 (26)'!F19 -> 24.93 | E20: =ROUND(D20*C20,0) -> 796439 | H20: =G20+E20 -> 796439
A21: =+A20+1 -> 7 | B21: អ្នកធ្វើការមិនរើសមុខ (Tạp vụ) | C21: 31947 | D21: ='BTHKL D1 T1 (26)'!F20 -> 13.11 | E21: =ROUND(D21*C21,0) -> 418825 | H21: =G21+E21 -> 418825 | L21: =ROUND(D23*C22,0) -> 45775578
A22: =+A21+1 -> 8 | B22: កម្លាំងផ្សេង (Công Khác) | C22: 31947 | D22: ='BTHKL D1 T1 (26)'!F21 -> 20.21 | E22: =ROUND(D22*C22,0) -> 645649 | H22: =G22+E22 -> 645649 | L22: ='TTL dot​2 (31947)'!G84 -> 45775579
B23: សរុប (Tổng cộng) | D23: =SUM(D15:D22) -> 1432.86 | E23: =SUM(E15:E22) -> 45775579 | H23: =G23+E23 -> 45775579 | L23: =L22-L21 -> 1
A25: សែសិបប្រាំលាន ប្រាំពីររយចិតសិបប្រាំពាន់ ប្រាំរយចិតសិបប្រាំបួន រៀលគត់។ | L25: =A25=[2]Sheet1!$N$9 -> FALSE
A26: ( Bằng chữ: Bốn mươi lăm triệu, bảy trăm bảy mươi lăm nghìn năm trăm bảy mươi chín riel)
E28: កំពង់ធំ, ថ្ងៃ (ngày) 31 ខែ (tháng) 01 ឆ្នាំ (năm) 2026 | L28: សរុបបៀវត្សខែ ០៤/២០២៥ (Tổng lương tháng 04/2025)
A29: រោងចក្រកែច្នៃ/ XƯỞNG CHẾ BIẾN | E29: អ្នករៀបចំ/ LẬP BIỂU
E32: Bùi Ngọc Triệu
A33: ផ្នែក ចាត់តាំង រដ្ឋបាល/ PHÒNG TCHC | E33: ផ.ហិរ.គណនេយ្យ / PHÒNG TCKT
A38: អនុម័តនាយកក្រុមហ៊ុន/ DUYỆT GIÁM ĐỐC

Sheet BCC D1(26)
A1: ក្រុមហ៊ុន កៅស៊ូ មេគង្គ ខូ អិលធីឌី | P1: ព្រះរាជាណាចក្រ កម្ពុជា
A2: CÔNG TY TNHH CAO SU MEKONG | P2: VƯƠNG QUỐC CAMPUCHIA
A3: រោងចក្រកែច្នៃ | P3: ជាតិ សាសនា ព្រះមហាក្សត្រ
A4: XƯỞNG CHẾ BIẾN | P4: Dân tộc - Tôn giáo - Quốc vương
A6: ='[3]BCC D1'!A6:W6 -> តារាងវត្តមានកម្មកររោងចក្រកែច្នៃជ័រកៅស៊ូ
A7: ='[3]BCC D1'!A7:W7 -> ថ្ងៃ ០១ ៦ឥ ១៥ ខែ ០១ ឆ្នាំ ២០២៦ (វគ្គទី ១)
A8: ='[3]BCC D1'!A8:W8 -> BẢNG CHẤM CÔNG CÔNG NHÂN XƯỞNG CHẾ BIẾN
A9: ='[3]BCC D1'!A9:W9 -> NGÀY 01 ĐẾN​15 THÁNG 01 NĂM 2026 (ĐỢT 1) | Z9: =COUNTIF(F9:T9,"-") -> 0
A11: ល.រ STT | B11: ត្រកូលនិងឈ្មោះ | C11: HỌ VÀ TÊN | D11: លេខអត្តសញ្ញាណ​បណ្ណ Số CMND | E11: ថ្ងៃខែឆ្នាំកំណើត Năm sinh | F11: 1 | G11: =F11+1 -> 2 | H11: =G11+1 -> 3 | I11: =H11+1 -> 4 | J11: =I11+1 -> 5 | K11: =J11+1 -> 6 | L11: =K11+1 -> 7 | M11: =L11+1 -> 8 | N11: =M11+1 -> 9 | ... T11: =S11+1 -> 15 | U11: មី និងប្រេងឆាឲ្យកម្មករ (Mì, dầu ăn cho CN) | V11: សរុប TỔNG CỘNG | W11: សម្គាល់ GHI CHÚ | Z11: Vắng Đ 1 | AA11: Vắng Đ 2
A12: 1 | B12: រិន ច្រិប | C12: RIN CHRIB | D12: 150952531 | E12: 32274 | F12: / | G12: X | H12: X | J12: X | K12: X | L12: - | M12: - | N12: X | O12: X | Q12: X | R12: X | S12: X | T12: X | V12: =COUNTIF(F12:T12,"X")+0.5*COUNTIF(F12:T12,"/")+COUNTIF(F12:T12,"R1")+COUNTIF(F12:T12,"R")+COUNTIF(F12:T12,"R")+COUNTIF(F12:T12,"Xcv") -> 10.5 | X12: =#REF!='[3]BCC D1'!#REF! -> #REF! | Y12: =U12=#REF! -> #REF! | Z12: 1 | AA12: =COUNTIF(F12:T12,"-") -> 2 | AB12: =ROUND(AD12/AC12,4) -> 0.9545 | AC12: 11 | AD12: =V12 -> 10.5 | AE12: =ROUND(AD12*31947,0) -> 335444
A13: =+A12+1 -> 2 | B13: កែវ សម្បត្តិ | C13: KEO SAMBATH | D13: 110471355 | E13: 27485 | F13: X | G13: X | H13: X | J13: X | K13: X | L13: X | M13: X | N13: X | O13: X | Q13: X | R13: X | S13: X | T13: X | V13: =COUNTIF(F13:T13,"X")+0.5*COUNTIF(F13:T13,"/")+COUNTIF(F13:T13,"R1")+COUNTIF(F13:T13,"R")+COUNTIF(F13:T13,"R")+COUNTIF(F13:T13,"Xcv") -> 13 | X13: =#REF!='[3]BCC D1'!#REF! -> #REF! | Y13: =U13=#REF! -> #REF! | Z13: 0 | AA13: =COUNTIF(F13:T13,"-") -> 0 | AB13: =ROUND(AD13/AC13,4) -> 1.1818 | AC13: 11 | AD13: =V13 -> 13 | AE13: =ROUND(AD13*31947,0) -> 415311
B14: កែវ សម្បត្តិ | C14: KEO SAMBATH | D14: Làm thêm giờ | L14: X | M14: X | N14: X | V14: =COUNTIF(F14:T14,"X")+0.5*COUNTIF(F14:T14,"/")+COUNTIF(F14:T14,"R1")+COUNTIF(F14:T14,"R")+COUNTIF(F14:T14,"R")+COUNTIF(F14:T14,"Xcv") -> 3 | Y14: =U14=#REF! -> #REF! | AB14: =ROUND(AD14/AC14,4) -> 0.2727 | AC14: 11 | AD14: =V14 -> 3 | AE14: =ROUND(AD14*31947,0) -> 95841
A15: =+A13+1 -> 3 | B15: ផន ឃី | C15: PHORN KHY | D15: 150981478 | E15: 28166 | F15: X | G15: / | H15: X | J15: X | K15: X | L15: X | M15: X | N15: X | O15: X | Q15: X | R15: X | S15: X | T15: X | V15: =COUNTIF(F15:T15,"X")+0.5*COUNTIF(F15:T15,"/")+COUNTIF(F15:T15,"R1")+COUNTIF(F15:T15,"R")+COUNTIF(F15:T15,"R")+COUNTIF(F15:T15,"Xcv") -> 12.5 | X15: =#REF!='[3]BCC D1'!#REF! -> #REF! | Y15: =U15=#REF! -> #REF! | Z15: 0 | AA15: =COUNTIF(F15:T15,"-") -> 0 | AB15: =ROUND(AD15/AC15,4) -> 1.0564 | AC15: 10 | AD15: =V15*0.8451 -> 10.56375 | AE15: =ROUND(AD15*31947,0) -> 337480
A16: =+A15+1 -> 4 | B16: ថន ម៉ន | C16: THORN MORN | D16: 150644309 | E16: 30376 | F16: X | H16: X | J16: X | K16: X | L16: X | M16: X | N16: X | O16: X | Q16: X | R16: X | S16: X | T16: X | V16: =COUNTIF(F16:T16,"X")+0.5*COUNTIF(F16:T16,"/")+COUNTIF(F16:T16,"R1")+COUNTIF(F16:T16,"R")+COUNTIF(F16:T16,"R")+COUNTIF(F16:T16,"Xcv") -> 12 | X16: =#REF!='[3]BCC D1'!#REF! -> #REF! | Y16: =U16=#REF! -> #REF! | Z16: 0 | AA16: =COUNTIF(F16:T16,"-") -> 0 | AB16: =ROUND(AD16/AC16,4) -> 1.3659 | AC16: 11 | AD16: =V16*1.2521 -> 15.0252 | AE16: =ROUND(AD16*31947,0) -> 480010
B17: ថន ម៉ន | C17: THORN MORN | D17: Làm thêm giờ | H17: / | J17: / | K17: / | L17: / | M17: / | N17: / | O17: / | Q17: / | R17: / | S17: / | T17: / | V17: =COUNTIF(F17:T17,"X")+0.5*COUNTIF(F17:T17,"/")+COUNTIF(F17:T17,"R1")+COUNTIF(F17:T17,"R")+COUNTIF(F17:T17,"R")+COUNTIF(F17:T17,"Xcv") -> 5.5 | AB17: =V17 -> 5.5 | AE17: =AB17*5000 -> 27500
A18: 5 | B18: សៃ រិទ្ធី | C18: SAI RITHY | D18: 220195668 | E18: 37000 | G18: X | H18: X | J18: / | K18: X | O18: X | Q18: X | R18: X | S18: X | T18: X | V18: =COUNTIF(F18:T18,"X")+0.5*COUNTIF(F18:T18,"/")+COUNTIF(F18:T18,"R1")+COUNTIF(F18:T18,"R")+COUNTIF(F18:T18,"R")+COUNTIF(F18:T18,"Xcv") -> 8.5 | X18: =#REF!='[3]BCC D1'!#REF! -> #REF! | Y18: =U18=#REF! -> #REF! | Z18: 0 | AA18: =COUNTIF(F18:T18,"-") -> 0 | AB18: =ROUND(AD18/AC18,4) -> 0.9675 | AC18: 11 | AD18: =V18*1.2521 -> 10.64285 | AE18: =ROUND(AD18*31947,0) -> 340007
B19: សៃ រិទ្ធី | C19: SAI RITHY | D19: Làm thêm giờ | O19: / | Q19: / | R19: / | S19: / | T19: / | V19: =COUNTIF(F19:T19,"X")+0.5*COUNTIF(F19:T19,"/")+COUNTIF(F19:T19,"R1")+COUNTIF(F19:T19,"R")+COUNTIF(F19:T19,"R")+COUNTIF(F19:T19,"Xcv") -> 2.5 | AB19: =V19 -> 2.5 | AE19: =AB19*5000 -> 12500
A20: 6 | B20: សាត រិទ្ធិសាក់ | C20: SAT RITHYSAK | D20: 220208913 | E20: 36814 | G20: X | H20: X | J20: X | K20: X | L20: X | M20: X | N20: X | O20: X | Q20: X | R20: X | S20: X | T20: X | V20: =COUNTIF(F20:T20,"X")+0.5*COUNTIF(F20:T20,"/")+COUNTIF(F20:T20,"R1")+COUNTIF(F20:T20,"R")+COUNTIF(F20:T20,"R")+COUNTIF(F20:T20,"Xcv") -> 12 | X20: =#REF!='[3]BCC D1'!#REF! -> #REF! | Y20: =U20=#REF! -> #REF! | Z20: 0 | AA20: =COUNTIF(F20:T20,"-") -> 0 | AB20: =V20*1.2521 -> 15.0252 | AC20: =ROUND(V20*31947,0) -> 383364
B21: សាត រិទ្ធិសាក់ | C21: SAT RITHYSAK | D21: Làm thêm giờ | H21: / | J21: / | K21: / | L21: / | M21: / | N21: / | O21: / | Q21: / | R21: / | S21: / | T21: / | V21: =COUNTIF(F21:T21,"X")+0.5*COUNTIF(F21:T21,"/")+COUNTIF(F21:T21,"R1")+COUNTIF(F21:T21,"R")+COUNTIF(F21:T21,"R")+COUNTIF(F21:T21,"Xcv") -> 5.5 | AB21: =V21 -> 5.5 | AC21: =V21*5000 -> 27500
A22: 7 | B22: ហឿង សុជឿន | C22: HOEUNG SOCHOEUN | D22: 150911076 | E22: 37169 | J22: Xcv | K22: Xcv | M22: Xcv | N22: X | O22: X | P22: X | Q22: X | R22: X | S22: X | T22: X | V22: =COUNTIF(F22:T22,"X")+0.5*COUNTIF(F22:T22,"/")+COUNTIF(F22:T22,"R1")+COUNTIF(F22:T22,"R")+COUNTIF(F22:T22,"R")+COUNTIF(F22:T22,"Xcv") -> 10 | X22: =#REF!='[3]BCC D1'!#REF! -> #REF! | Z22: 1 | AA22: =COUNTIF(F22:T22,"-") -> 0
A23: =A22+1 -> 8 | B23: ថន សំណាង | C23: THAN SAMNANG | D23: 220102094 | E23: 34977 | J23: Xcv | K23: Xcv | L23: Xcv | M23: Xcv | N23: X | O23: X | P23: X | Q23: X | R23: X | S23: - | T23: X | V23: =COUNTIF(F23:T23,"X")+0.5*COUNTIF(F23:T23,"/")+COUNTIF(F23:T23,"R1")+COUNTIF(F23:T23,"R")+COUNTIF(F23:T23,"R")+COUNTIF(F23:T23,"Xcv") -> 10 | X23: =#REF!='[3]BCC D1'!#REF! -> #REF! | Z23: 0 | AA23: =COUNTIF(F23:T23,"-") -> 1
A24: =A23+1 -> 9 | B24: ថូរ សុភ័ណ្ឌ | C24: THO SOPHORN | D24: 210050404 | E24: 35370 | N24: X | O24: X | P24: X | Q24: X | R24: X | S24: X | T24: X | V24: =COUNTIF(F24:T24,"X")+0.5*COUNTIF(F24:T24,"/")+COUNTIF(F24:T24,"R1")+COUNTIF(F24:T24,"R")+COUNTIF(F24:T24,"R")+COUNTIF(F24:T24,"Xcv") -> 7 | X24: =#REF!='[3]BCC D1'!#REF! -> #REF! | Z24: 1 | AA24: =COUNTIF(F24:T24,"-") -> 0
A25: =A24+1 -> 10 | B25: ធៀម សំនាង | C25: THEAM SAMNEANG | D25: 151006137 | E25: 38944 | N25: X | O25: X | P25: X | Q25: X | R25: X | S25: X | T25: - | V25: =COUNTIF(F25:T25,"X")+0.5*COUNTIF(F25:T25,"/")+COUNTIF(F25:T25,"R1")+COUNTIF(F25:T25,"R")+COUNTIF(F25:T25,"R")+COUNTIF(F25:T25,"Xcv") -> 6 | X25: =#REF!='[3]BCC D1'!#REF! -> #REF! | Z25: 1 | AA25: =COUNTIF(F25:T25,"-") -> 1
A26: =A25+1 -> 11 | B26: អែល សាន់ | C26: EL SANN | D26: 040322767 | E26: 34973 | J26: Xcv | K26: Xcv | L26: Xcv | M26: Xcv | N26: X | O26: X | P26: X | Q26: X | R26: X | S26: X | T26: X | V26: =COUNTIF(F26:T26,"X")+0.5*COUNTIF(F26:T26,"/")+COUNTIF(F26:T26,"R1")+COUNTIF(F26:T26,"R")+COUNTIF(F26:T26,"R")+COUNTIF(F26:T26,"Xcv") -> 11 | X26: =#REF!='[3]BCC D1'!#REF! -> #REF! | Z26: 1 | AA26: =COUNTIF(F26:T26,"-") -> 0
A27: =A26+1 -> 12 | B27: អ៊ាវ ខាត់ | C27: EAV KHATH | D27: 150469697 | E27: 33704 | L27: Xcv | N27: X | O27: X | P27: X | Q27: X | R27: X | S27: X | T27: X | V27: =COUNTIF(F27:T27,"X")+0.5*COUNTIF(F27:T27,"/")+COUNTIF(F27:T27,"R1")+COUNTIF(F27:T27,"R")+COUNTIF(F27:T27,"R")+COUNTIF(F27:T27,"Xcv") -> 8 | X27: =#REF!='[3]BCC D1'!#REF! -> #REF! | Z27: 4 | AA27: =COUNTIF(F27:T27,"-") -> 0
A28: =A27+1 -> 13 | B28: ភី ផូ | C28: PHI PHO | D28: 150927708 | E28: 37085 | N28: X | O28: X | P28: X | Q28: X | R28: X | S28: X | T28: X | V28: =COUNTIF(F28:T28,"X")+0.5*COUNTIF(F28:T28,"/")+COUNTIF(F28:T28,"R1")+COUNTIF(F28:T28,"R")+COUNTIF(F28:T28,"R")+COUNTIF(F28:T28,"Xcv") -> 7 | X28: =#REF!='[3]BCC D1'!#REF! -> #REF! | Z28: 0 | AA28: =COUNTIF(F28:T28,"-") -> 0
A29: =A28+1 -> 14 | B29: វុន វណ្ណនី | C29: VON VANNY | D29: 151034061 | E29: 39153 | N29: X | O29: / | P29: X | Q29: X | R29: X | S29: X | T29: - | V29: =COUNTIF(F29:T29,"X")+0.5*COUNTIF(F29:T29,"/")+COUNTIF(F29:T29,"R1")+COUNTIF(F29:T29,"R")+COUNTIF(F29:T29,"R")+COUNTIF(F29:T29,"Xcv") -> 5.5 | X29: =#REF!='[3]BCC D1'!#REF! -> #REF! | Z29: 3 | AA29: =COUNTIF(F29:T29,"-") -> 1
A30: =A29+1 -> 15 | B30: លឿន ឆាលី | C30: LOEUN CHALY | D30: 150911069 | E30: 37366 | N30: X | O30: X | P30: X | Q30: X | R30: X | S30: - | T30: X | V30: =COUNTIF(F30:T30,"X")+0.5*COUNTIF(F30:T30,"/")+COUNTIF(F30:T30,"R1")+COUNTIF(F30:T30,"R")+COUNTIF(F30:T30,"R")+COUNTIF(F30:T30,"Xcv") -> 6 | X30: =#REF!='[3]BCC D1'!#REF! -> #REF! | Z30: 1 | AA30: =COUNTIF(F30:T30,"-") -> 1
A31: =A30+1 -> 16 | B31: ហឿន សាវុធ | C31: HOEURN SAVUTH | D31: 020520213 | E31: 31484 | J31: Xcv | K31: Xcv | L31: Xcv | M31: Xcv | N31: - | O31: X | P31: X | Q31: X | R31: X | S31: X | T31: X | V31: =COUNTIF(F31:T31,"X")+0.5*COUNTIF(F31:T31,"/")+COUNTIF(F31:T31,"R1")+COUNTIF(F31:T31,"R")+COUNTIF(F31:T31,"R")+COUNTIF(F31:T31,"Xcv") -> 10 | X31: =#REF!='[3]BCC D1'!#REF! -> #REF! | Z31: 0 | AA31: =COUNTIF(F31:T31,"-") -> 1
A32: =A31+1 -> 17 | B32: រឿន សារី | C32: ROEUN SARY | D32: 220175393 | E32: 31413 | N32: - | O32: - | P32: X | Q32: X | R32: X | S32: X | T32: - | V32: =COUNTIF(F32:T32,"X")+0.5*COUNTIF(F32:T32,"/")+COUNTIF(F32:T32,"R1")+COUNTIF(F32:T32,"R")+COUNTIF(F32:T32,"R")+COUNTIF(F32:T32,"Xcv") -> 4 | X32: =#REF!='[3]BCC D1'!#REF! -> #REF! | Z32: 1 | AA32: =COUNTIF(F32:T32,"-") -> 3
A33: =A32+1 -> 18 | B33: ហ៊ុច សំណាង | C33: HOCH SOMNANG | D33: 150936257 | E33: 37356 | N33: X | O33: X | P33: X | Q33: X | R33: X | S33: X | T33: X | V33: =COUNTIF(F33:T33,"X")+0.5*COUNTIF(F33:T33,"/")+COUNTIF(F33:T33,"R1")+COUNTIF(F33:T33,"R")+COUNTIF(F33:T33,"R")+COUNTIF(F33:T33,"Xcv") -> 7 | X33: =#REF!='[3]BCC D1'!#REF! -> #REF! | Z33: 1 | AA33: =COUNTIF(F33:T33,"-") -> 0
A34: =A33+1 -> 19 | B34: បាន ចន្ថា | C34: BAN CHANTHA | D34: 220137301 | E34: 30074 | J34: Xcv | K34: Xcv | L34: Xcv | M34: Xcv | N34: X | O34: - | P34: X | Q34: X | R34: X | S34: X | T34: X | V34: =COUNTIF(F34:T34,"X")+0.5*COUNTIF(F34:T34,"/")+COUNTIF(F34:T34,"R1")+COUNTIF(F34:T34,"R")+COUNTIF(F34:T34,"R")+COUNTIF(F34:T34,"Xcv") -> 10 | X34: =#REF!='[3]BCC D1'!#REF! -> #REF! | Z34: 3 | AA34: =COUNTIF(F34:T34,"-") -> 1
A35: =A34+1 -> 20 | B35: សាន់ យូស័រ | C35: SAN YUSOR | D35: 150940509 | E35: 37662 | J35: Xcv | K35: Xcv | L35: Xcv | M35: Xcv | N35: X | O35: - | P35: X | Q35: X | R35: - | S35: X | T35: X | V35: =COUNTIF(F35:T35,"X")+0.5*COUNTIF(F35:T35,"/")+COUNTIF(F35:T35,"R1")+COUNTIF(F35:T35,"R")+COUNTIF(F35:T35,"R")+COUNTIF(F35:T35,"Xcv") -> 9 | X35: =#REF!='[3]BCC D1'!#REF! -> #REF! | Z35: 0 | AA35: =COUNTIF(F35:T35,"-") -> 2
A36: =A35+1 -> 21 | B36: វុន វណ្ណា | C36: VUN VANNA | D36: 150657948 | E36: 36192 | J36: Xcv | M36: Xcv | N36: X | O36: X | P36: X | Q36: X | R36: X | S36: X | T36: - | V36: =COUNTIF(F36:T36,"X")+0.5*COUNTIF(F36:T36,"/")+COUNTIF(F36:T36,"R1")+COUNTIF(F36:T36,"R")+COUNTIF(F36:T36,"R")+COUNTIF(F36:T36,"Xcv") -> 8 | X36: =#REF!='[3]BCC D1'!#REF! -> #REF! | Z36: 0 | AA36: =COUNTIF(F36:T36,"-") -> 1
A37: =A36+1 -> 22 | B37: ជឿន នីន | C37: CHOEUN NIN | D37: 150952503 | E37: 38207 | N37: X | O37: X | P37: X | Q37: X | R37: X | S37: X | T37: X | V37: =COUNTIF(F37:T37,"X")+0.5*COUNTIF(F37:T37,"/")+COUNTIF(F37:T37,"R1")+COUNTIF(F37:T37,"R")+COUNTIF(F37:T37,"R")+COUNTIF(F37:T37,"Xcv") -> 7 | X37: =#REF!='[3]BCC D1'!#REF! -> #REF! | Z37: 3 | AA37: =COUNTIF(F37:T37,"-") -> 0
A38: =A37+1 -> 23 | B38: ហឿង ហេង | C38: HOEUNG HENG | D38: 220248893 | E38: 33855 | N38: X | O38: X | P38: X | Q38: X | R38: X | S38: X | T38: X | V38: =COUNTIF(F38:T38,"X")+0.5*COUNTIF(F38:T38,"/")+COUNTIF(F38:T38,"R1")+COUNTIF(F38:T38,"R")+COUNTIF(F38:T38,"R")+COUNTIF(F38:T38,"Xcv") -> 7 | X38: =#REF!='[3]BCC D1'!#REF! -> #REF! | Z38: 3 | AA38: =COUNTIF(F38:T38,"-") -> 0
A39: =A38+1 -> 24 | B39: គង់ ចាន់ទ្រឿន | C39: KONG CHANTROEUN | D39: 220105697 | E39: 35623 | N39: X | O39: X | P39: X | Q39: X | R39: X | S39: X | T39: X | V39: =COUNTIF(F39:T39,"X")+0.5*COUNTIF(F39:T39,"/")+COUNTIF(F39:T39,"R1")+COUNTIF(F39:T39,"R")+COUNTIF(F39:T39,"R")+COUNTIF(F39:T39,"Xcv") -> 7 | X39: =#REF!='[3]BCC D1'!#REF! -> #REF! | Z39: 1 | AA39: =COUNTIF(F39:T39,"-") -> 0
A40: =A39+1 -> 25 | B40: ទៀង ឡៃស៊ីម | C40: TIENG LAISIM | D40: 220216744 | E40: 37994 | N40: X | O40: X | P40: X | Q40: X | R40: X | S40: X | T40: X | V40: =COUNTIF(F40:T40,"X")+0.5*COUNTIF(F40:T40,"/")+COUNTIF(F40:T40,"R1")+COUNTIF(F40:T40,"R")+COUNTIF(F40:T40,"R")+COUNTIF(F40:T40,"Xcv") -> 7 | X40: =#REF!='[3]BCC D1'!#REF! -> #REF! | Z40: 1 | AA40: =COUNTIF(F40:T40,"-") -> 0
A41: =A40+1 -> 26 | B41: ម៉ុន ម៉ោល | C41: MON MORL | D41: 220211460 | E41: 37970 | J41: Xcv | K41: Xcv | L41: Xcv | M41: Xcv | N41: - | O41: - | P41: - | Q41: - | R41: X | S41: X | T41: X | V41: =COUNTIF(F41:T41,"X")+0.5*COUNTIF(F41:T41,"/")+COUNTIF(F41:T41,"R1")+COUNTIF(F41:T41,"R")+COUNTIF(F41:T41,"R")+COUNTIF(F41:T41,"Xcv") -> 7 | X41: =#REF!='[3]BCC D1'!#REF! -> #REF! | Z41: 1 | AA41: =COUNTIF(F41:T41,"-") -> 4
A42: =A41+1 -> 27 | B42: កែវ ប្រុសសុទ្ធ | C42: KEO BROSSOTH | D42: 151056059 | E42: 38810 | J42: / | N42: X | O42: X | P42: - | Q42: - | R42: X | S42: X | T42: X | V42: =COUNTIF(F42:T42,"X")+0.5*COUNTIF(F42:T42,"/")+COUNTIF(F42:T42,"R1")+COUNTIF(F42:T42,"R")+COUNTIF(F42:T42,"R")+COUNTIF(F42:T42,"Xcv") -> 5.5 | X42: =#REF!='[3]BCC D1'!#REF! -> #REF! | Z42: 2 | AA42: =COUNTIF(F42:T42,"-") -> 2
...

Sheet BTHKL D1 T1 (26)
A1: ក្រុមហ៊ុន កៅស៊ូ មេគង្គ ខូ អិលធីឌី | E1: ព្រះរាជាណាចក្រ កម្ពុជា
A2: CÔNG TY TNHH CAO SU MEKONG | E2: VƯƠNG QUỐC CAMPUCHIA
A3: រោងចក្រកែច្នៃ | E3: ជាតិ សាសនា ព្រះមហាក្សត្រ
A4: XƯỞNG CHẾ BIẾN | E4: Dân tộc - Tôn giáo - Quốc vương
A6: តារាងបូកសរុបបរិមាណ​ ចាប់ពីថ្ងៃ ០១-១៥ ខែ ១២ ឆ្នាំ ២០២៦ (វគ្គទី ១)
A7: BẢNG TỔNG HỢP KHỐI LƯỢNG (ĐỢT 1)
A8: NGÀY​​​​ 01 ĐẾN 15 THÁNG 01 NĂM 2026
A10: ល.រ STT | B10: រាយនាមការងារ/ Hạng mục công việc | C10: ឯកតា ĐVT | D10: កម្រិត Định mức | E10: អនុវត្ត/THỰC HIỆN | G10: សម្គាល់/ Ghi chú | I10: Đợt 1
E11: បរិមាណ/ Khối lượng | F11: កម្លាំង / Công | K11: BC hàng ngày
A12: 1 | B12: ជ័រកិន /Mủ cán vắt ( Gồm phụ cấp phụ trợ trực tiếp 10%) | C12: តោន (Tấn) | D12: =ROUND(23000/31947,4) -> 0.7199 | E12: ='[3]BTHKL D1 T1'!E13 -> 1007.12 | F12: =ROUND(E12*D12,2) -> 725.03
A13: =+A12+1 -> 2 | B13: ជ័រសម្រេច/Mủ Thành phẩm (Gồm phụ cấp phụ trợ trực tiếp 15%) | C13: តោន (Tấn) | D13: =ROUND(35000/31947,4) -> 1.0956 | E13: ='[3]BTHKL D1 T1'!E14 -> 437.93 | F13: =ROUND(E13*D13,2) -> 479.8
A14: =+A13+1 -> 3 | B14: សន្ដិសុខការពារ​​​​​ (Bảo vệ) | C14: កម្លាំង (Công) | F14: =SUM(F15:F16) -> 27.04
A15: + | B15: សន្ដិសុខការពារ​​​​​ (Bảo vệ) | C15: ថ្ងៃ (Ngày) | D15: 1.014 | E15: ='[3]BCC D1(26)'!V55 -> 10 | F15: =ROUND(D15*E15,2) -> 10.14 | G15: 1 người | I15: =ROUND(K15/J15,4) -> 1.1267 | J15: 9 | K15: =F15 -> 10.14 | L15: =ROUND(F15*31947,0) -> 323943
A16: + | B16: សន្ដិសុខការពារ​​​​​ (Bảo vệ biết TV) | C16: ថ្ងៃ (Ngày) | D16: 1.0563 | E16: =SUM('[3]BCC D1(26)'!V13:V14) -> 16 | F16: =ROUND(D16*E16,2) -> 16.9 | G16: 1 người | I16: =ROUND(K16/J16,4) -> 1.3 | J16: 13 | K16: =F16 -> 16.9 | L16: =F16*31947 -> 539904.3
A17: =+A14+1 -> 4 | B17: កម្មករ មេកានិច (Công nhân cơ khí) | C17: កម្លាំង (Công) | D17: 1.4608 | E17: =SUM('[3]BCC D1(26)'!V62:V63,'[3]BCC D1(26)'!V20:V21) -> 36 | F17: =ROUND(D17*E17,2) -> 52.59 | G17: 2 người | I17: =ROUND(K17/J17,4) -> 1.5026 | J17: 35 | K17: =F17 -> 52.59 | L17: =ROUND(F17*31947,0) -> 1680093 | M17: =K17*2 -> 105.18
A18: =+A17+1 -> 5 | B18: អ្នកបើកឡាន (Tài xế) | C18: ថ្ងៃ (Ngày) | D18: 1.4779 | E18: =SUM('[3]BCC D1(26)'!V16:V19,'[3]BCC D1(26)'!V58:V61) -> 61 | F18: =ROUND(D18*E18,2) -> 90.15 | G18: 4 người | I18: =ROUND(K18/J18,4) -> 1.6391 | J18: 55 | K18: =F18 -> 90.15 | L18: =ROUND(F18*31947/4,0) -> 720006 | M18: =K18*4 -> 360.6
A19: =+A18+1 -> 6 | B19: សម្អាត (Vệ sinh) | C19: ថ្ងៃ (Ngày) | D19: 0.9776 | E19: =SUM('[3]BCC D1(26)'!V15,'[3]BCC D1(26)'!V56) -> 25.5 | F19: =ROUND(D19*E19,2) -> 24.93 | G19: 2 người | I19: =ROUND(K19/J19,4) -> 1.385 | J19: 18 | K19: =F19 -> 24.93 | L19: =ROUND(F19*31947/2,0) -> 398219 | M19: =K19*2 -> 49.86
A20: =+A19+1 -> 7 | B20: អ្នកធ្វើការមិនរើសមុខ (Tạp vụ) | C20: ថ្ងៃ (Ngày) | D20: 1.2486 | E20: =SUM('[3]BCC D1(26)'!V12) -> 10.5 | F20: =ROUND(D20*E20,2) -> 13.11 | I20: =ROUND(K20/J20,4) -> 1.6388 | J20: 8 | K20: =F20 -> 13.11 | L20: =F20*31947 -> 418825.17
A21: =+A20+1 -> 8 | B21: កម្លាំងលើកជញ្ជូន (Công khác) | C21: កម្លាំង (Công) | F21: =SUM(F22:F25) -> 20.21 | I21: =ROUND(K21/J21,4) -> 1.8373 | J21: 11 | K21: =F21 -> 20.21 | L21: =F21*31947 -> 645648.87
A22: 8.1 | B22: លាងសម្អាតធុងសម្ងួតជ័រ/ vệ sinh thùng sấy mủ | C22: ថ្ងៃ (Ngày) | D22: 0.9391 | E22: ='[3]BCC D1(26)'!V98 -> 8 | F22: =ROUNDUP(D22*E22,2) -> 7.52 | I22: =ROUND(K22/J22,4) -> 0.5785 | J22: 13 | K22: =F22 -> 7.52 | L22: =F22*31947 -> 240241.44
A23: 8.2 | B23: កម្លាំងធ្វើបន្ថែមម៉ោងកម្លាំងឆ្កឹះជ័រឆៅចេញ ពេលនាំចេញជ័រទៅលក់ (Công xịt cỏ; phát cỏ; lễ mủ sống xuất hàng) | C23: កម្លាំង (Công) | D23: 0.9391 | E23: ='[3]BCC D1(26)'!V95 -> 5.5 | F23: =ROUND(D23*E23,2) -> 5.17 | I23: =ROUND(K23/J23,4) -> 0.6082 | J23: 8.5 | K23: =F23 -> 5.17 | L23: =F23*31947 -> 165165.99
A24: 8.3 | B24: ថ្លឹង កៅស៊ូ ប៉េអឺ ដើម្បីធើ្វសារពើភ័ណ្ឌ ថ្ងៃ ៣១/១២/២០២៥/ Cân thảm kiểm kê VT | C24: កម្លាំង (Công) | D24: =ROUND(40000/31947,4) -> 1.2521 | E24: ='[3]BCC D1(26)'!V101 -> 6 | F24: =ROUNDUP(D24*E24,2) -> 7.52
A25: 8.4 | B25: មី និងប្រេងឆាឲ្យកម្មករ (Mì, dầu ăn cho CN) | C25: កេះ (Thùng) | D25: =ROUND(35000/31947,4) -> 1.0956 | E25: ='[3]BCC D1(26)'!U104 -> 0 | F25: =ROUND(D25*E25,2) -> 0
A26: សរុប/Tổng cộng | F26: =ROUND(SUM(F12:F14,F17:F21),2) -> 1432.86 | I26: =F26*31947 -> 45775578
I27: =2290.11-627 -> 1663.11 | J27: =ROUND(F26*31947,0) -> 45775578 | K27: 1140.84
E28: កំពង់ធំ, ថ្ងៃ (ngày) 31 ខែ (tháng) 01 ឆ្នាំ (năm) 2026 | J28: =ROUND(K27*31947,0) -> 36446415
B29: អ្នករៀបចំ / Lập biểu | E29: អង្គភាពអនុវត្ត /ĐƠN VỊ THỰC HIỆN
B32: Bùi Ngọc Triệu
F36: ផ.ហិរ.គណនេយ្យ
F37: PHÒNG TCKT

Sheet BPHAN CHIA 
A1: ក្រុមហ៊ុន កៅស៊ូ មេគង្គ ខូ អិលធីឌី
A2: CÔNG TY TNHH CAO SU VRG MEKONG
A3: រោងចក្រកែច្នៃ
A4: XƯỞNG CHẾ BIẾN
A5: តារាងបែងចែកបរិមាណ កម្មករធើ្វជ័រកិនរមូរ ក្រុម ១
A6: ថ្ងៃ ០១-១៥ ខែ ០១ ឆ្នាំ ២០២៦
A7: BẢNG PHÂN CHIA KHỐI LƯỢNG CÔNG NHÂN LÀM MỦ CÁN VẮT TỔ 1
A8: ='[3]BKECHITIET TO2'!A5:N5 -> NGÀY​​​​ 01 ĐẾN 15 THÁNG 01 NĂM 2026
A10: ល.រ STT | B10: ត្រកូលនិងឈ្មោះ HỌ VÀ TÊN | D10: ឯកតា ĐVT | E10: 1 | F10: =E10+1 -> 2 | G10: =F10+1 -> 3 | H10: =G10+1 -> 4 | I10: =H10+1 -> 5 | J10: =I10+1 -> 6 | K10: =J10+1 -> 7 | L10: =K10+1 -> 8 | M10: =L10+1 -> 9 | ... S10: =R10+1 -> 15 | T10: សរុប TỔNG CỘNG | U10: សម្គាល់ GHI CHÚ | V10: ហត្ថលេខាទទួល Ký nhận
A11: 1 | B11: ជឿន ថា | C11: CHOEUN THA | D11: តោន (Tấn) | G11: 3587 | H11: 4098 | I11: 3587 | J11: 3074 | K11: 3330 | L11: 3842 | M11: 4035 | N11: 2306 | O11: 3586 | P11: 3330 | Q11: 4355 | R11: 4355 | S11: 4098 | T11: =ROUND(U11/1000,3) -> 47.583 | U11: =SUM(E11:S11) -> 47583 | X11: =T11+T64+T100+T136 -> 111.39 | Y11: =ROUND(T11*0.1,2) -> 4.76 | Z11: =Y11+T11 -> 52.343
A12: 2 | B12: ហ៊ុន ម៉ៅ | C12: HUN MAO | D12: តោន (Tấn) | G12: 3587 | H12: 4098 | I12: 3587 | J12: 3074 | K12: 3330 | L12: 3842 | M12: 4035 | N12: 2305 | O12: 3587 | P12: 3330 | Q12: 4355 | R12: 4355 | S12: 4098 | T12: =ROUND(U12/1000,3) -> 47.583 | U12: =SUM(E12:S12) -> 47583
A13: 3 | B13: ជឿន ថី | C13: CHOEUN THEY | D13: តោន (Tấn) | G13: 3587 | H13: 4098 | I13: 3587 | J13: 3074 | K13: 3330 | L13: 3842 | M13: 4035 | N13: 2305 | O13: 3587 | P13: 3330 | Q13: 4355 | R13: 4355 | S13: 4098 | T13: =ROUND(U13/1000,3) -> 47.583 | U13: =SUM(E13:S13) -> 47583
A14: 4 | B14: ឆឹម ខុន | C14: CHHEOM KHON | D14: តោន (Tấn) | G14: 3586 | H14: 4099 | I14: 3586 | J14: 3074 | K14: 3331 | L14: 3842 | M14: 4035 | N14: 2305 | O14: 3587 | P14: 3330 | Q14: 4355 | R14: 4355 | S14: 4098 | T14: =ROUND(U14/1000,3) -> 47.583 | U14: =SUM(E14:S14) -> 47583
A15: 5 | B15: ថន សុខធា | C15: THON SOKHTHEA | D15: តោន (Tấn) | G15: 3586 | H15: 4099 | I15: 3586 | J15: 3074 | K15: 3331 | L15: 3842 | M15: 4035 | N15: 2305 | O15: 3586 | P15: 3331 | Q15: 4355 | R15: 4355 | S15: 4098 | T15: =ROUND(U15/1000,3) -> 47.583 | U15: =SUM(E15:S15) -> 47583
A16: 6 | B16: នី គីន | C16: NY KIN | D16: តោន (Tấn) | G16: 3586 | H16: 4099 | I16: 3586 | J16: 3074 | K16: 3330 | L16: 3843 | M16: - | N16: 2306 | O16: 3586 | P16: 3331 | Q16: 4354 | R16: 4355 | S16: 4100 | T16: =ROUND(U16/1000,3) -> 43.55 | U16: =SUM(E16:S16) -> 43550
A17: 7 | B17: វុន ហួន | C17: VUN HOUN | D17: តោន (Tấn) | G17: 3586 | H17: 4099 | I17: 3586 | J17: 3074 | K17: 3330 | L17: 3843 | M17: 4034 | N17: 2306 | O17: 3586 | P17: 3330 | Q17: 4355 | R17: 4355 | S17: 4099 | T17: =ROUND(U17/1000,3) -> 47.583 | U17: =SUM(E17:S17) -> 47583
A18: 8 | B18: លី​ ប៊ុនយ៉េន | C18: LY BUNYEN | D18: តោន (Tấn) | G18: 3586 | H18: 4099 | I18: 3586 | J18: 3074 | K18: 3330 | L18: 3843 | M18: 4034 | N18: 2306 | O18: 3586 | P18: 3330 | Q18: 4355 | R18: 4355 | S18: 4099 | T18: =ROUND(U18/1000,3) -> 47.583 | U18: =SUM(E18:S18) -> 47583
A19: 9 | B19: ធឿន​ វុឌ្ឍី | C19: THOEUN VUTHY | D19: តោន (Tấn) | G19: 3586 | H19: 4099 | I19: 3586 | J19: 3074 | K19: 3330 | L19: 3843 | M19: 4034 | N19: 2306 | O19: 3586 | P19: 3330 | Q19: 4355 | R19: 4354 | S19: 4100 | T19: =ROUND(U19/1000,3) -> 47.583 | U19: =SUM(E19:S19) -> 47583
B20: Cộng | E20: =SUM(E11:E19) -> 0 | F20: =SUM(F11:F19) -> 0 | G20: =SUM(G11:G19) -> 32277 | H20: =SUM(H11:H19) -> 36888 | I20: =SUM(I11:I19) -> 32277 | J20: =SUM(J11:J19) -> 27666 | K20: =SUM(K11:K19) -> 29972 | L20: =SUM(L11:L19) -> 34582 | ... U20: =SUM(U11:U19) -> 424214 | X20: 143710 | Y20: =T20+T73 -> 804.624
E21: =VLOOKUP(E10,'[3]BKECHITIET TO1'!$A$11:$K$24,11) -> 0 | F21: =VLOOKUP(F10,'[3]BKECHITIET TO1'!$A$11:$K$24,11) -> 0 | G21: =VLOOKUP(G10,'[3]BKECHITIET TO1'!$A$11:$K$24,11) -> 32277 | H21: =VLOOKUP(H10,'[3]BKECHITIET TO1'!$A$11:$K$24,11) -> 36888 | I21: =VLOOKUP(I10,'[3]BKECHITIET TO1'!$A$11:$K$24,11) -> 32277 | J21: =VLOOKUP(J10,'[3]BKECHITIET TO1'!$A$11:$K$24,11) -> 27666 | K21: =VLOOKUP(K10,'[3]BKECHITIET TO1'!$A$11:$K$24,11) -> 29972 | L21: =VLOOKUP(L10,'[3]BKECHITIET TO1'!$A$11:$K$24,11) -> 34582 | ... R21: =VLOOKUP(R10,'[3]BKECHITIET TO1'!$A$11:$K$24,11) -> 39194 | S21: =VLOOKUP(S10,'[3]BKECHITIET TO1'!$A$11:$K$25,11) -> 36888 | T21: =SUM(E21:S21) -> 424214
E22: =E21-E20 -> 0 | F22: =F21-F20 -> 0 | G22: =G21-G20 -> 0 | H22: =H21-H20 -> 0 | I22: =I21-I20 -> 0 | J22: =J21-J20 -> 0 | K22: =K21-K20 -> 0 | L22: =L21-L20 -> 0 | ... S22: =S21-S20 -> 0 | T22: =T21-U20 -> 0
E23: =COUNTIF(E11:E19,"X")+0.5*COUNTIF(E11:E19,"/") -> 0 | F23: =COUNTIF(F11:F19,"X")+0.5*COUNTIF(F11:F19,"/") -> 0 | G23: =COUNTIF(G11:G19,"X")+0.5*COUNTIF(G11:G19,"/") -> 0 | H23: =COUNTIF(H11:H19,"X")+0.5*COUNTIF(H11:H19,"/") -> 0 | I23: =COUNTIF(I11:I19,"X")+0.5*COUNTIF(I11:I19,"/") -> 0 | J23: =COUNTIF(J11:J19,"X")+0.5*COUNTIF(J11:J19,"/") -> 0 | K23: =COUNTIF(K11:K19,"X")+0.5*COUNTIF(K11:K19,"/") -> 0 | L23: =COUNTIF(L11:L19,"X")+0.5*COUNTIF(L11:L19,"/") -> 0 | ... S23: =COUNTIF(S11:S19,"X")+0.5*COUNTIF(S11:S19,"/") -> 0
E24: 8 | F24: 9 | G24: 9 | H24: 9 | I24: 9 | J24: 9 | K24: 9 | L24: 9 | M24: 8 | N24: 9 | O24: 9 | P24: 9 | Q24: 9 | R24: 9 | S24: 9
E25: =ROUND(E21/E24,1) -> 0 | F25: =ROUND(F21/F24,1) -> 0 | G25: =ROUND(G21/G24,1) -> 3586.3 | H25: =ROUND(H21/H24,1) -> 4098.7 | I25: =ROUND(I21/I24,1) -> 3586.3 | J25: =ROUND(J21/J24,1) -> 3074 | K25: =ROUND(K21/K24,1) -> 3330.2 | L25: =ROUND(L21/L24,1) -> 3842.4 | ... S25: =ROUND(S21/S24,1) -> 4098.7
F26: =F25/2 -> 0 | G26: =G25/2 -> 1793.15 | H26: =H25/2 -> 2049.35 | I26: =I25/2 -> 1793.15 | K26: =K25/2 -> 1665.1 | N26: =N25/2 -> 1152.8 | O26: =O25/2 -> 1793.15 | Q26: =Q25/2 -> 2177.45 | R26: =R25/2 -> 2177.45 | S26: =S25/2 -> 2049.35
Y27: =10%*(T11+T64) -> 9.1612
C38: 26129
C39: 24592
C40: 15370
A52: ក្រុមហ៊ុន កៅស៊ូ មេគង្គ ខូ អិលធីឌី
A53: =A2 -> CÔNG TY TNHH CAO SU VRG MEKONG
A54: រោងចក្រកែច្នៃ
A55: XƯỞNG CHẾ BIẾN
A58: តារាងបែងចែកបរិមាណ កម្មករធើ្វជ័រកិនរមូរ ក្រុម ២
A59: =A6 -> ថ្ងៃ ០១-១៥ ខែ ០១ ឆ្នាំ ២០២៦
A60: BẢNG PHÂN CHIA KHỐI LƯỢNG CÔNG NHÂN LÀM MỦ CÁN VẮT TỔ 2
A61: =A8 -> NGÀY​​​​ 01 ĐẾN 15 THÁNG 01 NĂM 2026
A63: ល.រ STT | B63: ត្រកូលនិងឈ្មោះ HỌ VÀ TÊN | D63: ឯកតា ĐVT | E63: =E10 -> 1 | F63: =E63+1 -> 2 | G63: =F63+1 -> 3 | H63: =G63+1 -> 4 | I63: =H63+1 -> 5 | J63: =I63+1 -> 6 | K63: =J63+1 -> 7 | L63: =K63+1 -> 8 | M63: =L63+1 -> 9 | ... S63: =R63+1 -> 15 | T63: សរុប TỔNG CỘNG | U63: សម្គាល់ GHI CHÚ | V63: Ký nhận
A64: 1 | B64: សន ម៉ាប់ | C64: SORN MAB | D64: តោន (Tấn) | G64: 4035 | H64: 4035 | I64: 3746 | J64: 3074 | K64: 3586 | L64: 3843 | M64: 3330 | N64: 3074 | O64: 3330 | Q64: 4035 | R64: 3586 | S64: 4355 | T64: =ROUND(U64/1000,3) -> 44.029 | U64: =SUM(E64:S64) -> 44029 | X64: =T179+#REF! -> #REF! | Y64: =ROUND(T64*0.1,2) -> 4.4 | Z64: =Y64+T64 -> 48.429
A65: 2 | B65: ម៉ន ពឿយ | C65: MORN POEUY | D65: តោន (Tấn) | G65: 4035 | H65: 4035 | I65: 3746 | J65: 3074 | K65: 3586 | L65: 3843 | M65: 3330 | N65: 3074 | O65: 3330 | Q65: 4035 | R65: 3586 | S65: 4355 | T65: =ROUND(U65/1000,3) -> 44.029 | U65: =SUM(E65:S65) -> 44029
...

Sheet KLCN t1 dot 1
A1: ក្រុមហ៊ុន កៅស៊ូ មេគង្គ ខូ អិលធីឌី | M1: ព្រះរាជាណាចក្រ កម្ពុជា
A2: CÔNG TY TNHH CAO SU MEKONG | M2: VƯƠNG QUỐC CAMPUCHIA
A3: រោងចក្រកែច្នៃ | M3: ជាតិ សាសនា ព្រះមហាក្សត្រ
A4: XƯỞNG CHẾ BIẾN | M4: Dân tộc - Tôn giáo - Quốc vương
A6: តារាងបរិមាណកម្មករ រោងចក្រកែច្នៃជ័រកៅស៊ូ ខែ ១២ ឆ្នាំ ២០២៥
A7: ចាប់ពីថ្ងៃ ០១-១៥ ខែ ១២ ឆ្នាំ ២០២៥ (វគ្គទី ១)
A8: BẢNG KHỐI LƯỢNG CÔNG NHÂN XƯỞNG CHẾ BIẾN THÁNG 12 NĂM 2025
A9: TỪ NGÀY 01-15 THÁNG 12 NĂM 2025 (ĐỢT 1)
A11: ល.រ STT | B11: ត្រកូលនិងឈ្មោះ Họ và tên | D11: ជ័រកិន (Làm mủ cán vắt) | F11: ជ័រសម្រេច (Làm mủ Thành phẩm) | H11: អ្នកធ្វើការមិនរើសមុខ (Tạp vụ) | J11: សន្ដិសុខការពារ​​​​​ (Bảo vệ) | L11: អ្នកបើកឡាន (Tài xế) | N11: សម្អាត (Vệ sinh) | P11: កម្មករ មេកានិច (Công nhân cơ khí) | R11: កម្លាំងកាត់ស្មៅបាញ់ថ្នាំស្មៅ ; ពេលនាំចេញជ័រទៅលក់/ (Công phát cỏ, xịt cỏ; xuất hàng) | T11: លាងសម្អាតធុងសម្ងួតជ័រ/ vệ sinh thùng sấy mủ | V11: ថ្លឹង កៅស៊ូ ប៉េអឺ ដើម្បីធើ្វសារពើភ័ណ្ឌ ថ្ងៃ ៣១/១២/២០២៥/ Cân thảm kiểm kê VT | X11: មី និងប្រេងឆាឲ្យកម្មករ (Mì, dầu ăn cho CN) | Z11: សរុប Tổng công | AA11: ហត្ថលេខា KÝ TÊN
B12: អក្សរខ្មែរ (Khmer) | C12: អក្សរ ឡាតាំង (La tinh) | D12: បរិមាណ Khối lượng | E12: កម្លាំង Công | F12: បរិមាណ Khối lượng | G12: កម្លាំង Công | H12: បរិមាណ Khối lượng | I12: កម្លាំង Công | J12: បរិមាណ Khối lượng | K12: កម្លាំង Công | L12: បរិមាណ Khối lượng | M12: កម្លាំង Công | N12: បរិមាណ Khối lượng | O12: កម្លាំង Công | P12: បរិមាណ Khối lượng | Q12: កម្លាំង Công | R12: បរិមាណ Khối lượng | S12: កម្លាំង Công | T12: បរិមាណ Khối lượng | U12: កម្លាំង Công | V12: បរិមាណ Khối lượng | W12: កម្លាំង Công | X12: បរិមាណ Khối lượng | Y12: កម្លាំង Công
A13: 1 | B13: រិន ច្រិប | C13: RIN CHRIB | H13: ='BCC D1(26)'!V12 -> 10.5 | I13: =ROUND(H13*1.2486,2) -> 13.11 | Z13: =SUM(G13,E13,S13,Q13,O13,M13,K13,I13,U13,W13,Y13) -> 13.11
A14: =+A13+1 -> 2 | B14: កែវ សម្បត្តិ | C14: KEO SAMBATH | J14: ='BCC D1(26)'!V13+'BCC D1(26)'!V14 -> 16 | K14: =ROUND(J14*1.0563,2) -> 16.9 | R14: ='BCC D1(26)'!V93 -> 3.5 | S14: =ROUND(R14*0.9391,2) -> 3.29 | Z14: =SUM(G14,E14,S14,Q14,O14,M14,K14,I14,U14,W14,Y14) -> 20.19 | AD14: គី គីន
A15: =+A14+1 -> 3 | B15: ផន ឃី | C15: PHORN KHY | N15: ='BCC D1(26)'!V15 -> 12.5 | O15: =ROUND(N15*0.9776,2) -> 12.22 | Z15: =SUM(G15,E15,S15,Q15,O15,M15,K15,I15,U15,W15,Y15) -> 12.22
A16: =+A15+1 -> 4 | B16: ថន ម៉ន | C16: THORN MORN | L16: =SUM('BCC D1(26)'!V16:V17) -> 17.5 | M16: =ROUND(L16*1.4667,2)-0.01 -> 25.66 | Z16: =SUM(G16,E16,S16,Q16,O16,M16,K16,I16,U16,W16,Y16) -> 25.66
A17: =+A16+1 -> 5 | B17: សៃ រិទ្ធី | C17: SAI RITHY | L17: =SUM('BCC D1(26)'!V18:V19) -> 11 | M17: =ROUND(L17*1.4779,2) -> 16.26 | Z17: =SUM(G17,E17,S17,Q17,O17,M17,K17,I17,U17,W17,Y17) -> 16.26
A18: =+A17+1 -> 6 | B18: សាត រិទ្ធិសាក់ | C18: SAT RITHYSAK | P18: =SUM('BCC D1(26)'!V20:V21) -> 17.5 | Q18: =ROUND(P18*1.4608,2) -> 25.56 | Z18: =SUM(G18,E18,S18,Q18,O18,M18,K18,I18,U18,W18,Y18) -> 25.56
A19: =+A18+1 -> 7 | B19: ហឿង សុជឿន | C19: HOEUNG SOCHOEUN | D19: =ROUND(VLOOKUP(B19,'BPHAN CHIA '!$B$100:$T$110,19,0)*1.1,2) -> 9.82 | E19: =ROUND(0.7199*D19,2) -> 7.07 | F19: =ROUND(1.15*VLOOKUP(B19,'BPHAN CHIA '!$B$179:$T$200,19,0),2) -> 13.75 | G19: =ROUND(F19*1.0956,2) -> 15.06 | U19: =ROUND(T19*0.9391,2) -> 0 | Z19: =SUM(G19,E19,S19,Q19,O19,M19,K19,I19,U19,W19,Y19) -> 22.13
A20: =+A19+1 -> 8 | B20: ថន សំណាង | C20: THAN SAMNANG | D20: =ROUND(VLOOKUP(B20,'BPHAN CHIA '!$B$100:$T$110,19,0),2) -> 12.55 | E20: =ROUND(0.7199*D20,2) -> 9.03 | F20: =ROUND(VLOOKUP(B20,'BPHAN CHIA '!$B$179:$T$200,19,0),2) -> 10.35 | G20: =ROUND(F20*1.0956,2) -> 11.34 | Z20: =SUM(G20,E20,S20,Q20,O20,M20,K20,I20,U20,W20,Y20) -> 20.37
A21: =+A20+1 -> 9 | B21: ថូរ សុភ័ណ្ឌ | C21: THO SOPHORN | F21: =ROUND(VLOOKUP(B21,'BPHAN CHIA '!$B$179:$T$200,19,0),2) -> 11.95 | G21: =ROUND(F21*1.0956,2) -> 13.09 | Z21: =SUM(G21,E21,S21,Q21,O21,M21,K21,I21,U21,W21,Y21) -> 13.09
A22: =+A21+1 -> 10 | B22: ធៀម សំនាង | C22: THEAM SAMNEANG | F22: =ROUND(VLOOKUP(B22,'BPHAN CHIA '!$B$179:$T$200,19,0),2) -> 9.96 | G22: =ROUND(F22*1.0956,2) -> 10.91 | Z22: =SUM(G22,E22,S22,Q22,O22,M22,K22,I22,U22,W22,Y22) -> 10.91
A23: =+A22+1 -> 11 | B23: អែល សាន់ | C23: EL SANN | D23: =ROUND(VLOOKUP(B23,'BPHAN CHIA '!$B$100:$T$110,19,0),2) -> 12.55 | E23: =ROUND(0.7199*D23,2) -> 9.03 | F23: =ROUND(VLOOKUP(B23,'BPHAN CHIA '!$B$179:$T$200,19,0),2) -> 11.95 | G23: =ROUND(F23*1.0956,2) -> 13.09 | Z23: =SUM(G23,E23,S23,Q23,O23,M23,K23,I23,U23,W23,Y23) -> 22.12
A24: =+A23+1 -> 12 | B24: អ៊ាវ ខាត់ | C24: EAV KHATH | D24: =ROUND(VLOOKUP(B24,'BPHAN CHIA '!$B$100:$T$110,19,0),2) -> 3.62 | E24: =ROUND(0.7199*D24,2) -> 2.61 | F24: =ROUND(VLOOKUP(B24,'BPHAN CHIA '!$B$179:$T$200,19,0),2) -> 11.95 | G24: =ROUND(F24*1.0956,2) -> 13.09 | Z24: =SUM(G24,E24,S24,Q24,O24,M24,K24,I24,U24,W24,Y24) -> 15.7
A25: =+A24+1 -> 13 | B25: ភី ផូ | C25: PHI PHO | F25: =ROUND(VLOOKUP(B25,'BPHAN CHIA '!$B$179:$T$200,19,0),2) -> 11.95 | G25: =ROUND(F25*1.0956,2) -> 13.09 | Z25: =SUM(G25,E25,S25,Q25,O25,M25,K25,I25,U25,W25,Y25) -> 13.09
A26: =+A25+1 -> 14 | B26: វុន វណ្ណនី | C26: VON VANNY | F26: =ROUND(VLOOKUP(B26,'BPHAN CHIA '!$B$179:$T$200,19,0),2) -> 8.99 | G26: =ROUND(F26*1.0956,2) -> 9.85 | Z26: =SUM(G26,E26,S26,Q26,O26,M26,K26,I26,U26,W26,Y26) -> 9.85
A27: =+A26+1 -> 15 | B27: លឿន ឆាលី | C27: LOEUN CHALY | F27: =ROUND(VLOOKUP(B27,'BPHAN CHIA '!$B$179:$T$200,19,0),2) -> 10.35 | G27: =ROUND(F27*1.0956,2) -> 11.34 | Z27: =SUM(G27,E27,S27,Q27,O27,M27,K27,I27,U27,W27,Y27) -> 11.34
A28: =+A27+1 -> 16 | B28: ហឿន សាវុធ | C28: HOEURN SAVUTH | D28: =ROUND(VLOOKUP(B28,'BPHAN CHIA '!$B$100:$T$110,19,0),2) -> 12.55 | E28: =ROUND(0.7199*D28,2) -> 9.03 | F28: =ROUND(VLOOKUP(B28,'BPHAN CHIA '!$B$179:$T$200,19,0),2) -> 10.58 | G28: =ROUND(F28*1.0956,2) -> 11.59 | Z28: =SUM(G28,E28,S28,Q28,O28,M28,K28,I28,U28,W28,Y28) -> 20.62
A29: =+A28+1 -> 17 | B29: រឿន សារី | C29: ROEUN SARY | F29: =ROUND(VLOOKUP(B29,'BPHAN CHIA '!$B$179:$T$200,19,0),2) -> 6.65 | G29: =ROUND(F29*1.0956,2) -> 7.29 | Z29: =SUM(G29,E29,S29,Q29,O29,M29,K29,I29,U29,W29,Y29) -> 7.29
A30: =+A29+1 -> 18 | B30: ហ៊ុច សំណាង | C30: HOCH SOMNANG | F30: =ROUND(VLOOKUP(B30,'BPHAN CHIA '!$B$179:$T$200,19,0),2) -> 11.95 | G30: =ROUND(F30*1.0956,2) -> 13.09 | Z30: =SUM(G30,E30,S30,Q30,O30,M30,K30,I30,U30,W30,Y30) -> 13.09
A31: =+A30+1 -> 19 | B31: បាន ចន្ថា | C31: BAN CHANTHA | D31: =ROUND(VLOOKUP(B31,'BPHAN CHIA '!$B$100:$T$110,19,0),2) -> 12.55 | E31: =ROUND(0.7199*D31,2) -> 9.03 | F31: =ROUND(VLOOKUP(B31,'BPHAN CHIA '!$B$179:$T$200,19,0),2) -> 10.01 | G31: =ROUND(F31*1.0956,2) -> 10.97 | T31: ='BCC D1(26)'!V95 -> 4 | U31: =ROUND(T31*0.9391,2) -> 3.76 | Z31: =SUM(G31,E31,S31,Q31,O31,M31,K31,I31,U31,W31,Y31) -> 23.76
A32: =+A31+1 -> 20 | B32: សាន់ យូស័រ | C32: SAN YUSOR | D32: =ROUND(VLOOKUP(B32,'BPHAN CHIA '!$B$100:$T$110,19,0),2) -> 12.55 | E32: =ROUND(0.7199*D32,2) -> 9.03 | F32: =ROUND(VLOOKUP(B32,'BPHAN CHIA '!$B$179:$T$200,19,0),2) -> 8.39 | G32: =ROUND(F32*1.0956,2) -> 9.19 | Z32: =SUM(G32,E32,S32,Q32,O32,M32,K32,I32,U32,W32,Y32) -> 18.22
A33: =+A32+1 -> 21 | B33: វុន វណ្ណា | C33: VUN VANNA | D33: =ROUND(VLOOKUP(B33,'BPHAN CHIA '!$B$100:$T$110,19,0),2) -> 6.33 | E33: =ROUND(0.7199*D33,2) -> 4.56 | F33: =ROUND(VLOOKUP(B33,'BPHAN CHIA '!$B$179:$T$200,19,0),2) -> 9.96 | G33: =ROUND(F33*1.0956,2) -> 10.91 | U33: =ROUND(T33*0.9391,2) -> 0 | Z33: =SUM(G33,E33,S33,Q33,O33,M33,K33,I33,U33,W33,Y33) -> 15.47
A34: =+A33+1 -> 22 | B34: ជឿន នីន | C34: CHOEUN NIN | F34: =ROUND(VLOOKUP(B34,'BPHAN CHIA '!$B$179:$T$200,19,0),2) -> 11.95 | G34: =ROUND(F34*1.0956,2) -> 13.09 | Z34: =SUM(G34,E34,S34,Q34,O34,M34,K34,I34,U34,W34,Y34) -> 13.09
A35: =+A34+1 -> 23 | B35: ហឿង ហេង | C35: HOEUNG HENG | F35: =ROUND(VLOOKUP(B35,'BPHAN CHIA '!$B$179:$T$200,19,0),2) -> 11.95 | G35: =ROUND(F35*1.0956,2) -> 13.09 | Z35: =SUM(G35,E35,S35,Q35,O35,M35,K35,I35,U35,W35,Y35) -> 13.09
A36: =+A35+1 -> 24 | B36: គង់ ចាន់ទ្រឿន | C36: KONG CHANTROEUN | F36: =ROUND(VLOOKUP(B36,'BPHAN CHIA '!$B$179:$T$200,19,0),2) -> 11.95 | G36: =ROUND(F36*1.0956,2) -> 13.09 | Z36: =SUM(G36,E36,S36,Q36,O36,M36,K36,I36,U36,W36,Y36) -> 13.09
A37: =+A36+1 -> 25 | B37: ទៀង ឡៃស៊ីម | C37: TIENG LAISIM | F37: =ROUND(VLOOKUP(B37,'BPHAN CHIA '!$B$179:$T$200,19,0),2) -> 11.95 | G37: =ROUND(F37*1.0956,2) -> 13.09 | Z37: =SUM(G37,E37,S37,Q37,O37,M37,K37,I37,U37,W37,Y37) -> 13.09
A38: =+A37+1 -> 26 | B38: ម៉ុន ម៉ោល | C38: MON MORL | D38: =ROUND(VLOOKUP(B38,'BPHAN CHIA '!$B$100:$T$110,19,0),2) -> 12.54 | E38: =ROUND(0.7199*D38,2) -> 9.03 | F38: =ROUND(VLOOKUP(B38,'BPHAN CHIA '!$B$179:$T$200,19,0),2) -> 5.22 | G38: =ROUND(F38*1.0956,2) -> 5.72 | T38: ='BCC D1(26)'!V96 -> 4 | U38: =ROUND(T38*0.9391,2) -> 3.76 | Z38: =SUM(G38,E38,S38,Q38,O38,M38,K38,I38,U38,W38,Y38) -> 18.51
A39: =+A38+1 -> 27 | B39: កែវ ប្រុសសុទ្ធ | C39: KEO BROSSOTH | D39: =ROUND(VLOOKUP(B39,'BPHAN CHIA '!$B$100:$T$110,19,0),2) -> 1.63 | E39: =ROUND(0.7199*D39,2) -> 1.17 | F39: =ROUND(VLOOKUP(B39,'BPHAN CHIA '!$B$179:$T$200,19,0),2) -> 8.53 | G39: =ROUND(F39*1.0956,2) -> 9.35 | Z39: =SUM(G39,E39,S39,Q39,O39,M39,K39,I39,U39,W39,Y39) -> 10.52
A40: =+A39+1 -> 28 | B40: ម៉ុក សុធា | C40: MOK SOTHEA | D40: =ROUND(VLOOKUP(B40,'BPHAN CHIA '!$B$100:$T$110,19,0),2) -> 5.67 | E40: =ROUND(0.7199*D40,2) -> 4.08 | F40: =ROUND(VLOOKUP(B40,'BPHAN CHIA '!$B$179:$T$200,19,0),2) -> 11.95 | G40: =ROUND(F40*1.0956,2) -> 13.09 | Z40: =SUM(G40,E40,S40,Q40,O40,M40,K40,I40,U40,W40,Y40) -> 17.17
A41: =+A40+1 -> 29 | B41: ជឿន ថា | C41: CHOEUN THA | D41: =ROUND(VLOOKUP(B41,'BPHAN CHIA '!$B$11:$T$19,19,0)*1.1,2) -> 52.34 | E41: =ROUND(0.7199*D41,2) -> 37.68 | Z41: =SUM(G41,E41,S41,Q41,O41,M41,K41,I41,U41,W41,Y41) -> 37.68
A42: =+A41+1 -> 30 | B42: ហ៊ុន ម៉ៅ | C42: HUN MAO | D42: =ROUND(VLOOKUP(B42,'BPHAN CHIA '!$B$11:$T$19,19,0),2) -> 47.58 | E42: =ROUND(0.7199*D42,2) -> 34.25 | Z42: =SUM(G42,E42,S42,Q42,O42,M42,K42,I42,U42,W42,Y42) -> 34.25
...

Sheet TTL dot​2 (31947)
A1: ក្រុមហ៊ុន កៅស៊ូ មេគង្គ ខូ អិលធីឌី | P1: ព្រះរាជាណាចក្រ កម្ពុជា
A2: CÔNG TY TNHH CAO SU MEKONG | P2: VƯƠNG QUỐC CAMPUCHIA
A3: រោងចក្រកែច្នៃ | P3: ជាតិ សាសនា ព្រះមហាក្សត្រ
A4: XƯỞNG CHẾ BIẾN | P4: Dân tộc - Tôn giáo - Quốc vương
A5: តារាងទូទាត់បៀវត្សកម្មកររោងចក្រកែច្នៃជ័រកៅស៊ូ ខែ ០១ ឆ្នាំ ២០២៦
A6: ចាប់ពីថ្ងៃ ០១-១៥ ខែ ០១ ឆ្នាំ ២០២៦ (វគ្គទី ១)
A7: BẢNG THANH TOÁN LƯƠNG CÔNG NHÂN XƯỞNG CHẾ BIẾN THÁNG 01 NĂM 2026​​ (ĐỢT 1)
A8: TỪ NGÀY 01-15 THÁNG​ 01 NĂM 2026
R9: ឯកតា/ | S9: ĐVT: Riel
A10: ល.រ STT | B10: ត្រកូល និង ឈ្មោះ / Họ và tên | D10: លេខអត្តសញ្ញាណ​បណ្ណ Số CMND | E10: បទដ្ឋាន Định mức 31.947 Riel/ công | F10: បៀវត្សថ្ងៃធម្មតា វគ្គទី១ Lương ngày | H10: បៀវត្សថ្ងៃធម្មតា វគ្គទី​​​២ Lương ngày | J10: បៀវត្សដាច់ឆ្នាំ (Lương thâm niên) | K10: សរុប Tổng lương | L10: បំណុល/ Công nợ | Q10: សរុបបំណុល Tổng nợ | R10: ត្រូវទទួល Thực nhận | S10: ហត្ថលេខាទទួល KÝ NHẬN | U10: Tạm ứng lương | V10: Thực lãnh
B11: អក្សរខ្មែរ (Khmer) | C11: អក្សរ ឡាតាំង (La tinh) | F11: កម្លាំង Công | G11: ជាប្រាក់ Thành Tiền | H11: កម្លាំង Công | I11: ជាប្រាក់ Thành Tiền | L11: បុរេប្រទាន បៀវត្ស T/ứ lương | M11: ភាគទានប្រាក់សោធនវគ្គទី១​​​/ BHXH đợt 1 | N11: ភាគទានប្រាក់សោធន​​​/ BHXH | O11: ភាគទានប្រាក់សោធនវគ្គទី២​​​/ BHXH đợt 2 | P11: ពន្ធលើប្រាក់បៀវត្ស/ TNCN | W11: Gia cảnh
A12: A | B12: B | C12: C | D12: D | E12: 1 | F12: 2 | G12: 3 | H12: 4 | I12: 5 | J12: 6 | K12: 6 | L12: 7 | M12: 8 | N12: 9 | O12: 10 | P12: 11 | Q12: 12 | R12: 13 | S12: 14
A13: 1 | B13: រិន ច្រិប | C13: RIN CHRIB | D13: 150952531 | E13: 31947 | F13: =VLOOKUP(B13,'KLCN t1 dot 1'!$B$13:$Z$83,25,0) -> 13.11 | G13: =ROUND(F13*E13,0) -> 418825 | K13: =I13+J13+G13 -> 418825 | M13: =IF(G13<=400000,400000*2%,IF(G13<=1200000,ROUND(G13*2%,0),ROUND(1200000*2%,0))) -> 8377 | P13: =ROUND(IF((K13-J13-N13)<=1500000,0,IF(AND(((K13-J13-N13))>1500000,((K13-J13-N13))<=2000000),((K13-J13-N13))*5%-75000,IF(AND(((K13-J13-N13))>2000000,((K13-J13-N13))<=8500000),((K13-J13-N13))*10%-175000))),0) -> 0 | Q13: =L13+M13+O13+P13 -> 8377 | R13: =ROUND(K13-Q13,0) -> 410448 | U13: 50000 | V13: =+R13-U13 -> 360448 | W13: =#REF! -> #REF! | X13: 200000
A14: =+A13+1 -> 2 | B14: កែវ សម្បត្តិ | C14: KEO SAMBATH | D14: 110471355 | E14: 31947 | F14: =VLOOKUP(B14,'KLCN t1 dot 1'!$B$13:$Z$83,25,0) -> 20.19 | G14: =ROUND(F14*E14,0) -> 645010 | K14: =I14+J14+G14 -> 645010 | M14: =IF(G14<=400000,400000*2%,IF(G14<=1200000,ROUND(G14*2%,0),ROUND(1200000*2%,0))) -> 12900 | P14: =ROUND(IF((K14-J14-N14)<=1500000,0,IF(AND(((K14-J14-N14))>1500000,((K14-J14-N14))<=2000000),((K14-J14-N14))*5%-75000,IF(AND(((K14-J14-N14))>2000000,((K14-J14-N14))<=8500000),((K14-J14-N14))*10%-175000))),0) -> 0 | Q14: =L14+M14+O14+P14 -> 12900 | R14: =ROUND(K14-Q14,0) -> 632110 | U14: 200000 | V14: =+R14-U14 -> 432110 | W14: =+#REF! -> #REF! | X14: 300000
A15: =+A14+1 -> 3 | B15: ផន ឃី | C15: PHORN KHY | D15: 150981478 | E15: 31947 | F15: =VLOOKUP(B15,'KLCN t1 dot 1'!$B$13:$Z$83,25,0) -> 12.22 | G15: =ROUND(F15*E15,0) -> 390392 | K15: =I15+J15+G15 -> 390392 | M15: =IF(G15<=400000,400000*2%,IF(G15<=1200000,ROUND(G15*2%,0),ROUND(1200000*2%,0))) -> 8000 | P15: =ROUND(IF((K15-J15-N15)<=1500000,0,IF(AND(((K15-J15-N15))>1500000,((K15-J15-N15))<=2000000),((K15-J15-N15))*5%-75000,IF(AND(((K15-J15-N15))>2000000,((K15-J15-N15))<=8500000),((K15-J15-N15))*10%-175000))),0) -> 0 | Q15: =L15+M15+O15+P15 -> 8000 | R15: =ROUND(K15-Q15,0) -> 382392 | V15: =R15-U15 -> 382392 | W15: =+#REF! -> #REF! | X15: 200000
A16: =+A15+1 -> 4 | B16: ថន ម៉ន | C16: THORN MORN | D16: 150644309 | E16: 31947 | F16: =VLOOKUP(B16,'KLCN t1 dot 1'!$B$13:$Z$83,25,0) -> 25.66 | G16: =ROUND(F16*E16,0) -> 819760 | K16: =I16+J16+G16 -> 819760 | M16: =IF(G16<=400000,400000*2%,IF(G16<=1200000,ROUND(G16*2%,0),ROUND(1200000*2%,0))) -> 16395 | P16: =ROUND(IF((K16-J16-N16)<=1500000,0,IF(AND(((K16-J16-N16))>1500000,((K16-J16-N16))<=2000000),((K16-J16-N16))*5%-75000,IF(AND(((K16-J16-N16))>2000000,((K16-J16-N16))<=8500000),((K16-J16-N16))*10%-175000))),0) -> 0 | Q16: =L16+M16+O16+P16 -> 16395 | R16: =ROUND(K16-Q16,0) -> 803365 | U16: 100000 | V16: =R16-U16 -> 703365 | W16: =+#REF! -> #REF! | X16: 200000
A17: =+A16+1 -> 5 | B17: សៃ រិទ្ធី | C17: SAI RITHY | D17: 220195668 | E17: 31947 | F17: =VLOOKUP(B17,'KLCN t1 dot 1'!$B$13:$Z$83,25,0) -> 16.26 | G17: =ROUND(F17*E17,0) -> 519458 | K17: =I17+J17+G17 -> 519458 | M17: =IF(G17<=400000,400000*2%,IF(G17<=1200000,ROUND(G17*2%,0),ROUND(1200000*2%,0))) -> 10389 | P17: =ROUND(IF((K17-J17-N17)<=1500000,0,IF(AND(((K17-J17-N17))>1500000,((K17-J17-N17))<=2000000),((K17-J17-N17))*5%-75000,IF(AND(((K17-J17-N17))>2000000,((K17-J17-N17))<=8500000),((K17-J17-N17))*10%-175000))),0) -> 0 | Q17: =L17+M17+O17+P17 -> 10389 | R17: =ROUND(K17-Q17,0) -> 509069 | U17: 200000 | V17: =R17-U17 -> 309069 | W17: =+#REF! -> #REF! | X17: 300000
A18: =+A17+1 -> 6 | B18: សាត រិទ្ធិសាក់ | C18: SAT RITHYSAK | D18: 220208913 | E18: 31947 | F18: =VLOOKUP(B18,'KLCN t1 dot 1'!$B$13:$Z$83,25,0) -> 25.56 | G18: =ROUND(F18*E18,0) -> 816565 | K18: =I18+J18+G18 -> 816565 | M18: =IF(G18<=400000,400000*2%,IF(G18<=1200000,ROUND(G18*2%,0),ROUND(1200000*2%,0))) -> 16331 | P18: =ROUND(IF((K18-J18-N18)<=1500000,0,IF(AND(((K18-J18-N18))>1500000,((K18-J18-N18))<=2000000),((K18-J18-N18))*5%-75000,IF(AND(((K18-J18-N18))>2000000,((K18-J18-N18))<=8500000),((K18-J18-N18))*10%-175000))),0) -> 0 | Q18: =L18+M18+O18+P18 -> 16331 | R18: =ROUND(K18-Q18,0) -> 800234 | V18: =SUM(V32:V66) -> 2266470 | X18: =SUM(X32:X66) -> 600000
A19: =+A18+1 -> 7 | B19: ហឿង សុជឿន | C19: HOEUNG SOCHOEUN | D19: 150911076 | E19: 31947 | F19: =VLOOKUP(B19,'KLCN t1 dot 1'!$B$13:$Z$83,25,0) -> 22.13 | G19: =ROUND(F19*E19,0) -> 706987 | K19: =I19+J19+G19 -> 706987 | M19: =IF(G19<=400000,400000*2%,IF(G19<=1200000,ROUND(G19*2%,0),ROUND(1200000*2%,0))) -> 14140 | P19: =ROUND(IF((K19-J19-N19)<=1500000,0,IF(AND(((K19-J19-N19))>1500000,((K19-J19-N19))<=2000000),((K19-J19-N19))*5%-75000,IF(AND(((K19-J19-N19))>2000000,((K19-J19-N19))<=8500000),((K19-J19-N19))*10%-175000))),0) -> 0 | Q19: =L19+M19+O19+P19 -> 14140 | R19: =ROUND(K19-Q19,0) -> 692847
A20: =+A19+1 -> 8 | B20: ថន សំណាង | C20: THAN SAMNANG | D20: 220102094 | E20: 31947 | F20: =VLOOKUP(B20,'KLCN t1 dot 1'!$B$13:$Z$83,25,0) -> 20.37 | G20: =ROUND(F20*E20,0) -> 650760 | K20: =I20+J20+G20 -> 650760 | M20: =IF(G20<=400000,400000*2%,IF(G20<=1200000,ROUND(G20*2%,0),ROUND(1200000*2%,0))) -> 13015 | P20: =ROUND(IF((K20-J20-N20)<=1500000,0,IF(AND(((K20-J20-N20))>1500000,((K20-J20-N20))<=2000000),((K20-J20-N20))*5%-75000,IF(AND(((K20-J20-N20))>2000000,((K20-J20-N20))<=8500000),((K20-J20-N20))*10%-175000))),0) -> 0 | Q20: =L20+M20+O20+P20 -> 13015 | R20: =ROUND(K20-Q20,0) -> 637745
A21: =+A20+1 -> 9 | B21: ថូរ សុភ័ណ្ឌ | C21: THO SOPHORN | D21: 210050404 | E21: 31947 | F21: =VLOOKUP(B21,'KLCN t1 dot 1'!$B$13:$Z$83,25,0) -> 13.09 | G21: =ROUND(F21*E21,0) -> 418186 | K21: =I21+J21+G21 -> 418186 | M21: =IF(G21<=400000,400000*2%,IF(G21<=1200000,ROUND(G21*2%,0),ROUND(1200000*2%,0))) -> 8364 | P21: =ROUND(IF((K21-J21-N21)<=1500000,0,IF(AND(((K21-J21-N21))>1500000,((K21-J21-N21))<=2000000),((K21-J21-N21))*5%-75000,IF(AND(((K21-J21-N21))>2000000,((K21-J21-N21))<=8500000),((K21-J21-N21))*10%-175000))),0) -> 0 | Q21: =L21+M21+O21+P21 -> 8364 | R21: =ROUND(K21-Q21,0) -> 409822
A22: =+A21+1 -> 10 | B22: ធៀម សំនាង | C22: THEAM SAMNEANG | D22: 151006137 | E22: 31947 | F22: =VLOOKUP(B22,'KLCN t1 dot 1'!$B$13:$Z$83,25,0) -> 10.91 | G22: =ROUND(F22*E22,0) -> 348542 | K22: =I22+J22+G22 -> 348542 | M22: =IF(G22<=400000,400000*2%,IF(G22<=1200000,ROUND(G22*2%,0),ROUND(1200000*2%,0))) -> 8000 | P22: =ROUND(IF((K22-J22-N22)<=1500000,0,IF(AND(((K22-J22-N22))>1500000,((K22-J22-N22))<=2000000),((K22-J22-N22))*5%-75000,IF(AND(((K22-J22-N22))>2000000,((K22-J22-N22))<=8500000),((K22-J22-N22))*10%-175000))),0) -> 0 | Q22: =L22+M22+O22+P22 -> 8000 | R22: =ROUND(K22-Q22,0) -> 340542
A23: =+A22+1 -> 11 | B23: អែល សាន់ | C23: EL SANN | D23: 040322767 | E23: 31947 | F23: =VLOOKUP(B23,'KLCN t1 dot 1'!$B$13:$Z$83,25,0) -> 22.12 | G23: =ROUND(F23*E23,0) -> 706668 | K23: =I23+J23+G23 -> 706668 | M23: =IF(G23<=400000,400000*2%,IF(G23<=1200000,ROUND(G23*2%,0),ROUND(1200000*2%,0))) -> 14133 | P23: =ROUND(IF((K23-J23-N23)<=1500000,0,IF(AND(((K23-J23-N23))>1500000,((K23-J23-N23))<=2000000),((K23-J23-N23))*5%-75000,IF(AND(((K23-J23-N23))>2000000,((K23-J23-N23))<=8500000),((K23-J23-N23))*10%-175000))),0) -> 0 | Q23: =L23+M23+O23+P23 -> 14133 | R23: =ROUND(K23-Q23,0) -> 692535
A24: =+A23+1 -> 12 | B24: អ៊ាវ ខាត់ | C24: EAV KHATH | D24: 150469697 | E24: 31947 | F24: =VLOOKUP(B24,'KLCN t1 dot 1'!$B$13:$Z$83,25,0) -> 15.7 | G24: =ROUND(F24*E24,0) -> 501568 | K24: =I24+J24+G24 -> 501568 | M24: =IF(G24<=400000,400000*2%,IF(G24<=1200000,ROUND(G24*2%,0),ROUND(1200000*2%,0))) -> 10031 | P24: =ROUND(IF((K24-J24-N24)<=1500000,0,IF(AND(((K24-J24-N24))>1500000,((K24-J24-N24))<=2000000),((K24-J24-N24))*5%-75000,IF(AND(((K24-J24-N24))>2000000,((K24-J24-N24))<=8500000),((K24-J24-N24))*10%-175000))),0) -> 0 | Q24: =L24+M24+O24+P24 -> 10031 | R24: =ROUND(K24-Q24,0) -> 491537
A25: =+A24+1 -> 13 | B25: ភី ផូ | C25: PHI PHO | D25: 150927708 | E25: 31947 | F25: =VLOOKUP(B25,'KLCN t1 dot 1'!$B$13:$Z$83,25,0) -> 13.09 | G25: =ROUND(F25*E25,0) -> 418186 | K25: =I25+J25+G25 -> 418186 | M25: =IF(G25<=400000,400000*2%,IF(G25<=1200000,ROUND(G25*2%,0),ROUND(1200000*2%,0))) -> 8364 | P25: =ROUND(IF((K25-J25-N25)<=1500000,0,IF(AND(((K25-J25-N25))>1500000,((K25-J25-N25))<=2000000),((K25-J25-N25))*5%-75000,IF(AND(((K25-J25-N25))>2000000,((K25-J25-N25))<=8500000),((K25-J25-N25))*10%-175000))),0) -> 0 | Q25: =L25+M25+O25+P25 -> 8364 | R25: =ROUND(K25-Q25,0) -> 409822
A26: =+A25+1 -> 14 | B26: វុន វណ្ណនី | C26: VON VANNY | D26: 151034061 | E26: 31947 | F26: =VLOOKUP(B26,'KLCN t1 dot 1'!$B$13:$Z$83,25,0) -> 9.85 | G26: =ROUND(F26*E26,0) -> 314678 | K26: =I26+J26+G26 -> 314678 | M26: =IF(G26<=400000,400000*2%,IF(G26<=1200000,ROUND(G26*2%,0),ROUND(1200000*2%,0))) -> 8000 | P26: =ROUND(IF((K26-J26-N26)<=1500000,0,IF(AND(((K26-J26-N26))>1500000,((K26-J26-N26))<=2000000),((K26-J26-N26))*5%-75000,IF(AND(((K26-J26-N26))>2000000,((K26-J26-N26))<=8500000),((K26-J26-N26))*10%-175000))),0) -> 0 | Q26: =L26+M26+O26+P26 -> 8000 | R26: =ROUND(K26-Q26,0) -> 306678
A27: =+A26+1 -> 15 | B27: លឿន ឆាលី | C27: LOEUN CHALY | D27: 150911069 | E27: 31947 | F27: =VLOOKUP(B27,'KLCN t1 dot 1'!$B$13:$Z$83,25,0) -> 11.34 | G27: =ROUND(F27*E27,0) -> 362279 | K27: =I27+J27+G27 -> 362279 | M27: =IF(G27<=400000,400000*2%,IF(G27<=1200000,ROUND(G27*2%,0),ROUND(1200000*2%,0))) -> 8000 | P27: =ROUND(IF((K27-J27-N27)<=1500000,0,IF(AND(((K27-J27-N27))>1500000,((K27-J27-N27))<=2000000),((K27-J27-N27))*5%-75000,IF(AND(((K27-J27-N27))>2000000,((K27-J27-N27))<=8500000),((K27-J27-N27))*10%-175000))),0) -> 0 | Q27: =L27+M27+O27+P27 -> 8000 | R27: =ROUND(K27-Q27,0) -> 354279
A28: =+A27+1 -> 16 | B28: ហឿន សាវុធ | C28: HOEURN SAVUTH | D28: 020520213 | E28: 31947 | F28: =VLOOKUP(B28,'KLCN t1 dot 1'!$B$13:$Z$83,25,0) -> 20.62 | G28: =ROUND(F28*E28,0) -> 658747 | K28: =I28+J28+G28 -> 658747 | M28: =IF(G28<=400000,400000*2%,IF(G28<=1200000,ROUND(G28*2%,0),ROUND(1200000*2%,0))) -> 13175 | P28: =ROUND(IF((K28-J28-N28)<=1500000,0,IF(AND(((K28-J28-N28))>1500000,((K28-J28-N28))<=2000000),((K28-J28-N28))*5%-75000,IF(AND(((K28-J28-N28))>2000000,((K28-J28-N28))<=8500000),((K28-J28-N28))*10%-175000))),0) -> 0 | Q28: =L28+M28+O28+P28 -> 13175 | R28: =ROUND(K28-Q28,0) -> 645572
A29: =+A28+1 -> 17 | B29: រឿន សារី | C29: ROEUN SARY | D29: 220175393 | E29: 31947 | F29: =VLOOKUP(B29,'KLCN t1 dot 1'!$B$13:$Z$83,25,0) -> 7.29 | G29: =ROUND(F29*E29,0) -> 232894 | K29: =I29+J29+G29 -> 232894 | M29: =IF(G29<=400000,400000*2%,IF(G29<=1200000,ROUND(G29*2%,0),ROUND(1200000*2%,0))) -> 8000 | P29: =ROUND(IF((K29-J29-N29)<=1500000,0,IF(AND(((K29-J29-N29))>1500000,((K29-J29-N29))<=2000000),((K29-J29-N29))*5%-75000,IF(AND(((K29-J29-N29))>2000000,((K29-J29-N29))<=8500000),((K29-J29-N29))*10%-175000))),0) -> 0 | Q29: =L29+M29+O29+P29 -> 8000 | R29: =ROUND(K29-Q29,0) -> 224894
A30: =+A29+1 -> 18 | B30: ហ៊ុច សំណាង | C30: HOCH SOMNANG | D30: 150936257 | E30: 31947 | F30: =VLOOKUP(B30,'KLCN t1 dot 1'!$B$13:$Z$83,25,0) -> 13.09 | G30: =ROUND(F30*E30,0) -> 418186 | K30: =I30+J30+G30 -> 418186 | M30: =IF(G30<=400000,400000*2%,IF(G30<=1200000,ROUND(G30*2%,0),ROUND(1200000*2%,0))) -> 8364 | P30: =ROUND(IF((K30-J30-N30)<=1500000,0,IF(AND(((K30-J30-N30))>1500000,((K30-J30-N30))<=2000000),((K30-J30-N30))*5%-75000,IF(AND(((K30-J30-N30))>2000000,((K30-J30-N30))<=8500000),((K30-J30-N30))*10%-175000))),0) -> 0 | Q30: =L30+M30+O30+P30 -> 8364 | R30: =ROUND(K30-Q30,0) -> 409822
A31: =+A30+1 -> 19 | B31: បាន ចន្ថា | C31: BAN CHANTHA | D31: 220137301 | E31: 31947 | F31: =VLOOKUP(B31,'KLCN t1 dot 1'!$B$13:$Z$83,25,0) -> 23.76 | G31: =ROUND(F31*E31,0) -> 759061 | K31: =I31+J31+G31 -> 759061 | M31: =IF(G31<=400000,400000*2%,IF(G31<=1200000,ROUND(G31*2%,0),ROUND(1200000*2%,0))) -> 15181 | P31: =ROUND(IF((K31-J31-N31)<=1500000,0,IF(AND(((K31-J31-N31))>1500000,((K31-J31-N31))<=2000000),((K31-J31-N31))*5%-75000,IF(AND(((K31-J31-N31))>2000000,((K31-J31-N31))<=8500000),((K31-J31-N31))*10%-175000))),0) -> 0 | Q31: =L31+M31+O31+P31 -> 15181 | R31: =ROUND(K31-Q31,0) -> 743880
A32: =+A31+1 -> 20 | B32: សាន់ យូស័រ | C32: SAN YUSOR | D32: 150940509 | E32: 31947 | F32: =VLOOKUP(B32,'KLCN t1 dot 1'!$B$13:$Z$83,25,0) -> 18.22 | G32: =ROUND(F32*E32,0) -> 582074 | K32: =I32+J32+G32 -> 582074 | M32: =IF(G32<=400000,400000*2%,IF(G32<=1200000,ROUND(G32*2%,0),ROUND(1200000*2%,0))) -> 11641 | P32: =ROUND(IF((K32-J32-N32)<=1500000,0,IF(AND(((K32-J32-N32))>1500000,((K32-J32-N32))<=2000000),((K32-J32-N32))*5%-75000,IF(AND(((K32-J32-N32))>2000000,((K32-J32-N32))<=8500000),((K32-J32-N32))*10%-175000))),0) -> 0 | Q32: =L32+M32+O32+P32 -> 11641 | R32: =ROUND(K32-Q32,0) -> 570433 | U32: 200000 | V32: =R32-U32 -> 370433 | W32: =#REF! -> #REF! | X32: 250000
A33: =+A32+1 -> 21 | B33: វុន វណ្ណា | C33: VUN VANNA | D33: 150657948 | E33: 31947 | F33: =VLOOKUP(B33,'KLCN t1 dot 1'!$B$13:$Z$83,25,0) -> 15.47 | G33: =ROUND(F33*E33,0) -> 494220 | K33: =I33+J33+G33 -> 494220 | M33: =IF(G33<=400000,400000*2%,IF(G33<=1200000,ROUND(G33*2%,0),ROUND(1200000*2%,0))) -> 9884 | P33: =ROUND(IF((K33-J33-N33)<=1500000,0,IF(AND(((K33-J33-N33))>1500000,((K33-J33-N33))<=2000000),((K33-J33-N33))*5%-75000,IF(AND(((K33-J33-N33))>2000000,((K33-J33-N33))<=8500000),((K33-J33-N33))*10%-175000))),0) -> 0 | Q33: =L33+M33+O33+P33 -> 9884 | R33: =ROUND(K33-Q33,0) -> 484336
A34: =+A33+1 -> 22 | B34: ជឿន នីន | C34: CHOEUN NIN | D34: 150952503 | E34: 31947 | F34: =VLOOKUP(B34,'KLCN t1 dot 1'!$B$13:$Z$83,25,0) -> 13.09 | G34: =ROUND(F34*E34,0) -> 418186 | K34: =I34+J34+G34 -> 418186 | M34: =IF(G34<=400000,400000*2%,IF(G34<=1200000,ROUND(G34*2%,0),ROUND(1200000*2%,0))) -> 8364 | P34: =ROUND(IF((K34-J34-N34)<=1500000,0,IF(AND(((K34-J34-N34))>1500000,((K34-J34-N34))<=2000000),((K34-J34-N34))*5%-75000,IF(AND(((K34-J34-N34))>2000000,((K34-J34-N34))<=8500000),((K34-J34-N34))*10%-175000))),0) -> 0 | Q34: =L34+M34+O34+P34 -> 8364 | R34: =ROUND(K34-Q34,0) -> 409822
A35: =+A34+1 -> 23 | B35: ហឿង ហេង | C35: HOEUNG HENG | D35: 220248893 | E35: 31947 | F35: =VLOOKUP(B35,'KLCN t1 dot 1'!$B$13:$Z$83,25,0) -> 13.09 | G35: =ROUND(F35*E35,0) -> 418186 | K35: =I35+J35+G35 -> 418186 | M35: =IF(G35<=400000,400000*2%,IF(G35<=1200000,ROUND(G35*2%,0),ROUND(1200000*2%,0))) -> 8364 | P35: =ROUND(IF((K35-J35-N35)<=1500000,0,IF(AND(((K35-J35-N35))>1500000,((K35-J35-N35))<=2000000),((K35-J35-N35))*5%-75000,IF(AND(((K35-J35-N35))>2000000,((K35-J35-N35))<=8500000),((K35-J35-N35))*10%-175000))),0) -> 0 | Q35: =L35+M35+O35+P35 -> 8364 | R35: =ROUND(K35-Q35,0) -> 409822
A36: =+A35+1 -> 24 | B36: គង់ ចាន់ទ្រឿន | C36: KONG CHANTROEUN | D36: 220105697 | E36: 31947 | F36: =VLOOKUP(B36,'KLCN t1 dot 1'!$B$13:$Z$83,25,0) -> 13.09 | G36: =ROUND(F36*E36,0) -> 418186 | K36: =I36+J36+G36 -> 418186 | M36: =IF(G36<=400000,400000*2%,IF(G36<=1200000,ROUND(G36*2%,0),ROUND(1200000*2%,0))) -> 8364 | P36: =ROUND(IF((K36-J36-N36)<=1500000,0,IF(AND(((K36-J36-N36))>1500000,((K36-J36-N36))<=2000000),((K36-J36-N36))*5%-75000,IF(AND(((K36-J36-N36))>2000000,((K36-J36-N36))<=8500000),((K36-J36-N36))*10%-175000))),0) -> 0 | Q36: =L36+M36+O36+P36 -> 8364 | R36: =ROUND(K36-Q36,0) -> 409822
A37: =+A36+1 -> 25 | B37: ទៀង ឡៃស៊ីម | C37: TIENG LAISIM | D37: 220216744 | E37: 31947 | F37: =VLOOKUP(B37,'KLCN t1 dot 1'!$B$13:$Z$83,25,0) -> 13.09 | G37: =ROUND(F37*E37,0) -> 418186 | K37: =I37+J37+G37 -> 418186 | M37: =IF(G37<=400000,400000*2%,IF(G37<=1200000,ROUND(G37*2%,0),ROUND(1200000*2%,0))) -> 8364 | P37: =ROUND(IF((K37-J37-N37)<=1500000,0,IF(AND(((K37-J37-N37))>1500000,((K37-J37-N37))<=2000000),((K37-J37-N37))*5%-75000,IF(AND(((K37-J37-N37))>2000000,((K37-J37-N37))<=8500000),((K37-J37-N37))*10%-175000))),0) -> 0 | Q37: =L37+M37+O37+P37 -> 8364 | R37: =ROUND(K37-Q37,0) -> 409822
A38: =+A37+1 -> 26 | B38: ម៉ុន ម៉ោល | C38: MON MORL | D38: 220211460 | E38: 31947 | F38: =VLOOKUP(B38,'KLCN t1 dot 1'!$B$13:$Z$83,25,0) -> 18.51 | G38: =ROUND(F38*E38,0) -> 591339 | K38: =I38+J38+G38 -> 591339 | M38: =IF(G38<=400000,400000*2%,IF(G38<=1200000,ROUND(G38*2%,0),ROUND(1200000*2%,0))) -> 11827 | P38: =ROUND(IF((K38-J38-N38)<=1500000,0,IF(AND(((K38-J38-N38))>1500000,((K38-J38-N38))<=2000000),((K38-J38-N38))*5%-75000,IF(AND(((K38-J38-N38))>2000000,((K38-J38-N38))<=8500000),((K38-J38-N38))*10%-175000))),0) -> 0 | Q38: =L38+M38+O38+P38 -> 11827 | R38: =ROUND(K38-Q38,0) -> 579512
A39: =+A38+1 -> 27 | B39: កែវ ប្រុសសុទ្ធ | C39: KEO BROSSOTH | D39: 151056059 | E39: 31947 | F39: =VLOOKUP(B39,'KLCN t1 dot 1'!$B$13:$Z$83,25,0) -> 10.52 | G39: =ROUND(F39*E39,0) -> 336082 | K39: =I39+J39+G39 -> 336082 | M39: =IF(G39<=400000,400000*2%,IF(G39<=1200000,ROUND(G39*2%,0),ROUND(1200000*2%,0))) -> 8000 | P39: =ROUND(IF((K39-J39-N39)<=1500000,0,IF(AND(((K39-J39-N39))>1500000,((K39-J39-N39))<=2000000),((K39-J39-N39))*5%-75000,IF(AND(((K39-J39-N39))>2000000,((K39-J39-N39))<=8500000),((K39-J39-N39))*10%-175000))),0) -> 0 | Q39: =L39+M39+O39+P39 -> 8000 | R39: =ROUND(K39-Q39,0) -> 328082
A40: =+A39+1 -> 28 | B40: ម៉ុក សុធា | C40: MOK SOTHEA | D40: 150306182 (01) | E40: 31947 | F40: =VLOOKUP(B40,'KLCN t1 dot 1'!$B$13:$Z$83,25,0) -> 17.17 | G40: =ROUND(F40*E40,0) -> 548530 | K40: =I40+J40+G40 -> 548530 | M40: =IF(G40<=400000,400000*2%,IF(G40<=1200000,ROUND(G40*2%,0),ROUND(1200000*2%,0))) -> 10971 | P40: =ROUND(IF((K40-J40-N40)<=1500000,0,IF(AND(((K40-J40-N40))>1500000,((K40-J40-N40))<=2000000),((K40-J40-N40))*5%-75000,IF(AND(((K40-J40-N40))>2000000,((K40-J40-N40))<=8500000),((K40-J40-N40))*10%-175000))),0) -> 0 | Q40: =L40+M40+O40+P40 -> 10971 | R40: =ROUND(K40-Q40,0) -> 537559
...
