Workbook

Sheet CDCN- VCKD
A1: ក្រុមហ៊ុន កៅស៊ូ មេគង្គ ខូអិលធីឌី | F1: ព្រះរាជាណាចក្រកម្ពុជា
A2: VRG Caoutchouc Mekong Co., Ltd | F2: VƯƠNG QUỐC CAMPUCHIA
A3: អង្គភាព:ក្រុមផលិត II | F3: ជាតិ សាសនា ព្រះមហាក្សត្រ
A4: Đơn vị: Đội sản xuất 2 | F4: Dân tộc - Tôn giáo - Quốc vương
A6: តារាងតុល្យភាពបំណុលបៀវត្ស​ កម្មកប្រមូលផល
A7: លើកទី ១ ពីថ្ងៃ ១-១៥ ខែ ០១ ឆ្នាំ ២០២៦
A8: BẢNG CÂN ĐỐI CÔNG NỢ LƯƠNG​ CÔNG NHÂN VƯỜN CÂY KINH DOANH
A9: ĐỢT 1TỪ NGÀY 1-15 THÁNG 01 NĂM 2026
B11: I/ សរុបបៀវត្សខែ 01/2026 (Tổng lương tháng 01/2026)៖ | G11: =SUM(G12:G13) -> 309975352 | H11: KHR
B12: 1/ ប្រាក់បៀវត្សទី ១ (Tiền lương đợt 1) ៖ | G12: ='TTTL VCKD chung'!Z580 -> 309975352 | H12: KHR | I12: 21655021
B13: 2/ ប្រាក់បៀវត្សទី ២ (Tiền lương đợt 2) ៖ | G13: 0 | H13: KHR | I13: 23368782
B14: II/ ប្រាក់បានទទួល (Các khoản đã nhận) ៖ | G14: =G15 -> 0 | H14: KHR | I14: 32668679
B15: 1/ទូទាត់ប្រាក់បៀវត្សលើកទី ១ (Thanh toán lương đợt 1) ៖ | G15: 0 | H15: KHR | I15: 26801519
B16: III/ប្រាក់ត្រូវប្រមូល (Các khoản phải thu) ៖ | G16: =G17+G18+G19 -> 0 | H16: KHR | I16: 23984019
B17: 1/ពន្ធលើប្រាក់បៀវត្ស (Thuế TNCN)៖ | G17: 0 | H17: KHR | I17: 26682458
B18: 2/បុរេប្រទានផ្ទាល់ខ្លួន (Tạm ứng cá nhân) ៖ | G18: 0 | H18: KHR | I18: 27120577
B19: 3/ ភាគទានប្រាក់សោធន (BHXH): | G19: 0 | H19: KHR | I19: 27102621
B20: IV/ប្រាក់ត្រូវទទួល (Thực nhận)៖ | G20: =SUM(G21:G21) -> 309975352 | H20: KHR | I20: 25073412
B21: 1/ប្រាក់បៀវត្សត្រូវទទួល (Tiền lương thực nhận) ៖ | G21: =G11-G14-G16 -> 309975352 | H21: KHR | I21: 25770395
I23: =SUM(I12:I21) -> 260227483
A24: (ជាអក្សរ៖បីរយប្រាំបួនលាន ប្រាំបួនរយចែតសិបប្រាំពាន់ បីរយហាសិបពីររៀលគត់។
A25: Bằng chữ: Ba trăm lẻ chín triệu chín trăm bảy mươi lăm ngàn ba trăm năm mươi hai riel chẵn
D27: Prasat Balang, ថ្ងៃ /ngày ខែ​/tháng 01 ឆ្នាំ/năm 2026
A28: ផ្នែក គណនេយ្យ | D28: ក្រុមផលិត ២ | G28: អ្នករៀបចំ
A29: PHÒNG TCKT | D29: ĐỘI SẢN XUẤT II | G29: NGƯỜI LẬP BIỂU
D33: Nguyễn Vũ Minh | G33: Kim Thảo
D35: អនុម័តនាយកក្រុមហ៊ុន
D36: DUYỆT
D37: GIÁM ĐỐC

Sheet KL VCKD chung
A1: ក្រុមហ៊ុន កៅស៊ូ មេគង្គ ខូអិលធីឌី
A2: CÔNG TY TNHH CAO SU VRG MEKONG
A3: អង្គភាព: ក្រុមផលិត II
A4: Đơn vị: Đội sản xuất​ 2
A6: តារាងបរិមាណការងាររបស់កម្មករ ប្រមូលផល លើកទី ១​​ពី​ថ្ងៃទី​ ១- ១៥ ខែ ០១ ឆ្នាំ ២០២៦ | U6: ទទួល
A7: BẢNG KHỐI LƯỢNG CÔNG NHÂN VƯỜN CÂY KINH DOANH ĐỢT 1 TỪ NGÀY 1 -15 THÁNG 01 NĂM 2026
A9: ល.រ (STT) | B9: Phần cạo | C9: ngày tháng năm sinh | D9: អត្ត.ប្រជាពលរដ្ឋ số CMND hoặc passport | E9: ត្រកូលនិងឈ្មោះ (Họ và tên) | F9: នាមត្រកូលនិងឈ្មោះ (Họ và tên) | G9: ជៀរ សាជ័រកៅស៊ូ | Q9: សារុប (Tổng cộng) | R9: ហត្ថលេខា (Ký Nhận) | S9: ការបំពាក់ក្បាង់ទឹកភ្លៀង
G10: Cạo trút và giao nộp mủ
G11: Cạo mủ 16.000riel | I11: Cạo D2 17.000riel | K11: Sản lượng mủ 455 riel/kg | M11: Sản lượng mủ 555 riel/kg | O11: Phụ cấp (xăng)
G12: បរិមាណ | H12: កម្លាំង | I12: បរិមាណ | J12: កម្លាំង | K12: បរិមាណ | L12: កម្លាំង | M12: បរិមាណ | N12: កម្លាំង | O12: បរិមាណ | P12: កម្លាំង | T12: =107/47 -> 2.2765957
G13: Khối lượng | H13: Công | I13: Khối lượng | J13: Công | K13: Khối lượng | L13: Công | M13: Khối lượng | N13: Công | O13: Khối lượng | P13: Công
A15: 1 | B15: 1 | E15: ទៀង ទី | F15: TEANG TY | G15: 10 | H15: 5.008 | M15: 315.04 | N15: 5.476 | O15: 10 | P15: 0.313 | Q15: =H15+L15+N15+P15+J15 -> 10.797 | S15: =G15*16000 -> 160000 | T15: =I15*17000 -> 0 | U15: =K15*455 -> 0 | V15: =M15*555 -> 174847.2 | W15: =O15*1000 -> 10000 | X15: =S15+T15+U15+V15+W15 -> 344847.2 | Y15: 466176.8
A16: 2 | B16: 2 | E16: រ៉ោន បូ រ៉ី | F16: RORN BOREY | G16: 15 | H16: 7.512 | M16: 483.56 | N16: 8.406 | O16: 15 | P16: 0.47 | Q16: =H16+L16+N16+P16+J16 -> 16.388 | S16: =G16*16000 -> 240000 | T16: =I16*17000 -> 0 | U16: =K16*455 -> 0 | V16: =M16*555 -> 268375.8 | W16: =O16*1000 -> 15000 | X16: =S16+T16+U16+V16+W16 -> 523375.8 | Y16: 510038.8
A17: 3 | B17: 3 | E17: រ៉ន សុវឿង | F17: RORN SOVOEUNG | G17: 15 | H17: 7.512 | M17: 514.36 | N17: 8.936 | O17: 15 | P17: 0.47 | Q17: =H17+L17+N17+P17+J17 -> 16.918 | S17: =G17*16000 -> 240000 | T17: =I17*17000 -> 0 | U17: =K17*455 -> 0 | V17: =M17*555 -> 285469.8 | W17: =O17*1000 -> 15000 | X17: =S17+T17+U17+V17+W17 -> 540469.8 | Y17: 487816.6
A18: 4 | B18: 4 | E18: ចាន ជឿន | F18: CHAN CHHOEUN | G18: 12 | H18: 6.01 | M18: 493.68 | N18: 8.576 | O18: 12 | P18: 0.376 | Q18: =H18+L18+N18+P18+J18 -> 14.962 | S18: =G18*16000 -> 192000 | T18: =I18*17000 -> 0 | U18: =K18*455 -> 0 | V18: =M18*555 -> 273992.4 | W18: =O18*1000 -> 12000 | X18: =S18+T18+U18+V18+W18 -> 477992.4 | Y18: 440479.6
A19: 5 | B19: 5 | E19: ជឿន ចាយ | F19: CHOEUN CHAY | G19: 15 | H19: 7.512 | M19: 510.84 | N19: 8.879 | O19: 15 | P19: 0.47 | Q19: =H19+L19+N19+P19+J19 -> 16.861 | S19: =G19*16000 -> 240000 | T19: =I19*17000 -> 0 | U19: =K19*455 -> 0 | V19: =M19*555 -> 283516.2 | W19: =O19*1000 -> 15000 | X19: =S19+T19+U19+V19+W19 -> 538516.2 | Y19: 485374.6
A20: 6 | B20: 6 | E20: ពឿន ប៉ុន | F20: POEUN PON | G20: 13 | H20: 6.51 | M20: 424.16 | N20: 7.369 | O20: 13 | P20: 0.407 | Q20: =H20+L20+N20+P20+J20 -> 14.286 | S20: =G20*16000 -> 208000 | T20: =I20*17000 -> 0 | U20: =K20*455 -> 0 | V20: =M20*555 -> 235408.8 | W20: =O20*1000 -> 13000 | X20: =S20+T20+U20+V20+W20 -> 456408.8 | Y20: 481016.8
A21: 7 | B21: 7 | E21: ឡាញ់ ខ្មៅ | F21: LANH KHMAO | G21: 12 | H21: 6.01 | M21: 416.24 | N21: 7.236 | O21: 12 | P21: 0.376 | Q21: =H21+L21+N21+P21+J21 -> 13.622 | S21: =G21*16000 -> 192000 | T21: =I21*17000 -> 0 | U21: =K21*455 -> 0 | V21: =M21*555 -> 231013.2 | W21: =O21*1000 -> 12000 | X21: =S21+T21+U21+V21+W21 -> 435013.2 | Y21: 476527.2
A22: 8 | B22: 8 | E22: ញិន ស៊ាងឡូត | F22: GNIN SEANG LOTH | G22: 15 | H22: 7.512 | M22: 483.56 | N22: 8.401 | O22: 15 | P22: 0.47 | Q22: =H22+L22+N22+P22+J22 -> 16.383 | S22: =G22*16000 -> 240000 | T22: =I22*17000 -> 0 | U22: =K22*455 -> 0 | V22: =M22*555 -> 268375.8 | W22: =O22*1000 -> 15000 | X22: =S22+T22+U22+V22+W22 -> 523375.8 | Y22: 501247.6
A23: 9 | B23: 9 | E23: ឡាត់ ឡែម | F23: LATH LEM | G23: 14 | H23: 7.011 | M23: 522.28 | N23: 9.073 | O23: 14 | P23: 0.438 | Q23: =H23+L23+N23+P23+J23 -> 16.522 | S23: =G23*16000 -> 224000 | T23: =I23*17000 -> 0 | U23: =K23*455 -> 0 | V23: =M23*555 -> 289865.4 | W23: =O23*1000 -> 14000 | X23: =S23+T23+U23+V23+W23 -> 527865.4 | Y23: 552529.6
A24: 10 | B24: 10 | E24: យឿន យាន់ | F24: YOEUN YOIN | G24: 14 | H24: 7.011 | M24: 465.52 | N24: 8.087 | O24: 14 | P24: 0.438 | Q24: =H24+L24+N24+P24+J24 -> 15.536 | S24: =G24*16000 -> 224000 | T24: =I24*17000 -> 0 | U24: =K24*455 -> 0 | V24: =M24*555 -> 258363.6 | W24: =O24*1000 -> 14000 | X24: =S24+T24+U24+V24+W24 -> 496363.6 | Y24: 520051
A25: 11 | B25: 11 | E25: ញិន​ ឡាយ | F25: NHIN LAY | G25: 14 | H25: 7.011 | M25: 523.16 | N25: 9.089 | O25: 14 | P25: 0.438 | Q25: =H25+L25+N25+P25+J25 -> 16.538 | S25: =G25*16000 -> 224000 | T25: =I25*17000 -> 0 | U25: =K25*455 -> 0 | V25: =M25*555 -> 290353.8 | W25: =O25*1000 -> 14000 | X25: =S25+T25+U25+V25+W25 -> 528353.8 | Y25: 509400.2
A26: 12 | B26: 12 | E26: ឃាន់ យ៉េន | F26: KHORN YEN | G26: 15 | H26: 7.512 | M26: 494.12 | N26: 8.584 | O26: 15 | P26: 0.47 | Q26: =H26+L26+N26+P26+J26 -> 16.566 | S26: =G26*16000 -> 240000 | T26: =I26*17000 -> 0 | U26: =K26*455 -> 0 | V26: =M26*555 -> 274236.6 | W26: =O26*1000 -> 15000 | X26: =S26+T26+U26+V26+W26 -> 529236.6 | Y26: 485618.8
... A103: 89 | B103: 89 | E103: កេះ ឆេងង៉ាន | F103: KES CHHENGNGAN | G103: 14 | H103: 7.011 | M103: 692.12 | N103: 12.029 | O103: 14 | P103: 0.438 | Q103: =H103+L103+N103+P103+J103 -> 19.478 | S103: =G103*16000 -> 224000 | T103: =I103*17000 -> 0 | U103: =K103*455 -> 0 | V103: =M103*555 -> 384126.6 | W103: =O103*1000 -> 14000 | X103: =S103+T103+U103+V103+W103 -> 622126.6 | Y103: 646208.4
A104: 90 | B104: 90 | E104: សន សុង | F104: SORN SONG | G104: 14 | H104: 7.011 | K104: 529.32 | L104: 7.539 | O104: 14 | P104: 0.438 | Q104: =H104+L104+N104+P104+J104 -> 14.988 | S104: =G104*16000 -> 224000 | T104: =I104*17000 -> 0 | U104: =K104*455 -> 240840.6 | V104: =M104*555 -> 0 | W104: =O104*1000 -> 14000 | X104: =S104+T104+U104+V104+W104 -> 478840.6 | Y104: 469997.8
A105: 91 | B105: 91 | E105: សន សា | F105: SORN SA | G105: 14 | H105: 7.011 | K105: 517.44 | L105: 7.37 | O105: 14 | P105: 0.438 | Q105: =H105+L105+N105+P105+J105 -> 14.819 | S105: =G105*16000 -> 224000 | T105: =I105*17000 -> 0 | U105: =K105*455 -> 235435.2 | V105: =M105*555 -> 0 | W105: =O105*1000 -> 14000 | X105: =S105+T105+U105+V105+W105 -> 473435.2 | Y105: 472200
A106: 92 | B106: 92 | E106: សន ចន្ធី | F106: SORN CHANTHY | G106: 15 | H106: 7.512 | K106: 557.48 | L106: 7.94 | O106: 15 | P106: 0.47 | Q106: =H106+L106+N106+P106+J106 -> 15.922 | S106: =G106*16000 -> 240000 | T106: =I106*17000 -> 0 | U106: =K106*455 -> 253653.4 | V106: =M106*555 -> 0 | W106: =O106*1000 -> 15000 | X106: =S106+T106+U106+V106+W106 -> 508653.4 | Y106: 509620.4
A107: 93 | B107: 93 | E107: ដន មិនា | F107: DORN MINEA | G107: 15 | H107: 7.512 | K107: 575.96 | L107: 8.203 | O107: 15 | P107: 0.47 | Q107: =H107+L107+N107+P107+J107 -> 16.185 | S107: =G107*16000 -> 240000 | T107: =I107*17000 -> 0 | U107: =K107*455 -> 262061.8 | V107: =M107*555 -> 0 | W107: =O107*1000 -> 15000 | X107: =S107+T107+U107+V107+W107 -> 517061.8 | Y107: 503013.8
A108: 94 | B108: 94 | E108: អែល សឿ | F108: AL SOEU | G108: 13 | H108: 6.51 | K108: 551.32 | L108: 7.852 | O108: 13 | P108: 0.407 | Q108: =H108+L108+N108+P108+J108 -> 14.769 | S108: =G108*16000 -> 208000 | T108: =I108*17000 -> 0 | U108: =K108*455 -> 250850.6 | V108: =M108*555 -> 0 | W108: =O108*1000 -> 13000 | X108: =S108+T108+U108+V108+W108 -> 471850.6 | Y108: 457001.8
A109: 95 | B109: 95 | E109: អែល សែល | F109: EL SEL | G109: 13 | H109: 6.51 | K109: 552.64 | L109: 7.871 | O109: 13 | P109: 0.407 | Q109: =H109+L109+N109+P109+J109 -> 14.788 | S109: =G109*16000 -> 208000 | T109: =I109*17000 -> 0 | U109: =K109*455 -> 251451.2 | V109: =M109*555 -> 0 | W109: =O109*1000 -> 13000 | X109: =S109+T109+U109+V109+W109 -> 472451.2 | Y109: 444389.2
A110: 96 | B110: 96 | E110: វី រិដ្ធា | F110: VY RITHA | G110: 13 | H110: 6.51 | K110: 594.88 | L110: 8.472 | O110: 13 | P110: 0.407 | Q110: =H110+L110+N110+P110+J110 -> 15.389 | S110: =G110*16000 -> 208000 | T110: =I110*17000 -> 0 | U110: =K110*455 -> 270670.4 | V110: =M110*555 -> 0 | W110: =O110*1000 -> 13000 | X110: =S110+T110+U110+V110+W110 -> 491670.4 | Y110: 443771.6
A111: 97 | B111: 97 | E111: ស៊ីម សុន | F111: SIM SON | G111: 14 | H111: 7.011 | K111: 450.56 | L111: 6.417 | O111: 14 | P111: 0.438 | Q111: =H111+L111+N111+P111+J111 -> 13.866 | S111: =G111*16000 -> 224000 | T111: =I111*17000 -> 0 | U111: =K111*455 -> 205004.8 | V111: =M111*555 -> 0 | W111: =O111*1000 -> 14000 | X111: =S111+T111+U111+V111+W111 -> 443004.8 | Y111: 425570.4
A112: 98 | B112: 98 | E112: ហ៊ុច សុនឿង | F112: HUCH SONOEUNG | G112: 15 | H112: 7.512 | K112: 510.84 | L112: 7.276 | O112: 15 | P112: 0.47 | Q112: =H112+L112+N112+P112+J112 -> 15.258 | S112: =G112*16000 -> 240000 | T112: =I112*17000 -> 0 | U112: =K112*455 -> 232432.2 | V112: =M112*555 -> 0 | W112: =O112*1000 -> 15000 | X112: =S112+T112+U112+V112+W112 -> 487432.2 | Y112: 518646.4
A113: 99 | B113: 99 | E113: សុក ហាន | F113: SOK HAN | G113: 15 | H113: 7.512 | K113: 362.12 | L113: 5.157 | O113: 15 | P113: 0.47 | Q113: =H113+L113+N113+P113+J113 -> 13.139 | S113: =G113*16000 -> 240000 | T113: =I113*17000 -> 0 | U113: =K113*455 -> 164764.6 | V113: =M113*555 -> 0 | W113: =O113*1000 -> 15000 | X113: =S113+T113+U113+V113+W113 -> 419764.6 | Y113: 487014.8
A114: 100 | B114: 100 | E114: ញ៉ែម ជីវ៉ា | F114: NHEM CHIVA | G114: 14 | H114: 7.011 | K114: 366.96 | L114: 5.226 | O114: 14 | P114: 0.438 | Q114: =H114+L114+N114+P114+J114 -> 12.675 | S114: =G114*16000 -> 224000 | T114: =I114*17000 -> 0 | U114: =K114*455 -> 166966.8 | V114: =M114*555 -> 0 | W114: =O114*1000 -> 14000 | X114: =S114+T114+U114+V114+W114 -> 404966.8 | Y114: 377522.4
A115: 101 | B115: 101 | E115: ម៉ៃ សុជា | F115: MAI SOCHEA | G115: 14 | H115: 7.011 | K115: 404.8 | L115: 5.765 | O115: 14 | P115: 0.438 | Q115: =H115+L115+N115+P115+J115 -> 13.214 | S115: =G115*16000 -> 224000 | T115: =I115*17000 -> 0 | U115: =K115*455 -> 184184 | V115: =M115*555 -> 0 | W115: =O115*1000 -> 14000 | X115: =S115+T115+U115+V115+W115 -> 422184 | Y115: 359304.2
... A427: 413 | B427: 413 | E427: ចាន ខ្មៅ | F427: CHAN KHMAO | G427: 15 | H427: 7.512 | K427: 634.04 | L427: 9.03 | O427: 15 | P427: 0.47 | Q427: =H427+L427+N427+P427+J427 -> 17.012 | S427: =G427*16000 -> 240000 | T427: =I427*17000 -> 0 | U427: =K427*455 -> 288488.2 | V427: =M427*555 -> 0 | W427: =O427*1000 -> 15000 | X427: =S427+T427+U427+V427+W427 -> 543488.2 | Y427: 576521.2
A428: 414 | B428: 414 | E428: ព្រីក ព្រីន | F428: PROEK PRIN | G428: 15 | H428: 7.512 | K428: 627 | L428: 8.93 | O428: 15 | P428: 0.47 | Q428: =H428+L428+N428+P428+J428 -> 16.912 | S428: =G428*16000 -> 240000 | T428: =I428*17000 -> 0 | U428: =K428*455 -> 285285 | V428: =M428*555 -> 0 | W428: =O428*1000 -> 15000 | X428: =S428+T428+U428+V428+W428 -> 540285 | Y428: 595940.6 | AB428: សែ សើ | AC428: SE SEU
A429: 415 | B429: 415 | E429: សែ សើ | F429: SE SEU | G429: 13 | H429: 6.51 | K429: 529.76 | L429: 7.545 | O429: 13 | P429: 0.407 | Q429: =H429+L429+N429+P429+J429 -> 14.462 | S429: =G429*16000 -> 208000 | T429: =I429*17000 -> 0 | U429: =K429*455 -> 241040.8 | V429: =M429*555 -> 0 | W429: =O429*1000 -> 13000 | X429: =S429+T429+U429+V429+W429 -> 462040.8 | Y429: 475471.2 | AB429: ផល ជីន | AC429: PHAL CHIN
A430: 416 | B430: 416 | E430: ផល ជីន | F430: PHAL CHIN | G430: 13 | H430: 6.51 | K430: 542.52 | L430: 7.727 | O430: 13 | P430: 0.407 | Q430: =H430+L430+N430+P430+J430 -> 14.644 | S430: =G430*16000 -> 208000 | T430: =I430*17000 -> 0 | U430: =K430*455 -> 246846.6 | V430: =M430*555 -> 0 | W430: =O430*1000 -> 13000 | X430: =S430+T430+U430+V430+W430 -> 467846.6 | Y430: 499495.2
...

Sheet TTTL VCKD chung
A1: ក្រុមហ៊ុន កៅស៊ូ មេគង្គ ខូអិលធីឌី | K1: ព្រះរាជាណាចក្រកម្ពុជា
A2: CÔNG TY TNHH CAO SU VRG MEKONG | K2: VƯƠNG QUỐC CAMPUCHIA
A3: អង្គភាព: ក្រុមផលិត II | K3: ជាតិ សាសនា ព្រះមហាក្សត្រ
A4: Đơn vị: Đội sản xuất 2 | K4: Dân tộc - Tôn giáo - Quốc vương
A6: តារាងទូទាត់ប្រាក់បៀវត្សកម្មកប្រមូលផល ពីថ្ងៃ​ ១- ១៥ ខែ​ ០១ ឆ្នាំ ២០២៦ វក្ត ០១
A7: BẢNG THANH TOÁN LƯƠNG CÔNG NHÂN VƯỜN CÂY KINH DOANHTỪ NGÀY 1-15 THÁNG​​​​​​ 01 NĂM 2026 ĐỢT 1
Z9: ឯកតា​​​​​​​​​​​​​​ (ĐVT)៖ KHR
A10: ល.រ (STT) | B10: PHẦN CẠO | C10: អត្ត.ប្រជាពលរដ្ឋ số CMND hoặc passport | D10: ត្រកូលនិងឈ្មោះ (Họ và tên) | E10: ត្រកូលនិងឈ្មោះ (Họ và tên) | F10: តម្លៃកម្រិត 31.947 KHRកម្លាំង (Định mức 31.947 KHR/công) | G10: បៀវត្សវគ្គ២ Lương đợt 2 | I10: Lương làm thêm giờ | J10: បៀវត្សថ្ងៃបុណ្យសម្រាក (Lương thưởng tết) | K10: សរុបប្រាក់បៀវត្ស (Tổng lương) | N10: បំណុល (Công nợ) | Q10: បៀវត្សវគ្គ១ Lương đợt 1 | S10: បៀវត្សដាច់ឆ្នាំ (Lương thâm niên) | V10: សរុប Tổng lương | W10: បំណុល Công nợ | Y10: សរុប (Tổng nợ) | Z10: បៀវត្សត្រូវទទួល (Thực nhận) | AA10: ហត្ថលេខា (KÝ NHẬN)
G11: កម្លាំង Công | H11: ជាប្រាក់ Thành Tiền | I11: Công | N11: បុរេប្រទាន (T/ứ lương) | O11: ពន្ធបៀវត្ស (TNCN) | P11: Tiền đóng bảo hiểm | Q11: កម្លាំង Công | R11: ជាប្រាក់ Thành Tiền | W11: ប្រាក់បៀវត្សវត្ត១បានទទូល/Lương đợt 1 đã nhận | X11: ពន្ធលើប្រាក់បៀវត្ស TNCN
A12: A | D12: B | E12: C | F12: 1 | G12: 2 | H12: 3=1*2 | I12: 4 | J12: 5 | K12: 6=3+5 | N12: 7 | O12: 8 | P12: 9 | Q12: 2 | R12: 3=2*1 | S12: 6 | V12: 4=3 | W12: 7 | X12: 5 | Y12: 6=5 | Z12: 7=4-5 | AA12: 8
A14: 1 | B14: ='KL VCKD chung'!B15 -> 1 | C14: 0 | D14: ='KL VCKD chung'!E15 -> ទៀង ទី | E14: ='KL VCKD chung'!F15 -> TEANG TY | F14: 31947 | G14: =#REF! -> #REF! | H14: =ROUND(F14*G14,-2) -> #REF! | I14: 0 | J14: 0 | K14: =J14+H14 -> #REF! | O14: =ROUND(IF(K14<=1200000,0,IF(AND((K14-#REF!)>1200000,(K14-#REF!)<=2000000),(K14-#REF!)*5%-60000,IF(AND((K14-#REF!)>2000000,(K14-#REF!)<=8500000),(K14-#REF!)*10%-160000))),2) -> #REF! | Q14: ='KL VCKD chung'!Q15 -> 10.797 | R14: =ROUND(F14*Q14,0) -> 344932 | T14: =H14+R14 -> #REF! | U14: =H14+S14 -> #REF! | V14: =R14 -> 344932 | W14: =R14 -> 344932 | X14: =ROUND(IF(V14<=1500000,0,IF(AND((V14)>1500000,(V14)<=2000000),(V14)*5%-75000,IF(AND((V14)>2000000,(V14)<=8500000),(V14)*10%-175000))),0) -> 0 | Y14: =X14 -> 0 | Z14: =V14-X14 -> 344932 | AB14: 31947 | AC14: =Z14/AB14 -> 10.797008 | AD14: =AC14*AB14 -> 344932
A15: 2 | B15: ='KL VCKD chung'!B16 -> 2 | C15: 0 | D15: ='KL VCKD chung'!E16 -> រ៉ោន បូ រ៉ី | E15: ='KL VCKD chung'!F16 -> RORN BOREY | F15: 31947 | G15: =#REF! -> #REF! | H15: =ROUND(F15*G15,-2) -> #REF! | J15: 0 | K15: =J15+H15 -> #REF! | O15: =ROUND(IF(K15<=1200000,0,IF(AND((K15-#REF!)>1200000,(K15-#REF!)<=2000000),(K15-#REF!)*5%-60000,IF(AND((K15-#REF!)>2000000,(K15-#REF!)<=8500000),(K15-#REF!)*10%-160000))),2) -> #REF! | Q15: ='KL VCKD chung'!Q16 -> 16.388 | R15: =ROUND(F15*Q15,0) -> 523547 | T15: =H15+R15 -> #REF! | U15: =H15+S15 -> #REF! | V15: =R15 -> 523547 | W15: =R15 -> 523547 | X15: =ROUND(IF(V15<=1500000,0,IF(AND((V15)>1500000,(V15)<=2000000),(V15)*5%-75000,IF(AND((V15)>2000000,(V15)<=8500000),(V15)*10%-175000))),0) -> 0 | Y15: =X15 -> 0 | Z15: =V15-X15 -> 523547 | AB15: 31947 | AC15: =Z15/AB15 -> 16.387986 | AD15: =AC15*AB15 -> 523547
A16: 3 | B16: ='KL VCKD chung'!B17 -> 3 | C16: 0 | D16: ='KL VCKD chung'!E17 -> រ៉ន សុវឿង | E16: ='KL VCKD chung'!F17 -> RORN SOVOEUNG | F16: 31947 | G16: =#REF! -> #REF! | H16: =ROUND(F16*G16,-2) -> #REF! | J16: 0 | K16: =J16+H16 -> #REF! | O16: =ROUND(IF(K16<=1200000,0,IF(AND((K16-#REF!)>1200000,(K16-#REF!)<=2000000),(K16-#REF!)*5%-60000,IF(AND((K16-#REF!)>2000000,(K16-#REF!)<=8500000),(K16-#REF!)*10%-160000))),2) -> #REF! | Q16: ='KL VCKD chung'!Q17 -> 16.918 | R16: =ROUND(F16*Q16,0) -> 540479 | T16: =H16+R16 -> #REF! | U16: =H16+S16 -> #REF! | V16: =R16 -> 540479 | W16: =R16 -> 540479 | X16: =ROUND(IF(V16<=1500000,0,IF(AND((V16)>1500000,(V16)<=2000000),(V16)*5%-75000,IF(AND((V16)>2000000,(V16)<=8500000),(V16)*10%-175000))),0) -> 0 | Y16: =X16 -> 0 | Z16: =V16-X16 -> 540479 | AB16: 31947 | AC16: =Z16/AB16 -> 16.917989 | AD16: =AC16*AB16 -> 540479
A17: 4 | B17: ='KL VCKD chung'!B18 -> 4 | C17: 0 | D17: ='KL VCKD chung'!E18 -> ចាន ជឿន | E17: ='KL VCKD chung'!F18 -> CHAN CHHOEUN | F17: 31947 | G17: =#REF! -> #REF! | H17: =ROUND(F17*G17,-2) -> #REF! | J17: 0 | K17: =J17+H17 -> #REF! | O17: =ROUND(IF(K17<=1200000,0,IF(AND((K17-#REF!)>1200000,(K17-#REF!)<=2000000),(K17-#REF!)*5%-60000,IF(AND((K17-#REF!)>2000000,(K17-#REF!)<=8500000),(K17-#REF!)*10%-160000))),2) -> #REF! | Q17: ='KL VCKD chung'!Q18 -> 14.962 | R17: =ROUND(F17*Q17,0) -> 477991 | T17: =H17+R17 -> #REF! | U17: =H17+S17 -> #REF! | V17: =R17 -> 477991 | W17: =R17 -> 477991 | X17: =ROUND(IF(V17<=1500000,0,IF(AND((V17)>1500000,(V17)<=2000000),(V17)*5%-75000,IF(AND((V17)>2000000,(V17)<=8500000),(V17)*10%-175000))),0) -> 0 | Y17: =X17 -> 0 | Z17: =V17-X17 -> 477991 | AB17: 31947 | AC17: =Z17/AB17 -> 14.962 | AD17: =AC17*AB17 -> 477991
A18: 5 | B18: ='KL VCKD chung'!B19 -> 5 | C18: 0 | D18: ='KL VCKD chung'!E19 -> ជឿន ចាយ | E18: ='KL VCKD chung'!F19 -> CHOEUN CHAY | F18: 31947 | G18: =#REF! -> #REF! | H18: =ROUND(F18*G18,-2) -> #REF! | J18: 0 | K18: =J18+H18 -> #REF! | O18: =ROUND(IF(K18<=1200000,0,IF(AND((K18-#REF!)>1200000,(K18-#REF!)<=2000000),(K18-#REF!)*5%-60000,IF(AND((K18-#REF!)>2000000,(K18-#REF!)<=8500000),(K18-#REF!)*10%-160000))),2) -> #REF! | Q18: ='KL VCKD chung'!Q19 -> 16.861 | R18: =ROUND(F18*Q18,0) -> 538658 | T18: =H18+R18 -> #REF! | U18: =H18+S18 -> #REF! | V18: =R18 -> 538658 | W18: =R18 -> 538658 | X18: =ROUND(IF(V18<=1500000,0,IF(AND((V18)>1500000,(V18)<=2000000),(V18)*5%-75000,IF(AND((V18)>2000000,(V18)<=8500000),(V18)*10%-175000))),0) -> 0 | Y18: =X18 -> 0 | Z18: =V18-X18 -> 538658 | AB18: 31947 | AC18: =Z18/AB18 -> 16.860989 | AD18: =AC18*AB18 -> 538658
A19: 6 | B19: ='KL VCKD chung'!B20 -> 6 | C19: 0 | D19: ='KL VCKD chung'!E20 -> ពឿន ប៉ុន | E19: ='KL VCKD chung'!F20 -> POEUN PON | F19: 31947 | G19: =#REF! -> #REF! | H19: =ROUND(F19*G19,-2) -> #REF! | I19: 0 | J19: 0 | K19: =J19+H19 -> #REF! | O19: =ROUND(IF(K19<=1200000,0,IF(AND((K19-#REF!)>1200000,(K19-#REF!)<=2000000),(K19-#REF!)*5%-60000,IF(AND((K19-#REF!)>2000000,(K19-#REF!)<=8500000),(K19-#REF!)*10%-160000))),2) -> #REF! | P19: =IF(K19<=200000,1600,IF(AND(K19>200000,K19<=250000),1800,IF(AND(K19>250000,K19<=300000),2200,IF(AND(K19>300000,K19<=350000),2600,IF(AND(K19>350000,K19<=400000),3000,IF(AND(K19>400000,K19<=450000),3400,IF(AND(K19>450000,K19<=500000),3800,IF(AND(K19>500000,K19<=550000),4200,IF(AND(K19>550000,K19<=600000),4600,IF(AND(K19>600000,K19<=650000),5000,IF(AND(K19>650000,K19<=700000),5400,IF(AND(K19>700000,K19<=750000),5800,IF(AND(K19>750000,K19<=800000),6200,IF(AND(K19>800000,K19<=850000),6600,IF(AND(K19>850000,K19<=900000),7000,IF(AND(K19>900000,K19<=950000),7400,IF(AND(K19>950000,K19<=1000000),7800,IF(K19>1000000,8000)))))))))))))))))) -> #REF! | Q19: ='KL VCKD chung'!Q20 -> 14.286 | R19: =ROUND(F19*Q19,0) -> 456395 | T19: =H19+R19 -> #REF! | U19: =H19+S19 -> #REF! | V19: =R19 -> 456395 | W19: =R19 -> 456395 | X19: =ROUND(IF(V19<=1500000,0,IF(AND((V19)>1500000,(V19)<=2000000),(V19)*5%-75000,IF(AND((V19)>2000000,(V19)<=8500000),(V19)*10%-175000))),0) -> 0 | Y19: =X19 -> 0 | Z19: =V19-X19 -> 456395 | AB19: 31947 | AC19: =Z19/AB19 -> 14.286005 | AD19: =AC19*AB19 -> 456395
A20: 7 | B20: ='KL VCKD chung'!B21 -> 7 | C20: 0 | D20: ='KL VCKD chung'!E21 -> ឡាញ់ ខ្មៅ | E20: ='KL VCKD chung'!F21 -> LANH KHMAO | F20: 31947 | G20: =#REF! -> #REF! | H20: =ROUND(F20*G20,-2) -> #REF! | I20: 0 | J20: 0 | K20: =J20+H20 -> #REF! | O20: =ROUND(IF(K20<=1200000,0,IF(AND((K20-#REF!)>1200000,(K20-#REF!)<=2000000),(K20-#REF!)*5%-60000,IF(AND((K20-#REF!)>2000000,(K20-#REF!)<=8500000),(K20-#REF!)*10%-160000))),2) -> #REF! | P20: =IF(K20<=200000,1600,IF(AND(K20>200000,K20<=250000),1800,IF(AND(K20>250000,K20<=300000),2200,IF(AND(K20>300000,K20<=350000),2600,IF(AND(K20>350000,K20<=400000),3000,IF(AND(K20>400000,K20<=450000),3400,IF(AND(K20>450000,K20<=500000),3800,IF(AND(K20>500000,K20<=550000),4200,IF(AND(K20>550000,K20<=600000),4600,IF(AND(K20>600000,K20<=650000),5000,IF(AND(K20>650000,K20<=700000),5400,IF(AND(K20>700000,K20<=750000),5800,IF(AND(K20>750000,K20<=800000),6200,IF(AND(K20>800000,K20<=850000),6600,IF(AND(K20>850000,K20<=900000),7000,IF(AND(K20>900000,K20<=950000),7400,IF(AND(K20>950000,K20<=1000000),7800,IF(K20>1000000,8000)))))))))))))))))) -> #REF! | Q20: ='KL VCKD chung'!Q21 -> 13.622 | R20: =ROUND(F20*Q20,0) -> 435182 | T20: =H20+R20 -> #REF! | U20: =H20+S20 -> #REF! | V20: =R20 -> 435182 | W20: =R20 -> 435182 | X20: =ROUND(IF(V20<=1500000,0,IF(AND((V20)>1500000,(V20)<=2000000),(V20)*5%-75000,IF(AND((V20)>2000000,(V20)<=8500000),(V20)*10%-175000))),0) -> 0 | Y20: =X20 -> 0 | Z20: =V20-X20 -> 435182 | AB20: 31947 | AC20: =Z20/AB20 -> 13.621999 | AD20: =AC20*AB20 -> 435182
A21: 8 | B21: ='KL VCKD chung'!B22 -> 8 | C21: 0 | D21: ='KL VCKD chung'!E22 -> ញិន ស៊ាងឡូត | E21: ='KL VCKD chung'!F22 -> GNIN SEANG LOTH | F21: 31947 | G21: =#REF! -> #REF! | H21: =ROUND(F21*G21,-2) -> #REF! | I21: 0 | J21: 0 | K21: =J21+H21 -> #REF! | O21: =ROUND(IF(K21<=1200000,0,IF(AND((K21-#REF!)>1200000,(K21-#REF!)<=2000000),(K21-#REF!)*5%-60000,IF(AND((K21-#REF!)>2000000,(K21-#REF!)<=8500000),(K21-#REF!)*10%-160000))),2) -> #REF! | P21: =IF(K21<=200000,1600,IF(AND(K21>200000,K21<=250000),1800,IF(AND(K21>250000,K21<=300000),2200,IF(AND(K21>300000,K21<=350000),2600,IF(AND(K21>350000,K21<=400000),3000,IF(AND(K21>400000,K21<=450000),3400,IF(AND(K21>450000,K21<=500000),3800,IF(AND(K21>500000,K21<=550000),4200,IF(AND(K21>550000,K21<=600000),4600,IF(AND(K21>600000,K21<=650000),5000,IF(AND(K21>650000,K21<=700000),5400,IF(AND(K21>700000,K21<=750000),5800,IF(AND(K21>750000,K21<=800000),6200,IF(AND(K21>800000,K21<=850000),6600,IF(AND(K21>850000,K21<=900000),7000,IF(AND(K21>900000,K21<=950000),7400,IF(AND(K21>950000,K21<=1000000),7800,IF(K21>1000000,8000)))))))))))))))))) -> #REF! | Q21: ='KL VCKD chung'!Q22 -> 16.383 | R21: =ROUND(F21*Q21,0) -> 523388 | T21: =H21+R21 -> #REF! | U21: =H21+S21 -> #REF! | V21: =R21 -> 523388 | W21: =R21 -> 523388 | X21: =ROUND(IF(V21<=1500000,0,IF(AND((V21)>1500000,(V21)<=2000000),(V21)*5%-75000,IF(AND((V21)>2000000,(V21)<=8500000),(V21)*10%-175000))),0) -> 0 | Y21: =X21 -> 0 | Z21: =V21-X21 -> 523388 | AB21: 31947 | AC21: =Z21/AB21 -> 16.383009 | AD21: =AC21*AB21 -> 523388
A22: 9 | B22: ='KL VCKD chung'!B23 -> 9 | C22: 0 | D22: ='KL VCKD chung'!E23 -> ឡាត់ ឡែម | E22: ='KL VCKD chung'!F23 -> LATH LEM | F22: 31947 | G22: =#REF! -> #REF! | H22: =ROUND(F22*G22,-2) -> #REF! | I22: 0 | J22: 0 | K22: =J22+H22 -> #REF! | O22: =ROUND(IF(K22<=1200000,0,IF(AND((K22-#REF!)>1200000,(K22-#REF!)<=2000000),(K22-#REF!)*5%-60000,IF(AND((K22-#REF!)>2000000,(K22-#REF!)<=8500000),(K22-#REF!)*10%-160000))),2) -> #REF! | P22: =IF(K22<=200000,1600,IF(AND(K22>200000,K22<=250000),1800,IF(AND(K22>250000,K22<=300000),2200,IF(AND(K22>300000,K22<=350000),2600,IF(AND(K22>350000,K22<=400000),3000,IF(AND(K22>400000,K22<=450000),3400,IF(AND(K22>450000,K22<=500000),3800,IF(AND(K22>500000,K22<=550000),4200,IF(AND(K22>550000,K22<=600000),4600,IF(AND(K22>600000,K22<=650000),5000,IF(AND(K22>650000,K22<=700000),5400,IF(AND(K22>700000,K22<=750000),5800,IF(AND(K22>750000,K22<=800000),6200,IF(AND(K22>800000,K22<=850000),6600,IF(AND(K22>850000,K22<=900000),7000,IF(AND(K22>900000,K22<=950000),7400,IF(AND(K22>950000,K22<=1000000),7800,IF(K22>1000000,8000)))))))))))))))))) -> #REF! | Q22: ='KL VCKD chung'!Q23 -> 16.522 | R22: =ROUND(F22*Q22,0) -> 527828 | T22: =H22+R22 -> #REF! | U22: =H22+S22 -> #REF! | V22: =R22 -> 527828 | W22: =R22 -> 527828 | X22: =ROUND(IF(V22<=1500000,0,IF(AND((V22)>1500000,(V22)<=2000000),(V22)*5%-75000,IF(AND((V22)>2000000,(V22)<=8500000),(V22)*10%-175000))),0) -> 0 | Y22: =X22 -> 0 | Z22: =V22-X22 -> 527828 | AB22: 31947 | AC22: =Z22/AB22 -> 16.52199 | AD22: =AC22*AB22 -> 527828
A23: 10 | B23: ='KL VCKD chung'!B24 -> 10 | C23: 0 | D23: ='KL VCKD chung'!E24 -> យឿន យាន់ | E23: ='KL VCKD chung'!F24 -> YOEUN YOIN | F23: 31947 | G23: =#REF! -> #REF! | H23: =ROUND(F23*G23,-2) -> #REF! | J23: 0 | K23: =J23+H23 -> #REF! | O23: =ROUND(IF(K23<=1200000,0,IF(AND((K23-#REF!)>1200000,(K23-#REF!)<=2000000),(K23-#REF!)*5%-60000,IF(AND((K23-#REF!)>2000000,(K23-#REF!)<=8500000),(K23-#REF!)*10%-160000))),2) -> #REF! | Q23: ='KL VCKD chung'!Q24 -> 15.536 | R23: =ROUND(F23*Q23,0) -> 496329 | T23: =H23+R23 -> #REF! | U23: =H23+S23 -> #REF! | V23: =R23 -> 496329 | W23: =R23 -> 496329 | X23: =ROUND(IF(V23<=1500000,0,IF(AND((V23)>1500000,(V23)<=2000000),(V23)*5%-75000,IF(AND((V23)>2000000,(V23)<=8500000),(V23)*10%-175000))),0) -> 0 | Y23: =X23 -> 0 | Z23: =V23-X23 -> 496329 | AB23: 31947 | AC23: =Z23/AB23 -> 15.536013 | AD23: =AC23*AB23 -> 496329
A24: 11 | B24: ='KL VCKD chung'!B25 -> 11 | C24: 0 | D24: ='KL VCKD chung'!E25 -> ញិន​ ឡាយ | E24: ='KL VCKD chung'!F25 -> NHIN LAY | F24: 31947 | G24: =#REF! -> #REF! | H24: =ROUND(F24*G24,-2) -> #REF! | J24: 0 | K24: =J24+H24 -> #REF! | O24: =ROUND(IF(K24<=1200000,0,IF(AND((K24-#REF!)>1200000,(K24-#REF!)<=2000000),(K24-#REF!)*5%-60000,IF(AND((K24-#REF!)>2000000,(K24-#REF!)<=8500000),(K24-#REF!)*10%-160000))),2) -> #REF! | Q24: ='KL VCKD chung'!Q25 -> 16.538 | R24: =ROUND(F24*Q24,0) -> 528339 | T24: =H24+R24 -> #REF! | U24: =H24+S24 -> #REF! | V24: =R24 -> 528339 | W24: =R24 -> 528339 | X24: =ROUND(IF(V24<=1500000,0,IF(AND((V24)>1500000,(V24)<=2000000),(V24)*5%-75000,IF(AND((V24)>2000000,(V24)<=8500000),(V24)*10%-175000))),0) -> 0 | Y24: =X24 -> 0 | Z24: =V24-X24 -> 528339 | AB24: 31947 | AC24: =Z24/AB24 -> 16.537985 | AD24: =AC24*AB24 -> 528339
A25: 12 | B25: ='KL VCKD chung'!B26 -> 12 | C25: 0 | D25: ='KL VCKD chung'!E26 -> ឃាន់ យ៉េន | E25: ='KL VCKD chung'!F26 -> KHORN YEN | F25: 31947 | G25: =#REF! -> #REF! | H25: =ROUND(F25*G25,-2) -> #REF! | J25: 0 | K25: =J25+H25 -> #REF! | O25: =ROUND(IF(K25<=1200000,0,IF(AND((K25-#REF!)>1200000,(K25-#REF!)<=2000000),(K25-#REF!)*5%-60000,IF(AND((K25-#REF!)>2000000,(K25-#REF!)<=8500000),(K25-#REF!)*10%-160000))),2) -> #REF! | Q25: ='KL VCKD chung'!Q26 -> 16.566 | R25: =ROUND(F25*Q25,0) -> 529234 | T25: =H25+R25 -> #REF! | U25: =H25+S25 -> #REF! | V25: =R25 -> 529234 | W25: =R25 -> 529234 | X25: =ROUND(IF(V25<=1500000,0,IF(AND((V25)>1500000,(V25)<=2000000),(V25)*5%-75000,IF(AND((V25)>2000000,(V25)<=8500000),(V25)*10%-175000))),0) -> 0 | Y25: =X25 -> 0 | Z25: =V25-X25 -> 529234 | AB25: 31947 | AC25: =Z25/AB25 -> 16.566 | AD25: =AC25*AB25 -> 529234
A26: 13 | B26: ='KL VCKD chung'!B27 -> 13 | C26: 0 | D26: ='KL VCKD chung'!E27 -> គុំ បុល | E26: ='KL VCKD chung'!F27 -> KUM BOL | F26: 31947 | G26: =#REF! -> #REF! | H26: =ROUND(F26*G26,-2) -> #REF! | J26: 0 | K26: =J26+H26 -> #REF! | O26: =ROUND(IF(K26<=1200000,0,IF(AND((K26-#REF!)>1200000,(K26-#REF!)<=2000000),(K26-#REF!)*5%-60000,IF(AND((K26-#REF!)>2000000,(K26-#REF!)<=8500000),(K26-#REF!)*10%-160000))),2) -> #REF! | Q26: ='KL VCKD chung'!Q27 -> 16.492 | R26: =ROUND(F26*Q26,0) -> 526870 | T26: =H26+R26 -> #REF! | U26: =H26+S26 -> #REF! | V26: =R26 -> 526870 | W26: =R26 -> 526870 | X26: =ROUND(IF(V26<=1500000,0,IF(AND((V26)>1500000,(V26)<=2000000),(V26)*5%-75000,IF(AND((V26)>2000000,(V26)<=8500000),(V26)*10%-175000))),0) -> 0 | Y26: =X26 -> 0 | Z26: =V26-X26 -> 526870 | AB26: 31947 | AC26: =Z26/AB26 -> 16.492002 | AD26: =AC26*AB26 -> 526870
A27: 14 | B27: ='KL VCKD chung'!B28 -> 14 | C27: 0 | D27: ='KL VCKD chung'!E28 -> ជិន ប៉ាក់ | E27: ='KL VCKD chung'!F28 -> CHIN PAK | F27: 31947 | G27: =#REF! -> #REF! | H27: =ROUND(F27*G27,-2) -> #REF! | J27: 0 | K27: =J27+H27 -> #REF! | O27: =ROUND(IF(K27<=1200000,0,IF(AND((K27-#REF!)>1200000,(K27-#REF!)<=2000000),(K27-#REF!)*5%-60000,IF(AND((K27-#REF!)>2000000,(K27-#REF!)<=8500000),(K27-#REF!)*10%-160000))),2) -> #REF! | Q27: ='KL VCKD chung'!Q28 -> 17.149 | R27: =ROUND(F27*Q27,0) -> 547859 | T27: =H27+R27 -> #REF! | U27: =H27+S27 -> #REF! | V27: =R27 -> 547859 | W27: =R27 -> 547859 | X27: =ROUND(IF(V27<=1500000,0,IF(AND((V27)>1500000,(V27)<=2000000),(V27)*5%-75000,IF(AND((V27)>2000000,(V27)<=8500000),(V27)*10%-175000))),0) -> 0 | Y27: =X27 -> 0 | Z27: =V27-X27 -> 547859 | AB27: 31947 | AC27: =Z27/AB27 -> 17.148997 | AD27: =AC27*AB27 -> 547859
A28: 15 | B28: ='KL VCKD chung'!B29 -> 15 | C28: 0 | D28: ='KL VCKD chung'!E29 -> ផល ផាត | E28: ='KL VCKD chung'!F29 -> PHAL PHAT | F28: 31947 | G28: =#REF! -> #REF! | H28: =ROUND(F28*G28,-2) -> #REF! | J28: 0 | K28: =J28+H28 -> #REF! | O28: =ROUND(IF(K28<=1200000,0,IF(AND((K28-#REF!)>1200000,(K28-#REF!)<=2000000),(K28-#REF!)*5%-60000,IF(AND((K28-#REF!)>2000000,(K28-#REF!)<=8500000),(K28-#REF!)*10%-160000))),2) -> #REF! | Q28: ='KL VCKD chung'!Q29 -> 14.148 | R28: =ROUND(F28*Q28,0) -> 451986 | T28: =H28+R28 -> #REF! | U28: =H28+S28 -> #REF! | V28: =R28 -> 451986 | W28: =R28 -> 451986 | X28: =ROUND(IF(V28<=1500000,0,IF(AND((V28)>1500000,(V28)<=2000000),(V28)*5%-75000,IF(AND((V28)>2000000,(V28)<=8500000),(V28)*10%-175000))),0) -> 0 | Y28: =X28 -> 0 | Z28: =V28-X28 -> 451986 | AB28: 31947 | AC28: =Z28/AB28 -> 14.147995 | AD28: =AC28*AB28 -> 451986
A29: 16 | B29: ='KL VCKD chung'!B30 -> 16 | C29: 0 | D29: ='KL VCKD chung'!E30 -> យាត ធីម | E29: ='KL VCKD chung'!F30 -> YEAT THIM | F29: 31947 | G29: =#REF! -> #REF! | H29: =ROUND(F29*G29,-2) -> #REF! | J29: 0 | K29: =J29+H29 -> #REF! | O29: =ROUND(IF(K29<=1200000,0,IF(AND((K29-#REF!)>1200000,(K29-#REF!)<=2000000),(K29-#REF!)*5%-60000,IF(AND((K29-#REF!)>2000000,(K29-#REF!)<=8500000),(K29-#REF!)*10%-160000))),2) -> #REF! | Q29: ='KL VCKD chung'!Q30 -> 16.614 | R29: =ROUND(F29*Q29,0) -> 530767 | T29: =H29+R29 -> #REF! | U29: =H29+S29 -> #REF! | V29: =R29 -> 530767 | W29: =R29 -> 530767 | X29: =ROUND(IF(V29<=1500000,0,IF(AND((V29)>1500000,(V29)<=2000000),(V29)*5%-75000,IF(AND((V29)>2000000,(V29)<=8500000),(V29)*10%-175000))),0) -> 0 | Y29: =X29 -> 0 | Z29: =V29-X29 -> 530767 | AB29: 31947 | AC29: =Z29/AB29 -> 16.613986 | AD29: =AC29*AB29 -> 530767
A30: 17 | B30: ='KL VCKD chung'!B31 -> 17 | C30: 0 | D30: ='KL VCKD chung'!E31 -> ញាន សាវៀត | E30: ='KL VCKD chung'!F31 -> NHEAN SAVET | F30: 31947 | G30: =#REF! -> #REF! | H30: =ROUND(F30*G30,-2) -> #REF! | J30: 0 | K30: =J30+H30 -> #REF! | O30: =ROUND(IF(K30<=1200000,0,IF(AND((K30-#REF!)>1200000,(K30-#REF!)<=2000000),(K30-#REF!)*5%-60000,IF(AND((K30-#REF!)>2000000,(K30-#REF!)<=8500000),(K30-#REF!)*10%-160000))),2) -> #REF! | Q30: ='KL VCKD chung'!Q31 -> 16.324 | R30: =ROUND(F30*Q30,0) -> 521503 | T30: =H30+R30 -> #REF! | U30: =H30+S30 -> #REF! | V30: =R30 -> 521503 | W30: =R30 -> 521503 | X30: =ROUND(IF(V30<=1500000,0,IF(AND((V30)>1500000,(V30)<=2000000),(V30)*5%-75000,IF(AND((V30)>2000000,(V30)<=8500000),(V30)*10%-175000))),0) -> 0 | Y30: =X30 -> 0 | Z30: =V30-X30 -> 521503 | AB30: 31947 | AC30: =Z30/AB30 -> 16.324005 | AD30: =AC30*AB30 -> 521503
A31: 18 | B31: ='KL VCKD chung'!B32 -> 18 | C31: 0 | D31: ='KL VCKD chung'!E32 -> យាត តារា | E31: ='KL VCKD chung'!F32 -> YEAT DARA | F31: 31947 | G31: =#REF! -> #REF! | H31: =ROUND(F31*G31,-2) -> #REF! | J31: 0 | K31: =J31+H31 -> #REF! | O31: =ROUND(IF(K31<=1200000,0,IF(AND((K31-#REF!)>1200000,(K31-#REF!)<=2000000),(K31-#REF!)*5%-60000,IF(AND((K31-#REF!)>2000000,(K31-#REF!)<=8500000),(K31-#REF!)*10%-160000))),2) -> #REF! | Q31: ='KL VCKD chung'!Q32 -> 15.893 | R31: =ROUND(F31*Q31,0) -> 507734 | T31: =H31+R31 -> #REF! | U31: =H31+S31 -> #REF! | V31: =R31 -> 507734 | W31: =R31 -> 507734 | X31: =ROUND(IF(V31<=1500000,0,IF(AND((V31)>1500000,(V31)<=2000000),(V31)*5%-75000,IF(AND((V31)>2000000,(V31)<=8500000),(V31)*10%-175000))),0) -> 0 | Y31: =X31 -> 0 | Z31: =V31-X31 -> 507734 | AB31: 31947 | AC31: =Z31/AB31 -> 15.89301 | AD31: =AC31*AB31 -> 507734
A32: 19 | B32: ='KL VCKD chung'!B33 -> 19 | C32: 0 | D32: ='KL VCKD chung'!E33 -> ឌុក ម៉ៅ | E32: ='KL VCKD chung'!F33 -> DUK MAO | F32: 31947 | G32: =#REF! -> #REF! | H32: =ROUND(F32*G32,-2) -> #REF! | J32: 0 | K32: =J32+H32 -> #REF! | O32: =ROUND(IF(K32<=1200000,0,IF(AND((K32-#REF!)>1200000,(K32-#REF!)<=2000000),(K32-#REF!)*5%-60000,IF(AND((K32-#REF!)>2000000,(K32-#REF!)<=8500000),(K32-#REF!)*10%-160000))),2) -> #REF! | Q32: ='KL VCKD chung'!Q33 -> 18.141 | R32: =ROUND(F32*Q32,0) -> 579551 | T32: =H32+R32 -> #REF! | U32: =H32+S32 -> #REF! | V32: =R32 -> 579551 | W32: =R32 -> 579551 | X32: =ROUND(IF(V32<=1500000,0,IF(AND((V32)>1500000,(V32)<=2000000),(V32)*5%-75000,IF(AND((V32)>2000000,(V32)<=8500000),(V32)*10%-175000))),0) -> 0 | Y32: =X32 -> 0 | Z32: =V32-X32 -> 579551 | AB32: 31947 | AC32: =Z32/AB32 -> 18.141015 | AD32: =AC32*AB32 -> 579551
A33: 20 | B33: ='KL VCKD chung'!B34 -> 20 | C33: 0 | D33: ='KL VCKD chung'!E34 -> នៅ គី | E33: ='KL VCKD chung'!F34 -> NOV KI | F33: 31947 | G33: =#REF! -> #REF! | H33: =ROUND(F33*G33,-2) -> #REF! | I33: 0 | J33: 0 | K33: =J33+H33 -> #REF! | O33: =ROUND(IF(K33<=1200000,0,IF(AND((K33-#REF!)>1200000,(K33-#REF!)<=2000000),(K33-#REF!)*5%-60000,IF(AND((K33-#REF!)>2000000,(K33-#REF!)<=8500000),(K33-#REF!)*10%-160000))),2) -> #REF! | P33: =IF(K33<=200000,1600,IF(AND(K33>200000,K33<=250000),1800,IF(AND(K33>250000,K33<=300000),2200,IF(AND(K33>300000,K33<=350000),2600,IF(AND(K33>350000,K33<=400000),3000,IF(AND(K33>400000,K33<=450000),3400,IF(AND(K33>450000,K33<=500000),3800,IF(AND(K33>500000,K33<=550000),4200,IF(AND(K33>550000,K33<=600000),4600,IF(AND(K33>600000,K33<=650000),5000,IF(AND(K33>650000,K33<=700000),5400,IF(AND(K33>700000,K33<=750000),5800,IF(AND(K33>750000,K33<=800000),6200,IF(AND(K33>800000,K33<=850000),6600,IF(AND(K33>850000,K33<=900000),7000,IF(AND(K33>900000,K33<=950000),7400,IF(AND(K33>950000,K33<=1000000),7800,IF(K33>1000000,8000)))))))))))))))))) -> #REF! | Q33: ='KL VCKD chung'!Q34 -> 16.344 | R33: =ROUND(F33*Q33,0) -> 522142 | T33: =H33+R33 -> #REF! | U33: =H33+S33 -> #REF! | V33: =R33 -> 522142 | W33: =R33 -> 522142 | X33: =ROUND(IF(V33<=1500000,0,IF(AND((V33)>1500000,(V33)<=2000000),(V33)*5%-75000,IF(AND((V33)>2000000,(V33)<=8500000),(V33)*10%-175000))),0) -> 0 | Y33: =X33 -> 0 | Z33: =V33-X33 -> 522142 | AB33: 31947 | AC33: =Z33/AB33 -> 16.344007 | AD33: =AC33*AB33 -> 522142
A34: 21 | B34: ='KL VCKD chung'!B35 -> 21 | C34: 0 | D34: ='KL VCKD chung'!E35 -> ឌុក ឃីម | E34: ='KL VCKD chung'!F35 -> DUK KHIM | F34: 31947 | G34: =#REF! -> #REF! | H34: =ROUND(F34*G34,-2) -> #REF! | I34: 0 | J34: 0 | K34: =J34+H34 -> #REF! | O34: =ROUND(IF(K34<=1200000,0,IF(AND((K34-#REF!)>1200000,(K34-#REF!)<=2000000),(K34-#REF!)*5%-60000,IF(AND((K34-#REF!)>2000000,(K34-#REF!)<=8500000),(K34-#REF!)*10%-160000))),2) -> #REF! | P34: =IF(K34<=200000,1600,IF(AND(K34>200000,K34<=250000),1800,IF(AND(K34>250000,K34<=300000),2200,IF(AND(K34>300000,K34<=350000),2600,IF(AND(K34>350000,K34<=400000),3000,IF(AND(K34>400000,K34<=450000),3400,IF(AND(K34>450000,K34<=500000),3800,IF(AND(K34>500000,K34<=550000),4200,IF(AND(K34>550000,K34<=600000),4600,IF(AND(K34>600000,K34<=650000),5000,IF(AND(K34>650000,K34<=700000),5400,IF(AND(K34>700000,K34<=750000),5800,IF(AND(K34>750000,K34<=800000),6200,IF(AND(K34>800000,K34<=850000),6600,IF(AND(K34>850000,K34<=900000),7000,IF(AND(K34>900000,K34<=950000),7400,IF(AND(K34>950000,K34<=1000000),7800,IF(K34>1000000,8000)))))))))))))))))) -> #REF! | Q34: ='KL VCKD chung'!Q35 -> 15.947 | R34: =ROUND(F34*Q34,0) -> 509459 | T34: =H34+R34 -> #REF! | U34: =H34+S34 -> #REF! | V34: =R34 -> 509459 | W34: =R34 -> 509459 | X34: =ROUND(IF(V34<=1500000,0,IF(AND((V34)>1500000,(V34)<=2000000),(V34)*5%-75000,IF(AND((V34)>2000000,(V34)<=8500000),(V34)*10%-175000))),0) -> 0 | Y34: =X34 -> 0 | Z34: =V34-X34 -> 509459 | AB34: 31947 | AC34: =Z34/AB34 -> 15.947006 | AD34: =AC34*AB34 -> 509459
A35: 22 | B35: ='KL VCKD chung'!B36 -> 22 | C35: 0 | D35: ='KL VCKD chung'!E36 -> ភឿក សុខ | E35: ='KL VCKD chung'!F36 -> PHOEUN SOK | F35: 31947 | G35: =#REF! -> #REF! | H35: =ROUND(F35*G35,-2) -> #REF! | K35: =J35+H35 -> #REF! | Q35: ='KL VCKD chung'!Q36 -> 15.32 | R35: =ROUND(F35*Q35,0) -> 489428 | T35: =H35+R35 -> #REF! | U35: =H35+S35 -> #REF! | V35: =R35 -> 489428 | W35: =R35 -> 489428 | X35: =ROUND(IF(V35<=1500000,0,IF(AND((V35)>1500000,(V35)<=2000000),(V35)*5%-75000,IF(AND((V35)>2000000,(V35)<=8500000),(V35)*10%-175000))),0) -> 0 | Y35: =X35 -> 0 | Z35: =V35-X35 -> 489428 | AB35: 31947 | AC35: =Z35/AB35 -> 15.319999 | AD35: =AC35*AB35 -> 489428
A36: 23 | B36: ='KL VCKD chung'!B37 -> 23 | C36: 0 | D36: ='KL VCKD chung'!E37 -> ភឿក ងយ | E36: ='KL VCKD chung'!F37 -> PHOEURK NGORY | F36: 31947 | G36: =#REF! -> #REF! | H36: =ROUND(F36*G36,-2) -> #REF! | K36: =J36+H36 -> #REF! | Q36: ='KL VCKD chung'!Q37 -> 14.734 | R36: =ROUND(F36*Q36,0) -> 470707 | T36: =H36+R36 -> #REF! | U36: =H36+S36 -> #REF! | V36: =R36 -> 470707 | W36: =R36 -> 470707 | X36: =ROUND(IF(V36<=1500000,0,IF(AND((V36)>1500000,(V36)<=2000000),(V36)*5%-75000,IF(AND((V36)>2000000,(V36)<=8500000),(V36)*10%-175000))),0) -> 0 | Y36: =X36 -> 0 | Z36: =V36-X36 -> 470707 | AB36: 31947 | AC36: =Z36/AB36 -> 14.733997 | AD36: =AC36*AB36 -> 470707
A37: 24 | B37: ='KL VCKD chung'!B38 -> 24 | C37: 0 | D37: ='KL VCKD chung'!E38 -> គង់ សេងឌី | E37: ='KL VCKD chung'!F38 -> KUNG SENGDY | F37: 31947 | G37: =#REF! -> #REF! | H37: =ROUND(F37*G37,-2) -> #REF! | K37: =J37+H37 -> #REF! | Q37: ='KL VCKD chung'!Q38 -> 13.781 | R37: =ROUND(F37*Q37,0) -> 440262 | T37: =H37+R37 -> #REF! | U37: =H37+S37 -> #REF! | V37: =R37 -> 440262 | W37: =R37 -> 440262 | X37: =ROUND(IF(V37<=1500000,0,IF(AND((V37)>1500000,(V37)<=2000000),(V37)*5%-75000,IF(AND((V37)>2000000,(V37)<=8500000),(V37)*10%-175000))),0) -> 0 | Y37: =X37 -> 0 | Z37: =V37-X37 -> 440262 | AB37: 31947 | AC37: =Z37/AB37 -> 13.781012 | AD37: =AC37*AB37 -> 440262
A38: 25 | B38: ='KL VCKD chung'!B39 -> 25 | C38: 0 | D38: ='KL VCKD chung'!E39 -> យាន់ សោម | E38: ='KL VCKD chung'!F39 -> YEANN SOAM | F38: 31947 | G38: =#REF! -> #REF! | H38: =ROUND(F38*G38,-2) -> #REF! | K38: =J38+H38 -> #REF! | Q38: ='KL VCKD chung'!Q39 -> 18.722 | R38: =ROUND(F38*Q38,0) -> 598112 | T38: =H38+R38 -> #REF! | U38: =H38+S38 -> #REF! | V38: =R38 -> 598112 | W38: =R38 -> 598112 | X38: =ROUND(IF(V38<=1500000,0,IF(AND((V38)>1500000,(V38)<=2000000),(V38)*5%-75000,IF(AND((V38)>2000000,(V38)<=8500000),(V38)*10%-175000))),0) -> 0 | Y38: =X38 -> 0 | Z38: =V38-X38 -> 598112 | AB38: 31947 | AC38: =Z38/AB38 -> 18.722008 | AD38: =AC38*AB38 -> 598112
A39: 26 | B39: ='KL VCKD chung'!B40 -> 26 | C39: 0 | D39: ='KL VCKD chung'!E40 -> ឆោម ជួ | E39: ='KL VCKD chung'!F40 -> CHAOM CHOU | F39: 31947 | G39: =#REF! -> #REF! | H39: =ROUND(F39*G39,-2) -> #REF! | K39: =J39+H39 -> #REF! | Q39: ='KL VCKD chung'!Q40 -> 18.057 | R39: =ROUND(F39*Q39,0) -> 576867 | T39: =H39+R39 -> #REF! | U39: =H39+S39 -> #REF! | V39: =R39 -> 576867 | W39: =R39 -> 576867 | X39: =ROUND(IF(V39<=1500000,0,IF(AND((V39)>1500000,(V39)<=2000000),(V39)*5%-75000,IF(AND((V39)>2000000,(V39)<=8500000),(V39)*10%-175000))),0) -> 0 | Y39: =X39 -> 0 | Z39: =V39-X39 -> 576867 | AB39: 31947 | AC39: =Z39/AB39 -> 18.057001 | AD39: =AC39*AB39 -> 576867
A40: 27 | B40: ='KL VCKD chung'!B41 -> 27 | C40: 0 | D40: ='KL VCKD chung'!E41 -> កាំង ខន | E40: ='KL VCKD chung'!F41 -> KANG KHAN | F40: 31947 | G40: =#REF! -> #REF! | H40: =ROUND(F40*G40,-2) -> #REF! | K40: =J40+H40 -> #REF! | Q40: ='KL VCKD chung'!Q41 -> 18.663 | R40: =ROUND(F40*Q40,0) -> 596227 | T40: =H40+R40 -> #REF! | U40: =H40+S40 -> #REF! | V40: =R40 -> 596227 | W40: =R40 -> 596227 | X40: =ROUND(IF(V40<=1500000,0,IF(AND((V40)>1500000,(V40)<=2000000),(V40)*5%-75000,IF(AND((V40)>2000000,(V40)<=8500000),(V40)*10%-175000))),0) -> 0 | Y40: =X40 -> 0 | Z40: =V40-X40 -> 596227 | AB40: 31947 | AC40: =Z40/AB40 -> 18.663004 | AD40: =AC40*AB40 -> 596227
A41: 28 | B41: ='KL VCKD chung'!B42 -> 28 | C41: 0 | D41: ='KL VCKD chung'!E42 -> ឃីម ញ៉ក់ | E41: ='KL VCKD chung'!F42 -> KHIM NHOK | F41: 31947 | G41: =#REF! -> #REF! | H41: =ROUND(F41*G41,-2) -> #REF! | K41: =J41+H41 -> #REF! | Q41: ='KL VCKD chung'!Q42 -> 18.15 | R41: =ROUND(F41*Q41,0) -> 579838 | T41: =H41+R41 -> #REF! | U41: =H41+S41 -> #REF! | V41: =R41 -> 579838 | W41: =R41 -> 579838 | X41: =ROUND(IF(V41<=1500000,0,IF(AND((V41)>1500000,(V41)<=2000000),(V41)*5%-75000,IF(AND((V41)>2000000,(V41)<=8500000),(V41)*10%-175000))),0) -> 0 | Y41: =X41 -> 0 | Z41: =V41-X41 -> 579838 | AB41: 31947 | AC41: =Z41/AB41 -> 18.149998 | AD41: =AC41*AB41 -> 579838
A42: 29 | B42: ='KL VCKD chung'!B43 -> 29 | C42: 0 | D42: ='KL VCKD chung'!E43 -> លឿន សុលាំ | E42: ='KL VCKD chung'!F43 -> LOEUN SOLAM | F42: 31947 | G42: =#REF! -> #REF! | H42: =ROUND(F42*G42,-2) -> #REF! | K42: =J42+H42 -> #REF! | Q42: ='KL VCKD chung'!Q43 -> 20.029 | R42: =ROUND(F42*Q42,0) -> 639866 | T42: =H42+R42 -> #REF! | U42: =H42+S42 -> #REF! | V42: =R42 -> 639866 | W42: =R42 -> 639866 | X42: =ROUND(IF(V42<=1500000,0,IF(AND((V42)>1500000,(V42)<=2000000),(V42)*5%-75000,IF(AND((V42)>2000000,(V42)<=8500000),(V42)*10%-175000))),0) -> 0 | Y42: =X42 -> 0 | Z42: =V42-X42 -> 639866 | AB42: 31947 | AC42: =Z42/AB42 -> 20.028986 | AD42: =AC42*AB42 -> 639866
A43: 30 | B43: ='KL VCKD chung'!B44 -> 30 | C43: 0 | D43: ='KL VCKD chung'!E44 -> ពៅ សុលុក | E43: ='KL VCKD chung'!F44 -> POV SOLUK | F43: 31947 | G43: =#REF! -> #REF! | H43: =ROUND(F43*G43,-2) -> #REF! | K43: =J43+H43 -> #REF! | Q43: ='KL VCKD chung'!Q44 -> 19.18 | R43: =ROUND(F43*Q43,0) -> 612743 | T43: =H43+R43 -> #REF! | U43: =H43+S43 -> #REF! | V43: =R43 -> 612743 | W43: =R43 -> 612743 | X43: =ROUND(IF(V43<=1500000,0,IF(AND((V43)>1500000,(V43)<=2000000),(V43)*5%-75000,IF(AND((V43)>2000000,(V43)<=8500000),(V43)*10%-175000))),0) -> 0 | Y43: =X43 -> 0 | Z43: =V43-X43 -> 612743 | AB43: 31947 | AC43: =Z43/AB43 -> 19.179986 | AD43: =AC43*AB43 -> 612743
...

Sheet PTL VCKD 1
D1: ព្រះរាជាណាចក្រកម្ពុជា
A2: ក្រុមហ៊ុន កៅស៊ូ មេគង្គ ខូអិលធីឌី | D2: VƯƠNG QUỐC CAMPUCHIA
A3: VRG Caoutchouc Mekong Co., Ltd | D3: ជាតិ សាសនា ព្រះមហាក្សត្រ
A4: អង្គភាព: ក្រុមផលិត II | D4: Dân tộc - Tôn giáo - Quốc vương
A5: Đơn vị: Đội sản xuất 2
A7: តារាងបែងចែកប្រាក់បៀវត្សកម្មករ​ប្រមូលផល
A8: លើកទី ១ ពីថ្ងៃ ១-១៥ ខែ ០១ ឆ្នាំ ២០២៦
A9: BẢNG PHÂN TOÁN LƯƠNG CÔNG NHÂN VƯỜN CÂY KINH DOANH
A10: ĐỢT 1 TỪ NGÀY 1-15 THÁNG 01 NĂM 2026
F12: ឯកតា (ĐVT)៖ KHR
A13: ល.រ | B13: រាយនាមការងារ | C13: តម្លៃ | D13: ជាកម្លាំង | F13: ជាប្រាក់ | G13: ចំណាំ
A14: STT | B14: Hạng mục công việc | C14: Đơn giá | D14: Quy công | E14: Công làm thêm giờ | F14: Thành tiền | G14: Ghi chú | I14: កំណត់
A15: A. | B15: ចំការកៅស៊ូ (VƯỜN CÂY) | D15: =#REF!+#REF!+#REF!+#REF!+#REF!+#REF! -> #REF! | E15: 0 | F15: =ROUND(D15*#REF!,-2)+300 -> #REF!
A16: I. | B16: អាជីវកម្មក្រុមទី​ ១ /KD NHÓM 1 (2795,2,ha) | C16: 31947 | D16: =SUM(D17:D18) -> 9702.8 | F16: =ROUND(D16*C16,0) -> 309975352
A17: 5 | B17: ប្រមូលសម្ភារៈចុងរដូវចៀរ/ Thu dọn cuối vụ cạo | C17: 31947 | F17: =ROUND(C17*D17,0) -> 0
A18: 1 | B18: ជៀ សានិងប្រគូលជ័រ/ Cạo trút và giao nộp mủ | C18: 31947 | D18: 9702.8 | F18: =ROUND(C18*D18,0) -> 309975352
A19: 6 | B19: ប្រាក់អតិ្តភាព/Tiền lương thâm niên
A20: II. | B20: ចំការបើកមុខជៀឆ្នាំ ២០២២ (264,8 HA)/Vườn cây mở cạo năm 2022 (264,8 HA) | C20: 30456 | D20: =SUM(D21:D25) -> 0 | F20: =ROUND(D20*C20,0) -> 0 | H20: =F20+#REF!+#REF! -> #REF!
A21: 1 | B21: បង្ការព្យាបាលជម្ងឺ/Phòng trị bệnh | C21: 30456 | F21: =ROUND(C21*D21,0) -> 0
A22: 1 | B22: លាបថ្នាំរំញោច/Bôi thuốc kích thích | C22: 30456 | F22: =ROUND(C22*D22,0) -> 0
A23: 3 | B23: បើកមុខចៀរជ័រដំបូង ដោតស្លាបព្រា​និងទគម្របចាន/Cạo xã miệng,đóng máng, gắn máy che chén | C23: 30456 | F23: =ROUND(C23*D23,0) -> 0
A24: 2 | B24: ជៀ សានិងប្រគូលជ័រ/ Cạo trút và giao nộp mủ | C24: 30456 | F24: =ROUND(C24*D24,0) -> 0
A25: 3 | B25: សន្តិសុខការពារចំការ/Bảo vệ vườn cây | C25: 30456 | F25: =ROUND(C25*D25,0) -> 0 | H25: =57.8/2 -> 28.9
A26: សរុប (Tổng cộng) | D26: =D20+D16 -> 9702.8 | F26: =F16 -> 309975352
A27: ប្រាក់អតិ្តភាព/Tiền lương thâm niên | F27: =#REF! -> #REF!
A28: សរុប (Tổng cộng) | F28: =F26+F27 -> #REF! | H28: =D28*#REF! -> #REF! | I28: =F28-#REF! -> #REF!
A30: (ជាអក្សរ៖បីរយប្រាំបួនលាន ប្រាំបួនរយចែតសិបប្រាំពាន់ បីរយហាសិបពីររៀលគត់។ | H30: (ជាអក្សរ៖ដប់បួនលានប្រាំរយម៉ាពីប្រាំបីពាន់ចែតសិបប្រាំបួនរៀលគត់។)
A31: Bằng chữ: Ba trăm lẻ chín triệu chín trăm bảy mươi lăm ngàn ba trăm năm mươi hai riel chẵn
A33: ​
B34: អង្គភាពអនុវត្ត -ĐƠN VỊ THỰC HIỆN | D34: អ្នករៀបចំ -NGƯỜI LẬP BIỂU
B37: Nguyễn Vũ Minh | D37: Kim Thảo
B39: ផែ្នក រដ្ឋបាល-PHÒNG TCHC | D39: ផ្នែក គណនេយ្យ -PHÒNG TCKT
A44: អនុម័តនាយកក្រុមហ៊ុន
A45: DUYỆT
A46: GIÁM ĐỐC

Sheet Kiểm tra
A1: KIỂM TRA
A2: Làm cỏ đường băng (7 công/ha) | C2: Làm cỏ đường băng (5 công/ha) | E2: Làm cỏ đường băng (3,5 công/ha) | G2: Làm cỏ đậu Kudzu (4 công/ha) | I2: Làm cỏ bồn (4 công/ha) | K2: Làm cỏ bồn (3,5 công/ha) | M2: Làm cỏ ranh chống cháy (300 m2/công) | O2: Phát cỏ luồng (3 công/ha) | Q2: Phòng chống cháy (1,08 công/ha) | S2: Phát dọn chống cháy (0,54 công/ha) | U2: Phát cỏ luồng (1 công/ha) | W2: Chặt nọc cắm cây cao su trồng dặm | Y2: Phun thuốc cỏ đường băng (1,56 công/ha) | AA2: Xịt phân Komix nước bón lá (0,2 công/ha) | AC2: Cắt chồi ngang (0,2 công/ha) | AE2: Đào mương | AG2: Phun thuốc BVTV diệt câu cấu | AI2: Xịt thuốc BVTV diệt rệp (0,4 công/ha)
A3: Khối lượng | B3: Công | C3: Khối lượng | D3: Công | E3: Khối lượng | F3: Công | G3: Khối lượng | H3: Công | I3: Khối lượng | J3: Công | K3: Khối lượng | L3: Công | M3: Khối lượng | N3: Công | O3: Khối lượng | P3: Công | Q3: Khối lượng | R3: Công | S3: Khối lượng | T3: Công | U3: Khối lượng | V3: Công | W3: Khối lượng | X3: Công | Y3: Khối lượng | Z3: Công | AA3: Khối lượng | AB3: Công | AC3: Khối lượng | AD3: Công | AE3: Khối lượng | AF3: Công | AG3: Khối lượng | AH3: Công | AI3: Khối lượng | AJ3: Công
Q4: ='KL Tổ BVTX '!BI$15 -> 0 | R4: ='KL Tổ BVTX '!BJ$15 -> 0 | U4: ='KL Tổ BVTX '!#REF!+'KL tổ 5'!R$45+'KL tổ 10'!#REF!+#REF!+'KL VCKD chung'!#REF! -> #REF! | V4: ='KL Tổ BVTX '!#REF!+'KL tổ 5'!S$45+'KL tổ 10'!V$22+#REF!+'KL VCKD chung'!#REF! -> #REF! | W4: ='KL tổ 10'!O$22+#REF! -> #REF! | X4: ='KL tổ 10'!P$22+#REF! -> #REF! | AE4: ='KL tổ 10'!AK$22+#REF! -> #REF! | AF4: ='KL tổ 10'!AL$22+#REF! -> #REF! | AG4: =#REF! -> #REF! | AH4: =#REF! -> #REF! | AI4: =#REF!+'KL tổ 10'!S$22 -> #REF! | AJ4: =#REF!+'KL tổ 10'!T$22 -> #REF!
AI6: 878.2
U7: 132.2
A9: Công tưới nước cao su | C9: Khoanh bồn tủ cỏ (130 bồn/công) | E9: Công quản lý (Tổ trưởng) | G9: Bón phân thúc vườn ương | I9: Làm mái che cao su | K9: Gác trâu | M9: Thiết kế súng tưới | O9: Sang bầu | Q9: Làm hàng rào | S9: Tưới nước | U9: Tưới phân vườn âm bầu | W9: Làm cỏ vườn ươm | Y9: Tưới nước vườn âm bầu | AA9: Phòng chống cháy - chống thú | AC9: Vệ sinh vườn âm bầu | AE9: Cắt ngọn cao su | AG9: Bốc bầu xuống xe (600 bầu/công) | AI9: Phun thuốc Vixazol vườn ương
A10: Khối lượng | B10: Công | C10: Khối lượng | D10: Công | E10: Khối lượng | F10: Công | G10: Khối lượng | H10: Công | I10: Khối lượng | J10: Công | K10: Khối lượng | L10: Công | M10: Khối lượng | N10: Công | O10: Khối lượng | P10: Công | Q10: Khối lượng | R10: Công | S10: Khối lượng | T10: Công | U10: Khối lượng | V10: Công | W10: Khối lượng | X10: Công | Y10: Khối lượng | Z10: Công | AA10: Khối lượng | AB10: Công | AC10: Khối lượng | AD10: Công | AE10: Khối lượng | AF10: Công | AG10: Khối lượng | AH10: Công | AI10: Khối lượng | AJ10: Công
A11: ='KL Tổ BVTX '!BE$15+'KL tổ 5'!BO$45+'KL tổ 4'!BJ$20+'KL VCKD chung'!#REF!+'KL tổ 10'!BA$22+#REF! -> #REF! | B11: ='KL Tổ BVTX '!#REF!+'KL tổ 5'!BR$45+'KL tổ 4'!BK$20+'KL VCKD chung'!#REF!+'KL tổ 10'!BB$22+#REF! -> #REF! | C11: ='KL tổ 10'!Q$22 -> 0 | D11: ='KL tổ 10'!R$22 -> 0 | E11: =#REF!+'KL tổ 5'!BU$45+'KL tổ 4'!BL$20+'KL VCKD chung'!#REF!+'KL tổ 10'!BE$22+#REF! -> #REF! | F11: =#REF!+'KL tổ 5'!BV$45+'KL tổ 4'!BM$20+'KL VCKD chung'!#REF!+'KL tổ 10'!BF$22+#REF! -> #REF! | G11: ='KL Tổ BVTX '!Q$15 -> 0 | H11: ='KL Tổ BVTX '!#REF! -> #REF! | I11: ='KL Tổ BVTX '!G$15 -> 0 | J11: ='KL Tổ BVTX '!#REF! -> #REF! | M11: ='KL Tổ BVTX '!AE$15 -> 0 | N11: ='KL Tổ BVTX '!#REF! -> #REF! | O11: ='KL Tổ BVTX '!AG$15 -> 0 | P11: ='KL Tổ BVTX '!#REF! -> #REF! | R11: ='KL Tổ BVTX '!AN$15 -> 0 | S11: ='KL Tổ BVTX '!AI$15 -> 0 | T11: ='KL Tổ BVTX '!#REF! -> #REF! | U11: ='KL Tổ BVTX '!O$15 -> 0 | V11: ='KL Tổ BVTX '!#REF! -> #REF! | X11: ='KL Tổ BVTX '!#REF! -> #REF! | Z11: ='KL Tổ BVTX '!#REF! -> #REF! | AC11: ='KL Tổ BVTX '!U$15 -> 0 | AD11: ='KL Tổ BVTX '!#REF! -> #REF! | AE11: =#REF! -> #REF! | AF11: =#REF! -> #REF! | AG11: ='KL Tổ BVTX '!BA$15+#REF!+'KL VCKD chung'!#REF! -> #REF! | AH11: ='KL Tổ BVTX '!#REF!+#REF!+'KL VCKD chung'!#REF! -> #REF! | AI11: ='KL Tổ BVTX '!K$15 -> 0 | AJ11: ='KL Tổ BVTX '!#REF! -> #REF!
A13: =34+104 -> 138
A16: Công tưới nước vườn ương + quản lý | C16: Vận chuyển nước xịt thuốc | E16: Công tài xế Kuzun | G16: Công tài xế máy cày | I16: Công giáo viên nhà trẻ | K16: Vận chuyển nước tưới cao su | M16: Công đưa rước công nhân | O16: Công vận chuyển cây làm hàng rào | Q16: Bắt câu cấu | S16: Phun thuốc trừ cỏ (6 công/ha) | U16: Bứng bầu cắt ngọn | W16: Xếp bầu | Y16: Đổi bầu | AA16: Bứng bầu tầng lá | AC16: Chặt cây cao không tháp được (1000 cây/công)
A17: Khối lượng | B17: Công | C17: Khối lượng | D17: Công | E17: Khối lượng | F17: Công | G17: Khối lượng | H17: Công | I17: Khối lượng | J17: Công | K17: Khối lượng | L17: Công | M17: Khối lượng | N17: Công | O17: Khối lượng | P17: Công | Q17: Khối lượng | R17: Công | S17: Khối lượng | T17: Công | U17: Khối lượng | V17: Công | W17: Khối lượng | X17: Công | Y17: Khối lượng | Z17: Công | AA17: Khối lượng | AB17: Công | AC17: Khối lượng | AD17: Công
B18: ='KL Tổ BVTX '!BH15 -> 0 | C18: ='KL tổ 9'!U$278 -> 0 | D18: ='KL tổ 9'!V$278 -> 0 | E18: ='KL Tổ BVTX '!#REF! -> #REF! | F18: ='KL Tổ BVTX '!#REF! -> #REF! | G18: ='KL Tổ BVTX '!#REF! -> #REF! | H18: ='KL Tổ BVTX '!#REF! -> #REF! | I18: =SUM('KL Tổ BVTX '!#REF!) -> #REF! | J18: =SUM('KL Tổ BVTX '!#REF!) -> #REF! | K18: ='KL tổ 9'!W$278 -> 0 | L18: ='KL tổ 9'!X$278 -> 0 | M18: ='KL tổ 9'!#REF! -> #REF! | N18: ='KL tổ 9'!#REF! -> #REF! | O18: ='KL tổ 9'!AA$278 -> 0 | P18: ='KL tổ 9'!AB$278 -> 0 | Q18: ='KL tổ 5'!V$45 -> 0 | R18: ='KL tổ 5'!W$45 -> 0 | S18: ='KL Tổ BVTX '!I$15 -> 0 | T18: ='KL Tổ BVTX '!#REF! -> #REF! | U18: ='KL Tổ BVTX '!AK$15+#REF!+'KL tổ 10'!AT$22+'KL VCKD chung'!#REF! -> #REF! | V18: ='KL Tổ BVTX '!#REF!+#REF!+'KL tổ 10'!AV$22+'KL VCKD chung'!#REF! -> #REF! | W18: ='KL Tổ BVTX '!AS$15+'KL tổ 4'!AK$20+#REF! -> #REF! | X18: ='KL Tổ BVTX '!#REF!+'KL tổ 4'!AN$20+#REF! -> #REF! | Y18: ='KL Tổ BVTX '!#REF!+'KL tổ 4'!#REF!+'KL VCKD chung'!#REF!+'KL tổ 10'!#REF!+#REF! -> #REF! | Z18: ='KL Tổ BVTX '!AR$15+'KL tổ 4'!Z$20+'KL VCKD chung'!#REF!+'KL tổ 10'!AN$22+#REF! -> #REF! | AA18: ='KL Tổ BVTX '!AO$15 -> 0 | AB18: ='KL Tổ BVTX '!#REF! -> #REF! | AC18: ='KL Tổ BVTX '!W$15 -> 0 | AD18: ='KL Tổ BVTX '!#REF! -> #REF!
A20: TỔNG CÔNG
D22: Từng tổ | F22: ='KL Tổ BVTX '!BR$15+#REF!+'KL tổ 5'!BW$45+'KL tổ 4'!BN$20+'KL VCKD chung'!Q$122+'KL tổ 10'!BG$22+#REF!+'KL tổ 9'!AC278 -> #REF!
H23: =F22-F24 -> #REF! | L23: 21706 | M23: =L23-V18 -> #REF! | S23: =#REF!+'KL tổ 5'!BW45+'KL tổ 3'!BR56+'KL tổ 4'!BN20+'KL VCKD chung'!Q122+'KL tổ 10'!BG22+#REF!+'KL tổ 9'!AC278+776+50 -> #REF! | U23: cc
F24: =B4+F4+J4+L4+P4+R4+T4+V4+X4+Z4+AB4+AD4+AF4+AJ4+B11+F11+J11+L11+P11+R11+T11+V11+X11+Z11+AB11+AF11+AJ11+B18+D18+F18+H18+J18+L18+N18+P18+R18+AD11+AH11+N4+AH4+N11+D11+T18+D4+H4+V18+X18+Z18+H11+AB18+AD18 -> #REF! | M24: =M23-F24 -> #REF! | R24: 2012 | T24: 2013 | U24: =#REF!+'KL tổ 5'!M45+'KL tổ 5'!O45+'KL tổ 3'!P56+'KL tổ 3'!T56+'KL tổ 4'!I20+'KL VCKD chung'!#REF!+'KL VCKD chung'!#REF!+'KL tổ 10'!L22+#REF! -> #REF! | W24: =708-355 -> 353
I25: =F22-I22 -> #REF! | Q25: tt | R25: =#REF!+'KL tổ 5'!E45+'KL tổ 3'!F56+'KL tổ 4'!D20+'KL VCKD chung'!#REF!+'KL tổ 10'!D22+#REF! -> #REF! | S25: tt | T25: ='KL tổ 5'!G45+'KL tổ 3'!I56+'KL VCKD chung'!#REF!+'KL tổ 10'!F22+#REF! -> #REF!
H26: =F22-I22 -> #REF! | L26: =L23-F22-V18 -> #REF! | R26: lc5c | T26: lc | X26: =621-410 -> 211
P27: =924+410 -> 1334 | Q27: =R25-R27 -> #REF! | R27: =ROUND(923.6*5,0) -> 4618 | T27: 959 | U27: =T27-691 -> 268

Sheet KL tổ 4
A1: CÔNG TY TNHH CAO SU MEKONG | M1: VƯƠNG QUỐC CAMPUCHIA
A2: ĐƠN VỊ: NÔNG TRƯỜNG II | M2: Dân tộc - Tôn giáo - Quốc vương
A4: BẢNG KHỐI LƯỢNG CÔNG NHÂN CAMPUCHIA TỔ 4
A5: THÁNG 12 NĂM 2016
A7: STT | B7: Họ và tên | D7: Làm cỏ đường băng (5,12 công/ha) | H7: Kiểm kê (1 công/ha) | J7: Bảo vệ thường xuyên (0,684 công/ha) | L7: Bảo vệ thường xuyên (0,93 công/ha) | N7: Lấp hố (1,97 công/ha) | P7: Trồng dặm (16,59 công/ha) | R7: Phúp bồn, tủ ẩm (17 công/ha) | T7: Lấp hố (0,1 công/ha) | V7: Làm điểm tập kết (0,5 công/ha) | X7: Trồng dặm (0,8 công/ha) | Z7: Quét vôi chống nắng (0,5 công/ha) | AB7: Phun thuốc BVTV diệt rệp (0,4 công/ha) | AD7: Cắt chồi ngang (0,35 công/ha) | AF7: Đào hố trồng dặm (25 hố/công) | AH7: Bón phân lót trồng mới (6,5 công/ha) | AJ7: Bón phân lấp hố cây trồng dặm (80 hố/công) | AL7: Bón phân lấp hố cây trồng dặm (61,67 hố/công) | AO7: Bón phân thúc (4,5 công/ha) | AQ7: Trồng dặm (30 cây/công) | AU7: Trồng dặm (25 cây/công) | AX7: Trồng dặm (27 cây/công) | BC7: Phúp bồn, tủ gốc (23 công/ha) | BE7: Cắt ngọn (800 bầu/công) | BG7: Bứng bầu (100 bầu/công) | BI7: Cắt chồi ngang (0,2 công/ha) | BK7: Xếp bầu (300 bầu/công) | BM7: Đổi bầu (150 bầu/công) | BO7: Làm cỏ vườn ương (35 công/ha) | BR7: Bốc phân xuống (0,4 công/ha) | BT7: Bốc phân lên + xuống (0,75 công/tấn) | BV7: Công tưới nước (1,33 công/ngày) | BX7: Công quản lý (100% x lương) | BZ7: Tổng công | CA7: Kí nhận
C8: Khối lượng | D8: Khối lượng | E8: Công | F8: Khối lượng | G8: Khối lượng | H8: Khối lượng | I8: Công | J8: Khối lượng | K8: Công | L8: Khối lượng | M8: Công | N8: Khối lượng | O8: Công | P8: Khối lượng | Q8: Công | R8: Khối lượng | S8: Công | T8: Khối lượng | U8: Công | V8: Khối lượng | W8: Công | X8: Khối lượng | Y8: Công | Z8: Khối lượng | AA8: Công | AB8: Khối lượng | AC8: Công | AD8: Khối lượng | AE8: Công | AF8: Khối lượng | AG8: Công | AH8: Khối lượng | AI8: Công | AJ8: Khối lượng | AK8: Công | AL8: Khối lượng | AM8: Công | AN8: Khối lượng | AO8: Khối lượng | AP8: Công | AQ8: Khối lượng | AR8: Công | AS8: Khối lượng | AT8: Khối lượng | AU8: Khối lượng | AV8: Công | AW8: Khối lượng | AX8: Khối lượng | AY8: Công | AZ8: Khối lượng | BA8: Khối lượng | BB8: Khối lượng | BC8: Khối lượng | BD8: Công | BE8: Khối lượng | BF8: Công | BG8: Khối lượng | BH8: Công | BI8: Khối lượng | BJ8: Công | BK8: Khối lượng | BL8: Công | BM8: Khối lượng | BN8: Công | BO8: Khối lượng | BP8: Khối lượng | BQ8: Công | BR8: Khối lượng | BS8: Công | BT8: Khối lượng | BU8: Công | BV8: Khối lượng | BW8: Công | BX8: Khối lượng | BY8: Công
A9: 1 | B9: Rat Non | C9: 0 | D9: 0 | E9: =ROUND(C9*5,2) -> 0 | F9: 0 | G9: 0 | H9: 0 | I9: =H9 -> 0 | J9: 0 | K9: =J9*0.684 -> 0 | L9: 0 | M9: =L9*0.93 -> 0 | N9: 0 | O9: =N9*1.97 -> 0 | P9: 0 | Q9: =P9*16.59 -> 0 | R9: 0 | S9: =R9*17 -> 0 | T9: 0 | U9: 0 | V9: 0 | W9: 0 | X9: 0 | Y9: =X9*0.8 -> 0 | Z9: 0 | AA9: 0 | AB9: 0 | AC9: 0 | AD9: 0 | AE9: =AD9*0.35 -> 0 | AF9: 0 | AG9: 0 | AH9: 0 | AI9: 0 | AJ9: 0 | AK9: 0 | AL9: 0 | AM9: =ROUND(AL9/70,2) -> 0 | AN9: 0 | AO9: 0 | AP9: =ROUND(AN9/70,2) -> 0 | AQ9: 0 | AR9: =ROUND(AQ9/35,2) -> 0 | AS9: 0 | AT9: 0 | AU9: 0 | AV9: =ROUND(AS9/35,2) -> 0 | AW9: 0 | AX9: 0 | AY9: 0 | AZ9: 0 | BA9: 0 | BB9: 0 | BC9: 0 | BD9: 0 | BE9: 0 | BF9: 0 | BG9: 0 | BH9: =ROUND(BG9/600,2) -> 0 | BI9: 0 | BJ9: 0 | BK9: 0 | BL9: 0 | BM9: 0 | BN9: =ROUND(BM9/350,2) -> 0 | BO9: 0 | BP9: 0 | BQ9: =ROUND(BO9/350,2) -> 0 | BR9: 0 | BS9: =ROUND(BR9*0.4,2) -> 0 | BT9: 0 | BU9: 0 | BV9: 0 | BW9: 0 | BX9: 0 | BY9: 0 | BZ9: =K9+M9+AC9+AE9+I9+Q9+U9+W9+Y9+S9+O9 -> 0 | CG9: 0
A10: 2 | B10: Dâm Vanh | C10: 0 | D10: =E10/5.12 -> 0 | E10: 0 | F10: 0 | G10: 0 | H10: 0 | I10: =H10 -> 0 | J10: 0 | K10: =J10*0.684 -> 0 | L10: 0 | M10: =L10*0.93 -> 0 | N10: 0 | O10: =N10*1.97 -> 0 | P10: 0 | Q10: =P10*16.59 -> 0 | R10: 0 | S10: =R10*17 -> 0 | T10: 0 | U10: =T10*0.1 -> 0 | V10: 0 | W10: =V10*0.5 -> 0 | X10: 0 | Y10: =X10*0.8 -> 0 | Z10: 0 | AA10: =Z10*0.5 -> 0 | AB10: 0 | AC10: =AB10*0.4 -> 0 | AD10: 0 | AE10: =AD10*0.35 -> 0 | AF10: 0 | AG10: =AF10/25 -> 0 | AH10: 0 | AI10: =AH10*6.5 -> 0 | AJ10: 0 | AK10: =AJ10/80 -> 0 | AL10: 0 | AM10: =AL10/61.67 -> 0 | AN10: 0 | AO10: 0 | AP10: =AO10*4.5 -> 0 | AQ10: 0 | AR10: =AQ10/30 -> 0 | AS10: 0 | AT10: 0 | AU10: 0 | AV10: =AU10/25 -> 0 | AW10: 0 | AX10: =AW10*27/30 -> 0 | AY10: =AX10/27 -> 0 | AZ10: 0 | BA10: 0 | BB10: 0 | BC10: =AZ10*600/663.06/555 -> 0 | BD10: =BC10*23 -> 0 | BE10: 0 | BF10: =BE10/800 -> 0 | BG10: 0 | BH10: =BG10/100 -> 0 | BI10: 0 | BJ10: =BI10*0.2 -> 0 | BK10: 0 | BL10: =BK10/300 -> 0 | BM10: 0 | BN10: =BM10/150 -> 0 | BO10: 0 | BP10: =BO10*33/35 -> 0 | BQ10: =BP10*35 -> 0 | BR10: 0 | BS10: =ROUND(BR10*0.4,2) -> 0 | BT10: 0 | BU10: =BT10*0.75 -> 0 | BV10: 0 | BW10: =BV10*1.3333333333 -> 0 | BX10: 0 | BY10: =ROUND(BX10*1.43,2) -> 0 | BZ10: =K10+M10+AC10+AE10+I10+Q10+U10+W10+Y10+S10+O10 -> 0 | CG10: 0
A11: 3 | B11: Sa Mêt | H11: 0 | I11: =H11 -> 0 | J11: 0 | K11: =J11*0.684 -> 0 | L11: 0 | M11: =L11*0.93 -> 0 | N11: 0 | O11: =N11*1.97 -> 0 | P11: 0 | Q11: =P11*16.59 -> 0 | R11: 0 | S11: =R11*17 -> 0 | T11: 0 | U11: =T11*0.1 -> 0 | V11: 0 | W11: =V11*0.5 -> 0 | X11: 0 | Y11: =X11*0.8 -> 0 | Z11: 0 | AA11: =Z11*0.5 -> 0 | AB11: 0 | AC11: =AB11*0.4 -> 0 | AD11: 0 | AE11: =AD11*0.35 -> 0 | AF11: 0 | AG11: =AF11/25 -> 0 | AH11: 0 | AI11: =AH11*6.5 -> 0 | AJ11: 0 | AK11: =AJ11/80 -> 0 | AL11: 0 | AM11: =AL11/61.67 -> 0 | AN11: 0 | AO11: 0 | AP11: =AO11*4.5 -> 0 | AQ11: 0 | AR11: =AQ11/30 -> 0 | AS11: 0 | AT11: 0 | AU11: 0 | AV11: =AU11/25 -> 0 | AW11: 0 | AX11: =AW11*27/30 -> 0 | AY11: =AX11/27 -> 0 | AZ11: 0 | BA11: 0 | BB11: 0 | BC11: =AZ11*600/663.06/555 -> 0 | BD11: =BC11*23 -> 0 | BE11: 0 | BF11: =BE11/800 -> 0 | BG11: 0 | BH11: =BG11/100 -> 0 | BI11: 0 | BJ11: =BI11*0.2 -> 0 | BK11: 0 | BL11: =BK11/300 -> 0 | BM11: 0 | BN11: =BM11/150 -> 0 | BO11: 0 | BP11: =BO11*33/35 -> 0 | BQ11: =BP11*35 -> 0 | BR11: 0 | BS11: =ROUND(BR11*0.4,2) -> 0 | BT11: 0 | BU11: =BT11*0.75 -> 0 | BV11: 0 | BW11: =BV11*1.3333333333 -> 0 | BX11: 0 | BY11: =ROUND(BX11*1.43,2) -> 0 | BZ11: =K11+M11+AC11+AE11+I11+Q11+U11+W11+Y11+S11+O11 -> 0
