Workbook

Sheet PTL VCKD 1
D1: ព្រះរាជាណាចក្រកម្ពុជា
A2: ក្រុមហ៊ុន កៅស៊ូ មេគង្គ ខូអិលធីឌី | D2: VƯƠNG QUỐC CAMPUCHIA
A3: Caoutchouc Mekong Co., Ltd | D3: ជាតិ សាសនា ព្រះមហាក្សត្រ
A4: អង្គភាព: កសិដ្ឋាន II | D4: Dân tộc - Tôn giáo - Quốc vương
A5: Đơn vị: Đội sản xuất 2
A7: តារាងបែងចែកប្រាក់បៀវត្សកម្មករ​ប្រមូលផល
A8: វត្សទី ២ ខែ ០១ ឆ្នាំ ២០២៦
A9: BẢNG PHÂN TOÁN LƯƠNG CÔNG NHÂN VƯỜN CÂY KINH DOANH
A10: THÁNG 01 NĂM 2026 ĐỢT 2
F12: ឯកតា (ĐVT)៖ KHR
A13: ល.រ | B13: រាយនាមការងារ | C13: តម្លៃ | D13: ជាកម្លាំង | F13: ជាប្រាក់ | G13: ចំណាំ
A14: STT | B14: Hạng mục công việc | C14: Đơn giá | D14: Quy công | E14: Công làm thêm giờ | F14: Thành tiền | G14: Ghi chú | I14: កំណត់
A15: A. | B15: ចំការកៅស៊ូ (VƯỜN CÂY) | D15: =#REF!+#REF!+#REF!+D17+#REF!+D25 -> #REF! | E15: 0 | F15: =ROUND(D15*#REF!,-2)+300 -> #REF!
A16: I. | B16: អាជីវកម្មក្រុមទី​ ១ /KD NHÓM 1 (2795,2,ha) | C16: 31947 | D16: =SUM(D17:D25) -> 18026.7 | F16: =ROUND(D16*C16,0) -> 575898985
A17: 1 | B17: ការពារភ្លើងឆេះ + យាមភ្លើង/Phòng chống cháy + gác lửa | C17: 31947 | F17: =ROUND(C17*D17,0) -> 0 | H17: =347-370.3 -> -23.3
A18: 3 | B18: បែងចែកផ្ទាំងចៀរ BO-2.1/Thiết kế mặt cạo BO- 2.1 | C18: 31947 | F18: =ROUND(C18*D18,0) -> 0
A19: 4 | B19: បំពាក់ឧបករណ៍ កង, ចាន BO-2.1/Trang bị kiềng chén mặt cạo BO-2.1 | C19: 31947 | F19: =ROUND(C19*D19,0) -> 0
A20: 3 | B20: បាញ់ថ្នាំស្មៅ/Xịt chồi dại | C20: 31947 | F20: =ROUND(C20*D20,0) -> 0
A21: 1 | B21: ជម្រះស្មៅចន្លោះរង/Phát cỏ luồng | C21: 31947 | D21: 570.1 | F21: =ROUND(C21*D21,0) -> 18212985
A22: 2 | B22: ការពារភ្លើងឆេះ + យាមភ្លើង/Phòng chống cháy + gác lửa | C22: 31947 | D22: 1302.1 | F22: =ROUND(C22*D22,0) -> 41598189
A23: 3 | B23: ជំរឿនដើមកៅស៊ូនៅដើមរដូវចៀរ/Kiểm kê cây cao su đầu vụ cạo | C23: 31947 | D23: 3354.2 | F23: =ROUND(C23*D23,0) -> 107156627
A24: 4 | B24: ជៀ សានិងប្រគូលជ័រ/ Cạo trút và giao nộp mủ | C24: 31947 | D24: 12182.6 | F24: =ROUND(C24*D24,0) -> 389197522
A25: 5 | B25: សន្តិសុខការពារចំការ/Bảo vệ vườn cây | C25: 31947 | D25: 617.7 | F25: =ROUND(C25*D25,0) -> 19733662 | H25: =434.5/16 -> 27.15625
A26: 1 | B26: បង្ការព្យាបាលជម្ងឺ/Phòng trị bệnh | C26: 30456 | F26: =ROUND(C26*D26,0) -> 0
A27: 1 | B27: លាបថ្នាំរំញោច/Bôi thuốc kích thích | C27: 30456 | F27: =ROUND(C27*D27,0) -> 0
A28: 3 | B28: បើកមុខចៀរជ័រដំបូង ដោតស្លាបព្រា​និងទគម្របចាន/Cạo xã miệng,đóng máng, gắn máy che chén | C28: 30456 | F28: =ROUND(C28*D28,0) -> 0
A29: 2 | B29: ជៀ សានិងប្រគូលជ័រ/ Cạo trút và giao nộp mủ | C29: 30456 | F29: =ROUND(C29*D29,0) -> 0
A30: 3 | B30: សន្តិសុខការពារចំការ/Bảo vệ vườn cây | C30: 30456 | F30: =ROUND(C30*D30,0) -> 0 | H30: =57.8/2 -> 28.9
A31: សរុប (Tổng công) | D31: =D16 -> 18026.7 | F31: =F16 -> 575898985
A32: ប្រាក់អតិតភាព/ Tiền thâm niên
A33: Tiền lương BS tháng 13
A34: សរុប (Tổng cộng) | E34: =ROUND(#REF!*C34,0) -> #REF! | F34: =F31+F32 -> 575898985 | H34: =ROUND(#REF!*F34,0) -> #REF! | I34: =ROUND(#REF!*G34,0) -> #REF! | J34: =ROUND(#REF!*H34,0) -> #REF! | K34: =ROUND(#REF!*I34,0) -> #REF! | L34: =ROUND(#REF!*J34,0) -> #REF! | M34: =ROUND(#REF!*K34,0) -> #REF! | N34: =ROUND(#REF!*L34,0) -> #REF! | O34: =ROUND(#REF!*M34,0) -> #REF! | ... BN34: =ROUND(#REF!*BL34,0) -> #REF! | BO34: =ROUND(BL34*BM34,0) -> #REF! | BP34: =ROUND(BM34*BN34,0) -> #REF! | BQ34: =ROUND(BN34*BO34,0) -> #REF! | BR34: =ROUND(BO34*BP34,0) -> #REF! | BS34: =ROUND(BP34*BQ34,0) -> #REF! | BT34: =ROUND(BQ34*BR34,0) -> #REF! | BU34: =ROUND(BR34*BS34,0) -> #REF! | BV34: =ROUND(BS34*BT34,0) -> #REF! | ... XFD34: =ROUND(XFA34*XFB34,0) -> #REF!
A36: (ជាអក្សរ៖ប្រាំរយចែតសិបប្រាំលាន ប្រាំបីរយកៅសិបប្រាំបីពាន់ ប្រាំបួនរយប៉ែតសិបប្រាំរៀលគត់។ | H36: (ជាអក្សរ៖ដប់បួនលានប្រាំរយម៉ាពីប្រាំបីពាន់ចែតសិបប្រាំបួនរៀលគត់។)
A37: Bằng chữ: Năm trăm bảy mươi lăm triệu tám trăm chín mươi tám ngàn chín trăm tám mươi lăm riel chẵn
A39: ​
B40: អង្គភាពអនុវត្ត -ĐƠN VỊ THỰC HIỆN | D40: អ្នករៀបចំ -NGƯỜI LẬP BIỂU
B43: Nguyễn Vũ Minh | D43: Kim Thảo
B45: ផែ្នក រដ្ឋបាល-PHÒNG TCHC | D45: ផ្នែក គណនេយ្យ -PHÒNG TCKT
A50: អនុម័តនាយកក្រុមហ៊ុន
A51: DUYỆT
...

Sheet CDCN- VCKD
A1: ក្រុមហ៊ុន កៅស៊ូ មេគង្គ ខូអិលធីឌី | F1: ព្រះរាជាណាចក្រកម្ពុជា
A2: Caoutchouc Mekong Co., Ltd | F2: VƯƠNG QUỐC CAMPUCHIA
A3: អង្គភាព: ក្រុមផលិត II | F3: ជាតិ សាសនា ព្រះមហាក្សត្រ
A4: Đơn vị: Đội sản xuất 2 | F4: Dân tộc - Tôn giáo - Quốc vương
A6: តារាងតុល្យភាពបំណុលបៀវត្ស​ កម្មកប្រមូលផល
A7: វត្សទី ២ ខែ ០១ ឆ្នាំ ២០២៦
A8: BẢNG CÂN ĐỐI CÔNG NỢ LƯƠNG​ CÔNG NHÂN VƯỜN CÂY KINH DOANH
A9: ĐỢT 2 THÁNG 01 NĂM 2026
B11: I/ សរុបបៀវត្សខែ 01/2026 (Tổng lương tháng 01/2026)៖ | G11: =SUM(G12:G16) -> 885874337 | H11: KHR | I11: 1016.1
B12: 1/ ប្រាក់បៀវត្សទី ១ (Tiền lương đợt 1) ៖ | G12: ='TTTL VCKD'!R604 -> 309975352 | H12: KHR | I12: 1810.666
B13: 2/ ប្រាក់បៀវត្សទី ២ (Tiền lương đợt 2) ៖ | G13: ='TTTL VCKD'!H604 -> 575898985 | H13: KHR | I13: 1716.246
B14: 3/ Tiền lương tháng 13 | G14: ='TTTL VCKD'!T604 -> 0 | H14: KHR
B15: 4/ Tiền thưởng đầu vụ cạo | G15: ='TTTL VCKD'!U604 -> 0 | H15: KHR
B16: 3/ប្រាក់អតិតភាពពី ខែ ៧ -១២ ឆ្នាំ ២០២៥ (Lương thâm niên 6 tháng cuối năm 2025) ៖ | G16: ='TTTL VCKD'!S604 -> 0 | H16: KHR
B17: II/ ប្រាក់បានទទួល (Các khoản đã nhận) ៖ | G17: =G18+G19 -> 309975352 | H17: KHR | I17: 2120.926
B18: 1/ទូទាត់ប្រាក់បៀវត្សលើកទី ១ (Thanh toán lương đợt 1) ៖ | G18: 0 | H18: KHR | I18: 2697.762
B19: 2/បុរេប្រប្រាក់បៀវត្សថ្ងៃចេញកម្លាំងចៀរ ( Ứng tiền lễ ra quân) ៖ | G19: ='TTTL VCKD'!X604 -> 309975352 | H19: KHR
B20: III/ប្រាក់ត្រូវប្រមូល (Các khoản phải thu) ៖ | G20: =G21+G22+G23 -> 14956159 | H20: KHR
B21: 1/ពន្ធលើប្រាក់បៀវត្ស (Thuế TNCN)៖ | G21: ='TTTL VCKD'!Y604 -> 825743 | H21: KHR
B22: 2/បុរេប្រទានខ្លួន(Tạm ứng cá nhân) ៖ | G22: 0 | H22: KHR
B23: 3/ ភាគទានប្រាក់សោធន (BHXH): | G23: ='TTTL VCKD'!Z604 -> 14130416 | H23: KHR
B24: IV/ប្រាក់ត្រូវទទួល (Thực nhận)៖ | G24: =SUM(G25:G25) -> 560942826 | H24: KHR
B25: 1/ប្រាក់បៀវត្សត្រូវទទួល (Tiền lương thực nhận) ៖ | G25: =G11-G17-G20 -> 560942826 | H25: KHR
A28: (ជាអក្សរ៖ប្រាំរយហុកសិបលាន ប្រាំបួនរយសែសិបពីរពាន់ ប្រាំបីរយម្ភៃប្រាំមួយរៀលគត់។ | I28: =SUM(I11:I27) -> 9361.7
A29: Bằng chữ: Năm trăm sáu mươi triệu chín trăm bốn mươi hai ngàn tám trăm hai mươi sáu riel chẵn
D31: Prasat Balang, ថ្ងៃ /ngày ខែ​/tháng ឆ្នាំ/năm 2026
A32: ផ្នែក គណនេយ្យ | D32: ក្រុមផលិត ២ | G32: អ្នករៀបចំ
A33: PHÒNG TCKT | D33: ĐỘI SẢN XUẤT II | G33: NGƯỜI LẬP BIỂU
D37: Nguyễn Vũ Minh | G37: Kim Thảo
D39: អនុម័តនាយកក្រុមហ៊ុន
D40: DUYỆT
D41: GIÁM ĐỐC

Sheet Kiểm tra
A1: KIỂM TRA
A2: Làm cỏ đường băng (7 công/ha) | C2: Làm cỏ đường băng (5 công/ha) | E2: Làm cỏ đường băng (3,5 công/ha) | G2: Làm cỏ đậu Kudzu (4 công/ha) | I2: Làm cỏ bồn (4 công/ha) | K2: Làm cỏ bồn (3,5 công/ha) | M2: Làm cỏ ranh chống cháy (300 m2/công) | O2: Phát cỏ luồng (3 công/ha) | Q2: Phòng chống cháy (1,08 công/ha) | S2: Phát dọn chống cháy (0,54 công/ha) | U2: Phát cỏ luồng (1 công/ha) | W2: Chặt nọc cắm cây cao su trồng dặm | Y2: Phun thuốc cỏ đường băng (1,56 công/ha) | AA2: Xịt phân Komix nước bón lá (0,2 công/ha) | AC2: Cắt chồi ngang (0,2 công/ha) | AE2: Đào mương | AG2: Phun thuốc BVTV diệt câu cấu | AI2: Xịt thuốc BVTV diệt rệp (0,4 công/ha)
A3: Khối lượng | B3: Công | C3: Khối lượng | D3: Công | E3: Khối lượng | F3: Công | G3: Khối lượng | H3: Công | I3: Khối lượng | J3: Công | K3: Khối lượng | L3: Công | M3: Khối lượng | N3: Công | O3: Khối lượng | P3: Công | Q3: Khối lượng | R3: Công | S3: Khối lượng | T3: Công | U3: Khối lượng | V3: Công | W3: Khối lượng | X3: Công | Y3: Khối lượng | Z3: Công | AA3: Khối lượng | AB3: Công | AC3: Khối lượng | AD3: Công | AE3: Khối lượng | AF3: Công | AG3: Khối lượng | AH3: Công | AI3: Khối lượng | AJ3: Công
Q4: ='KL Tổ BVTX '!BI$15 -> 0 | R4: ='KL Tổ BVTX '!BJ$15 -> 0 | U4: ='KL Tổ BVTX '!#REF!+'KL tổ 5'!R$45+'KL tổ 10'!#REF!+#REF!+'KL VCKD'!#REF! -> #REF! | V4: ='KL Tổ BVTX '!#REF!+'KL tổ 5'!S$45+'KL tổ 10'!V$22+#REF!+'KL VCKD'!#REF! -> #REF! | W4: ='KL tổ 10'!O$22+#REF! -> #REF! | X4: ='KL tổ 10'!P$22+#REF! -> #REF! | AE4: ='KL tổ 10'!AK$22+#REF! -> #REF! | AF4: ='KL tổ 10'!AL$22+#REF! -> #REF! | AG4: =#REF! -> #REF! | AH4: =#REF! -> #REF! | AI4: =#REF!+'KL tổ 10'!S$22 -> #REF! | AJ4: =#REF!+'KL tổ 10'!T$22 -> #REF!
AI6: 878.2
U7: 132.2
A9: Công tưới nước cao su | C9: Khoanh bồn tủ cỏ (130 bồn/công) | E9: Công quản lý (Tổ trưởng) | G9: Bón phân thúc vườn ương | I9: Làm mái che cao su | K9: Gác trâu | M9: Thiết kế súng tưới | O9: Sang bầu | Q9: Làm hàng rào | S9: Tưới nước | U9: Tưới phân vườn âm bầu | W9: Làm cỏ vườn ươm | Y9: Tưới nước vườn âm bầu | AA9: Phòng chống cháy - chống thú | AC9: Vệ sinh vườn âm bầu | AE9: Cắt ngọn cao su | AG9: Bốc bầu xuống xe (600 bầu/công) | AI9: Phun thuốc Vixazol vườn ương
A10: Khối lượng | B10: Công | C10: Khối lượng | D10: Công | E10: Khối lượng | F10: Công | G10: Khối lượng | H10: Công | I10: Khối lượng | J10: Công | K10: Khối lượng | L10: Công | M10: Khối lượng | N10: Công | O10: Khối lượng | P10: Công | Q10: Khối lượng | R10: Công | S10: Khối lượng | T10: Công | U10: Khối lượng | V10: Công | W10: Khối lượng | X10: Công | Y10: Khối lượng | Z10: Công | AA10: Khối lượng | AB10: Công | AC10: Khối lượng | AD10: Công | AE10: Khối lượng | AF10: Công | AG10: Khối lượng | AH10: Công | AI10: Khối lượng | AJ10: Công
A11: ='KL Tổ BVTX '!BE$15+'KL tổ 5'!BO$45+'KL tổ 4'!BJ$20+'KL VCKD'!#REF!+'KL tổ 10'!BA$22+#REF! -> #REF! | B11: ='KL Tổ BVTX '!#REF!+'KL tổ 5'!BR$45+'KL tổ 4'!BK$20+'KL VCKD'!#REF!+'KL tổ 10'!BB$22+#REF! -> #REF! | C11: ='KL tổ 10'!Q$22 -> 0 | D11: ='KL tổ 10'!R$22 -> 0 | E11: =#REF!+'KL tổ 5'!BU$45+'KL tổ 4'!BL$20+'KL VCKD'!#REF!+'KL tổ 10'!BE$22+#REF! -> #REF! | F11: =#REF!+'KL tổ 5'!BV$45+'KL tổ 4'!BM$20+'KL VCKD'!#REF!+'KL tổ 10'!BF$22+#REF! -> #REF! | G11: ='KL Tổ BVTX '!Q$15 -> 0 | H11: ='KL Tổ BVTX '!#REF! -> #REF! | I11: ='KL Tổ BVTX '!G$15 -> 0 | J11: ='KL Tổ BVTX '!#REF! -> #REF! | M11: ='KL Tổ BVTX '!AE$15 -> 0 | N11: ='KL Tổ BVTX '!#REF! -> #REF! | O11: ='KL Tổ BVTX '!AG$15 -> 0 | P11: ='KL Tổ BVTX '!#REF! -> #REF! | R11: ='KL Tổ BVTX '!AN$15 -> 0 | S11: ='KL Tổ BVTX '!AI$15 -> 0 | T11: ='KL Tổ BVTX '!#REF! -> #REF! | U11: ='KL Tổ BVTX '!O$15 -> 0 | V11: ='KL Tổ BVTX '!#REF! -> #REF! | X11: ='KL Tổ BVTX '!#REF! -> #REF! | Z11: ='KL Tổ BVTX '!#REF! -> #REF! | AC11: ='KL Tổ BVTX '!U$15 -> 0 | AD11: ='KL Tổ BVTX '!#REF! -> #REF! | AE11: =#REF! -> #REF! | AF11: =#REF! -> #REF! | AG11: ='KL Tổ BVTX '!BA$15+#REF!+'KL VCKD'!#REF! -> #REF! | AH11: ='KL Tổ BVTX '!#REF!+#REF!+'KL VCKD'!#REF! -> #REF! | AI11: ='KL Tổ BVTX '!K$15 -> 0 | AJ11: ='KL Tổ BVTX '!#REF! -> #REF!
A13: =34+104 -> 138
A16: Công tưới nước vườn ương + quản lý | C16: Vận chuyển nước xịt thuốc | E16: Công tài xế Kuzun | G16: Công tài xế máy cày | I16: Công giáo viên nhà trẻ | K16: Vận chuyển nước tưới cao su | M16: Công đưa rước công nhân | O16: Công vận chuyển cây làm hàng rào | Q16: Bắt câu cấu | S16: Phun thuốc trừ cỏ (6 công/ha) | U16: Bứng bầu cắt ngọn | W16: Xếp bầu | Y16: Đổi bầu | AA16: Bứng bầu tầng lá | AC16: Chặt cây cao không tháp được (1000 cây/công)
A17: Khối lượng | B17: Công | C17: Khối lượng | D17: Công | E17: Khối lượng | F17: Công | G17: Khối lượng | H17: Công | I17: Khối lượng | J17: Công | K17: Khối lượng | L17: Công | M17: Khối lượng | N17: Công | O17: Khối lượng | P17: Công | Q17: Khối lượng | R17: Công | S17: Khối lượng | T17: Công | U17: Khối lượng | V17: Công | W17: Khối lượng | X17: Công | Y17: Khối lượng | Z17: Công | AA17: Khối lượng | AB17: Công | AC17: Khối lượng | AD17: Công
B18: ='KL Tổ BVTX '!BH15 -> 0 | C18: ='KL tổ 9'!U$278 -> 0 | D18: ='KL tổ 9'!V$278 -> 0 | E18: ='KL Tổ BVTX '!#REF! -> #REF! | F18: ='KL Tổ BVTX '!#REF! -> #REF! | G18: ='KL Tổ BVTX '!#REF! -> #REF! | H18: ='KL Tổ BVTX '!#REF! -> #REF! | I18: =SUM('KL Tổ BVTX '!#REF!) -> #REF! | J18: =SUM('KL Tổ BVTX '!#REF!) -> #REF! | K18: ='KL tổ 9'!W$278 -> 0 | L18: ='KL tổ 9'!X$278 -> 0 | M18: ='KL tổ 9'!#REF! -> #REF! | N18: ='KL tổ 9'!#REF! -> #REF! | O18: ='KL tổ 9'!AA$278 -> 0 | P18: ='KL tổ 9'!AB$278 -> 0 | Q18: ='KL tổ 5'!V$45 -> 0 | R18: ='KL tổ 5'!W$45 -> 0 | S18: ='KL Tổ BVTX '!I$15 -> 0 | T18: ='KL Tổ BVTX '!#REF! -> #REF! | U18: ='KL Tổ BVTX '!AK$15+#REF!+'KL tổ 10'!AT$22+'KL VCKD'!#REF! -> #REF! | V18: ='KL Tổ BVTX '!#REF!+#REF!+'KL tổ 10'!AV$22+'KL VCKD'!#REF! -> #REF! | W18: ='KL Tổ BVTX '!AS$15+'KL tổ 4'!AK$20+#REF! -> #REF! | X18: ='KL Tổ BVTX '!#REF!+'KL tổ 4'!AN$20+#REF! -> #REF! | Y18: ='KL Tổ BVTX '!#REF!+'KL tổ 4'!#REF!+'KL VCKD'!#REF!+'KL tổ 10'!#REF!+#REF! -> #REF! | Z18: ='KL Tổ BVTX '!AR$15+'KL tổ 4'!Z$20+'KL VCKD'!#REF!+'KL tổ 10'!AN$22+#REF! -> #REF! | AA18: ='KL Tổ BVTX '!AO$15 -> 0 | AB18: ='KL Tổ BVTX '!#REF! -> #REF! | AC18: ='KL Tổ BVTX '!W$15 -> 0 | AD18: ='KL Tổ BVTX '!#REF! -> #REF!
A20: TỔNG CÔNG
D22: Từng tổ | F22: ='KL Tổ BVTX '!BR$15+#REF!+'KL tổ 5'!BW$45+'KL tổ 4'!BN$20+'KL VCKD'!BE$182+'KL tổ 10'!BG$22+#REF!+'KL tổ 9'!AC278 -> #REF!
H23: =F22-F24 -> #REF! | L23: 21706 | M23: =L23-V18 -> #REF! | S23: =#REF!+'KL tổ 5'!BW45+'KL tổ 3'!BR56+'KL tổ 4'!BN20+'KL VCKD'!BE182+'KL tổ 10'!BG22+#REF!+'KL tổ 9'!AC278+776+50 -> #REF! | U23: cc
F24: =B4+F4+J4+L4+P4+R4+T4+V4+X4+Z4+AB4+AD4+AF4+AJ4+B11+F11+J11+L11+P11+R11+T11+V11+X11+Z11+AB11+AF11+AJ11+B18+D18+F18+H18+J18+L18+N18+P18+R18+AD11+AH11+N4+AH4+N11+D11+T18+D4+H4+V18+X18+Z18+H11+AB18+AD18 -> #REF! | M24: =M23-F24 -> #REF! | R24: 2012 | T24: 2013 | U24: =#REF!+'KL tổ 5'!M45+'KL tổ 5'!O45+'KL tổ 3'!P56+'KL tổ 3'!T56+'KL tổ 4'!I20+'KL VCKD'!Z182+'KL VCKD'!#REF!+'KL tổ 10'!L22+#REF! -> #REF! | W24: =708-355 -> 353
I25: =F22-I22 -> #REF! | Q25: tt | R25: =#REF!+'KL tổ 5'!E45+'KL tổ 3'!F56+'KL tổ 4'!D20+'KL VCKD'!#REF!+'KL tổ 10'!D22+#REF! -> #REF! | S25: tt | T25: ='KL tổ 5'!G45+'KL tổ 3'!I56+'KL VCKD'!#REF!+'KL tổ 10'!F22+#REF! -> #REF!
H26: =F22-I22 -> #REF! | L26: =L23-F22-V18 -> #REF! | R26: lc5c | T26: lc | X26: =621-410 -> 211
P27: =924+410 -> 1334 | Q27: =R25-R27 -> #REF! | R27: =ROUND(923.6*5,0) -> 4618 | T27: 959 | U27: =T27-691 -> 268

Sheet KL tổ 4
A1: CÔNG TY TNHH CAO SU MEKONG | M1: VƯƠNG QUỐC CAMPUCHIA
A2: ĐƠN VỊ: NÔNG TRƯỜNG II | M2: Dân tộc - Tôn giáo - Quốc vương
A4: BẢNG KHỐI LƯỢNG CÔNG NHÂN CAMPUCHIA TỔ 4
A5: THÁNG 12 NĂM 2016
A7: STT | B7: Họ và tên | D7: Làm cỏ đường băng (5,12 công/ha) | H7: Kiểm kê (1 công/ha) | J7: Bảo vệ thường xuyên (0,684 công/ha) | L7: Bảo vệ thường xuyên (0,93 công/ha) | N7: Lấp hố (1,97 công/ha) | P7: Trồng dặm (16,59 công/ha) | R7: Phúp bồn, tủ ẩm (17 công/ha) | T7: Lấp hố (0,1 công/ha) | V7: Làm điểm tập kết (0,5 công/ha) | X7: Trồng dặm (0,8 công/ha) | Z7: Quét vôi chống nắng (0,5 công/ha) | AB7: Phun thuốc BVTV diệt rệp (0,4 công/ha) | AD7: Cắt chồi ngang (0,35 công/ha) | AF7: Đào hố trồng dặm (25 hố/công) | AH7: Bón phân lót trồng mới (6,5 công/ha) | AJ7: Bón phân lấp hố cây trồng dặm (80 hố/công) | AL7: Bón phân lấp hố cây trồng dặm (61,67 hố/công) | AO7: Bón phân thúc (4,5 công/ha) | AQ7: Trồng dặm (30 cây/công) | AU7: Trồng dặm (25 cây/công) | AX7: Trồng dặm (27 cây/công) | BC7: Phúp bồn, tủ gốc (23 công/ha) | BE7: Cắt ngọn (800 bầu/công) | BG7: Bứng bầu (100 bầu/công) | BI7: Cắt chồi ngang (0,2 công/ha) | BK7: Xếp bầu (300 bầu/công) | BM7: Đổi bầu (150 bầu/công) | BO7: Làm cỏ vườn ương (35 công/ha) | BR7: Bốc phân xuống (0,4 công/ha) | BT7: Bốc phân lên + xuống (0,75 công/tấn) | BV7: Công tưới nước (1,33 công/ngày) | BX7: Công quản lý (100% x lương) | BZ7: Tổng công | CA7: Kí nhận
C8: Khối lượng | D8: Khối lượng | E8: Công | F8: Khối lượng | G8: Khối lượng | H8: Khối lượng | I8: Công | J8: Khối lượng | K8: Công | L8: Khối lượng | M8: Công | N8: Khối lượng | O8: Công | P8: Khối lượng | Q8: Công | R8: Khối lượng | S8: Công | T8: Khối lượng | U8: Công | V8: Khối lượng | W8: Công | X8: Khối lượng | Y8: Công | Z8: Khối lượng | AA8: Công | AB8: Khối lượng | AC8: Công | AD8: Khối lượng | AE8: Công | AF8: Khối lượng | AG8: Công | AH8: Khối lượng | AI8: Công | AJ8: Khối lượng | AK8: Công | AL8: Khối lượng | AM8: Công | AN8: Khối lượng | AO8: Khối lượng | AP8: Công | AQ8: Khối lượng | AR8: Công | AS8: Khối lượng | AT8: Khối lượng | AU8: Khối lượng | AV8: Công | AW8: Khối lượng | AX8: Khối lượng | AY8: Công | AZ8: Khối lượng | BA8: Khối lượng | BB8: Khối lượng | BC8: Khối lượng | BD8: Công | BE8: Khối lượng | BF8: Công | BG8: Khối lượng | BH8: Công | BI8: Khối lượng | BJ8: Công | BK8: Khối lượng | BL8: Công | BM8: Khối lượng | BN8: Công | BO8: Khối lượng | BP8: Khối lượng | BQ8: Công | BR8: Khối lượng | BS8: Công | BT8: Khối lượng | BU8: Công | BV8: Khối lượng | BW8: Công | BX8: Khối lượng | BY8: Công
A9: 1 | B9: Rat Non | C9: 0 | D9: 0 | E9: =ROUND(C9*5,2) -> 0 | F9: 0 | G9: 0 | H9: 0 | I9: =H9 -> 0 | J9: 0 | K9: =J9*0.684 -> 0 | L9: 0 | M9: =L9*0.93 -> 0 | N9: 0 | O9: =N9*1.97 -> 0 | P9: 0 | Q9: =P9*16.59 -> 0 | R9: 0 | S9: =R9*17 -> 0 | T9: 0 | U9: 0 | V9: 0 | W9: 0 | X9: 0 | Y9: =X9*0.8 -> 0 | Z9: 0 | AA9: 0 | AB9: 0 | AC9: 0 | AD9: 0 | AE9: =AD9*0.35 -> 0 | AF9: 0 | AG9: 0 | AH9: 0 | AI9: 0 | AJ9: 0 | AK9: 0 | AL9: 0 | AM9: =ROUND(AL9/70,2) -> 0 | AN9: 0 | AO9: 0 | AP9: =ROUND(AN9/70,2) -> 0 | AQ9: 0 | AR9: =ROUND(AQ9/35,2) -> 0 | AS9: 0 | AT9: 0 | AU9: 0 | AV9: =ROUND(AS9/35,2) -> 0 | AW9: 0 | AX9: 0 | AY9: 0 | AZ9: 0 | BA9: 0 | BB9: 0 | BC9: 0 | BD9: 0 | BE9: 0 | BF9: 0 | BG9: 0 | BH9: =ROUND(BG9/600,2) -> 0 | BI9: 0 | BJ9: 0 | BK9: 0 | BL9: 0 | BM9: 0 | BN9: =ROUND(BM9/350,2) -> 0 | BO9: 0 | BP9: 0 | BQ9: =ROUND(BO9/350,2) -> 0 | BR9: 0 | BS9: =ROUND(BR9*0.4,2) -> 0 | BT9: 0 | BU9: 0 | BV9: 0 | BW9: 0 | BX9: 0 | BY9: 0 | BZ9: =K9+M9+AC9+AE9+I9+Q9+U9+W9+Y9+S9+O9 -> 0 | CG9: 0
A10: 2 | B10: Dâm Vanh | C10: 0 | D10: =E10/5.12 -> 0 | E10: 0 | F10: 0 | G10: 0 | H10: 0 | I10: =H10 -> 0 | J10: 0 | K10: =J10*0.684 -> 0 | L10: 0 | M10: =L10*0.93 -> 0 | N10: 0 | O10: =N10*1.97 -> 0 | P10: 0 | Q10: =P10*16.59 -> 0 | R10: 0 | S10: =R10*17 -> 0 | T10: 0 | U10: =T10*0.1 -> 0 | V10: 0 | W10: =V10*0.5 -> 0 | X10: 0 | Y10: =X10*0.8 -> 0 | Z10: 0 | AA10: =Z10*0.5 -> 0 | AB10: 0 | AC10: =AB10*0.4 -> 0 | AD10: 0 | AE10: =AD10*0.35 -> 0 | AF10: 0 | AG10: =AF10/25 -> 0 | AH10: 0 | AI10: =AH10*6.5 -> 0 | AJ10: 0 | AK10: =AJ10/80 -> 0 | AL10: 0 | AM10: =AL10/61.67 -> 0 | AN10: 0 | AO10: 0 | AP10: =AO10*4.5 -> 0 | AQ10: 0 | AR10: =AQ10/30 -> 0 | AS10: 0 | AT10: 0 | AU10: 0 | AV10: =AU10/25 -> 0 | AW10: 0 | AX10: =AW10*27/30 -> 0 | AY10: =AX10/27 -> 0 | AZ10: 0 | BA10: 0 | BB10: 0 | BC10: =AZ10*600/663.06/555 -> 0 | BD10: =BC10*23 -> 0 | BE10: 0 | BF10: =BE10/800 -> 0 | BG10: 0 | BH10: =BG10/100 -> 0 | BI10: 0 | BJ10: =BI10*0.2 -> 0 | BK10: 0 | BL10: =BK10/300 -> 0 | BM10: 0 | BN10: =BM10/150 -> 0 | BO10: 0 | BP10: =BO10*33/35 -> 0 | BQ10: =BP10*35 -> 0 | BR10: 0 | BS10: =ROUND(BR10*0.4,2) -> 0 | BT10: 0 | BU10: =BT10*0.75 -> 0 | BV10: 0 | BW10: =BV10*1.3333333333 -> 0 | BX10: 0 | BY10: =ROUND(BX10*1.43,2) -> 0 | BZ10: =K10+M10+AC10+AE10+I10+Q10+U10+W10+Y10+S10+O10 -> 0 | CG10: 0
A11: 3 | B11: Sa Mêt | H11: 0 | I11: =H11 -> 0 | J11: 0 | K11: =J11*0.684 -> 0 | L11: 0 | M11: =L11*0.93 -> 0 | N11: 0 | O11: =N11*1.97 -> 0 | P11: 0 | Q11: =P11*16.59 -> 0 | R11: 0 | S11: =R11*17 -> 0 | T11: 0 | U11: =T11*0.1 -> 0 | V11: 0 | W11: =V11*0.5 -> 0 | X11: 0 | Y11: =X11*0.8 -> 0 | Z11: 0 | AA11: =Z11*0.5 -> 0 | AB11: 0 | AC11: =AB11*0.4 -> 0 | AD11: 0 | AE11: =AD11*0.35 -> 0 | AF11: 0 | AG11: =AF11/25 -> 0 | AH11: 0 | AI11: =AH11*6.5 -> 0 | AJ11: 0 | AK11: =AJ11/80 -> 0 | AL11: 0 | AM11: =AL11/61.67 -> 0 | AN11: 0 | AO11: 0 | AP11: =AO11*4.5 -> 0 | AQ11: 0 | AR11: =AQ11/30 -> 0 | AS11: 0 | AT11: 0 | AU11: 0 | AV11: =AU11/25 -> 0 | AW11: 0 | AX11: =AW11*27/30 -> 0 | AY11: =AX11/27 -> 0 | AZ11: 0 | BA11: 0 | BB11: 0 | BC11: =AZ11*600/663.06/555 -> 0 | BD11: =BC11*23 -> 0 | BE11: 0 | BF11: =BE11/800 -> 0 | BG11: 0 | BH11: =BG11/100 -> 0 | BI11: 0 | BJ11: =BI11*0.2 -> 0 | BK11: 0 | BL11: =BK11/300 -> 0 | BM11: 0 | BN11: =BM11/150 -> 0 | BO11: 0 | BP11: =BO11*33/35 -> 0 | BQ11: =BP11*35 -> 0 | BR11: 0 | BS11: =ROUND(BR11*0.4,2) -> 0 | BT11: 0 | BU11: =BT11*0.75 -> 0 | BV11: 0 | BW11: =BV11*1.3333333333 -> 0 | BX11: 0 | BY11: =ROUND(BX11*1.43,2) -> 0 | BZ11: =K11+M11+AC11+AE11+I11+Q11+U11+W11+Y11+S11+O11 -> 0
A12: 4 | B12: Nu Rươn | H12: 0 | I12: =H12 -> 0 | J12: 0 | K12: =J12*0.684 -> 0 | L12: 0 | M12: =L12*0.93 -> 0 | N12: 0 | O12: =N12*1.97 -> 0 | P12: 0 | Q12: =P12*16.59 -> 0 | R12: 0 | S12: =R12*17 -> 0 | T12: 0 | U12: =T12*0.1 -> 0 | V12: 0 | W12: =V12*0.5 -> 0 | X12: 0 | Y12: =X12*0.8 -> 0 | Z12: 0 | AA12: =Z12*0.5 -> 0 | AB12: 0 | AC12: =AB12*0.4 -> 0 | AD12: 0 | AE12: =AD12*0.35 -> 0 | AF12: 0 | AG12: =AF12/25 -> 0 | AH12: 0 | AI12: =AH12*6.5 -> 0 | AJ12: 0 | AK12: =AJ12/80 -> 0 | AL12: 0 | AM12: =AL12/61.67 -> 0 | AN12: 0 | AO12: 0 | AP12: =AO12*4.5 -> 0 | AQ12: 0 | AR12: =AQ12/30 -> 0 | AS12: 0 | AT12: 0 | AU12: 0 | AV12: =AU12/25 -> 0 | AW12: 0 | AX12: =AW12*27/30 -> 0 | AY12: =AX12/27 -> 0 | AZ12: 0 | BA12: 0 | BB12: 0 | BC12: =AZ12*600/663.06/555 -> 0 | BD12: =BC12*23 -> 0 | BE12: 0 | BF12: =BE12/800 -> 0 | BG12: 0 | BH12: =BG12/100 -> 0 | BI12: 0 | BJ12: =BI12*0.2 -> 0 | BK12: 0 | BL12: =BK12/300 -> 0 | BM12: 0 | BN12: =BM12/150 -> 0 | BO12: 0 | BP12: =BO12*33/35 -> 0 | BQ12: =BP12*35 -> 0 | BR12: 0 | BS12: =ROUND(BR12*0.4,2) -> 0 | BT12: 0 | BU12: =BT12*0.75 -> 0 | BV12: 0 | BW12: =BV12*1.3333333333 -> 0 | BX12: 0 | BY12: =ROUND(BX12*1.43,2) -> 0 | BZ12: =K12+M12+AC12+AE12+I12+Q12+U12+W12+Y12+S12+O12 -> 0
A13: 5 | B13: Son Hay | C13: 0 | D13: =E13/5.12 -> 0 | E13: 0 | F13: 0 | G13: 0 | H13: 0 | I13: =H13 -> 0 | J13: 0 | K13: =J13*0.684 -> 0 | L13: 0 | M13: =L13*0.93 -> 0 | N13: 0 | O13: =N13*1.97 -> 0 | P13: 0 | Q13: =P13*16.59 -> 0 | R13: 0 | S13: =R13*17 -> 0 | T13: 0 | U13: =T13*0.1 -> 0 | V13: 0 | W13: =V13*0.5 -> 0 | X13: 0 | Y13: =X13*0.8 -> 0 | Z13: 0 | AA13: =Z13*0.5 -> 0 | AB13: 0 | AC13: =AB13*0.4 -> 0 | AD13: 0 | AE13: =AD13*0.35 -> 0 | AF13: 0 | AG13: =AF13/25 -> 0 | AH13: 0 | AI13: =AH13*6.5 -> 0 | AJ13: 0 | AK13: =AJ13/80 -> 0 | AL13: 0 | AM13: =AL13/61.67 -> 0 | AN13: 0 | AO13: 0 | AP13: =AO13*4.5 -> 0 | AQ13: 0 | AR13: =AQ13/30 -> 0 | AS13: 0 | AT13: 0 | AU13: 0 | AV13: =AU13/25 -> 0 | AW13: 0 | AX13: =AW13*27/30 -> 0 | AY13: =AX13/27 -> 0 | AZ13: 0 | BA13: 0 | BB13: 0 | BC13: =AZ13*600/663.06/555 -> 0 | BD13: =BC13*23 -> 0 | BE13: 0 | BF13: =BE13/800 -> 0 | BG13: 0 | BH13: =BG13/100 -> 0 | BI13: 0 | BJ13: =BI13*0.2 -> 0 | BK13: 0 | BL13: =BK13/300 -> 0 | BM13: 0 | BN13: =BM13/150 -> 0 | BO13: 0 | BP13: =BO13*33/35 -> 0 | BQ13: =BP13*35 -> 0 | BR13: 0 | BS13: =ROUND(BR13*0.4,2) -> 0 | BT13: 0 | BU13: =BT13*0.75 -> 0 | BV13: 0 | BW13: =BV13*1.3333333333 -> 0 | BX13: 0 | BY13: =ROUND(BX13*1.43,2) -> 0 | BZ13: =K13+M13+AC13+AE13+I13+Q13+U13+W13+Y13+S13+O13 -> 0 | CG13: 0
A14: 6 | B14: Chon Via | C14: 0 | D14: =E14/5.12 -> 0 | E14: 0 | F14: 0 | G14: 0 | H14: 0 | I14: =H14 -> 0 | J14: 0 | K14: =J14*0.684 -> 0 | L14: 0 | M14: =L14*0.93 -> 0 | N14: 0 | O14: =N14*1.97 -> 0 | P14: 0 | Q14: =P14*16.59 -> 0 | R14: 0 | S14: =R14*17 -> 0 | T14: 0 | U14: =T14*0.1 -> 0 | V14: 0 | W14: =V14*0.5 -> 0 | X14: 0 | Y14: =X14*0.8 -> 0 | Z14: 0 | AA14: =Z14*0.5 -> 0 | AB14: 0 | AC14: =AB14*0.4 -> 0 | AD14: 0 | AE14: =AD14*0.35 -> 0 | AF14: 0 | AG14: =AF14/25 -> 0 | AH14: 0 | AI14: =AH14*6.5 -> 0 | AJ14: 0 | AK14: =AJ14/80 -> 0 | AL14: 0 | AM14: =AL14/61.67 -> 0 | AN14: 0 | AO14: 0 | AP14: =AO14*4.5 -> 0 | AQ14: 0 | AR14: =AQ14/30 -> 0 | AS14: 0 | AT14: 0 | AU14: 0 | AV14: =AU14/25 -> 0 | AW14: 0 | AX14: =AW14*27/30 -> 0 | AY14: =AX14/27 -> 0 | AZ14: 0 | BA14: 0 | BB14: 0 | BC14: =AZ14*600/663.06/555 -> 0 | BD14: =BC14*23 -> 0 | BE14: 0 | BF14: =BE14/800 -> 0 | BG14: 0 | BH14: =BG14/100 -> 0 | BI14: 0 | BJ14: =BI14*0.2 -> 0 | BK14: 0 | BL14: =BK14/300 -> 0 | BM14: 0 | BN14: =BM14/150 -> 0 | BO14: 0 | BP14: =BO14*33/35 -> 0 | BQ14: =BP14*35 -> 0 | BR14: 0 | BS14: =ROUND(BR14*0.4,2) -> 0 | BT14: 0 | BU14: =BT14*0.75 -> 0 | BV14: 0 | BW14: =BV14*1.3333333333 -> 0 | BX14: 0 | BY14: =ROUND(BX14*1.43,2) -> 0 | BZ14: =K14+M14+AC14+AE14+I14+Q14+U14+W14+Y14+S14+O14 -> 0 | CG14: 0
A15: 7 | B15: Nit Nươn | H15: 0 | I15: =H15 -> 0 | J15: 0 | K15: =J15*0.684 -> 0 | L15: 0 | M15: =L15*0.93 -> 0 | N15: 0 | O15: =N15*1.97 -> 0 | P15: 0 | Q15: =P15*16.59 -> 0 | R15: 0 | S15: =R15*17 -> 0 | BZ15: =K15+M15+AC15+AE15+I15+Q15+U15+W15+Y15+S15+O15 -> 0
A16: 8 | B16: Nu Kha | C16: 0 | D16: =E16/5.12 -> 0 | E16: 0 | F16: 0 | G16: 0 | H16: 0 | I16: =H16 -> 0 | J16: 0 | K16: =J16*0.684 -> 0 | L16: 0 | M16: =L16*0.93 -> 0 | N16: 0 | O16: =N16*1.97 -> 0 | P16: 0 | Q16: =P16*16.59 -> 0 | R16: 0 | S16: =R16*17 -> 0 | T16: 0 | U16: =T16*0.1 -> 0 | V16: 0 | W16: =V16*0.5 -> 0 | X16: 0 | Y16: =X16*0.8 -> 0 | Z16: 0 | AA16: =Z16*0.5 -> 0 | AB16: 0 | AC16: =AB16*0.4 -> 0 | AD16: 0 | AE16: =AD16*0.35 -> 0 | AF16: 0 | AG16: =AF16/25 -> 0 | AH16: 0 | AI16: =AH16*6.5 -> 0 | AJ16: 0 | AK16: =AJ16/80 -> 0 | AL16: 0 | AM16: =AL16/61.67 -> 0 | AN16: 0 | AO16: 0 | AP16: =AO16*4.5 -> 0 | AQ16: 0 | AR16: =AQ16/30 -> 0 | AS16: 0 | AT16: 0 | AU16: 0 | AV16: =AU16/25 -> 0 | AW16: 0 | AX16: =AW16*27/30 -> 0 | AY16: =AX16/27 -> 0 | AZ16: 0 | BA16: 0 | BB16: 0 | BC16: =AZ16*600/663.06/555 -> 0 | BD16: =BC16*23 -> 0 | BE16: 0 | BF16: =BE16/800 -> 0 | BG16: 0 | BH16: =BG16/100 -> 0 | BI16: 0 | BJ16: =BI16*0.2 -> 0 | BK16: 0 | BL16: =BK16/300 -> 0 | BM16: 0 | BN16: =BM16/150 -> 0 | BO16: 0 | BP16: =BO16*33/35 -> 0 | BQ16: =BP16*35 -> 0 | BR16: 0 | BS16: =ROUND(BR16*0.4,2) -> 0 | BT16: 0 | BU16: =BT16*0.75 -> 0 | BV16: 0 | BW16: =BV16*1.3333333333 -> 0 | BX16: 0 | BY16: =ROUND(BX16*1.43,2) -> 0 | BZ16: =K16+M16+AC16+AE16+I16+Q16+U16+W16+Y16+S16+O16 -> 0 | CG16: 0
A17: 9 | B17: Du Mêt | C17: 0 | D17: =E17/5.12 -> 0 | E17: 0 | F17: 0 | G17: 0 | H17: 0 | I17: =H17 -> 0 | J17: 0 | K17: =J17*0.684 -> 0 | L17: 0 | M17: =L17*0.93 -> 0 | N17: 0 | O17: =N17*1.97 -> 0 | P17: 0 | Q17: =P17*16.59 -> 0 | R17: 0 | S17: =R17*17 -> 0 | T17: 0 | U17: =T17*0.1 -> 0 | V17: 0 | W17: =V17*0.5 -> 0 | X17: 0 | Y17: =X17*0.8 -> 0 | Z17: 0 | AA17: =Z17*0.5 -> 0 | AB17: 0 | AC17: =AB17*0.4 -> 0 | AD17: 0 | AE17: =AD17*0.35 -> 0 | AF17: 0 | AG17: =AF17/25 -> 0 | AH17: 0 | AI17: =AH17*6.5 -> 0 | AJ17: 0 | AK17: =AJ17/80 -> 0 | AL17: 0 | AM17: =AL17/61.67 -> 0 | AN17: 0 | AO17: 0 | AP17: =AO17*4.5 -> 0 | AQ17: 0 | AR17: =AQ17/30 -> 0 | AS17: 0 | AT17: 0 | AU17: 0 | AV17: =AU17/25 -> 0 | AW17: 0 | AX17: =AW17*27/30 -> 0 | AY17: =AX17/27 -> 0 | AZ17: 0 | BA17: 0 | BB17: 0 | BC17: =AZ17*600/663.06/555 -> 0 | BD17: =BC17*23 -> 0 | BE17: 0 | BF17: =BE17/800 -> 0 | BG17: 0 | BH17: =BG17/100 -> 0 | BI17: 0 | BJ17: =BI17*0.2 -> 0 | BK17: 0 | BL17: =BK17/300 -> 0 | BM17: 0 | BN17: =BM17/150 -> 0 | BO17: 0 | BP17: =BO17*33/35 -> 0 | BQ17: =BP17*35 -> 0 | BR17: 0 | BS17: =ROUND(BR17*0.4,2) -> 0 | BT17: 0 | BU17: =BT17*0.75 -> 0 | BV17: 0 | BW17: =BV17*1.3333333333 -> 0 | BX17: 0 | BY17: =ROUND(BX17*1.43,2) -> 0 | BZ17: =K17+M17+AC17+AE17+I17+Q17+U17+W17+Y17+S17+O17 -> 0 | CG17: 0
A18: 10 | B18: Khon Ra Đây | C18: 0 | D18: =E18/5.12 -> 0 | E18: 0 | F18: 0 | G18: 0 | H18: 0 | I18: =H18 -> 0 | J18: 0 | K18: =J18*0.684 -> 0 | L18: 0 | M18: =L18*0.93 -> 0 | N18: 0 | O18: =N18*1.97 -> 0 | P18: 0 | Q18: =P18*16.59 -> 0 | R18: 0 | S18: =R18*17 -> 0 | T18: 0 | U18: =T18*0.1 -> 0 | V18: 0 | W18: =V18*0.5 -> 0 | X18: 0 | Y18: =X18*0.8 -> 0 | Z18: 0 | AA18: =Z18*0.5 -> 0 | AB18: 0 | AC18: =AB18*0.4 -> 0 | AD18: 0 | AE18: =AD18*0.35 -> 0 | AF18: 0 | AG18: =AF18/25 -> 0 | AH18: 0 | AI18: =AH18*6.5 -> 0 | AJ18: 0 | AK18: =AJ18/80 -> 0 | AL18: 0 | AM18: =AL18/61.67 -> 0 | AN18: 0 | AO18: 0 | AP18: =AO18*4.5 -> 0 | AQ18: 0 | AR18: =AQ18/30 -> 0 | AS18: 0 | AT18: 0 | AU18: 0 | AV18: =AU18/25 -> 0 | AW18: 0 | AX18: =AW18*27/30 -> 0 | AY18: =AX18/27 -> 0 | AZ18: 0 | BA18: 0 | BB18: 0 | BC18: =AZ18*600/663.06/555 -> 0 | BD18: =BC18*23 -> 0 | BE18: 0 | BF18: =BE18/800 -> 0 | BG18: 0 | BH18: =BG18/100 -> 0 | BI18: 0 | BJ18: =BI18*0.2 -> 0 | BK18: 0 | BL18: =BK18/300 -> 0 | BM18: 0 | BN18: =BM18/150 -> 0 | BO18: 0 | BP18: =BO18*33/35 -> 0 | BQ18: =BP18*35 -> 0 | BR18: 0 | BS18: =ROUND(BR18*0.4,2) -> 0 | BT18: 0 | BU18: =BT18*0.75 -> 0 | BV18: 0 | BW18: =BV18*1.3333333333 -> 0 | BX18: 0 | BY18: =ROUND(BX18*1.43,2) -> 0 | BZ18: =K18+M18+AC18+AE18+I18+Q18+U18+W18+Y18+S18+O18 -> 0 | CG18: 0
A19: 11 | B19: An Hia | C19: 0 | D19: =E19/5.12 -> 0 | E19: 0 | F19: 0 | G19: 0 | H19: 0 | I19: =H19 -> 0 | J19: 0 | K19: =J19*0.684 -> 0 | L19: 0 | M19: =L19*0.93 -> 0 | N19: 0 | O19: =N19*1.97 -> 0 | P19: 0 | Q19: =P19*16.59 -> 0 | R19: 0 | S19: =R19*17 -> 0 | T19: 0 | U19: =T19*0.1 -> 0 | V19: 0 | W19: =V19*0.5 -> 0 | X19: 0 | Y19: =X19*0.8 -> 0 | Z19: 0 | AA19: =Z19*0.5 -> 0 | AB19: 0 | AC19: =AB19*0.4 -> 0 | AD19: 0 | AE19: =AD19*0.35 -> 0 | AF19: 0 | AG19: =AF19/25 -> 0 | AH19: 0 | AI19: =AH19*6.5 -> 0 | AJ19: 0 | AK19: =AJ19/80 -> 0 | AL19: 0 | AM19: =AL19/61.67 -> 0 | AN19: 0 | AO19: 0 | AP19: =AO19*4.5 -> 0 | AQ19: 0 | AR19: =AQ19/30 -> 0 | AS19: 0 | AT19: 0 | AU19: 0 | AV19: =AU19/25 -> 0 | AW19: 0 | AX19: =AW19*27/30 -> 0 | AY19: =AX19/27 -> 0 | AZ19: 0 | BA19: 0 | BB19: 0 | BC19: =AZ19*600/663.06/555 -> 0 | BD19: =BC19*23 -> 0 | BE19: 0 | BF19: =BE19/800 -> 0 | BG19: 0 | BH19: =BG19/100 -> 0 | BI19: 0 | BJ19: =BI19*0.2 -> 0 | BK19: 0 | BL19: =BK19/300 -> 0 | BM19: 0 | BN19: =BM19/150 -> 0 | BO19: 0 | BP19: =BO19*33/35 -> 0 | BQ19: =BP19*35 -> 0 | BR19: 0 | BS19: =ROUND(BR19*0.4,2) -> 0 | BT19: 0 | BU19: =BT19*0.75 -> 0 | BV19: 0 | BW19: =BV19*1.3333333333 -> 0 | BX19: 0 | BY19: =ROUND(BX19*1.43,2) -> 0 | BZ19: =K19+M19+AC19+AE19+I19+Q19+U19+W19+Y19+S19+O19 -> 0 | CG19: 0
A20: 12 | B20: Thi Thia | H20: 0 | I20: =H20 -> 0 | J20: 0 | K20: =J20*0.684 -> 0 | L20: 0 | M20: =L20*0.93 -> 0 | N20: 0 | O20: =N20*1.97 -> 0 | P20: 0 | Q20: =P20*16.59 -> 0 | R20: 0 | S20: =R20*17 -> 0 | T20: 0 | U20: =T20*0.1 -> 0 | V20: 0 | W20: =V20*0.5 -> 0 | X20: 0 | Y20: =X20*0.8 -> 0 | Z20: 0 | AA20: =Z20*0.5 -> 0 | AB20: 0 | AC20: =AB20*0.4 -> 0 | AD20: 0 | AE20: =AD20*0.35 -> 0 | AF20: 0 | AG20: =AF20/25 -> 0 | AH20: 0 | AI20: =AH20*6.5 -> 0 | AJ20: 0 | AK20: =AJ20/80 -> 0 | AL20: 0 | AM20: =AL20/61.67 -> 0 | AN20: 0 | AO20: 0 | AP20: =AO20*4.5 -> 0 | AQ20: 0 | AR20: =AQ20/30 -> 0 | AS20: 0 | AT20: 0 | AU20: 0 | AV20: =AU20/25 -> 0 | AW20: 0 | AX20: =AW20*27/30 -> 0 | AY20: =AX20/27 -> 0 | AZ20: 0 | BA20: 0 | BB20: 0 | BC20: =AZ20*600/663.06/555 -> 0 | BD20: =BC20*23 -> 0 | BE20: 0 | BF20: =BE20/800 -> 0 | BG20: 0 | BH20: =BG20/100 -> 0 | BI20: 0 | BJ20: =BI20*0.2 -> 0 | BK20: 0 | BL20: =BK20/300 -> 0 | BM20: 0 | BN20: =BM20/150 -> 0 | BO20: 0 | BP20: =BO20*33/35 -> 0 | BQ20: =BP20*35 -> 0 | BR20: 0 | BS20: =ROUND(BR20*0.4,2) -> 0 | BT20: 0 | BU20: =BT20*0.75 -> 0 | BV20: 0 | BW20: =BV20*1.3333333333 -> 0 | BX20: 0 | BY20: =ROUND(BX20*1.43,2) -> 0 | BZ20: =K20+M20+AC20+AE20+I20+Q20+U20+W20+Y20+S20+O20 -> 0
A21: 13 | B21: Dôt Mêt | H21: 0 | I21: =H21 -> 0 | J21: 0 | K21: =J21*0.684 -> 0 | L21: 0 | M21: =L21*0.93 -> 0 | N21: 0 | O21: =N21*1.97 -> 0 | P21: 0 | Q21: =P21*16.59 -> 0 | R21: 0 | S21: =R21*17 -> 0 | BZ21: =K21+M21+AC21+AE21+I21+Q21+U21+W21+Y21+S21+O21 -> 0
A22: 14 | B22: Lu Lươn | H22: 0 | I22: =H22 -> 0 | J22: 0 | K22: =J22*0.684 -> 0 | L22: 0 | M22: =L22*0.93 -> 0 | N22: 0 | O22: =N22*1.97 -> 0 | P22: 0 | Q22: =P22*16.59 -> 0 | R22: 0 | S22: =R22*17 -> 0 | T22: 0 | U22: =T22*0.1 -> 0 | V22: 0 | W22: =V22*0.5 -> 0 | X22: 0 | Y22: =X22*0.8 -> 0 | Z22: 0 | AA22: =Z22*0.5 -> 0 | AB22: 0 | AC22: =AB22*0.4 -> 0 | AD22: 0 | AE22: =AD22*0.35 -> 0 | AF22: 0 | AG22: =AF22/25 -> 0 | AH22: 0 | AI22: =AH22*6.5 -> 0 | AJ22: 0 | AK22: =AJ22/80 -> 0 | AL22: 0 | AM22: =AL22/61.67 -> 0 | AN22: 0 | AO22: 0 | AP22: =AO22*4.5 -> 0 | AQ22: 0 | AR22: =AQ22/30 -> 0 | AS22: 0 | AT22: 0 | AU22: 0 | AV22: =AU22/25 -> 0 | AW22: 0 | AX22: =AW22*27/30 -> 0 | AY22: =AX22/27 -> 0 | AZ22: 0 | BA22: 0 | BB22: 0 | BC22: =AZ22*600/663.06/555 -> 0 | BD22: =BC22*23 -> 0 | BE22: 0 | BF22: =BE22/800 -> 0 | BG22: 0 | BH22: =BG22/100 -> 0 | BI22: 0 | BJ22: =BI22*0.2 -> 0 | BK22: 0 | BL22: =BK22/300 -> 0 | BM22: 0 | BN22: =BM22/150 -> 0 | BO22: 0 | BP22: =BO22*33/35 -> 0 | BQ22: =BP22*35 -> 0 | BR22: 0 | BS22: =ROUND(BR22*0.4,2) -> 0 | BT22: 0 | BU22: =BT22*0.75 -> 0 | BV22: 0 | BW22: =BV22*1.3333333333 -> 0 | BX22: 0 | BY22: =ROUND(BX22*1.43,2) -> 0 | BZ22: =K22+M22+AC22+AE22+I22+Q22+U22+W22+Y22+S22+O22 -> 0
A23: 15 | B23: Sươn Săm | H23: 0 | I23: =H23 -> 0 | J23: 0 | K23: =J23*0.684 -> 0 | L23: 0 | M23: =L23*0.93 -> 0 | N23: 0 | O23: =N23*1.97 -> 0 | P23: 0 | Q23: =P23*16.59 -> 0 | R23: 0 | S23: =R23*17 -> 0 | T23: 0 | U23: =T23*0.1 -> 0 | V23: 0 | W23: =V23*0.5 -> 0 | X23: 0 | Y23: =X23*0.8 -> 0 | Z23: 0 | AA23: =Z23*0.5 -> 0 | AB23: 0 | AC23: =AB23*0.4 -> 0 | AD23: 0 | AE23: =AD23*0.35 -> 0 | AF23: 0 | AG23: =AF23/25 -> 0 | AH23: 0 | AI23: =AH23*6.5 -> 0 | AJ23: 0 | AK23: =AJ23/80 -> 0 | AL23: 0 | AM23: =AL23/61.67 -> 0 | AN23: 0 | AO23: 0 | AP23: =AO23*4.5 -> 0 | AQ23: 0 | AR23: =AQ23/30 -> 0 | AS23: 0 | AT23: 0 | AU23: 0 | AV23: =AU23/25 -> 0 | AW23: 0 | AX23: =AW23*27/30 -> 0 | AY23: =AX23/27 -> 0 | AZ23: 0 | BA23: 0 | BB23: 0 | BC23: =AZ23*600/663.06/555 -> 0 | BD23: =BC23*23 -> 0 | BE23: 0 | BF23: =BE23/800 -> 0 | BG23: 0 | BH23: =BG23/100 -> 0 | BI23: 0 | BJ23: =BI23*0.2 -> 0 | BK23: 0 | BL23: =BK23/300 -> 0 | BM23: 0 | BN23: =BM23/150 -> 0 | BO23: 0 | BP23: =BO23*33/35 -> 0 | BQ23: =BP23*35 -> 0 | BR23: 0 | BS23: =ROUND(BR23*0.4,2) -> 0 | BT23: 0 | BU23: =BT23*0.75 -> 0 | BV23: 0 | BW23: =BV23*1.3333333333 -> 0 | BX23: 0 | BY23: =ROUND(BX23*1.43,2) -> 0 | BZ23: =K23+M23+AC23+AE23+I23+Q23+U23+W23+Y23+S23+O23 -> 0
A24: 16 | B24: Tem Mơi | H24: 0 | I24: =H24 -> 0 | J24: 0 | K24: =J24*0.684 -> 0 | L24: 0 | M24: =L24*0.93 -> 0 | N24: 0 | O24: =N24*1.97 -> 0 | P24: 0 | Q24: =P24*16.59 -> 0 | R24: 0 | S24: =R24*17 -> 0 | T24: 0 | U24: =T24*0.1 -> 0 | V24: 0 | W24: =V24*0.5 -> 0 | X24: 0 | Y24: =X24*0.8 -> 0 | Z24: 0 | AA24: =Z24*0.5 -> 0 | AB24: 0 | AC24: =AB24*0.4 -> 0 | AD24: 0 | AE24: =AD24*0.35 -> 0 | AF24: 0 | AG24: =AF24/25 -> 0 | AH24: 0 | AI24: =AH24*6.5 -> 0 | AJ24: 0 | AK24: =AJ24/80 -> 0 | AL24: 0 | AM24: =AL24/61.67 -> 0 | AN24: 0 | AO24: 0 | AP24: =AO24*4.5 -> 0 | AQ24: 0 | AR24: =AQ24/30 -> 0 | AS24: 0 | AT24: 0 | AU24: 0 | AV24: =AU24/25 -> 0 | AW24: 0 | AX24: =AW24*27/30 -> 0 | AY24: =AX24/27 -> 0 | AZ24: 0 | BA24: 0 | BB24: 0 | BC24: =AZ24*600/663.06/555 -> 0 | BD24: =BC24*23 -> 0 | BE24: 0 | BF24: =BE24/800 -> 0 | BG24: 0 | BH24: =BG24/100 -> 0 | BI24: 0 | BJ24: =BI24*0.2 -> 0 | BK24: 0 | BL24: =BK24/300 -> 0 | BM24: 0 | BN24: =BM24/150 -> 0 | BO24: 0 | BP24: =BO24*33/35 -> 0 | BQ24: =BP24*35 -> 0 | BR24: 0 | BS24: =ROUND(BR24*0.4,2) -> 0 | BT24: 0 | BU24: =BT24*0.75 -> 0 | BV24: 0 | BW24: =BV24*1.3333333333 -> 0 | BX24: 0 | BY24: =ROUND(BX24*1.43,2) -> 0 | BZ24: =K24+M24+AC24+AE24+I24+Q24+U24+W24+Y24+S24+O24 -> 0
A25: 17 | B25: Thu Ranh | H25: 0 | I25: =H25 -> 0 | J25: 0 | K25: =J25*0.684 -> 0 | L25: 0 | M25: =L25*0.93 -> 0 | N25: 0 | O25: =N25*1.97 -> 0 | P25: 0 | Q25: =P25*16.59 -> 0 | R25: 0 | S25: =R25*17 -> 0 | T25: 0 | U25: =T25*0.1 -> 0 | V25: 0 | W25: =V25*0.5 -> 0 | X25: 0 | Y25: =X25*0.8 -> 0 | Z25: 0 | AA25: =Z25*0.5 -> 0 | AB25: 0 | AC25: =AB25*0.4 -> 0 | AD25: 0 | AE25: =AD25*0.35 -> 0 | AF25: 0 | AG25: =AF25/25 -> 0 | AH25: 0 | AI25: =AH25*6.5 -> 0 | AJ25: 0 | AK25: =AJ25/80 -> 0 | AL25: 0 | AM25: =AL25/61.67 -> 0 | AN25: 0 | AO25: 0 | AP25: =AO25*4.5 -> 0 | AQ25: 0 | AR25: =AQ25/30 -> 0 | AS25: 0 | AT25: 0 | AU25: 0 | AV25: =AU25/25 -> 0 | AW25: 0 | AX25: =AW25*27/30 -> 0 | AY25: =AX25/27 -> 0 | AZ25: 0 | BA25: 0 | BB25: 0 | BC25: =AZ25*600/663.06/555 -> 0 | BD25: =BC25*23 -> 0 | BE25: 0 | BF25: =BE25/800 -> 0 | BG25: 0 | BH25: =BG25/100 -> 0 | BI25: 0 | BJ25: =BI25*0.2 -> 0 | BK25: 0 | BL25: =BK25/300 -> 0 | BM25: 0 | BN25: =BM25/150 -> 0 | BO25: 0 | BP25: =BO25*33/35 -> 0 | BQ25: =BP25*35 -> 0 | BR25: 0 | BS25: =ROUND(BR25*0.4,2) -> 0 | BT25: 0 | BU25: =BT25*0.75 -> 0 | BV25: 0 | BW25: =BV25*1.3333333333 -> 0 | BX25: 0 | BY25: =ROUND(BX25*1.43,2) -> 0 | BZ25: =K25+M25+AC25+AE25+I25+Q25+U25+W25+Y25+S25+O25 -> 0
A26: 18 | B26: Dup Hanh | H26: 0 | I26: =H26 -> 0 | J26: 0 | K26: =J26*0.684 -> 0 | L26: 0 | M26: =L26*0.93 -> 0 | N26: 0 | O26: =N26*1.97 -> 0 | P26: 0 | Q26: =P26*16.59 -> 0 | R26: 0 | S26: =R26*17 -> 0 | BZ26: =K26+M26+AC26+AE26+I26+Q26+U26+W26+Y26+S26+O26 -> 0
A27: 19 | B27: Phon Thit | H27: 0 | I27: =H27 -> 0 | J27: 0 | K27: =J27*0.684 -> 0 | L27: 0 | M27: =L27*0.93 -> 0 | N27: 0 | O27: =N27*1.97 -> 0 | P27: 0 | Q27: =P27*16.59 -> 0 | R27: 0 | S27: =R27*17 -> 0 | T27: 0 | U27: =T27*0.1 -> 0 | V27: 0 | W27: =V27*0.5 -> 0 | X27: 0 | Y27: =X27*0.8 -> 0 | Z27: 0 | AA27: =Z27*0.5 -> 0 | AB27: 0 | AC27: =AB27*0.4 -> 0 | AD27: 0 | AE27: =AD27*0.35 -> 0 | AF27: 0 | AG27: =AF27/25 -> 0 | AH27: 0 | AI27: =AH27*6.5 -> 0 | AJ27: 0 | AK27: =AJ27/80 -> 0 | AL27: 0 | AM27: =AL27/61.67 -> 0 | AN27: 0 | AO27: 0 | AP27: =AO27*4.5 -> 0 | AQ27: 0 | AR27: =AQ27/30 -> 0 | AS27: 0 | AT27: 0 | AU27: 0 | AV27: =AU27/25 -> 0 | AW27: 0 | AX27: =AW27*27/30 -> 0 | AY27: =AX27/27 -> 0 | AZ27: 0 | BA27: 0 | BB27: 0 | BC27: =AZ27*600/663.06/555 -> 0 | BD27: =BC27*23 -> 0 | BE27: 0 | BF27: =BE27/800 -> 0 | BG27: 0 | BH27: =BG27/100 -> 0 | BI27: 0 | BJ27: =BI27*0.2 -> 0 | BK27: 0 | BL27: =BK27/300 -> 0 | BM27: 0 | BN27: =BM27/150 -> 0 | BO27: 0 | BP27: =BO27*33/35 -> 0 | BQ27: =BP27*35 -> 0 | BR27: 0 | BS27: =ROUND(BR27*0.4,2) -> 0 | BT27: 0 | BU27: =BT27*0.75 -> 0 | BV27: 0 | BW27: =BV27*1.3333333333 -> 0 | BX27: 0 | BY27: =ROUND(BX27*1.43,2) -> 0 | BZ27: =K27+M27+AC27+AE27+I27+Q27+U27+W27+Y27+S27+O27 -> 0
A28: 20 | B28: Ha Lay Hon | H28: 0 | I28: =H28 -> 0 | J28: 0 | K28: =J28*0.684 -> 0 | L28: 0 | M28: =L28*0.93 -> 0 | N28: 0 | O28: =N28*1.97 -> 0 | P28: 0 | Q28: =P28*16.59 -> 0 | R28: 0 | S28: =R28*17 -> 0 | T28: 0 | U28: =T28*0.1 -> 0 | V28: 0 | W28: =V28*0.5 -> 0 | X28: 0 | Y28: =X28*0.8 -> 0 | Z28: 0 | AA28: =Z28*0.5 -> 0 | AB28: 0 | AC28: =AB28*0.4 -> 0 | AD28: 0 | AE28: =AD28*0.35 -> 0 | AF28: 0 | AG28: =AF28/25 -> 0 | AH28: 0 | AI28: =AH28*6.5 -> 0 | AJ28: 0 | AK28: =AJ28/80 -> 0 | AL28: 0 | AM28: =AL28/61.67 -> 0 | AN28: 0 | AO28: 0 | AP28: =AO28*4.5 -> 0 | AQ28: 0 | AR28: =AQ28/30 -> 0 | AS28: 0 | AT28: 0 | AU28: 0 | AV28: =AU28/25 -> 0 | AW28: 0 | AX28: =AW28*27/30 -> 0 | AY28: =AX28/27 -> 0 | AZ28: 0 | BA28: 0 | BB28: 0 | BC28: =AZ28*600/663.06/555 -> 0 | BD28: =BC28*23 -> 0 | BE28: 0 | BF28: =BE28/800 -> 0 | BG28: 0 | BH28: =BG28/100 -> 0 | BI28: 0 | BJ28: =BI28*0.2 -> 0 | BK28: 0 | BL28: =BK28/300 -> 0 | BM28: 0 | BN28: =BM28/150 -> 0 | BO28: 0 | BP28: =BO28*33/35 -> 0 | BQ28: =BP28*35 -> 0 | BR28: 0 | BS28: =ROUND(BR28*0.4,2) -> 0 | BT28: 0 | BU28: =BT28*0.75 -> 0 | BV28: 0 | BW28: =BV28*1.3333333333 -> 0 | BX28: 0 | BY28: =ROUND(BX28*1.43,2) -> 0 | BZ28: =K28+M28+AC28+AE28+I28+Q28+U28+W28+Y28+S28+O28 -> 0
A29: 21 | B29: Lum Ron | H29: 0 | I29: =H29 -> 0 | J29: 0 | K29: =J29*0.684 -> 0 | L29: 0 | M29: =L29*0.93 -> 0 | N29: 0 | O29: =N29*1.979 -> 0 | P29: 0 | Q29: =P29*16.59 -> 0 | R29: 0 | S29: =R29*17 -> 0 | T29: 0 | U29: =T29*0.1 -> 0 | V29: 0 | W29: =V29*0.5 -> 0 | X29: 0 | Y29: =X29*0.8 -> 0 | Z29: 0 | AA29: =Z29*0.5 -> 0 | AB29: 0 | AC29: =AB29*0.4 -> 0 | AD29: 0 | AE29: =AD29*0.35 -> 0 | AF29: 0 | AG29: =AF29/25 -> 0 | AH29: 0 | AI29: =AH29*6.5 -> 0 | AJ29: 0 | AK29: =AJ29/80 -> 0 | AL29: 0 | AM29: =AL29/61.67 -> 0 | AN29: 0 | AO29: 0 | AP29: =AO29*4.5 -> 0 | AQ29: 0 | AR29: =AQ29/30 -> 0 | AS29: 0 | AT29: 0 | AU29: 0 | AV29: =AU29/25 -> 0 | AW29: 0 | AX29: =AW29*27/30 -> 0 | AY29: =AX29/27 -> 0 | AZ29: 0 | BA29: 0 | BB29: 0 | BC29: =AZ29*600/663.06/555 -> 0 | BD29: =BC29*23 -> 0 | BE29: 0 | BF29: =BE29/800 -> 0 | BG29: 0 | BH29: =BG29/100 -> 0 | BI29: 0 | BJ29: =BI29*0.2 -> 0 | BK29: 0 | BL29: =BK29/300 -> 0 | BM29: 0 | BN29: =BM29/150 -> 0 | BO29: 0 | BP29: =BO29*33/35 -> 0 | BQ29: =BP29*35 -> 0 | BR29: 0 | BS29: =ROUND(BR29*0.4,2) -> 0 | BT29: 0 | BU29: =BT29*0.75 -> 0 | BV29: 0 | BW29: =BV29*1.3333333333 -> 0 | BX29: 0 | BY29: =ROUND(BX29*1.43,2) -> 0 | BZ29: =K29+M29+AC29+AE29+I29+Q29+U29+W29+Y29+S29+O29 -> 0
A30: 22 | B30: Lup Hên | H30: 0 | I30: =H30 -> 0 | J30: 0 | K30: =J30*0.684 -> 0 | L30: 0 | M30: =L30*0.93 -> 0 | N30: 0 | O30: =N30*1.97 -> 0 | P30: 0 | Q30: =P30*16.59 -> 0 | R30: 0 | S30: =R30*17 -> 0 | T30: 0 | U30: =T30*0.1 -> 0 | V30: 0 | W30: =V30*0.5 -> 0 | X30: 0 | Y30: =X30*0.8 -> 0 | Z30: 0 | AA30: =Z30*0.5 -> 0 | AB30: 0 | AC30: =AB30*0.4 -> 0 | AD30: 0 | AE30: =AD30*0.35 -> 0 | AF30: 0 | AG30: =AF30/25 -> 0 | AH30: 0 | AI30: =AH30*6.5 -> 0 | AJ30: 0 | AK30: =AJ30/80 -> 0 | AL30: 0 | AM30: =AL30/61.67 -> 0 | AN30: 0 | AO30: 0 | AP30: =AO30*4.5 -> 0 | AQ30: 0 | AR30: =AQ30/30 -> 0 | AS30: 0 | AT30: 0 | AU30: 0 | AV30: =AU30/25 -> 0 | AW30: 0 | AX30: =AW30*27/30 -> 0 | AY30: =AX30/27 -> 0 | AZ30: 0 | BA30: 0 | BB30: 0 | BC30: =AZ30*600/663.06/555 -> 0 | BD30: =BC30*23 -> 0 | BE30: 0 | BF30: =BE30/800 -> 0 | BG30: 0 | BH30: =BG30/100 -> 0 | BI30: 0 | BJ30: =BI30*0.2 -> 0 | BK30: 0 | BL30: =BK30/300 -> 0 | BM30: 0 | BN30: =BM30/150 -> 0 | BO30: 0 | BP30: =BO30*33/35 -> 0 | BQ30: =BP30*35 -> 0 | BR30: 0 | BS30: =ROUND(BR30*0.4,2) -> 0 | BT30: 0 | BU30: =BT30*0.75 -> 0 | BV30: 0 | BW30: =BV30*1.3333333333 -> 0 | BX30: 0 | BY30: =ROUND(BX30*1.43,2) -> 0 | BZ30: =K30+M30+AC30+AE30+I30+Q30+U30+W30+Y30+S30+O30 -> 0
A31: 23 | B31: Nay Chên | H31: 0 | I31: =H31 -> 0 | J31: 0 | K31: =J31*0.684 -> 0 | L31: 0 | M31: =L31*0.93 -> 0 | N31: 0 | O31: =N31*1.97 -> 0 | P31: 0 | Q31: =P31*16.59 -> 0 | R31: 0 | S31: =R31*17 -> 0 | T31: 0 | U31: =T31*0.1 -> 0 | V31: 0 | W31: =V31*0.5 -> 0 | X31: 0 | Y31: =X31*0.8 -> 0 | Z31: 0 | AA31: =Z31*0.5 -> 0 | AB31: 0 | AC31: =AB31*0.4 -> 0 | AD31: 0 | AE31: =AD31*0.35 -> 0 | AF31: 0 | AG31: =AF31/25 -> 0 | AH31: 0 | AI31: =AH31*6.5 -> 0 | AJ31: 0 | AK31: =AJ31/80 -> 0 | AL31: 0 | AM31: =AL31/61.67 -> 0 | AN31: 0 | AO31: 0 | AP31: =AO31*4.5 -> 0 | AQ31: 0 | AR31: =AQ31/30 -> 0 | AS31: 0 | AT31: 0 | AU31: 0 | AV31: =AU31/25 -> 0 | AW31: 0 | AX31: =AW31*27/30 -> 0 | AY31: =AX31/27 -> 0 | AZ31: 0 | BA31: 0 | BB31: 0 | BC31: =AZ31*600/663.06/555 -> 0 | BD31: =BC31*23 -> 0 | BE31: 0 | BF31: =BE31/800 -> 0 | BG31: 0 | BH31: =BG31/100 -> 0 | BI31: 0 | BJ31: =BI31*0.2 -> 0 | BK31: 0 | BL31: =BK31/300 -> 0 | BM31: 0 | BN31: =BM31/150 -> 0 | BO31: 0 | BP31: =BO31*33/35 -> 0 | BQ31: =BP31*35 -> 0 | BR31: 0 | BS31: =ROUND(BR31*0.4,2) -> 0 | BT31: 0 | BU31: =BT31*0.75 -> 0 | BV31: 0 | BW31: =BV31*1.3333333333 -> 0 | BX31: 0 | BY31: =ROUND(BX31*1.43,2) -> 0 | BZ31: =K31+M31+AC31+AE31+I31+Q31+U31+W31+Y31+S31+O31 -> 0
A32: 24 | B32: Si Khưa | H32: 0 | I32: =H32 -> 0 | J32: 0 | K32: =J32*0.684 -> 0 | L32: 0 | M32: =L32*0.93 -> 0 | N32: 0 | O32: =N32*1.97 -> 0 | P32: 0 | Q32: =P32*16.59 -> 0 | R32: 0 | S32: =R32*17 -> 0 | T32: 0 | U32: =T32*0.1 -> 0 | V32: 0 | W32: =V32*0.5 -> 0 | X32: 0 | Y32: =X32*0.8 -> 0 | Z32: 0 | AA32: =Z32*0.5 -> 0 | AB32: 0 | AC32: =AB32*0.4 -> 0 | AD32: 0 | AE32: =AD32*0.35 -> 0 | AF32: 0 | AG32: =AF32/25 -> 0 | AH32: 0 | AI32: =AH32*6.5 -> 0 | AJ32: 0 | AK32: =AJ32/80 -> 0 | AL32: 0 | AM32: =AL32/61.67 -> 0 | AN32: 0 | AO32: 0 | AP32: =AO32*4.5 -> 0 | AQ32: 0 | AR32: =AQ32/30 -> 0 | AS32: 0 | AT32: 0 | AU32: 0 | AV32: =AU32/25 -> 0 | AW32: 0 | AX32: =AW32*27/30 -> 0 | AY32: =AX32/27 -> 0 | AZ32: 0 | BA32: 0 | BB32: 0 | BC32: =AZ32*600/663.06/555 -> 0 | BD32: =BC32*23 -> 0 | BE32: 0 | BF32: =BE32/800 -> 0 | BG32: 0 | BH32: =BG32/100 -> 0 | BI32: 0 | BJ32: =BI32*0.2 -> 0 | BK32: 0 | BL32: =BK32/300 -> 0 | BM32: 0 | BN32: =BM32/150 -> 0 | BO32: 0 | BP32: =BO32*33/35 -> 0 | BQ32: =BP32*35 -> 0 | BR32: 0 | BS32: =ROUND(BR32*0.4,2) -> 0 | BT32: 0 | BU32: =BT32*0.75 -> 0 | BV32: 0 | BW32: =BV32*1.3333333333 -> 0 | BX32: 0 | BY32: =ROUND(BX32*1.43,2) -> 0 | BZ32: =K32+M32+AC32+AE32+I32+Q32+U32+W32+Y32+S32+O32 -> 0
A33: 25 | B33: Khăm Vanh | H33: 0 | I33: =H33 -> 0 | J33: 0 | K33: =J33*0.684 -> 0 | L33: 0 | M33: =L33*0.93 -> 0 | N33: 0 | O33: =N33*1.97 -> 0 | P33: 0 | Q33: =P33*16.59 -> 0 | R33: 0 | S33: =R33*17 -> 0 | T33: 0 | U33: =T33*0.1 -> 0 | V33: 0 | W33: =V33*0.5 -> 0 | X33: 0 | Y33: =X33*0.8 -> 0 | Z33: 0 | AA33: =Z33*0.5 -> 0 | AB33: 0 | AC33: =AB33*0.4 -> 0 | AD33: 0 | AE33: =AD33*0.35 -> 0 | AF33: 0 | AG33: =AF33/25 -> 0 | AH33: 0 | AI33: =AH33*6.5 -> 0 | AJ33: 0 | AK33: =AJ33/80 -> 0 | AL33: 0 | AM33: =AL33/61.67 -> 0 | AN33: 0 | AO33: 0 | AP33: =AO33*4.5 -> 0 | AQ33: 0 | AR33: =AQ33/30 -> 0 | AS33: 0 | AT33: 0 | AU33: 0 | AV33: =AU33/25 -> 0 | AW33: 0 | AX33: =AW33*27/30 -> 0 | AY33: =AX33/27 -> 0 | AZ33: 0 | BA33: 0 | BB33: 0 | BC33: =AZ33*600/663.06/555 -> 0 | BD33: =BC33*23 -> 0 | BE33: 0 | BF33: =BE33/800 -> 0 | BG33: 0 | BH33: =BG33/100 -> 0 | BI33: 0 | BJ33: =BI33*0.2 -> 0 | BK33: 0 | BL33: =BK33/300 -> 0 | BM33: 0 | BN33: =BM33/150 -> 0 | BO33: 0 | BP33: =BO33*33/35 -> 0 | BQ33: =BP33*35 -> 0 | BR33: 0 | BS33: =ROUND(BR33*0.4,2) -> 0 | BT33: 0 | BU33: =BT33*0.75 -> 0 | BV33: 0 | BW33: =BV33*1.3333333333 -> 0 | BX33: 0 | BY33: =ROUND(BX33*1.43,2) -> 0 | BZ33: =K33+M33+AC33+AE33+I33+Q33+U33+W33+Y33+S33+O33 -> 0
A34: 26 | B34: Chu Chươn | H34: 0 | I34: =H34 -> 0 | J34: 0 | K34: =J34*0.684 -> 0 | L34: 0 | M34: =L34*0.93 -> 0 | N34: 0 | O34: =N34*1.97 -> 0 | P34: 0 | Q34: =P34*16.59 -> 0 | R34: 0 | S34: =R34*17 -> 0 | T34: 0 | U34: =T34*0.1 -> 0 | V34: 0 | W34: =V34*0.5 -> 0 | X34: 0 | Y34: =X34*0.8 -> 0 | Z34: 0 | AA34: =Z34*0.5 -> 0 | AB34: 0 | AC34: =AB34*0.4 -> 0 | AD34: 0 | AE34: =AD34*0.35 -> 0 | AF34: 0 | AG34: =AF34/25 -> 0 | AH34: 0 | AI34: =AH34*6.5 -> 0 | AJ34: 0 | AK34: =AJ34/80 -> 0 | AL34: 0 | AM34: =AL34/61.67 -> 0 | AN34: 0 | AO34: 0 | AP34: =AO34*4.5 -> 0 | AQ34: 0 | AR34: =AQ34/30 -> 0 | AS34: 0 | AT34: 0 | AU34: 0 | AV34: =AU34/25 -> 0 | AW34: 0 | AX34: =AW34*27/30 -> 0 | AY34: =AX34/27 -> 0 | AZ34: 0 | BA34: 0 | BB34: 0 | BC34: =AZ34*600/663.06/555 -> 0 | BD34: =BC34*23 -> 0 | BE34: 0 | BF34: =BE34/800 -> 0 | BG34: 0 | BH34: =BG34/100 -> 0 | BI34: 0 | BJ34: =BI34*0.2 -> 0 | BK34: 0 | BL34: =BK34/300 -> 0 | BM34: 0 | BN34: =BM34/150 -> 0 | BO34: 0 | BP34: =BO34*33/35 -> 0 | BQ34: =BP34*35 -> 0 | BR34: 0 | BS34: =ROUND(BR34*0.4,2) -> 0 | BT34: 0 | BU34: =BT34*0.75 -> 0 | BV34: 0 | BW34: =BV34*1.3333333333 -> 0 | BX34: 0 | BY34: =ROUND(BX34*1.43,2) -> 0 | BZ34: =K34+M34+AC34+AE34+I34+Q34+U34+W34+Y34+S34+O34 -> 0
A35: 27 | B35: Thon Da | H35: 0 | I35: =H35 -> 0 | J35: 0 | K35: =J35*0.684 -> 0 | L35: 0 | M35: =L35*0.93 -> 0 | N35: 0 | O35: =N35*1.97 -> 0 | P35: 0 | Q35: =P35*16.59 -> 0 | R35: 0 | S35: =R35*17 -> 0 | T35: 0 | U35: =T35*0.1 -> 0 | V35: 0 | W35: =V35*0.5 -> 0 | X35: 0 | Y35: =X35*0.8 -> 0 | Z35: 0 | AA35: =Z35*0.5 -> 0 | AB35: 0 | AC35: =AB35*0.4 -> 0 | AD35: 0 | AE35: =AD35*0.35 -> 0 | AF35: 0 | AG35: =AF35/25 -> 0 | AH35: 0 | AI35: =AH35*6.5 -> 0 | AJ35: 0 | AK35: =AJ35/80 -> 0 | AL35: 0 | AM35: =AL35/61.67 -> 0 | AN35: 0 | AO35: 0 | AP35: =AO35*4.5 -> 0 | AQ35: 0 | AR35: =AQ35/30 -> 0 | AS35: 0 | AT35: 0 | AU35: 0 | AV35: =AU35/25 -> 0 | AW35: 0 | AX35: =AW35*27/30 -> 0 | AY35: =AX35/27 -> 0 | AZ35: 0 | BA35: 0 | BB35: 0 | BC35: =AZ35*600/663.06/555 -> 0 | BD35: =BC35*23 -> 0 | BE35: 0 | BF35: =BE35/800 -> 0 | BG35: 0 | BH35: =BG35/100 -> 0 | BI35: 0 | BJ35: =BI35*0.2 -> 0 | BK35: 0 | BL35: =BK35/300 -> 0 | BM35: 0 | BN35: =BM35/150 -> 0 | BO35: 0 | BP35: =BO35*33/35 -> 0 | BQ35: =BP35*35 -> 0 | BR35: 0 | BS35: =ROUND(BR35*0.4,2) -> 0 | BT35: 0 | BU35: =BT35*0.75 -> 0 | BV35: 0 | BW35: =BV35*1.3333333333 -> 0 | BX35: 0 | BY35: =ROUND(BX35*1.43,2) -> 0 | BZ35: =K35+M35+AC35+AE35+I35+Q35+U35+W35+Y35+S35+O35 -> 0
A36: 28 | B36: Tia Hươn | H36: 0 | I36: =H36 -> 0 | J36: 0 | K36: =J36*0.684 -> 0 | L36: 0 | M36: =L36*0.93 -> 0 | N36: 0 | O36: =N36*1.97 -> 0 | P36: 0 | Q36: =P36*16.59 -> 0 | R36: 0 | S36: =R36*17 -> 0 | BZ36: =K36+M36+AC36+AE36+I36+Q36+U36+W36+Y36+S36+O36 -> 0
A37: 29 | B37: Song San | H37: 0 | I37: =H37 -> 0 | J37: 0 | K37: =J37*0.684 -> 0 | L37: 0 | M37: =L37*0.93 -> 0 | N37: 0 | O37: =N37*1.97 -> 0 | P37: 0 | Q37: =P37*16.59 -> 0 | R37: 0 | S37: =R37*17 -> 0 | T37: 0 | U37: =T37*0.1 -> 0 | V37: 0 | W37: =V37*0.5 -> 0 | X37: 0 | Y37: =X37*0.8 -> 0 | Z37: 0 | AA37: =Z37*0.5 -> 0 | AB37: 0 | AC37: =AB37*0.4 -> 0 | AD37: 0 | AE37: =AD37*0.35 -> 0 | AF37: 0 | AG37: =AF37/25 -> 0 | AH37: 0 | AI37: =AH37*6.5 -> 0 | AJ37: 0 | AK37: =AJ37/80 -> 0 | AL37: 0 | AM37: =AL37/61.67 -> 0 | AN37: 0 | AO37: 0 | AP37: =AO37*4.5 -> 0 | AQ37: 0 | AR37: =AQ37/30 -> 0 | AS37: 0 | AT37: 0 | AU37: 0 | AV37: =AU37/25 -> 0 | AW37: 0 | AX37: =AW37*27/30 -> 0 | AY37: =AX37/27 -> 0 | AZ37: 0 | BA37: 0 | BB37: 0 | BC37: =AZ37*600/663.06/555 -> 0 | BD37: =BC37*23 -> 0 | BE37: 0 | BF37: =BE37/800 -> 0 | BG37: 0 | BH37: =BG37/100 -> 0 | BI37: 0 | BJ37: =BI37*0.2 -> 0 | BK37: 0 | BL37: =BK37/300 -> 0 | BM37: 0 | BN37: =BM37/150 -> 0 | BO37: 0 | BP37: =BO37*33/35 -> 0 | BQ37: =BP37*35 -> 0 | BR37: 0 | BS37: =ROUND(BR37*0.4,2) -> 0 | BT37: 0 | BU37: =BT37*0.75 -> 0 | BV37: 0 | BW37: =BV37*1.3333333333 -> 0 | BX37: 0 | BY37: =ROUND(BX37*1.43,2) -> 0 | BZ37: =K37+M37+AC37+AE37+I37+Q37+U37+W37+Y37+S37+O37 -> 0
A38: 30 | B38: But Mum | H38: 0 | I38: =H38 -> 0 | J38: 0 | K38: =J38*0.684 -> 0 | L38: 0 | M38: =L38*0.93 -> 0 | N38: 0 | O38: =N38*1.97 -> 0 | P38: 0 | Q38: =P38*16.59 -> 0 | R38: 0 | S38: =R38*17 -> 0 | T38: 0 | U38: =T38*0.1 -> 0 | V38: 0 | W38: =V38*0.5 -> 0 | X38: 0 | Y38: =X38*0.8 -> 0 | Z38: 0 | AA38: =Z38*0.5 -> 0 | AB38: 0 | AC38: =AB38*0.4 -> 0 | AD38: 0 | AE38: =AD38*0.35 -> 0 | AF38: 0 | AG38: =AF38/25 -> 0 | AH38: 0 | AI38: =AH38*6.5 -> 0 | AJ38: 0 | AK38: =AJ38/80 -> 0 | AL38: 0 | AM38: =AL38/61.67 -> 0 | AN38: 0 | AO38: 0 | AP38: =AO38*4.5 -> 0 | AQ38: 0 | AR38: =AQ38/30 -> 0 | AS38: 0 | AT38: 0 | AU38: 0 | AV38: =AU38/25 -> 0 | AW38: 0 | AX38: =AW38*27/30 -> 0 | AY38: =AX38/27 -> 0 | AZ38: 0 | BA38: 0 | BB38: 0 | BC38: =AZ38*600/663.06/555 -> 0 | BD38: =BC38*23 -> 0 | BE38: 0 | BF38: =BE38/800 -> 0 | BG38: 0 | BH38: =BG38/100 -> 0 | BI38: 0 | BJ38: =BI38*0.2 -> 0 | BK38: 0 | BL38: =BK38/300 -> 0 | BM38: 0 | BN38: =BM38/150 -> 0 | BO38: 0 | BP38: =BO38*33/35 -> 0 | BQ38: =BP38*35 -> 0 | BR38: 0 | BS38: =ROUND(BR38*0.4,2) -> 0 | BT38: 0 | BU38: =BT38*0.75 -> 0 | BV38: 0 | BW38: =BV38*1.3333333333 -> 0 | BX38: 0 | BY38: =ROUND(BX38*1.43,2) -> 0 | BZ38: =K38+M38+AC38+AE38+I38+Q38+U38+W38+Y38+S38+O38 -> 0
A39: 31 | B39: Say Hia | H39: 0 | I39: =H39 -> 0 | J39: 0 | K39: =J39*0.684 -> 0 | L39: 0 | M39: =L39*0.93 -> 0 | N39: 0 | O39: =N39*1.97 -> 0 | P39: 0 | Q39: =P39*16.59 -> 0 | R39: 0 | S39: =R39*17 -> 0 | T39: 0 | U39: =T39*0.1 -> 0 | V39: 0 | W39: =V39*0.5 -> 0 | X39: 0 | Y39: =X39*0.8 -> 0 | Z39: 0 | AA39: =Z39*0.5 -> 0 | AB39: 0 | AC39: =AB39*0.4 -> 0 | AD39: 0 | AE39: =AD39*0.35 -> 0 | AF39: 0 | AG39: =AF39/25 -> 0 | AH39: 0 | AI39: =AH39*6.5 -> 0 | AJ39: 0 | AK39: =AJ39/80 -> 0 | AL39: 0 | AM39: =AL39/61.67 -> 0 | AN39: 0 | AO39: 0 | AP39: =AO39*4.5 -> 0 | AQ39: 0 | AR39: =AQ39/30 -> 0 | AS39: 0 | AT39: 0 | AU39: 0 | AV39: =AU39/25 -> 0 | AW39: 0 | AX39: =AW39*27/30 -> 0 | AY39: =AX39/27 -> 0 | AZ39: 0 | BA39: 0 | BB39: 0 | BC39: =AZ39*600/663.06/555 -> 0 | BD39: =BC39*23 -> 0 | BE39: 0 | BF39: =BE39/800 -> 0 | BG39: 0 | BH39: =BG39/100 -> 0 | BI39: 0 | BJ39: =BI39*0.2 -> 0 | BK39: 0 | BL39: =BK39/300 -> 0 | BM39: 0 | BN39: =BM39/150 -> 0 | BO39: 0 | BP39: =BO39*33/35 -> 0 | BQ39: =BP39*35 -> 0 | BR39: 0 | BS39: =ROUND(BR39*0.4,2) -> 0 | BT39: 0 | BU39: =BT39*0.75 -> 0 | BV39: 0 | BW39: =BV39*1.3333333333 -> 0 | BX39: 0 | BY39: =ROUND(BX39*1.43,2) -> 0 | BZ39: =K39+M39+AC39+AE39+I39+Q39+U39+W39+Y39+S39+O39 -> 0
A40: 32 | B40: Sat Kia | H40: 0 | I40: =H40 -> 0 | J40: 0 | K40: =J40*0.684 -> 0 | L40: 0 | M40: =L40*0.93 -> 0 | N40: 0 | O40: =N40*1.97 -> 0 | P40: 0 | Q40: =P40*16.59 -> 0 | R40: 0 | S40: =R40*17 -> 0 | T40: 0 | U40: =T40*0.1 -> 0 | V40: 0 | W40: =V40*0.5 -> 0 | X40: 0 | Y40: =X40*0.8 -> 0 | Z40: 0 | AA40: =Z40*0.5 -> 0 | AB40: 0 | AC40: =AB40*0.4 -> 0 | AD40: 0 | AE40: =AD40*0.35 -> 0 | AF40: 0 | AG40: =AF40/25 -> 0 | AH40: 0 | AI40: =AH40*6.5 -> 0 | AJ40: 0 | AK40: =AJ40/80 -> 0 | AL40: 0 | AM40: =AL40/61.67 -> 0 | AN40: 0 | AO40: 0 | AP40: =AO40*4.5 -> 0 | AQ40: 0 | AR40: =AQ40/30 -> 0 | AS40: 0 | AT40: 0 | AU40: 0 | AV40: =AU40/25 -> 0 | AW40: 0 | AX40: =AW40*27/30 -> 0 | AY40: =AX40/27 -> 0 | AZ40: 0 | BA40: 0 | BB40: 0 | BC40: =AZ40*600/663.06/555 -> 0 | BD40: =BC40*23 -> 0 | BE40: 0 | BF40: =BE40/800 -> 0 | BG40: 0 | BH40: =BG40/100 -> 0 | BI40: 0 | BJ40: =BI40*0.2 -> 0 | BK40: 0 | BL40: =BK40/300 -> 0 | BM40: 0 | BN40: =BM40/150 -> 0 | BO40: 0 | BP40: =BO40*33/35 -> 0 | BQ40: =BP40*35 -> 0 | BR40: 0 | BS40: =ROUND(BR40*0.4,2) -> 0 | BT40: 0 | BU40: =BT40*0.75 -> 0 | BV40: 0 | BW40: =BV40*1.3333333333 -> 0 | BX40: 0 | BY40: =ROUND(BX40*1.43,2) -> 0 | BZ40: =K40+M40+AC40+AE40+I40+Q40+U40+W40+Y40+S40+O40 -> 0
A41: 33 | B41: Tem Tưa | H41: 0 | I41: =H41 -> 0 | J41: 0 | K41: =J41*0.684 -> 0 | L41: 0 | M41: =L41*0.93 -> 0 | N41: 0 | O41: =N41*1.97 -> 0 | P41: 0 | Q41: =P41*16.59 -> 0 | R41: 0 | S41: =R41*17 -> 0 | T41: 0 | U41: =T41*0.1 -> 0 | V41: 0 | W41: =V41*0.5 -> 0 | X41: 0 | Y41: =X41*0.8 -> 0 | Z41: 0 | AA41: =Z41*0.5 -> 0 | AB41: 0 | AC41: =AB41*0.4 -> 0 | AD41: 0 | AE41: =AD41*0.35 -> 0 | AF41: 0 | AG41: =AF41/25 -> 0 | AH41: 0 | AI41: =AH41*6.5 -> 0 | AJ41: 0 | AK41: =AJ41/80 -> 0 | AL41: 0 | AM41: =AL41/61.67 -> 0 | AN41: 0 | AO41: 0 | AP41: =AO41*4.5 -> 0 | AQ41: 0 | AR41: =AQ41/30 -> 0 | AS41: 0 | AT41: 0 | AU41: 0 | AV41: =AU41/25 -> 0 | AW41: 0 | AX41: =AW41*27/30 -> 0 | AY41: =AX41/27 -> 0 | AZ41: 0 | BA41: 0 | BB41: 0 | BC41: =AZ41*600/663.06/555 -> 0 | BD41: =BC41*23 -> 0 | BE41: 0 | BF41: =BE41/800 -> 0 | BG41: 0 | BH41: =BG41/100 -> 0 | BI41: 0 | BJ41: =BI41*0.2 -> 0 | BK41: 0 | BL41: =BK41/300 -> 0 | BM41: 0 | BN41: =BM41/150 -> 0 | BO41: 0 | BP41: =BO41*33/35 -> 0 | BQ41: =BP41*35 -> 0 | BR41: 0 | BS41: =ROUND(BR41*0.4,2) -> 0 | BT41: 0 | BU41: =BT41*0.75 -> 0 | BV41: 0 | BW41: =BV41*1.3333333333 -> 0 | BX41: 0 | BY41: =ROUND(BX41*1.43,2) -> 0 | BZ41: =K41+M41+AC41+AE41+I41+Q41+U41+W41+Y41+S41+O41 -> 0
A42: 34 | B42: Von Chia | H42: 0 | I42: =H42 -> 0 | J42: 0 | K42: =J42*0.684 -> 0 | L42: 0 | M42: =L42*0.931 -> 0 | N42: 0 | O42: =N42*1.97 -> 0 | P42: 0 | Q42: =P42*16.59 -> 0 | R42: 0 | S42: =R42*17 -> 0 | T42: 0 | U42: =T42*0.1 -> 0 | V42: 0 | W42: =V42*0.5 -> 0 | X42: 0 | Y42: =X42*0.8 -> 0 | Z42: 0 | AA42: =Z42*0.5 -> 0 | AB42: 0 | AC42: =AB42*0.4 -> 0 | AD42: 0 | AE42: =AD42*0.35 -> 0 | AF42: 0 | AG42: =AF42/25 -> 0 | AH42: 0 | AI42: =AH42*6.5 -> 0 | AJ42: 0 | AK42: =AJ42/80 -> 0 | AL42: 0 | AM42: =AL42/61.67 -> 0 | AN42: 0 | AO42: 0 | AP42: =AO42*4.5 -> 0 | AQ42: 0 | AR42: =AQ42/30 -> 0 | AS42: 0 | AT42: 0 | AU42: 0 | AV42: =AU42/25 -> 0 | AW42: 0 | AX42: =AW42*27/30 -> 0 | AY42: =AX42/27 -> 0 | AZ42: 0 | BA42: 0 | BB42: 0 | BC42: =AZ42*600/663.06/555 -> 0 | BD42: =BC42*23 -> 0 | BE42: 0 | BF42: =BE42/800 -> 0 | BG42: 0 | BH42: =BG42/100 -> 0 | BI42: 0 | BJ42: =BI42*0.2 -> 0 | BK42: 0 | BL42: =BK42/300 -> 0 | BM42: 0 | BN42: =BM42/150 -> 0 | BO42: 0 | BP42: =BO42*33/35 -> 0 | BQ42: =BP42*35 -> 0 | BR42: 0 | BS42: =ROUND(BR42*0.4,2) -> 0 | BT42: 0 | BU42: =BT42*0.75 -> 0 | BV42: 0 | BW42: =BV42*1.3333333333 -> 0 | BX42: 0 | BY42: =ROUND(BX42*1.43,2) -> 0 | BZ42: =K42+M42+AC42+AE42+I42+Q42+U42+W42+Y42+S42+O42 -> 0
...

Sheet TTTL tổ 4
A1: CÔNG TY TNHH CAO SU MEKONG | J1: VƯƠNG QUỐC CAMPUCHIA
A2: ĐƠN VỊ: NÔNG TRƯỜNG II | J2: Dân tộc - Tôn giáo - Quốc vương
A4: BẢNG THANH TOÁN LƯƠNG CÔNG NHÂN CAMPUCHIA TỔ 4
A5: THÁNG 12 NĂM 2016
N7: ĐVT: Riel
A8: STT | B8: Họ và tên | C8: Định mức 22.000 Riel/công | D8: Tổng công | E8: Thành tiền | F8: Lương làm thêm giờ | G8: Lương thưởng tết | H8: Tổng lương | I8: Công nợ | L8: Tổng nợ | M8: Thực nhận | N8: KÝ NHẬN
F9: Công | I9: T/ứ lương | J9: TNCN | K9: Tiền đóng bảo hiểm
A10: A | B10: B | C10: 1 | D10: 2 | E10: 3=1*2 | F10: 4 | G10: 5 | H10: 6=3+5 | I10: 7 | J10: 8 | K10: 9 | L10: 10=7+8+9 | M10: 11=6-10 | N10: 12
A11: ='KL tổ 4'!A9 -> 1 | B11: ='KL tổ 4'!B9 -> Rat Non | C11: 22000 | D11: ='KL tổ 4'!BZ9 -> 0 | E11: 0 | F11: 0 | G11: 0 | H11: =E11+G11 -> 0 | I11: 0 | J11: =ROUND(IF(H11<=800000,0,IF(AND((H11-'[1]Gia cảnh 2 '!I6)>800000,(H11-'[1]Gia cảnh 2 '!I6)<=1250000),(H11-'[1]Gia cảnh 2 '!I6)*5%-40000,IF(AND((H11-'[1]Gia cảnh 2 '!I6)>1250000,(H11-'[1]Gia cảnh 2 '!I6)<=8500000),(H11-'[1]Gia cảnh 2 '!I6)*10%-102500))),2) -> 0 | K11: 1600 | L11: 0 | M11: 0
A12: ='KL tổ 4'!A10 -> 2 | B12: ='KL tổ 4'!B10 -> Dâm Vanh | C12: 22000 | D12: ='KL tổ 4'!BZ10 -> 0 | E12: 0 | F12: 0 | G12: 0 | H12: =E12+G12 -> 0 | I12: 0 | J12: 0 | K12: =IF(H12<=200000,1600,IF(AND(H12>200000,H12<=250000),1800,IF(AND(H12>250000,H12<=300000),2200,IF(AND(H12>300000,H12<=350000),2600,IF(AND(H12>350000,H12<=400000),3000,IF(AND(H12>400000,H12<=450000),3400,IF(AND(H12>450000,H12<=500000),3800,IF(AND(H12>500000,H12<=550000),4200,IF(AND(H12>550000,H12<=600000),4600,IF(AND(H12>600000,H12<=650000),5000,IF(AND(H12>650000,H12<=700000),5400,IF(AND(H12>700000,H12<=750000),5800,IF(AND(H12>750000,H12<=800000),6200,IF(AND(H12>800000,H12<=850000),6600,IF(AND(H12>850000,H12<=900000),7000,IF(AND(H12>900000,H12<=950000),7400,IF(AND(H12>950000,H12<=1000000),7800,IF(H12>1000000,8000)))))))))))))))))) -> 1600 | L12: 0 | M12: =IF(L12>0,H12-L12,H12) -> 0
A13: ='KL tổ 4'!A11 -> 3 | B13: ='KL tổ 4'!B11 -> Sa Mêt | C13: 22000 | D13: ='KL tổ 4'!BZ11 -> 0 | E13: 0 | F13: 0 | G13: 0 | H13: =E13+G13 -> 0 | I13: 0 | J13: =ROUND(IF(H13<=800000,0,IF(AND((H13-'[1]Gia cảnh 2 '!I8)>800000,(H13-'[1]Gia cảnh 2 '!I8)<=1250000),(H13-'[1]Gia cảnh 2 '!I8)*5%-40000,IF(AND((H13-'[1]Gia cảnh 2 '!I8)>1250000,(H13-'[1]Gia cảnh 2 '!I8)<=8500000),(H13-'[1]Gia cảnh 2 '!I8)*10%-102500))),2) -> 0 | K13: =IF(H13<=200000,1600,IF(AND(H13>200000,H13<=250000),1800,IF(AND(H13>250000,H13<=300000),2200,IF(AND(H13>300000,H13<=350000),2600,IF(AND(H13>350000,H13<=400000),3000,IF(AND(H13>400000,H13<=450000),3400,IF(AND(H13>450000,H13<=500000),3800,IF(AND(H13>500000,H13<=550000),4200,IF(AND(H13>550000,H13<=600000),4600,IF(AND(H13>600000,H13<=650000),5000,IF(AND(H13>650000,H13<=700000),5400,IF(AND(H13>700000,H13<=750000),5800,IF(AND(H13>750000,H13<=800000),6200,IF(AND(H13>800000,H13<=850000),6600,IF(AND(H13>850000,H13<=900000),7000,IF(AND(H13>900000,H13<=950000),7400,IF(AND(H13>950000,H13<=1000000),7800,IF(H13>1000000,8000)))))))))))))))))) -> 1600 | L13: 0 | M13: =IF(L13>0,H13-L13,H13) -> 0
A14: ='KL tổ 4'!A12 -> 4 | B14: ='KL tổ 4'!B12 -> Nu Rươn | C14: 22000 | D14: ='KL tổ 4'!BZ12 -> 0 | E14: 0 | F14: 0 | G14: 0 | H14: =E14+G14 -> 0 | I14: 0 | J14: =ROUND(IF(H14<=800000,0,IF(AND((H14-'[1]Gia cảnh 2 '!I9)>800000,(H14-'[1]Gia cảnh 2 '!I9)<=1250000),(H14-'[1]Gia cảnh 2 '!I9)*5%-40000,IF(AND((H14-'[1]Gia cảnh 2 '!I9)>1250000,(H14-'[1]Gia cảnh 2 '!I9)<=8500000),(H14-'[1]Gia cảnh 2 '!I9)*10%-102500))),2) -> 0 | K14: =IF(H14<=200000,1600,IF(AND(H14>200000,H14<=250000),1800,IF(AND(H14>250000,H14<=300000),2200,IF(AND(H14>300000,H14<=350000),2600,IF(AND(H14>350000,H14<=400000),3000,IF(AND(H14>400000,H14<=450000),3400,IF(AND(H14>450000,H14<=500000),3800,IF(AND(H14>500000,H14<=550000),4200,IF(AND(H14>550000,H14<=600000),4600,IF(AND(H14>600000,H14<=650000),5000,IF(AND(H14>650000,H14<=700000),5400,IF(AND(H14>700000,H14<=750000),5800,IF(AND(H14>750000,H14<=800000),6200,IF(AND(H14>800000,H14<=850000),6600,IF(AND(H14>850000,H14<=900000),7000,IF(AND(H14>900000,H14<=950000),7400,IF(AND(H14>950000,H14<=1000000),7800,IF(H14>1000000,8000)))))))))))))))))) -> 1600 | L14: 0 | M14: =IF(L14>0,H14-L14,H14) -> 0
