Workbook

Sheet Chấm công KT
B1: CỘNG HÒA DÂN CHỦ NHÂN DÂN LÀO
B2: Hòa Bình -Độc Lập - Dân Chủ - thống Nhất - Thịnh Vượng
B3: -----o0o-----
B5: CÔNG TY TNHH CP QUASA - GERUCO LÀO
B6: ĐỘI SẢN XUẤT SỐ 04
B7: BẢNG CHẤM CÔNG PHỤ CẤP CHO CÔNG NHÂN KHAI THÁC THÁNG 05 NĂM 2025
A8: (Từ ngày 01 đến 31/05/2025)
A10: STT | B10: STT | C10: HỌ VÀ TÊN | D10: BẢN | E10: Phụ cấp ngày cạo, ngày chủ nhật | AJ10: Ngày công đi cạo thường (x) | AK10: Ngày CN thường (cn) | AL10: Ngày công đi cạo 2 lát (đ) | AM10: Ngày công chủ nhật cạo 2 lát (đc) | AN10: Ngày công cạo gia tăng 2 miêng (gt) | AO10: Ngày chủ nhật cạo gia tăng 2 miệng (ct) | AP10: Tổng công | AQ10: Kí tên | AU10: Ngày công đi cạo thường (x) | AV10: Ngày CN thường (cn) | AW10: Ngày công đi cạo 2 lát (đ) | AX10: Ngày công chủ nhật cạo 2 lát (đc) | AY10: Ngày công cạo gia tăng 2 miêng (gt) | AZ10: Ngày chủ nhật cạo gia tăng 2 miệng (ct)
E11: 1 | F11: 2 | G11: 3 | H11: 4 | I11: 5 | J11: 6 | K11: 7 | L11: 8 | M11: 9 | N11: 10 | O11: 11 | P11: 12 | Q11: 13 | R11: 14 | S11: 15 | T11: 16 | U11: 17 | V11: 18 | W11: 19 | X11: 20 | Y11: 21 | Z11: 22 | AA11: 23 | AB11: 24 | AC11: 25 | AD11: 26 | AE11: 27 | AF11: 28 | AG11: 29 | AH11: 30 | AI11: 31
B12: Trạm 1 | E12: =SUM(COUNTIF(E13:E92,"x"))+(COUNTIF(E13:E92,"cn"))+(COUNTIF(E13:E92,"gt"))+(COUNTIF(E13:E92,"ct")) -> 66 | F12: =SUM(COUNTIF(F13:F92,"x"))+(COUNTIF(F13:F92,"cn"))+(COUNTIF(F13:F92,"gt"))+(COUNTIF(F13:F92,"ct")) -> 60 | G12: =SUM(COUNTIF(G13:G92,"x"))+(COUNTIF(G13:G92,"cn"))+(COUNTIF(G13:G92,"gt"))+(COUNTIF(G13:G92,"ct")) -> 60 | H12: =SUM(COUNTIF(H13:H92,"x"))+(COUNTIF(H13:H92,"cn"))+(COUNTIF(H13:H92,"gt"))+(COUNTIF(H13:H92,"ct")) -> 59 | I12: =SUM(COUNTIF(I13:I92,"x"))+(COUNTIF(I13:I92,"cn"))+(COUNTIF(I13:I92,"gt"))+(COUNTIF(I13:I92,"ct")) -> 65 | J12: =SUM(COUNTIF(J13:J92,"x"))+(COUNTIF(J13:J92,"cn"))+(COUNTIF(J13:J92,"gt"))+(COUNTIF(J13:J92,"ct")) -> 58 | K12: =SUM(COUNTIF(K13:K92,"x"))+(COUNTIF(K13:K92,"cn"))+(COUNTIF(K13:K92,"gt"))+(COUNTIF(K13:K92,"ct")) -> 52 | L12: =SUM(COUNTIF(L13:L92,"x"))+(COUNTIF(L13:L92,"cn"))+(COUNTIF(L13:L92,"gt"))+(COUNTIF(L13:L92,"ct")) -> 67 | ... AH12: =SUM(COUNTIF(AH13:AH92,"x"))+(COUNTIF(AH13:AH92,"cn"))+(COUNTIF(AH13:AH92,"gt"))+(COUNTIF(AH13:AH92,"ct")) -> 71 | AI12: =SUM(COUNTIF(AI13:AI92,"x"))+(COUNTIF(AI13:AI92,"cn"))+(COUNTIF(AI13:AI92,"đ")) -> 73 | AJ12: =SUM(AJ13:AJ92) -> 1842 | AK12: =SUM(AK13:AK92) -> 271 | AL12: =SUM(AL13:AL92) -> 0 | AM12: =SUM(AM13:AM92) -> 0 | AN12: =SUM(AN13:AN92) -> 0 | AO12: =SUM(AO13:AO92) -> 0 | AP12: =SUM(AP13:AP92) -> 2113 | AS12: =VLOOKUP(C13,'[1]NT 2'!$C$2:$J$259,8,0) -> 03456 | AT12: =D13-AS12 -> 0
A13: 1 | B13: 1 | C13: T. Vôn | D13: =VLOOKUP(C13,'[1]NT 2'!$C$2:$J$259,8,0) -> 03456 | E13: x | F13: x | H13: cn | I13: x | J13: x | K13: x | L13: x | M13: x | N13: x | O13: cn | P13: x | Q13: x | R13: x | T13: x | U13: x | V13: cn | W13: x | X13: x | Y13: x | Z13: x | AA13: x | AB13: tt | AC13: cn | AD13: x | AE13: x | AF13: x | AG13: x | AH13: x | AI13: tt | AJ13: =SUM(COUNTIF(E13:AI13,"x")) -> 23 | AK13: =SUM(COUNTIF(E13:AI13,"cn")) -> 4 | AL13: =SUM(COUNTIF(E13:AI13,"đ")) -> 0 | AM13: =SUM(COUNTIF(E13:AI13,"đc")) -> 0 | AN13: =SUM(COUNTIF(E13:AI13,"gt")) -> 0 | AO13: =SUM(COUNTIF(E13:AI13,"ct")) -> 0 | AP13: =AJ13+AK13+AL13+AM13+AN13+AO13 -> 27 | AS13: =VLOOKUP(C14,'[1]NT 2'!$C$2:$J$259,8,0) -> #N/A | AT13: =D14-AS13 -> #N/A
A14: 2 | B14: 2 | C14: T. Feng | E14: x | F14: x | G14: x | H14: cn | I14: x | L14: x | M14: x | O14: cn | P14: x | Q14: x | R14: x | S14: x | T14: x | U14: x | V14: cn | W14: x | X14: x | Y14: x | Z14: x | AA14: x | AB14: x | AC14: cn | AD14: x | AE14: x | AG14: x | AH14: x | AI14: x | AJ14: =SUM(COUNTIF(E14:AI14,"x")) -> 23 | AK14: =SUM(COUNTIF(E14:AI14,"cn")) -> 4 | AL14: =SUM(COUNTIF(E14:AI14,"đ")) -> 0 | AM14: =SUM(COUNTIF(E14:AI14,"đc")) -> 0 | AN14: =SUM(COUNTIF(E14:AI14,"gt")) -> 0 | AO14: =SUM(COUNTIF(E14:AI14,"ct")) -> 0 | AP14: =AJ14+AK14+AL14+AM14+AN14+AO14 -> 27 | AS14: =VLOOKUP(C15,'[1]NT 2'!$C$2:$J$259,8,0) -> 02725 | AT14: =D15-AS14 -> 0
A15: 3 | B15: 3 | C15: T. Sa Văn | D15: =VLOOKUP(C15,'[1]NT 2'!$C$2:$J$259,8,0) -> 02725 | E15: x | F15: x | G15: x | H15: cn | J15: x | K15: x | L15: x | M15: x | N15: x | O15: cn | P15: x | Q15: x | R15: x | S15: x | T15: x | U15: x | V15: cn | W15: x | X15: x | Y15: x | Z15: x | AA15: x | AB15: x | AC15: cn | AD15: x | AE15: x | AF15: x | AG15: x | AH15: x | AI15: x | AJ15: =SUM(COUNTIF(E15:AI15,"x")) -> 26 | AK15: =SUM(COUNTIF(E15:AI15,"cn")) -> 4 | AL15: =SUM(COUNTIF(E15:AI15,"đ")) -> 0 | AM15: =SUM(COUNTIF(E15:AI15,"đc")) -> 0 | AN15: =SUM(COUNTIF(E15:AI15,"gt")) -> 0 | AO15: =SUM(COUNTIF(E15:AI15,"ct")) -> 0 | AP15: =AJ15+AK15+AL15+AM15+AN15+AO15 -> 30 | AS15: =VLOOKUP(C16,'[1]NT 2'!$C$2:$J$259,8,0) -> #N/A | AT15: =D16-AS15 -> #N/A
A16: 4 | B16: 4 | C16: Lăm Ma Thu | D16: =VLOOKUP(C16,'[1]NT 2'!$C$2:$J$259,8,0) -> #N/A | E16: x | F16: x | G16: x | H16: cn | I16: x | J16: x | K16: x | L16: x | M16: x | N16: x | O16: cn | P16: x | Q16: x | S16: x | T16: x | U16: x | V16: cn | W16: x | X16: x | Y16: x | AA16: x | AB16: x | AC16: cn | AD16: x | AE16: x | AF16: x | AG16: x | AH16: x | AI16: x | AJ16: =SUM(COUNTIF(E16:AI16,"x")) -> 25 | AK16: =SUM(COUNTIF(E16:AI16,"cn")) -> 4 | AL16: =SUM(COUNTIF(E16:AI16,"đ")) -> 0 | AM16: =SUM(COUNTIF(E16:AI16,"đc")) -> 0 | AN16: =SUM(COUNTIF(E16:AI16,"gt")) -> 0 | AO16: =SUM(COUNTIF(E16:AI16,"ct")) -> 0 | AP16: =AJ16+AK16+AL16+AM16+AN16+AO16 -> 29 | AS16: =VLOOKUP(C17,'[1]NT 2'!$C$2:$J$259,8,0) -> 03459 | AT16: =D17-AS16 -> 0
A17: 5 | B17: 5 | C17: N. Vạt | D17: =VLOOKUP(C17,'[1]NT 2'!$C$2:$J$259,8,0) -> 03459 | E17: x | G17: x | H17: cn | L17: x | M17: x | N17: x | O17: cn | P17: x | Q17: x | R17: x | U17: x | W17: x | X17: x | Y17: x | Z17: tt | AA17: x | AB17: x | AC17: cn | AD17: x | AE17: x | AF17: x | AG17: x | AH17: x | AI17: x | AJ17: =SUM(COUNTIF(E17:AI17,"x")) -> 20 | AK17: =SUM(COUNTIF(E17:AI17,"cn")) -> 3 | AL17: =SUM(COUNTIF(E17:AI17,"đ")) -> 0 | AM17: =SUM(COUNTIF(E17:AI17,"đc")) -> 0 | AN17: =SUM(COUNTIF(E17:AI17,"gt")) -> 0 | AO17: =SUM(COUNTIF(E17:AI17,"ct")) -> 0 | AP17: =AJ17+AK17+AL17+AM17+AN17+AO17 -> 23 | AS17: =VLOOKUP(C18,'[1]NT 2'!$C$2:$J$259,8,0) -> #N/A | AT17: =D18-AS17 -> #N/A
A18: 6 | B18: 6 | C18: N. Kay Son | D18: =VLOOKUP(C18,'[1]NT 2'!$C$2:$J$259,8,0) -> #N/A | E18: x | F18: x | I18: x | M18: x | N18: x | O18: cn | P18: x | Q18: x | S18: x | T18: x | U18: x | V18: cn | W18: x | X18: x | Y18: x | Z18: x | AA18: x | AB18: x | AC18: cn | AD18: x | AE18: x | AF18: x | AG18: x | AH18: x | AI18: x | AJ18: =SUM(COUNTIF(E18:AI18,"x")) -> 22 | AK18: =SUM(COUNTIF(E18:AI18,"cn")) -> 3 | AL18: =SUM(COUNTIF(E18:AI18,"đ")) -> 0 | AM18: =SUM(COUNTIF(E18:AI18,"đc")) -> 0 | AN18: =SUM(COUNTIF(E18:AI18,"gt")) -> 0 | AO18: =SUM(COUNTIF(E18:AI18,"ct")) -> 0 | AP18: =AJ18+AK18+AL18+AM18+AN18+AO18 -> 25 | AS18: =VLOOKUP(C19,'[1]NT 2'!$C$2:$J$259,8,0) -> #N/A | AT18: =D19-AS18 -> #N/A
A19: 7 | B19: 7 | C19: T. Đèng 1 | D19: =VLOOKUP(C19,'[1]NT 2'!$C$2:$J$259,8,0) -> #N/A | E19: x | F19: x | G19: x | H19: cn | I19: x | J19: x | K19: x | L19: x | M19: x | N19: x | O19: cn | P19: x | Q19: x | R19: x | S19: x | T19: x | U19: x | V19: cn | W19: x | X19: x | Y19: x | Z19: x | AA19: x | AB19: x | AC19: cn | AD19: x | AE19: x | AF19: x | AG19: x | AH19: x | AI19: x | AJ19: =SUM(COUNTIF(E19:AI19,"x")) -> 27 | AK19: =SUM(COUNTIF(E19:AI19,"cn")) -> 4 | AL19: =SUM(COUNTIF(E19:AI19,"đ")) -> 0 | AM19: =SUM(COUNTIF(E19:AI19,"đc")) -> 0 | AN19: =SUM(COUNTIF(E19:AI19,"gt")) -> 0 | AO19: =SUM(COUNTIF(E19:AI19,"ct")) -> 0 | AP19: =AJ19+AK19+AL19+AM19+AN19+AO19 -> 31 | AS19: =VLOOKUP(C20,'[1]NT 2'!$C$2:$J$259,8,0) -> 03462 | AT19: =D20-AS19 -> 0
A20: 8 | B20: 8 | C20: T . Bua Ngân | D20: =VLOOKUP(C20,'[1]NT 2'!$C$2:$J$259,8,0) -> 03462 | E20: x | F20: x | G20: x | H20: cn | I20: x | J20: x | K20: x | L20: x | M20: x | N20: x | O20: cn | P20: x | R20: x | S20: x | T20: x | U20: x | W20: x | X20: x | Y20: x | Z20: x | AA20: x | AB20: x | AC20: cn | AD20: x | AE20: x | AF20: x | AG20: x | AH20: x | AI20: x | AJ20: =SUM(COUNTIF(E20:AI20,"x")) -> 26 | AK20: =SUM(COUNTIF(E20:AI20,"cn")) -> 3 | AL20: =SUM(COUNTIF(E20:AI20,"đ")) -> 0 | AM20: =SUM(COUNTIF(E20:AI20,"đc")) -> 0 | AN20: =SUM(COUNTIF(E20:AI20,"gt")) -> 0 | AO20: =SUM(COUNTIF(E20:AI20,"ct")) -> 0 | AP20: =AJ20+AK20+AL20+AM20+AN20+AO20 -> 29 | AS20: =VLOOKUP(C21,'[1]NT 2'!$C$2:$J$259,8,0) -> 03463 | AT20: =D21-AS20 -> 0
A21: 9 | B21: 9 | C21: T Căng | D21: =VLOOKUP(C21,'[1]NT 2'!$C$2:$J$259,8,0) -> 03463 | E21: x | F21: x | G21: x | I21: x | J21: x | K21: x | L21: x | M21: x | N21: x | O21: cn | P21: x | Q21: x | R21: x | S21: x | T21: x | U21: x | V21: cn | W21: x | X21: x | Y21: x | Z21: x | AA21: x | AB21: x | AC21: cn | AD21: x | AE21: x | AF21: x | AG21: x | AH21: x | AI21: x | AJ21: =SUM(COUNTIF(E21:AI21,"x")) -> 27 | AK21: =SUM(COUNTIF(E21:AI21,"cn")) -> 3 | AL21: =SUM(COUNTIF(E21:AI21,"đ")) -> 0 | AM21: =SUM(COUNTIF(E21:AI21,"đc")) -> 0 | AN21: =SUM(COUNTIF(E21:AI21,"gt")) -> 0 | AO21: =SUM(COUNTIF(E21:AI21,"ct")) -> 0 | AP21: =AJ21+AK21+AL21+AM21+AN21+AO21 -> 30 | AS21: =VLOOKUP(C22,'[1]NT 2'!$C$2:$J$259,8,0) -> 03464 | AT21: =D22-AS21 -> 0
A22: 10 | B22: 10 | C22: N. Phôn 1 | D22: =VLOOKUP(C22,'[1]NT 2'!$C$2:$J$259,8,0) -> 03464 | E22: x | F22: x | G22: x | I22: x | J22: x | K22: x | L22: x | M22: x | N22: x | O22: cn | P22: x | Q22: x | R22: x | S22: x | T22: x | U22: x | V22: cn | W22: x | X22: x | Y22: x | Z22: x | AA22: x | AB22: x | AC22: cn | AD22: x | AE22: x | AF22: x | AG22: x | AH22: x | AI22: x | AJ22: =SUM(COUNTIF(E22:AI22,"x")) -> 27 | AK22: =SUM(COUNTIF(E22:AI22,"cn")) -> 3 | AL22: =SUM(COUNTIF(E22:AI22,"đ")) -> 0 | AM22: =SUM(COUNTIF(E22:AI22,"đc")) -> 0 | AN22: =SUM(COUNTIF(E22:AI22,"gt")) -> 0 | AO22: =SUM(COUNTIF(E22:AI22,"ct")) -> 0 | AP22: =AJ22+AK22+AL22+AM22+AN22+AO22 -> 30 | AS22: =VLOOKUP(C23,'[1]NT 2'!$C$2:$J$259,8,0) -> 03465 | AT22: =D23-AS22 -> 0
A23: 11 | B23: 11 | C23: T. In Păn | D23: =VLOOKUP(C23,'[1]NT 2'!$C$2:$J$259,8,0) -> 03465 | F23: x | H23: cn | I23: x | J23: x | L23: x | M23: x | N23: x | O23: cn | P23: x | Q23: x | R23: x | S23: x | T23: x | U23: x | V23: cn | W23: x | X23: x | Y23: x | Z23: x | AA23: x | AB23: x | AC23: cn | AD23: x | AE23: x | AF23: x | AG23: x | AH23: x | AI23: tt | AJ23: =SUM(COUNTIF(E23:AI23,"x")) -> 23 | AK23: =SUM(COUNTIF(E23:AI23,"cn")) -> 4 | AL23: =SUM(COUNTIF(E23:AI23,"đ")) -> 0 | AM23: =SUM(COUNTIF(E23:AI23,"đc")) -> 0 | AN23: =SUM(COUNTIF(E23:AI23,"gt")) -> 0 | AO23: =SUM(COUNTIF(E23:AI23,"ct")) -> 0 | AP23: =AJ23+AK23+AL23+AM23+AN23+AO23 -> 27 | AS23: =VLOOKUP(C24,'[1]NT 2'!$C$2:$J$259,8,0) -> 03466 | AT23: =D24-AS23 -> 0
A24: 12 | B24: 12 | C24: N. Keo | D24: =VLOOKUP(C24,'[1]NT 2'!$C$2:$J$259,8,0) -> 03466 | E24: x | F24: x | H24: cn | I24: x | J24: x | K24: x | L24: x | M24: x | N24: x | O24: cn | P24: x | Q24: x | R24: x | S24: x | T24: x | U24: x | V24: cn | W24: x | X24: x | Y24: x | Z24: x | AA24: x | AB24: x | AC24: cn | AD24: x | AE24: x | AF24: x | AG24: x | AH24: x | AI24: x | AJ24: =SUM(COUNTIF(E24:AI24,"x")) -> 26 | AK24: =SUM(COUNTIF(E24:AI24,"cn")) -> 4 | AL24: =SUM(COUNTIF(E24:AI24,"đ")) -> 0 | AM24: =SUM(COUNTIF(E24:AI24,"đc")) -> 0 | AN24: =SUM(COUNTIF(E24:AI24,"gt")) -> 0 | AO24: =SUM(COUNTIF(E24:AI24,"ct")) -> 0 | AP24: =AJ24+AK24+AL24+AM24+AN24+AO24 -> 30 | AS24: =VLOOKUP(C25,'[1]NT 2'!$C$2:$J$259,8,0) -> 02727 | AT24: =D25-AS24 -> 0
A25: 13 | B25: 13 | C25: T. Thong Đon | D25: =VLOOKUP(C25,'[1]NT 2'!$C$2:$J$259,8,0) -> 02727 | E25: x | I25: x | J25: x | K25: x | L25: x | M25: x | N25: x | O25: cn | P25: x | Q25: x | R25: x | S25: x | T25: x | U25: x | V25: cn | W25: x | X25: x | Y25: x | Z25: x | AA25: x | AB25: tt | AC25: cn | AD25: x | AE25: x | AF25: x | AG25: x | AH25: x | AI25: x | AJ25: =SUM(COUNTIF(E25:AI25,"x")) -> 24 | AK25: =SUM(COUNTIF(E25:AI25,"cn")) -> 3 | AL25: =SUM(COUNTIF(E25:AI25,"đ")) -> 0 | AM25: =SUM(COUNTIF(E25:AI25,"đc")) -> 0 | AN25: =SUM(COUNTIF(E25:AI25,"gt")) -> 0 | AO25: =SUM(COUNTIF(E25:AI25,"ct")) -> 0 | AP25: =AJ25+AK25+AL25+AM25+AN25+AO25 -> 27 | AS25: =VLOOKUP(C26,'[1]NT 2'!$C$2:$J$259,8,0) -> 03467 | AT25: =D26-AS25 -> 0
A26: 14 | B26: 14 | C26: T. Hin | D26: =VLOOKUP(C26,'[1]NT 2'!$C$2:$J$259,8,0) -> 03467 | E26: x | F26: x | G26: x | H26: cn | I26: x | J26: x | K26: x | L26: x | M26: x | N26: x | O26: cn | P26: x | Q26: x | R26: x | S26: x | T26: x | U26: x | V26: cn | W26: x | X26: x | Y26: x | Z26: x | AA26: x | AB26: x | AC26: cn | AD26: x | AE26: x | AF26: x | AG26: x | AH26: x | AI26: x | AJ26: =SUM(COUNTIF(E26:AI26,"x")) -> 27 | AK26: =SUM(COUNTIF(E26:AI26,"cn")) -> 4 | AL26: =SUM(COUNTIF(E26:AI26,"đ")) -> 0 | AM26: =SUM(COUNTIF(E26:AI26,"đc")) -> 0 | AN26: =SUM(COUNTIF(E26:AI26,"gt")) -> 0 | AO26: =SUM(COUNTIF(E26:AI26,"ct")) -> 0 | AP26: =AJ26+AK26+AL26+AM26+AN26+AO26 -> 31 | AS26: =VLOOKUP(C27,'[1]NT 2'!$C$2:$J$259,8,0) -> #N/A | AT26: =D27-AS26 -> #N/A
A27: 15 | B27: 15 | C27: N. Ly Phon | D27: =VLOOKUP(C27,'[1]NT 2'!$C$2:$J$259,8,0) -> #N/A | E27: x | F27: x | G27: x | H27: cn | I27: x | J27: x | K27: x | L27: x | M27: x | N27: x | O27: cn | P27: x | Q27: x | R27: x | S27: x | T27: x | U27: x | V27: cn | W27: x | X27: x | Y27: x | Z27: x | AA27: x | AB27: x | AC27: cn | AD27: x | AE27: x | AF27: x | AG27: x | AH27: x | AI27: x | AJ27: =SUM(COUNTIF(E27:AI27,"x")) -> 27 | AK27: =SUM(COUNTIF(E27:AI27,"cn")) -> 4 | AL27: =SUM(COUNTIF(E27:AI27,"đ")) -> 0 | AM27: =SUM(COUNTIF(E27:AI27,"đc")) -> 0 | AN27: =SUM(COUNTIF(E27:AI27,"gt")) -> 0 | AO27: =SUM(COUNTIF(E27:AI27,"ct")) -> 0 | AP27: =AJ27+AK27+AL27+AM27+AN27+AO27 -> 31 | AS27: =VLOOKUP(C28,'[1]NT 2'!$C$2:$J$259,8,0) -> 03469 | AT27: =D28-AS27 -> 0
A28: 16 | B28: 16 | C28: T. Xôm Va Nít | D28: =VLOOKUP(C28,'[1]NT 2'!$C$2:$J$259,8,0) -> 03469 | E28: x | F28: x | H28: cn | I28: x | J28: x | K28: x | L28: x | M28: x | N28: x | O28: cn | P28: x | Q28: x | R28: x | S28: x | T28: x | U28: x | V28: cn | W28: x | X28: x | Y28: x | Z28: x | AA28: x | AB28: x | AC28: cn | AD28: x | AE28: x | AF28: x | AG28: x | AH28: x | AI28: x | AJ28: =SUM(COUNTIF(E28:AI28,"x")) -> 26 | AK28: =SUM(COUNTIF(E28:AI28,"cn")) -> 4 | AL28: =SUM(COUNTIF(E28:AI28,"đ")) -> 0 | AM28: =SUM(COUNTIF(E28:AI28,"đc")) -> 0 | AN28: =SUM(COUNTIF(E28:AI28,"gt")) -> 0 | AO28: =SUM(COUNTIF(E28:AI28,"ct")) -> 0 | AP28: =AJ28+AK28+AL28+AM28+AN28+AO28 -> 30 | AS28: =VLOOKUP(C29,'[1]NT 2'!$C$2:$J$259,8,0) -> 03470 | AT28: =D29-AS28 -> 0
A29: 17 | B29: 17 | C29: T. Lọi | D29: =VLOOKUP(C29,'[1]NT 2'!$C$2:$J$259,8,0) -> 03470 | E29: x | G29: x | H29: cn | L29: x | M29: x | N29: x | O29: cn | P29: x | Q29: x | R29: x | S29: x | U29: tt | W29: x | X29: x | Y29: x | Z29: tt | AA29: x | AB29: x | AC29: cn | AD29: x | AE29: x | AF29: x | AG29: x | AH29: x | AI29: x | AJ29: =SUM(COUNTIF(E29:AI29,"x")) -> 20 | AK29: =SUM(COUNTIF(E29:AI29,"cn")) -> 3 | AL29: =SUM(COUNTIF(E29:AI29,"đ")) -> 0 | AM29: =SUM(COUNTIF(E29:AI29,"đc")) -> 0 | AN29: =SUM(COUNTIF(E29:AI29,"gt")) -> 0 | AO29: =SUM(COUNTIF(E29:AI29,"ct")) -> 0 | AP29: =AJ29+AK29+AL29+AM29+AN29+AO29 -> 23 | AS29: =VLOOKUP(C30,'[1]NT 2'!$C$2:$J$259,8,0) -> 03471 | AT29: =D30-AS29 -> 0
A30: 18 | B30: 18 | C30: T. Phô Thong | D30: =VLOOKUP(C30,'[1]NT 2'!$C$2:$J$259,8,0) -> 03471 | E30: x | F30: x | G30: x | H30: cn | I30: x | J30: x | K30: x | L30: x | M30: x | N30: x | O30: cn | P30: x | Q30: x | R30: x | S30: x | T30: x | U30: x | V30: cn | W30: x | X30: x | Y30: x | Z30: x | AA30: x | AB30: x | AC30: cn | AD30: x | AE30: x | AF30: x | AG30: x | AH30: x | AI30: x | AJ30: =SUM(COUNTIF(E30:AI30,"x")) -> 27 | AK30: =SUM(COUNTIF(E30:AI30,"cn")) -> 4 | AL30: =SUM(COUNTIF(E30:AI30,"đ")) -> 0 | AM30: =SUM(COUNTIF(E30:AI30,"đc")) -> 0 | AN30: =SUM(COUNTIF(E30:AI30,"gt")) -> 0 | AO30: =SUM(COUNTIF(E30:AI30,"ct")) -> 0 | AP30: =AJ30+AK30+AL30+AM30+AN30+AO30 -> 31 | AS30: =VLOOKUP(C31,'[1]NT 2'!$C$2:$J$259,8,0) -> 03472 | AT30: =D31-AS30 -> 0
A31: 19 | B31: 19 | C31: N. Soi | D31: =VLOOKUP(C31,'[1]NT 2'!$C$2:$J$259,8,0) -> 03472 | E31: x | F31: x | G31: x | I31: x | J31: x | K31: x | L31: x | M31: x | N31: x | O31: cn | P31: x | Q31: x | R31: x | S31: x | T31: x | U31: x | V31: cn | W31: x | X31: x | Y31: x | Z31: x | AA31: x | AB31: x | AC31: cn | AD31: x | AE31: x | AF31: x | AG31: x | AH31: x | AI31: x | AJ31: =SUM(COUNTIF(E31:AI31,"x")) -> 27 | AK31: =SUM(COUNTIF(E31:AI31,"cn")) -> 3 | AL31: =SUM(COUNTIF(E31:AI31,"đ")) -> 0 | AM31: =SUM(COUNTIF(E31:AI31,"đc")) -> 0 | AN31: =SUM(COUNTIF(E31:AI31,"gt")) -> 0 | AO31: =SUM(COUNTIF(E31:AI31,"ct")) -> 0 | AP31: =AJ31+AK31+AL31+AM31+AN31+AO31 -> 30 | AS31: =VLOOKUP(C32,'[1]NT 2'!$C$2:$J$259,8,0) -> 03473 | AT31: =D32-AS31 -> 0
A32: 20 | B32: 20 | C32: N. Me Kha La | D32: =VLOOKUP(C32,'[1]NT 2'!$C$2:$J$259,8,0) -> 03473 | E32: x | F32: x | G32: x | H32: cn | J32: x | K32: x | L32: x | M32: x | N32: x | O32: cn | P32: x | Q32: x | R32: x | S32: x | T32: x | U32: x | V32: cn | W32: x | X32: x | Y32: x | Z32: x | AA32: x | AB32: x | AC32: cn | AD32: x | AE32: x | AF32: x | AG32: x | AH32: x | AI32: x | AJ32: =SUM(COUNTIF(E32:AI32,"x")) -> 26 | AK32: =SUM(COUNTIF(E32:AI32,"cn")) -> 4 | AL32: =SUM(COUNTIF(E32:AI32,"đ")) -> 0 | AM32: =SUM(COUNTIF(E32:AI32,"đc")) -> 0 | AN32: =SUM(COUNTIF(E32:AI32,"gt")) -> 0 | AO32: =SUM(COUNTIF(E32:AI32,"ct")) -> 0 | AP32: =AJ32+AK32+AL32+AM32+AN32+AO32 -> 30 | AS32: =VLOOKUP(C33,'[1]NT 2'!$C$2:$J$259,8,0) -> 03474 | AT32: =D33-AS32 -> 0
A33: 21 | B33: 21 | C33: N. Mon Khăm | D33: =VLOOKUP(C33,'[1]NT 2'!$C$2:$J$259,8,0) -> 03474 | F33: x | H33: cn | I33: x | J33: x | L33: x | M33: x | N33: x | O33: cn | P33: x | Q33: x | R33: x | S33: x | T33: x | U33: x | V33: cn | W33: x | X33: x | Y33: x | Z33: x | AA33: x | AB33: x | AC33: cn | AD33: x | AE33: x | AF33: x | AG33: x | AH33: x | AI33: x | AJ33: =SUM(COUNTIF(E33:AI33,"x")) -> 24 | AK33: =SUM(COUNTIF(E33:AI33,"cn")) -> 4 | AL33: =SUM(COUNTIF(E33:AI33,"đ")) -> 0 | AM33: =SUM(COUNTIF(E33:AI33,"đc")) -> 0 | AN33: =SUM(COUNTIF(E33:AI33,"gt")) -> 0 | AO33: =SUM(COUNTIF(E33:AI33,"ct")) -> 0 | AP33: =AJ33+AK33+AL33+AM33+AN33+AO33 -> 28 | AS33: =VLOOKUP(C34,'[1]NT 2'!$C$2:$J$259,8,0) -> #N/A | AT33: =D34-AS33 -> #N/A
A34: 22 | B34: 22 | C34: N. Bua Lay | D34: =VLOOKUP(C34,'[1]NT 2'!$C$2:$J$259,8,0) -> #N/A | E34: x | F34: x | G34: x | H34: cn | I34: x | J34: x | K34: x | L34: x | M34: x | N34: x | O34: cn | P34: x | Q34: x | R34: x | S34: x | T34: x | U34: x | V34: cn | W34: x | X34: x | Z34: x | AA34: x | AB34: x | AC34: cn | AD34: x | AE34: x | AF34: x | AI34: tt | AJ34: =SUM(COUNTIF(E34:AI34,"x")) -> 23 | AK34: =SUM(COUNTIF(E34:AI34,"cn")) -> 4 | AL34: =SUM(COUNTIF(E34:AI34,"đ")) -> 0 | AM34: =SUM(COUNTIF(E34:AI34,"đc")) -> 0 | AN34: =SUM(COUNTIF(E34:AI34,"gt")) -> 0 | AO34: =SUM(COUNTIF(E34:AI34,"ct")) -> 0 | AP34: =AJ34+AK34+AL34+AM34+AN34+AO34 -> 27 | AS34: =VLOOKUP(C35,'[1]NT 2'!$C$2:$J$259,8,0) -> 03476 | AT34: =D35-AS34 -> 0
A35: 23 | B35: 23 | C35: T. Bin Ly. | D35: =VLOOKUP(C35,'[1]NT 2'!$C$2:$J$259,8,0) -> 03476 | E35: x | F35: x | G35: x | H35: cn | I35: x | J35: x | K35: x | L35: x | M35: x | N35: x | O35: cn | P35: x | Q35: x | R35: x | S35: x | T35: x | U35: x | V35: cn | W35: x | X35: x | Y35: x | Z35: x | AA35: x | AB35: x | AC35: cn | AD35: x | AE35: x | AF35: x | AG35: x | AH35: x | AI35: x | AJ35: =SUM(COUNTIF(E35:AI35,"x")) -> 27 | AK35: =SUM(COUNTIF(E35:AI35,"cn")) -> 4 | AL35: =SUM(COUNTIF(E35:AI35,"đ")) -> 0 | AM35: =SUM(COUNTIF(E35:AI35,"đc")) -> 0 | AN35: =SUM(COUNTIF(E35:AI35,"gt")) -> 0 | AO35: =SUM(COUNTIF(E35:AI35,"ct")) -> 0 | AP35: =AJ35+AK35+AL35+AM35+AN35+AO35 -> 31 | AS35: =VLOOKUP(C36,'[1]NT 2'!$C$2:$J$259,8,0) -> 03477 | AT35: =D36-AS35 -> 0
A36: 24 | B36: 24 | C36: N. Phim Phon. | D36: =VLOOKUP(C36,'[1]NT 2'!$C$2:$J$259,8,0) -> 03477 | E36: x | G36: x | H36: cn | I36: x | J36: x | K36: x | L36: x | M36: x | N36: x | O36: cn | P36: x | Q36: x | R36: x | S36: x | T36: x | U36: x | W36: x | X36: x | Y36: x | Z36: x | AA36: x | AB36: x | AC36: cn | AE36: x | AF36: x | AI36: x | AJ36: =SUM(COUNTIF(E36:AI36,"x")) -> 23 | AK36: =SUM(COUNTIF(E36:AI36,"cn")) -> 3 | AL36: =SUM(COUNTIF(E36:AI36,"đ")) -> 0 | AM36: =SUM(COUNTIF(E36:AI36,"đc")) -> 0 | AN36: =SUM(COUNTIF(E36:AI36,"gt")) -> 0 | AO36: =SUM(COUNTIF(E36:AI36,"ct")) -> 0 | AP36: =AJ36+AK36+AL36+AM36+AN36+AO36 -> 26 | AS36: =VLOOKUP(C37,'[1]NT 2'!$C$2:$J$259,8,0) -> 03478 | AT36: =D37-AS36 -> 0
A37: 25 | B37: 25 | C37: N. Nong | D37: =VLOOKUP(C37,'[1]NT 2'!$C$2:$J$259,8,0) -> 03478 | E37: x | F37: x | G37: x | I37: x | J37: x | K37: x | L37: x | M37: x | N37: x | O37: cn | P37: x | Q37: x | R37: x | S37: x | T37: x | U37: x | V37: cn | W37: x | X37: x | Y37: x | Z37: x | AA37: x | AB37: x | AC37: cn | AD37: x | AE37: x | AF37: x | AG37: x | AH37: x | AI37: x | AJ37: =SUM(COUNTIF(E37:AI37,"x")) -> 27 | AK37: =SUM(COUNTIF(E37:AI37,"cn")) -> 3 | AL37: =SUM(COUNTIF(E37:AI37,"đ")) -> 0 | AM37: =SUM(COUNTIF(E37:AI37,"đc")) -> 0 | AN37: =SUM(COUNTIF(E37:AI37,"gt")) -> 0 | AO37: =SUM(COUNTIF(E37:AI37,"ct")) -> 0 | AP37: =AJ37+AK37+AL37+AM37+AN37+AO37 -> 30 | AS37: =VLOOKUP(C38,'[1]NT 2'!$C$2:$J$259,8,0) -> 03479 | AT37: =D38-AS37 -> 0
A38: 26 | B38: 26 | C38: N. Tun 1 | D38: =VLOOKUP(C38,'[1]NT 2'!$C$2:$J$259,8,0) -> 03479 | E38: x | F38: x | G38: x | H38: cn | I38: x | K38: x | L38: x | M38: x | N38: x | O38: cn | P38: x | Q38: x | R38: x | S38: x | T38: x | U38: x | V38: cn | W38: x | X38: x | Y38: x | Z38: x | AA38: x | AB38: x | AC38: cn | AD38: x | AE38: x | AF38: x | AG38: x | AH38: x | AI38: x | AJ38: =SUM(COUNTIF(E38:AI38,"x")) -> 26 | AK38: =SUM(COUNTIF(E38:AI38,"cn")) -> 4 | AL38: =SUM(COUNTIF(E38:AI38,"đ")) -> 0 | AM38: =SUM(COUNTIF(E38:AI38,"đc")) -> 0 | AN38: =SUM(COUNTIF(E38:AI38,"gt")) -> 0 | AO38: =SUM(COUNTIF(E38:AI38,"ct")) -> 0 | AP38: =AJ38+AK38+AL38+AM38+AN38+AO38 -> 30 | AS38: =VLOOKUP(C39,'[1]NT 2'!$C$2:$J$259,8,0) -> 03480 | AT38: =D39-AS38 -> 0
A39: 27 | B39: 27 | C39: T . Lốc | D39: =VLOOKUP(C39,'[1]NT 2'!$C$2:$J$259,8,0) -> 03480 | E39: x | F39: x | G39: x | H39: cn | I39: x | K39: x | L39: x | M39: x | N39: x | O39: cn | P39: x | Q39: x | R39: x | S39: x | T39: x | U39: x | V39: cn | W39: x | X39: x | Y39: x | Z39: x | AA39: x | AB39: x | AC39: cn | AD39: x | AE39: x | AF39: x | AG39: x | AH39: x | AI39: x | AJ39: =SUM(COUNTIF(E39:AI39,"x")) -> 26 | AK39: =SUM(COUNTIF(E39:AI39,"cn")) -> 4 | AL39: =SUM(COUNTIF(E39:AI39,"đ")) -> 0 | AM39: =SUM(COUNTIF(E39:AI39,"đc")) -> 0 | AN39: =SUM(COUNTIF(E39:AI39,"gt")) -> 0 | AO39: =SUM(COUNTIF(E39:AI39,"ct")) -> 0 | AP39: =AJ39+AK39+AL39+AM39+AN39+AO39 -> 30 | AS39: =VLOOKUP(C40,'[1]NT 2'!$C$2:$J$259,8,0) -> 03481 | AT39: =D40-AS39 -> 0
A40: 28 | B40: 28 | C40: N . Khâm (1) | D40: =VLOOKUP(C40,'[1]NT 2'!$C$2:$J$259,8,0) -> 03481 | G40: x | H40: cn | I40: x | J40: x | K40: x | L40: x | M40: x | N40: x | O40: cn | P40: x | Q40: x | R40: x | S40: x | T40: x | U40: tt | V40: cn | W40: x | X40: x | Y40: x | Z40: x | AA40: x | AB40: x | AC40: cn | AD40: x | AE40: x | AF40: x | AG40: x | AH40: x | AI40: x | AJ40: =SUM(COUNTIF(E40:AI40,"x")) -> 24 | AK40: =SUM(COUNTIF(E40:AI40,"cn")) -> 4 | AL40: =SUM(COUNTIF(E40:AI40,"đ")) -> 0 | AM40: =SUM(COUNTIF(E40:AI40,"đc")) -> 0 | AN40: =SUM(COUNTIF(E40:AI40,"gt")) -> 0 | AO40: =SUM(COUNTIF(E40:AI40,"ct")) -> 0 | AP40: =AJ40+AK40+AL40+AM40+AN40+AO40 -> 28 | AS40: =VLOOKUP(C41,'[1]NT 2'!$C$2:$J$259,8,0) -> 03482 | AT40: =D41-AS40 -> 0
A41: 29 | B41: 29 | C41: T . Phết | D41: =VLOOKUP(C41,'[1]NT 2'!$C$2:$J$259,8,0) -> 03482 | G41: x | H41: cn | I41: x | J41: x | K41: x | L41: x | M41: x | N41: x | O41: cn | P41: x | Q41: x | R41: x | S41: x | T41: x | U41: tt | V41: cn | W41: x | X41: x | Y41: x | Z41: x | AA41: x | AB41: x | AC41: cn | AD41: x | AE41: x | AF41: x | AG41: x | AH41: x | AI41: x | AJ41: =SUM(COUNTIF(E41:AI41,"x")) -> 24 | AK41: =SUM(COUNTIF(E41:AI41,"cn")) -> 4 | AL41: =SUM(COUNTIF(E41:AI41,"đ")) -> 0 | AM41: =SUM(COUNTIF(E41:AI41,"đc")) -> 0 | AN41: =SUM(COUNTIF(E41:AI41,"gt")) -> 0 | AO41: =SUM(COUNTIF(E41:AI41,"ct")) -> 0 | AP41: =AJ41+AK41+AL41+AM41+AN41+AO41 -> 28 | AS41: =VLOOKUP(C42,'[1]NT 2'!$C$2:$J$259,8,0) -> 03483 | AT41: =D42-AS41 -> 0
A42: 30 | B42: 30 | C42: T. Viêng Sa Văn | D42: =VLOOKUP(C42,'[1]NT 2'!$C$2:$J$259,8,0) -> 03483 | E42: x | H42: cn | I42: x | J42: x | K42: x | L42: x | M42: x | N42: x | O42: cn | P42: x | Q42: x | R42: x | S42: x | T42: x | U42: x | V42: cn | W42: x | X42: x | Y42: x | Z42: x | AA42: x | AB42: x | AC42: cn | AD42: x | AE42: x | AF42: x | AG42: x | AH42: x | AI42: x | AJ42: =SUM(COUNTIF(E42:AI42,"x")) -> 25 | AK42: =SUM(COUNTIF(E42:AI42,"cn")) -> 4 | AL42: =SUM(COUNTIF(E42:AI42,"đ")) -> 0 | AM42: =SUM(COUNTIF(E42:AI42,"đc")) -> 0 | AN42: =SUM(COUNTIF(E42:AI42,"gt")) -> 0 | AO42: =SUM(COUNTIF(E42:AI42,"ct")) -> 0 | AP42: =AJ42+AK42+AL42+AM42+AN42+AO42 -> 29 | AS42: =VLOOKUP(C43,'[1]NT 2'!$C$2:$J$259,8,0) -> 03484 | AT42: =D43-AS42 -> 0
...

Sheet BTH mủ tạp
A2: CỘNG HÒA DÂN CHỦ NHÂN DÂN LÀO
A3: Hòa Bình -Độc Lập - Dân Chủ - thống Nhất - Thịnh Vượng
A4: -----o0o-----
B6: CÔNG TY TNHH CP QUASA - GERUCO LÀO
B7: ĐỘI SẢN XUẤT SỐ 04
A9: BẢNG THEO DÕI SẢN LƯỢNG MỦ TẠP THÁNG 05 NĂM 2025
A10: (Từ ngày 01 đến 31/05/2025)
A13: Stt | B13: Stt | C13: Họ và tên | D13: Ngày | AI13: Tổng mủ tạp | AJ13: DRC bình quân | AK13: Quy khô | AL13: Xếp hạng kỹ thuật | AM13: Kí tên
D14: 1 | E14: 2 | F14: 3 | G14: 4 | H14: 5 | I14: 6 | J14: 7 | K14: 8 | L14: 9 | M14: 10 | N14: 11 | O14: 12 | P14: 13 | Q14: 14 | R14: 15 | S14: 16 | T14: 17 | U14: 18 | V14: 19 | W14: 20 | X14: 21 | Y14: 22 | Z14: 23 | AA14: 24 | AB14: 25 | AC14: 26 | AD14: 27 | AE14: 28 | AF14: 29 | AG14: 30 | AH14: 31 | AO14: DRC bình quân
B15: TRẠM 1 | AR15: =AR16/AO16-5% -> 0.46348287
A16: Tổng | D16: =SUM(D17:D96) -> 1087 | E16: =SUM(E17:E96) -> 732 | F16: =SUM(F17:F96) -> 0 | G16: =SUM(G17:G96) -> 0 | H16: =SUM(H17:H96) -> 0 | I16: =SUM(I17:I96) -> 0 | J16: =SUM(J17:J96) -> 283 | K16: =SUM(K17:K96) -> 2276 | ... AG16: =SUM(AG17:AG96) -> 4281 | AH16: =SUM(AH17:AH95) -> 4744 | AI16: =SUM(AI17:AI96) -> 107359 | AK16: =SUM(AK17:AK96) -> 55127.007 | AO16: 107359 | AR16: 55127.007
A17: 1 | B17: 1 | C17: ='Chấm công KT'!C13 -> T. Vôn | D17: 0 | E17: 0 | F17: 0 | G17: 0 | H17: 0 | I17: 0 | J17: 0 | K17: 0 | L17: 0 | M17: 0 | N17: 0 | O17: 92 | P17: 42 | Q17: 63 | R17: 0 | S17: 55 | T17: 46 | U17: 0 | V17: 62 | W17: 49 | X17: 58 | Y17: 38 | Z17: 30 | AA17: 0 | AB17: 50 | AC17: 40 | AD17: 0 | AE17: 97 | AF17: 0 | AG17: 54 | AH17: 0 | AI17: =SUM(D17:AH17) -> 776 | AJ17: 51.348287 | AK17: =AI17*AJ17/100 -> 398.4627 | AL17: C
A18: 2 | B18: 2 | C18: ='Chấm công KT'!C14 -> T. Feng | D18: 0 | E18: 0 | F18: 0 | G18: 0 | H18: 0 | I18: 0 | J18: 0 | K18: 0 | L18: 0 | M18: 0 | N18: 0 | O18: 0 | P18: 0 | Q18: 83 | R18: 0 | S18: 0 | T18: 63 | U18: 13 | V18: 75 | W18: 75 | X18: 0 | Y18: 66 | Z18: 20 | AA18: 0 | AB18: 78 | AC18: 52 | AD18: 21 | AE18: 0 | AF18: 54 | AG18: 54 | AH18: 0 | AI18: =SUM(D18:AH18) -> 654 | AJ18: 51.348287 | AK18: =AI18*AJ18/100 -> 335.81779 | AL18: B
A19: 3 | B19: 3 | C19: ='Chấm công KT'!C15 -> T. Sa Văn | D19: 20 | E19: 0 | F19: 0 | G19: 0 | H19: 0 | I19: 0 | J19: 0 | K19: 38 | L19: 0 | M19: 114 | N19: 183 | O19: 12 | P19: 105 | Q19: 127 | R19: 102 | S19: 95 | T19: 84 | U19: 128 | V19: 56 | W19: 78 | X19: 95 | Y19: 108 | Z19: 0 | AA19: 85 | AB19: 66 | AC19: 87 | AD19: 89 | AE19: 88 | AF19: 81 | AG19: 100 | AH19: 70 | AI19: =SUM(D19:AH19) -> 2011 | AJ19: 51.348287 | AK19: =AI19*AJ19/100 -> 1032.614 | AL19: B
A20: 4 | B20: 4 | C20: ='Chấm công KT'!C16 -> Lăm Ma Thu | D20: 0 | E20: 0 | F20: 0 | G20: 0 | H20: 0 | I20: 0 | J20: 0 | K20: 37 | L20: 33 | M20: 0 | N20: 120 | O20: 91 | P20: 82 | Q20: 0 | R20: 83 | S20: 72 | T20: 0 | U20: 122 | V20: 87 | W20: 59 | X20: 60 | Y20: 0 | Z20: 68 | AA20: 82 | AB20: 0 | AC20: 105 | AD20: 69 | AE20: 68 | AF20: 54 | AG20: 58 | AH20: 64 | AI20: =SUM(D20:AH20) -> 1414 | AJ20: 51.348287 | AK20: =AI20*AJ20/100 -> 726.06477 | AL20: B
A21: 5 | B21: 5 | C21: ='Chấm công KT'!C17 -> N. Vạt | D21: 30 | E21: 0 | F21: 0 | G21: 0 | H21: 0 | I21: 0 | J21: 0 | K21: 0 | L21: 0 | M21: 0 | N21: 39 | O21: 56 | P21: 0 | Q21: 0 | R21: 0 | S21: 100 | T21: 0 | U21: 0 | V21: 0 | W21: 105 | X21: 0 | Y21: 110 | Z21: 31 | AA21: 67 | AB21: 136 | AC21: 60 | AD21: 0 | AE21: 65 | AF21: 0 | AG21: 61 | AH21: 0 | AI21: =SUM(D21:AH21) -> 860 | AJ21: 51.348287 | AK21: =AI21*AJ21/100 -> 441.59526 | AL21: B
A22: 6 | B22: 6 | C22: ='Chấm công KT'!C18 -> N. Kay Son | D22: 0 | E22: 0 | F22: 0 | G22: 0 | H22: 0 | I22: 0 | J22: 0 | K22: 0 | L22: 36 | M22: 0 | N22: 0 | O22: 0 | P22: 35 | Q22: 0 | R22: 110 | S22: 50 | T22: 0 | U22: 46 | V22: 49 | W22: 63 | X22: 41 | Y22: 34 | Z22: 46 | AA22: 57 | AB22: 107 | AC22: 104 | AD22: 34 | AE22: 57 | AF22: 82 | AG22: 95 | AH22: 52 | AI22: =SUM(D22:AH22) -> 1098 | AJ22: 51.348287 | AK22: =AI22*AJ22/100 -> 563.80419 | AL22: C
A23: 7 | B23: 7 | C23: ='Chấm công KT'!C19 -> T. Đèng 1 | D23: 36 | E23: 0 | F23: 0 | G23: 0 | H23: 0 | I23: 0 | J23: 0 | K23: 0 | L23: 39 | M23: 45 | N23: 90 | O23: 35 | P23: 96 | Q23: 71 | R23: 0 | S23: 55 | T23: 100 | U23: 52 | V23: 113 | W23: 55 | X23: 93 | Y23: 70 | Z23: 49 | AA23: 56 | AB23: 73 | AC23: 71 | AD23: 43 | AE23: 54 | AF23: 85 | AG23: 60 | AH23: 0 | AI23: =SUM(D23:AH23) -> 1441 | AJ23: 51.348287 | AK23: =AI23*AJ23/100 -> 739.92881 | AL23: A
A24: 8 | B24: 8 | C24: ='Chấm công KT'!C20 -> T . Bua Ngân | D24: 0 | E24: 0 | F24: 0 | G24: 0 | H24: 0 | I24: 0 | J24: 0 | K24: 53 | L24: 33 | M24: 45 | N24: 133 | O24: 104 | P24: 0 | Q24: 0 | R24: 0 | S24: 0 | T24: 94 | U24: 143 | V24: 120 | W24: 97 | X24: 100 | Y24: 71 | Z24: 91 | AA24: 80 | AB24: 82 | AC24: 60 | AD24: 69 | AE24: 83 | AF24: 77 | AG24: 51 | AH24: 88 | AI24: =SUM(D24:AH24) -> 1674 | AJ24: 51.348287 | AK24: =AI24*AJ24/100 -> 859.57032 | AL24: A
A25: 9 | B25: 9 | C25: ='Chấm công KT'!C21 -> T Căng | D25: 79 | E25: 30 | F25: 0 | G25: 0 | H25: 0 | I25: 0 | J25: 0 | K25: 41 | L25: 102 | M25: 45 | N25: 154 | O25: 114 | P25: 159 | Q25: 0 | R25: 66 | S25: 91 | T25: 135 | U25: 130 | V25: 0 | W25: 98 | X25: 110 | Y25: 89 | Z25: 98 | AA25: 69 | AB25: 102 | AC25: 73 | AD25: 50 | AE25: 70 | AF25: 92 | AG25: 74 | AH25: 50 | AI25: =SUM(D25:AH25) -> 2121 | AJ25: 51.348287 | AK25: =AI25*AJ25/100 -> 1089.0972 | AL25: B
A26: 10 | B26: 10 | C26: ='Chấm công KT'!C22 -> N. Phôn 1 | D26: 50 | E26: 33 | F26: 0 | G26: 0 | H26: 0 | I26: 0 | J26: 0 | K26: 41 | L26: 85 | M26: 36 | N26: 159 | O26: 126 | P26: 165 | Q26: 0 | R26: 78 | S26: 87 | T26: 139 | U26: 117 | V26: 0 | W26: 96 | X26: 120 | Y26: 60 | Z26: 122 | AA26: 75 | AB26: 102 | AC26: 76 | AD26: 49 | AE26: 60 | AF26: 92 | AG26: 74 | AH26: 60 | AI26: =SUM(D26:AH26) -> 2102 | AJ26: 51.348287 | AK26: =AI26*AJ26/100 -> 1079.341 | AL26: A
A27: 11 | B27: 11 | C27: ='Chấm công KT'!C23 -> T. In Păn | D27: 0 | E27: 0 | F27: 0 | G27: 0 | H27: 0 | I27: 0 | J27: 0 | K27: 10 | L27: 0 | M27: 0 | N27: 24 | O27: 0 | P27: 0 | Q27: 22 | R27: 75 | S27: 55 | T27: 110 | U27: 104 | V27: 50 | W27: 0 | X27: 69 | Y27: 89 | Z27: 0 | AA27: 100 | AB27: 61 | AC27: 61 | AD27: 0 | AE27: 63 | AF27: 0 | AG27: 65 | AH27: 99 | AI27: =SUM(D27:AH27) -> 1057 | AJ27: 51.348287 | AK27: =AI27*AJ27/100 -> 542.75139 | AL27: A
A28: 12 | B28: 12 | C28: ='Chấm công KT'!C24 -> N. Keo | D28: 0 | E28: 0 | F28: 0 | G28: 0 | H28: 0 | I28: 0 | J28: 0 | K28: 35 | L28: 107 | M28: 0 | N28: 137 | O28: 101 | P28: 130 | Q28: 0 | R28: 112 | S28: 85 | T28: 135 | U28: 109 | V28: 94 | W28: 80 | X28: 102 | Y28: 75 | Z28: 104 | AA28: 80 | AB28: 118 | AC28: 54 | AD28: 70 | AE28: 74 | AF28: 91 | AG28: 58 | AH28: 74 | AI28: =SUM(D28:AH28) -> 2025 | AJ28: 51.348287 | AK28: =AI28*AJ28/100 -> 1039.8028 | AL28: B
... A93: 77 | B93: 77 | C93: ='Chấm công KT'!C89 -> T.Pu | D93: 0 | E93: 0 | F93: 0 | G93: 0 | H93: 0 | I93: 0 | J93: 0 | K93: 0 | L93: 0 | M93: 0 | N93: 0 | O93: 0 | P93: 0 | Q93: 0 | R93: 0 | S93: 0 | T93: 0 | U93: 0 | V93: 0 | W93: 35 | X93: 0 | Y93: 0 | Z93: 0 | AA93: 0 | AB93: 0 | AC93: 0 | AD93: 0 | AE93: 0 | AF93: 0 | AG93: 0 | AH93: 0 | AI93: =SUM(D93:AH93) -> 35 | AJ93: 51.348287 | AK93: =AI93*AJ93/100 -> 17.9719 | AL93: C.
A94: 78 | B94: 78 | C94: ='Chấm công KT'!C90 -> T.Ta | AI94: =SUM(D94:AH94) -> 0 | AK94: =AI94*AJ94/100 -> 0
A95: 79 | B95: 79 | C95: ='Chấm công KT'!C91 -> N.Nang | AI95: =SUM(D95:AH95) -> 0 | AK95: =AI95*AJ95/100 -> 0
A96: 80 | B96: 80 | C96: ='Chấm công KT'!C92 -> T. Tan | AI96: =SUM(D96:AH96) -> 0 | AK96: =AI96*AJ96/100 -> 0
B97: TRẠM 2
A98: Tổng | D98: =SUM(D99:D160) -> 2615 | E98: =SUM(E99:E160) -> 0 | F98: =SUM(F99:F160) -> 0 | G98: =SUM(G99:G160) -> 0 | H98: =SUM(H99:H160) -> 0 | I98: =SUM(I99:I160) -> 1417 | J98: =SUM(J99:J160) -> 1674 | K98: =SUM(K99:K160) -> 1678 | ... AI98: =SUM(AI99:AI160) -> 99980 | AK98: =SUM(AK99:AK160) -> 50774.636
A99: 78 | B99: 1 | C99: ='Chấm công KT'!C94 -> T. Lun | D99: 70 | E99: 0 | F99: 0 | G99: 0 | H99: 0 | I99: 34 | J99: 0 | K99: 48 | L99: 115 | M99: 0 | N99: 119 | O99: 36 | P99: 99 | Q99: 98 | R99: 0 | S99: 85 | T99: 76 | U99: 0 | V99: 151 | W99: 89 | X99: 149 | Y99: 100 | Z99: 73 | AA99: 0 | AB99: 127 | AC99: 44 | AD99: 61 | AE99: 209 | AF99: 132 | AG99: 37 | AH99: 54 | AI99: =SUM(D99:AH99) -> 2006 | AJ99: 50.784793 | AK99: =AI99*AJ99/100 -> 1018.7429 | AL99: A
A100: 79 | B100: 2 | C100: ='Chấm công KT'!C95 -> N. Keo | D100: 92 | E100: 0 | F100: 0 | G100: 0 | H100: 0 | I100: 30 | J100: 37 | K100: 23 | L100: 69 | M100: 34 | N100: 103 | O100: 84 | P100: 54 | Q100: 20 | R100: 108 | S100: 93 | T100: 66 | U100: 37 | V100: 105 | W100: 77 | X100: 0 | Y100: 126 | Z100: 92 | AA100: 46 | AB100: 139 | AC100: 100 | AD100: 94 | AE100: 79 | AF100: 80 | AG100: 0 | AH100: 0 | AI100: =SUM(D100:AH100) -> 1788 | AJ100: 50.784793 | AK100: =AI100*AJ100/100 -> 908.0321 | AL100: A
A101: 80 | B101: 3 | C101: ='Chấm công KT'!C96 -> T .Nhum | D101: 13 | E101: 0 | F101: 0 | G101: 0 | H101: 0 | I101: 0 | J101: 0 | K101: 0 | L101: 18 | M101: 17 | N101: 97 | O101: 56 | P101: 20 | Q101: 23 | R101: 76 | S101: 41 | T101: 70 | U101: 40 | V101: 67 | W101: 68 | X101: 94 | Y101: 54 | Z101: 65 | AA101: 61 | AB101: 0 | AC101: 48 | AD101: 0 | AE101: 94 | AF101: 150 | AG101: 52 | AH101: 120 | AI101: =SUM(D101:AH101) -> 1344 | AJ101: 50.784793 | AK101: =AI101*AJ101/100 -> 682.54762 | AL101: A
A102: 81 | B102: 4 | C102: ='Chấm công KT'!C97 -> N.Vông Ma Ni | D102: 54 | E102: 0 | F102: 0 | G102: 0 | H102: 0 | I102: 10 | J102: 30 | K102: 28 | L102: 34 | M102: 20 | N102: 92 | O102: 50 | P102: 84 | Q102: 70 | R102: 52 | S102: 83 | T102: 103 | U102: 57 | V102: 74 | W102: 74 | X102: 98 | Y102: 57 | Z102: 91 | AA102: 112 | AB102: 129 | AC102: 50 | AD102: 91 | AE102: 93 | AF102: 134 | AG102: 62 | AH102: 74 | AI102: =SUM(D102:AH102) -> 1906 | AJ102: 50.784793 | AK102: =AI102*AJ102/100 -> 967.95815 | AL102: A
A103: 82 | B103: 5 | C103: ='Chấm công KT'!C98 -> Đao Hương | D103: 83 | E103: 0 | F103: 0 | G103: 0 | H103: 0 | I103: 18 | J103: 25 | K103: 20 | L103: 34 | M103: 26 | N103: 74 | O103: 50 | P103: 114 | Q103: 75 | R103: 66 | S103: 40 | T103: 100 | U103: 44 | V103: 75 | W103: 73 | X103: 126 | Y103: 50 | Z103: 64 | AA103: 105 | AB103: 151 | AC103: 58 | AD103: 60 | AE103: 94 | AF103: 89 | AG103: 50 | AH103: 82 | AI103: =SUM(D103:AH103) -> 1846 | AJ103: 50.784793 | AK103: =AI103*AJ103/100 -> 937.48728 | AL103: A
A104: 83 | B104: 6 | C104: ='Chấm công KT'!C99 -> T. Xi Nun | D104: 38 | E104: 0 | F104: 0 | G104: 0 | H104: 0 | I104: 18 | J104: 0 | K104: 0 | L104: 0 | M104: 0 | N104: 0 | O104: 37 | P104: 50 | Q104: 0 | R104: 104 | S104: 102 | T104: 122 | U104: 34 | V104: 92 | W104: 0 | X104: 0 | Y104: 0 | Z104: 45 | AA104: 80 | AB104: 0 | AC104: 0 | AD104: 34 | AE104: 0 | AF104: 128 | AG104: 0 | AH104: 0 | AI104: =SUM(D104:AH104) -> 884 | AJ104: 50.784793 | AK104: =AI104*AJ104/100 -> 448.93757 | AL104: B
A105: 84 | B105: 7 | C105: ='Chấm công KT'!C100 -> T. Bun Hinh | D105: 40 | E105: 0 | F105: 0 | G105: 0 | H105: 0 | I105: 35 | J105: 27 | K105: 40 | L105: 100 | M105: 20 | N105: 142 | O105: 76 | P105: 72 | Q105: 43 | R105: 134 | S105: 98 | T105: 33 | U105: 52 | V105: 128 | W105: 110 | X105: 100 | Y105: 63 | Z105: 0 | AA105: 100 | AB105: 72 | AC105: 64 | AD105: 185 | AE105: 111 | AF105: 58 | AG105: 50 | AH105: 115 | AI105: =SUM(D105:AH105) -> 2068 | AJ105: 50.784793 | AK105: =AI105*AJ105/100 -> 1050.2295 | AL105: A
A106: 85 | B106: 8 | C106: ='Chấm công KT'!C101 -> T. Miềng | D106: 54 | E106: 0 | F106: 0 | G106: 0 | H106: 0 | I106: 43 | J106: 35 | K106: 51 | L106: 76 | M106: 22 | N106: 57 | O106: 61 | P106: 44 | Q106: 0 | R106: 74 | S106: 0 | T106: 94 | U106: 96 | V106: 69 | W106: 82 | X106: 90 | Y106: 52 | Z106: 65 | AA106: 99 | AB106: 96 | AC106: 22 | AD106: 60 | AE106: 107 | AF106: 69 | AG106: 0 | AH106: 67 | AI106: =SUM(D106:AH106) -> 1585 | AJ106: 50.784793 | AK106: =AI106*AJ106/100 -> 804.93897 | AL106: A
A107: 86 | B107: 9 | C107: ='Chấm công KT'!C102 -> N. Xúc | D107: 60 | E107: 0 | F107: 0 | G107: 0 | H107: 0 | I107: 46 | J107: 30 | K107: 35 | L107: 66 | M107: 0 | N107: 113 | O107: 52 | P107: 65 | Q107: 102 | R107: 121 | S107: 127 | T107: 45 | U107: 72 | V107: 151 | W107: 101 | X107: 100 | Y107: 54 | Z107: 142 | AA107: 116 | AB107: 71 | AC107: 44 | AD107: 110 | AE107: 0 | AF107: 77 | AG107: 66 | AH107: 144 | AI107: =SUM(D107:AH107) -> 2110 | AJ107: 50.784793 | AK107: =AI107*AJ107/100 -> 1071.5591 | AL107: B
A108: 87 | B108: 10 | C108: ='Chấm công KT'!C103 -> N. Lẹ | D108: 20 | E108: 0 | F108: 0 | G108: 0 | H108: 0 | I108: 0 | J108: 0 | K108: 0 | L108: 15 | M108: 10 | N108: 77 | O108: 21 | P108: 30 | Q108: 20 | R108: 60 | S108: 51 | T108: 59 | U108: 60 | V108: 81 | W108: 69 | X108: 90 | Y108: 64 | Z108: 57 | AA108: 100 | AB108: 0 | AC108: 56 | AD108: 0 | AE108: 100 | AF108: 164 | AG108: 49 | AH108: 121 | AI108: =SUM(D108:AH108) -> 1374 | AJ108: 50.784793 | AK108: =AI108*AJ108/100 -> 697.78306 | AL108: A
A109: 88 | B109: 11 | C109: ='Chấm công KT'!C104 -> N . Thích | D109: 30 | E109: 0 | F109: 0 | G109: 0 | H109: 0 | I109: 0 | J109: 29 | K109: 10 | L109: 51 | M109: 0 | N109: 107 | O109: 69 | P109: 40 | Q109: 65 | R109: 60 | S109: 100 | T109: 106 | U109: 49 | V109: 110 | W109: 103 | X109: 99 | Y109: 34 | Z109: 88 | AA109: 79 | AB109: 120 | AC109: 30 | AD109: 70 | AE109: 108 | AF109: 77 | AG109: 38 | AH109: 62 | AI109: =SUM(D109:AH109) -> 1734 | AJ109: 50.784793 | AK109: =AI109*AJ109/100 -> 880.60831 | AL109: A
...

Sheet BTH mủ Sỉum
A2: CỘNG HÒA DÂN CHỦ NHÂN DÂN LÀO
A3: Hòa Bình -Độc Lập - Dân Chủ - thống Nhất - Thịnh Vượng
A4: -----o0o-----
A6: CÔNG TY TNHH CP QUASA - GERUCO LÀO
A7: ĐỘI SẢN XUẤT SỐ 5
A9: BẢNG THEO DÕI SẢN LƯỢNG MỦ SERUM THÁNG 02 NĂM 2025
AK10: DRC
A11: Stt | B11: Họ và tên | C11: Ngày | AH11: Tổng mủ Xirum | AI11: DRC bình quân | AJ11: Quy khô | AK11: Xếp hạng kỹ thuật | AL11: Kí tên
C12: 1 | D12: 2 | E12: 3 | F12: 4 | G12: 5 | H12: 6 | I12: 7 | J12: 8 | K12: 9 | L12: 10 | M12: 11 | N12: 12 | O12: 13 | P12: 14 | Q12: 15 | R12: 16 | S12: 17 | T12: 18 | U12: 19 | V12: 20 | W12: 21 | X12: 22 | Y12: 23 | Z12: 24 | AA12: 25 | AB12: 26 | AC12: 27 | AD12: 28 | AE12: 29 | AF12: 30
A13: ĐỘI 1 | C13: =C14 -> 0 | D13: =D14 -> 0 | E13: =E14 -> 0 | F13: =F14 -> 0 | G13: =G14 -> 0 | H13: =H14 -> 0 | I13: =I14 -> 0 | J13: =J14 -> 0 | ... AF13: =AF14 -> 0 | AH13: =AH14 -> 0 | AJ13: =AJ14 -> 0 | AK13: =AK14 -> 0
A14: 1 | B14: Mủ Xirum | AH14: =SUM(C14:AG14) -> 0 | AI14: 48.216842 | AJ14: =AH14*AI14/100 -> 0
A15: ĐỘI 2 | C15: =C16 -> 0 | D15: =D16 -> 0 | E15: =E16 -> 0 | F15: =F16 -> 0 | G15: =G16 -> 0 | H15: =H16 -> 0 | I15: =I16 -> 0 | J15: =J16 -> 0 | ... AF15: =AF16 -> 0 | AH15: =AH16 -> 0 | AJ15: =AJ16 -> 0
A16: 1 | B16: Mủ Xirum | AH16: =SUM(C16:AG16) -> 0 | AI16: 44.235 | AJ16: =AH16*AI16/100 -> 0
A17: ĐỘI 3 | C17: =C18 -> 0 | D17: =D18 -> 0 | E17: =E18 -> 0 | F17: =F18 -> 0 | G17: =G18 -> 0 | H17: =H18 -> 0 | I17: =I18 -> 0 | J17: =J18 -> 0 | ... AF17: =AF18 -> 0 | AH17: =AH18 -> 0 | AJ17: =AJ18 -> 0 | AK17: =AK18 -> 0
A18: 1 | B18: Mủ Xirum | AH18: =SUM(C18:AG18) -> 0 | AI18: 47.395652 | AJ18: =AH18*AI18/100 -> 0
A19: ĐỘI 4 | C19: =C20 -> 0 | D19: =D20 -> 0 | E19: =E20 -> 0 | F19: =F20 -> 0 | G19: =G20 -> 0 | H19: =H20 -> 0 | I19: =I20 -> 0 | J19: =J20 -> 0 | ... AF19: =AF20 -> 0 | AH19: =AH20 -> 0 | AJ19: =AJ20 -> 0 | AN19: =SUM(#REF!) -> #REF!
A20: 1 | B20: Mủ Xirum | AH20: =SUM(C20:AG20) -> 0 | AI20: 47.340606 | AJ20: =AH20*AI20/100 -> 0
A21: Tổng cộng | AE21: =AE13+AE15+AE17+AE19 -> 0 | AF21: =AF13+AF15+AF17+AF19 -> 0 | AH21: =AH13+AH15+AH17+AH19 -> 0 | AJ21: =AJ13+AJ15+AJ17+AJ19 -> 0 | AK21: =AK13+AK15+AK17+AK19 -> 0
X23: Mường phìn, ngày 02 tháng 03 năm 2025
B24: TỔNG GIÁM ĐỐC | M24: PHÒNG KT - NN | W24: ĐỘI TRƯỞNG | AH24: NGƯỜI LẬP
V32: Nguyễn Minh Thành | AH32: Trần Viết Hùng

Sheet TONGHOPCONGDOI
A2: CÔNG TY TNHH CỔ PHẦN QUASA - GERUCO | R2: CỘNG HÒA DÂN CHỦ NHÂN DÂN LÀO
A3: NÔNG TRƯỜNG 2 | N3: =144/0.67 -> 214.92537 | R3: Hòa Bình - Độc Lập - Dân Chủ - Thống Nhất - Thịnh Vượng
A4: Đội: 1.2.3.4 | J4: =F11*25000 -> 600000 | K4: =G11*25000 -> 0 | T4: =Q9-19035.02 -> -9843.14
A5: BẢNG TỔNG HỢP CÔNG THỰC HIỆN THÁNG 01 NĂM 2025
A6: STT | B6: Mã số nhân viên | C6: Họ và Tên Lào | D6: Chức vụ
E7: Bôi thuốc kích thích | F7: Gắn màng phủ chén | G7: Gắn mái che mưa miệng ngữa | H7: Gắn mái che mưa miệng úp | I7: Thiết kế miệng cạo ngữa | J7: Rút máng | K7: Cột kiềng | L7: Xả miệng cạo ngữa | M7: Phát chồi đại trà | N7: Gom chén | P7: Thổi lá hàng 3m | Q7: Tổng công | R7: Sản lượng mủ | V7: Các khoản PC | AC7: Tổng cộng | AD7: Xếp loại KT tính lương | AE7: Xác Nhận
R8: Mủ tạp | S8: Mủ Xirum | T8: Quy khô DRC=50 | U8: Tổng sản lượng mủ tạp+mủ dây quy khô | V8: Ngày công đi cạo thường (x) | W8: Ngày CN thường (cn) | X8: Ngày công đi cạo 2 lát (đ) | Y8: Ngày công chủ nhật cạo 2 lát (đc) | Z8: Ngày công cạo gia tăng 2 miêng (gt) | AA8: Ngày chủ nhật cạo gia tăng 2 miệng (ct) | AB8: Phụ cấp nhỏ a xít | AI8: =5308.01-Q9 -> -3883.87
A9: I | B9: VC KINH DOANH NĂM | E9: =E10+E92 -> 419.2 | F9: =F10+F92 -> 3144 | G9: =G10+G92 -> 441 | H9: =H10+H92 -> 3688 | I9: =I10+I92 -> 0 | J9: =J10+J92 -> 0 | K9: =K10+K92 -> 0 | L9: =L10+L92 -> 0 | ... AC9: =AC10+AC92 -> 9191.88 | AF9: 6716.8 | AG9: =6716.8-Q9 -> -2475.08
A10: A | B10: TRẠM 1 | E10: =SUM(E11:E91) -> 233.6 | F10: =SUM(F11:F91) -> 1752 | G10: =SUM(G11:G91) -> 28 | H10: =SUM(H11:H91) -> 2304 | I10: =SUM(I11:I91) -> 0 | J10: =SUM(J11:J91) -> 0 | K10: =SUM(K11:K91) -> 0 | L10: =SUM(L11:L91) -> 0 | ... AC10: =SUM(AC11:AC91) -> 5223.88 | AF10: 1618 | AG10: 194
A11: 1 | B11: ='Chấm công KT'!D13 -> 03456 | C11: ='Chấm công KT'!C13 -> T. Vôn | D11: CN-KT | E11: =4/1.25 -> 3.2 | F11: =600000/25000 -> 24 | H11: 32 | Q11: =SUM(E11:P11) -> 59.2 | R11: =VLOOKUP(C11,'BTH mủ tạp'!$C$17:$AI$96,33,0) -> 776 | T11: =S11*50/100 -> 0 | U11: =R11 -> 776 | V11: =VLOOKUP(C11,'Chấm công KT'!$C$13:$AJ$92,34,0) -> 23 | W11: =VLOOKUP(C11,'Chấm công KT'!$C$13:$AK$92,35,0) -> 4 | Z11: =VLOOKUP(C11,'Chấm công KT'!$C$13:$AN$92,38,0) -> 0 | AA11: =VLOOKUP(C11,'Chấm công KT'!$C$13:$AO$92,39,0) -> 0 | AC11: =Q11 -> 59.2 | AD11: =VLOOKUP(C11,'BTH mủ tạp'!$C$17:$AL$160,36,0) -> C
A12: 2 | B12: ='Chấm công KT'!D14 -> 0 | C12: ='Chấm công KT'!C14 -> T. Feng | D12: CN-KT | E12: =4/1.25 -> 3.2 | F12: =600000/25000 -> 24 | H12: 32 | Q12: =SUM(E12:P12) -> 59.2 | R12: =VLOOKUP(C12,'BTH mủ tạp'!$C$17:$AI$96,33,0) -> 654 | T12: =S12*50/100 -> 0 | U12: =R12 -> 654 | V12: =VLOOKUP(C12,'Chấm công KT'!$C$13:$AJ$92,34,0) -> 23 | W12: =VLOOKUP(C12,'Chấm công KT'!$C$13:$AK$92,35,0) -> 4 | Z12: =VLOOKUP(C12,'Chấm công KT'!$C$13:$AN$92,38,0) -> 0 | AA12: =VLOOKUP(C12,'Chấm công KT'!$C$13:$AO$92,39,0) -> 0 | AC12: =Q12 -> 59.2 | AD12: =VLOOKUP(C12,'BTH mủ tạp'!$C$17:$AL$160,36,0) -> B
A13: 3 | B13: ='Chấm công KT'!D15 -> 02725 | C13: ='Chấm công KT'!C15 -> T. Sa Văn | D13: CN-KT | E13: =4/1.25 -> 3.2 | F13: =600000/25000 -> 24 | H13: 32 | Q13: =SUM(E13:P13) -> 59.2 | R13: =VLOOKUP(C13,'BTH mủ tạp'!$C$17:$AI$96,33,0) -> 2011 | T13: =S13*50/100 -> 0 | U13: =R13 -> 2011 | V13: =VLOOKUP(C13,'Chấm công KT'!$C$13:$AJ$92,34,0) -> 26 | W13: =VLOOKUP(C13,'Chấm công KT'!$C$13:$AK$92,35,0) -> 4 | Z13: =VLOOKUP(C13,'Chấm công KT'!$C$13:$AN$92,38,0) -> 0 | AA13: =VLOOKUP(C13,'Chấm công KT'!$C$13:$AO$92,39,0) -> 0 | AC13: =Q13 -> 59.2 | AD13: =VLOOKUP(C13,'BTH mủ tạp'!$C$17:$AL$160,36,0) -> B | AG13: 119657 | AH13: 197
A14: 4 | B14: ='Chấm công KT'!D16 -> #N/A | C14: ='Chấm công KT'!C16 -> Lăm Ma Thu | D14: CN-KT | E14: =4/1.25 -> 3.2 | F14: =600000/25000 -> 24 | H14: 32 | Q14: =SUM(E14:P14) -> 59.2 | R14: =VLOOKUP(C14,'BTH mủ tạp'!$C$17:$AI$96,33,0) -> 1414 | T14: =S14*50/100 -> 0 | U14: =R14 -> 1414 | V14: =VLOOKUP(C14,'Chấm công KT'!$C$13:$AJ$92,34,0) -> 25 | W14: =VLOOKUP(C14,'Chấm công KT'!$C$13:$AK$92,35,0) -> 4 | Z14: =VLOOKUP(C14,'Chấm công KT'!$C$13:$AN$92,38,0) -> 0 | AA14: =VLOOKUP(C14,'Chấm công KT'!$C$13:$AO$92,39,0) -> 0 | AC14: =Q14 -> 59.2 | AD14: =VLOOKUP(C14,'BTH mủ tạp'!$C$17:$AL$160,36,0) -> B | AG14: 125408 | AH14: 554
A15: 5 | B15: ='Chấm công KT'!D17 -> 03459 | C15: ='Chấm công KT'!C17 -> N. Vạt | D15: CN-KT | E15: =4/1.25 -> 3.2 | F15: =600000/25000 -> 24 | H15: 32 | Q15: =SUM(E15:P15) -> 59.2 | R15: =VLOOKUP(C15,'BTH mủ tạp'!$C$17:$AI$96,33,0) -> 860 | T15: =S15*50/100 -> 0 | U15: =R15 -> 860 | V15: =VLOOKUP(C15,'Chấm công KT'!$C$13:$AJ$92,34,0) -> 20 | W15: =VLOOKUP(C15,'Chấm công KT'!$C$13:$AK$92,35,0) -> 3 | Z15: =VLOOKUP(C15,'Chấm công KT'!$C$13:$AN$92,38,0) -> 0 | AA15: =VLOOKUP(C15,'Chấm công KT'!$C$13:$AO$92,39,0) -> 0 | AC15: =Q15 -> 59.2 | AD15: =VLOOKUP(C15,'BTH mủ tạp'!$C$17:$AL$160,36,0) -> B | AG15: 97048 | AH15: 92
A16: 6 | B16: ='Chấm công KT'!D18 -> #N/A | C16: ='Chấm công KT'!C18 -> N. Kay Son | D16: CN-KT | E16: =4/1.25 -> 3.2 | F16: =600000/25000 -> 24 | H16: 32 | Q16: =SUM(E16:P16) -> 59.2 | R16: =VLOOKUP(C16,'BTH mủ tạp'!$C$17:$AI$96,33,0) -> 1098 | T16: =S16*50/100 -> 0 | U16: =R16 -> 1098 | V16: =VLOOKUP(C16,'Chấm công KT'!$C$13:$AJ$92,34,0) -> 22 | W16: =VLOOKUP(C16,'Chấm công KT'!$C$13:$AK$92,35,0) -> 3 | Z16: =VLOOKUP(C16,'Chấm công KT'!$C$13:$AN$92,38,0) -> 0 | AA16: =VLOOKUP(C16,'Chấm công KT'!$C$13:$AO$92,39,0) -> 0 | AC16: =Q16 -> 59.2 | AD16: =VLOOKUP(C16,'BTH mủ tạp'!$C$17:$AL$160,36,0) -> C | AG16: 46179
A17: 7 | B17: ='Chấm công KT'!D19 -> #N/A | C17: ='Chấm công KT'!C19 -> T. Đèng 1 | D17: CN-KT | E17: =4/1.25 -> 3.2 | F17: =600000/25000 -> 24 | H17: 32 | Q17: =SUM(E17:P17) -> 59.2 | R17: =VLOOKUP(C17,'BTH mủ tạp'!$C$17:$AI$96,33,0) -> 1441 | T17: =S17*50/100 -> 0 | U17: =R17 -> 1441 | V17: =VLOOKUP(C17,'Chấm công KT'!$C$13:$AJ$92,34,0) -> 27 | W17: =VLOOKUP(C17,'Chấm công KT'!$C$13:$AK$92,35,0) -> 4 | Z17: =VLOOKUP(C17,'Chấm công KT'!$C$13:$AN$92,38,0) -> 0 | AA17: =VLOOKUP(C17,'Chấm công KT'!$C$13:$AO$92,39,0) -> 0 | AC17: =Q17 -> 59.2 | AD17: =VLOOKUP(C17,'BTH mủ tạp'!$C$17:$AL$160,36,0) -> A
A18: 8 | B18: ='Chấm công KT'!D20 -> 03462 | C18: ='Chấm công KT'!C20 -> T . Bua Ngân | D18: CN-KT | E18: =4/1.25 -> 3.2 | F18: =600000/25000 -> 24 | H18: 32 | Q18: =SUM(E18:P18) -> 59.2 | R18: =VLOOKUP(C18,'BTH mủ tạp'!$C$17:$AI$96,33,0) -> 1674 | T18: =S18*50/100 -> 0 | U18: =R18 -> 1674 | V18: =VLOOKUP(C18,'Chấm công KT'!$C$13:$AJ$92,34,0) -> 26 | W18: =VLOOKUP(C18,'Chấm công KT'!$C$13:$AK$92,35,0) -> 3 | Z18: =VLOOKUP(C18,'Chấm công KT'!$C$13:$AN$92,38,0) -> 0 | AA18: =VLOOKUP(C18,'Chấm công KT'!$C$13:$AO$92,39,0) -> 0 | AC18: =Q18 -> 59.2 | AD18: =VLOOKUP(C18,'BTH mủ tạp'!$C$17:$AL$160,36,0) -> A | AI18: =1155.43-Q9 -> -8036.45
A19: 9 | B19: ='Chấm công KT'!D21 -> 03463 | C19: ='Chấm công KT'!C21 -> T Căng | D19: CN-KT | E19: =4/1.25 -> 3.2 | F19: =600000/25000 -> 24 | H19: 32 | Q19: =SUM(E19:P19) -> 59.2 | R19: =VLOOKUP(C19,'BTH mủ tạp'!$C$17:$AI$96,33,0) -> 2121 | T19: =S19*50/100 -> 0 | U19: =R19 -> 2121 | V19: =VLOOKUP(C19,'Chấm công KT'!$C$13:$AJ$92,34,0) -> 27 | W19: =VLOOKUP(C19,'Chấm công KT'!$C$13:$AK$92,35,0) -> 3 | Z19: =VLOOKUP(C19,'Chấm công KT'!$C$13:$AN$92,38,0) -> 0 | AA19: =VLOOKUP(C19,'Chấm công KT'!$C$13:$AO$92,39,0) -> 0 | AC19: =Q19 -> 59.2 | AD19: =VLOOKUP(C19,'BTH mủ tạp'!$C$17:$AL$160,36,0) -> B
A20: 10 | B20: ='Chấm công KT'!D22 -> 03464 | C20: ='Chấm công KT'!C22 -> N. Phôn 1 | D20: CN-KT | E20: =4/1.25 -> 3.2 | F20: =600000/25000 -> 24 | H20: 32 | Q20: =SUM(E20:P20) -> 59.2 | R20: =VLOOKUP(C20,'BTH mủ tạp'!$C$17:$AI$96,33,0) -> 2102 | T20: =S20*50/100 -> 0 | U20: =R20 -> 2102 | V20: =VLOOKUP(C20,'Chấm công KT'!$C$13:$AJ$92,34,0) -> 27 | W20: =VLOOKUP(C20,'Chấm công KT'!$C$13:$AK$92,35,0) -> 3 | Z20: =VLOOKUP(C20,'Chấm công KT'!$C$13:$AN$92,38,0) -> 0 | AA20: =VLOOKUP(C20,'Chấm công KT'!$C$13:$AO$92,39,0) -> 0 | AC20: =Q20 -> 59.2 | AD20: =VLOOKUP(C20,'BTH mủ tạp'!$C$17:$AL$160,36,0) -> A | AG20: =Q9 -> 9191.88
A21: 11 | B21: ='Chấm công KT'!D23 -> 03465 | C21: ='Chấm công KT'!C23 -> T. In Păn | D21: CN-KT | E21: =4/1.25 -> 3.2 | F21: =600000/25000 -> 24 | H21: 32 | Q21: =SUM(E21:P21) -> 59.2 | R21: =VLOOKUP(C21,'BTH mủ tạp'!$C$17:$AI$96,33,0) -> 1057 | T21: =S21*50/100 -> 0 | U21: =R21 -> 1057 | V21: =VLOOKUP(C21,'Chấm công KT'!$C$13:$AJ$92,34,0) -> 23 | W21: =VLOOKUP(C21,'Chấm công KT'!$C$13:$AK$92,35,0) -> 4 | Z21: =VLOOKUP(C21,'Chấm công KT'!$C$13:$AN$92,38,0) -> 0 | AA21: =VLOOKUP(C21,'Chấm công KT'!$C$13:$AO$92,39,0) -> 0 | AC21: =Q21 -> 59.2 | AD21: =VLOOKUP(C21,'BTH mủ tạp'!$C$17:$AL$160,36,0) -> A | AG21: =AG20-2544.38 -> 6647.5
A22: 12 | B22: ='Chấm công KT'!D24 -> 03466 | C22: ='Chấm công KT'!C24 -> N. Keo | D22: CN-KT | E22: =4/1.25 -> 3.2 | F22: =600000/25000 -> 24 | H22: 32 | Q22: =SUM(E22:P22) -> 59.2 | R22: =VLOOKUP(C22,'BTH mủ tạp'!$C$17:$AI$96,33,0) -> 2025 | T22: =S22*50/100 -> 0 | U22: =R22 -> 2025 | V22: =VLOOKUP(C22,'Chấm công KT'!$C$13:$AJ$92,34,0) -> 26 | W22: =VLOOKUP(C22,'Chấm công KT'!$C$13:$AK$92,35,0) -> 4 | Z22: =VLOOKUP(C22,'Chấm công KT'!$C$13:$AN$92,38,0) -> 0 | AA22: =VLOOKUP(C22,'Chấm công KT'!$C$13:$AO$92,39,0) -> 0 | AC22: =Q22 -> 59.2 | AD22: =VLOOKUP(C22,'BTH mủ tạp'!$C$17:$AL$160,36,0) -> B | AG22: =AG21-6.33 -> 6641.17
A23: 13 | B23: ='Chấm công KT'!D25 -> 02727 | C23: ='Chấm công KT'!C25 -> T. Thong Đon | D23: CN-KT | E23: =4/1.25 -> 3.2 | F23: =600000/25000 -> 24 | H23: 32 | Q23: =SUM(E23:P23) -> 59.2 | R23: =VLOOKUP(C23,'BTH mủ tạp'!$C$17:$AI$96,33,0) -> 1825 | T23: =S23*50/100 -> 0 | U23: =R23 -> 1825 | V23: =VLOOKUP(C23,'Chấm công KT'!$C$13:$AJ$92,34,0) -> 24 | W23: =VLOOKUP(C23,'Chấm công KT'!$C$13:$AK$92,35,0) -> 3 | Z23: =VLOOKUP(C23,'Chấm công KT'!$C$13:$AN$92,38,0) -> 0 | AA23: =VLOOKUP(C23,'Chấm công KT'!$C$13:$AO$92,39,0) -> 0 | AC23: =Q23 -> 59.2 | AD23: =VLOOKUP(C23,'BTH mủ tạp'!$C$17:$AL$160,36,0) -> B
A24: 14 | B24: ='Chấm công KT'!D26 -> 03467 | C24: ='Chấm công KT'!C26 -> T. Hin | D24: CN-KT | E24: =4/1.25 -> 3.2 | F24: =600000/25000 -> 24 | H24: 32 | Q24: =SUM(E24:P24) -> 59.2 | R24: =VLOOKUP(C24,'BTH mủ tạp'!$C$17:$AI$96,33,0) -> 1407 | T24: =S24*50/100 -> 0 | U24: =R24 -> 1407 | V24: =VLOOKUP(C24,'Chấm công KT'!$C$13:$AJ$92,34,0) -> 27 | W24: =VLOOKUP(C24,'Chấm công KT'!$C$13:$AK$92,35,0) -> 4 | Z24: =VLOOKUP(C24,'Chấm công KT'!$C$13:$AN$92,38,0) -> 0 | AA24: =VLOOKUP(C24,'Chấm công KT'!$C$13:$AO$92,39,0) -> 0 | AC24: =Q24 -> 59.2 | AD24: =VLOOKUP(C24,'BTH mủ tạp'!$C$17:$AL$160,36,0) -> A
A25: 15 | B25: ='Chấm công KT'!D27 -> #N/A | C25: ='Chấm công KT'!C27 -> N. Ly Phon | D25: CN-KT | E25: =4/1.25 -> 3.2 | F25: =600000/25000 -> 24 | H25: 32 | Q25: =SUM(E25:P25) -> 59.2 | R25: =VLOOKUP(C25,'BTH mủ tạp'!$C$17:$AI$96,33,0) -> 1562 | T25: =S25*50/100 -> 0 | U25: =R25 -> 1562 | V25: =VLOOKUP(C25,'Chấm công KT'!$C$13:$AJ$92,34,0) -> 27 | W25: =VLOOKUP(C25,'Chấm công KT'!$C$13:$AK$92,35,0) -> 4 | Z25: =VLOOKUP(C25,'Chấm công KT'!$C$13:$AN$92,38,0) -> 0 | AA25: =VLOOKUP(C25,'Chấm công KT'!$C$13:$AO$92,39,0) -> 0 | AC25: =Q25 -> 59.2 | AD25: =VLOOKUP(C25,'BTH mủ tạp'!$C$17:$AL$160,36,0) -> A
A26: 16 | B26: ='Chấm công KT'!D28 -> 03469 | C26: ='Chấm công KT'!C28 -> T. Xôm Va Nít | D26: CN-KT | E26: =4/1.25 -> 3.2 | F26: =600000/25000 -> 24 | H26: 32 | Q26: =SUM(E26:P26) -> 59.2 | R26: =VLOOKUP(C26,'BTH mủ tạp'!$C$17:$AI$96,33,0) -> 1985 | T26: =S26*50/100 -> 0 | U26: =R26 -> 1985 | V26: =VLOOKUP(C26,'Chấm công KT'!$C$13:$AJ$92,34,0) -> 26 | W26: =VLOOKUP(C26,'Chấm công KT'!$C$13:$AK$92,35,0) -> 4 | Z26: =VLOOKUP(C26,'Chấm công KT'!$C$13:$AN$92,38,0) -> 0 | AA26: =VLOOKUP(C26,'Chấm công KT'!$C$13:$AO$92,39,0) -> 0 | AC26: =Q26 -> 59.2 | AD26: =VLOOKUP(C26,'BTH mủ tạp'!$C$17:$AL$160,36,0) -> A
A27: 17 | B27: ='Chấm công KT'!D29 -> 03470 | C27: ='Chấm công KT'!C29 -> T. Lọi | D27: CN-KT | E27: =4/1.25 -> 3.2 | F27: =600000/25000 -> 24 | H27: 32 | Q27: =SUM(E27:P27) -> 59.2 | R27: =VLOOKUP(C27,'BTH mủ tạp'!$C$17:$AI$96,33,0) -> 673 | T27: =S27*50/100 -> 0 | U27: =R27 -> 673 | V27: =VLOOKUP(C27,'Chấm công KT'!$C$13:$AJ$92,34,0) -> 20 | W27: =VLOOKUP(C27,'Chấm công KT'!$C$13:$AK$92,35,0) -> 3 | Z27: =VLOOKUP(C27,'Chấm công KT'!$C$13:$AN$92,38,0) -> 0 | AA27: =VLOOKUP(C27,'Chấm công KT'!$C$13:$AO$92,39,0) -> 0 | AC27: =Q27 -> 59.2 | AD27: =VLOOKUP(C27,'BTH mủ tạp'!$C$17:$AL$160,36,0) -> A
A28: 18 | B28: ='Chấm công KT'!D30 -> 03471 | C28: ='Chấm công KT'!C30 -> T. Phô Thong | D28: CN-KT | E28: =4/1.25 -> 3.2 | F28: =600000/25000 -> 24 | H28: 32 | Q28: =SUM(E28:P28) -> 59.2 | R28: =VLOOKUP(C28,'BTH mủ tạp'!$C$17:$AI$96,33,0) -> 1929 | T28: =S28*50/100 -> 0 | U28: =R28 -> 1929 | V28: =VLOOKUP(C28,'Chấm công KT'!$C$13:$AJ$92,34,0) -> 27 | W28: =VLOOKUP(C28,'Chấm công KT'!$C$13:$AK$92,35,0) -> 4 | Z28: =VLOOKUP(C28,'Chấm công KT'!$C$13:$AN$92,38,0) -> 0 | AA28: =VLOOKUP(C28,'Chấm công KT'!$C$13:$AO$92,39,0) -> 0 | AC28: =Q28 -> 59.2 | AD28: =VLOOKUP(C28,'BTH mủ tạp'!$C$17:$AL$160,36,0) -> A | AF28: =Q9-10084 -> -892.12
A29: 19 | B29: ='Chấm công KT'!D31 -> 03472 | C29: ='Chấm công KT'!C31 -> N. Soi | D29: CN-KT | E29: =4/1.25 -> 3.2 | F29: =600000/25000 -> 24 | H29: 32 | Q29: =SUM(E29:P29) -> 59.2 | R29: =VLOOKUP(C29,'BTH mủ tạp'!$C$17:$AI$96,33,0) -> 1261 | T29: =S29*50/100 -> 0 | U29: =R29 -> 1261 | V29: =VLOOKUP(C29,'Chấm công KT'!$C$13:$AJ$92,34,0) -> 27 | W29: =VLOOKUP(C29,'Chấm công KT'!$C$13:$AK$92,35,0) -> 3 | Z29: =VLOOKUP(C29,'Chấm công KT'!$C$13:$AN$92,38,0) -> 0 | AA29: =VLOOKUP(C29,'Chấm công KT'!$C$13:$AO$92,39,0) -> 0 | AC29: =Q29 -> 59.2 | AD29: =VLOOKUP(C29,'BTH mủ tạp'!$C$17:$AL$160,36,0) -> A
A30: 20 | B30: ='Chấm công KT'!D32 -> 03473 | C30: ='Chấm công KT'!C32 -> N. Me Kha La | D30: CN-KT | E30: =4/1.25 -> 3.2 | F30: =600000/25000 -> 24 | H30: 32 | Q30: =SUM(E30:P30) -> 59.2 | R30: =VLOOKUP(C30,'BTH mủ tạp'!$C$17:$AI$96,33,0) -> 2186 | T30: =S30*50/100 -> 0 | U30: =R30 -> 2186 | V30: =VLOOKUP(C30,'Chấm công KT'!$C$13:$AJ$92,34,0) -> 26 | W30: =VLOOKUP(C30,'Chấm công KT'!$C$13:$AK$92,35,0) -> 4 | Z30: =VLOOKUP(C30,'Chấm công KT'!$C$13:$AN$92,38,0) -> 0 | AA30: =VLOOKUP(C30,'Chấm công KT'!$C$13:$AO$92,39,0) -> 0 | AC30: =Q30 -> 59.2 | AD30: =VLOOKUP(C30,'BTH mủ tạp'!$C$17:$AL$160,36,0) -> A
A31: 21 | B31: ='Chấm công KT'!D33 -> 03474 | C31: ='Chấm công KT'!C33 -> N. Mon Khăm | D31: CN-KT | E31: =4/1.25 -> 3.2 | F31: =600000/25000 -> 24 | H31: 32 | Q31: =SUM(E31:P31) -> 59.2 | R31: =VLOOKUP(C31,'BTH mủ tạp'!$C$17:$AI$96,33,0) -> 1011 | T31: =S31*50/100 -> 0 | U31: =R31 -> 1011 | V31: =VLOOKUP(C31,'Chấm công KT'!$C$13:$AJ$92,34,0) -> 24 | W31: =VLOOKUP(C31,'Chấm công KT'!$C$13:$AK$92,35,0) -> 4 | Z31: =VLOOKUP(C31,'Chấm công KT'!$C$13:$AN$92,38,0) -> 0 | AA31: =VLOOKUP(C31,'Chấm công KT'!$C$13:$AO$92,39,0) -> 0 | AC31: =Q31 -> 59.2 | AD31: =VLOOKUP(C31,'BTH mủ tạp'!$C$17:$AL$160,36,0) -> A
A32: 22 | B32: ='Chấm công KT'!D34 -> #N/A | C32: ='Chấm công KT'!C34 -> N. Bua Lay | D32: CN-KT | E32: =4/1.25 -> 3.2 | F32: =600000/25000 -> 24 | H32: 32 | Q32: =SUM(E32:P32) -> 59.2 | R32: =VLOOKUP(C32,'BTH mủ tạp'!$C$17:$AI$96,33,0) -> 1305 | T32: =S32*50/100 -> 0 | U32: =R32 -> 1305 | V32: =VLOOKUP(C32,'Chấm công KT'!$C$13:$AJ$92,34,0) -> 23 | W32: =VLOOKUP(C32,'Chấm công KT'!$C$13:$AK$92,35,0) -> 4 | Z32: =VLOOKUP(C32,'Chấm công KT'!$C$13:$AN$92,38,0) -> 0 | AA32: =VLOOKUP(C32,'Chấm công KT'!$C$13:$AO$92,39,0) -> 0 | AC32: =Q32 -> 59.2 | AD32: =VLOOKUP(C32,'BTH mủ tạp'!$C$17:$AL$160,36,0) -> B
A33: 23 | B33: ='Chấm công KT'!D35 -> 03476 | C33: ='Chấm công KT'!C35 -> T. Bin Ly. | D33: CN-KT | E33: =4/1.25 -> 3.2 | F33: =600000/25000 -> 24 | H33: 32 | Q33: =SUM(E33:P33) -> 59.2 | R33: =VLOOKUP(C33,'BTH mủ tạp'!$C$17:$AI$96,33,0) -> 1795 | T33: =S33*50/100 -> 0 | U33: =R33 -> 1795 | V33: =VLOOKUP(C33,'Chấm công KT'!$C$13:$AJ$92,34,0) -> 27 | W33: =VLOOKUP(C33,'Chấm công KT'!$C$13:$AK$92,35,0) -> 4 | Z33: =VLOOKUP(C33,'Chấm công KT'!$C$13:$AN$92,38,0) -> 0 | AA33: =VLOOKUP(C33,'Chấm công KT'!$C$13:$AO$92,39,0) -> 0 | AC33: =Q33 -> 59.2 | AD33: =VLOOKUP(C33,'BTH mủ tạp'!$C$17:$AL$160,36,0) -> A
A34: 24 | B34: ='Chấm công KT'!D36 -> 03477 | C34: ='Chấm công KT'!C36 -> N. Phim Phon. | D34: CN-KT | E34: =4/1.25 -> 3.2 | F34: =600000/25000 -> 24 | H34: 32 | Q34: =SUM(E34:P34) -> 59.2 | R34: =VLOOKUP(C34,'BTH mủ tạp'!$C$17:$AI$96,33,0) -> 1083 | T34: =S34*50/100 -> 0 | U34: =R34 -> 1083 | V34: =VLOOKUP(C34,'Chấm công KT'!$C$13:$AJ$92,34,0) -> 23 | W34: =VLOOKUP(C34,'Chấm công KT'!$C$13:$AK$92,35,0) -> 3 | Z34: =VLOOKUP(C34,'Chấm công KT'!$C$13:$AN$92,38,0) -> 0 | AA34: =VLOOKUP(C34,'Chấm công KT'!$C$13:$AO$92,39,0) -> 0 | AC34: =Q34 -> 59.2 | AD34: =VLOOKUP(C34,'BTH mủ tạp'!$C$17:$AL$160,36,0) -> B
A35: 25 | B35: ='Chấm công KT'!D37 -> 03478 | C35: ='Chấm công KT'!C37 -> N. Nong | D35: CN-KT | E35: =4/1.25 -> 3.2 | F35: =600000/25000 -> 24 | H35: 32 | Q35: =SUM(E35:P35) -> 59.2 | R35: =VLOOKUP(C35,'BTH mủ tạp'!$C$17:$AI$96,33,0) -> 1798 | T35: =S35*50/100 -> 0 | U35: =R35 -> 1798 | V35: =VLOOKUP(C35,'Chấm công KT'!$C$13:$AJ$92,34,0) -> 27 | W35: =VLOOKUP(C35,'Chấm công KT'!$C$13:$AK$92,35,0) -> 3 | Z35: =VLOOKUP(C35,'Chấm công KT'!$C$13:$AN$92,38,0) -> 0 | AA35: =VLOOKUP(C35,'Chấm công KT'!$C$13:$AO$92,39,0) -> 0 | AC35: =Q35 -> 59.2 | AD35: =VLOOKUP(C35,'BTH mủ tạp'!$C$17:$AL$160,36,0) -> A
A36: 26 | B36: ='Chấm công KT'!D38 -> 03479 | C36: ='Chấm công KT'!C38 -> N. Tun 1 | D36: CN-KT | E36: =4/1.25 -> 3.2 | F36: =600000/25000 -> 24 | H36: 32 | Q36: =SUM(E36:P36) -> 59.2 | R36: =VLOOKUP(C36,'BTH mủ tạp'!$C$17:$AI$96,33,0) -> 1356 | T36: =S36*50/100 -> 0 | U36: =R36 -> 1356 | V36: =VLOOKUP(C36,'Chấm công KT'!$C$13:$AJ$92,34,0) -> 26 | W36: =VLOOKUP(C36,'Chấm công KT'!$C$13:$AK$92,35,0) -> 4 | Z36: =VLOOKUP(C36,'Chấm công KT'!$C$13:$AN$92,38,0) -> 0 | AA36: =VLOOKUP(C36,'Chấm công KT'!$C$13:$AO$92,39,0) -> 0 | AC36: =Q36 -> 59.2 | AD36: =VLOOKUP(C36,'BTH mủ tạp'!$C$17:$AL$160,36,0) -> A
A37: 27 | B37: ='Chấm công KT'!D39 -> 03480 | C37: ='Chấm công KT'!C39 -> T . Lốc | D37: CN-KT | E37: =4/1.25 -> 3.2 | F37: =600000/25000 -> 24 | H37: 32 | Q37: =SUM(E37:P37) -> 59.2 | R37: =VLOOKUP(C37,'BTH mủ tạp'!$C$17:$AI$96,33,0) -> 1357 | T37: =S37*50/100 -> 0 | U37: =R37 -> 1357 | V37: =VLOOKUP(C37,'Chấm công KT'!$C$13:$AJ$92,34,0) -> 26 | W37: =VLOOKUP(C37,'Chấm công KT'!$C$13:$AK$92,35,0) -> 4 | Z37: =VLOOKUP(C37,'Chấm công KT'!$C$13:$AN$92,38,0) -> 0 | AA37: =VLOOKUP(C37,'Chấm công KT'!$C$13:$AO$92,39,0) -> 0 | AC37: =Q37 -> 59.2 | AD37: =VLOOKUP(C37,'BTH mủ tạp'!$C$17:$AL$160,36,0) -> B
A38: 28 | B38: ='Chấm công KT'!D40 -> 03481 | C38: ='Chấm công KT'!C40 -> N . Khâm (1) | D38: CN-KT | E38: =4/1.25 -> 3.2 | F38: =600000/25000 -> 24 | H38: 32 | Q38: =SUM(E38:P38) -> 59.2 | R38: =VLOOKUP(C38,'BTH mủ tạp'!$C$17:$AI$96,33,0) -> 1772 | T38: =S38*50/100 -> 0 | U38: =R38 -> 1772 | V38: =VLOOKUP(C38,'Chấm công KT'!$C$13:$AJ$92,34,0) -> 24 | W38: =VLOOKUP(C38,'Chấm công KT'!$C$13:$AK$92,35,0) -> 4 | Z38: =VLOOKUP(C38,'Chấm công KT'!$C$13:$AN$92,38,0) -> 0 | AA38: =VLOOKUP(C38,'Chấm công KT'!$C$13:$AO$92,39,0) -> 0 | AC38: =Q38 -> 59.2 | AD38: =VLOOKUP(C38,'BTH mủ tạp'!$C$17:$AL$160,36,0) -> A
