Workbook

Sheet thưởng 300
A1: CỘNG HÒA DÂN CHỦ NHÂN DÂN LÀO
A2: Hòa Bình - Độc Lập - Dân Chủ - Thống Nhất - Thịnh Vượng
A3: -----oOo-----
A5: CÔNG TY TNHH CỔ PHẦN QUASA - GERUCO LÀO
A6: ĐƠN VỊ: NÔNG TRƯỜNG 1
A8: BẢNG THANH TOÁN PHỤ CẤP TRANG BỊ VẬT TƯ - XÃ MIỆNG CẠO CHO CÔNG NHÂN KHAI THÁC
A10: STT | C10: Mã số nhân viên | E10: Tên công nhân | F10: Chức vụ | G10: Thành tiền(kíp) | H10: Kí Nhận | I10: Ghi chú
A11: ĐỘI 1 | G11: =SUM(G12:G54) -> 21500000
A12: 1 | B12: 1 | E12: Bôn | F12: CNKT | G12: 500000 | I12: =E12 -> Bôn
A13: 2 | B13: 2 | E13: E | F13: CNKT | G13: 500000 | I13: =E13 -> E
A14: 3 | B14: 3 | E14: Khương (3) | F14: CNKT | G14: 500000 | I14: =E14 -> Khương (3)
A15: 4 | B15: 4 | E15: Nít Ni Lanh | F15: CNKT | G15: 500000 | I15: =E15 -> Nít Ni Lanh
A16: 5 | B16: 5 | E16: Khăm Đeng | F16: CNKT | G16: 500000 | I16: =E16 -> Khăm Đeng
A17: 6 | B17: 6 | E17: Nàng Năt | F17: CNKT | G17: 500000 | I17: =E17 -> Nàng Năt
A18: 7 | B18: 7 | E18: Xay (3) | F18: CNKT | G18: 500000 | I18: =E18 -> Xay (3)
A19: 8 | B19: 8 | E19: Xôn | F19: CNKT | G19: 500000 | I19: =E19 -> Xôn
A20: 9 | B20: 9 | E20: Phum Hom | F20: CNKT | G20: 500000 | I20: =E20 -> Phum Hom
A21: 10 | B21: 10 | E21: Pa Lay | F21: CNKT | G21: 500000 | I21: =E21 -> Pa Lay
A22: 11 | B22: 11 | E22: Măm | F22: CNKT | G22: 500000 | I22: =E22 -> Măm
A23: 12 | B23: 12 | E23: Muôi | F23: CNKT | G23: 500000 | I23: =E23 -> Muôi
... A54: 43 | B54: 43 | E54: Me Son | F54: CNKT | G54: 500000 | I54: =E54 -> Me Son
A55: ĐỘI 2 | G55: =SUM(G56:G112) -> 28500000
A56: 44 | B56: 1 | E56: Bôn | F56: CNKT | G56: 500000 | I56: =E56 -> Bôn
A57: 45 | B57: 2 | E57: E | F57: CNKT | G57: 500000 | I57: =E57 -> E
A58: 46 | B58: 3 | E58: Khương (3) | F58: CNKT | G58: 500000 | I58: =E58 -> Khương (3)
A59: 47 | B59: 4 | E59: Nít Ni Lanh | F59: CNKT | G59: 500000 | I59: =E59 -> Nít Ni Lanh
A60: 48 | B60: 5 | E60: Khăm Đeng | F60: CNKT | G60: 500000 | I60: =E60 -> Khăm Đeng
A61: 49 | B61: 6 | E61: Nàng Năt | F61: CNKT | G61: 500000 | I61: =E61 -> Nàng Năt
A62: 50 | B62: 7 | E62: Xay (3) | F62: CNKT | G62: 500000 | I62: =E62 -> Xay (3)
A63: 51 | B63: 8 | E63: Xôn | F63: CNKT | G63: 500000 | I63: =E63 -> Xôn
A64: 52 | B64: 9 | E64: Phum Hom | F64: CNKT | G64: 500000 | I64: =E64 -> Phum Hom
A65: 53 | B65: 10 | E65: Pa Lay | F65: CNKT | G65: 500000 | I65: =E65 -> Pa Lay
A66: 54 | B66: 11 | E66: Măm | F66: CNKT | G66: 500000 | I66: =E66 -> Măm
A67: 55 | B67: 12 | E67: Muôi | F67: CNKT | G67: 500000 | I67: =E67 -> Muôi
... A99: 87 | B99: 44 | E99: Nít | F99: CNKT | G99: 500000 | I99: =E99 -> Nít
A100: 88 | B100: 45 | E100: Nui | F100: CNKT | G100: 500000 | I100: =E100 -> Nui | Q100: =760.5-48.5 -> 712
A101: 89 | B101: 46 | E101: Đuông Chăn | F101: CNKT | G101: 500000 | I101: =E101 -> Đuông Chăn | Q101: =+Q100*30 -> 21360
A102: 90 | B102: 47 | E102: Đăm (3) | F102: CNKT | G102: 500000 | I102: =E102 -> Đăm (3)
A103: 91 | B103: 48 | E103: Hăm Nọi A | F103: CNKT | G103: 500000 | I103: =E103 -> Hăm Nọi A
A104: 92 | B104: 49 | E104: Hip | F104: CNKT | G104: 500000 | I104: =E104 -> Hip
...

Sheet PLC   (2)
A1: ĐỘI 1
A2: =$K$2 -> THÁNG 09/2024 | G2: =$K$2 -> THÁNG 09/2024 | K2: THÁNG 09/2024
A3: Họ và tên | B3: Thô | G3: Họ và tên | H3: Mè Ta Van | L3: 680.47
A4: Công sản phẩm | B4: ²½ìò©ªະພັນ | C4: =VLOOKUP(B3,'LƯƠNG KT'!$D$16:$AC$184,3,0) -> #N/A | D4: =+C4*25000 -> #N/A | G4: Công sản phẩm | H4: ²½ìò©ªະພັນ | I4: =VLOOKUP(H3,'LƯƠNG KT'!$D$16:$AC$184,3,0) -> #N/A | J4: =+I4*25000 -> #N/A | K4: Công đi cạo | L4: =46.1*L3 -> 31369.667
A5: Công đi cạo | B5: ໝວດໄປຂີດ | C5: =VLOOKUP(B3,'LƯƠNG KT'!$D$16:$AC$184,14,0) -> #N/A | D5: =C5*$L$4 -> #N/A | G5: Công đi cạo | H5: ໝວດໄປຂີດ | I5: =VLOOKUP(H3,'LƯƠNG KT'!$D$16:$AC$184,14,0) -> #N/A | J5: =I5*$L$4 -> #N/A | K5: Công chủ nhật | L5: =76.9*L3 -> 52328.143
A6: Công làm ngày chủ nhật | B6: ໝວດເຮັດວຽກວັນທິດ | C6: =VLOOKUP(B3,'LƯƠNG KT'!$D$16:$AC$184,15,0) -> #N/A | D6: =C6*$L$5 -> #N/A | G6: Công làm ngày chủ nhật | H6: ໝວດເຮັດວຽກວັນທິດ | I6: =VLOOKUP(H3,'LƯƠNG KT'!$D$16:$AC$184,15,0) -> #N/A | J6: =I6*$L$5 -> #N/A | K6: PC đánh axit | L6: 10000
A7: Công nhỏ axit đánh đông | C7: =VLOOKUP(B3,'LƯƠNG KT'!$D$16:$AC$184,16,0) -> #N/A | D7: =+C7*$L$6 -> #N/A | G7: Công nhỏ axit đánh đông | I7: =VLOOKUP(H3,'LƯƠNG KT'!$D$16:$AC$184,16,0) -> #N/A | J7: =+I7*$L$6 -> #N/A | K7: PC cây non | L7: =30.7*L3 -> 20890.429
A8: Phụ cấp cạo 2 lát | C8: =VLOOKUP(B4,'LƯƠNG KT'!$D$16:$AC$184,16,0) -> #N/A | D8: =+C8*$L$6 -> #N/A | G8: Công nhỏ axit đánh đông | I8: =VLOOKUP(H4,'LƯƠNG KT'!$D$16:$AC$184,16,0) -> #N/A | J8: =+I8*$L$6 -> #N/A | K8: PC cây non | L8: =30.7*L4 -> 963048.78
A9: Phụ cấp tiền lương | C9: =VLOOKUP(B5,'LƯƠNG KT'!$D$16:$AC$184,16,0) -> #N/A | D9: =+C9*$L$6 -> #N/A | G9: Công nhỏ axit đánh đông | I9: =VLOOKUP(H5,'LƯƠNG KT'!$D$16:$AC$184,16,0) -> #N/A | J9: =+I9*$L$6 -> #N/A | K9: PC cây non | L9: =30.7*L5 -> 1606474
A10: Mủ dây | B10: ຢ່າງເສັ້ນ | C10: =VLOOKUP(B3,'LƯƠNG KT'!$D$16:$AC$184,9,0)*$L$10 -> #N/A | D10: =+C10*0.5*3000 -> #N/A | G10: Mủ dây | H10: ຢ່າງເສັ້ນ | I10: =VLOOKUP(H3,'LƯƠNG KT'!$D$16:$AC$184,9,0)*$L$10 -> #N/A | J10: =+I10*0.5*3000 -> #N/A | K10: DRC mủ dây | L10: 0.5
A11: Sản lượng mủ | B11: ໝວດຂີດທັບເກັບຢາງ | C11: =VLOOKUP(B3,'LƯƠNG KT'!$D$16:$AC$184,8,0)*$L$11 -> #N/A | D11: =VLOOKUP(B3,'LƯƠNG KT'!$D$16:$AC$184,13,0)-D10 -> #N/A | G11: Sản lượng mủ | H11: ໝວດຂີດທັບເກັບຢາງ | I11: =VLOOKUP(H3,'LƯƠNG KT'!$D$16:$AC$184,8,0)*$L$11 -> #N/A | J11: =VLOOKUP(H3,'LƯƠNG KT'!$D$16:$AC$184,13,0)-J10 -> #N/A | K11: DRC mủ tạp | L11: 0.42315994
A12: Các khoản trừ | B12: ການຫັກລົບ | G12: Các khoản trừ | H12: ການຫັກລົບ
A13: Tạm ứng | B13: ຄວາມກ້າວໜ້າ | D13: =56*25000 -> 1400000 | G13: Tạm ứng | H13: ຄວາມກ້າວໜ້າ | J13: =56*25000 -> 1400000
A14: Tổng trừ: | B14: ລວມທັງໝົດ | D14: =D13 -> 1400000 | G14: Tổng trừ: | H14: ລວມທັງໝົດ | J14: =J13 -> 1400000
A15: Còn lãnh | B15: ຍັງເຫລືອ | D15: =SUM(D4:D11)-D14 -> #N/A | G15: Còn lãnh | H15: ຍັງເຫລືອ | J15: =SUM(J4:J11)-J14 -> #N/A
L16: Phụ cấp cạo 2 lát | M16: Phụ cấp tiền lương
A18: =$K$2 -> THÁNG 09/2024 | G18: =$K$2 -> THÁNG 09/2024
A19: Họ và tên | B19: Ka Tho | G19: Họ và tên | H19: Xay
A20: Công sản phẩm | B20: ²½ìò©ªະພັນ | C20: =VLOOKUP(B19,'LƯƠNG KT'!$D$16:$AC$184,3,0) -> #N/A | D20: =+C20*25000 -> #N/A | G20: Công sản phẩm | H20: ²½ìò©ªະພັນ | I20: =VLOOKUP(H19,'LƯƠNG KT'!$D$16:$AC$184,3,0) -> #N/A | J20: =+I20*25000 -> #N/A
A21: Công đi cạo | B21: ໝວດໄປຂີດ | C21: =VLOOKUP(B19,'LƯƠNG KT'!$D$16:$AC$184,14,0) -> #N/A | D21: =C21*$L$4 -> #N/A | G21: Công đi cạo | H21: ໝວດໄປຂີດ | I21: =VLOOKUP(H19,'LƯƠNG KT'!$D$16:$AC$184,14,0) -> #N/A | J21: =I21*$L$4 -> #N/A
A22: Công làm ngày chủ nhật | B22: ໝວດເຮັດວຽກວັນທິດ | C22: =VLOOKUP(B19,'LƯƠNG KT'!$D$16:$AC$184,15,0) -> #N/A | D22: =C22*$L$5 -> #N/A | G22: Công làm ngày chủ nhật | H22: ໝວດເຮັດວຽກວັນທິດ | I22: =VLOOKUP(H19,'LƯƠNG KT'!$D$16:$AC$184,15,0) -> #N/A | J22: =I22*$L$5 -> #N/A
A23: Công nhỏ axit đánh đông | C23: =VLOOKUP(B19,'LƯƠNG KT'!$D$16:$AC$184,16,0) -> #N/A | D23: =+C23*$L$6 -> #N/A | G23: Công nhỏ axit đánh đông | I23: =VLOOKUP(H19,'LƯƠNG KT'!$D$16:$AC$184,16,0) -> #N/A | J23: =+I23*$L$6 -> #N/A | M23: =425*50 -> 21250
A24: Công nhỏ axit đánh đông | C24: =VLOOKUP(B20,'LƯƠNG KT'!$D$16:$AC$184,16,0) -> #N/A | D24: =+C24*$L$6 -> #N/A | G24: Công nhỏ axit đánh đông | I24: =VLOOKUP(H20,'LƯƠNG KT'!$D$16:$AC$184,16,0) -> #N/A | J24: =+I24*$L$6 -> #N/A | M24: =425*50 -> 21250
A25: Công nhỏ axit đánh đông | C25: =VLOOKUP(B21,'LƯƠNG KT'!$D$16:$AC$184,16,0) -> #N/A | D25: =+C25*$L$6 -> #N/A | G25: Công nhỏ axit đánh đông | I25: =VLOOKUP(H21,'LƯƠNG KT'!$D$16:$AC$184,16,0) -> #N/A | J25: =+I25*$L$6 -> #N/A | M25: =425*50 -> 21250
A26: Mủ dây | B26: ຢ່າງເສັ້ນ | C26: =VLOOKUP(B19,'LƯƠNG KT'!$D$16:$AC$184,9,0)*$L$10 -> #N/A | D26: =+C26*0.5*3000 -> #N/A | G26: Mủ dây | H26: ຢ່າງເສັ້ນ | I26: =VLOOKUP(H19,'LƯƠNG KT'!$D$16:$AC$184,9,0)*$L$10 -> #N/A | J26: =+I26*0.5*3000 -> #N/A
A27: Sản lượng mủ | B27: ໝວດຂີດທັບເກັບຢາງ | C27: =VLOOKUP(B19,'LƯƠNG KT'!$D$16:$AC$184,8,0)*$L$11 -> #N/A | D27: =VLOOKUP(B19,'LƯƠNG KT'!$D$16:$AC$184,13,0)-D26 -> #N/A | G27: Sản lượng mủ | H27: ໝວດຂີດທັບເກັບຢາງ | I27: =VLOOKUP(H19,'LƯƠNG KT'!$D$16:$AC$184,8,0)*$L$11 -> #N/A | J27: =VLOOKUP(H19,'LƯƠNG KT'!$D$16:$AC$184,13,0)-J26+I21*20000+I22*20000 -> #N/A
A28: Các khoản trừ | B28: ການຫັກລົບ | G28: Các khoản trừ | H28: ການຫັກລົບ
A29: Tạm ứng | B29: ຄວາມກ້າວໜ້າ | D29: =56*25000 -> 1400000 | G29: Tạm ứng | H29: ຄວາມກ້າວໜ້າ | J29: =56*25000 -> 1400000 | M29: =425+9 -> 434 | N29: =+M29*20 -> 8680
A30: Tổng trừ: | B30: ລວມທັງໝົດ | D30: =D29 -> 1400000 | G30: Tổng trừ: | H30: ລວມທັງໝົດ | J30: =J29 -> 1400000 | M30: =+M29*50 -> 21700
A31: Còn lãnh | B31: ຍັງເຫລືອ | D31: =SUM(D20:D27)-D30 -> #N/A | G31: Còn lãnh | H31: ຍັງເຫລືອ | J31: =SUM(J20:J27)-J30 -> #N/A
A34: =$K$2 -> THÁNG 09/2024 | G34: =$K$2 -> THÁNG 09/2024
A35: Họ và tên | B35: Thảo In | G35: Họ và tên | H35: Cha La
A36: Công sản phẩm | B36: ²½ìò©ªະພັນ | C36: =VLOOKUP(B35,'LƯƠNG KT'!$D$16:$AC$184,3,0) -> #N/A | D36: =+C36*25000 -> #N/A | G36: Công sản phẩm | H36: ²½ìò©ªະພັນ | I36: =VLOOKUP(H35,'LƯƠNG KT'!$D$16:$AC$184,3,0) -> #N/A | J36: =+I36*25000 -> #N/A
A37: Công đi cạo | B37: ໝວດໄປຂີດ | C37: =VLOOKUP(B35,'LƯƠNG KT'!$D$16:$AC$184,14,0) -> #N/A | D37: =C37*$L$4 -> #N/A | G37: Công đi cạo | H37: ໝວດໄປຂີດ | I37: =VLOOKUP(H35,'LƯƠNG KT'!$D$16:$AC$184,14,0) -> #N/A | J37: =I37*$L$4 -> #N/A
A38: Công làm ngày chủ nhật | B38: ໝວດເຮັດວຽກວັນທິດ | C38: =VLOOKUP(B35,'LƯƠNG KT'!$D$16:$AC$184,15,0) -> #N/A | D38: =C38*$L$5 -> #N/A | G38: Công làm ngày chủ nhật | H38: ໝວດເຮັດວຽກວັນທິດ | I38: =VLOOKUP(H35,'LƯƠNG KT'!$D$16:$AC$184,15,0) -> #N/A | J38: =I38*$L$5 -> #N/A
A39: Công nhỏ axit đánh đông | C39: =VLOOKUP(B35,'LƯƠNG KT'!$D$16:$AC$184,16,0) -> #N/A | D39: =+C39*$L$6 -> #N/A | G39: Công nhỏ axit đánh đông | I39: =VLOOKUP(H35,'LƯƠNG KT'!$D$16:$AC$184,16,0) -> #N/A | J39: =+I39*$L$6 -> #N/A
A42: Mủ dây | B42: ຢ່າງເສັ້ນ | C42: =VLOOKUP(B35,'LƯƠNG KT'!$D$16:$AC$184,9,0)*$L$10 -> #N/A | D42: =+C42*0.5*3000 -> #N/A | G42: Mủ dây | H42: ຢ່າງເສັ້ນ | I42: =VLOOKUP(H35,'LƯƠNG KT'!$D$16:$AC$184,9,0)*$L$10 -> #N/A | J42: =+I42*0.5*3000 -> #N/A
A43: Sản lượng mủ | B43: ໝວດຂີດທັບເກັບຢາງ | C43: =VLOOKUP(B35,'LƯƠNG KT'!$D$16:$AC$184,8,0)*$L$11 -> #N/A | D43: =VLOOKUP(B35,'LƯƠNG KT'!$D$16:$AC$184,13,0)-D42+C37*20000+C38*20000 -> #N/A | G43: Sản lượng mủ | H43: ໝວດຂີດທັບເກັບຢາງ | I43: =VLOOKUP(H35,'LƯƠNG KT'!$D$16:$AC$184,8,0)*$L$11 -> #N/A | J43: =VLOOKUP(H35,'LƯƠNG KT'!$D$16:$AC$184,13,0)-J42 -> #N/A
A44: Các khoản trừ | B44: ການຫັກລົບ | G44: Các khoản trừ | H44: ການຫັກລົບ
A45: Tạm ứng | B45: ຄວາມກ້າວໜ້າ | D45: =56*25000 -> 1400000 | G45: Tạm ứng | H45: ຄວາມກ້າວໜ້າ | J45: =56*25000 -> 1400000
...

Sheet PCNC BUN 
A1: CỘNG HÒA DÂN CHỦ NHÂN DÂN LÀO
A2: Hòa Bình - Độc Lập - Dân Chủ - Thống Nhất - Thịnh Vượng
A3: -----oOo-----
A5: CÔNG TY TNHH CỔ PHẦN QUASA - GERUCO LÀO
A6: ĐƠN VỊ: NÔNG TRƯỜNG 1
A8: BẢNG THANH TOÁN PHỤ CẤP NGÀY CÔNG CHO CÔNG NHÂN TRỰC TIẾP THÁNG 11 NĂM 2024
A10: STT | C10: Mã số nhân viên | E10: Tên công nhân | F10: Chức vụ | G10: Ngày công | K10: Tổng công | L10: Thành tiền(kíp) | M10: Ký nhận
G11: 2/11 | H11: 3/11 | I11: 4/11 | J11: 5/11
A12: ĐỘI 1 | G12: =COUNTIF(G13:G55,"X") -> 43 | H12: =COUNTIF(H13:H55,"X") -> 43 | I12: =COUNTIF(I13:I55,"X") -> 42 | J12: =COUNTIF(J13:J55,"X") -> 40 | K12: =SUM(K13:K55) -> 168 | L12: =SUM(L13:L55) -> 16800000
A13: 1 | B13: 1 | E13: Thô | F13: CNKT | G13: X | H13: X | I13: X | J13: X | K13: =COUNTIF(G13:J13,"X") -> 4 | L13: =K13*100000 -> 400000
A14: 2 | B14: 2 | E14: Mè Ta Van | F14: CNKT | G14: X | H14: X | I14: X | K14: =COUNTIF(G14:J14,"X") -> 3 | L14: =K14*100000 -> 300000
A15: 3 | B15: 3 | E15: Ka Tho | F15: CNKT | G15: X | H15: X | I15: X | J15: X | K15: =COUNTIF(G15:J15,"X") -> 4 | L15: =K15*100000 -> 400000
A16: 4 | B16: 4 | E16: Xay | F16: CNKT | G16: X | H16: X | I16: X | K16: =COUNTIF(G16:J16,"X") -> 3 | L16: =K16*100000 -> 300000
A17: 5 | B17: 5 | E17: Thảo In | F17: CNKT | G17: X | H17: X | K17: =COUNTIF(G17:J17,"X") -> 2 | L17: =K17*100000 -> 200000
A18: 6 | B18: 6 | E18: Cha La | F18: CNKT | G18: X | H18: X | I18: X | J18: X | K18: =COUNTIF(G18:J18,"X") -> 4 | L18: =K18*100000 -> 400000
A19: 7 | B19: 7 | E19: Nang Nga | F19: CNKT | G19: X | H19: X | I19: X | J19: X | K19: =COUNTIF(G19:J19,"X") -> 4 | L19: =K19*100000 -> 400000
A20: 8 | B20: 8 | E20: Khăm Đi | F20: CNKT | G20: X | H20: X | I20: X | J20: X | K20: =COUNTIF(G20:J20,"X") -> 4 | L20: =K20*100000 -> 400000
A21: 9 | B21: 9 | E21: Me Đuông | F21: CNKT | G21: X | H21: X | I21: X | J21: X | K21: =COUNTIF(G21:J21,"X") -> 4 | L21: =K21*100000 -> 400000
A22: 10 | B22: 10 | E22: Nang Môn | F22: CNKT | G22: X | H22: X | I22: X | J22: X | K22: =COUNTIF(G22:J22,"X") -> 4 | L22: =K22*100000 -> 400000
A23: 11 | B23: 11 | E23: Ziên | F23: CNKT | G23: X | H23: X | I23: X | J23: X | K23: =COUNTIF(G23:J23,"X") -> 4 | L23: =K23*100000 -> 400000
A24: 12 | B24: 12 | E24: Me Pê | F24: CNKT | G24: X | H24: X | I24: X | J24: X | K24: =COUNTIF(G24:J24,"X") -> 4 | L24: =K24*100000 -> 400000
A25: 13 | B25: 13 | E25: Thảo chòi | F25: CNKT | G25: X | H25: X | I25: X | J25: X | K25: =COUNTIF(G25:J25,"X") -> 4 | L25: =K25*100000 -> 400000
A26: 14 | B26: 14 | E26: Tìng A | F26: CNKT | G26: X | H26: X | I26: X | J26: X | K26: =COUNTIF(G26:J26,"X") -> 4 | L26: =K26*100000 -> 400000
A27: 15 | B27: 15 | E27: Phò Set Tha | F27: CNKT | G27: X | H27: X | I27: X | J27: X | K27: =COUNTIF(G27:J27,"X") -> 4 | L27: =K27*100000 -> 400000
A28: 16 | B28: 16 | E28: Sắt | F28: CNKT | G28: X | H28: X | I28: X | J28: X | K28: =COUNTIF(G28:J28,"X") -> 4 | L28: =K28*100000 -> 400000
A29: 17 | B29: 17 | E29: Khăm | F29: CNKT | G29: X | H29: X | I29: X | J29: X | K29: =COUNTIF(G29:J29,"X") -> 4 | L29: =K29*100000 -> 400000
... A55: 43 | B55: 43 | E55: Nang Hỏm | F55: CNKT | G55: X | H55: X | I55: X | J55: X | K55: =COUNTIF(G55:J55,"X") -> 4 | L55: =K55*100000 -> 400000
A56: ĐỘI 2 | G56: =COUNTIF(G57:G111,"X") -> 50 | H56: =COUNTIF(H57:H111,"X") -> 53 | I56: =COUNTIF(I57:I111,"X") -> 52 | J56: =COUNTIF(J57:J111,"X") -> 49 | K56: =SUM(K57:K111) -> 204 | L56: =SUM(L57:L111) -> 20400000
A57: 44 | B57: 1 | E57: Lếc | F57: CNKT | I57: X | K57: =COUNTIF(G57:J57,"X") -> 1 | L57: =K57*100000 -> 100000
A58: 45 | B58: 2 | E58: Hăm Lẹ | F58: CNKT | G58: X | H58: X | I58: X | J58: X | K58: =COUNTIF(G58:J58,"X") -> 4 | L58: =K58*100000 -> 400000
A59: 46 | B59: 3 | E59: Vông | F59: CNKT | G59: X | H59: X | I59: X | J59: X | K59: =COUNTIF(G59:J59,"X") -> 4 | L59: =K59*100000 -> 400000
A60: 47 | B60: 4 | E60: Ma Ni Son | F60: CNKT | G60: X | H60: X | I60: X | J60: X | K60: =COUNTIF(G60:J60,"X") -> 4 | L60: =K60*100000 -> 400000
A61: 48 | B61: 5 | E61: Cong Ma | F61: CNKT | G61: X | H61: X | I61: X | J61: X | K61: =COUNTIF(G61:J61,"X") -> 4 | L61: =K61*100000 -> 400000 | P61: =5+2+3+6 -> 16
A62: 49 | B62: 6 | E62: Kệt | F62: CNKT | H62: X | I62: X | J62: X | K62: =COUNTIF(G62:J62,"X") -> 3 | L62: =K62*100000 -> 300000 | P62: =55*4 -> 220
A63: 50 | B63: 7 | E63: Măn | F63: CNKT | G63: X | H63: X | I63: X | J63: X | K63: =COUNTIF(G63:J63,"X") -> 4 | L63: =K63*100000 -> 400000 | P63: =+P62-P61 -> 204
A64: 51 | B64: 8 | E64: Soi | F64: CNKT | G64: X | H64: X | J64: X | K64: =COUNTIF(G64:J64,"X") -> 3 | L64: =K64*100000 -> 300000
A65: 52 | B65: 9 | E65: Phò Mom | F65: CNKT | G65: X | H65: X | I65: X | J65: X | K65: =COUNTIF(G65:J65,"X") -> 4 | L65: =K65*100000 -> 400000
A66: 53 | B66: 10 | E66: Pệt | F66: CNKT | G66: X | H66: X | I66: X | K66: =COUNTIF(G66:J66,"X") -> 3 | L66: =K66*100000 -> 300000
A67: 54 | B67: 11 | E67: Khay Khăm | F67: CNKT | G67: X | H67: X | I67: X | J67: X | K67: =COUNTIF(G67:J67,"X") -> 4 | L67: =K67*100000 -> 400000
A68: 55 | B68: 12 | E68: Ô Lích | F68: CNKT | G68: X | H68: X | I68: X | J68: X | K68: =COUNTIF(G68:J68,"X") -> 4 | L68: =K68*100000 -> 400000
...

Sheet LƯƠNG GIA THUỘC THÁNG 11
A1: CỘNG HOÀ DÂN CHỦ NHÂN DÂN LÀO
A2: Hoà bình - Độc lập - Dân chủ - Thống nhất - Thịnh vượng
A3: ----oOo----
A4: CÔNG TY TNHH CỔ PHẦN QUASA - GERUCO LÀO
A5: NÔNG TRƯỜNG CAO SU SỐ 1
A6: BẢNG LƯƠNG CB QUẢN LÝ & CN TRỰC TIẾP NGƯỜI LÀO THÁNG 11 NĂM 2024
D8: Tỷ giá Bath qua Kip | F8: 660
A10: Stt | B10: Mã nhân viên | C10: Lào | D10: Việt Nam | E10: Chức vụ | F10: Ký tên | G10: Lương | J10: Tổng tiền lương | K10: Thưởng hoàn thanh nước rút | L10: Thuế TNCN | M10: Tiền lương còn lại | N10: Ghi chú
G11: Lương chăm sóc | H11: Lương sản lượng | I11: Lương phụ cấp
A12: ì© | C12: §ˆ²¾¦¾ì¾¸ | D12: §ˆ²¾¦¾¹¸¼© | E12: ª¿ÁÎÈ¤ | G12: ¸ñ­¤¾­ | H12: À¤ò­À©õº­ª¾ ´°½ìò©ª½²ñ­ | I12: º÷©Îø­¡ó©µ¾¤* | J12: ລວມເປັນເເງິນ | K12: ì¸´À¤ò­»ñ® | L12: º¾¡º­ì¾¨ Ä©É | M12: À¤ò­»ñ ®ªö¸¥ò¤
A13: 1 | C13: ອ່ວນ | D13: Sủng | E13: CNKT | G13: 40000 | H13: 614840.62 | I13: 118679 | J13: =SUM(G13:I13) -> 773519.62 | M13: =J13-L13 -> 773519.62 | O13: =1300000-M13 -> 526480.38
A14: 2 | C14: ຕອງ | D14: Thảo Mút | E14: CNKT | G14: 40000 | H14: 554373.1 | I14: 107985.27 | J14: =SUM(G14:I14) -> 702358.37 | M14: =J14-L14 -> 702358.37 | O14: =MIN(M14:M193,M195:M524,M526:M1097,M1099:M1141,M1143:M1183,M1185:M1694,M1696:M2162,M2164:M2552) -> 544338.9
A15: 3 | B15: =VLOOKUP(D15,'[1]DS CN MOI UP'!$B$11:$C$447,2,0) -> 02429 | C15: ຄຳບຸນ | D15: Nang Thôn | E15: CNKT | G15: 40000 | H15: 554373.1 | I15: 106506.79 | J15: =SUM(G15:I15) -> 700879.89 | M15: =J15-L15 -> 700879.89
A16: 4 | B16: =VLOOKUP(D16,'[1]DS CN MOI UP'!$B$11:$C$447,2,0) -> #N/A | C16: ນ ວັນ | D16: Khai Thong | E16: CNKT | G16: 40000 | H16: 554373.1 | I16: 75304.754 | J16: =SUM(G16:I16) -> 669677.85 | M16: =J16-L16 -> 669677.85
A17: 5 | B17: =VLOOKUP(D17,'[1]DS CN MOI UP'!$B$11:$C$447,2,0) -> 02431 | C17: ນ ວັນ | D17: Xăm Phon | E17: CNKT | G17: 40000 | H17: 635040.19 | I17: 150609.51 | J17: =SUM(G17:I17) -> 825649.7 | M17: =J17-L17 -> 825649.7
A18: 6 | B18: =VLOOKUP(D18,'[1]DS CN MOI UP'!$B$11:$C$447,2,0) -> #N/A | C18: ນ ວັນ | D18: Nang Tìng | E18: CNKT | G18: 40000 | H18: 544338.9 | I18: 146532.6 | J18: =SUM(G18:I18) -> 730871.5 | M18: =J18-L18 -> 730871.5
A19: 7 | B19: =VLOOKUP(D19,'[1]DS CN MOI UP'!$B$11:$C$447,2,0) -> 02433 | C19: ນ ວັນ | D19: Me Đuông | E19: CNKT | G19: 40000 | H19: 574572.66 | I19: 107519.12 | J19: =SUM(G19:I19) -> 722091.79 | M19: =J19-L19 -> 722091.79
A20: 8 | B20: =VLOOKUP(D20,'[1]DS CN MOI UP'!$B$11:$C$447,2,0) -> #N/A | C20: ນ ວັນ | D20: Xơi | E20: CNKT | G20: 40000 | H20: 604806.43 | I20: 109019.12 | J20: =SUM(G20:I20) -> 753825.55 | M20: =J20-L20 -> 753825.55
A21: 9 | B21: =VLOOKUP(D21,'[1]DS CN MOI UP'!$B$11:$C$447,2,0) -> 03436 | C21: ນ ວັນ | D21: Sắt | E21: CNKT | G21: 40000 | H21: 584606.86 | I21: 229728.84 | J21: =SUM(G21:I21) -> 854335.7 | M21: =J21-L21 -> 854335.7
A22: 10 | B22: =VLOOKUP(D22,'[1]DS CN MOI UP'!$B$11:$C$447,2,0) -> 02638 | C22: ນ ວັນ | D22: Đăm | E22: CNKT | G22: 40000 | H22: 635040.19 | I22: 193212.23 | J22: =SUM(G22:I22) -> 868252.41 | M22: =J22-L22 -> 868252.41
A23: 11 | B23: =VLOOKUP(D23,'[1]DS CN MOI UP'!$B$11:$C$447,2,0) -> 02437 | C23: ນ ວັນ | D23: Bun Nác | E23: CNKT | G23: 40000 | H23: 524139.34 | I23: 524139.34 | J23: =SUM(G23:I23) -> 1088278.7 | M23: =J23-L23 -> 1088278.7
A24: 12 | B24: =VLOOKUP(D24,'[1]DS CN MOI UP'!$B$11:$C$447,2,0) -> 02438 | C24: ນ ວັນ | D24: Nàng Chăn A | E24: CNKT | G24: 40000 | H24: 635040.19 | I24: 524139.34 | J24: =SUM(G24:I24) -> 1199179.5 | M24: =J24-L24 -> 1199179.5
A25: 13 | B25: =VLOOKUP(D25,'[1]DS CN MOI UP'!$B$11:$C$447,2,0) -> 02440 | C25: ນ ວັນ | D25: Thô | E25: CNKT | G25: 40000 | H25: 635040.19 | I25: 524139.34 | J25: =SUM(G25:I25) -> 1199179.5 | M25: =J25-L25 -> 1199179.5
A26: 14 | B26: =VLOOKUP(D26,'[1]DS CN MOI UP'!$B$11:$C$447,2,0) -> 02442 | C26: ນ ວັນ | D26: Nang Thong | E26: CNKT | G26: 40000 | H26: 554373.1 | I26: 524139.34 | J26: =SUM(G26:I26) -> 1118512.4 | M26: =J26-L26 -> 1118512.4
... A33: 21 | B33: =VLOOKUP(D33,'[1]DS CN MOI UP'!$B$11:$C$447,2,0) -> #N/A | C33: ແຕງ | D33: Thảo Nọi | E33: CNKT | G33: 40000 | H33: 554373.1 | I33: 554373.1 | J33: =SUM(G33:I33) -> 1148746.2 | M33: =J33-L33 -> 1148746.2
A34: 22 | B34: =VLOOKUP(D34,'[1]DS CN MOI UP'!$B$11:$C$447,2,0) -> #N/A | C34: ແຕງ | D34: Phò Thiêm | E34: CNKT | H34: 635040.19 | I34: 635040.19 | J34: =SUM(G34:I34) -> 1270080.4 | M34: =J34-L34 -> 1270080.4
A35: 23 | B35: =VLOOKUP(D35,'[1]DS CN MOI UP'!$B$11:$C$447,2,0) -> #N/A | C35: ແຕງ | D35: Nàng Nun | E35: CNKT | G35: 40000 | H35: 544338.9 | I35: 544338.9 | J35: =SUM(G35:I35) -> 1128677.8 | M35: =J35-L35 -> 1128677.8
A36: 24 | B36: =VLOOKUP(D36,'[1]DS CN MOI UP'!$B$11:$C$447,2,0) -> #N/A | C36: ແຕງ | D36: Thảo Bổ | E36: CNKT | G36: 40000 | H36: 574572.66 | I36: 574572.66 | J36: =SUM(G36:I36) -> 1189145.3 | M36: =J36-L36 -> 1189145.3
A37: 25 | B37: =VLOOKUP(D37,'[1]DS CN MOI UP'!$B$11:$C$447,2,0) -> #N/A | C37: ແຕງ | D37: Nàng Tủi | E37: CNKT | G37: 40000 | H37: 604806.43 | I37: 604806.43 | J37: =SUM(G37:I37) -> 1249612.9 | M37: =J37-L37 -> 1249612.9
A38: 26 | B38: =VLOOKUP(D38,'[1]DS CN MOI UP'!$B$11:$C$447,2,0) -> #N/A | C38: ແຕງ | D38: Nang Miu | E38: CNKT | G38: 40000 | H38: 584606.86 | I38: 584606.86 | J38: =SUM(G38:I38) -> 1209213.7 | M38: =J38-L38 -> 1209213.7
A39: 27 | B39: =VLOOKUP(D39,'[1]DS CN MOI UP'!$B$11:$C$447,2,0) -> 03442 | C39: ແຕງ | D39: Lec | E39: CNKT | H39: 635040.19 | I39: 635040.19 | J39: =SUM(G39:I39) -> 1270080.4 | M39: =J39-L39 -> 1270080.4
A40: 28 | B40: =VLOOKUP(D40,'[1]DS CN MOI UP'!$B$11:$C$447,2,0) -> 03439 | C40: ແຕງ | D40: Khu | E40: CNKT | G40: 40000 | H40: 524139.34 | I40: 524139.34 | J40: =SUM(G40:I40) -> 1088278.7 | M40: =J40-L40 -> 1088278.7
A41: 29 | B41: =VLOOKUP(D41,'[1]DS CN MOI UP'!$B$11:$C$447,2,0) -> #N/A | C41: ແຕງ | D41: Hài | E41: CNKT | G41: 40000 | H41: 554373.1 | I41: 554373.1 | J41: =SUM(G41:I41) -> 1148746.2 | M41: =J41-L41 -> 1148746.2
A42: 30 | B42: =VLOOKUP(D42,'[1]DS CN MOI UP'!$B$11:$C$447,2,0) -> 03443 | C42: ແຕງ | D42: Chun | E42: CNKT | G42: 40000 | H42: 554373.1 | I42: 265581.23 | J42: =SUM(G42:I42) -> 859954.33 | M42: =J42-L42 -> 859954.33
A43: 31 | B43: =VLOOKUP(D43,'[1]DS CN MOI UP'!$B$11:$C$447,2,0) -> #N/A | C43: ແຕງ | D43: Phò Đon | E43: CNKT | G43: 40000 | H43: 614840.62 | I43: 118679 | J43: =SUM(G43:I43) -> 773519.62 | M43: =J43-L43 -> 773519.62
A44: 32 | B44: =VLOOKUP(D44,'[1]DS CN MOI UP'!$B$11:$C$447,2,0) -> 03446 | C44: ແຕງ | D44: Thảo Công | E44: CNKT | G44: 40000 | H44: 554373.1 | I44: 107985.27 | J44: =SUM(G44:I44) -> 702358.37 | M44: =J44-L44 -> 702358.37
A45: 33 | B45: =VLOOKUP(D45,'[1]DS CN MOI UP'!$B$11:$C$447,2,0) -> 03440 | C45: ແຕງ | D45: Xeng | E45: CNKT | G45: 40000 | H45: 554373.1 | I45: 106506.79 | J45: =SUM(G45:I45) -> 700879.89 | M45: =J45-L45 -> 700879.89
A46: 34 | B46: =VLOOKUP(D46,'[1]DS CN MOI UP'!$B$11:$C$447,2,0) -> 03852 | C46: ແຕງ | D46: Na Ly | E46: CNKT | G46: 40000 | H46: 554373.1 | I46: 75304.754 | J46: =SUM(G46:I46) -> 669677.85 | M46: =J46-L46 -> 669677.85
A47: 35 | B47: =VLOOKUP(D47,'[1]DS CN MOI UP'!$B$11:$C$447,2,0) -> #N/A | C47: ແຕງ | D47: Ngui | E47: CNKT | G47: 40000 | H47: 635040.19 | I47: 150609.51 | J47: =SUM(G47:I47) -> 825649.7 | M47: =J47-L47 -> 825649.7
A48: 36 | B48: =VLOOKUP(D48,'[1]DS CN MOI UP'!$B$11:$C$447,2,0) -> #N/A | C48: ແຕງ | D48: Ca Lo | E48: CNKT | G48: 40000 | H48: 544338.9 | I48: 146532.6 | J48: =SUM(G48:I48) -> 730871.5 | M48: =J48-L48 -> 730871.5
...

Sheet CHẤM CÔNG Axit
A1: CÔNG TY TNHH CP QUASA-GERUCO | R1: CỘNG HÒA DÂN CHỦ NHÂN DÂN LÀO
A2: NÔNG TRƯỜNG 1 | R2: Hòa Bình - Độc Lập - Dân Chủ - Thống Nhất - Thịnh Vượng
R3: ----oOo----
A4: BẢNG CHẤM CÔNG THEO DÕI CHẤM CÔNG SỬ DỤNG AXIT ĐÁNH ĐÔNG THÁNG 06 NĂM 2024
A5: (Từ ngày 01 đến 30/06/2024)
A6: Stt | B6: MSNV | C6: Họ và tên | D6: Ngày công | AI6: Tổng số ngày làm việc | AJ6: Ký tên CN
D7: 1 | E7: 2 | F7: 3 | G7: 4 | H7: 5 | I7: 6 | J7: 7 | K7: 8 | L7: 9 | M7: 10 | N7: 11 | O7: 12 | P7: 13 | Q7: 14 | R7: 15 | S7: 16 | T7: 17 | U7: 18 | V7: 19 | W7: 20 | X7: 21 | Y7: 22 | Z7: 23 | AA7: 24 | AB7: 25 | AC7: 26 | AD7: 27 | AE7: 28 | AF7: 29 | AG7: 30 | AH7: 31
C8: Tên Việt
A9: Đội 1 | D9: =COUNTIF(D10:D52,"X")+COUNTIF(D10:D52,"CN") -> 0 | E9: =COUNTIF(E10:E52,"X")+COUNTIF(E10:E52,"CN") -> 0 | F9: =COUNTIF(F10:F52,"X")+COUNTIF(F10:F52,"CN") -> 0 | G9: =COUNTIF(G10:G52,"X")+COUNTIF(G10:G52,"CN") -> 0 | H9: =COUNTIF(H10:H52,"X")+COUNTIF(H10:H52,"CN") -> 0 | I9: =COUNTIF(I10:I52,"X")+COUNTIF(I10:I52,"CN") -> 0 | J9: =COUNTIF(J10:J52,"X")+COUNTIF(J10:J52,"CN") -> 0 | K9: =COUNTIF(K10:K52,"X")+COUNTIF(K10:K52,"CN") -> 0 | ... AH9: =COUNTIF(AH10:AH52,"X")+COUNTIF(AH10:AH52,"CN") -> 0 | AI9: =SUM(AI10:AI52) -> 0
A10: 1 | B10: =VLOOKUP(C10,'DS CN MOI UP'!$B$10:$C$347,2,0) -> #N/A | C10: Thô | AI10: =COUNTIF(D10:AH10,"X") -> 0
A11: 2 | B11: =VLOOKUP(C11,'DS CN MOI UP'!$B$10:$C$347,2,0) -> #N/A | C11: Mè Ta Van | AI11: =COUNTIF(D11:AH11,"X") -> 0
A12: 3 | B12: =VLOOKUP(C12,'DS CN MOI UP'!$B$10:$C$347,2,0) -> #N/A | C12: Ka Tho | AI12: =COUNTIF(D12:AH12,"X") -> 0
A13: 4 | B13: =VLOOKUP(C13,'DS CN MOI UP'!$B$10:$C$347,2,0) -> #N/A | C13: Tô Tộ | AI13: =COUNTIF(D13:AH13,"X") -> 0
A14: 5 | B14: =VLOOKUP(C14,'DS CN MOI UP'!$B$10:$C$347,2,0) -> #N/A | C14: Thảo In | AI14: =COUNTIF(D14:AH14,"X") -> 0
A15: 6 | B15: =VLOOKUP(C15,'DS CN MOI UP'!$B$10:$C$347,2,0) -> #N/A | C15: Cha La | AI15: =COUNTIF(D15:AH15,"X") -> 0
A16: 7 | B16: =VLOOKUP(C16,'DS CN MOI UP'!$B$10:$C$347,2,0) -> #N/A | C16: Nang Nga | AI16: =COUNTIF(D16:AH16,"X") -> 0
A17: 8 | B17: =VLOOKUP(C17,'DS CN MOI UP'!$B$10:$C$347,2,0) -> #N/A | C17: Viêng (1) | AI17: =COUNTIF(D17:AH17,"X") -> 0
A18: 9 | B18: =VLOOKUP(C18,'DS CN MOI UP'!$B$10:$C$347,2,0) -> #N/A | C18: Me Đuông | AI18: =COUNTIF(D18:AH18,"X") -> 0
A19: 10 | B19: =VLOOKUP(C19,'DS CN MOI UP'!$B$10:$C$347,2,0) -> #N/A | C19: Nang Môn | AI19: =COUNTIF(D19:AH19,"X") -> 0
A20: 11 | B20: =VLOOKUP(C20,'DS CN MOI UP'!$B$10:$C$347,2,0) -> #N/A | C20: Ziên | AI20: =COUNTIF(D20:AH20,"X") -> 0
A21: 12 | B21: =VLOOKUP(C21,'DS CN MOI UP'!$B$10:$C$347,2,0) -> #N/A | C21: Me Pê | AI21: =COUNTIF(D21:AH21,"X") -> 0
... A52: 43 | B52: =VLOOKUP(C52,'DS CN MOI UP'!$B$10:$C$347,2,0) -> #N/A | C52: Nang Hỏm | AI52: =COUNTIF(D52:AH52,"X") -> 0
A53: Đội 2 | B53: =VLOOKUP(C53,'DS CN MOI UP'!$B$10:$C$347,2,0) -> #N/A | D53: =COUNTIF(D54:D108,"X")+COUNTIF(D54:D108,"CN") -> 0 | E53: =COUNTIF(E54:E108,"X")+COUNTIF(E54:E108,"CN") -> 0 | F53: =COUNTIF(F54:F108,"X")+COUNTIF(F54:F108,"CN") -> 12 | G53: =COUNTIF(G54:G108,"X")+COUNTIF(G54:G108,"CN") -> 0 | H53: =COUNTIF(H54:H108,"X")+COUNTIF(H54:H108,"CN") -> 15 | I53: =COUNTIF(I54:I108,"X")+COUNTIF(I54:I108,"CN") -> 16 | J53: =COUNTIF(J54:J108,"X")+COUNTIF(J54:J108,"CN") -> 12 | K53: =COUNTIF(K54:K108,"X")+COUNTIF(K54:K108,"CN") -> 21 | ... AH53: =COUNTIF(AH54:AH108,"X")+COUNTIF(AH54:AH108,"CN") -> 0 | AI53: =SUM(AI54:AI108) -> 173
A54: 1 | B54: =VLOOKUP(C54,'DS CN MOI UP'!$B$10:$C$347,2,0) -> #N/A | C54: Lếc | AI54: =COUNTIF(D54:AH54,"X") -> 0
A55: 2 | B55: =VLOOKUP(C55,'DS CN MOI UP'!$B$10:$C$347,2,0) -> #N/A | C55: Hăm Lẹ | R55: X | T55: X | AI55: =COUNTIF(D55:AH55,"X") -> 2
A56: 3 | B56: =VLOOKUP(C56,'DS CN MOI UP'!$B$10:$C$347,2,0) -> #N/A | C56: Vông | F56: X | H56: X | O56: X | T56: X | AI56: =COUNTIF(D56:AH56,"X") -> 4
A57: 4 | B57: =VLOOKUP(C57,'DS CN MOI UP'!$B$10:$C$347,2,0) -> #N/A | C57: Ma Ni Son | H57: X | K57: X | Q57: X | R57: X | AI57: =COUNTIF(D57:AH57,"X") -> 4
A58: 5 | B58: =VLOOKUP(C58,'DS CN MOI UP'!$B$10:$C$347,2,0) -> #N/A | C58: Cong Ma | H58: X | Q58: X | U58: X | AI58: =COUNTIF(D58:AH58,"X") -> 3
A59: 6 | B59: =VLOOKUP(C59,'DS CN MOI UP'!$B$10:$C$347,2,0) -> #N/A | C59: Két | H59: X | K59: X | AI59: =COUNTIF(D59:AH59,"X") -> 2
A60: 7 | B60: =VLOOKUP(C60,'DS CN MOI UP'!$B$10:$C$347,2,0) -> #N/A | C60: Măn | AI60: =COUNTIF(D60:AH60,"X") -> 0
A61: 8 | B61: =VLOOKUP(C61,'DS CN MOI UP'!$B$10:$C$347,2,0) -> #N/A | C61: Soi | I61: X | K61: X | O61: X | AI61: =COUNTIF(D61:AH61,"X") -> 3
A62: 9 | B62: =VLOOKUP(C62,'DS CN MOI UP'!$B$10:$C$347,2,0) -> #N/A | C62: Pò Mòm | F62: X | I62: X | K62: X | O62: X | P62: X | Q62: X | T62: X | U62: X | AI62: =COUNTIF(D62:AH62,"X") -> 8
A63: 10 | B63: =VLOOKUP(C63,'DS CN MOI UP'!$B$10:$C$347,2,0) -> #N/A | C63: Pệt | AI63: =COUNTIF(D63:AH63,"X") -> 0
A64: 11 | B64: =VLOOKUP(C64,'DS CN MOI UP'!$B$10:$C$347,2,0) -> #N/A | C64: Khay Khăm | H64: X | O64: X | AI64: =COUNTIF(D64:AH64,"X") -> 2
A65: 12 | B65: =VLOOKUP(C65,'DS CN MOI UP'!$B$10:$C$347,2,0) -> #N/A | C65: Ô Lích | I65: X | K65: X | P65: X | R65: X | T65: X | U65: X | AI65: =COUNTIF(D65:AH65,"X") -> 6
A66: 13 | B66: =VLOOKUP(C66,'DS CN MOI UP'!$B$10:$C$347,2,0) -> #N/A | C66: Va Khăm | I66: X | K66: X | Q66: X | AI66: =COUNTIF(D66:AH66,"X") -> 3
A67: 14 | B67: =VLOOKUP(C67,'DS CN MOI UP'!$B$10:$C$347,2,0) -> #N/A | C67: Căn Nha | I67: X | R67: X | AI67: =COUNTIF(D67:AH67,"X") -> 2
A68: 15 | B68: =VLOOKUP(C68,'DS CN MOI UP'!$B$10:$C$347,2,0) -> #N/A | C68: Nọi (2) | P68: X | AI68: =COUNTIF(D68:AH68,"X") -> 1
A69: 16 | B69: =VLOOKUP(C69,'DS CN MOI UP'!$B$10:$C$347,2,0) -> #N/A | C69: Lợt | H69: X | K69: X | Q69: X | T69: X | AI69: =COUNTIF(D69:AH69,"X") -> 4
A70: 17 | B70: =VLOOKUP(C70,'DS CN MOI UP'!$B$10:$C$347,2,0) -> #N/A | C70: Ếch | H70: X | K70: X | O70: X | Q70: X | T70: X | AI70: =COUNTIF(D70:AH70,"X") -> 5
...

Sheet MỦ XIRUM
A1: CÔNG TY TNHH CP QUASA-GERUCO LÀO | S1: CỘNG HÒA DÂN CHỦ NHÂN DÂN LÀO
A2: NÔNG TRƯỜNG 1 | S2: Hòa Bình - Độc Lập - Dân Chủ - Thống Nhất - Thịnh Vượng
S3: ----oOo----
A4: BẢNG THEO DÕI SẢN LƯỢNG MỦ TẠP THÁNG 09 NĂM 2024
A5: (Từ ngày 01 đến 31/07/2024) | AK5: DRC | AL5: 0.4986
A6: Stt | B6: Stt | C6: MSNV | D6: Họ và tên | E6: Ngày | AL6: Ký tên
E7: 1 | F7: 2 | G7: 3 | H7: 4 | I7: 5 | J7: 6 | K7: 7 | L7: 8 | M7: 9 | N7: 10 | O7: 11 | P7: 12 | Q7: 13 | R7: 14 | S7: 15 | T7: 16 | U7: 17 | V7: 18 | W7: 19 | X7: 20 | Y7: 21 | Z7: 22 | AA7: 23 | AB7: 24 | AC7: 25 | AD7: 26 | AE7: 27 | AF7: 28 | AG7: 29 | AH7: 30 | AI7: 31 | AJ7: Tổng mủ Xirum | AK7: Quy khô
A8: Lát bốc | E8: B | F8: C | G8: A | H8: B | I8: C | J8: A | K8: B | L8: C | M8: A | N8: B | O8: C | P8: A | Q8: B | R8: C | S8: A | T8: B | U8: C | V8: A | W8: B | X8: C | Y8: A | Z8: B | AA8: C | AB8: A | AC8: B | AD8: C | AE8: A | AF8: B | AG8: C | AH8: A | AI8: B | AM8: DRC | AN8: 0.42315994
A9: Đội 1 | E9: =SUM(E10:E10) -> 0 | F9: =SUM(F10:F10) -> 0 | G9: =SUM(G10:G10) -> 0 | H9: =SUM(H10:H10) -> 0 | I9: =SUM(I10:I10) -> 0 | J9: =SUM(J10:J10) -> 0 | K9: =SUM(K10:K10) -> 0 | L9: =SUM(L10:L10) -> 0 | ... AI9: =SUM(AI10:AI10) -> 0 | AJ9: =AJ10 -> 0 | AK9: =AK10 -> 0
A10: 1 | B10: 1 | C10: Mủ xirum | D10: Mủ xirum 1 | AJ10: =SUM(E10:AI10) -> 0 | AK10: =+AJ10*$AL$5 -> 0 | AM10: =SUM(E10:AI10) -> 0 | AN10: Mủ serum Đội 3 | AO10: 0.17504745
A11: Đội 2 | E11: =SUM(E12:E12) -> 0 | F11: =SUM(F12:F12) -> 0 | G11: =SUM(G12:G12) -> 0 | H11: =SUM(H12:H12) -> 0 | I11: =SUM(I12:I12) -> 0 | J11: =SUM(J12:J12) -> 0 | K11: =SUM(K12:K12) -> 0 | L11: =SUM(L12:L12) -> 0 | ... AI11: =SUM(AI12:AI12) -> 0 | AJ11: =AJ12 -> 290 | AK11: =AK12 -> 144.594 | AN11: Mủ serum Đội 4 | AO11: 0.31672615
A12: 1 | B12: 1 | C12: Mủ xirum | D12: Mủ xirum 2 | AH12: 290 | AJ12: =SUM(E12:AI12) -> 290 | AK12: =+AJ12*$AL$5 -> 144.594 | AM12: =SUM(E12:AI12) -> 290 | AN12: Mủ serum Đội 5 | AO12: 0.4986
A13: Đội 3 | E13: =SUM(E14:E14) -> 0 | F13: =SUM(F14:F14) -> 0 | G13: =SUM(G14:G14) -> 0 | H13: =SUM(H14:H14) -> 0 | I13: =SUM(I14:I14) -> 0 | J13: =SUM(J14:J14) -> 0 | K13: =SUM(K14:K14) -> 0 | L13: =SUM(L14:L14) -> 0 | ... AI13: =SUM(AI14:AI14) -> 0 | AJ13: =AJ14 -> 0 | AK13: =AK14 -> 0
A14: 2 | B14: 1 | C14: Phong | D14: Mủ xirum 3 | AJ14: =SUM(E14:AI14) -> 0 | AK14: =+AJ14*$AO$10 -> 0
A15: Đội 4 | E15: =SUM(E16:E16) -> 0 | F15: =SUM(F16:F16) -> 0 | G15: =SUM(G16:G16) -> 0 | H15: =SUM(H16:H16) -> 0 | I15: =SUM(I16:I16) -> 0 | J15: =SUM(J16:J16) -> 0 | K15: =SUM(K16:K16) -> 0 | L15: =SUM(L16:L16) -> 0 | ... AI15: =SUM(AI16:AI16) -> 0 | AJ15: =AJ16 -> 0 | AK15: =AK16 -> 0 | AM15: =SUM(AK9,AK11,AK13,AK15) -> 144.594
A16: 2 | B16: 1 | C16: Phong | D16: Mủ xirum 4 | AJ16: =SUM(E16:AI16) -> 0 | AK16: =+AJ16*$AO$11 -> 0
A17: Đội 5 | E17: =SUM(E18:E18) -> 0 | F17: =SUM(F18:F18) -> 0 | G17: =SUM(G18:G18) -> 0 | H17: =SUM(H18:H18) -> 0 | I17: =SUM(I18:I18) -> 0 | J17: =SUM(J18:J18) -> 0 | K17: =SUM(K18:K18) -> 0 | L17: =SUM(L18:L18) -> 0 | ... AI17: =SUM(AI18:AI18) -> 0 | AJ17: =SUM(E17:AI17) -> 0 | AK17: =SUM(AK18:AK18) -> 0
A18: 3 | B18: 1 | C18: Nàng Mon | D18: Mủ xirum 5 | AJ18: =SUM(E18:AI18) -> 0 | AK18: =+AJ18*$AO$12 -> 0
A19: Tổng | E19: =E11+E13+E15 -> 0 | F19: =F11+F13+F15 -> 0 | G19: =G11+G13+G15 -> 0 | H19: =H11+H13+H15 -> 0 | I19: =I11+I13+I15 -> 0 | J19: =J11+J13+J15 -> 0 | K19: =K11+K13+K15 -> 0 | L19: =L11+L13+L15 -> 0 | ... AI19: =AI11+AI13+AI15 -> 0 | AJ19: =AJ11+AJ13+AJ15+AJ9+AJ18 -> 290 | AK19: =AK11+AK13+AK15+AK9+AK18 -> 144.594 | AM19: =+AK19+'sản lượng'!AL170 -> 221555.43
A22: TỔNG GIÁM ĐỐC | J22: PHÒNG KT - NN | Q22: GĐ. NÔNG TRƯỜNG | Z22: TL. TC - KT | AG22: TL. KH - NN | AJ22: NGƯỜI LẬP BIỂU

Sheet MỦ DÂY
A1: CÔNG TY TNHH CP QUASA-GERUCO LÀO | S1: CỘNG HÒA DÂN CHỦ NHÂN DÂN LÀO
A2: NÔNG TRƯỜNG 1 | S2: Hòa Bình - Độc Lập - Dân Chủ - Thống Nhất - Thịnh Vượng
S3: ----oOo----
A4: BẢNG THEO DÕI SẢN LƯỢNG MỦ TẠP THÁNG 07 NĂM 2024
A5: (Từ ngày 01 đến 31/07/2024)
A6: Stt | B6: Stt | C6: MSNV | D6: Họ và tên | E6: Ngày | AJ6: Tổng mủ dây | AK6: Quy khô | AL6: Ký tên | AM6: DRC | AN6: 0.5
E7: 1 | F7: 2 | G7: 3 | H7: 4 | I7: 5 | J7: 6 | K7: 7 | L7: 8 | M7: 9 | N7: 10 | O7: 11 | P7: 12 | Q7: 13 | R7: 14 | S7: 15 | T7: 16 | U7: 17 | V7: 18 | W7: 19 | X7: 20 | Y7: 21 | Z7: 22 | AA7: 23 | AB7: 24 | AC7: 25 | AD7: 26 | AE7: 27 | AF7: 28 | AG7: 29 | AH7: 30 | AI7: 31
A8: Lát bốc | E8: B | F8: C | G8: A | H8: B | I8: C | J8: A | K8: B | L8: C | M8: A | N8: B | O8: C | P8: A | Q8: B | R8: C | S8: A | T8: B | U8: C | V8: A | W8: B | X8: C | Y8: A | Z8: B | AA8: C | AB8: A | AC8: B | AD8: C | AE8: A | AF8: B | AG8: C | AH8: A | AI8: B
A9: Đội 1 | E9: =SUM(E10:E52) -> 0 | F9: =SUM(F10:F52) -> 0 | G9: =SUM(G10:G52) -> 0 | H9: =SUM(H10:H52) -> 0 | I9: =SUM(I10:I52) -> 0 | J9: =SUM(J10:J52) -> 0 | K9: =SUM(K10:K52) -> 0 | L9: =SUM(L10:L52) -> 0 | ... AK9: =SUM(AK10:AK52) -> 0
A10: 1 | B10: 1 | C10: =VLOOKUP(D10,'DS CN MOI UP'!$B$10:$C$347,2,0) -> #N/A | D10: Thô | AJ10: =SUM(E10:AI10) -> 0 | AK10: =AJ10*$AN$6 -> 0
A11: 2 | B11: 2 | C11: =VLOOKUP(D11,'DS CN MOI UP'!$B$10:$C$347,2,0) -> #N/A | D11: Mè Ta Van | AJ11: =SUM(E11:AI11) -> 0 | AK11: =AJ11*$AN$6 -> 0
A12: 3 | B12: 3 | C12: =VLOOKUP(D12,'DS CN MOI UP'!$B$10:$C$347,2,0) -> #N/A | D12: Ka Tho | AJ12: =SUM(E12:AI12) -> 0 | AK12: =AJ12*$AN$6 -> 0
A13: 4 | B13: 4 | C13: =VLOOKUP(D13,'DS CN MOI UP'!$B$10:$C$347,2,0) -> #N/A | D13: Tô Tộ | AJ13: =SUM(E13:AI13) -> 0 | AK13: =AJ13*$AN$6 -> 0
A14: 5 | B14: 5 | C14: =VLOOKUP(D14,'DS CN MOI UP'!$B$10:$C$347,2,0) -> #N/A | D14: Thảo In | AJ14: =SUM(E14:AI14) -> 0 | AK14: =AJ14*$AN$6 -> 0
A15: 6 | B15: 6 | C15: =VLOOKUP(D15,'DS CN MOI UP'!$B$10:$C$347,2,0) -> #N/A | D15: Cha La | AJ15: =SUM(E15:AI15) -> 0 | AK15: =AJ15*$AN$6 -> 0
A16: 7 | B16: 7 | C16: =VLOOKUP(D16,'DS CN MOI UP'!$B$10:$C$347,2,0) -> #N/A | D16: Nang Nga | AJ16: =SUM(E16:AI16) -> 0 | AK16: =AJ16*$AN$6 -> 0
A17: 8 | B17: 8 | C17: =VLOOKUP(D17,'DS CN MOI UP'!$B$10:$C$347,2,0) -> #N/A | D17: Viêng (1) | AJ17: =SUM(E17:AI17) -> 0 | AK17: =AJ17*$AN$6 -> 0
A18: 9 | B18: 9 | C18: =VLOOKUP(D18,'DS CN MOI UP'!$B$10:$C$347,2,0) -> #N/A | D18: Me Đuông | AJ18: =SUM(E18:AI18) -> 0 | AK18: =AJ18*$AN$6 -> 0
A19: 10 | B19: 10 | C19: =VLOOKUP(D19,'DS CN MOI UP'!$B$10:$C$347,2,0) -> #N/A | D19: Nang Môn | AJ19: =SUM(E19:AI19) -> 0 | AK19: =AJ19*$AN$6 -> 0
A20: 11 | B20: 11 | C20: =VLOOKUP(D20,'DS CN MOI UP'!$B$10:$C$347,2,0) -> #N/A | D20: Ziên | AJ20: =SUM(E20:AI20) -> 0 | AK20: =AJ20*$AN$6 -> 0
A21: 12 | B21: 12 | C21: =VLOOKUP(D21,'DS CN MOI UP'!$B$10:$C$347,2,0) -> #N/A | D21: Me Pê | AJ21: =SUM(E21:AI21) -> 0 | AK21: =AJ21*$AN$6 -> 0
... A52: 43 | B52: 43 | C52: =VLOOKUP(D52,'DS CN MOI UP'!$B$10:$C$347,2,0) -> #N/A | D52: Nang Hỏm | AJ52: =SUM(E52:AI52) -> 0 | AK52: =AJ52*$AN$6 -> 0
A53: Đội 2 | C53: =VLOOKUP(D53,'DS CN MOI UP'!$B$10:$C$347,2,0) -> #N/A | AJ53: =SUM(AJ54:AJ109) -> 0 | AK53: =SUM(AK54:AK109) -> 0
A54: 44 | B54: 1 | C54: =VLOOKUP(D54,'DS CN MOI UP'!$B$10:$C$347,2,0) -> #N/A | D54: Lếc | AJ54: =SUM(E54:AI54) -> 0 | AK54: =AJ54*$AN$6 -> 0 | AM54: =SUM(E54:AI54) -> 0 | AN54: =+#REF!-AM54 -> #REF!
A55: 45 | B55: 2 | C55: =VLOOKUP(D55,'DS CN MOI UP'!$B$10:$C$347,2,0) -> #N/A | D55: Hăm Lẹ | AJ55: =SUM(E55:AI55) -> 0 | AK55: =AJ55*$AN$6 -> 0 | AM55: =SUM(E55:AI55) -> 0 | AN55: =+#REF!-AM55 -> #REF!
A56: 46 | B56: 3 | C56: =VLOOKUP(D56,'DS CN MOI UP'!$B$10:$C$347,2,0) -> #N/A | D56: Vông | AJ56: =SUM(E56:AI56) -> 0 | AK56: =AJ56*$AN$6 -> 0 | AM56: =SUM(E56:AI56) -> 0 | AN56: =+#REF!-AM56 -> #REF!
A57: 47 | B57: 4 | C57: =VLOOKUP(D57,'DS CN MOI UP'!$B$10:$C$347,2,0) -> #N/A | D57: Ma Ni Son | AJ57: =SUM(E57:AI57) -> 0 | AK57: =AJ57*$AN$6 -> 0 | AM57: =SUM(E57:AI57) -> 0 | AN57: =+#REF!-AM57 -> #REF!
A58: 48 | B58: 5 | C58: =VLOOKUP(D58,'DS CN MOI UP'!$B$10:$C$347,2,0) -> #N/A | D58: Cong Ma | AJ58: =SUM(E58:AI58) -> 0 | AK58: =AJ58*$AN$6 -> 0 | AM58: =SUM(E58:AI58) -> 0 | AN58: =+#REF!-AM58 -> #REF!
A59: 49 | B59: 6 | C59: =VLOOKUP(D59,'DS CN MOI UP'!$B$10:$C$347,2,0) -> #N/A | D59: Két | AJ59: =SUM(E59:AI59) -> 0 | AK59: =AJ59*$AN$6 -> 0 | AM59: =SUM(E59:AI59) -> 0 | AN59: =+#REF!-AM59 -> #REF!
A60: 50 | B60: 7 | C60: =VLOOKUP(D60,'DS CN MOI UP'!$B$10:$C$347,2,0) -> #N/A | D60: Măn | AJ60: =SUM(E60:AI60) -> 0 | AK60: =AJ60*$AN$6 -> 0 | AM60: =SUM(E60:AI60) -> 0 | AN60: =+#REF!-AM60 -> #REF!
A61: 51 | B61: 8 | C61: =VLOOKUP(D61,'DS CN MOI UP'!$B$10:$C$347,2,0) -> #N/A | D61: Soi | AJ61: =SUM(E61:AI61) -> 0 | AK61: =AJ61*$AN$6 -> 0 | AM61: =SUM(E61:AI61) -> 0 | AN61: =+#REF!-AM61 -> #REF!
A62: 52 | B62: 9 | C62: =VLOOKUP(D62,'DS CN MOI UP'!$B$10:$C$347,2,0) -> #N/A | D62: Pò Mòm | AJ62: =SUM(E62:AI62) -> 0 | AK62: =AJ62*$AN$6 -> 0 | AM62: =SUM(E62:AI62) -> 0 | AN62: =+#REF!-AM62 -> #REF!
A63: 53 | B63: 10 | C63: =VLOOKUP(D63,'DS CN MOI UP'!$B$10:$C$347,2,0) -> #N/A | D63: Pệt | AJ63: =SUM(E63:AI63) -> 0 | AK63: =AJ63*$AN$6 -> 0 | AM63: =SUM(E63:AI63) -> 0 | AN63: =+#REF!-AM63 -> #REF!
A64: 54 | B64: 11 | C64: =VLOOKUP(D64,'DS CN MOI UP'!$B$10:$C$347,2,0) -> #N/A | D64: Khay Khăm | AJ64: =SUM(E64:AI64) -> 0 | AK64: =AJ64*$AN$6 -> 0 | AM64: =SUM(E64:AI64) -> 0 | AN64: =+#REF!-AM64 -> #REF!
A65: 55 | B65: 12 | C65: =VLOOKUP(D65,'DS CN MOI UP'!$B$10:$C$347,2,0) -> #N/A | D65: Ô Lích | AJ65: =SUM(E65:AI65) -> 0 | AK65: =AJ65*$AN$6 -> 0 | AM65: =SUM(E65:AI65) -> 0 | AN65: =+#REF!-AM65 -> #REF!
... A109: 99 | B109: 55 | C109: =VLOOKUP(D109,'DS CN MOI UP'!$B$10:$C$347,2,0) -> #N/A | D109: Mủ xirum | AJ109: =SUM(E109:AI109) -> 0 | AK109: =AJ109*$AN$6 -> 0 | AM109: =SUM(E109:AI109) -> 0 | AN109: =+#REF!-AM109 -> #REF!
A110: Đội 3 | C110: =VLOOKUP(D110,'DS CN MOI UP'!$B$10:$C$347,2,0) -> #N/A | AJ110: =SUM(AJ111:AJ204) -> 0 | AK110: =SUM(AK111:AK204) -> 0
A111: 100 | B111: 1 | C111: =VLOOKUP(D111,'DS CN MOI UP'!$B$10:$C$347,2,0) -> 03319 | D111: Bôn | AJ111: =SUM(E111:AI111) -> 0 | AK111: =AJ111*$AN$6 -> 0
A112: 101 | B112: 2 | C112: =VLOOKUP(D112,'DS CN MOI UP'!$B$10:$C$347,2,0) -> 03320 | D112: E | AJ112: =SUM(E112:AI112) -> 0 | AK112: =AJ112*$AN$6 -> 0
A113: 102 | B113: 3 | C113: =VLOOKUP(D113,'DS CN MOI UP'!$B$10:$C$347,2,0) -> 02453 | D113: Khương (3) | AJ113: =SUM(E113:AI113) -> 0 | AK113: =AJ113*$AN$6 -> 0
...

Sheet DS CN MOI UP
A1: CÔNG TY TNHH CP QUASA-GERUCO LÀO | D1: CỘNG HÒA DÂN CHỦ NHÂN DÂN LÀO
A2: NÔNG TRƯỜNG 1 | D2: Hòa bình - Độc lập - Dân chủ - Thống nhất - Thịnh vượng
A4: DANH SÁCH CÔNG NHÂN KHAI THÁC + BẢO VỆ
A7: Stt | B7: Họ và tên | C7: MSNV | D7: Giới tính | E7: Ngày tháng năm sinh | F7: Nơi ở | G7: Ghi chú
A8: A | B8: CÔNG NHÂN KHAI THÁC
A10: Đội 3
A11: 1 | B11: Bôn | C11: 03319 | D11: Nam | F11: Non Say
A12: 2 | B12: E | C12: 03320 | D12: Nam | F12: Non Say
A13: 3 | B13: Khương (3) | C13: 02453 | D13: Nam | F13: Non Say
A14: 4 | B14: Nít Ni Lanh | C14: 02471 | D14: Nam | F14: Non Say
A15: 5 | B15: Khăm Đeng | C15: 02465 | D15: Nam | F15: Non Say
A16: 6 | B16: Nàng Năt | C16: 03321 | D16: Nữ | F16: Non Say
A17: 7 | B17: Xay (3) | C17: 03322 | D17: Nam | F17: Non Say
A18: 8 | B18: Xôn | C18: 02452 | D18: Nam | F18: Non Say
A19: 9 | B19: Phum Hom | C19: 02508 | D19: Nam | F19: Non Say
A20: 10 | B20: Pa Lay | C20: 03323 | D20: Nam | F20: Non Say
A21: 11 | B21: Măm | C21: 02466 | D21: Nam | F21: Non Say
A22: 12 | B22: Muôi | C22: 02493 | D22: Nữ | F22: Non Say
... A103: 93 | B103: Chinh | C103: 02480 | D103: Nữ | F103: Non Say
A104: XC
A105: 1 | B105: Pho Thông | C105: 03346 | D105: Nam | E105: 26696 | F105: Non Say
A106: 2 | B106: Ka Púc | C106: 02472 | D106: Nam | E106: 32579 | F106: Non Say
A107: 3 | B107: Chay Đi | C107: 02477 | D107: Nữ | E107: 34889 | F107: Non Say
A108: 4 | B108: Lăng B | C108: 02495 | D108: Nam | E108: 25486 | F108: Non Say
A109: 5 | B109: Vi Say | C109: 02505 | D109: Nam | E109: 26183 | F109: Non Say
A110: 6 | B110: On | C110: 02516 | D110: Nữ | E110: 35013 | F110: Non Say
A111: 7 | B111: Tuc | C111: 03347 | D111: Nữ | E111: 26671 | F111: Non Say
A112: TC
A113: 1 | B113: Thon | C113: 03343 | D113: Nam | E113: 38400 | F113: Non Say
A114: 2 | B114: Nhon | C114: 02444 | D114: Nữ | E114: 29503 | F114: Non Say
A115: 3 | B115: Hăm (3) | C115: 02447 | D115: Nam | E115: 32960 | F115: Xay Xăm Bun
A116: 4 | B116: Nang (3) | C116: 03344 | D116: Nữ | E116: 36203 | F116: Xay Xăm Bun
A117: 5 | B117: Khăm | C117: 02449 | D117: Nam | E117: 28619 | F117: Non Say
A118: 6 | B118: Nàng Bát | C118: 02445 | D118: Nữ | E118: 29405 | F118: Non Say
A119: 7 | B119: Dộc | C119: 02446 | D119: Nam | E119: 29803 | F119: Non Say
A120: 8 | B120: Chăn (3) | C120: 03345 | D120: Nam | E120: 32762 | F120: Xi Bun Hương
A121: 9 | B121: Hát | C121: 03854 | D121: Nam | E121: =2024-1982 -> 42 | F121: Xay Xăm Bun | G121: Chưa có HĐ
A122: 10 | B122: Bun (3) | C122: 03855 | D122: Nam | E122: =2024-1975 -> 49 | F122: Bản Cang | G122: Chưa có HĐ
A123: 11 | B123: My | C123: 03856 | D123: Nữ | E123: =2024-1986 -> 38 | F123: Xay Xăm Bun | G123: Chưa có HĐ
A124: Đội 4
...

Sheet CÔNG CHĂM SÓC
A2: BẢNG TỔNG HỢP CÁC CÔNG CHĂM SÓC
A4: STT | B4: Tên CN | C4: Tên công việc | L4: Tổng
C5: Bôi thuốc kích thích | D5: Bấm mái chắn mưa ngữa | E5: Bấm mái chắn mưa úp | F5: Gắn màng phủ chén | G5: Bấm mái HO4 | H5: Gia cố | N5: Bấm mái chắn mưa | O5: Bấm mái chắn mưa HO4 | P5: Bấm màng phủ chén | Q5: Bôi thuốc kích thích
C6: 1.25 | D6: 0.14285714 | E6: 0.125 | F6: 0.16666667 | G6: 0.083333333 | H6: 0.5
A7: Trạm 1 | C7: =SUM(C8:C113) -> 249.6 | D7: =SUM(D8:D113) -> 0 | E7: =SUM(E8:E113) -> 1904 | F7: =SUM(F8:F113) -> 1872 | G7: =SUM(G8:G113) -> 888 | H7: =SUM(H8:H113) -> 0 | I7: =SUM(I8:I113) -> 0 | J7: =SUM(J8:J113) -> 0 | ... L7: =SUM(L8:L113) -> 4913.6
A8: 1 | B8: Thá | C8: =Q8/$C$6 -> 2.4 | E8: =N8/$E$6 -> 16 | F8: =P8/$F$6 -> 18 | G8: =O8/$G$6 -> 12 | L8: =SUM(C8:K8) -> 48.4 | N8: 2 | O8: 1 | P8: 3 | Q8: 3
A9: 2 | B9: Đăm (3) | C9: =Q9/$C$6 -> 2.4 | E9: =N9/$E$6 -> 8 | F9: =P9/$F$6 -> 18 | G9: =O9/$G$6 -> 24 | L9: =SUM(C9:K9) -> 52.4 | N9: 1 | O9: 2 | P9: 3 | Q9: 3
A10: 3 | B10: Chọt | C10: =Q10/$C$6 -> 2.4 | E10: =N10/$E$6 -> 8 | F10: =P10/$F$6 -> 18 | G10: =O10/$G$6 -> 24 | L10: =SUM(C10:K10) -> 52.4 | N10: 1 | O10: 2 | P10: 3 | Q10: 3
A11: 4 | B11: Vat Sa Na | C11: =Q11/$C$6 -> 2.4 | E11: =N11/$E$6 -> 8 | F11: =P11/$F$6 -> 18 | G11: =O11/$G$6 -> 24 | L11: =SUM(C11:K11) -> 52.4 | N11: 1 | O11: 2 | P11: 3 | Q11: 3
A12: 5 | B12: Xi La | C12: =Q12/$C$6 -> 2.4 | E12: =N12/$E$6 -> 8 | F12: =P12/$F$6 -> 18 | G12: =O12/$G$6 -> 24 | L12: =SUM(C12:K12) -> 52.4 | N12: 1 | O12: 2 | P12: 3 | Q12: 3
A13: 6 | B13: Nàng Lên | C13: =Q13/$C$6 -> 2.4 | E13: =N13/$E$6 -> 8 | F13: =P13/$F$6 -> 18 | G13: =O13/$G$6 -> 24 | L13: =SUM(C13:K13) -> 52.4 | N13: 1 | O13: 2 | P13: 3 | Q13: 3
A14: 7 | B14: Kum Man | C14: =Q14/$C$6 -> 2.4 | E14: =N14/$E$6 -> 8 | F14: =P14/$F$6 -> 18 | G14: =O14/$G$6 -> 24 | L14: =SUM(C14:K14) -> 52.4 | N14: 1 | O14: 2 | P14: 3 | Q14: 3
A15: 8 | B15: Xai Ta | C15: =Q15/$C$6 -> 2.4 | E15: =N15/$E$6 -> 8 | F15: =P15/$F$6 -> 18 | G15: =O15/$G$6 -> 24 | L15: =SUM(C15:K15) -> 52.4 | N15: 1 | O15: 2 | P15: 3 | Q15: 3
A16: 9 | B16: Ót | C16: =Q16/$C$6 -> 2.4 | E16: =N16/$E$6 -> 8 | F16: =P16/$F$6 -> 18 | G16: =O16/$G$6 -> 24 | L16: =SUM(C16:K16) -> 52.4 | N16: 1 | O16: 2 | P16: 3 | Q16: 3
A17: 10 | B17: Thảo Tom | C17: =Q17/$C$6 -> 2.4 | E17: =N17/$E$6 -> 8 | F17: =P17/$F$6 -> 18 | G17: =O17/$G$6 -> 24 | L17: =SUM(C17:K17) -> 52.4 | N17: 1 | O17: 2 | P17: 3 | Q17: 3
A18: 11 | B18: Me Nhon | C18: =Q18/$C$6 -> 2.4 | E18: =N18/$E$6 -> 8 | F18: =P18/$F$6 -> 18 | G18: =O18/$G$6 -> 24 | L18: =SUM(C18:K18) -> 52.4 | N18: 1 | O18: 2 | P18: 3 | Q18: 3
A19: 12 | B19: Son | C19: =Q19/$C$6 -> 2.4 | E19: =N19/$E$6 -> 8 | F19: =P19/$F$6 -> 18 | G19: =O19/$G$6 -> 24 | L19: =SUM(C19:K19) -> 52.4 | N19: 1 | O19: 2 | P19: 3 | Q19: 3
... A44: 37 | B44: Nang Ny | C44: =Q44/$C$6 -> 2.4 | E44: =N44/$E$6 -> 8 | F44: =P44/$F$6 -> 18 | G44: =O44/$G$6 -> 24 | L44: =SUM(C44:K44) -> 52.4 | N44: 1 | O44: 2 | P44: 3 | Q44: 3
A45: 38 | B45: Thảo Lúi | C45: =Q45/$C$6 -> 2.4 | E45: =N45/$E$6 -> 24 | F45: =P45/$F$6 -> 18 | G45: =O45/$G$6 -> 0 | L45: =SUM(C45:K45) -> 44.4 | N45: 3 | P45: 3 | Q45: 3
A46: 39 | B46: Lên | C46: =Q46/$C$6 -> 2.4 | E46: =N46/$E$6 -> 24 | F46: =P46/$F$6 -> 18 | G46: =O46/$G$6 -> 0 | L46: =SUM(C46:K46) -> 44.4 | N46: 3 | P46: 3 | Q46: 3
A47: 40 | B47: Ô | C47: =Q47/$C$6 -> 2.4 | E47: =N47/$E$6 -> 24 | F47: =P47/$F$6 -> 18 | G47: =O47/$G$6 -> 0 | L47: =SUM(C47:K47) -> 44.4 | N47: 3 | P47: 3 | Q47: 3
A48: 41 | B48: Văn Thong | C48: =Q48/$C$6 -> 2.4 | E48: =N48/$E$6 -> 24 | F48: =P48/$F$6 -> 18 | G48: =O48/$G$6 -> 0 | L48: =SUM(C48:K48) -> 44.4 | N48: 3 | P48: 3 | Q48: 3
A49: 42 | B49: Khôn (3) | C49: =Q49/$C$6 -> 2.4 | E49: =N49/$E$6 -> 24 | F49: =P49/$F$6 -> 18 | G49: =O49/$G$6 -> 0 | L49: =SUM(C49:K49) -> 44.4 | N49: 3 | P49: 3 | Q49: 3
A50: 43 | B50: Me Son | C50: =Q50/$C$6 -> 2.4 | E50: =N50/$E$6 -> 24 | F50: =P50/$F$6 -> 18 | G50: =O50/$G$6 -> 0 | L50: =SUM(C50:K50) -> 44.4 | N50: 3 | P50: 3 | Q50: 3
A51: 44 | B51: Me Ly | C51: =Q51/$C$6 -> 2.4 | E51: =N51/$E$6 -> 24 | F51: =P51/$F$6 -> 18 | G51: =O51/$G$6 -> 0 | L51: =SUM(C51:K51) -> 44.4 | N51: 3 | P51: 3 | Q51: 3
A52: 45 | B52: Nít Ni Lanh | C52: =Q52/$C$6 -> 2.4 | E52: =N52/$E$6 -> 24 | F52: =P52/$F$6 -> 18 | G52: =O52/$G$6 -> 0 | L52: =SUM(C52:K52) -> 44.4 | N52: 3 | P52: 3 | Q52: 3
A53: 46 | B53: Lăng A | C53: =Q53/$C$6 -> 2.4 | E53: =N53/$E$6 -> 24 | F53: =P53/$F$6 -> 18 | G53: =O53/$G$6 -> 0 | L53: =SUM(C53:K53) -> 44.4 | N53: 3 | P53: 3 | Q53: 3
A54: 47 | B54: Phơn | C54: =Q54/$C$6 -> 2.4 | E54: =N54/$E$6 -> 24 | F54: =P54/$F$6 -> 18 | G54: =O54/$G$6 -> 0 | L54: =SUM(C54:K54) -> 44.4 | N54: 3 | P54: 3 | Q54: 3
A55: 48 | B55: Chít | C55: =Q55/$C$6 -> 2.4 | E55: =N55/$E$6 -> 24 | F55: =P55/$F$6 -> 18 | G55: =O55/$G$6 -> 0 | L55: =SUM(C55:K55) -> 44.4 | N55: 3 | P55: 3 | Q55: 3
A56: 49 | B56: Chec | C56: =Q56/$C$6 -> 2.4 | E56: =N56/$E$6 -> 24 | F56: =P56/$F$6 -> 18 | G56: =O56/$G$6 -> 0 | L56: =SUM(C56:K56) -> 44.4 | N56: 3 | P56: 3 | Q56: 3
... A61: 54 | B61: Ðuông Chăn | C61: =Q61/$C$6 -> 2.4 | E61: =N61/$E$6 -> 24 | F61: =P61/$F$6 -> 18 | G61: =O61/$G$6 -> 0 | L61: =SUM(C61:K61) -> 44.4 | N61: 3 | P61: 3 | Q61: 3
A62: 55 | B62: Xing | C62: =Q62/$C$6 -> 2.4 | E62: =N62/$E$6 -> 16 | F62: =P62/$F$6 -> 18 | G62: =O62/$G$6 -> 12 | L62: =SUM(C62:K62) -> 48.4 | N62: 2 | O62: 1 | P62: 3 | Q62: 3
A63: 56 | B63: Xi No | C63: =Q63/$C$6 -> 2.4 | E63: =N63/$E$6 -> 24 | F63: =P63/$F$6 -> 18 | G63: =O63/$G$6 -> 0 | L63: =SUM(C63:K63) -> 44.4 | N63: 3 | P63: 3 | Q63: 3
A64: 57 | B64: Lói | C64: =Q64/$C$6 -> 2.4 | E64: =N64/$E$6 -> 24 | F64: =P64/$F$6 -> 18 | G64: =O64/$G$6 -> 0 | L64: =SUM(C64:K64) -> 44.4 | N64: 3 | P64: 3 | Q64: 3
A65: 58 | B65: Nọi (3) | C65: =Q65/$C$6 -> 2.4 | E65: =N65/$E$6 -> 24 | F65: =P65/$F$6 -> 18 | G65: =O65/$G$6 -> 0 | L65: =SUM(C65:K65) -> 44.4 | N65: 3 | P65: 3 | Q65: 3
A66: 59 | B66: Thảo Ký | C66: =Q66/$C$6 -> 2.4 | E66: =N66/$E$6 -> 24 | F66: =P66/$F$6 -> 18 | G66: =O66/$G$6 -> 0 | L66: =SUM(C66:K66) -> 44.4 | N66: 3 | P66: 3 | Q66: 3
A67: 60 | B67: Nam phon | C67: =Q67/$C$6 -> 2.4 | E67: =N67/$E$6 -> 24 | F67: =P67/$F$6 -> 18 | G67: =O67/$G$6 -> 0 | L67: =SUM(C67:K67) -> 44.4 | N67: 3 | P67: 3 | Q67: 3
A68: 61 | B68: Nang Ta | C68: =Q68/$C$6 -> 2.4 | E68: =N68/$E$6 -> 24 | F68: =P68/$F$6 -> 18 | G68: =O68/$G$6 -> 0 | L68: =SUM(C68:K68) -> 44.4 | N68: 3 | P68: 3 | Q68: 3
A69: 62 | B69: Pa Lay | C69: =Q69/$C$6 -> 2.4 | E69: =N69/$E$6 -> 24 | F69: =P69/$F$6 -> 18 | G69: =O69/$G$6 -> 0 | L69: =SUM(C69:K69) -> 44.4 | N69: 3 | P69: 3 | Q69: 3
A70: 63 | B70: Lăm phon (3) | C70: =Q70/$C$6 -> 2.4 | E70: =N70/$E$6 -> 24 | F70: =P70/$F$6 -> 18 | G70: =O70/$G$6 -> 0 | L70: =SUM(C70:K70) -> 44.4 | N70: 3 | P70: 3 | Q70: 3
...

Sheet sản lượng
A1: CỘNG HÒA DÂN CHỦ NHÂN DÂN LÀO
A2: Hòa Bình - Độc Lập - Dân Chủ - Thống Nhất - Thịnh Vượng
A3: ----oOo----
A4: CÔNG TY TNHH MTV QUASA-GERUCO LÀO
A5: ĐỘI SẢN XUẤT SỐ 05
A7: BẢNG TỔNG HỢP SẢN LƯỢNG MỦ TẠP THÁNG 06 NĂM 2025
A8: (Từ ngày 01 đến 31/12/2025)
A9: Stt | C9: MSNV | D9: Họ và tên | E9: Ký tên | F9: Ngày | AK9: Tổng mủ tạp | AL9: Mủ tạp quy khô T12 | AM9: Tổng mủ tạp | AN9: Mủ tạp quy khô truy lĩnh T1,4,5,7,9 | AO9: Tổng trả lương | AP9: Xếp hạng kỹ thuật | AQ9: Ghi chú | AS9: T12 | AT9: TRUY THU
F10: 1 | G10: 2 | H10: 3 | I10: 4 | J10: 5 | K10: 6 | L10: 7 | M10: 8 | N10: 9 | O10: 10 | P10: 11 | Q10: 12 | R10: 13 | S10: 14 | T10: 15 | U10: 16 | V10: 17 | W10: 18 | X10: 19 | Y10: 20 | Z10: 21 | AA10: 22 | AB10: 23 | AC10: 24 | AD10: 25 | AE10: 26 | AF10: 27 | AG10: 28 | AH10: 29 | AI10: 30 | AJ10: 31 | AR10: DRC trạm 1 | AS10: 0.4250277 | AT10: 0.054801866
A11: Lát bốc | F11: A | G11: B | H11: C | I11: A | J11: B | K11: C | L11: A | M11: B | N11: C | O11: A | P11: B | Q11: C | R11: A | S11: B | T11: C | U11: A | V11: B | W11: C | X11: A | Y11: B | Z11: C | AA11: A | AB11: B | AC11: C | AD11: A | AE11: B | AF11: C | AG11: A | AH11: B | AI11: C | AJ11: A | AR11: DRC trạm 2 | AS11: 0.43569027 | AT11: 0.040575403
A12: Trạm 1 | F12: =SUM(F14:F97) -> 8361 | G12: =SUM(G14:G97) -> 12810 | H12: =SUM(H14:H97) -> 11535 | I12: =SUM(I14:I97) -> 9842 | J12: =SUM(J14:J97) -> 7910 | K12: =SUM(K14:K97) -> 11372 | L12: =SUM(L14:L97) -> 11376 | M12: =SUM(M14:M97) -> 11150 | ... AO12: =SUM(AO14:AO97) -> 161656.02 | AQ12: =SUM(AQ14:AQ97) -> 134761.2 | AR12: =SUM(AR14:AR97) -> 8431.9075
G13: =IF('sản lượng'!$Q$192:$S$192,8,IF('sản lượng'!$Q$191:$S$191>10,8,IF(E>5,9,IF(E14,10,IF(E12<50,11,12)))))/10 -> #VALUE!
A14: 1 | B14: 1 | C14: 04086 | D14: =TONGHOPCONGDOI!C11 -> T. Lê | F14: 160 | G14: 188 | H14: 152 | I14: 138 | J14: 77 | K14: 0 | L14: 159 | M14: 177 | N14: 100 | O14: 244 | P14: 174 | Q14: 221 | R14: 122 | S14: 179 | T14: 213 | U14: 201 | V14: 0 | W14: 211 | X14: 150 | Y14: 208 | Z14: 173 | AA14: 182 | AB14: 176 | AC14: 175 | AD14: 97 | AE14: 165 | AF14: 140 | AG14: 166 | AH14: 97 | AI14: 153 | AJ14: 118 | AK14: =SUM(F14:AJ14) -> 4716 | AL14: =AK14*$AS$10 -> 2004.4306 | AM14: =AK14 -> 4716 | AN14: =AM14*$AT$10 -> 258.4456 | AO14: =AL14+AN14 -> 2262.8762 | AP14: B | AQ14: =+AK14*40% -> 1886.4 | AR14: =+AL14-AQ14 -> 118.03064
A15: 2 | B15: 2 | C15: 02735 | D15: =TONGHOPCONGDOI!C12 -> Nang On Teng | F15: 0 | G15: 159 | H15: 191 | I15: 0 | J15: 131 | K15: 135 | L15: 0 | M15: 178 | N15: 0 | O15: 180 | P15: 121 | Q15: 245 | R15: 125 | S15: 222 | T15: 152 | U15: 206 | V15: 0 | W15: 214 | X15: 206 | Y15: 0 | Z15: 136 | AA15: 193 | AB15: 0 | AC15: 176 | AD15: 63 | AE15: 0 | AF15: 253 | AG15: 154 | AH15: 83 | AI15: 129 | AJ15: 158 | AK15: =SUM(F15:AJ15) -> 3810 | AL15: =AK15*$AS$10 -> 1619.3555 | AM15: =AK15 -> 3810 | AN15: =AM15*$AT$10 -> 208.79511 | AO15: =AL15+AN15 -> 1828.1507 | AP15: A | AQ15: =+AK15*40% -> 1524 | AR15: =+AL15-AQ15 -> 95.35554
A16: 3 | B16: 3 | C16: 03518 | D16: =TONGHOPCONGDOI!C13 -> T. Đôn Ma | F16: 0 | G16: 160 | H16: 191 | I16: 0 | J16: 131 | K16: 135 | L16: 0 | M16: 178 | N16: 0 | O16: 181 | P16: 121 | Q16: 245 | R16: 125 | S16: 223 | T16: 153 | U16: 207 | V16: 0 | W16: 213 | X16: 206 | Y16: 0 | Z16: 136 | AA16: 193 | AB16: 0 | AC16: 176 | AD16: 64 | AE16: 0 | AF16: 253 | AG16: 154 | AH16: 84 | AI16: 130 | AJ16: 159 | AK16: =SUM(F16:AJ16) -> 3818 | AL16: =AK16*$AS$10 -> 1622.7558 | AM16: =AK16 -> 3818 | AN16: =AM16*$AT$10 -> 209.23353 | AO16: =AL16+AN16 -> 1831.9893 | AP16: A | AQ16: =+AK16*40% -> 1527.2 | AR16: =+AL16-AQ16 -> 95.555762
A17: 4 | B17: 4 | C17: 04087 | D17: =TONGHOPCONGDOI!C14 -> N. La Ty | F17: 0 | G17: 249 | H17: 137 | I17: 130 | J17: 209 | K17: 140 | L17: 126 | M17: 135 | N17: 130 | O17: 209 | P17: 155 | Q17: 195 | R17: 117 | S17: 175 | T17: 143 | U17: 151 | V17: 0 | W17: 246 | X17: 194 | Y17: 160 | Z17: 220 | AA17: 180 | AB17: 167 | AC17: 160 | AD17: 105 | AE17: 156 | AF17: 156 | AG17: 120 | AH17: 0 | AI17: 120 | AJ17: 120 | AK17: =SUM(F17:AJ17) -> 4505 | AL17: =AK17*$AS$10 -> 1914.7498 | AM17: =AK17 -> 4505 | AN17: =AM17*$AT$10 -> 246.88241 | AO17: =AL17+AN17 -> 2161.6322 | AP17: A | AQ17: =+AK17*40% -> 1802 | AR17: =+AL17-AQ17 -> 112.74979
A18: 5 | B18: 5 | C18: 04088 | D18: =TONGHOPCONGDOI!C15 -> Thong Say | F18: 114 | G18: 144 | H18: 167 | I18: 71 | J18: 85 | K18: 88 | L18: 107 | M18: 0 | N18: 92 | O18: 183 | P18: 199 | Q18: 174 | R18: 89 | S18: 162 | T18: 183 | U18: 142 | V18: 96 | W18: 176 | X18: 189 | Y18: 144 | Z18: 90 | AA18: 159 | AB18: 159 | AC18: 106 | AD18: 105 | AE18: 119 | AF18: 130 | AG18: 113 | AH18: 86 | AI18: 139 | AJ18: 130 | AK18: =SUM(F18:AJ18) -> 3941 | AL18: =AK18*$AS$10 -> 1675.0342 | AM18: =AK18 -> 3941 | AN18: =AM18*$AT$10 -> 215.97416 | AO18: =AL18+AN18 -> 1891.0083 | AP18: B | AQ18: =+AK18*40% -> 1576.4 | AR18: =+AL18-AQ18 -> 98.634169
A19: 6 | B19: 6 | C19: 03545 | D19: =TONGHOPCONGDOI!C16 -> Phon Xa Văn | F19: 98 | G19: 183 | H19: 174 | I19: 125 | J19: 80 | K19: 157 | L19: 175 | M19: 130 | N19: 88 | O19: 193 | P19: 201 | Q19: 184 | R19: 89 | S19: 175 | T19: 185 | U19: 158 | V19: 89 | W19: 175 | X19: 173 | Y19: 140 | Z19: 105 | AA19: 153 | AB19: 154 | AC19: 131 | AD19: 72 | AE19: 132 | AF19: 147 | AG19: 116 | AH19: 95 | AI19: 185 | AJ19: 161 | AK19: =SUM(F19:AJ19) -> 4423 | AL19: =AK19*$AS$10 -> 1879.8975 | AM19: =AK19 -> 4423 | AN19: =AM19*$AT$10 -> 242.38866 | AO19: =AL19+AN19 -> 2122.2862 | AP19: A | AQ19: =+AK19*40% -> 1769.2 | AR19: =+AL19-AQ19 -> 110.69752
A20: 7 | B20: 7 | C20: 04089 | D20: =TONGHOPCONGDOI!C17 -> N. Tỏi | F20: 144 | G20: 199 | H20: 175 | I20: 139 | J20: 120 | K20: 150 | L20: 146 | M20: 153 | N20: 0 | O20: 174 | P20: 179 | Q20: 131 | R20: 246 | S20: 166 | T20: 237 | U20: 150 | V20: 0 | W20: 201 | X20: 175 | Y20: 0 | Z20: 195 | AA20: 0 | AB20: 0 | AC20: 131 | AD20: 0 | AE20: 0 | AF20: 405 | AG20: 142 | AH20: 100 | AI20: 59 | AJ20: 123 | AK20: =SUM(F20:AJ20) -> 4040 | AL20: =AK20*$AS$10 -> 1717.1119 | AM20: =AK20 -> 4040 | AN20: =AM20*$AT$10 -> 221.39954 | AO20: =AL20+AN20 -> 1938.5115 | AP20: A | AQ20: =+AK20*40% -> 1616 | AR20: =+AL20-AQ20 -> 101.11191
A21: 8 | B21: 8 | D21: =TONGHOPCONGDOI!C18 -> Na Ly | F21: 0 | G21: 155 | H21: 208 | I21: 152 | J21: 208 | K21: 136 | L21: 203 | M21: 140 | N21: 108 | O21: 163 | P21: 247 | Q21: 190 | R21: 112 | S21: 175 | T21: 176 | U21: 141 | V21: 0 | W21: 153 | X21: 153 | Y21: 169 | Z21: 124 | AA21: 136 | AB21: 224 | AC21: 144 | AD21: 114 | AE21: 162 | AF21: 173 | AG21: 180 | AH21: 126 | AI21: 191 | AJ21: 191 | AK21: =SUM(F21:AJ21) -> 4754 | AL21: =AK21*$AS$10 -> 2020.5817 | AM21: =AK21 -> 4754 | AN21: =AM21*$AT$10 -> 260.52807 | AO21: =AL21+AN21 -> 2281.1098 | AP21: A | AQ21: =+AK21*40% -> 1901.6 | AR21: =+AL21-AQ21 -> 118.98169
A22: 9 | B22: 9 | C22: 02739 | D22: =TONGHOPCONGDOI!C19 -> Thảo Lẹ | F22: 140 | G22: 145 | H22: 163 | I22: 153 | J22: 115 | K22: 139 | L22: 215 | M22: 144 | N22: 0 | O22: 242 | P22: 242 | Q22: 212 | R22: 246 | S22: 222 | T22: 254 | U22: 194 | V22: 126 | W22: 170 | X22: 178 | Y22: 207 | Z22: 128 | AA22: 218 | AB22: 219 | AC22: 157 | AD22: 129 | AE22: 156 | AF22: 229 | AG22: 200 | AH22: 140 | AI22: 166 | AJ22: 138 | AK22: =SUM(F22:AJ22) -> 5387 | AL22: =AK22*$AS$10 -> 2289.6242 | AM22: =AK22 -> 5387 | AN22: =AM22*$AT$10 -> 295.21765 | AO22: =AL22+AN22 -> 2584.8419 | AP22: B | AQ22: =+AK22*40% -> 2154.8 | AR22: =+AL22-AQ22 -> 134.82422
A23: 10 | B23: 10 | C23: 04090 | D23: =TONGHOPCONGDOI!C20 -> N. Đeng (2) | F23: 120 | G23: 163 | H23: 136 | I23: 132 | J23: 96 | K23: 163 | L23: 115 | M23: 140 | N23: 99 | O23: 179 | P23: 123 | Q23: 202 | R23: 113 | S23: 154 | T23: 165 | U23: 161 | V23: 116 | W23: 162 | X23: 149 | Y23: 162 | Z23: 107 | AA23: 141 | AB23: 150 | AC23: 131 | AD23: 97 | AE23: 128 | AF23: 152 | AG23: 177 | AH23: 112 | AI23: 161 | AJ23: 153 | AK23: =SUM(F23:AJ23) -> 4359 | AL23: =AK23*$AS$10 -> 1852.6957 | AM23: =AK23 -> 4359 | AN23: =AM23*$AT$10 -> 238.88134 | AO23: =AL23+AN23 -> 2091.5771 | AP23: B | AQ23: =+AK23*40% -> 1743.6 | AR23: =+AL23-AQ23 -> 109.09575
A24: 11 | B24: 11 | C24: 03509 | D24: =TONGHOPCONGDOI!C21 -> T. May | F24: 107 | G24: 215 | H24: 157 | I24: 108 | J24: 182 | K24: 245 | L24: 250 | M24: 174 | N24: 146 | O24: 203 | P24: 194 | Q24: 166 | R24: 0 | S24: 261 | T24: 261 | U24: 188 | V24: 248 | W24: 163 | X24: 145 | Y24: 116 | Z24: 147 | AA24: 225 | AB24: 221 | AC24: 170 | AD24: 82 | AE24: 135 | AF24: 142 | AG24: 99 | AH24: 183 | AI24: 211 | AJ24: 228 | AK24: =SUM(F24:AJ24) -> 5372 | AL24: =AK24*$AS$10 -> 2283.2488 | AM24: =AK24 -> 5372 | AN24: =AM24*$AT$10 -> 294.39563 | AO24: =AL24+AN24 -> 2577.6444 | AP24: A | AQ24: =+AK24*40% -> 2148.8 | AR24: =+AL24-AQ24 -> 134.44881
A25: 12 | B25: 12 | C25: 04091 | D25: =TONGHOPCONGDOI!C22 -> N. Bay | F25: 0 | G25: 93 | H25: 135 | I25: 118 | J25: 123 | K25: 97 | L25: 159 | M25: 128 | N25: 0 | O25: 132 | P25: 168 | Q25: 132 | R25: 94 | S25: 110 | T25: 137 | U25: 123 | V25: 0 | W25: 0 | X25: 187 | Y25: 133 | Z25: 79 | AA25: 160 | AB25: 166 | AC25: 117 | AD25: 0 | AE25: 0 | AF25: 116 | AG25: 92 | AH25: 0 | AI25: 111 | AJ25: 120 | AK25: =SUM(F25:AJ25) -> 3030 | AL25: =AK25*$AS$10 -> 1287.8339 | AM25: =AK25 -> 3030 | AN25: =AM25*$AT$10 -> 166.04966 | AO25: =AL25+AN25 -> 1453.8836 | AP25: B | AQ25: =+AK25*40% -> 1212 | AR25: =+AL25-AQ25 -> 75.833933
A26: 13 | B26: 13 | C26: 03527 | D26: =TONGHOPCONGDOI!C23 -> T Núc | F26: 0 | G26: 94 | H26: 136 | I26: 118 | J26: 124 | K26: 98 | L26: 160 | M26: 128 | N26: 0 | O26: 132 | P26: 168 | Q26: 133 | R26: 95 | S26: 110 | T26: 138 | U26: 123 | V26: 0 | W26: 0 | X26: 188 | Y26: 133 | Z26: 79 | AA26: 160 | AB26: 166 | AC26: 117 | AD26: 0 | AE26: 0 | AF26: 116 | AG26: 93 | AH26: 0 | AI26: 111 | AJ26: 120 | AK26: =SUM(F26:AJ26) -> 3040 | AL26: =AK26*$AS$10 -> 1292.0842 | AM26: =AK26 -> 3040 | AN26: =AM26*$AT$10 -> 166.59767 | AO26: =AL26+AN26 -> 1458.6819 | AP26: B | AQ26: =+AK26*40% -> 1216 | AR26: =+AL26-AQ26 -> 76.08421
A27: 14 | B27: 14 | C27: 03528 | D27: =TONGHOPCONGDOI!C24 -> T. Cô | F27: 98 | G27: 183 | H27: 174 | I27: 125 | J27: 80 | K27: 157 | L27: 175 | M27: 130 | N27: 88 | O27: 193 | P27: 205 | Q27: 185 | R27: 89 | S27: 175 | T27: 186 | U27: 159 | V27: 89 | W27: 145 | X27: 173 | Y27: 139 | Z27: 105 | AA27: 153 | AB27: 154 | AC27: 131 | AD27: 72 | AE27: 132 | AF27: 147 | AG27: 116 | AH27: 95 | AI27: 185 | AJ27: 161 | AK27: =SUM(F27:AJ27) -> 4399 | AL27: =AK27*$AS$10 -> 1869.6969 | AM27: =AK27 -> 4399 | AN27: =AM27*$AT$10 -> 241.07341 | AO27: =AL27+AN27 -> 2110.7703 | AP27: A | AQ27: =+AK27*40% -> 1759.6 | AR27: =+AL27-AQ27 -> 110.09686
A28: 15 | B28: 15 | C28: 03524 | D28: =TONGHOPCONGDOI!C25 -> T. Nả | F28: 115 | G28: 155 | H28: 154 | I28: 126 | J28: 0 | K28: 151 | L28: 179 | M28: 140 | N28: 180 | O28: 161 | P28: 194 | Q28: 136 | R28: 97 | S28: 153 | T28: 160 | U28: 137 | V28: 88 | W28: 149 | X28: 175 | Y28: 124 | Z28: 81 | AA28: 139 | AB28: 141 | AC28: 162 | AD28: 88 | AE28: 146 | AF28: 134 | AG28: 138 | AH28: 113 | AI28: 142 | AJ28: 217 | AK28: =SUM(F28:AJ28) -> 4275 | AL28: =AK28*$AS$10 -> 1816.9934 | AM28: =AK28 -> 4275 | AN28: =AM28*$AT$10 -> 234.27798 | AO28: =AL28+AN28 -> 2051.2714 | AP28: B | AQ28: =+AK28*40% -> 1710 | AR28: =+AL28-AQ28 -> 106.99342
