Workbook

Sheet Chấm công KT
B1: CỘNG HÒA DÂN CHỦ NHÂN DÂN LÀO
B2: Hòa Bình -Độc Lập - Dân Chủ - thống Nhất - Thịnh Vượng
B3: -----o0o-----
B5: CÔNG TY TNHH CP QUASA - GERUCO LÀO
B6: NÔNG TRƯỜNG 2
B7: BẢNG CHẤM CÔNG PHỤ CẤP CHO CÔNG NHÂN KHAI THÁC THÁNG 02 NĂM 2025
A8: STT | B8: STT | C8: HỌ VÀ TÊN | D8: BẢN | E8: Phụ cấp ngày cạo, ngày chủ nhật | AJ8: Ngày công đi cạo thường (x) | AK8: Ngày CN thường (cn) | AL8: Ngày công đi cạo 2 lát (đ) | AM8: Ngày công chủ nhật cạo 2 lát (đc) | AN8: Ngày công cạo gia tăng 2 miêng (gt) | AO8: Ngày chủ nhật cạo gia tăng 2 miệng (ct) | AP8: Tổng công | AQ8: Kí tên | AU8: Ngày công đi cạo thường (x) | AV8: Ngày CN thường (cn) | AW8: Ngày công đi cạo 2 lát (đ) | AX8: Ngày công chủ nhật cạo 2 lát (đc) | AY8: Ngày công cạo gia tăng 2 miêng (gt) | AZ8: Ngày chủ nhật cạo gia tăng 2 miệng (ct)
E9: 1 | F9: 2 | G9: 3 | H9: 4 | I9: 5 | J9: 6 | K9: 7 | L9: 8 | M9: 9 | N9: 10 | O9: 11 | P9: 12 | Q9: 13 | R9: 14 | S9: 15 | T9: 16 | U9: 17 | V9: 18 | W9: 19 | X9: 20 | Y9: 21 | Z9: 22 | AA9: 23 | AB9: 24 | AC9: 25 | AD9: 26 | AE9: 27 | AF9: 28 | AG9: 29 | AH9: 30 | AI9: 31
B10: Đội I | E10: =SUM(COUNTIF(E11:E90,"x"))+(COUNTIF(E11:E90,"cn"))+(COUNTIF(E11:E90,"gt"))+(COUNTIF(E11:E90,"ct")) -> 0 | F10: =SUM(COUNTIF(F11:F90,"x"))+(COUNTIF(F11:F90,"cn"))+(COUNTIF(F11:F90,"gt"))+(COUNTIF(F11:F90,"ct")) -> 0 | G10: =SUM(COUNTIF(G11:G90,"x"))+(COUNTIF(G11:G90,"cn"))+(COUNTIF(G11:G90,"gt"))+(COUNTIF(G11:G90,"ct")) -> 0 | H10: =SUM(COUNTIF(H11:H90,"x"))+(COUNTIF(H11:H90,"cn"))+(COUNTIF(H11:H90,"gt"))+(COUNTIF(H11:H90,"ct")) -> 0 | I10: =SUM(COUNTIF(I11:I90,"x"))+(COUNTIF(I11:I90,"cn"))+(COUNTIF(I11:I90,"gt"))+(COUNTIF(I11:I90,"ct")) -> 0 | J10: =SUM(COUNTIF(J11:J90,"x"))+(COUNTIF(J11:J90,"cn"))+(COUNTIF(J11:J90,"gt"))+(COUNTIF(J11:J90,"ct")) -> 0 | K10: =SUM(COUNTIF(K11:K90,"x"))+(COUNTIF(K11:K90,"cn"))+(COUNTIF(K11:K90,"gt"))+(COUNTIF(K11:K90,"ct")) -> 0 | L10: =SUM(COUNTIF(L11:L90,"x"))+(COUNTIF(L11:L90,"cn"))+(COUNTIF(L11:L90,"gt"))+(COUNTIF(L11:L90,"ct")) -> 0 | ... AH10: =SUM(COUNTIF(AH11:AH90,"x"))+(COUNTIF(AH11:AH90,"cn"))+(COUNTIF(AH11:AH90,"gt"))+(COUNTIF(AH11:AH90,"ct")) -> 0 | AI10: =SUM(COUNTIF(AI11:AI90,"x"))+(COUNTIF(AI11:AI90,"cn"))+(COUNTIF(AI11:AI90,"đ")) -> 0 | AJ10: =SUM(AJ11:AJ90) -> 0 | AK10: =SUM(AK11:AK90) -> 0 | AL10: =SUM(AL11:AL90) -> 0 | AM10: =SUM(AM11:AM90) -> 0 | AN10: =SUM(AN11:AN90) -> 0 | AO10: =SUM(AO11:AO90) -> 0 | AP10: =SUM(AP11:AP90) -> 0 | AS10: =VLOOKUP(C11,'[1]NT 2'!$C$2:$J$259,8,0) -> 03456 | AT10: =D11-AS10 -> 0
A11: 1 | B11: 1 | C11: T. Vôn | D11: =VLOOKUP(C11,'[1]NT 2'!$C$2:$J$259,8,0) -> 03456 | AJ11: =SUM(COUNTIF(E11:AI11,"x")) -> 0 | AK11: =SUM(COUNTIF(E11:AI11,"cn")) -> 0 | AL11: =SUM(COUNTIF(E11:AI11,"đ")) -> 0 | AM11: =SUM(COUNTIF(E11:AI11,"đc")) -> 0 | AN11: =SUM(COUNTIF(E11:AI11,"gt")) -> 0 | AO11: =SUM(COUNTIF(E11:AI11,"ct")) -> 0 | AP11: =AJ11+AK11+AL11+AM11+AN11+AO11 -> 0 | AS11: =VLOOKUP(C12,'[1]NT 2'!$C$2:$J$259,8,0) -> #N/A | AT11: =D12-AS11 -> #N/A
A12: 2 | B12: 2 | C12: T. Feng | AJ12: =SUM(COUNTIF(E12:AI12,"x")) -> 0 | AK12: =SUM(COUNTIF(E12:AI12,"cn")) -> 0 | AL12: =SUM(COUNTIF(E12:AI12,"đ")) -> 0 | AM12: =SUM(COUNTIF(E12:AI12,"đc")) -> 0 | AN12: =SUM(COUNTIF(E12:AI12,"gt")) -> 0 | AO12: =SUM(COUNTIF(E12:AI12,"ct")) -> 0 | AP12: =AJ12+AK12+AL12+AM12+AN12+AO12 -> 0 | AS12: =VLOOKUP(C13,'[1]NT 2'!$C$2:$J$259,8,0) -> 02725 | AT12: =D13-AS12 -> 0
A13: 3 | B13: 3 | C13: T. Sa Văn | D13: =VLOOKUP(C13,'[1]NT 2'!$C$2:$J$259,8,0) -> 02725 | AJ13: =SUM(COUNTIF(E13:AI13,"x")) -> 0 | AK13: =SUM(COUNTIF(E13:AI13,"cn")) -> 0 | AL13: =SUM(COUNTIF(E13:AI13,"đ")) -> 0 | AM13: =SUM(COUNTIF(E13:AI13,"đc")) -> 0 | AN13: =SUM(COUNTIF(E13:AI13,"gt")) -> 0 | AO13: =SUM(COUNTIF(E13:AI13,"ct")) -> 0 | AP13: =AJ13+AK13+AL13+AM13+AN13+AO13 -> 0 | AS13: =VLOOKUP(C14,'[1]NT 2'!$C$2:$J$259,8,0) -> 03458 | AT13: =D14-AS13 -> 0
A14: 4 | B14: 4 | C14: N. Pheng Mi | D14: =VLOOKUP(C14,'[1]NT 2'!$C$2:$J$259,8,0) -> 03458 | AJ14: =SUM(COUNTIF(E14:AI14,"x")) -> 0 | AK14: =SUM(COUNTIF(E14:AI14,"cn")) -> 0 | AL14: =SUM(COUNTIF(E14:AI14,"đ")) -> 0 | AM14: =SUM(COUNTIF(E14:AI14,"đc")) -> 0 | AN14: =SUM(COUNTIF(E14:AI14,"gt")) -> 0 | AO14: =SUM(COUNTIF(E14:AI14,"ct")) -> 0 | AP14: =AJ14+AK14+AL14+AM14+AN14+AO14 -> 0 | AS14: =VLOOKUP(C15,'[1]NT 2'!$C$2:$J$259,8,0) -> 03459 | AT14: =D15-AS14 -> 0
A15: 5 | B15: 5 | C15: N. Vạt | D15: =VLOOKUP(C15,'[1]NT 2'!$C$2:$J$259,8,0) -> 03459 | AJ15: =SUM(COUNTIF(E15:AI15,"x")) -> 0 | AK15: =SUM(COUNTIF(E15:AI15,"cn")) -> 0 | AL15: =SUM(COUNTIF(E15:AI15,"đ")) -> 0 | AM15: =SUM(COUNTIF(E15:AI15,"đc")) -> 0 | AN15: =SUM(COUNTIF(E15:AI15,"gt")) -> 0 | AO15: =SUM(COUNTIF(E15:AI15,"ct")) -> 0 | AP15: =AJ15+AK15+AL15+AM15+AN15+AO15 -> 0 | AS15: =VLOOKUP(C16,'[1]NT 2'!$C$2:$J$259,8,0) -> 03460 | AT15: =D16-AS15 -> 0
A16: 6 | B16: 6 | C16: T. Tích | D16: =VLOOKUP(C16,'[1]NT 2'!$C$2:$J$259,8,0) -> 03460 | AJ16: =SUM(COUNTIF(E16:AI16,"x")) -> 0 | AK16: =SUM(COUNTIF(E16:AI16,"cn")) -> 0 | AL16: =SUM(COUNTIF(E16:AI16,"đ")) -> 0 | AM16: =SUM(COUNTIF(E16:AI16,"đc")) -> 0 | AN16: =SUM(COUNTIF(E16:AI16,"gt")) -> 0 | AO16: =SUM(COUNTIF(E16:AI16,"ct")) -> 0 | AP16: =AJ16+AK16+AL16+AM16+AN16+AO16 -> 0 | AS16: =VLOOKUP(C17,'[1]NT 2'!$C$2:$J$259,8,0) -> 03461 | AT16: =D17-AS16 -> 0
A17: 7 | B17: 7 | C17: T. Bi Ly | D17: =VLOOKUP(C17,'[1]NT 2'!$C$2:$J$259,8,0) -> 03461 | AJ17: =SUM(COUNTIF(E17:AI17,"x")) -> 0 | AK17: =SUM(COUNTIF(E17:AI17,"cn")) -> 0 | AL17: =SUM(COUNTIF(E17:AI17,"đ")) -> 0 | AM17: =SUM(COUNTIF(E17:AI17,"đc")) -> 0 | AN17: =SUM(COUNTIF(E17:AI17,"gt")) -> 0 | AO17: =SUM(COUNTIF(E17:AI17,"ct")) -> 0 | AP17: =AJ17+AK17+AL17+AM17+AN17+AO17 -> 0 | AS17: =VLOOKUP(C18,'[1]NT 2'!$C$2:$J$259,8,0) -> 03462 | AT17: =D18-AS17 -> 0
A18: 8 | B18: 8 | C18: T . Bua Ngân | D18: =VLOOKUP(C18,'[1]NT 2'!$C$2:$J$259,8,0) -> 03462 | AJ18: =SUM(COUNTIF(E18:AI18,"x")) -> 0 | AK18: =SUM(COUNTIF(E18:AI18,"cn")) -> 0 | AL18: =SUM(COUNTIF(E18:AI18,"đ")) -> 0 | AM18: =SUM(COUNTIF(E18:AI18,"đc")) -> 0 | AN18: =SUM(COUNTIF(E18:AI18,"gt")) -> 0 | AO18: =SUM(COUNTIF(E18:AI18,"ct")) -> 0 | AP18: =AJ18+AK18+AL18+AM18+AN18+AO18 -> 0 | AS18: =VLOOKUP(C19,'[1]NT 2'!$C$2:$J$259,8,0) -> 03463 | AT18: =D19-AS18 -> 0
A19: 9 | B19: 9 | C19: T Căng | D19: =VLOOKUP(C19,'[1]NT 2'!$C$2:$J$259,8,0) -> 03463 | AJ19: =SUM(COUNTIF(E19:AI19,"x")) -> 0 | AK19: =SUM(COUNTIF(E19:AI19,"cn")) -> 0 | AL19: =SUM(COUNTIF(E19:AI19,"đ")) -> 0 | AM19: =SUM(COUNTIF(E19:AI19,"đc")) -> 0 | AN19: =SUM(COUNTIF(E19:AI19,"gt")) -> 0 | AO19: =SUM(COUNTIF(E19:AI19,"ct")) -> 0 | AP19: =AJ19+AK19+AL19+AM19+AN19+AO19 -> 0 | AS19: =VLOOKUP(C20,'[1]NT 2'!$C$2:$J$259,8,0) -> 03464 | AT19: =D20-AS19 -> 0
A20: 10 | B20: 10 | C20: N. Phôn 1 | D20: =VLOOKUP(C20,'[1]NT 2'!$C$2:$J$259,8,0) -> 03464 | AJ20: =SUM(COUNTIF(E20:AI20,"x")) -> 0 | AK20: =SUM(COUNTIF(E20:AI20,"cn")) -> 0 | AL20: =SUM(COUNTIF(E20:AI20,"đ")) -> 0 | AM20: =SUM(COUNTIF(E20:AI20,"đc")) -> 0 | AN20: =SUM(COUNTIF(E20:AI20,"gt")) -> 0 | AO20: =SUM(COUNTIF(E20:AI20,"ct")) -> 0 | AP20: =AJ20+AK20+AL20+AM20+AN20+AO20 -> 0 | AS20: =VLOOKUP(C21,'[1]NT 2'!$C$2:$J$259,8,0) -> 03465 | AT20: =D21-AS20 -> 0
A21: 11 | B21: 11 | C21: T. In Păn | D21: =VLOOKUP(C21,'[1]NT 2'!$C$2:$J$259,8,0) -> 03465 | AJ21: =SUM(COUNTIF(E21:AI21,"x")) -> 0 | AK21: =SUM(COUNTIF(E21:AI21,"cn")) -> 0 | AL21: =SUM(COUNTIF(E21:AI21,"đ")) -> 0 | AM21: =SUM(COUNTIF(E21:AI21,"đc")) -> 0 | AN21: =SUM(COUNTIF(E21:AI21,"gt")) -> 0 | AO21: =SUM(COUNTIF(E21:AI21,"ct")) -> 0 | AP21: =AJ21+AK21+AL21+AM21+AN21+AO21 -> 0 | AS21: =VLOOKUP(C22,'[1]NT 2'!$C$2:$J$259,8,0) -> 03466 | AT21: =D22-AS21 -> 0
A22: 12 | B22: 12 | C22: N. Keo | D22: =VLOOKUP(C22,'[1]NT 2'!$C$2:$J$259,8,0) -> 03466 | AJ22: =SUM(COUNTIF(E22:AI22,"x")) -> 0 | AK22: =SUM(COUNTIF(E22:AI22,"cn")) -> 0 | AL22: =SUM(COUNTIF(E22:AI22,"đ")) -> 0 | AM22: =SUM(COUNTIF(E22:AI22,"đc")) -> 0 | AN22: =SUM(COUNTIF(E22:AI22,"gt")) -> 0 | AO22: =SUM(COUNTIF(E22:AI22,"ct")) -> 0 | AP22: =AJ22+AK22+AL22+AM22+AN22+AO22 -> 0 | AS22: =VLOOKUP(C23,'[1]NT 2'!$C$2:$J$259,8,0) -> 02727 | AT22: =D23-AS22 -> 0
A23: 13 | B23: 13 | C23: T. Thong Đon | D23: =VLOOKUP(C23,'[1]NT 2'!$C$2:$J$259,8,0) -> 02727 | AJ23: =SUM(COUNTIF(E23:AI23,"x")) -> 0 | AK23: =SUM(COUNTIF(E23:AI23,"cn")) -> 0 | AL23: =SUM(COUNTIF(E23:AI23,"đ")) -> 0 | AM23: =SUM(COUNTIF(E23:AI23,"đc")) -> 0 | AN23: =SUM(COUNTIF(E23:AI23,"gt")) -> 0 | AO23: =SUM(COUNTIF(E23:AI23,"ct")) -> 0 | AP23: =AJ23+AK23+AL23+AM23+AN23+AO23 -> 0 | AS23: =VLOOKUP(C24,'[1]NT 2'!$C$2:$J$259,8,0) -> 03467 | AT23: =D24-AS23 -> 0
A24: 14 | B24: 14 | C24: T. Hin | D24: =VLOOKUP(C24,'[1]NT 2'!$C$2:$J$259,8,0) -> 03467 | AJ24: =SUM(COUNTIF(E24:AI24,"x")) -> 0 | AK24: =SUM(COUNTIF(E24:AI24,"cn")) -> 0 | AL24: =SUM(COUNTIF(E24:AI24,"đ")) -> 0 | AM24: =SUM(COUNTIF(E24:AI24,"đc")) -> 0 | AN24: =SUM(COUNTIF(E24:AI24,"gt")) -> 0 | AO24: =SUM(COUNTIF(E24:AI24,"ct")) -> 0 | AP24: =AJ24+AK24+AL24+AM24+AN24+AO24 -> 0 | AS24: =VLOOKUP(C25,'[1]NT 2'!$C$2:$J$259,8,0) -> 03468 | AT24: =D25-AS24 -> 0
... A50: 40 | B50: 40 | C50: T. Tinh | D50: =VLOOKUP(C50,'[1]NT 2'!$C$2:$J$259,8,0) -> 03489 | AJ50: =SUM(COUNTIF(E50:AI50,"x")) -> 0 | AK50: =SUM(COUNTIF(E50:AI50,"cn")) -> 0 | AL50: =SUM(COUNTIF(E50:AI50,"đ")) -> 0 | AM50: =SUM(COUNTIF(E50:AI50,"đc")) -> 0 | AN50: =SUM(COUNTIF(E50:AI50,"gt")) -> 0 | AO50: =SUM(COUNTIF(E50:AI50,"ct")) -> 0 | AP50: =AJ50+AK50+AL50+AM50+AN50+AO50 -> 0 | AS50: =VLOOKUP(C51,'[1]NT 2'!$C$2:$J$259,8,0) -> #N/A | AT50: =D51-AS50 -> #N/A
A51: 41 | B51: 41 | C51: T. Khăm Pỏi | AJ51: =SUM(COUNTIF(E51:AI51,"x")) -> 0 | AK51: =SUM(COUNTIF(E51:AI51,"cn")) -> 0 | AL51: =SUM(COUNTIF(E51:AI51,"đ")) -> 0 | AM51: =SUM(COUNTIF(E51:AI51,"đc")) -> 0 | AN51: =SUM(COUNTIF(E51:AI51,"gt")) -> 0 | AO51: =SUM(COUNTIF(E51:AI51,"ct")) -> 0 | AP51: =AJ51+AK51+AL51+AM51+AN51+AO51 -> 0 | AS51: =VLOOKUP(C52,'[1]NT 2'!$C$2:$J$259,8,0) -> 03491 | AT51: =D52-AS51 -> 0
A52: 42 | B52: 42 | C52: Lăm Ngân | D52: =VLOOKUP(C52,'[1]NT 2'!$C$2:$J$259,8,0) -> 03491 | AJ52: =SUM(COUNTIF(E52:AI52,"x")) -> 0 | AK52: =SUM(COUNTIF(E52:AI52,"cn")) -> 0 | AL52: =SUM(COUNTIF(E52:AI52,"đ")) -> 0 | AM52: =SUM(COUNTIF(E52:AI52,"đc")) -> 0 | AN52: =SUM(COUNTIF(E52:AI52,"gt")) -> 0 | AO52: =SUM(COUNTIF(E52:AI52,"ct")) -> 0 | AP52: =AJ52+AK52+AL52+AM52+AN52+AO52 -> 0 | AS52: =VLOOKUP(C53,'[1]NT 2'!$C$2:$J$259,8,0) -> 02715 | AT52: =D53-AS52 -> 0
A53: 43 | B53: 43 | C53: N. Ting | D53: =VLOOKUP(C53,'[1]NT 2'!$C$2:$J$259,8,0) -> 02715 | AJ53: =SUM(COUNTIF(E53:AI53,"x")) -> 0 | AK53: =SUM(COUNTIF(E53:AI53,"cn")) -> 0 | AL53: =SUM(COUNTIF(E53:AI53,"đ")) -> 0 | AM53: =SUM(COUNTIF(E53:AI53,"đc")) -> 0 | AN53: =SUM(COUNTIF(E53:AI53,"gt")) -> 0 | AO53: =SUM(COUNTIF(E53:AI53,"ct")) -> 0 | AP53: =AJ53+AK53+AL53+AM53+AN53+AO53 -> 0 | AS53: =VLOOKUP(C54,'[1]NT 2'!$C$2:$J$259,8,0) -> 03492 | AT53: =D54-AS53 -> 0
A54: 44 | B54: 44 | C54: T. Lem | D54: =VLOOKUP(C54,'[1]NT 2'!$C$2:$J$259,8,0) -> 03492 | AJ54: =SUM(COUNTIF(E54:AI54,"x")) -> 0 | AK54: =SUM(COUNTIF(E54:AI54,"cn")) -> 0 | AL54: =SUM(COUNTIF(E54:AI54,"đ")) -> 0 | AM54: =SUM(COUNTIF(E54:AI54,"đc")) -> 0 | AN54: =SUM(COUNTIF(E54:AI54,"gt")) -> 0 | AO54: =SUM(COUNTIF(E54:AI54,"ct")) -> 0 | AP54: =AJ54+AK54+AL54+AM54+AN54+AO54 -> 0 | AS54: =VLOOKUP(C55,'[1]NT 2'!$C$2:$J$259,8,0) -> 03493 | AT54: =D55-AS54 -> 0
A55: 45 | B55: 45 | C55: T. Pông | D55: =VLOOKUP(C55,'[1]NT 2'!$C$2:$J$259,8,0) -> 03493 | AJ55: =SUM(COUNTIF(E55:AI55,"x")) -> 0 | AK55: =SUM(COUNTIF(E55:AI55,"cn")) -> 0 | AL55: =SUM(COUNTIF(E55:AI55,"đ")) -> 0 | AM55: =SUM(COUNTIF(E55:AI55,"đc")) -> 0 | AN55: =SUM(COUNTIF(E55:AI55,"gt")) -> 0 | AO55: =SUM(COUNTIF(E55:AI55,"ct")) -> 0 | AP55: =AJ55+AK55+AL55+AM55+AN55+AO55 -> 0 | AS55: =VLOOKUP(C56,'[1]NT 2'!$C$2:$J$259,8,0) -> 02721 | AT55: =D56-AS55 -> 0
A56: 46 | B56: 46 | C56: T. Chít | D56: =VLOOKUP(C56,'[1]NT 2'!$C$2:$J$259,8,0) -> 02721 | AJ56: =SUM(COUNTIF(E56:AI56,"x")) -> 0 | AK56: =SUM(COUNTIF(E56:AI56,"cn")) -> 0 | AL56: =SUM(COUNTIF(E56:AI56,"đ")) -> 0 | AM56: =SUM(COUNTIF(E56:AI56,"đc")) -> 0 | AN56: =SUM(COUNTIF(E56:AI56,"gt")) -> 0 | AO56: =SUM(COUNTIF(E56:AI56,"ct")) -> 0 | AP56: =AJ56+AK56+AL56+AM56+AN56+AO56 -> 0 | AS56: =VLOOKUP(C57,'[1]NT 2'!$C$2:$J$259,8,0) -> 02720 | AT56: =D57-AS56 -> 0
A57: 47 | B57: 47 | C57: N. La | D57: =VLOOKUP(C57,'[1]NT 2'!$C$2:$J$259,8,0) -> 02720 | AJ57: =SUM(COUNTIF(E57:AI57,"x")) -> 0 | AK57: =SUM(COUNTIF(E57:AI57,"cn")) -> 0 | AL57: =SUM(COUNTIF(E57:AI57,"đ")) -> 0 | AM57: =SUM(COUNTIF(E57:AI57,"đc")) -> 0 | AN57: =SUM(COUNTIF(E57:AI57,"gt")) -> 0 | AO57: =SUM(COUNTIF(E57:AI57,"ct")) -> 0 | AP57: =AJ57+AK57+AL57+AM57+AN57+AO57 -> 0 | AS57: =VLOOKUP(C58,'[1]NT 2'!$C$2:$J$259,8,0) -> 03494 | AT57: =D58-AS57 -> 0
A58: 48 | B58: 48 | C58: T. Đi | D58: =VLOOKUP(C58,'[1]NT 2'!$C$2:$J$259,8,0) -> 03494 | AJ58: =SUM(COUNTIF(E58:AI58,"x")) -> 0 | AK58: =SUM(COUNTIF(E58:AI58,"cn")) -> 0 | AL58: =SUM(COUNTIF(E58:AI58,"đ")) -> 0 | AM58: =SUM(COUNTIF(E58:AI58,"đc")) -> 0 | AN58: =SUM(COUNTIF(E58:AI58,"gt")) -> 0 | AO58: =SUM(COUNTIF(E58:AI58,"ct")) -> 0 | AP58: =AJ58+AK58+AL58+AM58+AN58+AO58 -> 0 | AS58: =VLOOKUP(C59,'[1]NT 2'!$C$2:$J$259,8,0) -> 03495 | AT58: =D59-AS58 -> 0
A59: 49 | B59: 49 | C59: N. On Xi | D59: =VLOOKUP(C59,'[1]NT 2'!$C$2:$J$259,8,0) -> 03495 | AJ59: =SUM(COUNTIF(E59:AI59,"x")) -> 0 | AK59: =SUM(COUNTIF(E59:AI59,"cn")) -> 0 | AL59: =SUM(COUNTIF(E59:AI59,"đ")) -> 0 | AM59: =SUM(COUNTIF(E59:AI59,"đc")) -> 0 | AN59: =SUM(COUNTIF(E59:AI59,"gt")) -> 0 | AO59: =SUM(COUNTIF(E59:AI59,"ct")) -> 0 | AP59: =AJ59+AK59+AL59+AM59+AN59+AO59 -> 0 | AS59: =VLOOKUP(C60,'[1]NT 2'!$C$2:$J$259,8,0) -> 03496 | AT59: =D60-AS59 -> 0
A60: 50 | B60: 50 | C60: T. Lốp | D60: =VLOOKUP(C60,'[1]NT 2'!$C$2:$J$259,8,0) -> 03496 | AJ60: =SUM(COUNTIF(E60:AI60,"x")) -> 0 | AK60: =SUM(COUNTIF(E60:AI60,"cn")) -> 0 | AL60: =SUM(COUNTIF(E60:AI60,"đ")) -> 0 | AM60: =SUM(COUNTIF(E60:AI60,"đc")) -> 0 | AN60: =SUM(COUNTIF(E60:AI60,"gt")) -> 0 | AO60: =SUM(COUNTIF(E60:AI60,"ct")) -> 0 | AP60: =AJ60+AK60+AL60+AM60+AN60+AO60 -> 0 | AS60: =VLOOKUP(C61,'[1]NT 2'!$C$2:$J$259,8,0) -> 03497 | AT60: =D61-AS60 -> 0
A61: 51 | B61: 51 | C61: T. Son Xay | D61: =VLOOKUP(C61,'[1]NT 2'!$C$2:$J$259,8,0) -> 03497 | AJ61: =SUM(COUNTIF(E61:AI61,"x")) -> 0 | AK61: =SUM(COUNTIF(E61:AI61,"cn")) -> 0 | AL61: =SUM(COUNTIF(E61:AI61,"đ")) -> 0 | AM61: =SUM(COUNTIF(E61:AI61,"đc")) -> 0 | AN61: =SUM(COUNTIF(E61:AI61,"gt")) -> 0 | AO61: =SUM(COUNTIF(E61:AI61,"ct")) -> 0 | AP61: =AJ61+AK61+AL61+AM61+AN61+AO61 -> 0 | AS61: =VLOOKUP(C62,'[1]NT 2'!$C$2:$J$259,8,0) -> 03498 | AT61: =D62-AS61 -> 0
A62: 52 | B62: 52 | C62: N. Lăm Phay | D62: =VLOOKUP(C62,'[1]NT 2'!$C$2:$J$259,8,0) -> 03498 | AJ62: =SUM(COUNTIF(E62:AI62,"x")) -> 0 | AK62: =SUM(COUNTIF(E62:AI62,"cn")) -> 0 | AL62: =SUM(COUNTIF(E62:AI62,"đ")) -> 0 | AM62: =SUM(COUNTIF(E62:AI62,"đc")) -> 0 | AN62: =SUM(COUNTIF(E62:AI62,"gt")) -> 0 | AO62: =SUM(COUNTIF(E62:AI62,"ct")) -> 0 | AP62: =AJ62+AK62+AL62+AM62+AN62+AO62 -> 0 | AS62: =VLOOKUP(C63,'[1]NT 2'!$C$2:$J$259,8,0) -> 02706 | AT62: =D63-AS62 -> 0
A63: 53 | B63: 53 | C63: T. Nhung | D63: =VLOOKUP(C63,'[1]NT 2'!$C$2:$J$259,8,0) -> 02706 | AJ63: =SUM(COUNTIF(E63:AI63,"x")) -> 0 | AK63: =SUM(COUNTIF(E63:AI63,"cn")) -> 0 | AL63: =SUM(COUNTIF(E63:AI63,"đ")) -> 0 | AM63: =SUM(COUNTIF(E63:AI63,"đc")) -> 0 | AN63: =SUM(COUNTIF(E63:AI63,"gt")) -> 0 | AO63: =SUM(COUNTIF(E63:AI63,"ct")) -> 0 | AP63: =AJ63+AK63+AL63+AM63+AN63+AO63 -> 0 | AS63: =VLOOKUP(C64,'[1]NT 2'!$C$2:$J$259,8,0) -> 03499 | AT63: =D64-AS63 -> 0
A64: 54 | B64: 54 | C64: N. In Ton | D64: =VLOOKUP(C64,'[1]NT 2'!$C$2:$J$259,8,0) -> 03499 | AJ64: =SUM(COUNTIF(E64:AI64,"x")) -> 0 | AK64: =SUM(COUNTIF(E64:AI64,"cn")) -> 0 | AL64: =SUM(COUNTIF(E64:AI64,"đ")) -> 0 | AM64: =SUM(COUNTIF(E64:AI64,"đc")) -> 0 | AN64: =SUM(COUNTIF(E64:AI64,"gt")) -> 0 | AO64: =SUM(COUNTIF(E64:AI64,"ct")) -> 0 | AP64: =AJ64+AK64+AL64+AM64+AN64+AO64 -> 0 | AS64: =VLOOKUP(C65,'[1]NT 2'!$C$2:$J$259,8,0) -> #N/A | AT64: =D65-AS64 -> #N/A
A65: 55 | B65: 55 | C65: N. Khay Chăn | AJ65: =SUM(COUNTIF(E65:AI65,"x")) -> 0 | AK65: =SUM(COUNTIF(E65:AI65,"cn")) -> 0 | AL65: =SUM(COUNTIF(E65:AI65,"đ")) -> 0 | AM65: =SUM(COUNTIF(E65:AI65,"đc")) -> 0 | AN65: =SUM(COUNTIF(E65:AI65,"gt")) -> 0 | AO65: =SUM(COUNTIF(E65:AI65,"ct")) -> 0 | AP65: =AJ65+AK65+AL65+AM65+AN65+AO65 -> 0 | AS65: =VLOOKUP(C66,'[1]NT 2'!$C$2:$J$259,8,0) -> 03501 | AT65: =D66-AS65 -> 0
A66: 56 | B66: 56 | C66: T Dăn | D66: =VLOOKUP(C66,'[1]NT 2'!$C$2:$J$259,8,0) -> 03501 | AJ66: =SUM(COUNTIF(E66:AI66,"x")) -> 0 | AK66: =SUM(COUNTIF(E66:AI66,"cn")) -> 0 | AL66: =SUM(COUNTIF(E66:AI66,"đ")) -> 0 | AM66: =SUM(COUNTIF(E66:AI66,"đc")) -> 0 | AN66: =SUM(COUNTIF(E66:AI66,"gt")) -> 0 | AO66: =SUM(COUNTIF(E66:AI66,"ct")) -> 0 | AP66: =AJ66+AK66+AL66+AM66+AN66+AO66 -> 0 | AS66: =VLOOKUP(C67,'[1]NT 2'!$C$2:$J$259,8,0) -> 03502 | AT66: =D67-AS66 -> 0
...

Sheet BTH mủ tạp
A2: CỘNG HÒA DÂN CHỦ NHÂN DÂN LÀO
A3: Hòa Bình -Độc Lập - Dân Chủ - thống Nhất - Thịnh Vượng
A4: -----o0o-----
B6: CÔNG TY TNHH CP QUASA - GERUCO LÀO
B7: NÔNG TRƯỜNG 2
B9: BẢNG THEO DÕI SẢN LƯỢNG MỦ TẠP THÁNG 02 NĂM 2025
A11: Stt | B11: Stt | C11: Họ và tên | D11: Ngày | AI11: Tổng mủ tạp | AJ11: DRC bình quân | AK11: Quy khô | AL11: Xếp hạng kỹ thuật | AM11: Kí tên
D12: 1 | E12: 2 | F12: 3 | G12: 4 | H12: 5 | I12: 6 | J12: 7 | K12: 8 | L12: 9 | M12: 10 | N12: 11 | O12: 12 | P12: 13 | Q12: 14 | R12: 15 | S12: 16 | T12: 17 | U12: 18 | V12: 19 | W12: 20 | X12: 21 | Y12: 22 | Z12: 23 | AA12: 24 | AB12: 25 | AC12: 26 | AD12: 27 | AE12: 28 | AF12: 45717 | AG12: 45718 | AH12: 31 | AO12: DRC bình quân
B13: ĐỘI 1
A14: Tổng | D14: =SUM(D15:D94) -> 0 | E14: =SUM(E15:E94) -> 0 | F14: =SUM(F15:F94) -> 0 | G14: =SUM(G15:G94) -> 0 | H14: =SUM(H15:H94) -> 0 | I14: =SUM(I15:I94) -> 0 | J14: =SUM(J15:J94) -> 0 | K14: =SUM(K15:K94) -> 0 | ... AG14: =SUM(AG15:AG94) -> 0 | AH14: =SUM(AH15:AH93) -> 0 | AI14: =SUM(AI15:AI94) -> 0 | AK14: =SUM(AK15:AK94) -> 0
A15: 1 | B15: 1 | C15: ='Chấm công KT'!C11 -> T. Vôn | AI15: =SUM(D15:AH15) -> 0 | AJ15: 43.78515 | AK15: =AI15*AJ15/100 -> 0 | AL15: C
A16: 2 | B16: 2 | C16: ='Chấm công KT'!C12 -> T. Feng | AI16: =SUM(D16:AH16) -> 0 | AJ16: 43.78515 | AK16: =AI16*AJ16/100 -> 0 | AL16: A
A17: 3 | B17: 3 | C17: ='Chấm công KT'!C13 -> T. Sa Văn | AI17: =SUM(D17:AH17) -> 0 | AJ17: 43.78515 | AK17: =AI17*AJ17/100 -> 0 | AL17: A
A18: 4 | B18: 4 | C18: ='Chấm công KT'!C14 -> N. Pheng Mi | AI18: =SUM(D18:AH18) -> 0 | AJ18: 43.78515 | AK18: =AI18*AJ18/100 -> 0 | AL18: B
A19: 5 | B19: 5 | C19: ='Chấm công KT'!C15 -> N. Vạt | AI19: =SUM(D19:AH19) -> 0 | AJ19: 43.78515 | AK19: =AI19*AJ19/100 -> 0 | AL19: A
A20: 6 | B20: 6 | C20: ='Chấm công KT'!C16 -> T. Tích | AI20: =SUM(D20:AH20) -> 0 | AJ20: 43.78515 | AK20: =AI20*AJ20/100 -> 0 | AL20: A
A21: 7 | B21: 7 | C21: ='Chấm công KT'!C17 -> T. Bi Ly | AI21: =SUM(D21:AH21) -> 0 | AJ21: 43.78515 | AK21: =AI21*AJ21/100 -> 0 | AL21: A
A22: 8 | B22: 8 | C22: ='Chấm công KT'!C18 -> T . Bua Ngân | AI22: =SUM(D22:AH22) -> 0 | AJ22: 43.78515 | AK22: =AI22*AJ22/100 -> 0 | AL22: A
A23: 9 | B23: 9 | C23: ='Chấm công KT'!C19 -> T Căng | AI23: =SUM(D23:AH23) -> 0 | AJ23: 43.78515 | AK23: =AI23*AJ23/100 -> 0 | AL23: A
A24: 10 | B24: 10 | C24: ='Chấm công KT'!C20 -> N. Phôn 1 | AI24: =SUM(D24:AH24) -> 0 | AJ24: 43.78515 | AK24: =AI24*AJ24/100 -> 0 | AL24: A
A25: 11 | B25: 11 | C25: ='Chấm công KT'!C21 -> T. In Păn | AI25: =SUM(D25:AH25) -> 0 | AJ25: 43.78515 | AK25: =AI25*AJ25/100 -> 0 | AL25: B
A26: 12 | B26: 12 | C26: ='Chấm công KT'!C22 -> N. Keo | AI26: =SUM(D26:AH26) -> 0 | AJ26: 43.78515 | AK26: =AI26*AJ26/100 -> 0 | AL26: A
... A88: 74 | B88: 74 | C88: ='Chấm công KT'!C84 -> T. Xem | AI88: =SUM(D88:AH88) -> 0 | AJ88: 43.78515 | AK88: =AI88*AJ88/100 -> 0 | AL88: C.
A89: 75 | B89: 75 | C89: ='Chấm công KT'!C85 -> T.Trí | AI89: =SUM(D89:AH89) -> 0 | AK89: =AI89*AJ89/100 -> 0 | AL89: C.
A90: 76 | B90: 76 | C90: ='Chấm công KT'!C86 -> T. Ngân | AI90: =SUM(D90:AH90) -> 0 | AK90: =AI90*AJ90/100 -> 0 | AL90: C.
A91: 77 | B91: 77 | C91: ='Chấm công KT'!C87 -> T.Pu | AI91: =SUM(D91:AH91) -> 0 | AK91: =AI91*AJ91/100 -> 0 | AL91: C.
A92: 78 | B92: 78 | C92: ='Chấm công KT'!C88 -> T.Ta | AI92: =SUM(D92:AH92) -> 0 | AK92: =AI92*AJ92/100 -> 0 | AL92: C.
A93: 79 | B93: 79 | C93: ='Chấm công KT'!C89 -> N.Nang | AI93: =SUM(D93:AH93) -> 0 | AK93: =AI93*AJ93/100 -> 0 | AL93: C.
A94: 80 | B94: 80 | C94: T. Tan | AI94: =SUM(D94:AH94) -> 0 | AK94: =AI94*AJ94/100 -> 0 | AL94: C.
B95: ĐỘI 2 | AO95: =SUM(AI88:AI92) -> 0
A96: Tổng | D96: =SUM(D97:D180) -> 0 | E96: =SUM(E97:E180) -> 0 | F96: =SUM(F97:F180) -> 0 | G96: =SUM(G97:G180) -> 0 | H96: =SUM(H97:H180) -> 0 | I96: =SUM(I97:I180) -> 0 | J96: =SUM(J97:J180) -> 0 | K96: =SUM(K97:K180) -> 0 | ... AG96: =SUM(AG97:AG180) -> 0 | AH96: =SUM(AH97:AH176) -> 0 | AI96: =SUM(AI97:AI180) -> 0 | AK96: =SUM(AK97:AK180) -> 0
A97: 81 | B97: 1 | C97: ='Chấm công KT'!C92 -> T. Lê | AI97: =SUM(D97:AH97) -> 0 | AJ97: 43.829255 | AK97: =AI97*AJ97/100 -> 0 | AL97: A
A98: 82 | B98: 2 | C98: ='Chấm công KT'!C93 -> Nang On Teng | AI98: =SUM(D98:AH98) -> 0 | AJ98: 43.829255 | AK98: =AI98*AJ98/100 -> 0 | AL98: A
A99: 83 | B99: 3 | C99: ='Chấm công KT'!C94 -> T. Đôn Ma | AI99: =SUM(D99:AH99) -> 0 | AJ99: 43.829255 | AK99: =AI99*AJ99/100 -> 0 | AL99: A
A100: 84 | B100: 4 | C100: ='Chấm công KT'!C95 -> T Nôn | AI100: =SUM(D100:AH100) -> 0 | AJ100: 43.829255 | AK100: =AI100*AJ100/100 -> 0 | AL100: A
A101: 85 | B101: 5 | C101: ='Chấm công KT'!C96 -> N. Khăm.. | AI101: =SUM(D101:AH101) -> 0 | AJ101: 43.829255 | AK101: =AI101*AJ101/100 -> 0 | AL101: A
A102: 86 | B102: 6 | C102: ='Chấm công KT'!C97 -> Nang La Ty | AI102: =SUM(D102:AH102) -> 0 | AJ102: 43.829255 | AK102: =AI102*AJ102/100 -> 0 | AL102: A
A103: 87 | B103: 7 | C103: ='Chấm công KT'!C98 -> N.T.T Trang (1) | AI103: =SUM(D103:AH103) -> 0 | AJ103: 43.829255 | AK103: =AI103*AJ103/100 -> 0 | AL103: A
A104: 88 | B104: 8 | C104: ='Chấm công KT'!C99 -> T. Ni On | AI104: =SUM(D104:AH104) -> 0 | AJ104: 43.829255 | AK104: =AI104*AJ104/100 -> 0 | AL104: B
A105: 89 | B105: 9 | C105: ='Chấm công KT'!C100 -> Thảo Lẹ | AI105: =SUM(D105:AH105) -> 0 | AJ105: 43.829255 | AK105: =AI105*AJ105/100 -> 0 | AL105: A
...

Sheet BTH mủ Sỉum
A2: CỘNG HÒA DÂN CHỦ NHÂN DÂN LÀO
A3: Hòa Bình -Độc Lập - Dân Chủ - thống Nhất - Thịnh Vượng
A4: -----o0o-----
A6: CÔNG TY TNHH CP QUASA - GERUCO LÀO
A7: NÔNG TRƯỜNG 2
A9: BẢNG THEO DÕI SẢN LƯỢNG MỦ SERUM THÁNG 02 NĂM 2025
AK10: DRC
A11: Stt | B11: Họ và tên | C11: Ngày | AH11: Tổng mủ Xirum | AI11: DRC bình quân | AJ11: Quy khô | AK11: Xếp hạng kỹ thuật | AL11: Kí tên
C12: 1 | D12: 2 | E12: 3 | F12: 4 | G12: 5 | H12: 6 | I12: 7 | J12: 8 | K12: 9 | L12: 10 | M12: 11 | N12: 12 | O12: 13 | P12: 14 | Q12: 15 | R12: 16 | S12: 17 | T12: 18 | U12: 19 | V12: 20 | W12: 21 | X12: 22 | Y12: 23 | Z12: 24 | AA12: 25 | AB12: 26 | AC12: 27 | AD12: 28 | AE12: 45717 | AF12: 45718
A13: ĐỘI 1 | C13: =C14 -> 0 | D13: =D14 -> 0 | E13: =E14 -> 0 | F13: =F14 -> 0 | G13: =G14 -> 0 | H13: =H14 -> 0 | I13: =I14 -> 0 | J13: =J14 -> 0 | ... AF13: =AF14 -> 0 | AH13: =AH14 -> 0 | AJ13: =AJ14 -> 0 | AK13: =AK14 -> 0
A14: 1 | B14: Mủ Xirum | AH14: =SUM(C14:AG14) -> 0 | AI14: 48.216842 | AJ14: =AH14*AI14/100 -> 0
A15: ĐỘI 2 | C15: =C16 -> 0 | D15: =D16 -> 0 | E15: =E16 -> 0 | F15: =F16 -> 0 | G15: =G16 -> 0 | H15: =H16 -> 0 | I15: =I16 -> 0 | J15: =J16 -> 0 | ... AF15: =AF16 -> 0 | AH15: =AH16 -> 0 | AJ15: =AJ16 -> 0
A16: 1 | B16: Mủ Xirum | AH16: =SUM(C16:AG16) -> 0 | AI16: 44.235 | AJ16: =AH16*AI16/100 -> 0
A17: ĐỘI 3 | C17: =C18 -> 0 | D17: =D18 -> 0 | E17: =E18 -> 0 | F17: =F18 -> 0 | G17: =G18 -> 0 | H17: =H18 -> 0 | I17: =I18 -> 0 | J17: =J18 -> 0 | ... AF17: =AF18 -> 0 | AH17: =AH18 -> 0 | AJ17: =AJ18 -> 0 | AK17: =AK18 -> 0
A18: 1 | B18: Mủ Xirum | AH18: =SUM(C18:AG18) -> 0 | AI18: 47.395652 | AJ18: =AH18*AI18/100 -> 0
A19: ĐỘI 4 | C19: =C20 -> 0 | D19: =D20 -> 0 | E19: =E20 -> 0 | F19: =F20 -> 0 | G19: =G20 -> 0 | H19: =H20 -> 0 | I19: =I20 -> 0 | J19: =J20 -> 0 | ... AF19: =AF20 -> 0 | AH19: =AH20 -> 0 | AJ19: =AJ20 -> 0 | AN19: =SUM(#REF!) -> #REF!
A20: 1 | B20: Mủ Xirum | AH20: =SUM(C20:AG20) -> 0 | AI20: 47.340606 | AJ20: =AH20*AI20/100 -> 0
A21: Tổng cộng | AE21: =AE13+AE15+AE17+AE19 -> 0 | AF21: =AF13+AF15+AF17+AF19 -> 0 | AH21: =AH13+AH15+AH17+AH19 -> 0 | AJ21: =AJ13+AJ15+AJ17+AJ19 -> 0 | AK21: =AK13+AK15+AK17+AK19 -> 0
X23: Nông trường 2, ngày 02 tháng 03 năm 2025
B24: TỔNG GIÁM ĐỐC | J24: PHÒNG KT - NN | R24: GĐ. NÔNG TRƯỜNG | Z24: TL. NÔNG NGHIỆP | AH24: TL. TC - KT
AH32: Trần Viết Hùng

Sheet TONGHOPCONGDOI
A2: CÔNG TY TNHH CỔ PHẦN QUASA - GERUCO | R2: CỘNG HÒA DÂN CHỦ NHÂN DÂN LÀO
A3: NÔNG TRƯỜNG 2 | N3: =144/0.67 -> 214.92537 | R3: Hòa Bình - Độc Lập - Dân Chủ - Thống Nhất - Thịnh Vượng
A4: Đội: 1.2.3.4 | J4: =F11*25000 -> 0 | K4: =G11*25000 -> 0 | T4: =Q9-19035.02 -> -5308.44
A5: BẢNG TỔNG HỢP CÔNG THỰC HIỆN THÁNG 01 NĂM 2025
A6: STT | B6: Mã số nhân viên | C6: Họ và Tên Lào | D6: Chức vụ
E7: Bôi thuốc kích thích | F7: Đánh đông A xít | G7: Ủi cục bộ | H7: Phun thuốc bô try | I7: Phun cỏ bao lô chống cháy | J7: Mở miêng cạo úp (mới) | K7: Ủi bao lô chống cháy | L7: Kiểm kê 0 giờ | M7: Phát chồi đại trà | N7: Băm chồi hàng | P7: Thổi lá hàng 3m | Q7: Tổng công | R7: Sản lượng mủ | V7: Các khoản PC | AC7: Tổng cộng | AD7: Xếp loại KT tính lương | AE7: Xác Nhận
R8: Mủ tạp | S8: Mủ Xirum | T8: Quy khô DRC=50 | U8: Tổng sản lượng mủ tạp+mủ dây quy khô | V8: Ngày công đi cạo thường (x) | W8: Ngày CN thường (cn) | X8: Ngày công đi cạo 2 lát (đ) | Y8: Ngày công chủ nhật cạo 2 lát (đc) | Z8: Ngày công cạo gia tăng 2 miêng (gt) | AA8: Ngày chủ nhật cạo gia tăng 2 miệng (ct) | AB8: Phụ cấp nhỏ a xít | AI8: =5308.01-Q9 -> -8418.57
A9: I | B9: VC KINH DOANH NĂM | E9: =E10+E95+E184+E250 -> 0 | F9: =F10+F95+F184+F250 -> 0 | G9: =G10+G95+G184+G250 -> 0 | H9: =H10+H95+H184+H250 -> 0 | I9: =I10+I95+I184+I250 -> 0 | J9: =J10+J95+J184+J250 -> 0 | K9: =K10+K95+K184+K250 -> 0 | L9: =L10+L95+L184+L250 -> 0 | ... N9: =N10+N95+N184+N250 -> 0 | P9: =P10+P95+P184+P250 -> 13726.58 | Q9: =Q10+Q95+Q184+Q250 -> 13726.58 | R9: =R10+R95+R184+R250 -> 0 | S9: =S10+S95+S184+S250 -> 0 | T9: =T10+T95+T184+T250 -> 0 | U9: =U10+U95+U184+U250 -> 0 | V9: =V10+V95+V184+V250 -> 0 | W9: =W10+W95+W184+W250 -> 0 | ... AC9: =AC10+AC95+AC184+AC250 -> 13726.58 | AF9: 6716.8 | AG9: =6716.8-Q9 -> -7009.78
A10: A | B10: Đội I | E10: =SUM(E11:E94) -> 0 | F10: =SUM(F11:F94) -> 0 | G10: =SUM(G11:G94) -> 0 | H10: =SUM(H11:H94) -> 0 | I10: =SUM(I11:I94) -> 0 | J10: =SUM(J11:J94) -> 0 | K10: =SUM(K11:K94) -> 0 | L10: =SUM(L11:L94) -> 0 | ... AC10: =SUM(AC11:AC94) -> 3813.57 | AF10: 1618 | AG10: 194
A11: 1 | B11: ='Chấm công KT'!D11 -> 03456 | C11: ='Chấm công KT'!C11 -> T. Vôn | D11: CN-KT | Q11: =SUM(E11:P11) -> 0 | R11: =VLOOKUP(C11,'BTH mủ tạp'!$C$15:$AI$94,33,0) -> 0 | T11: =S11*50/100 -> 0 | U11: =R11 -> 0 | V11: =VLOOKUP(C11,'Chấm công KT'!$C$11:$AJ$90,34,0) -> 0 | W11: =VLOOKUP(C11,'Chấm công KT'!$C$11:$AK$90,35,0) -> 0 | Z11: =VLOOKUP(C11,'Chấm công KT'!$C$11:$AN$90,38,0) -> 0 | AA11: =VLOOKUP(C11,'Chấm công KT'!$C$11:$AO$90,39,0) -> 0 | AC11: =Q11 -> 0 | AD11: =VLOOKUP(C11,'BTH mủ tạp'!$C$15:$AL$305,36,0) -> C
A12: 2 | B12: ='Chấm công KT'!D12 -> 0 | C12: ='Chấm công KT'!C12 -> T. Feng | D12: CN-KT | Q12: =SUM(E12:P12) -> 0 | R12: =VLOOKUP(C12,'BTH mủ tạp'!$C$15:$AI$94,33,0) -> 0 | T12: =S12*50/100 -> 0 | U12: =R12 -> 0 | V12: =VLOOKUP(C12,'Chấm công KT'!$C$11:$AJ$90,34,0) -> 0 | W12: =VLOOKUP(C12,'Chấm công KT'!$C$11:$AK$90,35,0) -> 0 | Z12: =VLOOKUP(C12,'Chấm công KT'!$C$11:$AN$90,38,0) -> 0 | AA12: =VLOOKUP(C12,'Chấm công KT'!$C$11:$AO$90,39,0) -> 0 | AC12: =Q12 -> 0 | AD12: =VLOOKUP(C12,'BTH mủ tạp'!$C$15:$AL$305,36,0) -> A
A13: 3 | B13: ='Chấm công KT'!D13 -> 02725 | C13: ='Chấm công KT'!C13 -> T. Sa Văn | D13: CN-KT | Q13: =SUM(E13:P13) -> 0 | R13: =VLOOKUP(C13,'BTH mủ tạp'!$C$15:$AI$94,33,0) -> 0 | T13: =S13*50/100 -> 0 | U13: =R13 -> 0 | V13: =VLOOKUP(C13,'Chấm công KT'!$C$11:$AJ$90,34,0) -> 0 | W13: =VLOOKUP(C13,'Chấm công KT'!$C$11:$AK$90,35,0) -> 0 | Z13: =VLOOKUP(C13,'Chấm công KT'!$C$11:$AN$90,38,0) -> 0 | AA13: =VLOOKUP(C13,'Chấm công KT'!$C$11:$AO$90,39,0) -> 0 | AC13: =Q13 -> 0 | AD13: =VLOOKUP(C13,'BTH mủ tạp'!$C$15:$AL$305,36,0) -> A | AG13: 119657 | AH13: 197
A14: 4 | B14: ='Chấm công KT'!D14 -> 03458 | C14: ='Chấm công KT'!C14 -> N. Pheng Mi | D14: CN-KT | Q14: =SUM(E14:P14) -> 0 | R14: =VLOOKUP(C14,'BTH mủ tạp'!$C$15:$AI$94,33,0) -> 0 | T14: =S14*50/100 -> 0 | U14: =R14 -> 0 | V14: =VLOOKUP(C14,'Chấm công KT'!$C$11:$AJ$90,34,0) -> 0 | W14: =VLOOKUP(C14,'Chấm công KT'!$C$11:$AK$90,35,0) -> 0 | Z14: =VLOOKUP(C14,'Chấm công KT'!$C$11:$AN$90,38,0) -> 0 | AA14: =VLOOKUP(C14,'Chấm công KT'!$C$11:$AO$90,39,0) -> 0 | AC14: =Q14 -> 0 | AD14: =VLOOKUP(C14,'BTH mủ tạp'!$C$15:$AL$305,36,0) -> B | AG14: 125408 | AH14: 554
A15: 5 | B15: ='Chấm công KT'!D15 -> 03459 | C15: ='Chấm công KT'!C15 -> N. Vạt | D15: CN-KT | Q15: =SUM(E15:P15) -> 0 | R15: =VLOOKUP(C15,'BTH mủ tạp'!$C$15:$AI$94,33,0) -> 0 | T15: =S15*50/100 -> 0 | U15: =R15 -> 0 | V15: =VLOOKUP(C15,'Chấm công KT'!$C$11:$AJ$90,34,0) -> 0 | W15: =VLOOKUP(C15,'Chấm công KT'!$C$11:$AK$90,35,0) -> 0 | Z15: =VLOOKUP(C15,'Chấm công KT'!$C$11:$AN$90,38,0) -> 0 | AA15: =VLOOKUP(C15,'Chấm công KT'!$C$11:$AO$90,39,0) -> 0 | AC15: =Q15 -> 0 | AD15: =VLOOKUP(C15,'BTH mủ tạp'!$C$15:$AL$305,36,0) -> A | AG15: 97048 | AH15: 92
A16: 6 | B16: ='Chấm công KT'!D16 -> 03460 | C16: ='Chấm công KT'!C16 -> T. Tích | D16: CN-KT | Q16: =SUM(E16:P16) -> 0 | R16: =VLOOKUP(C16,'BTH mủ tạp'!$C$15:$AI$94,33,0) -> 0 | T16: =S16*50/100 -> 0 | U16: =R16 -> 0 | V16: =VLOOKUP(C16,'Chấm công KT'!$C$11:$AJ$90,34,0) -> 0 | W16: =VLOOKUP(C16,'Chấm công KT'!$C$11:$AK$90,35,0) -> 0 | Z16: =VLOOKUP(C16,'Chấm công KT'!$C$11:$AN$90,38,0) -> 0 | AA16: =VLOOKUP(C16,'Chấm công KT'!$C$11:$AO$90,39,0) -> 0 | AC16: =Q16 -> 0 | AD16: =VLOOKUP(C16,'BTH mủ tạp'!$C$15:$AL$305,36,0) -> A | AG16: 46179
A17: 7 | B17: ='Chấm công KT'!D17 -> 03461 | C17: ='Chấm công KT'!C17 -> T. Bi Ly | D17: CN-KT | Q17: =SUM(E17:P17) -> 0 | R17: =VLOOKUP(C17,'BTH mủ tạp'!$C$15:$AI$94,33,0) -> 0 | T17: =S17*50/100 -> 0 | U17: =R17 -> 0 | V17: =VLOOKUP(C17,'Chấm công KT'!$C$11:$AJ$90,34,0) -> 0 | W17: =VLOOKUP(C17,'Chấm công KT'!$C$11:$AK$90,35,0) -> 0 | Z17: =VLOOKUP(C17,'Chấm công KT'!$C$11:$AN$90,38,0) -> 0 | AA17: =VLOOKUP(C17,'Chấm công KT'!$C$11:$AO$90,39,0) -> 0 | AC17: =Q17 -> 0 | AD17: =VLOOKUP(C17,'BTH mủ tạp'!$C$15:$AL$305,36,0) -> A
A18: 8 | B18: ='Chấm công KT'!D18 -> 03462 | C18: ='Chấm công KT'!C18 -> T . Bua Ngân | D18: CN-KT | Q18: =SUM(E18:P18) -> 0 | R18: =VLOOKUP(C18,'BTH mủ tạp'!$C$15:$AI$94,33,0) -> 0 | T18: =S18*50/100 -> 0 | U18: =R18 -> 0 | V18: =VLOOKUP(C18,'Chấm công KT'!$C$11:$AJ$90,34,0) -> 0 | W18: =VLOOKUP(C18,'Chấm công KT'!$C$11:$AK$90,35,0) -> 0 | Z18: =VLOOKUP(C18,'Chấm công KT'!$C$11:$AN$90,38,0) -> 0 | AA18: =VLOOKUP(C18,'Chấm công KT'!$C$11:$AO$90,39,0) -> 0 | AC18: =Q18 -> 0 | AD18: =VLOOKUP(C18,'BTH mủ tạp'!$C$15:$AL$305,36,0) -> A | AI18: =1155.43-Q9 -> -12571.15
A19: 9 | B19: ='Chấm công KT'!D19 -> 03463 | C19: ='Chấm công KT'!C19 -> T Căng | D19: CN-KT | Q19: =SUM(E19:P19) -> 0 | R19: =VLOOKUP(C19,'BTH mủ tạp'!$C$15:$AI$94,33,0) -> 0 | T19: =S19*50/100 -> 0 | U19: =R19 -> 0 | V19: =VLOOKUP(C19,'Chấm công KT'!$C$11:$AJ$90,34,0) -> 0 | W19: =VLOOKUP(C19,'Chấm công KT'!$C$11:$AK$90,35,0) -> 0 | Z19: =VLOOKUP(C19,'Chấm công KT'!$C$11:$AN$90,38,0) -> 0 | AA19: =VLOOKUP(C19,'Chấm công KT'!$C$11:$AO$90,39,0) -> 0 | AC19: =Q19 -> 0 | AD19: =VLOOKUP(C19,'BTH mủ tạp'!$C$15:$AL$305,36,0) -> A
A20: 10 | B20: ='Chấm công KT'!D20 -> 03464 | C20: ='Chấm công KT'!C20 -> N. Phôn 1 | D20: CN-KT | Q20: =SUM(E20:P20) -> 0 | R20: =VLOOKUP(C20,'BTH mủ tạp'!$C$15:$AI$94,33,0) -> 0 | T20: =S20*50/100 -> 0 | U20: =R20 -> 0 | V20: =VLOOKUP(C20,'Chấm công KT'!$C$11:$AJ$90,34,0) -> 0 | W20: =VLOOKUP(C20,'Chấm công KT'!$C$11:$AK$90,35,0) -> 0 | Z20: =VLOOKUP(C20,'Chấm công KT'!$C$11:$AN$90,38,0) -> 0 | AA20: =VLOOKUP(C20,'Chấm công KT'!$C$11:$AO$90,39,0) -> 0 | AC20: =Q20 -> 0 | AD20: =VLOOKUP(C20,'BTH mủ tạp'!$C$15:$AL$305,36,0) -> A | AG20: =Q9 -> 13726.58
A21: 11 | B21: ='Chấm công KT'!D21 -> 03465 | C21: ='Chấm công KT'!C21 -> T. In Păn | D21: CN-KT | Q21: =SUM(E21:P21) -> 0 | R21: =VLOOKUP(C21,'BTH mủ tạp'!$C$15:$AI$94,33,0) -> 0 | T21: =S21*50/100 -> 0 | U21: =R21 -> 0 | V21: =VLOOKUP(C21,'Chấm công KT'!$C$11:$AJ$90,34,0) -> 0 | W21: =VLOOKUP(C21,'Chấm công KT'!$C$11:$AK$90,35,0) -> 0 | Z21: =VLOOKUP(C21,'Chấm công KT'!$C$11:$AN$90,38,0) -> 0 | AA21: =VLOOKUP(C21,'Chấm công KT'!$C$11:$AO$90,39,0) -> 0 | AC21: =Q21 -> 0 | AD21: =VLOOKUP(C21,'BTH mủ tạp'!$C$15:$AL$305,36,0) -> B | AG21: =AG20-2544.38 -> 11182.2
A22: 12 | B22: ='Chấm công KT'!D22 -> 03466 | C22: ='Chấm công KT'!C22 -> N. Keo | D22: CN-KT | Q22: =SUM(E22:P22) -> 0 | R22: =VLOOKUP(C22,'BTH mủ tạp'!$C$15:$AI$94,33,0) -> 0 | T22: =S22*50/100 -> 0 | U22: =R22 -> 0 | V22: =VLOOKUP(C22,'Chấm công KT'!$C$11:$AJ$90,34,0) -> 0 | W22: =VLOOKUP(C22,'Chấm công KT'!$C$11:$AK$90,35,0) -> 0 | Z22: =VLOOKUP(C22,'Chấm công KT'!$C$11:$AN$90,38,0) -> 0 | AA22: =VLOOKUP(C22,'Chấm công KT'!$C$11:$AO$90,39,0) -> 0 | AC22: =Q22 -> 0 | AD22: =VLOOKUP(C22,'BTH mủ tạp'!$C$15:$AL$305,36,0) -> A | AG22: =AG21-6.33 -> 11175.87
A23: 13 | B23: ='Chấm công KT'!D23 -> 02727 | C23: ='Chấm công KT'!C23 -> T. Thong Đon | D23: CN-KT | Q23: =SUM(E23:P23) -> 0 | R23: =VLOOKUP(C23,'BTH mủ tạp'!$C$15:$AI$94,33,0) -> 0 | T23: =S23*50/100 -> 0 | U23: =R23 -> 0 | V23: =VLOOKUP(C23,'Chấm công KT'!$C$11:$AJ$90,34,0) -> 0 | W23: =VLOOKUP(C23,'Chấm công KT'!$C$11:$AK$90,35,0) -> 0 | Z23: =VLOOKUP(C23,'Chấm công KT'!$C$11:$AN$90,38,0) -> 0 | AA23: =VLOOKUP(C23,'Chấm công KT'!$C$11:$AO$90,39,0) -> 0 | AC23: =Q23 -> 0 | AD23: =VLOOKUP(C23,'BTH mủ tạp'!$C$15:$AL$305,36,0) -> B
A24: 14 | B24: ='Chấm công KT'!D24 -> 03467 | C24: ='Chấm công KT'!C24 -> T. Hin | D24: CN-KT | Q24: =SUM(E24:P24) -> 0 | R24: =VLOOKUP(C24,'BTH mủ tạp'!$C$15:$AI$94,33,0) -> 0 | T24: =S24*50/100 -> 0 | U24: =R24 -> 0 | V24: =VLOOKUP(C24,'Chấm công KT'!$C$11:$AJ$90,34,0) -> 0 | W24: =VLOOKUP(C24,'Chấm công KT'!$C$11:$AK$90,35,0) -> 0 | Z24: =VLOOKUP(C24,'Chấm công KT'!$C$11:$AN$90,38,0) -> 0 | AA24: =VLOOKUP(C24,'Chấm công KT'!$C$11:$AO$90,39,0) -> 0 | AC24: =Q24 -> 0 | AD24: =VLOOKUP(C24,'BTH mủ tạp'!$C$15:$AL$305,36,0) -> A
A25: 15 | B25: ='Chấm công KT'!D25 -> 03468 | C25: ='Chấm công KT'!C25 -> T. Son | D25: CN-KT | Q25: =SUM(E25:P25) -> 0 | R25: =VLOOKUP(C25,'BTH mủ tạp'!$C$15:$AI$94,33,0) -> 0 | T25: =S25*50/100 -> 0 | U25: =R25 -> 0 | V25: =VLOOKUP(C25,'Chấm công KT'!$C$11:$AJ$90,34,0) -> 0 | W25: =VLOOKUP(C25,'Chấm công KT'!$C$11:$AK$90,35,0) -> 0 | Z25: =VLOOKUP(C25,'Chấm công KT'!$C$11:$AN$90,38,0) -> 0 | AA25: =VLOOKUP(C25,'Chấm công KT'!$C$11:$AO$90,39,0) -> 0 | AC25: =Q25 -> 0 | AD25: =VLOOKUP(C25,'BTH mủ tạp'!$C$15:$AL$305,36,0) -> A
A26: 16 | B26: ='Chấm công KT'!D26 -> 03469 | C26: ='Chấm công KT'!C26 -> T. Xôm Va Nít | D26: CN-KT | Q26: =SUM(E26:P26) -> 0 | R26: =VLOOKUP(C26,'BTH mủ tạp'!$C$15:$AI$94,33,0) -> 0 | T26: =S26*50/100 -> 0 | U26: =R26 -> 0 | V26: =VLOOKUP(C26,'Chấm công KT'!$C$11:$AJ$90,34,0) -> 0 | W26: =VLOOKUP(C26,'Chấm công KT'!$C$11:$AK$90,35,0) -> 0 | Z26: =VLOOKUP(C26,'Chấm công KT'!$C$11:$AN$90,38,0) -> 0 | AA26: =VLOOKUP(C26,'Chấm công KT'!$C$11:$AO$90,39,0) -> 0 | AC26: =Q26 -> 0 | AD26: =VLOOKUP(C26,'BTH mủ tạp'!$C$15:$AL$305,36,0) -> A
A27: 17 | B27: ='Chấm công KT'!D27 -> 03470 | C27: ='Chấm công KT'!C27 -> T. Lọi | D27: CN-KT | Q27: =SUM(E27:P27) -> 0 | R27: =VLOOKUP(C27,'BTH mủ tạp'!$C$15:$AI$94,33,0) -> 0 | T27: =S27*50/100 -> 0 | U27: =R27 -> 0 | V27: =VLOOKUP(C27,'Chấm công KT'!$C$11:$AJ$90,34,0) -> 0 | W27: =VLOOKUP(C27,'Chấm công KT'!$C$11:$AK$90,35,0) -> 0 | Z27: =VLOOKUP(C27,'Chấm công KT'!$C$11:$AN$90,38,0) -> 0 | AA27: =VLOOKUP(C27,'Chấm công KT'!$C$11:$AO$90,39,0) -> 0 | AC27: =Q27 -> 0 | AD27: =VLOOKUP(C27,'BTH mủ tạp'!$C$15:$AL$305,36,0) -> A
A28: 18 | B28: ='Chấm công KT'!D28 -> 03471 | C28: ='Chấm công KT'!C28 -> T. Phô Thong | D28: CN-KT | Q28: =SUM(E28:P28) -> 0 | R28: =VLOOKUP(C28,'BTH mủ tạp'!$C$15:$AI$94,33,0) -> 0 | T28: =S28*50/100 -> 0 | U28: =R28 -> 0 | V28: =VLOOKUP(C28,'Chấm công KT'!$C$11:$AJ$90,34,0) -> 0 | W28: =VLOOKUP(C28,'Chấm công KT'!$C$11:$AK$90,35,0) -> 0 | Z28: =VLOOKUP(C28,'Chấm công KT'!$C$11:$AN$90,38,0) -> 0 | AA28: =VLOOKUP(C28,'Chấm công KT'!$C$11:$AO$90,39,0) -> 0 | AC28: =Q28 -> 0 | AD28: =VLOOKUP(C28,'BTH mủ tạp'!$C$15:$AL$305,36,0) -> A | AF28: =Q9-10084 -> 3642.58
A29: 19 | B29: ='Chấm công KT'!D29 -> 03472 | C29: ='Chấm công KT'!C29 -> N. Soi | D29: CN-KT | Q29: =SUM(E29:P29) -> 0 | R29: =VLOOKUP(C29,'BTH mủ tạp'!$C$15:$AI$94,33,0) -> 0 | T29: =S29*50/100 -> 0 | U29: =R29 -> 0 | V29: =VLOOKUP(C29,'Chấm công KT'!$C$11:$AJ$90,34,0) -> 0 | W29: =VLOOKUP(C29,'Chấm công KT'!$C$11:$AK$90,35,0) -> 0 | Z29: =VLOOKUP(C29,'Chấm công KT'!$C$11:$AN$90,38,0) -> 0 | AA29: =VLOOKUP(C29,'Chấm công KT'!$C$11:$AO$90,39,0) -> 0 | AC29: =Q29 -> 0 | AD29: =VLOOKUP(C29,'BTH mủ tạp'!$C$15:$AL$305,36,0) -> A
A30: 20 | B30: ='Chấm công KT'!D30 -> 03473 | C30: ='Chấm công KT'!C30 -> N. Me Kha La | D30: CN-KT | Q30: =SUM(E30:P30) -> 0 | R30: =VLOOKUP(C30,'BTH mủ tạp'!$C$15:$AI$94,33,0) -> 0 | T30: =S30*50/100 -> 0 | U30: =R30 -> 0 | V30: =VLOOKUP(C30,'Chấm công KT'!$C$11:$AJ$90,34,0) -> 0 | W30: =VLOOKUP(C30,'Chấm công KT'!$C$11:$AK$90,35,0) -> 0 | Z30: =VLOOKUP(C30,'Chấm công KT'!$C$11:$AN$90,38,0) -> 0 | AA30: =VLOOKUP(C30,'Chấm công KT'!$C$11:$AO$90,39,0) -> 0 | AC30: =Q30 -> 0 | AD30: =VLOOKUP(C30,'BTH mủ tạp'!$C$15:$AL$305,36,0) -> A
A31: 21 | B31: ='Chấm công KT'!D31 -> 03474 | C31: ='Chấm công KT'!C31 -> N. Mon Khăm | D31: CN-KT | Q31: =SUM(E31:P31) -> 0 | R31: =VLOOKUP(C31,'BTH mủ tạp'!$C$15:$AI$94,33,0) -> 0 | T31: =S31*50/100 -> 0 | U31: =R31 -> 0 | V31: =VLOOKUP(C31,'Chấm công KT'!$C$11:$AJ$90,34,0) -> 0 | W31: =VLOOKUP(C31,'Chấm công KT'!$C$11:$AK$90,35,0) -> 0 | Z31: =VLOOKUP(C31,'Chấm công KT'!$C$11:$AN$90,38,0) -> 0 | AA31: =VLOOKUP(C31,'Chấm công KT'!$C$11:$AO$90,39,0) -> 0 | AC31: =Q31 -> 0 | AD31: =VLOOKUP(C31,'BTH mủ tạp'!$C$15:$AL$305,36,0) -> B
A32: 22 | B32: ='Chấm công KT'!D32 -> 03475 | C32: ='Chấm công KT'!C32 -> T. In | D32: CN-KT | Q32: =SUM(E32:P32) -> 0 | R32: =VLOOKUP(C32,'BTH mủ tạp'!$C$15:$AI$94,33,0) -> 0 | T32: =S32*50/100 -> 0 | U32: =R32 -> 0 | V32: =VLOOKUP(C32,'Chấm công KT'!$C$11:$AJ$90,34,0) -> 0 | W32: =VLOOKUP(C32,'Chấm công KT'!$C$11:$AK$90,35,0) -> 0 | Z32: =VLOOKUP(C32,'Chấm công KT'!$C$11:$AN$90,38,0) -> 0 | AA32: =VLOOKUP(C32,'Chấm công KT'!$C$11:$AO$90,39,0) -> 0 | AC32: =Q32 -> 0 | AD32: =VLOOKUP(C32,'BTH mủ tạp'!$C$15:$AL$305,36,0) -> C
A33: 23 | B33: ='Chấm công KT'!D33 -> 03476 | C33: ='Chấm công KT'!C33 -> T. Bin Ly. | D33: CN-KT | Q33: =SUM(E33:P33) -> 0 | R33: =VLOOKUP(C33,'BTH mủ tạp'!$C$15:$AI$94,33,0) -> 0 | T33: =S33*50/100 -> 0 | U33: =R33 -> 0 | V33: =VLOOKUP(C33,'Chấm công KT'!$C$11:$AJ$90,34,0) -> 0 | W33: =VLOOKUP(C33,'Chấm công KT'!$C$11:$AK$90,35,0) -> 0 | Z33: =VLOOKUP(C33,'Chấm công KT'!$C$11:$AN$90,38,0) -> 0 | AA33: =VLOOKUP(C33,'Chấm công KT'!$C$11:$AO$90,39,0) -> 0 | AC33: =Q33 -> 0 | AD33: =VLOOKUP(C33,'BTH mủ tạp'!$C$15:$AL$305,36,0) -> B
A34: 24 | B34: ='Chấm công KT'!D34 -> 03477 | C34: ='Chấm công KT'!C34 -> N. Phim Phon. | D34: CN-KT | Q34: =SUM(E34:P34) -> 0 | R34: =VLOOKUP(C34,'BTH mủ tạp'!$C$15:$AI$94,33,0) -> 0 | T34: =S34*50/100 -> 0 | U34: =R34 -> 0 | V34: =VLOOKUP(C34,'Chấm công KT'!$C$11:$AJ$90,34,0) -> 0 | W34: =VLOOKUP(C34,'Chấm công KT'!$C$11:$AK$90,35,0) -> 0 | Z34: =VLOOKUP(C34,'Chấm công KT'!$C$11:$AN$90,38,0) -> 0 | AA34: =VLOOKUP(C34,'Chấm công KT'!$C$11:$AO$90,39,0) -> 0 | AC34: =Q34 -> 0 | AD34: =VLOOKUP(C34,'BTH mủ tạp'!$C$15:$AL$305,36,0) -> C
A35: 25 | B35: ='Chấm công KT'!D35 -> 03478 | C35: ='Chấm công KT'!C35 -> N. Nong | D35: CN-KT | Q35: =SUM(E35:P35) -> 0 | R35: =VLOOKUP(C35,'BTH mủ tạp'!$C$15:$AI$94,33,0) -> 0 | T35: =S35*50/100 -> 0 | U35: =R35 -> 0 | V35: =VLOOKUP(C35,'Chấm công KT'!$C$11:$AJ$90,34,0) -> 0 | W35: =VLOOKUP(C35,'Chấm công KT'!$C$11:$AK$90,35,0) -> 0 | Z35: =VLOOKUP(C35,'Chấm công KT'!$C$11:$AN$90,38,0) -> 0 | AA35: =VLOOKUP(C35,'Chấm công KT'!$C$11:$AO$90,39,0) -> 0 | AC35: =Q35 -> 0 | AD35: =VLOOKUP(C35,'BTH mủ tạp'!$C$15:$AL$305,36,0) -> A
A36: 26 | B36: ='Chấm công KT'!D36 -> 03479 | C36: ='Chấm công KT'!C36 -> N. Tun 1 | D36: CN-KT | Q36: =SUM(E36:P36) -> 0 | R36: =VLOOKUP(C36,'BTH mủ tạp'!$C$15:$AI$94,33,0) -> 0 | T36: =S36*50/100 -> 0 | U36: =R36 -> 0 | V36: =VLOOKUP(C36,'Chấm công KT'!$C$11:$AJ$90,34,0) -> 0 | W36: =VLOOKUP(C36,'Chấm công KT'!$C$11:$AK$90,35,0) -> 0 | Z36: =VLOOKUP(C36,'Chấm công KT'!$C$11:$AN$90,38,0) -> 0 | AA36: =VLOOKUP(C36,'Chấm công KT'!$C$11:$AO$90,39,0) -> 0 | AC36: =Q36 -> 0 | AD36: =VLOOKUP(C36,'BTH mủ tạp'!$C$15:$AL$305,36,0) -> A
A37: 27 | B37: ='Chấm công KT'!D37 -> 03480 | C37: ='Chấm công KT'!C37 -> T . Lốc | D37: CN-KT | Q37: =SUM(E37:P37) -> 0 | R37: =VLOOKUP(C37,'BTH mủ tạp'!$C$15:$AI$94,33,0) -> 0 | T37: =S37*50/100 -> 0 | U37: =R37 -> 0 | V37: =VLOOKUP(C37,'Chấm công KT'!$C$11:$AJ$90,34,0) -> 0 | W37: =VLOOKUP(C37,'Chấm công KT'!$C$11:$AK$90,35,0) -> 0 | Z37: =VLOOKUP(C37,'Chấm công KT'!$C$11:$AN$90,38,0) -> 0 | AA37: =VLOOKUP(C37,'Chấm công KT'!$C$11:$AO$90,39,0) -> 0 | AC37: =Q37 -> 0 | AD37: =VLOOKUP(C37,'BTH mủ tạp'!$C$15:$AL$305,36,0) -> B
A38: 28 | B38: ='Chấm công KT'!D38 -> 03481 | C38: ='Chấm công KT'!C38 -> N . Khâm (1) | D38: CN-KT | Q38: =SUM(E38:P38) -> 0 | R38: =VLOOKUP(C38,'BTH mủ tạp'!$C$15:$AI$94,33,0) -> 0 | T38: =S38*50/100 -> 0 | U38: =R38 -> 0 | V38: =VLOOKUP(C38,'Chấm công KT'!$C$11:$AJ$90,34,0) -> 0 | W38: =VLOOKUP(C38,'Chấm công KT'!$C$11:$AK$90,35,0) -> 0 | Z38: =VLOOKUP(C38,'Chấm công KT'!$C$11:$AN$90,38,0) -> 0 | AA38: =VLOOKUP(C38,'Chấm công KT'!$C$11:$AO$90,39,0) -> 0 | AC38: =Q38 -> 0 | AD38: =VLOOKUP(C38,'BTH mủ tạp'!$C$15:$AL$305,36,0) -> A
A39: 29 | B39: ='Chấm công KT'!D39 -> 03482 | C39: ='Chấm công KT'!C39 -> T . Phết | D39: CN-KT | Q39: =SUM(E39:P39) -> 0 | R39: =VLOOKUP(C39,'BTH mủ tạp'!$C$15:$AI$94,33,0) -> 0 | T39: =S39*50/100 -> 0 | U39: =R39 -> 0 | V39: =VLOOKUP(C39,'Chấm công KT'!$C$11:$AJ$90,34,0) -> 0 | W39: =VLOOKUP(C39,'Chấm công KT'!$C$11:$AK$90,35,0) -> 0 | Z39: =VLOOKUP(C39,'Chấm công KT'!$C$11:$AN$90,38,0) -> 0 | AA39: =VLOOKUP(C39,'Chấm công KT'!$C$11:$AO$90,39,0) -> 0 | AC39: =Q39 -> 0 | AD39: =VLOOKUP(C39,'BTH mủ tạp'!$C$15:$AL$305,36,0) -> A
A40: 30 | B40: ='Chấm công KT'!D40 -> 03483 | C40: ='Chấm công KT'!C40 -> T. Viêng Sa Văn | D40: CN-KT | Q40: =SUM(E40:P40) -> 0 | R40: =VLOOKUP(C40,'BTH mủ tạp'!$C$15:$AI$94,33,0) -> 0 | T40: =S40*50/100 -> 0 | U40: =R40 -> 0 | V40: =VLOOKUP(C40,'Chấm công KT'!$C$11:$AJ$90,34,0) -> 0 | W40: =VLOOKUP(C40,'Chấm công KT'!$C$11:$AK$90,35,0) -> 0 | Z40: =VLOOKUP(C40,'Chấm công KT'!$C$11:$AN$90,38,0) -> 0 | AA40: =VLOOKUP(C40,'Chấm công KT'!$C$11:$AO$90,39,0) -> 0 | AC40: =Q40 -> 0 | AD40: =VLOOKUP(C40,'BTH mủ tạp'!$C$15:$AL$305,36,0) -> A
... A83: 73 | B83: ='Chấm công KT'!D83 -> 02733 | C83: ='Chấm công KT'!C83 -> N. Phôn | D83: CN-KT | Q83: =SUM(E83:P83) -> 0 | R83: =VLOOKUP(C83,'BTH mủ tạp'!$C$15:$AI$94,33,0) -> 0 | T83: =S83*50/100 -> 0 | U83: =R83 -> 0 | V83: =VLOOKUP(C83,'Chấm công KT'!$C$11:$AJ$90,34,0) -> 0 | W83: =VLOOKUP(C83,'Chấm công KT'!$C$11:$AK$90,35,0) -> 0 | Z83: =VLOOKUP(C83,'Chấm công KT'!$C$11:$AN$90,38,0) -> 0 | AA83: =VLOOKUP(C83,'Chấm công KT'!$C$11:$AO$90,39,0) -> 0 | AC83: =Q83 -> 0 | AD83: =VLOOKUP(C83,'BTH mủ tạp'!$C$15:$AL$305,36,0) -> A
...

Sheet CNKT Đ1
A2: CỘNG HÒA DÂN CHỦ NHÂN DÂN LÀO
A3: Hòa Bình - Độc Lập - Dân Chủ - Thống Nhất - Thịnh Vượng
A4: -----o0o-----
A6: CÔNG TY TNHH CỔ PHẦN QUASA - GERUCO LÀO
A7: ĐƠN VỊ: NÔNG TRƯỜNG 2
A9: BẢNG LƯƠNG KHAI THÁC ĐỘI 1 THÁNG 02 NĂM 2025 | AA9: Mủ tạp | AB9: ='BTH mủ tạp'!$AI$14 -> 0
AA10: mủ QK | AB10: ='BTH mủ tạp'!$AK$14 -> 0
AA11: DRC mủ dây | AB11: 0.5
C12: Tỷ giá Bath qua Kip: | E12: ='CNKT '!E11 -> 656 | Z12: =AB10/AB9 -> #DIV/0! | AA12: DRC mủ serum | AB12: 0.2
A13: STT | B13: Mã số nhân viên | C13: Họ và tên | D13: Kí nhận | E13: LƯƠNG | X13: Tổng lương | Y13: Thuế TNCN | Z13: Tiền lương còn lại
E14: Lương chăm sóc ( đơn giá 25.000 kíp/ công) | J14: Lương sản lượng | M14: Phụ cấp khai thác
E15: Ngày công | F15: Thành tiền | G15: Mủ tạp (kg) | H15: Mủ dây (kg) | I15: Mủ xirum (kg) | J15: Quy khô ( kg) | K15: Hạng kỹ thuật | L15: Thành tiền | M15: Phụ cấp ngày công bình thường | N15: Phụ cấp ngày CN thường | O15: Phụ cấp ngày công đi cạo 2 lát | P15: Phụ cấp ngày công chủ nhật cạo 2 lát | Q15: Phụ cấp ngày công cạo gia tăng 2 miêng | R15: Phụ cấp ngày chủ nhật cạo gia tăng 2 miệng | S15: Phụ cấp nhỏ a xít (20.000 kíp/phần) | T15: Phụ cấp tiền lương (10.000 kíp/phần) | U15: Phụ cấp tiền lương (30.000 kíp/phần) | W15: Thành tiền | AB15: =5.5*E12 -> 3608 | AC15: =265*AB15 -> 956120
A16: 1 | B16: ='Chấm công KT'!D11 -> 03456 | C16: =TONGHOPCONGDOI!C11 -> T. Vôn | X16: =F16+L16+W16 -> 0 | Z16: =VLOOKUP(C16,'CNKT '!C16:Z93,24,0) -> 0 | AA16: =Z16-X16 -> 0
A17: 2 | C17: =TONGHOPCONGDOI!C12 -> T. Feng | X17: =F17+L17+W17 -> 0 | Z17: =VLOOKUP(C17,'CNKT '!C17:Z94,24,0) -> 0 | AA17: =Z17-X17 -> 0
A18: 3 | B18: ='Chấm công KT'!D13 -> 02725 | C18: =TONGHOPCONGDOI!C13 -> T. Sa Văn | X18: =F18+L18+W18 -> 0 | Z18: =VLOOKUP(C18,'CNKT '!C18:Z95,24,0) -> 0 | AA18: =Z18-X18 -> 0
A19: 4 | B19: ='Chấm công KT'!D14 -> 03458 | C19: =TONGHOPCONGDOI!C14 -> N. Pheng Mi | X19: =F19+L19+W19 -> 0 | Z19: =VLOOKUP(C19,'CNKT '!C19:Z96,24,0) -> 0 | AA19: =Z19-X19 -> 0
A20: 5 | B20: ='Chấm công KT'!D15 -> 03459 | C20: =TONGHOPCONGDOI!C15 -> N. Vạt | X20: =F20+L20+W20 -> 0 | Z20: =VLOOKUP(C20,'CNKT '!C20:Z97,24,0) -> 0 | AA20: =Z20-X20 -> 0
A21: 6 | B21: ='Chấm công KT'!D16 -> 03460 | C21: =TONGHOPCONGDOI!C16 -> T. Tích | X21: =F21+L21+W21 -> 0 | Z21: =VLOOKUP(C21,'CNKT '!C21:Z98,24,0) -> 0 | AA21: =Z21-X21 -> 0
A22: 7 | B22: ='Chấm công KT'!D17 -> 03461 | C22: =TONGHOPCONGDOI!C17 -> T. Bi Ly | X22: =F22+L22+W22 -> 0 | Z22: =VLOOKUP(C22,'CNKT '!C22:Z99,24,0) -> 0 | AA22: =Z22-X22 -> 0
A23: 8 | B23: ='Chấm công KT'!D18 -> 03462 | C23: =TONGHOPCONGDOI!C18 -> T . Bua Ngân | X23: =F23+L23+W23 -> 0 | Z23: =VLOOKUP(C23,'CNKT '!C23:Z100,24,0) -> 0 | AA23: =Z23-X23 -> 0
A24: 9 | B24: ='Chấm công KT'!D19 -> 03463 | C24: =TONGHOPCONGDOI!C19 -> T Căng | X24: =F24+L24+W24 -> 0 | Z24: =VLOOKUP(C24,'CNKT '!C24:Z101,24,0) -> 0 | AA24: =Z24-X24 -> 0
A25: 10 | B25: ='Chấm công KT'!D20 -> 03464 | C25: =TONGHOPCONGDOI!C20 -> N. Phôn 1 | X25: =F25+L25+W25 -> 0 | Z25: =VLOOKUP(C25,'CNKT '!C25:Z102,24,0) -> 0 | AA25: =Z25-X25 -> 0
A26: 11 | B26: ='Chấm công KT'!D21 -> 03465 | C26: =TONGHOPCONGDOI!C21 -> T. In Păn | X26: =F26+L26+W26 -> 0 | Z26: =VLOOKUP(C26,'CNKT '!C26:Z103,24,0) -> 0 | AA26: =Z26-X26 -> 0
A27: 12 | B27: ='Chấm công KT'!D22 -> 03466 | C27: =TONGHOPCONGDOI!C22 -> N. Keo | X27: =F27+L27+W27 -> 0 | Z27: =VLOOKUP(C27,'CNKT '!C27:Z104,24,0) -> 0 | AA27: =Z27-X27 -> 0
A28: 13 | B28: ='Chấm công KT'!D23 -> 02727 | C28: =TONGHOPCONGDOI!C23 -> T. Thong Đon | X28: =F28+L28+W28 -> 0 | Z28: =VLOOKUP(C28,'CNKT '!C28:Z105,24,0) -> 0 | AA28: =Z28-X28 -> 0
A29: 14 | B29: ='Chấm công KT'!D24 -> 03467 | C29: =TONGHOPCONGDOI!C24 -> T. Hin | X29: =F29+L29+W29 -> 0 | Z29: =VLOOKUP(C29,'CNKT '!C29:Z106,24,0) -> 0 | AA29: =Z29-X29 -> 0
... A69: 54 | B69: ='Chấm công KT'!D64 -> 03499 | C69: =TONGHOPCONGDOI!C64 -> N. In Ton | X69: =F69+L69+W69 -> 0 | Z69: =VLOOKUP(C69,'CNKT '!C69:Z146,24,0) -> 0 | AA69: =Z69-X69 -> 0
A70: 55 | C70: =TONGHOPCONGDOI!C65 -> N. Khay Chăn | X70: =F70+L70+W70 -> 0 | Z70: =VLOOKUP(C70,'CNKT '!C70:Z147,24,0) -> 0 | AA70: =Z70-X70 -> 0
A71: 56 | B71: ='Chấm công KT'!D66 -> 03501 | C71: =TONGHOPCONGDOI!C66 -> T Dăn | X71: =F71+L71+W71 -> 0 | Z71: =VLOOKUP(C71,'CNKT '!C71:Z148,24,0) -> 0 | AA71: =Z71-X71 -> 0
A72: 57 | B72: ='Chấm công KT'!D67 -> 03502 | C72: =TONGHOPCONGDOI!C67 -> T. Xợt | X72: =F72+L72+W72 -> 0 | Z72: =VLOOKUP(C72,'CNKT '!C72:Z149,24,0) -> 0 | AA72: =Z72-X72 -> 0
A73: 58 | C73: =TONGHOPCONGDOI!C68 -> N. Phết 2 | X73: =F73+L73+W73 -> 0 | Z73: =VLOOKUP(C73,'CNKT '!C73:Z150,24,0) -> 0 | AA73: =Z73-X73 -> 0
A74: 59 | B74: ='Chấm công KT'!D69 -> 03504 | C74: =TONGHOPCONGDOI!C69 -> T. Cạp | X74: =F74+L74+W74 -> 0 | Z74: =VLOOKUP(C74,'CNKT '!C74:Z151,24,0) -> 0 | AA74: =Z74-X74 -> 0
A75: 60 | B75: ='Chấm công KT'!D70 -> 03505 | C75: =TONGHOPCONGDOI!C70 -> N. Phết | X75: =F75+L75+W75 -> 0 | Z75: =VLOOKUP(C75,'CNKT '!C75:Z152,24,0) -> 0 | AA75: =Z75-X75 -> 0
A76: 61 | B76: ='Chấm công KT'!D71 -> 03506 | C76: =TONGHOPCONGDOI!C71 -> N. Bua Hom | X76: =F76+L76+W76 -> 0 | Z76: =VLOOKUP(C76,'CNKT '!C76:Z153,24,0) -> 0 | AA76: =Z76-X76 -> 0
A77: 62 | B77: ='Chấm công KT'!D72 -> 03507 | C77: =TONGHOPCONGDOI!C72 -> N. Không | X77: =F77+L77+W77 -> 0 | Z77: =VLOOKUP(C77,'CNKT '!C77:Z154,24,0) -> 0 | AA77: =Z77-X77 -> 0
A78: 63 | B78: ='Chấm công KT'!D73 -> 03508 | C78: =TONGHOPCONGDOI!C73 -> T. Đèng | X78: =F78+L78+W78 -> 0 | Z78: =VLOOKUP(C78,'CNKT '!C78:Z155,24,0) -> 0 | AA78: =Z78-X78 -> 0
A79: 64 | B79: ='Chấm công KT'!D74 -> 03509 | C79: =TONGHOPCONGDOI!C74 -> T. May | X79: =F79+L79+W79 -> 0 | Z79: =VLOOKUP(C79,'CNKT '!C79:Z156,24,0) -> 0 | AA79: =Z79-X79 -> 0
A80: 65 | C80: =TONGHOPCONGDOI!C75 -> T. La | X80: =F80+L80+W80 -> 0 | Z80: =VLOOKUP(C80,'CNKT '!C80:Z157,24,0) -> 0 | AA80: =Z80-X80 -> 0
A81: 66 | C81: =TONGHOPCONGDOI!C76 -> T. Bờm | X81: =F81+L81+W81 -> 0 | Z81: =VLOOKUP(C81,'CNKT '!C81:Z158,24,0) -> 0 | AA81: =Z81-X81 -> 0
A82: 67 | B82: ='Chấm công KT'!D77 -> 03512 | C82: =TONGHOPCONGDOI!C77 -> N. Đon | X82: =F82+L82+W82 -> 0 | Z82: =VLOOKUP(C82,'CNKT '!C82:Z159,24,0) -> 0 | AA82: =Z82-X82 -> 0
...

Sheet CNKT Đ2
A2: CỘNG HÒA DÂN CHỦ NHÂN DÂN LÀO
A3: Hòa Bình - Độc Lập - Dân Chủ - Thống Nhất - Thịnh Vượng
A4: -----o0o-----
A6: CÔNG TY TNHH CỔ PHẦN QUASA - GERUCO LÀO
A7: ĐƠN VỊ: NÔNG TRƯỜNG 2
A10: BẢNG LƯƠNG KHAI THÁC ĐỘI 2 THÁNG 02 NĂM 2025 | AA10: Mủ tạp | AB10: ='BTH mủ tạp'!$AI$96 -> 0
AA11: mủ QK | AB11: ='BTH mủ tạp'!$AK$96 -> 0
AA12: DRC mủ dây | AB12: 0.5
C13: Tỷ giá Bath qua Kip: | E13: ='CNKT '!E11 -> 656 | X13: DRC thực tế | Z13: =AB11/AB10 -> #DIV/0! | AA13: DRC mủ serum | AB13: 0.2
A14: STT | B14: Mã số nhân viên | C14: Họ và tên | D14: Kí nhận | E14: LƯƠNG | X14: Tổng Tiền lương | Y14: Thuế TNCN | Z14: Tiền lương còn lại
E15: Lương chăm sóc ( đơn giá 25.000 kíp/ công) | G15: Lương sản lượng | M15: Phụ cấp khai thác
E16: Ngày công | F16: Thành tiền | G16: Mủ tạp (kg) | H16: Mủ dây (kg) | I16: Mủ xirum (kg) | J16: Quy khô ( kg) | K16: Hạng kỹ thuật | L16: Thành tiền | M16: Phụ cấp ngày công bình thường | N16: Phụ cấp ngày CN thường | O16: Phụ cấp ngày công đi cạo 2 lát | P16: Phụ cấp ngày công chủ nhật cạo 2 lát | Q16: Phụ cấp ngày công cạo gia tăng 2 miêng | R16: Phụ cấp ngày chủ nhật cạo gia tăng 2 miệng | S16: Phụ cấp nhỏ a xít (20.000 kíp/phần) | T16: Phụ cấp tiền lương (10.000 kíp/phần) | U16: Phụ cấp tiền lương (30.000 kíp/phần) | W16: Thành tiền
A17: 1 | C17: =TONGHOPCONGDOI!C96 -> T. Lê | E17: =VLOOKUP(C17,TONGHOPCONGDOI!C96:Q183,15,0) -> 0 | F17: =E17*25000 -> 0 | G17: =VLOOKUP(C17,TONGHOPCONGDOI!C96:AD183,16,0) -> 0 | H17: =VLOOKUP(C17,TONGHOPCONGDOI!C96:AD183,18,0) -> 0 | J17: =$AB$11/$AB$10*G17+H17*$AB$12+I17*$AB$13 -> #DIV/0! | K17: =VLOOKUP(C17,'BTH mủ tạp'!C97:AL175,36,0) -> A | L17: =ROUND((IF(K17="A",(G17*$Z$13*6.1),IF(K17="B",(G17*$Z$13*5.8),IF(K17="C",(G17*$Z$13*5.5),IF(K17="D",(G17*$Z$13*5.2),0))))*$E$13+(H17*$AB$12*$E$13*6.1)+I17*$E$13*$AB$13*6.1),0) -> #DIV/0! | M17: =VLOOKUP(C17,TONGHOPCONGDOI!$C$96:$AD$183,20,0) -> 0 | N17: =VLOOKUP(C17,TONGHOPCONGDOI!$C$96:$AD$183,21,0) -> 0 | O17: =VLOOKUP(C17,TONGHOPCONGDOI!$C$96:$AD$183,22,0) -> 0 | P17: =VLOOKUP(C17,TONGHOPCONGDOI!$C$96:$AD$183,23,0) -> 0 | Q17: =VLOOKUP(C17,TONGHOPCONGDOI!$C$96:$AD$183,24,0) -> 0 | R17: =VLOOKUP(C17,TONGHOPCONGDOI!$C$96:$AD$183,25,0) -> 0 | T17: =SUM(M17:R17) -> 0 | U17: =SUM(M17:R17) -> 0 | W17: =ROUND(((M17*46.1)+(N17*76.9)+(O17*92.2)+(P17*153.8)+(Q17*92.2)+(R17*153.8))*$E$13+(S17*20000)+(T17*10000)+(U17*30000),0) -> 0 | X17: =F17+L17+W17 -> #DIV/0! | Z17: =VLOOKUP(C17,'CNKT '!$C$101:$Z$182,24,0) -> 0 | AA17: =X17-Z17 -> #DIV/0!
A18: 2 | B18: ='Chấm công KT'!D93 -> 02735 | C18: =TONGHOPCONGDOI!C97 -> Nang On Teng | E18: =VLOOKUP(C18,TONGHOPCONGDOI!C97:Q184,15,0) -> 0 | F18: =E18*25000 -> 0 | G18: =VLOOKUP(C18,TONGHOPCONGDOI!C97:AD184,16,0) -> 0 | H18: =VLOOKUP(C18,TONGHOPCONGDOI!C97:AD184,18,0) -> 0 | J18: =$AB$11/$AB$10*G18+H18*$AB$12+I18*$AB$13 -> #DIV/0! | K18: =VLOOKUP(C18,'BTH mủ tạp'!C98:AL181,36,0) -> A | L18: =ROUND((IF(K18="A",(G18*$Z$13*6.1),IF(K18="B",(G18*$Z$13*5.8),IF(K18="C",(G18*$Z$13*5.5),IF(K18="D",(G18*$Z$13*5.2),0))))*$E$13+(H18*$AB$12*$E$13*6.1)+I18*$E$13*$AB$13*6.1),0) -> #DIV/0! | M18: =VLOOKUP(C18,TONGHOPCONGDOI!$C$96:$AD$183,20,0) -> 0 | N18: =VLOOKUP(C18,TONGHOPCONGDOI!$C$96:$AD$183,21,0) -> 0 | O18: =VLOOKUP(C18,TONGHOPCONGDOI!$C$96:$AD$183,22,0) -> 0 | P18: =VLOOKUP(C18,TONGHOPCONGDOI!$C$96:$AD$183,23,0) -> 0 | Q18: =VLOOKUP(C18,TONGHOPCONGDOI!$C$96:$AD$183,24,0) -> 0 | R18: =VLOOKUP(C18,TONGHOPCONGDOI!$C$96:$AD$183,25,0) -> 0 | T18: =SUM(M18:R18) -> 0 | U18: =SUM(M18:R18) -> 0 | W18: =ROUND(((M18*46.1)+(N18*76.9)+(O18*92.2)+(P18*153.8)+(Q18*92.2)+(R18*153.8))*$E$13+(S18*20000)+(T18*10000)+(U18*30000),0) -> 0 | X18: =F18+L18+W18 -> #DIV/0! | Z18: =VLOOKUP(C18,'CNKT '!$C$101:$Z$182,24,0) -> 0 | AA18: =X18-Z18 -> #DIV/0!
A19: 3 | B19: ='Chấm công KT'!D94 -> 03518 | C19: =TONGHOPCONGDOI!C98 -> T. Đôn Ma | E19: =VLOOKUP(C19,TONGHOPCONGDOI!C98:Q185,15,0) -> 0 | F19: =E19*25000 -> 0 | G19: =VLOOKUP(C19,TONGHOPCONGDOI!C98:AD185,16,0) -> 0 | H19: =VLOOKUP(C19,TONGHOPCONGDOI!C98:AD185,18,0) -> 0 | J19: =$AB$11/$AB$10*G19+H19*$AB$12+I19*$AB$13 -> #DIV/0! | K19: =VLOOKUP(C19,'BTH mủ tạp'!C99:AL182,36,0) -> A | L19: =ROUND((IF(K19="A",(G19*$Z$13*6.1),IF(K19="B",(G19*$Z$13*5.8),IF(K19="C",(G19*$Z$13*5.5),IF(K19="D",(G19*$Z$13*5.2),0))))*$E$13+(H19*$AB$12*$E$13*6.1)+I19*$E$13*$AB$13*6.1),0) -> #DIV/0! | M19: =VLOOKUP(C19,TONGHOPCONGDOI!$C$96:$AD$183,20,0) -> 0 | N19: =VLOOKUP(C19,TONGHOPCONGDOI!$C$96:$AD$183,21,0) -> 0 | O19: =VLOOKUP(C19,TONGHOPCONGDOI!$C$96:$AD$183,22,0) -> 0 | P19: =VLOOKUP(C19,TONGHOPCONGDOI!$C$96:$AD$183,23,0) -> 0 | Q19: =VLOOKUP(C19,TONGHOPCONGDOI!$C$96:$AD$183,24,0) -> 0 | R19: =VLOOKUP(C19,TONGHOPCONGDOI!$C$96:$AD$183,25,0) -> 0 | T19: =SUM(M19:R19) -> 0 | U19: =SUM(M19:R19) -> 0 | W19: =ROUND(((M19*46.1)+(N19*76.9)+(O19*92.2)+(P19*153.8)+(Q19*92.2)+(R19*153.8))*$E$13+(S19*20000)+(T19*10000)+(U19*30000),0) -> 0 | X19: =F19+L19+W19 -> #DIV/0! | Z19: =VLOOKUP(C19,'CNKT '!$C$101:$Z$182,24,0) -> 0 | AA19: =X19-Z19 -> #DIV/0!
A20: 4 | B20: ='Chấm công KT'!D95 -> 03519 | C20: =TONGHOPCONGDOI!C99 -> T Nôn | E20: =VLOOKUP(C20,TONGHOPCONGDOI!C99:Q186,15,0) -> 0 | F20: =E20*25000 -> 0 | G20: =VLOOKUP(C20,TONGHOPCONGDOI!C99:AD186,16,0) -> 0 | H20: =VLOOKUP(C20,TONGHOPCONGDOI!C99:AD186,18,0) -> 0 | J20: =$AB$11/$AB$10*G20+H20*$AB$12+I20*$AB$13 -> #DIV/0! | K20: =VLOOKUP(C20,'BTH mủ tạp'!C100:AL183,36,0) -> A | L20: =ROUND((IF(K20="A",(G20*$Z$13*6.1),IF(K20="B",(G20*$Z$13*5.8),IF(K20="C",(G20*$Z$13*5.5),IF(K20="D",(G20*$Z$13*5.2),0))))*$E$13+(H20*$AB$12*$E$13*6.1)+I20*$E$13*$AB$13*6.1),0) -> #DIV/0! | M20: =VLOOKUP(C20,TONGHOPCONGDOI!$C$96:$AD$183,20,0) -> 0 | N20: =VLOOKUP(C20,TONGHOPCONGDOI!$C$96:$AD$183,21,0) -> 0 | O20: =VLOOKUP(C20,TONGHOPCONGDOI!$C$96:$AD$183,22,0) -> 0 | P20: =VLOOKUP(C20,TONGHOPCONGDOI!$C$96:$AD$183,23,0) -> 0 | Q20: =VLOOKUP(C20,TONGHOPCONGDOI!$C$96:$AD$183,24,0) -> 0 | R20: =VLOOKUP(C20,TONGHOPCONGDOI!$C$96:$AD$183,25,0) -> 0 | T20: =SUM(M20:R20) -> 0 | U20: =SUM(M20:R20) -> 0 | W20: =ROUND(((M20*46.1)+(N20*76.9)+(O20*92.2)+(P20*153.8)+(Q20*92.2)+(R20*153.8))*$E$13+(S20*20000)+(T20*10000)+(U20*30000),0) -> 0 | X20: =F20+L20+W20 -> #DIV/0! | Z20: =VLOOKUP(C20,'CNKT '!$C$101:$Z$182,24,0) -> 0 | AA20: =X20-Z20 -> #DIV/0!
A21: 5 | B21: ='Chấm công KT'!D96 -> 03520 | C21: =TONGHOPCONGDOI!C100 -> N. Khăm.. | E21: =VLOOKUP(C21,TONGHOPCONGDOI!C100:Q187,15,0) -> 0 | F21: =E21*25000 -> 0 | G21: =VLOOKUP(C21,TONGHOPCONGDOI!C100:AD187,16,0) -> 0 | H21: =VLOOKUP(C21,TONGHOPCONGDOI!C100:AD187,18,0) -> 0 | J21: =$AB$11/$AB$10*G21+H21*$AB$12+I21*$AB$13 -> #DIV/0! | K21: =VLOOKUP(C21,'BTH mủ tạp'!C101:AL184,36,0) -> A | L21: =ROUND((IF(K21="A",(G21*$Z$13*6.1),IF(K21="B",(G21*$Z$13*5.8),IF(K21="C",(G21*$Z$13*5.5),IF(K21="D",(G21*$Z$13*5.2),0))))*$E$13+(H21*$AB$12*$E$13*6.1)+I21*$E$13*$AB$13*6.1),0) -> #DIV/0! | M21: =VLOOKUP(C21,TONGHOPCONGDOI!$C$96:$AD$183,20,0) -> 0 | N21: =VLOOKUP(C21,TONGHOPCONGDOI!$C$96:$AD$183,21,0) -> 0 | O21: =VLOOKUP(C21,TONGHOPCONGDOI!$C$96:$AD$183,22,0) -> 0 | P21: =VLOOKUP(C21,TONGHOPCONGDOI!$C$96:$AD$183,23,0) -> 0 | Q21: =VLOOKUP(C21,TONGHOPCONGDOI!$C$96:$AD$183,24,0) -> 0 | R21: =VLOOKUP(C21,TONGHOPCONGDOI!$C$96:$AD$183,25,0) -> 0 | T21: =SUM(M21:R21) -> 0 | U21: =SUM(M21:R21) -> 0 | W21: =ROUND(((M21*46.1)+(N21*76.9)+(O21*92.2)+(P21*153.8)+(Q21*92.2)+(R21*153.8))*$E$13+(S21*20000)+(T21*10000)+(U21*30000),0) -> 0 | X21: =F21+L21+W21 -> #DIV/0! | Z21: =VLOOKUP(C21,'CNKT '!$C$101:$Z$182,24,0) -> 0 | AA21: =X21-Z21 -> #DIV/0!
A22: 6 | B22: ='Chấm công KT'!D97 -> 03521 | C22: =TONGHOPCONGDOI!C101 -> Nang La Ty | E22: =VLOOKUP(C22,TONGHOPCONGDOI!C101:Q188,15,0) -> 0 | F22: =E22*25000 -> 0 | G22: =VLOOKUP(C22,TONGHOPCONGDOI!C101:AD188,16,0) -> 0 | H22: =VLOOKUP(C22,TONGHOPCONGDOI!C101:AD188,18,0) -> 0 | J22: =$AB$11/$AB$10*G22+H22*$AB$12+I22*$AB$13 -> #DIV/0! | K22: =VLOOKUP(C22,'BTH mủ tạp'!C102:AL185,36,0) -> A | L22: =ROUND((IF(K22="A",(G22*$Z$13*6.1),IF(K22="B",(G22*$Z$13*5.8),IF(K22="C",(G22*$Z$13*5.5),IF(K22="D",(G22*$Z$13*5.2),0))))*$E$13+(H22*$AB$12*$E$13*6.1)+I22*$E$13*$AB$13*6.1),0) -> #DIV/0! | M22: =VLOOKUP(C22,TONGHOPCONGDOI!$C$96:$AD$183,20,0) -> 0 | N22: =VLOOKUP(C22,TONGHOPCONGDOI!$C$96:$AD$183,21,0) -> 0 | O22: =VLOOKUP(C22,TONGHOPCONGDOI!$C$96:$AD$183,22,0) -> 0 | P22: =VLOOKUP(C22,TONGHOPCONGDOI!$C$96:$AD$183,23,0) -> 0 | Q22: =VLOOKUP(C22,TONGHOPCONGDOI!$C$96:$AD$183,24,0) -> 0 | R22: =VLOOKUP(C22,TONGHOPCONGDOI!$C$96:$AD$183,25,0) -> 0 | T22: =SUM(M22:R22) -> 0 | U22: =SUM(M22:R22) -> 0 | W22: =ROUND(((M22*46.1)+(N22*76.9)+(O22*92.2)+(P22*153.8)+(Q22*92.2)+(R22*153.8))*$E$13+(S22*20000)+(T22*10000)+(U22*30000),0) -> 0 | X22: =F22+L22+W22 -> #DIV/0! | Z22: =VLOOKUP(C22,'CNKT '!$C$101:$Z$182,24,0) -> 0 | AA22: =X22-Z22 -> #DIV/0!
A23: 7 | B23: ='Chấm công KT'!D98 -> 03522 | C23: =TONGHOPCONGDOI!C102 -> N.T.T Trang (1) | E23: =VLOOKUP(C23,TONGHOPCONGDOI!C102:Q189,15,0) -> 0 | F23: =E23*25000 -> 0 | G23: =VLOOKUP(C23,TONGHOPCONGDOI!C102:AD189,16,0) -> 0 | H23: =VLOOKUP(C23,TONGHOPCONGDOI!C102:AD189,18,0) -> 0 | J23: =$AB$11/$AB$10*G23+H23*$AB$12+I23*$AB$13 -> #DIV/0! | K23: =VLOOKUP(C23,'BTH mủ tạp'!C103:AL186,36,0) -> A | L23: =ROUND((IF(K23="A",(G23*$Z$13*6.1),IF(K23="B",(G23*$Z$13*5.8),IF(K23="C",(G23*$Z$13*5.5),IF(K23="D",(G23*$Z$13*5.2),0))))*$E$13+(H23*$AB$12*$E$13*6.1)+I23*$E$13*$AB$13*6.1),0) -> #DIV/0! | M23: =VLOOKUP(C23,TONGHOPCONGDOI!$C$96:$AD$183,20,0) -> 0 | N23: =VLOOKUP(C23,TONGHOPCONGDOI!$C$96:$AD$183,21,0) -> 0 | O23: =VLOOKUP(C23,TONGHOPCONGDOI!$C$96:$AD$183,22,0) -> 0 | P23: =VLOOKUP(C23,TONGHOPCONGDOI!$C$96:$AD$183,23,0) -> 0 | Q23: =VLOOKUP(C23,TONGHOPCONGDOI!$C$96:$AD$183,24,0) -> 0 | R23: =VLOOKUP(C23,TONGHOPCONGDOI!$C$96:$AD$183,25,0) -> 0 | T23: =SUM(M23:R23) -> 0 | U23: =SUM(M23:R23) -> 0 | W23: =ROUND(((M23*46.1)+(N23*76.9)+(O23*92.2)+(P23*153.8)+(Q23*92.2)+(R23*153.8))*$E$13+(S23*20000)+(T23*10000)+(U23*30000),0) -> 0 | X23: =F23+L23+W23 -> #DIV/0! | Z23: =VLOOKUP(C23,'CNKT '!$C$101:$Z$182,24,0) -> 0 | AA23: =X23-Z23 -> #DIV/0!
