Workbook

Sheet Chấm công KT
B1: CỘNG HÒA DÂN CHỦ NHÂN DÂN LÀO
B2: Hòa Bình -Độc Lập - Dân Chủ - thống Nhất - Thịnh Vượng
B3: -----o0o-----
B5: CÔNG TY TNHH MTV QUASA - GERUCO LÀO
B6: ĐỘI SẢN XUẤT SỐ 04
B7: BẢNG CHẤM CÔNG PHỤ CẤP CHO CÔNG NHÂN KHAI THÁC THÁNG 06 NĂM 2025
A8: (Từ ngày 01/06 đến 30/06/2025)
A10: STT | C10: MSNV | D10: HỌ VÀ TÊN | E10: Kí tên | F10: Phụ cấp ngày cạo, ngày chủ nhật | AK10: Ngày công đi cạo thường | AL10: Ngày CN thường | AM10: Ngày công đi cạo 2 lát (đ) | AN10: Ngày công chủ nhật cạo 2 lát (đc) | AO10: Ngày công cạo gia tăng 2 miêng (gt) | AP10: Ngày chủ nhật cạo gia tăng 2 miệng (ct) | AQ10: Tổng công | AU10: Ngày công đi cạo thường (x) | AV10: Ngày CN thường (cn) | AW10: Ngày công đi cạo 2 lát (đ) | AX10: Ngày công chủ nhật cạo 2 lát (đc) | AY10: Ngày công cạo gia tăng 2 miêng (gt) | AZ10: Ngày chủ nhật cạo gia tăng 2 miệng (ct)
F11: 1 | G11: 2 | H11: 3 | I11: 4 | J11: 5 | K11: 6 | L11: 7 | M11: 8 | N11: 9 | O11: 10 | P11: 11 | Q11: 12 | R11: 13 | S11: 14 | T11: 15 | U11: 16 | V11: 17 | W11: 18 | X11: 19 | Y11: 20 | Z11: 21 | AA11: 22 | AB11: 23 | AC11: 24 | AD11: 25 | AE11: 26 | AF11: 27 | AG11: 28 | AH11: 29 | AI11: 30 | AJ11: 31
A12: Trạm 1 | F12: =SUM(COUNTIF(F13:F93,"x"))+(COUNTIF(F13:F93,"cn"))+(COUNTIF(F13:F93,"gt"))+(COUNTIF(F13:F93,"ct")) -> 73 | G12: =SUM(COUNTIF(G13:G93,"x"))+(COUNTIF(G13:G93,"cn"))+(COUNTIF(G13:G93,"gt"))+(COUNTIF(G13:G93,"ct")) -> 73 | H12: =SUM(COUNTIF(H13:H93,"x"))+(COUNTIF(H13:H93,"cn"))+(COUNTIF(H13:H93,"gt"))+(COUNTIF(H13:H93,"ct")) -> 73 | I12: =SUM(COUNTIF(I13:I93,"x"))+(COUNTIF(I13:I93,"cn"))+(COUNTIF(I13:I93,"gt"))+(COUNTIF(I13:I93,"ct")) -> 73 | J12: =SUM(COUNTIF(J13:J93,"x"))+(COUNTIF(J13:J93,"cn"))+(COUNTIF(J13:J93,"gt"))+(COUNTIF(J13:J93,"ct")) -> 73 | K12: =SUM(COUNTIF(K13:K93,"x"))+(COUNTIF(K13:K93,"cn"))+(COUNTIF(K13:K93,"gt"))+(COUNTIF(K13:K93,"ct")) -> 73 | L12: =SUM(COUNTIF(L13:L93,"x"))+(COUNTIF(L13:L93,"cn"))+(COUNTIF(L13:L93,"gt"))+(COUNTIF(L13:L93,"ct")) -> 73 | M12: =SUM(COUNTIF(M13:M93,"x"))+(COUNTIF(M13:M93,"cn"))+(COUNTIF(M13:M93,"gt"))+(COUNTIF(M13:M93,"ct")) -> 73 | ... AI12: =SUM(COUNTIF(AI13:AI93,"x"))+(COUNTIF(AI13:AI93,"cn"))+(COUNTIF(AI13:AI93,"gt"))+(COUNTIF(AI13:AI93,"ct")) -> 70 | AJ12: =SUM(COUNTIF(AJ13:AJ92,"x"))+(COUNTIF(AJ13:AJ92,"cn"))+(COUNTIF(AJ13:AJ92,"đ")) -> 0 | AK12: =SUM(AK13:AK93) -> 1623 | AL12: =SUM(AL13:AL93) -> 357 | AM12: =SUM(AM13:AM93) -> 0 | AN12: =SUM(AN13:AN93) -> 0 | AO12: =SUM(AO13:AO93) -> 0 | AP12: =SUM(AP13:AP93) -> 0 | AQ12: =SUM(AQ13:AQ93) -> 1980 | AS12: ='Mã số nhân viên'!I3 -> 03456 | AT12: =C13-AS12 -> 0
A13: 1 | B13: 1 | C13: =VLOOKUP(D13,'Mã số nhân viên'!B3:I134,8,0) -> 03456 | D13: T. Vôn | F13: cn | G13: x | H13: x | I13: x | J13: x | K13: x | L13: x | M13: cn | N13: x | O13: x | P13: x | U13: x | V13: x | W13: x | X13: tt | Y13: tt | Z13: tt | AA13: tt | AB13: tt | AC13: tt | AD13: tt | AE13: tt | AF13: tt | AG13: tt | AH13: tt | AI13: tt | AK13: =SUM(COUNTIF(F13:AJ13,"x")) -> 12 | AL13: =SUM(COUNTIF(F13:AJ13,"cn")) -> 2 | AM13: =SUM(COUNTIF(F13:AJ13,"đ")) -> 0 | AN13: =SUM(COUNTIF(F13:AJ13,"đc")) -> 0 | AO13: =SUM(COUNTIF(F13:AJ13,"gt")) -> 0 | AP13: =SUM(COUNTIF(F13:AJ13,"ct")) -> 0 | AQ13: =AK13+AL13+AM13+AN13+AO13+AP13 -> 14 | AS13: ='Mã số nhân viên'!I4 -> 04052 | AT13: =C14-AS13 -> 0
A14: 2 | B14: 2 | C14: =VLOOKUP(D14,'Mã số nhân viên'!B4:I135,8,0) -> 04052 | D14: T. Feng | F14: cn | G14: x | H14: x | I14: x | J14: x | K14: x | L14: x | M14: cn | N14: x | O14: x | P14: x | S14: x | T14: cn | U14: x | V14: x | W14: x | X14: x | Y14: x | Z14: x | AA14: cn | AB14: x | AC14: x | AE14: x | AF14: tt | AG14: x | AH14: tt | AI14: x | AK14: =SUM(COUNTIF(F14:AJ14,"x")) -> 21 | AL14: =SUM(COUNTIF(F14:AJ14,"cn")) -> 4 | AM14: =SUM(COUNTIF(F14:AJ14,"đ")) -> 0 | AN14: =SUM(COUNTIF(F14:AJ14,"đc")) -> 0 | AO14: =SUM(COUNTIF(F14:AJ14,"gt")) -> 0 | AP14: =SUM(COUNTIF(F14:AJ14,"ct")) -> 0 | AQ14: =AK14+AL14+AM14+AN14+AO14+AP14 -> 25 | AS14: ='Mã số nhân viên'!I5 -> 02725 | AT14: =C15-AS14 -> 0
A15: 3 | B15: 3 | C15: =VLOOKUP(D15,'Mã số nhân viên'!B5:I136,8,0) -> 02725 | D15: T. Sa Văn | F15: cn | G15: x | H15: x | I15: x | J15: x | K15: x | L15: x | M15: cn | N15: x | O15: x | P15: x | R15: x | S15: x | T15: cn | U15: tt | V15: tt | W15: tt | Y15: tt | Z15: x | AA15: cn | AB15: x | AC15: x | AD15: x | AE15: x | AF15: x | AG15: x | AH15: cn | AI15: x | AK15: =SUM(COUNTIF(F15:AJ15,"x")) -> 19 | AL15: =SUM(COUNTIF(F15:AJ15,"cn")) -> 5 | AM15: =SUM(COUNTIF(F15:AJ15,"đ")) -> 0 | AN15: =SUM(COUNTIF(F15:AJ15,"đc")) -> 0 | AO15: =SUM(COUNTIF(F15:AJ15,"gt")) -> 0 | AP15: =SUM(COUNTIF(F15:AJ15,"ct")) -> 0 | AQ15: =AK15+AL15+AM15+AN15+AO15+AP15 -> 24 | AS15: ='Mã số nhân viên'!I6 -> 04053 | AT15: =C16-AS15 -> 0
A16: 4 | B16: 4 | C16: =VLOOKUP(D16,'Mã số nhân viên'!B6:I137,8,0) -> 04053 | D16: Lăm Ma Thu | F16: cn | G16: x | H16: x | I16: x | J16: x | K16: x | L16: x | M16: cn | N16: x | O16: x | P16: x | S16: x | T16: cn | U16: tt | V16: tt | W16: x | X16: x | Y16: x | Z16: x | AA16: cn | AC16: x | AD16: x | AE16: x | AF16: x | AG16: x | AH16: cn | AI16: x | AK16: =SUM(COUNTIF(F16:AJ16,"x")) -> 20 | AL16: =SUM(COUNTIF(F16:AJ16,"cn")) -> 5 | AM16: =SUM(COUNTIF(F16:AJ16,"đ")) -> 0 | AN16: =SUM(COUNTIF(F16:AJ16,"đc")) -> 0 | AO16: =SUM(COUNTIF(F16:AJ16,"gt")) -> 0 | AP16: =SUM(COUNTIF(F16:AJ16,"ct")) -> 0 | AQ16: =AK16+AL16+AM16+AN16+AO16+AP16 -> 25 | AS16: ='Mã số nhân viên'!I7 -> 03459 | AT16: =C17-AS16 -> 0
A17: 5 | B17: 5 | C17: =VLOOKUP(D17,'Mã số nhân viên'!B7:I138,8,0) -> 03459 | D17: N. Vạt | F17: cn | G17: x | H17: x | I17: x | J17: x | K17: x | L17: x | M17: cn | N17: tt | O17: tt | S17: tt | T17: tt | U17: x | V17: x | W17: x | X17: x | Y17: x | Z17: x | AA17: cn | AB17: x | AC17: x | AD17: x | AE17: x | AF17: x | AG17: x | AH17: cn | AI17: x | AK17: =SUM(COUNTIF(F17:AJ17,"x")) -> 19 | AL17: =SUM(COUNTIF(F17:AJ17,"cn")) -> 4 | AM17: =SUM(COUNTIF(F17:AJ17,"đ")) -> 0 | AN17: =SUM(COUNTIF(F17:AJ17,"đc")) -> 0 | AO17: =SUM(COUNTIF(F17:AJ17,"gt")) -> 0 | AP17: =SUM(COUNTIF(F17:AJ17,"ct")) -> 0 | AQ17: =AK17+AL17+AM17+AN17+AO17+AP17 -> 23 | AS17: ='Mã số nhân viên'!I8 -> 04054 | AT17: =C18-AS17 -> 0
A18: 6 | B18: 6 | C18: =VLOOKUP(D18,'Mã số nhân viên'!B8:I139,8,0) -> 04054 | D18: N. Kay Son | F18: cn | G18: x | H18: x | I18: x | J18: x | K18: x | L18: x | M18: cn | N18: x | O18: x | P18: x | U18: tt | V18: tt | W18: x | X18: x | Y18: x | Z18: x | AA18: cn | AB18: x | AC18: x | AD18: x | AE18: x | AF18: x | AG18: x | AH18: cn | AI18: x | AK18: =SUM(COUNTIF(F18:AJ18,"x")) -> 20 | AL18: =SUM(COUNTIF(F18:AJ18,"cn")) -> 4 | AM18: =SUM(COUNTIF(F18:AJ18,"đ")) -> 0 | AN18: =SUM(COUNTIF(F18:AJ18,"đc")) -> 0 | AO18: =SUM(COUNTIF(F18:AJ18,"gt")) -> 0 | AP18: =SUM(COUNTIF(F18:AJ18,"ct")) -> 0 | AQ18: =AK18+AL18+AM18+AN18+AO18+AP18 -> 24 | AS18: ='Mã số nhân viên'!I9 -> 04055 | AT18: =C19-AS18 -> 0
A19: 7 | B19: 7 | C19: =VLOOKUP(D19,'Mã số nhân viên'!B9:I140,8,0) -> 04055 | D19: T. Đèng 1 | F19: cn | G19: x | H19: x | I19: x | J19: x | K19: x | L19: x | M19: cn | N19: x | O19: x | P19: x | S19: x | T19: cn | U19: x | V19: x | W19: x | X19: x | Y19: x | Z19: x | AA19: cn | AB19: x | AC19: x | AD19: x | AE19: x | AF19: x | AG19: x | AH19: cn | AI19: x | AK19: =SUM(COUNTIF(F19:AJ19,"x")) -> 23 | AL19: =SUM(COUNTIF(F19:AJ19,"cn")) -> 5 | AM19: =SUM(COUNTIF(F19:AJ19,"đ")) -> 0 | AN19: =SUM(COUNTIF(F19:AJ19,"đc")) -> 0 | AO19: =SUM(COUNTIF(F19:AJ19,"gt")) -> 0 | AP19: =SUM(COUNTIF(F19:AJ19,"ct")) -> 0 | AQ19: =AK19+AL19+AM19+AN19+AO19+AP19 -> 28 | AS19: ='Mã số nhân viên'!I10 -> 03462 | AT19: =C20-AS19 -> 0
A20: 8 | B20: 8 | C20: =VLOOKUP(D20,'Mã số nhân viên'!B10:I141,8,0) -> 03462 | D20: T . Bua Ngân | F20: cn | G20: x | H20: x | I20: x | J20: x | K20: x | L20: x | M20: cn | N20: x | O20: x | P20: x | S20: x | T20: cn | U20: x | V20: x | W20: x | X20: x | Y20: x | Z20: x | AA20: cn | AB20: x | AC20: x | AD20: x | AE20: x | AF20: x | AG20: x | AH20: cn | AI20: x | AK20: =SUM(COUNTIF(F20:AJ20,"x")) -> 23 | AL20: =SUM(COUNTIF(F20:AJ20,"cn")) -> 5 | AM20: =SUM(COUNTIF(F20:AJ20,"đ")) -> 0 | AN20: =SUM(COUNTIF(F20:AJ20,"đc")) -> 0 | AO20: =SUM(COUNTIF(F20:AJ20,"gt")) -> 0 | AP20: =SUM(COUNTIF(F20:AJ20,"ct")) -> 0 | AQ20: =AK20+AL20+AM20+AN20+AO20+AP20 -> 28 | AS20: ='Mã số nhân viên'!I11 -> 03463 | AT20: =C21-AS20 -> 0
A21: 9 | B21: 9 | C21: =VLOOKUP(D21,'Mã số nhân viên'!B11:I142,8,0) -> 03463 | D21: T Căng | F21: cn | G21: x | H21: x | I21: x | J21: x | K21: x | L21: x | M21: cn | N21: x | O21: x | P21: x | S21: x | T21: cn | U21: x | V21: x | W21: x | X21: x | Y21: x | Z21: x | AA21: cn | AB21: x | AC21: x | AD21: x | AE21: x | AF21: x | AG21: x | AH21: cn | AI21: x | AK21: =SUM(COUNTIF(F21:AJ21,"x")) -> 23 | AL21: =SUM(COUNTIF(F21:AJ21,"cn")) -> 5 | AM21: =SUM(COUNTIF(F21:AJ21,"đ")) -> 0 | AN21: =SUM(COUNTIF(F21:AJ21,"đc")) -> 0 | AO21: =SUM(COUNTIF(F21:AJ21,"gt")) -> 0 | AP21: =SUM(COUNTIF(F21:AJ21,"ct")) -> 0 | AQ21: =AK21+AL21+AM21+AN21+AO21+AP21 -> 28 | AS21: ='Mã số nhân viên'!I12 -> 03464 | AT21: =C22-AS21 -> 0
A22: 10 | B22: 10 | C22: =VLOOKUP(D22,'Mã số nhân viên'!B12:I143,8,0) -> 03464 | D22: N. Phôn 1 | F22: cn | G22: x | H22: x | I22: x | J22: x | K22: x | L22: x | M22: cn | N22: x | O22: x | P22: x | S22: x | T22: cn | U22: x | V22: x | W22: x | X22: x | Y22: x | Z22: x | AA22: cn | AB22: x | AC22: x | AD22: x | AE22: x | AF22: x | AG22: x | AH22: cn | AI22: x | AK22: =SUM(COUNTIF(F22:AJ22,"x")) -> 23 | AL22: =SUM(COUNTIF(F22:AJ22,"cn")) -> 5 | AM22: =SUM(COUNTIF(F22:AJ22,"đ")) -> 0 | AN22: =SUM(COUNTIF(F22:AJ22,"đc")) -> 0 | AO22: =SUM(COUNTIF(F22:AJ22,"gt")) -> 0 | AP22: =SUM(COUNTIF(F22:AJ22,"ct")) -> 0 | AQ22: =AK22+AL22+AM22+AN22+AO22+AP22 -> 28 | AS22: ='Mã số nhân viên'!I13 -> 03465 | AT22: =C23-AS22 -> 0
A23: 11 | B23: 11 | C23: =VLOOKUP(D23,'Mã số nhân viên'!B13:I144,8,0) -> 03465 | D23: T. In Păn | F23: cn | G23: x | H23: x | I23: x | J23: x | K23: x | L23: x | M23: cn | N23: tt | O23: x | S23: x | T23: cn | U23: x | V23: x | W23: x | X23: x | Y23: x | Z23: x | AA23: cn | AB23: x | AC23: x | AD23: x | AE23: x | AF23: x | AH23: cn | AI23: x | AK23: =SUM(COUNTIF(F23:AJ23,"x")) -> 20 | AL23: =SUM(COUNTIF(F23:AJ23,"cn")) -> 5 | AM23: =SUM(COUNTIF(F23:AJ23,"đ")) -> 0 | AN23: =SUM(COUNTIF(F23:AJ23,"đc")) -> 0 | AO23: =SUM(COUNTIF(F23:AJ23,"gt")) -> 0 | AP23: =SUM(COUNTIF(F23:AJ23,"ct")) -> 0 | AQ23: =AK23+AL23+AM23+AN23+AO23+AP23 -> 25 | AS23: ='Mã số nhân viên'!I14 -> 03466 | AT23: =C24-AS23 -> 0
A24: 12 | B24: 12 | C24: =VLOOKUP(D24,'Mã số nhân viên'!B14:I145,8,0) -> 03466 | D24: N. Keo | F24: cn | G24: x | H24: x | I24: x | J24: x | K24: x | L24: x | M24: cn | N24: x | O24: x | P24: x | S24: x | T24: cn | U24: x | V24: x | W24: x | X24: x | Y24: x | Z24: x | AA24: cn | AB24: x | AC24: x | AD24: x | AE24: x | AF24: x | AG24: x | AH24: cn | AI24: x | AK24: =SUM(COUNTIF(F24:AJ24,"x")) -> 23 | AL24: =SUM(COUNTIF(F24:AJ24,"cn")) -> 5 | AM24: =SUM(COUNTIF(F24:AJ24,"đ")) -> 0 | AN24: =SUM(COUNTIF(F24:AJ24,"đc")) -> 0 | AO24: =SUM(COUNTIF(F24:AJ24,"gt")) -> 0 | AP24: =SUM(COUNTIF(F24:AJ24,"ct")) -> 0 | AQ24: =AK24+AL24+AM24+AN24+AO24+AP24 -> 28 | AS24: ='Mã số nhân viên'!I15 -> 02727 | AT24: =C25-AS24 -> 0
A25: 13 | B25: 13 | C25: =VLOOKUP(D25,'Mã số nhân viên'!B15:I146,8,0) -> 02727 | D25: T. Thong Đon | F25: cn | G25: x | H25: x | I25: x | J25: x | K25: x | L25: x | M25: cn | N25: x | O25: x | P25: x | S25: x | T25: cn | W25: x | X25: x | Y25: x | Z25: x | AA25: cn | AB25: x | AC25: x | AD25: x | AE25: x | AF25: x | AH25: cn | AI25: x | AK25: =SUM(COUNTIF(F25:AJ25,"x")) -> 20 | AL25: =SUM(COUNTIF(F25:AJ25,"cn")) -> 5 | AM25: =SUM(COUNTIF(F25:AJ25,"đ")) -> 0 | AN25: =SUM(COUNTIF(F25:AJ25,"đc")) -> 0 | AO25: =SUM(COUNTIF(F25:AJ25,"gt")) -> 0 | AP25: =SUM(COUNTIF(F25:AJ25,"ct")) -> 0 | AQ25: =AK25+AL25+AM25+AN25+AO25+AP25 -> 25 | AS25: ='Mã số nhân viên'!I16 -> 03467 | AT25: =C26-AS25 -> 0
A26: 14 | B26: 14 | C26: =VLOOKUP(D26,'Mã số nhân viên'!B16:I147,8,0) -> 03467 | D26: T. Hin | F26: cn | G26: x | H26: x | I26: x | J26: x | K26: x | L26: x | M26: cn | N26: x | O26: x | P26: x | S26: x | T26: cn | U26: x | V26: x | W26: x | X26: x | Y26: x | Z26: x | AA26: cn | AB26: x | AC26: x | AD26: x | AE26: x | AF26: x | AH26: cn | AI26: x | AK26: =SUM(COUNTIF(F26:AJ26,"x")) -> 22 | AL26: =SUM(COUNTIF(F26:AJ26,"cn")) -> 5 | AM26: =SUM(COUNTIF(F26:AJ26,"đ")) -> 0 | AN26: =SUM(COUNTIF(F26:AJ26,"đc")) -> 0 | AO26: =SUM(COUNTIF(F26:AJ26,"gt")) -> 0 | AP26: =SUM(COUNTIF(F26:AJ26,"ct")) -> 0 | AQ26: =AK26+AL26+AM26+AN26+AO26+AP26 -> 27 | AS26: ='Mã số nhân viên'!I17 -> 04056 | AT26: =C27-AS26 -> 0
A27: 15 | B27: 15 | C27: =VLOOKUP(D27,'Mã số nhân viên'!B17:I148,8,0) -> 04056 | D27: N. Ly Phon | F27: cn | G27: x | H27: x | I27: x | J27: x | K27: x | L27: x | M27: cn | N27: x | O27: x | P27: x | S27: x | V27: x | W27: tt | X27: tt | Y27: x | Z27: x | AA27: cn | AC27: x | AD27: x | AE27: x | AF27: x | AG27: x | AH27: cn | AI27: x | AK27: =SUM(COUNTIF(F27:AJ27,"x")) -> 19 | AL27: =SUM(COUNTIF(F27:AJ27,"cn")) -> 4 | AM27: =SUM(COUNTIF(F27:AJ27,"đ")) -> 0 | AN27: =SUM(COUNTIF(F27:AJ27,"đc")) -> 0 | AO27: =SUM(COUNTIF(F27:AJ27,"gt")) -> 0 | AP27: =SUM(COUNTIF(F27:AJ27,"ct")) -> 0 | AQ27: =AK27+AL27+AM27+AN27+AO27+AP27 -> 23 | AS27: ='Mã số nhân viên'!I18 -> 03469 | AT27: =C28-AS27 -> 0
A28: 16 | B28: 16 | C28: =VLOOKUP(D28,'Mã số nhân viên'!B18:I149,8,0) -> 03469 | D28: T. Xôm Va Nít | F28: cn | G28: x | H28: x | I28: x | J28: x | K28: x | L28: x | M28: cn | N28: x | O28: x | P28: x | S28: x | T28: cn | U28: x | V28: x | W28: x | X28: x | Y28: x | Z28: x | AA28: cn | AB28: x | AC28: x | AD28: x | AE28: x | AF28: x | AG28: x | AH28: cn | AI28: x | AK28: =SUM(COUNTIF(F28:AJ28,"x")) -> 23 | AL28: =SUM(COUNTIF(F28:AJ28,"cn")) -> 5 | AM28: =SUM(COUNTIF(F28:AJ28,"đ")) -> 0 | AN28: =SUM(COUNTIF(F28:AJ28,"đc")) -> 0 | AO28: =SUM(COUNTIF(F28:AJ28,"gt")) -> 0 | AP28: =SUM(COUNTIF(F28:AJ28,"ct")) -> 0 | AQ28: =AK28+AL28+AM28+AN28+AO28+AP28 -> 28 | AS28: ='Mã số nhân viên'!I19 -> 03470 | AT28: =C29-AS28 -> 0
A29: 17 | B29: 17 | C29: =VLOOKUP(D29,'Mã số nhân viên'!B19:I150,8,0) -> 03470 | D29: T. Lọi | F29: cn | G29: x | H29: x | I29: x | J29: x | K29: x | L29: x | M29: cn | N29: tt | O29: tt | S29: tt | T29: tt | U29: x | V29: x | W29: x | X29: x | Y29: x | Z29: x | AA29: cn | AB29: x | AC29: x | AD29: x | AE29: x | AF29: x | AG29: x | AH29: cn | AI29: x | AK29: =SUM(COUNTIF(F29:AJ29,"x")) -> 19 | AL29: =SUM(COUNTIF(F29:AJ29,"cn")) -> 4 | AM29: =SUM(COUNTIF(F29:AJ29,"đ")) -> 0 | AN29: =SUM(COUNTIF(F29:AJ29,"đc")) -> 0 | AO29: =SUM(COUNTIF(F29:AJ29,"gt")) -> 0 | AP29: =SUM(COUNTIF(F29:AJ29,"ct")) -> 0 | AQ29: =AK29+AL29+AM29+AN29+AO29+AP29 -> 23 | AS29: ='Mã số nhân viên'!I20 -> 03471 | AT29: =C30-AS29 -> 0
A30: 18 | B30: 18 | C30: =VLOOKUP(D30,'Mã số nhân viên'!B20:I151,8,0) -> 03471 | D30: T. Phô Thong | F30: cn | G30: x | H30: x | I30: x | J30: x | K30: x | L30: x | M30: cn | N30: x | O30: x | P30: x | S30: x | T30: cn | U30: x | V30: x | W30: x | X30: x | Y30: x | Z30: x | AA30: cn | AB30: x | AC30: x | AD30: x | AE30: x | AF30: x | AG30: x | AH30: cn | AI30: x | AK30: =SUM(COUNTIF(F30:AJ30,"x")) -> 23 | AL30: =SUM(COUNTIF(F30:AJ30,"cn")) -> 5 | AM30: =SUM(COUNTIF(F30:AJ30,"đ")) -> 0 | AN30: =SUM(COUNTIF(F30:AJ30,"đc")) -> 0 | AO30: =SUM(COUNTIF(F30:AJ30,"gt")) -> 0 | AP30: =SUM(COUNTIF(F30:AJ30,"ct")) -> 0 | AQ30: =AK30+AL30+AM30+AN30+AO30+AP30 -> 28 | AS30: ='Mã số nhân viên'!I21 -> 03472 | AT30: =C31-AS30 -> 0
A31: 19 | B31: 19 | C31: =VLOOKUP(D31,'Mã số nhân viên'!B21:I152,8,0) -> 03472 | D31: N. Soi | F31: cn | G31: x | H31: x | I31: x | J31: x | K31: x | L31: x | M31: cn | N31: x | P31: x | T31: cn | U31: x | V31: tt | W31: x | X31: x | Y31: x | Z31: x | AA31: cn | AB31: x | AC31: x | AD31: x | AE31: x | AF31: x | AG31: x | AH31: cn | AI31: x | AK31: =SUM(COUNTIF(F31:AJ31,"x")) -> 20 | AL31: =SUM(COUNTIF(F31:AJ31,"cn")) -> 5 | AM31: =SUM(COUNTIF(F31:AJ31,"đ")) -> 0 | AN31: =SUM(COUNTIF(F31:AJ31,"đc")) -> 0 | AO31: =SUM(COUNTIF(F31:AJ31,"gt")) -> 0 | AP31: =SUM(COUNTIF(F31:AJ31,"ct")) -> 0 | AQ31: =AK31+AL31+AM31+AN31+AO31+AP31 -> 25 | AS31: ='Mã số nhân viên'!I22 -> 03473 | AT31: =C32-AS31 -> 0
A32: 20 | B32: 20 | C32: =VLOOKUP(D32,'Mã số nhân viên'!B22:I153,8,0) -> 03473 | D32: N. Me Kha La | F32: cn | G32: x | H32: x | I32: x | J32: x | K32: x | L32: x | M32: cn | N32: x | O32: x | P32: x | R32: x | S32: x | T32: cn | W32: tt | X32: tt | Y32: tt | Z32: x | AA32: cn | AB32: x | AC32: x | AD32: x | AE32: x | AF32: x | AG32: x | AH32: cn | AI32: x | AK32: =SUM(COUNTIF(F32:AJ32,"x")) -> 19 | AL32: =SUM(COUNTIF(F32:AJ32,"cn")) -> 5 | AM32: =SUM(COUNTIF(F32:AJ32,"đ")) -> 0 | AN32: =SUM(COUNTIF(F32:AJ32,"đc")) -> 0 | AO32: =SUM(COUNTIF(F32:AJ32,"gt")) -> 0 | AP32: =SUM(COUNTIF(F32:AJ32,"ct")) -> 0 | AQ32: =AK32+AL32+AM32+AN32+AO32+AP32 -> 24 | AS32: ='Mã số nhân viên'!I23 -> 03474 | AT32: =C33-AS32 -> 0
A33: 21 | B33: 21 | C33: =VLOOKUP(D33,'Mã số nhân viên'!B23:I154,8,0) -> 03474 | D33: N. Mon Khăm | F33: cn | G33: x | H33: x | I33: x | J33: x | K33: x | L33: x | M33: cn | N33: x | O33: x | P33: x | S33: x | T33: cn | U33: x | V33: x | W33: x | X33: x | Y33: x | Z33: x | AA33: cn | AB33: x | AC33: x | AD33: x | AE33: x | AF33: x | AG33: tt | AH33: cn | AI33: x | AK33: =SUM(COUNTIF(F33:AJ33,"x")) -> 22 | AL33: =SUM(COUNTIF(F33:AJ33,"cn")) -> 5 | AM33: =SUM(COUNTIF(F33:AJ33,"đ")) -> 0 | AN33: =SUM(COUNTIF(F33:AJ33,"đc")) -> 0 | AO33: =SUM(COUNTIF(F33:AJ33,"gt")) -> 0 | AP33: =SUM(COUNTIF(F33:AJ33,"ct")) -> 0 | AQ33: =AK33+AL33+AM33+AN33+AO33+AP33 -> 27 | AS33: ='Mã số nhân viên'!I24 -> 04057 | AT33: =C34-AS33 -> 0
A34: 22 | B34: 22 | C34: =VLOOKUP(D34,'Mã số nhân viên'!B24:I155,8,0) -> 04057 | D34: N. Bua Lay | F34: cn | G34: x | H34: x | I34: x | J34: x | K34: x | L34: x | M34: cn | N34: x | O34: x | P34: x | S34: x | T34: cn | U34: x | V34: x | W34: x | X34: x | Y34: x | Z34: x | AA34: cn | AB34: x | AC34: x | AD34: x | AE34: x | AF34: x | AG34: x | AH34: cn | AI34: x | AK34: =SUM(COUNTIF(F34:AJ34,"x")) -> 23 | AL34: =SUM(COUNTIF(F34:AJ34,"cn")) -> 5 | AM34: =SUM(COUNTIF(F34:AJ34,"đ")) -> 0 | AN34: =SUM(COUNTIF(F34:AJ34,"đc")) -> 0 | AO34: =SUM(COUNTIF(F34:AJ34,"gt")) -> 0 | AP34: =SUM(COUNTIF(F34:AJ34,"ct")) -> 0 | AQ34: =AK34+AL34+AM34+AN34+AO34+AP34 -> 28 | AS34: ='Mã số nhân viên'!I25 -> 03476 | AT34: =C35-AS34 -> 0
A35: 23 | B35: 23 | C35: =VLOOKUP(D35,'Mã số nhân viên'!B25:I156,8,0) -> 03476 | D35: T. Bin Ly. | F35: cn | G35: x | H35: x | I35: x | J35: x | K35: x | L35: x | M35: cn | N35: x | O35: x | P35: x | S35: x | T35: cn | U35: x | V35: x | W35: x | X35: x | Y35: x | Z35: x | AA35: cn | AB35: x | AC35: x | AD35: x | AE35: x | AF35: x | AG35: tt | AH35: cn | AK35: =SUM(COUNTIF(F35:AJ35,"x")) -> 21 | AL35: =SUM(COUNTIF(F35:AJ35,"cn")) -> 5 | AM35: =SUM(COUNTIF(F35:AJ35,"đ")) -> 0 | AN35: =SUM(COUNTIF(F35:AJ35,"đc")) -> 0 | AO35: =SUM(COUNTIF(F35:AJ35,"gt")) -> 0 | AP35: =SUM(COUNTIF(F35:AJ35,"ct")) -> 0 | AQ35: =AK35+AL35+AM35+AN35+AO35+AP35 -> 26 | AS35: ='Mã số nhân viên'!I26 -> 03477 | AT35: =C36-AS35 -> 0
A36: 24 | B36: 24 | C36: =VLOOKUP(D36,'Mã số nhân viên'!B26:I157,8,0) -> 03477 | D36: N. Phim Phon. | F36: cn | G36: x | H36: x | I36: x | J36: x | K36: x | L36: x | M36: cn | N36: x | O36: x | P36: x | S36: x | T36: cn | U36: x | V36: x | W36: x | X36: x | Y36: x | Z36: x | AA36: cn | AB36: x | AC36: x | AD36: x | AE36: x | AF36: x | AG36: x | AH36: cn | AI36: x | AK36: =SUM(COUNTIF(F36:AJ36,"x")) -> 23 | AL36: =SUM(COUNTIF(F36:AJ36,"cn")) -> 5 | AM36: =SUM(COUNTIF(F36:AJ36,"đ")) -> 0 | AN36: =SUM(COUNTIF(F36:AJ36,"đc")) -> 0 | AO36: =SUM(COUNTIF(F36:AJ36,"gt")) -> 0 | AP36: =SUM(COUNTIF(F36:AJ36,"ct")) -> 0 | AQ36: =AK36+AL36+AM36+AN36+AO36+AP36 -> 28 | AS36: ='Mã số nhân viên'!I27 -> 03478 | AT36: =C37-AS36 -> 0
A37: 25 | B37: 25 | C37: =VLOOKUP(D37,'Mã số nhân viên'!B27:I158,8,0) -> 03478 | D37: N. Nong | F37: cn | G37: x | H37: x | I37: x | J37: x | K37: x | L37: x | M37: cn | N37: x | O37: x | P37: x | S37: x | T37: cn | U37: x | V37: x | W37: x | X37: x | Y37: x | Z37: x | AA37: cn | AB37: x | AC37: x | AD37: tt | AE37: x | AF37: tt | AH37: cn | AI37: x | AK37: =SUM(COUNTIF(F37:AJ37,"x")) -> 20 | AL37: =SUM(COUNTIF(F37:AJ37,"cn")) -> 5 | AM37: =SUM(COUNTIF(F37:AJ37,"đ")) -> 0 | AN37: =SUM(COUNTIF(F37:AJ37,"đc")) -> 0 | AO37: =SUM(COUNTIF(F37:AJ37,"gt")) -> 0 | AP37: =SUM(COUNTIF(F37:AJ37,"ct")) -> 0 | AQ37: =AK37+AL37+AM37+AN37+AO37+AP37 -> 25 | AS37: ='Mã số nhân viên'!I28 -> 03479 | AT37: =C38-AS37 -> 0
A38: 26 | B38: 26 | C38: =VLOOKUP(D38,'Mã số nhân viên'!B28:I159,8,0) -> 03479 | D38: N. Tun 1 | F38: cn | G38: x | H38: x | I38: tt | J38: tt | K38: tt | L38: x | M38: cn | N38: x | O38: x | P38: x | S38: x | T38: cn | U38: x | V38: x | W38: x | X38: x | Y38: x | Z38: x | AA38: cn | AB38: x | AC38: x | AD38: x | AE38: x | AF38: x | AG38: x | AH38: cn | AI38: x | AK38: =SUM(COUNTIF(F38:AJ38,"x")) -> 20 | AL38: =SUM(COUNTIF(F38:AJ38,"cn")) -> 5 | AM38: =SUM(COUNTIF(F38:AJ38,"đ")) -> 0 | AN38: =SUM(COUNTIF(F38:AJ38,"đc")) -> 0 | AO38: =SUM(COUNTIF(F38:AJ38,"gt")) -> 0 | AP38: =SUM(COUNTIF(F38:AJ38,"ct")) -> 0 | AQ38: =AK38+AL38+AM38+AN38+AO38+AP38 -> 25 | AS38: ='Mã số nhân viên'!I29 -> 03480 | AT38: =C39-AS38 -> 0
A39: 27 | B39: 27 | C39: =VLOOKUP(D39,'Mã số nhân viên'!B29:I160,8,0) -> 03480 | D39: T . Lốc | F39: cn | G39: x | H39: x | I39: tt | J39: tt | K39: tt | L39: x | M39: cn | N39: x | O39: x | P39: x | S39: x | T39: cn | U39: x | V39: x | W39: x | X39: x | Y39: x | Z39: x | AA39: cn | AB39: x | AC39: x | AD39: x | AE39: x | AF39: x | AG39: x | AH39: cn | AI39: x | AK39: =SUM(COUNTIF(F39:AJ39,"x")) -> 20 | AL39: =SUM(COUNTIF(F39:AJ39,"cn")) -> 5 | AM39: =SUM(COUNTIF(F39:AJ39,"đ")) -> 0 | AN39: =SUM(COUNTIF(F39:AJ39,"đc")) -> 0 | AO39: =SUM(COUNTIF(F39:AJ39,"gt")) -> 0 | AP39: =SUM(COUNTIF(F39:AJ39,"ct")) -> 0 | AQ39: =AK39+AL39+AM39+AN39+AO39+AP39 -> 25 | AS39: ='Mã số nhân viên'!I30 -> 03481 | AT39: =C40-AS39 -> 0
A40: 28 | B40: 28 | C40: =VLOOKUP(D40,'Mã số nhân viên'!B30:I161,8,0) -> 03481 | D40: N . Khâm (1) | F40: cn | G40: x | H40: x | I40: x | J40: x | K40: x | L40: x | M40: cn | N40: x | O40: x | S40: x | T40: cn | U40: x | V40: x | W40: x | X40: x | Y40: x | Z40: x | AA40: cn | AB40: x | AC40: x | AD40: x | AE40: x | AF40: x | AG40: x | AH40: cn | AI40: x | AK40: =SUM(COUNTIF(F40:AJ40,"x")) -> 22 | AL40: =SUM(COUNTIF(F40:AJ40,"cn")) -> 5 | AM40: =SUM(COUNTIF(F40:AJ40,"đ")) -> 0 | AN40: =SUM(COUNTIF(F40:AJ40,"đc")) -> 0 | AO40: =SUM(COUNTIF(F40:AJ40,"gt")) -> 0 | AP40: =SUM(COUNTIF(F40:AJ40,"ct")) -> 0 | AQ40: =AK40+AL40+AM40+AN40+AO40+AP40 -> 27 | AS40: ='Mã số nhân viên'!I31 -> 03482 | AT40: =C41-AS40 -> 0
A41: 29 | B41: 29 | C41: =VLOOKUP(D41,'Mã số nhân viên'!B31:I162,8,0) -> 03482 | D41: T . Phết | F41: cn | G41: x | H41: x | I41: x | J41: x | K41: x | L41: x | M41: cn | N41: x | O41: x | S41: x | T41: cn | U41: x | V41: x | W41: x | X41: x | Y41: x | Z41: x | AA41: cn | AB41: x | AC41: x | AD41: x | AE41: x | AF41: x | AG41: x | AH41: cn | AI41: x | AK41: =SUM(COUNTIF(F41:AJ41,"x")) -> 22 | AL41: =SUM(COUNTIF(F41:AJ41,"cn")) -> 5 | AM41: =SUM(COUNTIF(F41:AJ41,"đ")) -> 0 | AN41: =SUM(COUNTIF(F41:AJ41,"đc")) -> 0 | AO41: =SUM(COUNTIF(F41:AJ41,"gt")) -> 0 | AP41: =SUM(COUNTIF(F41:AJ41,"ct")) -> 0 | AQ41: =AK41+AL41+AM41+AN41+AO41+AP41 -> 27 | AS41: ='Mã số nhân viên'!I32 -> 03483 | AT41: =C42-AS41 -> 0
A42: 30 | B42: 30 | C42: =VLOOKUP(D42,'Mã số nhân viên'!B32:I163,8,0) -> 03483 | D42: T. Viêng Sa Văn | F42: cn | G42: x | H42: x | I42: x | J42: x | K42: x | L42: x | M42: cn | N42: x | O42: x | P42: x | S42: x | T42: cn | U42: x | V42: x | W42: x | X42: x | Y42: x | Z42: x | AA42: cn | AB42: x | AC42: x | AD42: x | AE42: x | AF42: x | AG42: tt | AH42: cn | AI42: x | AK42: =SUM(COUNTIF(F42:AJ42,"x")) -> 22 | AL42: =SUM(COUNTIF(F42:AJ42,"cn")) -> 5 | AM42: =SUM(COUNTIF(F42:AJ42,"đ")) -> 0 | AN42: =SUM(COUNTIF(F42:AJ42,"đc")) -> 0 | AO42: =SUM(COUNTIF(F42:AJ42,"gt")) -> 0 | AP42: =SUM(COUNTIF(F42:AJ42,"ct")) -> 0 | AQ42: =AK42+AL42+AM42+AN42+AO42+AP42 -> 27 | AS42: ='Mã số nhân viên'!I33 -> 03484 | AT42: =C43-AS42 -> 0
...

Sheet BTH mủ tạp
A2: CỘNG HÒA DÂN CHỦ NHÂN DÂN LÀO
A3: Hòa Bình -Độc Lập - Dân Chủ - thống Nhất - Thịnh Vượng
A4: -----o0o-----
B6: CÔNG TY TNHH MTV QUASA - GERUCO LÀO
B7: ĐỘI SẢN XUẤT SỐ 04
A9: BẢNG THEO DÕI SẢN LƯỢNG MỦ TẠP THÁNG 06 NĂM 2025
A10: (Từ ngày 01 đến 31/05/2025)
A13: Stt | C13: MSNV | D13: Họ và tên | E13: Kí tên | F13: Ngày | AK13: Tổng mủ tạp | AL13: DRC bình quân | AM13: Quy khô | AN13: Xếp hạng kỹ thuật
F14: 1 | G14: 2 | H14: 3 | I14: 4 | J14: 5 | K14: 6 | L14: 7 | M14: 8 | N14: 9 | O14: 10 | P14: 11 | Q14: 12 | R14: 13 | S14: 14 | T14: 15 | U14: 16 | V14: 17 | W14: 18 | X14: 19 | Y14: 20 | Z14: 21 | AA14: 22 | AB14: 23 | AC14: 24 | AD14: 25 | AE14: 26 | AF14: 27 | AG14: 28 | AH14: 29 | AI14: 30 | AJ14: 31 | AP14: DRC bình quân
A15: Lát bốc | F15: C | G15: D | H15: A | I15: B | J15: C | K15: D | L15: A | M15: B | N15: C | O15: D | P15: A | Q15: B | R15: C | S15: D | T15: A | U15: B | V15: C | W15: D | X15: A | Y15: B | Z15: C | AA15: D | AB15: A | AC15: B | AD15: C | AE15: D | AF15: A | AG15: B | AH15: C | AI15: D
A16: Trạm 2 | F16: =SUM(F17:F97) -> 3836 | G16: =SUM(G17:G97) -> 3892 | H16: =SUM(H17:H97) -> 4476 | I16: =SUM(I17:I97) -> 4305 | J16: =SUM(J17:J97) -> 4164 | K16: =SUM(K17:K97) -> 4839 | L16: =SUM(L17:L97) -> 9907 | M16: =SUM(M17:M97) -> 9612 | ... AK16: =SUM(AK17:AK97) -> 168911 | AM16: =SUM(AM17:AM97) -> 78326.587
A17: 1 | B17: 1 | C17: ='Chấm công KT'!C13 -> 03456 | D17: ='Chấm công KT'!D13 -> T. Vôn | F17: 39 | G17: 58 | H17: 44 | I17: 51 | J17: 49 | K17: 46 | L17: 90 | M17: 79 | N17: 98 | O17: 94 | P17: 67 | Q17: 0 | R17: 0 | S17: 0 | T17: 0 | U17: 0 | V17: 0 | W17: 0 | X17: 0 | Y17: 60 | Z17: 176 | AA17: 100 | AB17: 84 | AC17: 0 | AD17: 0 | AE17: 0 | AF17: 0 | AG17: 0 | AH17: 0 | AI17: 0 | AK17: =SUM(F17:AJ17) -> 1135 | AL17: 46.371513 | AM17: =AK17*AL17/100 -> 526.31668 | AN17: B | AS17: =AM16/15*100 -> 522177.25
A18: 2 | B18: 2 | C18: ='Chấm công KT'!C14 -> 04052 | D18: ='Chấm công KT'!D14 -> T. Feng | F18: 65 | G18: 53 | H18: 62 | I18: 20 | J18: 28 | K18: 50 | L18: 124 | M18: 93 | N18: 90 | O18: 99 | P18: 97 | Q18: 87 | R18: 81 | S18: 108 | T18: 0 | U18: 0 | V18: 96 | W18: 82 | X18: 90 | Y18: 63 | Z18: 70 | AA18: 85 | AB18: 94 | AC18: 75 | AD18: 75 | AE18: 83 | AF18: 85 | AG18: 0 | AH18: 0 | AI18: 0 | AK18: =SUM(F18:AJ18) -> 1955 | AL18: 46.371513 | AM18: =AK18*AL18/100 -> 906.56309 | AN18: A
A19: 3 | B19: 3 | C19: ='Chấm công KT'!C15 -> 02725 | D19: ='Chấm công KT'!D15 -> T. Sa Văn | F19: 75 | G19: 0 | H19: 61 | I19: 0 | J19: 53 | K19: 70 | L19: 141 | M19: 174 | N19: 147 | O19: 100 | P19: 156 | Q19: 93 | R19: 89 | S19: 0 | T19: 0 | U19: 0 | V19: 0 | W19: 0 | X19: 0 | Y19: 0 | Z19: 0 | AA19: 0 | AB19: 0 | AC19: 142 | AD19: 165 | AE19: 134 | AF19: 71 | AG19: 96 | AH19: 50 | AI19: 86 | AK19: =SUM(F19:AJ19) -> 1903 | AL19: 46.371513 | AM19: =AK19*AL19/100 -> 882.4499 | AN19: A
A20: 4 | B20: 4 | C20: ='Chấm công KT'!C16 -> 04053 | D20: ='Chấm công KT'!D16 -> Lăm Ma Thu | F20: 61 | G20: 41 | H20: 54 | I20: 62 | J20: 48 | K20: 40 | L20: 125 | M20: 190 | N20: 127 | O20: 100 | P20: 103 | Q20: 139 | R20: 134 | S20: 73 | T20: 0 | U20: 0 | V20: 0 | W20: 0 | X20: 0 | Y20: 40 | Z20: 137 | AA20: 125 | AB20: 0 | AC20: 64 | AD20: 55 | AE20: 0 | AF20: 142 | AG20: 93 | AH20: 106 | AI20: 86 | AK20: =SUM(F20:AJ20) -> 2145 | AL20: 46.371513 | AM20: =AK20*AL20/100 -> 994.66896 | AN20: B
A21: 5 | B21: 5 | C21: ='Chấm công KT'!C17 -> 03459 | D21: ='Chấm công KT'!D17 -> N. Vạt | F21: 60 | G21: 96 | H21: 72 | I21: 52 | J21: 49 | K21: 84 | L21: 159 | M21: 0 | N21: 147 | O21: 0 | P21: 104 | Q21: 0 | R21: 0 | S21: 0 | T21: 0 | U21: 0 | V21: 0 | W21: 0 | X21: 85 | Y21: 90 | Z21: 49 | AA21: 176 | AB21: 100 | AC21: 81 | AD21: 90 | AE21: 139 | AF21: 89 | AG21: 54 | AH21: 85 | AI21: 154 | AK21: =SUM(F21:AJ21) -> 2015 | AL21: 46.371513 | AM21: =AK21*AL21/100 -> 934.386 | AN21: A
A22: 6 | B22: 6 | C22: ='Chấm công KT'!C18 -> 04054 | D22: ='Chấm công KT'!D18 -> N. Kay Son | F22: 59 | G22: 91 | H22: 105 | I22: 64 | J22: 57 | K22: 73 | L22: 160 | M22: 127 | N22: 109 | O22: 174 | P22: 124 | Q22: 82 | R22: 83 | S22: 0 | T22: 0 | U22: 0 | V22: 0 | W22: 0 | X22: 0 | Y22: 70 | Z22: 77 | AA22: 207 | AB22: 112 | AC22: 85 | AD22: 77 | AE22: 108 | AF22: 93 | AG22: 80 | AH22: 85 | AI22: 99 | AK22: =SUM(F22:AJ22) -> 2401 | AL22: 46.371513 | AM22: =AK22*AL22/100 -> 1113.38 | AN22: A
A23: 7 | B23: 7 | C23: ='Chấm công KT'!C19 -> 04055 | D23: ='Chấm công KT'!D19 -> T. Đèng 1 | F23: 47 | G23: 75 | H23: 55 | I23: 67 | J23: 38 | K23: 51 | L23: 119 | M23: 88 | N23: 112 | O23: 130 | P23: 91 | Q23: 0 | R23: 0 | S23: 0 | T23: 0 | U23: 0 | V23: 63 | W23: 191 | X23: 0 | Y23: 107 | Z23: 73 | AA23: 95 | AB23: 118 | AC23: 0 | AD23: 64 | AE23: 87 | AF23: 59 | AG23: 103 | AH23: 63 | AI23: 97 | AK23: =SUM(F23:AJ23) -> 1993 | AL23: 46.371513 | AM23: =AK23*AL23/100 -> 924.18426 | AN23: A
A24: 8 | B24: 8 | C24: ='Chấm công KT'!C20 -> 03462 | D24: ='Chấm công KT'!D20 -> T . Bua Ngân | F24: 65 | G24: 49 | H24: 54 | I24: 66 | J24: 67 | K24: 67 | L24: 129 | M24: 119 | N24: 118 | O24: 145 | P24: 99 | Q24: 84 | R24: 0 | S24: 0 | T24: 0 | U24: 0 | V24: 179 | W24: 0 | X24: 75 | Y24: 107 | Z24: 102 | AA24: 126 | AB24: 95 | AC24: 90 | AD24: 102 | AE24: 60 | AF24: 87 | AG24: 87 | AH24: 101 | AI24: 60 | AK24: =SUM(F24:AJ24) -> 2333 | AL24: 46.371513 | AM24: =AK24*AL24/100 -> 1081.8474 | AN24: A
A25: 9 | B25: 9 | C25: ='Chấm công KT'!C21 -> 03463 | D25: ='Chấm công KT'!D21 -> T Căng | F25: 95 | G25: 119 | H25: 64 | I25: 45 | J25: 50 | K25: 93 | L25: 169 | M25: 109 | N25: 152 | O25: 195 | P25: 126 | Q25: 84 | R25: 141 | S25: 163 | T25: 0 | U25: 0 | V25: 91 | W25: 155 | X25: 73 | Y25: 0 | Z25: 0 | AA25: 0 | AB25: 0 | AC25: 139 | AD25: 152 | AE25: 250 | AF25: 140 | AG25: 66 | AH25: 92 | AI25: 122 | AK25: =SUM(F25:AJ25) -> 2885 | AL25: 46.371513 | AM25: =AK25*AL25/100 -> 1337.8182 | AN25: A
A26: 10 | B26: 10 | C26: ='Chấm công KT'!C22 -> 03464 | D26: ='Chấm công KT'!D22 -> N. Phôn 1 | F26: 95 | G26: 95 | H26: 65 | I26: 45 | J26: 84 | K26: 101 | L26: 134 | M26: 117 | N26: 152 | O26: 203 | P26: 126 | Q26: 100 | R26: 133 | S26: 156 | T26: 0 | U26: 0 | V26: 88 | W26: 167 | X26: 88 | Y26: 0 | Z26: 0 | AA26: 0 | AB26: 0 | AC26: 117 | AD26: 152 | AE26: 241 | AF26: 140 | AG26: 50 | AH26: 79 | AI26: 120 | AK26: =SUM(F26:AJ26) -> 2848 | AL26: 46.371513 | AM26: =AK26*AL26/100 -> 1320.6607 | AN26: A
A27: 11 | B27: 11 | C27: ='Chấm công KT'!C23 -> 03465 | D27: ='Chấm công KT'!D23 -> T. In Păn | F27: 76 | G27: 50 | H27: 0 | I27: 32 | J27: 30 | K27: 60 | L27: 195 | M27: 0 | N27: 130 | O27: 114 | P27: 147 | Q27: 150 | R27: 100 | S27: 0 | T27: 0 | U27: 0 | V27: 75 | W27: 0 | X27: 0 | Y27: 91 | Z27: 54 | AA27: 185 | AB27: 156 | AC27: 0 | AD27: 70 | AE27: 0 | AF27: 107 | AG27: 104 | AH27: 90 | AI27: 166 | AK27: =SUM(F27:AJ27) -> 2182 | AL27: 46.371513 | AM27: =AK27*AL27/100 -> 1011.8264 | AN27: A
A28: 12 | B28: 12 | C28: ='Chấm công KT'!C24 -> 03466 | D28: ='Chấm công KT'!D24 -> N. Keo | F28: 70 | G28: 100 | H28: 75 | I28: 76 | J28: 63 | K28: 100 | L28: 146 | M28: 179 | N28: 155 | O28: 200 | P28: 110 | Q28: 149 | R28: 123 | S28: 152 | T28: 0 | U28: 0 | V28: 90 | W28: 145 | X28: 96 | Y28: 92 | Z28: 74 | AA28: 148 | AB28: 65 | AC28: 117 | AD28: 94 | AE28: 150 | AF28: 69 | AG28: 90 | AH28: 89 | AI28: 162 | AK28: =SUM(F28:AJ28) -> 3179 | AL28: 46.371513 | AM28: =AK28*AL28/100 -> 1474.1504 | AN28: A
A29: 13 | B29: 13 | C29: ='Chấm công KT'!C25 -> 02727 | D29: ='Chấm công KT'!D25 -> T. Thong Đon | F29: 61 | G29: 221 | H29: 59 | I29: 54 | J29: 69 | K29: 122 | L29: 136 | M29: 143 | N29: 152 | O29: 232 | P29: 119 | Q29: 101 | R29: 106 | S29: 198 | T29: 0 | U29: 0 | V29: 0 | W29: 0 | X29: 0 | Y29: 0 | Z29: 163 | AA29: 277 | AB29: 70 | AC29: 0 | AD29: 0 | AE29: 0 | AF29: 0 | AG29: 0 | AH29: 0 | AI29: 240 | AK29: =SUM(F29:AJ29) -> 2523 | AL29: 46.371513 | AM29: =AK29*AL29/100 -> 1169.9533 | AN29: A
... A89: 73 | B89: 73 | C89: ='Chấm công KT'!C85 -> 04071 | D89: ='Chấm công KT'!D85 -> T. Ne | F89: 40 | G89: 0 | H89: 68 | I89: 42 | J89: 31 | K89: 0 | L89: 123 | M89: 129 | N89: 96 | O89: 92 | P89: 87 | Q89: 86 | R89: 73 | S89: 73 | T89: 0 | U89: 60 | V89: 61 | W89: 54 | X89: 55 | Y89: 56 | Z89: 58 | AA89: 0 | AB89: 50 | AC89: 54 | AD89: 52 | AE89: 49 | AF89: 0 | AG89: 0 | AH89: 0 | AI89: 99 | AK89: =SUM(F89:AJ89) -> 1588 | AL89: 46.371513 | AM89: =AK89*AL89/100 -> 736.37963 | AN89: A
A90: 74 | B90: 74 | D90: ='Chấm công KT'!D86 -> T. Tý | F90: 0 | G90: 0 | H90: 0 | I90: 0 | J90: 0 | K90: 0 | L90: 0 | M90: 0 | N90: 0 | O90: 0 | P90: 0 | Q90: 0 | R90: 0 | S90: 0 | T90: 0 | U90: 0 | V90: 0 | W90: 0 | X90: 0 | Y90: 0 | Z90: 0 | AA90: 0 | AB90: 0 | AC90: 0 | AD90: 0 | AE90: 0 | AF90: 0 | AG90: 0 | AH90: 0 | AI90: 109 | AK90: =SUM(F90:AJ90) -> 109 | AL90: 46.371513 | AM90: =AK90*AL90/100 -> 50.54495 | AN90: C.
A91: 75 | B91: 75 | D91: ='Chấm công KT'!D87 -> T. Lã | F91: 0 | G91: 0 | H91: 0 | I91: 0 | J91: 0 | K91: 70 | L91: 70 | M91: 0 | N91: 0 | O91: 80 | P91: 189 | Q91: 118 | R91: 0 | S91: 0 | T91: 0 | U91: 0 | V91: 0 | W91: 0 | X91: 0 | Y91: 0 | Z91: 0 | AA91: 0 | AB91: 138 | AC91: 92 | AD91: 93 | AE91: 0 | AF91: 62 | AG91: 104 | AH91: 59 | AI91: 62 | AK91: =SUM(F91:AJ91) -> 1137 | AL91: 46.371513 | AM91: =AK91*AL91/100 -> 527.24411 | AN91: C.
A92: 76 | B92: 76 | D92: ='Chấm công KT'!D88 -> N. Veo | F92: 0 | G92: 0 | H92: 0 | I92: 0 | J92: 0 | K92: 80 | L92: 188 | M92: 0 | N92: 0 | O92: 0 | P92: 137 | Q92: 100 | R92: 0 | S92: 0 | T92: 0 | U92: 0 | V92: 142 | W92: 0 | X92: 0 | Y92: 0 | Z92: 106 | AA92: 109 | AB92: 139 | AC92: 0 | AD92: 103 | AE92: 0 | AF92: 92 | AG92: 106 | AH92: 45 | AI92: 0 | AK92: =SUM(F92:AJ92) -> 1347 | AL92: 46.371513 | AM92: =AK92*AL92/100 -> 624.62429 | AN92: C.
A93: 77 | B93: 77 | D93: ='Chấm công KT'!D89 -> T. Pu | F93: 0 | G93: 0 | H93: 0 | I93: 0 | J93: 0 | K93: 0 | L93: 200 | M93: 0 | N93: 0 | O93: 0 | P93: 124 | Q93: 0 | R93: 0 | S93: 0 | T93: 0 | U93: 0 | V93: 0 | W93: 0 | X93: 88 | Y93: 0 | Z93: 82 | AA93: 155 | AB93: 0 | AC93: 0 | AD93: 0 | AE93: 0 | AF93: 0 | AG93: 100 | AH93: 121 | AI93: 0 | AK93: =SUM(F93:AJ93) -> 870 | AL93: 46.371513 | AM93: =AK93*AL93/100 -> 403.43217 | AN93: C.
A94: 78 | B94: 78 | D94: ='Chấm công KT'!D90 -> T. Ta. | F94: 0 | G94: 0 | H94: 0 | I94: 0 | J94: 0 | K94: 0 | L94: 0 | M94: 0 | N94: 0 | O94: 0 | P94: 0 | Q94: 0 | R94: 0 | S94: 0 | T94: 0 | U94: 0 | V94: 144 | W94: 0 | X94: 68 | Y94: 0 | Z94: 119 | AA94: 84 | AB94: 131 | AC94: 0 | AD94: 0 | AE94: 0 | AF94: 0 | AG94: 93 | AH94: 78 | AI94: 0 | AK94: =SUM(F94:AJ94) -> 717 | AL94: 46.371513 | AM94: =AK94*AL94/100 -> 332.48375 | AN94: C.
A95: 79 | B95: 79 | D95: ='Chấm công KT'!D91 -> N. Nang | F95: 0 | G95: 0 | H95: 0 | I95: 0 | J95: 0 | K95: 0 | L95: 0 | M95: 0 | N95: 0 | O95: 0 | P95: 0 | Q95: 0 | R95: 0 | S95: 0 | T95: 0 | U95: 0 | V95: 0 | W95: 0 | X95: 76 | Y95: 80 | Z95: 120 | AA95: 0 | AB95: 121 | AC95: 0 | AD95: 0 | AE95: 0 | AF95: 0 | AG95: 0 | AH95: 80 | AI95: 0 | AK95: =SUM(F95:AJ95) -> 477 | AL95: 46.371513 | AM95: =AK95*AL95/100 -> 221.19212 | AN95: C.
A96: 80 | B96: 80 | D96: ='Chấm công KT'!D92 -> T. Tan | F96: 0 | G96: 0 | H96: 0 | I96: 0 | J96: 0 | K96: 0 | L96: 0 | M96: 0 | N96: 0 | O96: 0 | P96: 0 | Q96: 0 | R96: 0 | S96: 0 | T96: 0 | U96: 0 | V96: 0 | W96: 0 | X96: 0 | Y96: 80 | Z96: 119 | AA96: 0 | AB96: 152 | AC96: 0 | AD96: 0 | AE96: 0 | AF96: 0 | AG96: 0 | AH96: 0 | AI96: 0 | AK96: =SUM(F96:AJ96) -> 351 | AL96: 46.371513 | AM96: =AK96*AL96/100 -> 162.76401 | AN96: C.
A97: 81 | B97: 81 | D97: ='Chấm công KT'!D93 -> T. Tu | F97: 0 | G97: 0 | H97: 0 | I97: 0 | J97: 0 | K97: 0 | L97: 0 | M97: 0 | N97: 0 | O97: 0 | P97: 0 | Q97: 0 | R97: 0 | S97: 0 | T97: 0 | U97: 0 | V97: 0 | W97: 0 | X97: 0 | Y97: 0 | Z97: 120 | AA97: 0 | AB97: 152 | AC97: 0 | AD97: 0 | AE97: 0 | AF97: 0 | AG97: 0 | AH97: 0 | AI97: 0 | AK97: =SUM(F97:AJ97) -> 272 | AL97: 46.371513 | AM97: =AK97*AL97/100 -> 126.13052 | AN97: C.
A98: Tram 2 | F98: =SUM(F99:F160) -> 4989 | G98: =SUM(G99:G160) -> 3957 | H98: =SUM(H99:H160) -> 2998 | I98: =SUM(I99:I160) -> 5483 | J98: =SUM(J99:J160) -> 5090 | K98: =SUM(K99:K160) -> 3780 | L98: =SUM(L99:L160) -> 5743 | M98: =SUM(M99:M160) -> 9622 | ... AI98: =SUM(AI99:AI160) -> 4649 | AK98: =SUM(AK99:AK160) -> 158146 | AM98: =SUM(AM99:AM160) -> 73024.987
A99: 82 | B99: 1 | C99: ='Chấm công KT'!C95 -> 04072 | D99: ='Chấm công KT'!D95 -> T. Lun | F99: 88 | G99: 116 | H99: 43 | I99: 51 | J99: 84 | K99: 115 | L99: 31 | M99: 109 | N99: 174 | O99: 121 | P99: 122 | Q99: 78 | R99: 136 | S99: 105 | T99: 0 | U99: 0 | V99: 98 | W99: 60 | X99: 69 | Y99: 101 | Z99: 102 | AA99: 207 | AB99: 46 | AC99: 68 | AD99: 125 | AE99: 120 | AF99: 0 | AG99: 44 | AH99: 82 | AI99: 106 | AK99: =SUM(F99:AJ99) -> 2601 | AL99: 46.175678 | AM99: =AK99*AL99/100 -> 1201.0294 | AN99: A
A100: 83 | B100: 2 | C100: ='Chấm công KT'!C96 -> 03466 | D100: ='Chấm công KT'!D96 -> N. Keo | F100: 0 | G100: 74 | H100: 61 | I100: 151 | J100: 0 | K100: 45 | L100: 167 | M100: 165 | N100: 260 | O100: 84 | P100: 151 | Q100: 158 | R100: 0 | S100: 44 | T100: 0 | U100: 0 | V100: 218 | W100: 0 | X100: 139 | Y100: 196 | Z100: 118 | AA100: 130 | AB100: 118 | AC100: 111 | AD100: 124 | AE100: 67 | AF100: 109 | AG100: 103 | AH100: 0 | AI100: 70 | AK100: =SUM(F100:AJ100) -> 2863 | AL100: 46.175678 | AM100: =AK100*AL100/100 -> 1322.0096 | AN100: B
A101: 84 | B101: 3 | C101: ='Chấm công KT'!C97 -> 03590 | D101: ='Chấm công KT'!D97 -> T .Nhum | F101: 91 | G101: 64 | H101: 66 | I101: 71 | J101: 88 | K101: 70 | L101: 116 | M101: 127 | N101: 212 | O101: 91 | P101: 95 | Q101: 141 | R101: 0 | S101: 0 | T101: 0 | U101: 59 | V101: 229 | W101: 121 | X101: 64 | Y101: 0 | Z101: 123 | AA101: 139 | AB101: 68 | AC101: 73 | AD101: 124 | AE101: 93 | AF101: 46 | AG101: 59 | AH101: 117 | AI101: 0 | AK101: =SUM(F101:AJ101) -> 2547 | AL101: 46.175678 | AM101: =AK101*AL101/100 -> 1176.0945 | AN101: A
A102: 85 | B102: 4 | C102: ='Chấm công KT'!C98 -> 03591 | D102: ='Chấm công KT'!D98 -> N.Vông Ma Ni | F102: 89 | G102: 150 | H102: 74 | I102: 83 | J102: 77 | K102: 77 | L102: 90 | M102: 153 | N102: 151 | O102: 108 | P102: 89 | Q102: 0 | R102: 140 | S102: 0 | T102: 0 | U102: 177 | V102: 101 | W102: 176 | X102: 63 | Y102: 81 | Z102: 100 | AA102: 173 | AB102: 48 | AC102: 85 | AD102: 80 | AE102: 128 | AF102: 54 | AG102: 81 | AH102: 102 | AI102: 168 | AK102: =SUM(F102:AJ102) -> 2898 | AL102: 46.175678 | AM102: =AK102*AL102/100 -> 1338.1711 | AN102: A
A103: 86 | B103: 5 | C103: ='Chấm công KT'!C99 -> 03592 | D103: ='Chấm công KT'!D99 -> Đao Hương | F103: 88 | G103: 134 | H103: 60 | I103: 87 | J103: 100 | K103: 112 | L103: 107 | M103: 172 | N103: 156 | O103: 121 | P103: 92 | Q103: 0 | R103: 156 | S103: 0 | T103: 0 | U103: 183 | V103: 82 | W103: 182 | X103: 64 | Y103: 69 | Z103: 104 | AA103: 198 | AB103: 51 | AC103: 92 | AD103: 86 | AE103: 169 | AF103: 54 | AG103: 83 | AH103: 79 | AI103: 133 | AK103: =SUM(F103:AJ103) -> 3014 | AL103: 46.175678 | AM103: =AK103*AL103/100 -> 1391.7349 | AN103: A
A104: 87 | B104: 6 | C104: ='Chấm công KT'!C100 -> 03593 | D104: ='Chấm công KT'!D100 -> T. Xi Nun | F104: 76 | G104: 100 | H104: 68 | I104: 128 | J104: 158 | K104: 72 | L104: 116 | M104: 198 | N104: 184 | O104: 0 | P104: 60 | Q104: 121 | R104: 0 | S104: 0 | T104: 0 | U104: 0 | V104: 123 | W104: 79 | X104: 33 | Y104: 0 | Z104: 0 | AA104: 137 | AB104: 0 | AC104: 100 | AD104: 219 | AE104: 115 | AF104: 0 | AG104: 94 | AH104: 102 | AI104: 0 | AK104: =SUM(F104:AJ104) -> 2283 | AL104: 46.175678 | AM104: =AK104*AL104/100 -> 1054.1907 | AN104: B
...

Sheet BTH mủ Sỉum
A1: CỘNG HÒA DÂN CHỦ NHÂN DÂN LÀO
A2: Hòa Bình -Độc Lập - Dân Chủ - thống Nhất - Thịnh Vượng
A3: -----o0o-----
A5: CÔNG TY TNHH MTV QUASA - GERUCO LÀO
A6: ĐỘI SẢN XUẤT SỐ 4
A12: BẢNG THEO DÕI SẢN LƯỢNG MỦ SERUM THÁNG 06 NĂM 2025
AK13: DRC
A14: Stt | B14: Họ và tên | C14: Ngày | AH14: Tổng mủ Xirum | AI14: DRC bình quân | AJ14: Quy khô | AK14: Xếp hạng kỹ thuật | AL14: Kí tên
C15: 1 | D15: 2 | E15: 3 | F15: 4 | G15: 5 | H15: 6 | I15: 7 | J15: 8 | K15: 9 | L15: 10 | M15: 11 | N15: 12 | O15: 13 | P15: 14 | Q15: 15 | R15: 16 | S15: 17 | T15: 18 | U15: 19 | V15: 20 | W15: 21 | X15: 22 | Y15: 23 | Z15: 24 | AA15: 25 | AB15: 26 | AC15: 27 | AD15: 28 | AE15: 29 | AF15: 30
A16: Trạm 1 | C16: =C17 -> 0 | D16: =D17 -> 0 | E16: =E17 -> 0 | F16: =F17 -> 0 | G16: =G17 -> 0 | H16: =H17 -> 0 | I16: =I17 -> 0 | J16: =J17 -> 0 | ... AF16: =AF17 -> 0 | AH16: =AH17 -> 0 | AJ16: =AJ17 -> 0 | AK16: =AK17 -> 0
A17: 1 | B17: Mủ Xirum | AH17: =SUM(C17:AG17) -> 0 | AI17: 48.216842 | AJ17: =AH17*AI17/100 -> 0
A18: Trạm 2 | C18: =C19 -> 0 | D18: =D19 -> 0 | E18: =E19 -> 0 | F18: =F19 -> 0 | G18: =G19 -> 0 | H18: =H19 -> 0 | I18: =I19 -> 0 | J18: =J19 -> 0 | ... AF18: =AF19 -> 0 | AH18: =AH19 -> 0 | AJ18: =AJ19 -> 0
A19: 1 | B19: Mủ Xirum | AH19: =SUM(C19:AG19) -> 0 | AI19: 44.235 | AJ19: =AH19*AI19/100 -> 0
A20: Tổng cộng | AE20: =AE16+AE18 -> 0 | AF20: =AF16+AF18 -> 0 | AG20: =AG16+AG18 -> 0 | AH20: =AH16+AH18 -> 0 | AI20: =AI16+AI18 -> 0 | AJ20: =AJ16+AJ18 -> 0 | AK20: =AK16+AK18+#REF!+#REF! -> #REF!
Y22: Mường phìn, ngày 02 tháng 06 năm 2025
A23: TỔNG GIÁM ĐỐC PHÒNG KT - NN P. PHÒNG PHỤ TRÁCH ĐỘI TRƯỞNG NGƯỜI LẬP

Sheet TONGHOPCONGDOI
A2: CÔNG TY TNHH CỔ PHẦN QUASA - GERUCO | R2: CỘNG HÒA DÂN CHỦ NHÂN DÂN LÀO
A3: NÔNG TRƯỜNG 2 | N3: =144/0.67 -> 214.92537 | R3: Hòa Bình - Độc Lập - Dân Chủ - Thống Nhất - Thịnh Vượng
A4: Đội: 1.2.3.4 | J4: =F11*25000 -> 0 | K4: =G11*25000 -> 0 | T4: =Q9-19035.02 -> -16832.72
A5: BẢNG TỔNG HỢP CÔNG THỰC HIỆN THÁNG 01 NĂM 2025
A6: STT | B6: Mã số nhân viên | C6: Họ và Tên Lào | D6: Chức vụ
E7: Bôi thuốc kích thích | F7: Bôi thuốc loét sọc | G7: Phun cỏ đại trà | H7: Phát chồi đại trà | I7: Thiết kế miệng cạo ngữa | J7: Rút máng | K7: Cột kiềng | L7: Xả miệng cạo ngữa | M7: Phát chồi đại trà | N7: Gom chén | P7: Thổi lá hàng 3m | Q7: Tổng công | R7: Sản lượng mủ | V7: Các khoản PC | AC7: Tổng cộng | AD7: Xếp loại KT tính lương | AE7: Xác Nhận
R8: Mủ tạp | S8: Mủ Xirum | T8: Quy khô DRC=50 | U8: Tổng sản lượng mủ tạp+mủ dây quy khô | V8: Ngày công đi cạo thường (x) | W8: Ngày CN thường (cn) | X8: Ngày công đi cạo 2 lát (đ) | Y8: Ngày công chủ nhật cạo 2 lát (đc) | Z8: Ngày công cạo gia tăng 2 miêng (gt) | AA8: Ngày chủ nhật cạo gia tăng 2 miệng (ct) | AB8: Phụ cấp nhỏ a xít | AI8: =5308.01-Q9 -> 3105.71
A9: I | B9: VC KINH DOANH NĂM | E9: =E10+E95 -> 419.2 | F9: =F10+F95 -> 50.4 | G9: =G10+G95 -> 254.7 | H9: =H10+H95 -> 1340.8 | I9: =I10+I95 -> 0 | J9: =J10+J95 -> 0 | K9: =K10+K95 -> 0 | L9: =L10+L95 -> 0 | ... AC9: =AC10+AC95 -> 2202.3 | AF9: 6716.8 | AG9: =6716.8-Q9 -> 4514.5
A10: A | B10: Đội I | E10: =SUM(E11:E94) -> 233.6 | F10: =SUM(F11:F94) -> 3.2 | G10: =SUM(G11:G94) -> 0 | H10: =SUM(H11:H94) -> 431.16 | I10: =SUM(I11:I94) -> 0 | J10: =SUM(J11:J94) -> 0 | K10: =SUM(K11:K94) -> 0 | L10: =SUM(L11:L94) -> 0 | ... AC10: =SUM(AC11:AC94) -> 805.16 | AF10: 1618 | AG10: 194
A11: 1 | B11: ='Chấm công KT'!C13 -> 03456 | C11: ='Chấm công KT'!D13 -> T. Vôn | D11: CN-KT | E11: =4/1.25 -> 3.2 | Q11: =SUM(E11:P11) -> 3.2 | R11: =VLOOKUP(C11,'BTH mủ tạp'!D17:AK97,34,0) -> 1135 | T11: =S11*50/100 -> 0 | U11: =R11 -> 1135 | V11: =VLOOKUP(C11,'Chấm công KT'!D13:AK93,34,0) -> 12 | W11: =VLOOKUP(C11,'Chấm công KT'!D13:AL93,35,0) -> 2 | Z11: =VLOOKUP(C11,'Chấm công KT'!$D$13:$AO$92,38,0) -> 0 | AA11: =VLOOKUP(C11,'Chấm công KT'!$D$13:$AP$92,39,0) -> 0 | AC11: =Q11 -> 3.2 | AD11: =VLOOKUP(C11,'BTH mủ tạp'!$D$17:$AN$160,36,0) -> 526.31668
A12: 2 | B12: ='Chấm công KT'!C14 -> 04052 | C12: ='Chấm công KT'!D14 -> T. Feng | D12: CN-KT | E12: =4/1.25 -> 3.2 | Q12: =SUM(E12:P12) -> 3.2 | R12: =VLOOKUP(C12,'BTH mủ tạp'!D18:AK98,34,0) -> 1955 | T12: =S12*50/100 -> 0 | U12: =R12 -> 1955 | V12: =VLOOKUP(C12,'Chấm công KT'!D14:AK94,34,0) -> 21 | W12: =VLOOKUP(C12,'Chấm công KT'!D14:AL94,35,0) -> 4 | Z12: =VLOOKUP(C12,'Chấm công KT'!$D$13:$AO$92,38,0) -> 0 | AA12: =VLOOKUP(C12,'Chấm công KT'!$D$13:$AP$92,39,0) -> 0 | AC12: =Q12 -> 3.2 | AD12: =VLOOKUP(C12,'BTH mủ tạp'!$D$17:$AN$160,36,0) -> 906.56309
A13: 3 | B13: ='Chấm công KT'!C15 -> 02725 | C13: ='Chấm công KT'!D15 -> T. Sa Văn | D13: CN-KT | E13: =4/1.25 -> 3.2 | Q13: =SUM(E13:P13) -> 3.2 | R13: =VLOOKUP(C13,'BTH mủ tạp'!D19:AK99,34,0) -> 1903 | T13: =S13*50/100 -> 0 | U13: =R13 -> 1903 | V13: =VLOOKUP(C13,'Chấm công KT'!D15:AK95,34,0) -> 19 | W13: =VLOOKUP(C13,'Chấm công KT'!D15:AL95,35,0) -> 5 | Z13: =VLOOKUP(C13,'Chấm công KT'!$D$13:$AO$92,38,0) -> 0 | AA13: =VLOOKUP(C13,'Chấm công KT'!$D$13:$AP$92,39,0) -> 0 | AC13: =Q13 -> 3.2 | AD13: =VLOOKUP(C13,'BTH mủ tạp'!$D$17:$AN$160,36,0) -> 882.4499 | AG13: 119657 | AH13: 197
A14: 4 | B14: ='Chấm công KT'!C16 -> 04053 | C14: ='Chấm công KT'!D16 -> Lăm Ma Thu | D14: CN-KT | E14: =4/1.25 -> 3.2 | Q14: =SUM(E14:P14) -> 3.2 | R14: =VLOOKUP(C14,'BTH mủ tạp'!D20:AK100,34,0) -> 2145 | T14: =S14*50/100 -> 0 | U14: =R14 -> 2145 | V14: =VLOOKUP(C14,'Chấm công KT'!D16:AK96,34,0) -> 20 | W14: =VLOOKUP(C14,'Chấm công KT'!D16:AL96,35,0) -> 5 | Z14: =VLOOKUP(C14,'Chấm công KT'!$D$13:$AO$92,38,0) -> 0 | AA14: =VLOOKUP(C14,'Chấm công KT'!$D$13:$AP$92,39,0) -> 0 | AC14: =Q14 -> 3.2 | AD14: =VLOOKUP(C14,'BTH mủ tạp'!$D$17:$AN$160,36,0) -> 994.66896 | AG14: 125408 | AH14: 554
A15: 5 | B15: ='Chấm công KT'!C17 -> 03459 | C15: ='Chấm công KT'!D17 -> N. Vạt | D15: CN-KT | E15: =4/1.25 -> 3.2 | Q15: =SUM(E15:P15) -> 3.2 | R15: =VLOOKUP(C15,'BTH mủ tạp'!D21:AK101,34,0) -> 2015 | T15: =S15*50/100 -> 0 | U15: =R15 -> 2015 | V15: =VLOOKUP(C15,'Chấm công KT'!D17:AK97,34,0) -> 19 | W15: =VLOOKUP(C15,'Chấm công KT'!D17:AL97,35,0) -> 4 | Z15: =VLOOKUP(C15,'Chấm công KT'!$D$13:$AO$92,38,0) -> 0 | AA15: =VLOOKUP(C15,'Chấm công KT'!$D$13:$AP$92,39,0) -> 0 | AC15: =Q15 -> 3.2 | AD15: =VLOOKUP(C15,'BTH mủ tạp'!$D$17:$AN$160,36,0) -> 934.386 | AG15: 97048 | AH15: 92
A16: 6 | B16: ='Chấm công KT'!C18 -> 04054 | C16: ='Chấm công KT'!D18 -> N. Kay Son | D16: CN-KT | E16: =4/1.25 -> 3.2 | Q16: =SUM(E16:P16) -> 3.2 | R16: =VLOOKUP(C16,'BTH mủ tạp'!D22:AK102,34,0) -> 2401 | T16: =S16*50/100 -> 0 | U16: =R16 -> 2401 | V16: =VLOOKUP(C16,'Chấm công KT'!D18:AK98,34,0) -> 20 | W16: =VLOOKUP(C16,'Chấm công KT'!D18:AL98,35,0) -> 4 | Z16: =VLOOKUP(C16,'Chấm công KT'!$D$13:$AO$92,38,0) -> 0 | AA16: =VLOOKUP(C16,'Chấm công KT'!$D$13:$AP$92,39,0) -> 0 | AC16: =Q16 -> 3.2 | AD16: =VLOOKUP(C16,'BTH mủ tạp'!$D$17:$AN$160,36,0) -> 1113.38 | AG16: 46179
A17: 7 | B17: ='Chấm công KT'!C19 -> 04055 | C17: ='Chấm công KT'!D19 -> T. Đèng 1 | D17: CN-KT | E17: =4/1.25 -> 3.2 | Q17: =SUM(E17:P17) -> 3.2 | R17: =VLOOKUP(C17,'BTH mủ tạp'!D23:AK103,34,0) -> 1993 | T17: =S17*50/100 -> 0 | U17: =R17 -> 1993 | V17: =VLOOKUP(C17,'Chấm công KT'!D19:AK99,34,0) -> 23 | W17: =VLOOKUP(C17,'Chấm công KT'!D19:AL99,35,0) -> 5 | Z17: =VLOOKUP(C17,'Chấm công KT'!$D$13:$AO$92,38,0) -> 0 | AA17: =VLOOKUP(C17,'Chấm công KT'!$D$13:$AP$92,39,0) -> 0 | AC17: =Q17 -> 3.2 | AD17: =VLOOKUP(C17,'BTH mủ tạp'!$D$17:$AN$160,36,0) -> 924.18426
A18: 8 | B18: ='Chấm công KT'!C20 -> 03462 | C18: ='Chấm công KT'!D20 -> T . Bua Ngân | D18: CN-KT | E18: =4/1.25 -> 3.2 | Q18: =SUM(E18:P18) -> 3.2 | R18: =VLOOKUP(C18,'BTH mủ tạp'!D24:AK104,34,0) -> 2333 | T18: =S18*50/100 -> 0 | U18: =R18 -> 2333 | V18: =VLOOKUP(C18,'Chấm công KT'!D20:AK100,34,0) -> 23 | W18: =VLOOKUP(C18,'Chấm công KT'!D20:AL100,35,0) -> 5 | Z18: =VLOOKUP(C18,'Chấm công KT'!$D$13:$AO$92,38,0) -> 0 | AA18: =VLOOKUP(C18,'Chấm công KT'!$D$13:$AP$92,39,0) -> 0 | AC18: =Q18 -> 3.2 | AD18: =VLOOKUP(C18,'BTH mủ tạp'!$D$17:$AN$160,36,0) -> 1081.8474 | AI18: =1155.43-Q9 -> -1046.87
A19: 9 | B19: ='Chấm công KT'!C21 -> 03463 | C19: ='Chấm công KT'!D21 -> T Căng | D19: CN-KT | E19: =4/1.25 -> 3.2 | Q19: =SUM(E19:P19) -> 3.2 | R19: =VLOOKUP(C19,'BTH mủ tạp'!D25:AK105,34,0) -> 2885 | T19: =S19*50/100 -> 0 | U19: =R19 -> 2885 | V19: =VLOOKUP(C19,'Chấm công KT'!D21:AK101,34,0) -> 23 | W19: =VLOOKUP(C19,'Chấm công KT'!D21:AL101,35,0) -> 5 | Z19: =VLOOKUP(C19,'Chấm công KT'!$D$13:$AO$92,38,0) -> 0 | AA19: =VLOOKUP(C19,'Chấm công KT'!$D$13:$AP$92,39,0) -> 0 | AC19: =Q19 -> 3.2 | AD19: =VLOOKUP(C19,'BTH mủ tạp'!$D$17:$AN$160,36,0) -> 1337.8182
A20: 10 | B20: ='Chấm công KT'!C22 -> 03464 | C20: ='Chấm công KT'!D22 -> N. Phôn 1 | D20: CN-KT | E20: =4/1.25 -> 3.2 | Q20: =SUM(E20:P20) -> 3.2 | R20: =VLOOKUP(C20,'BTH mủ tạp'!D26:AK106,34,0) -> 2848 | T20: =S20*50/100 -> 0 | U20: =R20 -> 2848 | V20: =VLOOKUP(C20,'Chấm công KT'!D22:AK102,34,0) -> 23 | W20: =VLOOKUP(C20,'Chấm công KT'!D22:AL102,35,0) -> 5 | Z20: =VLOOKUP(C20,'Chấm công KT'!$D$13:$AO$92,38,0) -> 0 | AA20: =VLOOKUP(C20,'Chấm công KT'!$D$13:$AP$92,39,0) -> 0 | AC20: =Q20 -> 3.2 | AD20: =VLOOKUP(C20,'BTH mủ tạp'!$D$17:$AN$160,36,0) -> 1320.6607 | AG20: =Q9 -> 2202.3
A21: 11 | B21: ='Chấm công KT'!C23 -> 03465 | C21: ='Chấm công KT'!D23 -> T. In Păn | D21: CN-KT | E21: =4/1.25 -> 3.2 | Q21: =SUM(E21:P21) -> 3.2 | R21: =VLOOKUP(C21,'BTH mủ tạp'!D27:AK107,34,0) -> 2182 | T21: =S21*50/100 -> 0 | U21: =R21 -> 2182 | V21: =VLOOKUP(C21,'Chấm công KT'!D23:AK103,34,0) -> 20 | W21: =VLOOKUP(C21,'Chấm công KT'!D23:AL103,35,0) -> 5 | Z21: =VLOOKUP(C21,'Chấm công KT'!$D$13:$AO$92,38,0) -> 0 | AA21: =VLOOKUP(C21,'Chấm công KT'!$D$13:$AP$92,39,0) -> 0 | AC21: =Q21 -> 3.2 | AD21: =VLOOKUP(C21,'BTH mủ tạp'!$D$17:$AN$160,36,0) -> 1011.8264 | AG21: =AG20-2544.38 -> -342.08
A22: 12 | B22: ='Chấm công KT'!C24 -> 03466 | C22: ='Chấm công KT'!D24 -> N. Keo | D22: CN-KT | E22: =4/1.25 -> 3.2 | Q22: =SUM(E22:P22) -> 3.2 | R22: =VLOOKUP(C22,'BTH mủ tạp'!D28:AK108,34,0) -> 3179 | T22: =S22*50/100 -> 0 | U22: =R22 -> 3179 | V22: =VLOOKUP(C22,'Chấm công KT'!D24:AK104,34,0) -> 23 | W22: =VLOOKUP(C22,'Chấm công KT'!D24:AL104,35,0) -> 5 | Z22: =VLOOKUP(C22,'Chấm công KT'!$D$13:$AO$92,38,0) -> 0 | AA22: =VLOOKUP(C22,'Chấm công KT'!$D$13:$AP$92,39,0) -> 0 | AC22: =Q22 -> 3.2 | AD22: =VLOOKUP(C22,'BTH mủ tạp'!$D$17:$AN$160,36,0) -> 1474.1504 | AG22: =AG21-6.33 -> -348.41
A23: 13 | B23: ='Chấm công KT'!C25 -> 02727 | C23: ='Chấm công KT'!D25 -> T. Thong Đon | D23: CN-KT | E23: =4/1.25 -> 3.2 | Q23: =SUM(E23:P23) -> 3.2 | R23: =VLOOKUP(C23,'BTH mủ tạp'!D29:AK109,34,0) -> 2523 | T23: =S23*50/100 -> 0 | U23: =R23 -> 2523 | V23: =VLOOKUP(C23,'Chấm công KT'!D25:AK105,34,0) -> 20 | W23: =VLOOKUP(C23,'Chấm công KT'!D25:AL105,35,0) -> 5 | Z23: =VLOOKUP(C23,'Chấm công KT'!$D$13:$AO$92,38,0) -> 0 | AA23: =VLOOKUP(C23,'Chấm công KT'!$D$13:$AP$92,39,0) -> 0 | AC23: =Q23 -> 3.2 | AD23: =VLOOKUP(C23,'BTH mủ tạp'!$D$17:$AN$160,36,0) -> 1169.9533
A24: 14 | B24: ='Chấm công KT'!C26 -> 03467 | C24: ='Chấm công KT'!D26 -> T. Hin | D24: CN-KT | E24: =4/1.25 -> 3.2 | Q24: =SUM(E24:P24) -> 3.2 | R24: =VLOOKUP(C24,'BTH mủ tạp'!D30:AK110,34,0) -> 2309 | T24: =S24*50/100 -> 0 | U24: =R24 -> 2309 | V24: =VLOOKUP(C24,'Chấm công KT'!D26:AK106,34,0) -> 22 | W24: =VLOOKUP(C24,'Chấm công KT'!D26:AL106,35,0) -> 5 | Z24: =VLOOKUP(C24,'Chấm công KT'!$D$13:$AO$92,38,0) -> 0 | AA24: =VLOOKUP(C24,'Chấm công KT'!$D$13:$AP$92,39,0) -> 0 | AC24: =Q24 -> 3.2 | AD24: =VLOOKUP(C24,'BTH mủ tạp'!$D$17:$AN$160,36,0) -> 1070.7182
A25: 15 | B25: ='Chấm công KT'!C27 -> 04056 | C25: ='Chấm công KT'!D27 -> N. Ly Phon | D25: CN-KT | E25: =4/1.25 -> 3.2 | Q25: =SUM(E25:P25) -> 3.2 | R25: =VLOOKUP(C25,'BTH mủ tạp'!D31:AK111,34,0) -> 1650 | T25: =S25*50/100 -> 0 | U25: =R25 -> 1650 | V25: =VLOOKUP(C25,'Chấm công KT'!D27:AK107,34,0) -> 19 | W25: =VLOOKUP(C25,'Chấm công KT'!D27:AL107,35,0) -> 4 | Z25: =VLOOKUP(C25,'Chấm công KT'!$D$13:$AO$92,38,0) -> 0 | AA25: =VLOOKUP(C25,'Chấm công KT'!$D$13:$AP$92,39,0) -> 0 | AC25: =Q25 -> 3.2 | AD25: =VLOOKUP(C25,'BTH mủ tạp'!$D$17:$AN$160,36,0) -> 765.12997
A26: 16 | B26: ='Chấm công KT'!C28 -> 03469 | C26: ='Chấm công KT'!D28 -> T. Xôm Va Nít | D26: CN-KT | E26: =4/1.25 -> 3.2 | Q26: =SUM(E26:P26) -> 3.2 | R26: =VLOOKUP(C26,'BTH mủ tạp'!D32:AK112,34,0) -> 3122 | T26: =S26*50/100 -> 0 | U26: =R26 -> 3122 | V26: =VLOOKUP(C26,'Chấm công KT'!D28:AK108,34,0) -> 23 | W26: =VLOOKUP(C26,'Chấm công KT'!D28:AL108,35,0) -> 5 | Z26: =VLOOKUP(C26,'Chấm công KT'!$D$13:$AO$92,38,0) -> 0 | AA26: =VLOOKUP(C26,'Chấm công KT'!$D$13:$AP$92,39,0) -> 0 | AC26: =Q26 -> 3.2 | AD26: =VLOOKUP(C26,'BTH mủ tạp'!$D$17:$AN$160,36,0) -> 1447.7186
A27: 17 | B27: ='Chấm công KT'!C29 -> 03470 | C27: ='Chấm công KT'!D29 -> T. Lọi | D27: CN-KT | E27: =4/1.25 -> 3.2 | Q27: =SUM(E27:P27) -> 3.2 | R27: =VLOOKUP(C27,'BTH mủ tạp'!D33:AK113,34,0) -> 2112 | T27: =S27*50/100 -> 0 | U27: =R27 -> 2112 | V27: =VLOOKUP(C27,'Chấm công KT'!D29:AK109,34,0) -> 19 | W27: =VLOOKUP(C27,'Chấm công KT'!D29:AL109,35,0) -> 4 | Z27: =VLOOKUP(C27,'Chấm công KT'!$D$13:$AO$92,38,0) -> 0 | AA27: =VLOOKUP(C27,'Chấm công KT'!$D$13:$AP$92,39,0) -> 0 | AC27: =Q27 -> 3.2 | AD27: =VLOOKUP(C27,'BTH mủ tạp'!$D$17:$AN$160,36,0) -> 979.36636
A28: 18 | B28: ='Chấm công KT'!C30 -> 03471 | C28: ='Chấm công KT'!D30 -> T. Phô Thong | D28: CN-KT | E28: =4/1.25 -> 3.2 | Q28: =SUM(E28:P28) -> 3.2 | R28: =VLOOKUP(C28,'BTH mủ tạp'!D34:AK114,34,0) -> 2729 | T28: =S28*50/100 -> 0 | U28: =R28 -> 2729 | V28: =VLOOKUP(C28,'Chấm công KT'!D30:AK110,34,0) -> 23 | W28: =VLOOKUP(C28,'Chấm công KT'!D30:AL110,35,0) -> 5 | Z28: =VLOOKUP(C28,'Chấm công KT'!$D$13:$AO$92,38,0) -> 0 | AA28: =VLOOKUP(C28,'Chấm công KT'!$D$13:$AP$92,39,0) -> 0 | AC28: =Q28 -> 3.2 | AD28: =VLOOKUP(C28,'BTH mủ tạp'!$D$17:$AN$160,36,0) -> 1265.4786 | AF28: =Q9-10084 -> -7881.7
A29: 19 | B29: ='Chấm công KT'!C31 -> 03472 | C29: ='Chấm công KT'!D31 -> N. Soi | D29: CN-KT | E29: =4/1.25 -> 3.2 | Q29: =SUM(E29:P29) -> 3.2 | R29: =VLOOKUP(C29,'BTH mủ tạp'!D35:AK115,34,0) -> 1472 | T29: =S29*50/100 -> 0 | U29: =R29 -> 1472 | V29: =VLOOKUP(C29,'Chấm công KT'!D31:AK111,34,0) -> 20 | W29: =VLOOKUP(C29,'Chấm công KT'!D31:AL111,35,0) -> 5 | Z29: =VLOOKUP(C29,'Chấm công KT'!$D$13:$AO$92,38,0) -> 0 | AA29: =VLOOKUP(C29,'Chấm công KT'!$D$13:$AP$92,39,0) -> 0 | AC29: =Q29 -> 3.2 | AD29: =VLOOKUP(C29,'BTH mủ tạp'!$D$17:$AN$160,36,0) -> 682.58868
A30: 20 | B30: ='Chấm công KT'!C32 -> 03473 | C30: ='Chấm công KT'!D32 -> N. Me Kha La | D30: CN-KT | E30: =4/1.25 -> 3.2 | Q30: =SUM(E30:P30) -> 3.2 | R30: =VLOOKUP(C30,'BTH mủ tạp'!D36:AK116,34,0) -> 2260 | T30: =S30*50/100 -> 0 | U30: =R30 -> 2260 | V30: =VLOOKUP(C30,'Chấm công KT'!D32:AK112,34,0) -> 19 | W30: =VLOOKUP(C30,'Chấm công KT'!D32:AL112,35,0) -> 5 | Z30: =VLOOKUP(C30,'Chấm công KT'!$D$13:$AO$92,38,0) -> 0 | AA30: =VLOOKUP(C30,'Chấm công KT'!$D$13:$AP$92,39,0) -> 0 | AC30: =Q30 -> 3.2 | AD30: =VLOOKUP(C30,'BTH mủ tạp'!$D$17:$AN$160,36,0) -> 1047.9962
A31: 21 | B31: ='Chấm công KT'!C33 -> 03474 | C31: ='Chấm công KT'!D33 -> N. Mon Khăm | D31: CN-KT | E31: =4/1.25 -> 3.2 | Q31: =SUM(E31:P31) -> 3.2 | R31: =VLOOKUP(C31,'BTH mủ tạp'!D37:AK117,34,0) -> 2248 | T31: =S31*50/100 -> 0 | U31: =R31 -> 2248 | V31: =VLOOKUP(C31,'Chấm công KT'!D33:AK113,34,0) -> 22 | W31: =VLOOKUP(C31,'Chấm công KT'!D33:AL113,35,0) -> 5 | Z31: =VLOOKUP(C31,'Chấm công KT'!$D$13:$AO$92,38,0) -> 0 | AA31: =VLOOKUP(C31,'Chấm công KT'!$D$13:$AP$92,39,0) -> 0 | AC31: =Q31 -> 3.2 | AD31: =VLOOKUP(C31,'BTH mủ tạp'!$D$17:$AN$160,36,0) -> 1042.4316
A32: 22 | B32: ='Chấm công KT'!C34 -> 04057 | C32: ='Chấm công KT'!D34 -> N. Bua Lay | D32: CN-KT | E32: =4/1.25 -> 3.2 | Q32: =SUM(E32:P32) -> 3.2 | R32: =VLOOKUP(C32,'BTH mủ tạp'!D38:AK118,34,0) -> 1824 | T32: =S32*50/100 -> 0 | U32: =R32 -> 1824 | V32: =VLOOKUP(C32,'Chấm công KT'!D34:AK114,34,0) -> 23 | W32: =VLOOKUP(C32,'Chấm công KT'!D34:AL114,35,0) -> 5 | Z32: =VLOOKUP(C32,'Chấm công KT'!$D$13:$AO$92,38,0) -> 0 | AA32: =VLOOKUP(C32,'Chấm công KT'!$D$13:$AP$92,39,0) -> 0 | AC32: =Q32 -> 3.2 | AD32: =VLOOKUP(C32,'BTH mủ tạp'!$D$17:$AN$160,36,0) -> 845.8164
A33: 23 | B33: ='Chấm công KT'!C35 -> 03476 | C33: ='Chấm công KT'!D35 -> T. Bin Ly. | D33: CN-KT | E33: =4/1.25 -> 3.2 | Q33: =SUM(E33:P33) -> 3.2 | R33: =VLOOKUP(C33,'BTH mủ tạp'!D39:AK119,34,0) -> 2609 | T33: =S33*50/100 -> 0 | U33: =R33 -> 2609 | V33: =VLOOKUP(C33,'Chấm công KT'!D35:AK115,34,0) -> 21 | W33: =VLOOKUP(C33,'Chấm công KT'!D35:AL115,35,0) -> 5 | Z33: =VLOOKUP(C33,'Chấm công KT'!$D$13:$AO$92,38,0) -> 0 | AA33: =VLOOKUP(C33,'Chấm công KT'!$D$13:$AP$92,39,0) -> 0 | AC33: =Q33 -> 3.2 | AD33: =VLOOKUP(C33,'BTH mủ tạp'!$D$17:$AN$160,36,0) -> 1209.8328
A34: 24 | B34: ='Chấm công KT'!C36 -> 03477 | C34: ='Chấm công KT'!D36 -> N. Phim Phon. | D34: CN-KT | E34: =4/1.25 -> 3.2 | Q34: =SUM(E34:P34) -> 3.2 | R34: =VLOOKUP(C34,'BTH mủ tạp'!D40:AK120,34,0) -> 1924 | T34: =S34*50/100 -> 0 | U34: =R34 -> 1924 | V34: =VLOOKUP(C34,'Chấm công KT'!D36:AK116,34,0) -> 23 | W34: =VLOOKUP(C34,'Chấm công KT'!D36:AL116,35,0) -> 5 | Z34: =VLOOKUP(C34,'Chấm công KT'!$D$13:$AO$92,38,0) -> 0 | AA34: =VLOOKUP(C34,'Chấm công KT'!$D$13:$AP$92,39,0) -> 0 | AC34: =Q34 -> 3.2 | AD34: =VLOOKUP(C34,'BTH mủ tạp'!$D$17:$AN$160,36,0) -> 892.18792
A35: 25 | B35: ='Chấm công KT'!C37 -> 03478 | C35: ='Chấm công KT'!D37 -> N. Nong | D35: CN-KT | E35: =4/1.25 -> 3.2 | Q35: =SUM(E35:P35) -> 3.2 | R35: =VLOOKUP(C35,'BTH mủ tạp'!D41:AK121,34,0) -> 2449 | T35: =S35*50/100 -> 0 | U35: =R35 -> 2449 | V35: =VLOOKUP(C35,'Chấm công KT'!D37:AK117,34,0) -> 20 | W35: =VLOOKUP(C35,'Chấm công KT'!D37:AL117,35,0) -> 5 | Z35: =VLOOKUP(C35,'Chấm công KT'!$D$13:$AO$92,38,0) -> 0 | AA35: =VLOOKUP(C35,'Chấm công KT'!$D$13:$AP$92,39,0) -> 0 | AC35: =Q35 -> 3.2 | AD35: =VLOOKUP(C35,'BTH mủ tạp'!$D$17:$AN$160,36,0) -> 1135.6384
A36: 26 | B36: ='Chấm công KT'!C38 -> 03479 | C36: ='Chấm công KT'!D38 -> N. Tun 1 | D36: CN-KT | E36: =4/1.25 -> 3.2 | Q36: =SUM(E36:P36) -> 3.2 | R36: =VLOOKUP(C36,'BTH mủ tạp'!D42:AK122,34,0) -> 2717 | T36: =S36*50/100 -> 0 | U36: =R36 -> 2717 | V36: =VLOOKUP(C36,'Chấm công KT'!D38:AK118,34,0) -> 20 | W36: =VLOOKUP(C36,'Chấm công KT'!D38:AL118,35,0) -> 5 | Z36: =VLOOKUP(C36,'Chấm công KT'!$D$13:$AO$92,38,0) -> 0 | AA36: =VLOOKUP(C36,'Chấm công KT'!$D$13:$AP$92,39,0) -> 0 | AC36: =Q36 -> 3.2 | AD36: =VLOOKUP(C36,'BTH mủ tạp'!$D$17:$AN$160,36,0) -> 1259.914
A37: 27 | B37: ='Chấm công KT'!C39 -> 03480 | C37: ='Chấm công KT'!D39 -> T . Lốc | D37: CN-KT | E37: =4/1.25 -> 3.2 | Q37: =SUM(E37:P37) -> 3.2 | R37: =VLOOKUP(C37,'BTH mủ tạp'!D43:AK123,34,0) -> 2702 | T37: =S37*50/100 -> 0 | U37: =R37 -> 2702 | V37: =VLOOKUP(C37,'Chấm công KT'!D39:AK119,34,0) -> 20 | W37: =VLOOKUP(C37,'Chấm công KT'!D39:AL119,35,0) -> 5 | Z37: =VLOOKUP(C37,'Chấm công KT'!$D$13:$AO$92,38,0) -> 0 | AA37: =VLOOKUP(C37,'Chấm công KT'!$D$13:$AP$92,39,0) -> 0 | AC37: =Q37 -> 3.2 | AD37: =VLOOKUP(C37,'BTH mủ tạp'!$D$17:$AN$160,36,0) -> 1252.9583
A38: 28 | B38: ='Chấm công KT'!C40 -> 03481 | C38: ='Chấm công KT'!D40 -> N . Khâm (1) | D38: CN-KT | E38: =4/1.25 -> 3.2 | Q38: =SUM(E38:P38) -> 3.2 | R38: =VLOOKUP(C38,'BTH mủ tạp'!D44:AK124,34,0) -> 3031 | T38: =S38*50/100 -> 0 | U38: =R38 -> 3031 | V38: =VLOOKUP(C38,'Chấm công KT'!D40:AK120,34,0) -> 22 | W38: =VLOOKUP(C38,'Chấm công KT'!D40:AL120,35,0) -> 5 | Z38: =VLOOKUP(C38,'Chấm công KT'!$D$13:$AO$92,38,0) -> 0 | AA38: =VLOOKUP(C38,'Chấm công KT'!$D$13:$AP$92,39,0) -> 0 | AC38: =Q38 -> 3.2 | AD38: =VLOOKUP(C38,'BTH mủ tạp'!$D$17:$AN$160,36,0) -> 1405.5206
A39: 29 | B39: ='Chấm công KT'!C41 -> 03482 | C39: ='Chấm công KT'!D41 -> T . Phết | D39: CN-KT | E39: =4/1.25 -> 3.2 | Q39: =SUM(E39:P39) -> 3.2 | R39: =VLOOKUP(C39,'BTH mủ tạp'!D45:AK125,34,0) -> 3072 | T39: =S39*50/100 -> 0 | U39: =R39 -> 3072 | V39: =VLOOKUP(C39,'Chấm công KT'!D41:AK121,34,0) -> 22 | W39: =VLOOKUP(C39,'Chấm công KT'!D41:AL121,35,0) -> 5 | Z39: =VLOOKUP(C39,'Chấm công KT'!$D$13:$AO$92,38,0) -> 0 | AA39: =VLOOKUP(C39,'Chấm công KT'!$D$13:$AP$92,39,0) -> 0 | AC39: =Q39 -> 3.2 | AD39: =VLOOKUP(C39,'BTH mủ tạp'!$D$17:$AN$160,36,0) -> 1424.5329
