Workbook
Name So_XN: [1]PHATSINH!$B$6:$B$2093

Sheet BẢNG PHÂN TOÁN
A1: CỘNG HÒA DÂN CHỦ NHÂN DÂN LÀO
A2: Hòa bình - Độc lập - Dân chủ - Thống nhất - Thịnh vượng
A3: -----oOo-----
A4: CÔNG TY TNHH CỔ PHẦN QUASA - GERUCO LÀO
A5: ĐỘI SẢN XUẤT SEPON
A8: BẢNG PHÂN TOÁN TIỀN LƯƠNG THÁNG 01 NĂM 2025
A9: Từ ngày 01/01/2025 đến ngày 31/01/2025
I10: Đvt: Kip
A11: STT | B11: Danh mục | C11: Đvt | D11: Số lượng | E11: Sản lượng thực hiện quy khô | F11: Đơn giá | G11: Tổng tiền lương | H11: Tổng tiền thực nhận | I11: Ghi chú
A12: I | B12: Tiền lương kinh doanh | G12: =G13+G32 -> 4.290727e+08 | H12: =H13+H32 -> 3.939927e+08 | K12: Tỷ giá: USD qua Kíp: | L12: 21923
A13: 1 | B13: Tiền lương công nhân trực tiếp | G13: =G14+G23+G31 -> 3.9796625e+08 | H13: =H14+H23+H31 -> 3.6288625e+08
A14: 1.1 | B14: Sản lượng | E14: =+SUM(E15:E22) -> 63154.458 | G14: =H14 -> 2.5060559e+08 | H14: =SUM(H15:H22) -> 2.5060559e+08 | K14: Tỷ giá Bath qua Kíp | L14: 656
B15: Xếp loại kỹ thuật A (đơn giá chuẩn) | C15: Kg | E15: =+SUMIF('BẢNG LƯƠNG KT'!$K$17:$K$69,"A",'BẢNG LƯƠNG KT'!$J$17:$J$69) -> 25897.94 | F15: =6.1*$L$14 -> 4001.6 | G15: =E15*F15 -> 1.036332e+08 | H15: =+E15*F15 -> 1.036332e+08
B16: Xếp loại kỹ thuật B (đơn giá chuẩn) | C16: Kg | E16: =+SUMIF('BẢNG LƯƠNG KT'!$K$17:$K$69,"B",'BẢNG LƯƠNG KT'!$J$17:$J$69) -> 21418.57 | F16: =5.8*$L$14 -> 3804.8 | G16: =E16*F16 -> 81493376 | H16: =+E16*F16 -> 81493376
B17: Xếp loại kỹ thuật C (đơn giá chuẩn) | C17: Kg | E17: =+SUMIF('BẢNG LƯƠNG KT'!$K$17:$K$69,"C",'BẢNG LƯƠNG KT'!$J$17:$J$69) -> 4348.0415 | F17: =5.5*$L$14 -> 3608 | G17: =E17*F17 -> 15687734 | H17: =+E17*F17 -> 15687734
B18: Xếp loại kỹ thuật D (đơn giá chuẩn) | C18: Kg | E18: =+SUMIF('BẢNG LƯƠNG KT'!$K$17:$K$52,"D",'BẢNG LƯƠNG KT'!$J$17:$J$52) -> 0 | F18: =5.2*$L$14 -> 3411.2 | G18: =E18*F18 -> 0 | H18: =+E18*F18 -> 0
B19: Xếp loại kỹ thuật A (đơn giá phụ cấp ) | C19: Kg | E19: =+SUMIF('BẢNG LƯƠNG KT'!$K$72:$K$87,"A",'BẢNG LƯƠNG KT'!$J$72:$J$87) -> 7886.5068 | F19: =+(6.1+0.6)*$L$14 -> 4395.2 | G19: =E19*F19 -> 34662775 | H19: =+E19*F19 -> 34662775
B20: Xếp loại kỹ thuật B (đơn giá phụ cấp ) | C20: Kg | E20: =+SUMIF('BẢNG LƯƠNG KT'!$K$72:$K$87,"B",'BẢNG LƯƠNG KT'!$J$72:$J$87) -> 3603.3992 | F20: =+(5.8+0.6)*$L$14 -> 4198.4 | G20: =E20*F20 -> 15128511 | H20: =+E20*F20 -> 15128511
B21: Xếp loại kỹ thuật C (đơn giá phụ cấp ) | C21: Kg | E21: =+SUMIF('BẢNG LƯƠNG KT'!$K$72:$K$87,"C",'BẢNG LƯƠNG KT'!$J$72:$J$87) -> 0 | F21: =+(5.5+0.6)*$L$14 -> 4001.6 | G21: =E21*F21 -> 0 | H21: =+E21*F21 -> 0
B22: Xếp loại kỹ thuật D (đơn giá phụ cấp ) | C22: Kg | E22: =+SUMIF('BẢNG LƯƠNG KT'!$K$72:$K$87,"D",'BẢNG LƯƠNG KT'!$J$72:$J$87) -> 0 | F22: =+(5.2+0.6)*$L$14 -> 3804.8 | G22: =E22*F22 -> 0 | H22: =+E22*F22 -> 0
A23: 1.2 | B23: Phụ cấp khai thác | C23: Công | D23: =+SUM(D24:D29) -> 3162 | G23: =SUM(G24:G30) -> 1.4736065e+08 | H23: =SUM(H24:H29) -> 1.1228065e+08
B24: Phụ cấp ngày công thường | C24: Ngày | D24: ='BẢNG LƯƠNG KT'!M16+'BẢNG LƯƠNG KT'!M54 -> 1086 | F24: =46.1*'BẢNG PHÂN TOÁN'!$L$14 -> 30241.6 | G24: =D24*F24 -> 32842378 | H24: =D24*F24 -> 32842378
B25: Phụ cấp ngày công chủ nhật | C25: Ngày | D25: ='BẢNG LƯƠNG KT'!N54+'BẢNG LƯƠNG KT'!N16 -> 170 | F25: =76.9*$L$14 -> 50446.4 | G25: =D25*F25 -> 8575888 | H25: =D25*F25 -> 8575888
B26: Phụ cấp ngày công vườn cây non | C26: Ngày | D26: ='BẢNG LƯƠNG KT'!O89 -> 130 | F26: =76.8*'BẢNG PHÂN TOÁN'!$L$14 -> 50380.8 | G26: =D26*F26 -> 6549504 | H26: =D26*F26 -> 6549504
B27: Phụ cấp chủ nhật vườn cây non | C27: Ngày | D27: ='BẢNG LƯƠNG KT'!P89 -> 22 | F27: =107.6*'BẢNG PHÂN TOÁN'!$L$14 -> 70585.6 | G27: =D27*F27 -> 1552883.2 | H27: =D27*F27 -> 1552883.2 | K27: =G13+G32+G35+G36 -> 4.357327e+08
B28: Phụ cấp vùng khó khăn | C28: Ngày | D28: =SUM(D24:D27) -> 1408 | F28: 20000 | G28: =D28*F28 -> 28160000 | H28: =D28*F28 -> 28160000
B29: Phụ cấp ngày công tổ 3 | C29: Ngày | D29: ='BẢNG LƯƠNG KT'!M71+'BẢNG LƯƠNG KT'!N71 -> 346 | F29: 100000 | G29: =D29*F29 -> 34600000 | H29: =D29*F29 -> 34600000 | K29: ='1'!U51+'2'!U35+'3'!S33 -> 3.9796625e+08
B30: Phụ cấp tiền lương tháng 01 | C30: Ngày | D30: ='BẢNG LƯƠNG KT'!R89 -> 1754 | F30: 20000 | G30: =D30*F30 -> 35080000
A31: 1.3 | B31: Tiền lương chăm sóc vườn cây | C31: Công | D31: ='BẢNG LƯƠNG KT'!G89 -> 0 | F31: 25000 | G31: =D31*F31 -> 0 | H31: =+D31*F31 -> 0
A32: 2 | B32: Tiền lương bảo vệ vườn cây | C32: Công | D32: =G32/F32 -> 1244.2581 | F32: 25000 | G32: =BV!U26 -> 31106452 | H32: =+D32*F32 -> 31106452 | K32: =G35 -> 1700000
A33: II | B33: Tiền lương KTCB | C33: Công | D33: =D34 -> 0 | F33: 25000 | G33: =G34 -> 0 | H33: =H34 -> 0
A34: 1 | B34: Vườn cây 2018 | C34: Công | F34: 25000 | G34: =D34*F34 -> 0 | H34: =D34*F34 -> 0
A35: II | B35: Tiền lương tạp vụ | C35: Ngày | D35: ='Tạp vụ'!G13 -> 31 | F35: =G35/D35 -> 54838.71 | G35: 1700000 | H35: =G35-20000 -> 1680000 | K35: ='Phụ cấp người Việt'!F15 -> 4960000
A36: III | B36: Tiền lương phụ cấp CNKT người Việt | C36: Kíp | D36: ='Phụ cấp người Việt'!D15 -> 62 | F36: ='Phụ cấp người Việt'!E12 -> 80000 | G36: ='Phụ cấp người Việt'!F15 -> 4960000 | K36: =G32 -> 31106452
A37: TỔNG CỘNG: | E37: =E14 -> 63154.458 | G37: =G12+G33+G35+G36 -> 4.357327e+08 | H37: =H12+H33+H35 -> 3.956727e+08 | K37: =K29+K36+K32+K35+K30 -> 4.357327e+08
A38: Số tiền bằng chữ: Bốn trăm ba mươi lăm triệu bảy trăm ba mươi hai nghìn sáu trăm chín mươi tám kíp.
G40: Sepon, ngày 03 tháng 02 năm 2025
A41: TỔNG GIÁM ĐỐC PHÒNG TC - KT PHÒNG TC - HC ĐỘI SẢN XUẤT SEPON

Sheet Phụ cấp người Việt
A1: CỘNG HÒA DÂN CHỦ NHÂN DÂN LÀO
A2: Hòa Bình - Độc Lập - Dân Chủ - Thống Nhất - Thịnh Vượng
A3: ----- o0o-----
AA4: =1372+388 -> 1760 | AB4: =AA4*30000 -> 52800000 | AC4: =AB4+#REF!+#REF! -> #REF!
A5: CÔNG TY TNHH CỔ PHẦN QUASA - GERUCO LÀO
A6: ĐỘI SẢN XUẤT SEPON
A8: BẢNG THANH TOÁN TIỀN PHỤ CẤP THÁNG 01 NĂM 2025
I9: ĐVT : Kíp
A10: STT | B10: Tên Công nhân | C10: Chức Vụ | D10: Ngày công | E10: Đơn giá | F10: Thành tiền | G10: Thuế TNCN | H10: Thực nhận | I10: Ký nhận | J10: Ghi chú
A12: 1 | B12: Hồ Văn Tăng | C12: CNKT | D12: ='Chấm công công nhân'!AV73 -> 21 | E12: 80000 | F12: =D12*E12 -> 1680000 | G12: =IF(F12>65000000,((F12-65000000)*25%+10685000),IF(F12>25000000,((F12-25000000)*20%+2685000),IF(F12>15000000,((F12-15000000)*15%+1185000),IF(F12>5000000,(F12-5000000)*10%+185000,IF(F12>1300000,(F12-1300000)*5%,0))))) -> 19000 | H12: =+F12-G12 -> 1661000
A13: 2 | B13: Hồ Văn Khoa | C13: CNKT | D13: ='Chấm công công nhân'!AV74 -> 20 | E13: 80000 | F13: =D13*E13 -> 1600000 | G13: =IF(F13>65000000,((F13-65000000)*25%+10685000),IF(F13>25000000,((F13-25000000)*20%+2685000),IF(F13>15000000,((F13-15000000)*15%+1185000),IF(F13>5000000,(F13-5000000)*10%+185000,IF(F13>1300000,(F13-1300000)*5%,0))))) -> 15000 | H13: =+F13-G13 -> 1585000
A14: 3 | B14: Hồ Xa My | C14: CNKT | D14: ='Chấm công công nhân'!AV75 -> 21 | E14: 80000 | F14: =D14*E14 -> 1680000 | G14: =IF(F14>65000000,((F14-65000000)*25%+10685000),IF(F14>25000000,((F14-25000000)*20%+2685000),IF(F14>15000000,((F14-15000000)*15%+1185000),IF(F14>5000000,(F14-5000000)*10%+185000,IF(F14>1300000,(F14-1300000)*5%,0))))) -> 19000 | H14: =+F14-G14 -> 1661000
A15: Tổng cộng | D15: =SUM(D12:D14) -> 62 | F15: =SUM(F12:F14) -> 4960000 | G15: =SUM(G12:G14) -> 53000 | H15: =SUM(H12:H14) -> 4907000
A16: Số tiền bằng chữ: Bốn triệu chín trăm sáu mươi nghìn kíp.
G17: Sepon, ngày 03 tháng 02 năm 2025
A18: PHÒNG TC - KT | C18: PHÒNG TC - HC | F18: ĐỘI TRƯỞNG ĐỘI SEPON | H18: NGƯỜI LẬP BIỂU

Sheet BẢNG PHÂN TOÁN ĐÚNG
A1: CỘNG HÒA DÂN CHỦ NHÂN DÂN LÀO
A2: Hòa bình - Độc lập - Dân chủ - Thống nhất - Thịnh vượng
A3: -----oOo-----
A4: CÔNG TY TNHH CỔ PHẦN QUASA - GERUCO LÀO
A5: ĐỘI SẢN XUẤT SEPON
A8: BẢNG PHÂN TOÁN TIỀN LƯƠNG THÁNG 10 NĂM 2024
A9: Từ ngày 01/10/2024 đến ngày 31/10/2024
K10: Đvt: Kip
A11: STT | B11: Danh mục | C11: Đvt | D11: Số lượng | E11: Sản lượng thực hiện quy khô | F11: Đơn giá | G11: Tổng tiền lương | H11: Tổng tiền thực nhận | I11: Tiền lương tạm ứng theo sản lượng | J11: Tổng cộng | K11: Ghi chú
A12: I | B12: Tiền lương kinh doanh | G12: 5.4015776e+08 | H12: =H13+H31 -> 0 | I12: =I13+I31 -> 4720954.3 | J12: 5.4487872e+08 | L12: Tỷ giá: USD qua Kíp: | N12: 22036
A13: 1 | B13: Tiền lương công nhân trực tiếp | G13: 5.2975776e+08 | I13: =I14+I23+I30 -> 4720954.3 | J13: 5.3447872e+08
A14: 1.1 | B14: Sản lượng | E14: =+SUM(E15:E22) -> 63154.458 | G14: 3.3068032e+08 | I14: =SUM(I15:I22) -> 4720954.3 | J14: 3.3540128e+08 | L14: Tỷ giá Bath qua Kíp | M14: Tỷ giá Bath qua Kíp | N14: 657.39
B15: Xếp loại kỹ thuật A (đơn giá chuẩn) | C15: Kg | E15: =+SUMIF('BẢNG LƯƠNG KT'!$K$17:$K$69,"A",'BẢNG LƯƠNG KT'!$J$17:$J$69) -> 25897.94 | F15: =6.1*$N$14 -> 4010.079 | G15: 1.7012465e+08 | I15: 2639184.2 | J15: 1.7276383e+08
B16: Xếp loại kỹ thuật B (đơn giá chuẩn) | C16: Kg | E16: =+SUMIF('BẢNG LƯƠNG KT'!$K$17:$K$69,"B",'BẢNG LƯƠNG KT'!$J$17:$J$69) -> 21418.57 | F16: =5.8*$N$14 -> 3812.862 | G16: 1.0566893e+08 | I16: 2081770.1 | J16: 1.077507e+08
B17: Xếp loại kỹ thuật C (đơn giá chuẩn) | C17: Kg | E17: =+SUMIF('BẢNG LƯƠNG KT'!$K$17:$K$69,"C",'BẢNG LƯƠNG KT'!$J$17:$J$69) -> 4348.0415 | F17: =5.5*$N$14 -> 3615.645 | G17: 0 | J17: 0 | M17: =#REF!-#REF! -> #REF!
B18: Xếp loại kỹ thuật D (đơn giá chuẩn) | C18: Kg | E18: =+SUMIF('BẢNG LƯƠNG KT'!$K$17:$K$52,"D",'BẢNG LƯƠNG KT'!$J$17:$J$52) -> 0 | F18: =5.2*$N$14 -> 3418.428 | G18: 0 | J18: 0
B19: Xếp loại kỹ thuật A (đơn giá phụ cấp ) | C19: Kg | E19: =+SUMIF('BẢNG LƯƠNG KT'!$K$72:$K$87,"A",'BẢNG LƯƠNG KT'!$J$72:$J$87) -> 7886.5068 | F19: =+(6.1+0.6)*$N$14 -> 4404.513 | G19: 28570730 | J19: 28570730
B20: Xếp loại kỹ thuật B (đơn giá phụ cấp ) | C20: Kg | E20: =+SUMIF('BẢNG LƯƠNG KT'!$K$72:$K$87,"B",'BẢNG LƯƠNG KT'!$J$72:$J$87) -> 3603.3992 | F20: =+(5.8+0.6)*$N$14 -> 4207.296 | G20: 26316016 | J20: 26316016
B21: Xếp loại kỹ thuật C (đơn giá phụ cấp ) | C21: Kg | E21: =+SUMIF('BẢNG LƯƠNG KT'!$K$72:$K$87,"C",'BẢNG LƯƠNG KT'!$J$72:$J$87) -> 0 | F21: =+(5.5+0.6)*$N$14 -> 4010.079 | G21: 0 | J21: 0
B22: Xếp loại kỹ thuật D (đơn giá phụ cấp ) | C22: Kg | E22: =+SUMIF('BẢNG LƯƠNG KT'!$K$72:$K$87,"D",'BẢNG LƯƠNG KT'!$J$72:$J$87) -> 0 | F22: =+(5.2+0.6)*$N$14 -> 3812.862 | G22: 0 | J22: 0
A23: 1.2 | B23: Phụ cấp khai thác | C23: Công | D23: =+SUM(D24:D29) -> 3162 | G23: 1.1504985e+08 | I23: =SUM(I24:I29) -> 0 | J23: 1.1504985e+08
B24: Phụ cấp ngày công thường | C24: Ngày | D24: ='BẢNG LƯƠNG KT'!M16+'BẢNG LƯƠNG KT'!M54 -> 1086 | F24: =46.1*'BẢNG PHÂN TOÁN ĐÚNG'!$N$14 -> 30305.679 | G24: 35093976 | J24: 35093976
B25: Phụ cấp ngày công chủ nhật | C25: Ngày | D25: ='BẢNG LƯƠNG KT'!N54+'BẢNG LƯƠNG KT'!N16 -> 170 | F25: =76.9*$N$14 -> 50553.291 | G25: 6571927.8 | J25: 6571927.8
B26: Phụ cấp ngày công vườn cây non | C26: Ngày | D26: ='BẢNG LƯƠNG KT'!O89 -> 130 | F26: =76.8*'BẢNG PHÂN TOÁN ĐÚNG'!$N$14 -> 50487.552 | G26: 7977033.2 | J26: 7977033.2
B27: Phụ cấp chủ nhật vườn cây non | C27: Ngày | D27: ='BẢNG LƯƠNG KT'!P89 -> 22 | F27: =107.6*'BẢNG PHÂN TOÁN ĐÚNG'!$N$14 -> 70735.164 | G27: 1626908.8 | J27: 1626908.8 | M27: =G35+I35 -> 5.4718586e+08
B28: Phụ cấp vùng khó khăn | C28: Ngày | D28: =SUM(D24:D27) -> 1408 | F28: 20000 | G28: 29380000 | J28: 29380000
B29: Phụ cấp ngày công tổ 3 | C29: Ngày | D29: ='BẢNG LƯƠNG KT'!M71+'BẢNG LƯƠNG KT'!N71 -> 346 | F29: 100000 | G29: 34400000 | J29: 34400000
A30: 1.3 | B30: Tiền lương chăm sóc vườn cây | C30: Công | D30: ='BẢNG LƯƠNG KT'!G89 -> 0 | F30: 25000 | G30: 84027594 | J30: 84027594
A31: 2 | B31: Tiền lương bảo vệ vườn cây | C31: Công | D31: ='QL LƯƠNG'!G16 -> 416 | F31: 25000 | G31: 10400000 | J31: 10400000
A32: II | B32: Tiền lương KTCB | C32: Công | D32: =D33 -> 24.285714 | F32: 25000 | G32: 607142.86 | J32: 607142.86 | M32: ='LƯƠNG TT'!#REF! -> #REF! | N32: =M32+#REF!+#REF! -> #REF! | P32: =#REF!-455517042 -> #REF!
A33: 1 | B33: Vườn cây 2018 | C33: Công | D33: 24.285714 | F33: 25000 | G33: 607142.86 | J33: 607142.86
A34: III | B34: Tiền lương tạp vụ | C34: Ngày | D34: 30 | F34: 56666.667 | G34: 1700000 | J34: 1700000
A35: TỔNG CỘNG: | E35: =E14 -> 63154.458 | G35: 5.424649e+08 | H35: =H12+H32+H34 -> 0 | I35: =I12+I32 -> 4720954.3 | J35: 5.4718586e+08 | M35: =#REF!-#REF! -> #REF!
A36: Số tiền bằng chữ: Năm trăm bốn mươi bảy triệu một trăm tám mươi lăm nghìn tám trăm năm mươi tám kíp. | N36: =H35-H31 -> 0 | P36: =#REF!+1680000-#REF! -> #REF!
I38: Sepon, ngày 02 tháng 11 năm 2024
A40: TỔNG GIÁM ĐỐC PHÒNG TC - KT PHÒNG TC - HC ĐỘI SẢN XUẤT SEPON | N40: =#REF!+H33 -> #REF!
P42: =#REF!+1680000 -> #REF!

Sheet Mủ BN D40
A1: CỘNG HÒA DÂN CHỦ NHÂN DÂN LÀO
A2: Hòa bình - Độc lập - Dân chủ - Thống nhất - Thịnh vượng
A3: -----oOo-----
A5: CÔNG TY TNHH CỔ PHẦN QUASA-GERUCO LÀO
A6: ĐỘI SẢN XUẤT SEPON
A8: BẢNG THEO DÕI SẢN LƯỢNG MỦ THÁNG 10 NĂM 2024 TẠM TÍNH DRC 40%
A10: STT | B10: STT | C10: TÊN CN | D10: NGÀY | AI10: TẠP | AJ10: Quy khô (40%) | AK10: Xếp hạng kỹ thuật | AL10: Ký tên
D11: 1 | E11: 2 | F11: 3 | G11: 4 | H11: 5 | I11: 6 | J11: 7 | K11: 8 | L11: 9 | M11: 10 | N11: 11 | O11: 12 | P11: 13 | Q11: 14 | R11: 15 | S11: 16 | T11: 17 | U11: 18 | V11: 19 | W11: 20 | X11: 21 | Y11: 22 | Z11: 23 | AA11: 24 | AB11: 25 | AC11: 26 | AD11: 27 | AE11: 28 | AF11: 29 | AG11: 30 | AH11: 31 | AN11: bôi kt
A12: 52 | B12: 1 | C12: ='Chấm công công nhân'!L66 -> Phò Đăm | AB12: 167 | AC12: 206 | AG12: 0 | AI12: =SUM(D12:AH12) -> 373 | AJ12: =AI12*0.4 -> 149.2 | AK12: A | AM12: =IF(AJ12>=2790,700000,IF(AJ12>=2425,500000,IF(AJ12>2110,300000,IF(AJ12>=2110,0,0)))) -> 0 | AN12: =+#REF!-#REF! -> #REF! | AT12: =+AI12+[2]Mủ!AI13 -> 1418 | AX12: 9081.093 | AZ12: 1335.9741
A13: 53 | B13: 2 | C13: ='Chấm công công nhân'!L67 -> Thảo Mai | AB13: 147 | AC13: 187 | AG13: 0 | AI13: =SUM(D13:AH13) -> 334 | AJ13: =AI13*0.4 -> 133.6 | AK13: B | AM13: =IF(AJ13>=2790,700000,IF(AJ13>=2425,500000,IF(AJ13>2110,300000,IF(AJ13>=2110,0,0)))) -> 0 | AT13: =+AI13+[2]Mủ!AI14 -> 1138 | AX13: =AX12/#REF!*100 -> #REF! | AZ13: 785.2036
A14: 54 | B14: 3 | C14: ='Chấm công công nhân'!L68 -> Thảo Tưng | AB14: 0 | AC14: 0 | AG14: 91 | AI14: =SUM(D14:AH14) -> 91 | AJ14: =AI14*0.4 -> 36.4 | AK14: B | AM14: =IF(AJ14>=2790,700000,IF(AJ14>=2425,500000,IF(AJ14>2110,300000,IF(AJ14>=2110,0,0)))) -> 0 | AT14: =+AI14+[2]Mủ!AI15 -> 1676 | AZ14: 832.28639
A15: 55 | B15: 4 | C15: ='Chấm công công nhân'!L69 -> Thảo Xay | AB15: 66 | AC15: 77 | AG15: 151 | AI15: =SUM(D15:AH15) -> 294 | AJ15: =AI15*0.4 -> 117.6 | AK15: A | AM15: =IF(AJ15>=2790,700000,IF(AJ15>=2425,500000,IF(AJ15>2110,300000,IF(AJ15>=2110,0,0)))) -> 0 | AT15: =+AI15+[2]Mủ!AI16 -> 1529 | AX15: =SUM(AI12:AI16) -> 1383 | AZ15: 1005.9042
A16: 56 | B16: 5 | C16: ='Chấm công công nhân'!L70 -> Nàng Nọi | AB16: 64 | AC16: 78 | AG16: 149 | AI16: =SUM(D16:AH16) -> 291 | AJ16: =AI16*0.4 -> 116.4 | AK16: B | AM16: =IF(AJ16>=2790,700000,IF(AJ16>=2425,500000,IF(AJ16>2110,300000,IF(AJ16>=2110,0,0)))) -> 0 | AT16: =+AI16+[2]Mủ!AI17 -> 1522 | AX16: =SUM(AJ12:AJ16) -> 553.2 | AY16: =AX16/AX15*100 -> 40 | AZ16: 851.41377
A17: 57 | B17: 6 | C17: ='Chấm công công nhân'!L71 -> Thảo Đăm | AB17: 92 | AC17: 170 | AG17: 0 | AI17: =SUM(D17:AH17) -> 262 | AJ17: =AI17*0.4 -> 104.8 | AK17: B | AM17: =IF(AJ17>=2790,700000,IF(AJ17>=2425,500000,IF(AJ17>2110,300000,IF(AJ17>=2110,0,0)))) -> 0 | AT17: =+AI17+[2]Mủ!AI18 -> 1035 | AX17: =AX16-523 -> 30.2 | AY17: =AX17/AX15*100 -> 2.1836587
A18: 58 | B18: 7 | C18: ='Chấm công công nhân'!L72 -> Thảo chăn | AB18: 112 | AC18: 165 | AG18: 0 | AI18: =SUM(D18:AH18) -> 277 | AJ18: =AI18*0.4 -> 110.8 | AK18: A | AM18: =IF(AJ18>=2790,700000,IF(AJ18>=2425,500000,IF(AJ18>2110,300000,IF(AJ18>=2110,0,0)))) -> 0 | AT18: =+AI18+[2]Mủ!AI19 -> 1026 | AY18: 43.712734
A19: 59 | B19: 8 | C19: ='Chấm công công nhân'!L73 -> Hồ Văn Tăng | AB19: 0 | AC19: 0 | AG19: 0 | AI19: =SUM(D19:AH19) -> 0 | AJ19: =AI19*0.4 -> 0 | AK19: B | AM19: =IF(AJ19>=2790,700000,IF(AJ19>=2425,500000,IF(AJ19>2110,300000,IF(AJ19>=2110,0,0)))) -> 0
A20: 60 | B20: 9 | C20: ='Chấm công công nhân'!L74 -> Hồ Văn Khoa | AB20: 0 | AC20: 0 | AG20: 0 | AI20: =SUM(D20:AH20) -> 0 | AJ20: =AI20*0.4 -> 0 | AK20: A | AM20: =IF(AJ20>=2790,700000,IF(AJ20>=2425,500000,IF(AJ20>2110,300000,IF(AJ20>=2110,0,0)))) -> 0
A21: 61 | B21: 10 | C21: ='Chấm công công nhân'!L75 -> Hồ Xa My | AB21: 0 | AC21: 0 | AG21: 0 | AI21: =SUM(D21:AH21) -> 0 | AJ21: =AI21*0.4 -> 0 | AK21: B | AM21: =IF(AJ21>=2790,700000,IF(AJ21>=2425,500000,IF(AJ21>2110,300000,IF(AJ21>=2110,0,0)))) -> 0
A22: 62 | B22: 11 | C22: ='Chấm công công nhân'!L76 -> Thảo lay | AB22: 0 | AC22: 109 | AG22: 0 | AI22: =SUM(D22:AH22) -> 109 | AJ22: =AI22*0.4 -> 43.6 | AK22: B | AM22: =IF(AJ22>=2790,700000,IF(AJ22>=2425,500000,IF(AJ22>2110,300000,IF(AJ22>=2110,0,0)))) -> 0
A23: 63 | B23: 12 | C23: ='Chấm công công nhân'!L77 -> Thảo khên | AB23: 135 | AC23: 193 | AG23: 0 | AI23: =SUM(D23:AH23) -> 328 | AJ23: =AI23*0.4 -> 131.2 | AK23: A | AM23: =IF(AJ23>=2790,700000,IF(AJ23>=2425,500000,IF(AJ23>2110,300000,IF(AJ23>=2110,0,0)))) -> 0
A24: 64 | B24: 13 | C24: ='Chấm công công nhân'!L78 -> Thảo khon | AB24: 0 | AC24: 74 | AG24: 152 | AI24: =SUM(D24:AH24) -> 226 | AJ24: =AI24*0.4 -> 90.4 | AK24: A | AM24: =IF(AJ24>=2790,700000,IF(AJ24>=2425,500000,IF(AJ24>2110,300000,IF(AJ24>=2110,0,0)))) -> 0
A25: 65 | B25: 14 | C25: ='Chấm công công nhân'!L79 -> Thảo nga | AB25: 0 | AC25: 0 | AG25: 150 | AI25: =SUM(D25:AH25) -> 150 | AJ25: =AI25*0.4 -> 60 | AK25: B | AM25: =IF(AJ25>=2790,700000,IF(AJ25>=2425,500000,IF(AJ25>2110,300000,IF(AJ25>=2110,0,0)))) -> 0
A26: 62 | B26: 15 | C26: ='Chấm công công nhân'!L80 -> Thảo lăm ma | AB26: 0 | AC26: 0 | AG26: 0 | AJ26: =AI26*0.4 -> 0 | AK26: A | AM26: =IF(AJ26>=2790,700000,IF(AJ26>=2425,500000,IF(AJ26>2110,300000,IF(AJ26>=2110,0,0)))) -> 0
A27: TỔNG CỘNG | D27: =SUM(D12:D26) -> 0 | E27: =SUM(E12:E26) -> 0 | F27: =SUM(F12:F26) -> 0 | G27: =SUM(G12:G26) -> 0 | H27: =SUM(H12:H26) -> 0 | I27: =SUM(I12:I26) -> 0 | J27: =SUM(J12:J26) -> 0 | K27: =SUM(K12:K26) -> 0 | ... AJ27: =SUM(AJ12:AJ26) -> 1094
A29: STT | D29: SỐ CÔNG NHÂN | G29: HẠNG KỸ THUẬT | J29: SẢN LƯỢNG MỦ TẠP (kg) | P29: SẢN LƯỢNG MỦ QUY KHÔ
A30: 1 | G30: A | J30: =SUMIF($AK$12:$AK$26,"A",$AI$12:$AI$26) -> 1498 | P30: =SUMIF($AK$12:$AK$26,"A",$AJ$12:$AJ$26) -> 599.2
A31: 2 | G31: B | J31: =SUMIF($AK$12:$AK$26,"B",$AI$12:$AI$26) -> 1237 | P31: =SUMIF($AK$12:$AK$26,"B",$AJ$12:$AJ$26) -> 494.8 | AP31: =97677*43.16 -> 4215739.3
A32: 3 | G32: C | J32: =SUMIF($AK$12:$AK$26,"C",$AI$12:$AI$26) -> 0 | P32: =SUMIF($AK$12:$AK$26,"C",$AJ$12:$AJ$26) -> 0
A33: 4 | D33: =SUM(COUNTIF(AK12:AK21,"D")) -> 0 | G33: D | J33: =SUMIF($AK$12:$AK$18,"D",$AI$12:$AI$18) -> 0 | P33: =SUMIF($AK$12:$AK$18,"D",$AJ$12:$AJ$18) -> 0
A34: TỔNG | D34: =SUM(D30:F33) -> 0 | J34: =SUM(J30:O33) -> 2735 | P34: =SUM(P30:V33) -> 1094
AE35: Sepon, ngày 31 tháng 10 năm 2024
C36: TỔNG GIÁM ĐỐC | O36: PHÒNG. KTNN | AE36: ĐỘI TRƯỞNG ĐỘI SEPON
AE42: Phạm Đắc Nhân

Sheet THƯỞNG SL
A1: CÔNG TY TNHH CP QUASA - GERUCO | G1: CỘNG HÒA DÂN CHỦ NHÂN DÂN LÀO
G2: Hòa bình - Độc lập - Dân chủ - Thống nhất - Thịnh vượng
A5: TIỀN THƯỞNG HOÀN THÀNH VƯỢT SẢN LƯỢNG THÁNG 11 NĂM 2023
A6: ĐƠN VỊ: ĐỘI SX SEPON
A7: STT | B7: Họ và tên | D7: MS NV | E7: Chức vụ | F7: Bộ phận | G7: Số kg qui khô đạt trong tháng | H7: Tiền thưởng (Kíp) | I7: Ký nhận
B9: Lào | C9: Việt Nam
A10: 1 | B10: =VLOOKUP(C10,[4]Sheet1!$B$9:$C$115,2,0) -> #N/A
A11: 2 | B11: =VLOOKUP(C11,[4]Sheet1!$B$9:$C$115,2,0) -> #N/A
A12: 3 | B12: =VLOOKUP(C12,[4]Sheet1!$B$9:$C$115,2,0) -> #N/A
A13: TỔNG CỘNG | G13: =SUBTOTAL(9,G10:G12) -> 0 | H13: =SUBTOTAL(9,H10:H12) -> 0
H14: Sepon,ngày 03 tháng 12 năm 2023
A15: P.TC -KT | E15: P.TC -HC | G15: THỦ TRƯỞNG ĐƠN VỊ | H15: NGƯỜI LẬP

Sheet QL LƯƠNG
A1: CỘNG HÒA DÂN CHỦ NHÂN DÂN LÀO
A2: Hòa bình - Độc lập - Dân chủ - Thống nhất - Thịnh vượng
A3: -----oOo-----
A4: CÔNG TY TNHH CỔ PHẦN QUASA-GERUCO LÀO
A5: ĐỘI SẢN XUẤT SEPON
A7: BẢNG LƯƠNG QUẢN LÝ VÀ CÔNG NHÂN TRỰC TIẾP NGƯỜI LÀO THÁNG 09 NĂM 2024
C9: Tỷ giá: USD - LAK | D9: =+'Lương Tổng NT'!E6 -> 21555
B10: VND-LAK | D10: =+'Lương Tổng NT'!E7 -> 0.9894
C11: BATH-LAK | F11: =+'Lương Tổng NT'!E8 -> 670.65
A12: STT | B12: Họ và tên | D12: MS NV | E12: Chức vụ | F12: Số người | G12: LƯƠNG | P12: Tổng lương (kip) | Q12: BHXH BHYT BHTN 10.5% | R12: Truy thu BHXH BHYT BHTN năm 2020 | S12: Tổng cộng ( kip) | T12: Thuế TNCN | U12: Trích KP Công Đoàn | V12: Tổng thu nhập (Kíp) | W12: Ký nhận | X12: Ghi chú
G13: Lương chăm sóc (25000kip/tháng) | I13: Truy lĩnh lương T7+T8 | J13: Truy lãnh lương T8 - T12 | K13: Tổng lương | L13: Quy đổi USD-LAK | M13: Phụ cấp trách nhiệm | N13: Lương sản lượng | O13: Phụ cấp khai thác
G14: Công | H14: Thành tiền
A16: I | C16: BẢO VỆ | F16: 4 | G16: =10400000/25000 -> 416 | H16: =G16*25000 -> 10400000 | L16: =+H16 -> 10400000 | P16: =+L16 -> 10400000 | S16: =P16-Q16 -> 10400000 | V16: =S16 -> 10400000
A17: II | C17: VƯỜN CÂY KINH DOANH | F17: =+F21+F18+F23 -> 54 | G17: =+G21+G18+G23 -> 0 | H17: =H18+H21+H23 -> 0 | I17: =I18+I21+I23 -> 0 | J17: =J18+J21+J23 -> 0 | K17: =K18+K21+K23 -> 0 | L17: =L18+L21+L23 -> 0 | M17: =M18+M21+M23 -> 0 | N17: =N18+N21+N23 -> #REF! | O17: =O18+O21+O23 -> #REF! | ... U17: =U18+U21+U23 -> 0 | V17: =S17 -> #REF! | W17: =+W21+W18+W23 -> 0
A18: 1 | C18: TỔ 1 | F18: 32 | G18: =+G19 -> 0 | H18: =G18*25000 -> 0 | I18: =+I19 -> 0 | J18: =+J19 -> 0 | K18: =+K19 -> 0 | L18: =+L19 -> 0 | M18: =+M19 -> 0 | N18: =+'Tổ 1'!K53 -> 1.3932816e+08 | O18: =+'Tổ 1'!L53 -> 959 | P18: =+'Tổ 1'!M53 -> 1.3932912e+08 | Q18: =+Q19 -> 0 | R18: =+R19 -> 0 | S18: =+'Tổ 1'!O53 -> 1.3932912e+08 | T18: =+T19 -> 0 | U18: =+U19 -> 0 | V18: =S18 -> 1.3932912e+08
A19: 1.1 | C19: Lương công nhân khai thác | F19: 32 | G19: ='Tổ 1'!H53 -> 0 | H19: =G19*25000 -> 0 | L19: =+H19 -> 0 | N19: ='1'!L51 -> 1.3932816e+08 | O19: ='1'!S51 -> 73110091 | P19: =O19+L19+N19 -> 2.1243825e+08 | S19: =+P19 -> 2.1243825e+08 | V19: =S19 -> 2.1243825e+08
A20: 1.2 | C20: Lương công nhân khoán | G20: ='Tổ 1'!H52 -> 0 | H20: =G20*25000 -> 0 | L20: =+H20 -> 0 | P20: =O20+L20+N20 -> 0 | S20: =+P20 -> 0 | V20: =S20 -> 0
A21: 2 | C21: TỔ 2 | F21: =+F22 -> 15 | G21: =+G22 -> 0 | H21: =G21*25000 -> 0 | I21: =+I22 -> 0 | J21: =+J22 -> 0 | K21: =+K22 -> 0 | L21: =+L22 -> 0 | M21: =+M22 -> 0 | N21: =+N22 -> #REF! | O21: =+O22 -> #REF! | P21: =+P22 -> 61486597 | ... U21: =+U22 -> 0 | V21: =S21 -> 61486597
A22: 2..1 | C22: Lương công nhân khai thác | F22: 15 | G22: =+'Tổ 2'!H30 -> 0 | H22: =G22*25000 -> 0 | L22: =+H22 -> 0 | N22: =#REF! -> #REF! | O22: =#REF! -> #REF! | P22: =+'Tổ 2'!M30 -> 61486597 | S22: =+P22 -> 61486597 | V22: =S22 -> 61486597
A23: 3 | C23: TỔ 3 | F23: 7 | G23: =+G24 -> 0 | H23: =G23*25000 -> 0 | I23: =+I24 -> 0 | J23: =+J24 -> 0 | K23: =+K24 -> 0 | L23: =+L24 -> 0 | M23: =+M24 -> 0 | N23: =+N24 -> #REF! | O23: =+O24 -> #REF! | P23: =+P24 -> #REF! | ... U23: =+U24 -> 0 | V23: =S23 -> #REF! | Y23: =+[5]VCKD!AD163 -> 104551558 | Z23: =+Y23-V23 -> #REF!
A24: 3.1 | C24: Lương công nhân khai thác | F24: 7 | G24: =+'Tổ 3'!H24 -> 0 | H24: =G24*25000 -> 0 | L24: =+H24 -> 0 | N24: ='3'!#REF! -> #REF! | O24: ='3'!#REF! -> #REF! | P24: =+L24+N24+O24 -> #REF! | S24: =+P24 -> #REF! | V24: =S24 -> #REF!
A25: 3.2 | C25: VƯỜN CÂY KTCB | G25: =+G26 -> 0 | H25: =G25*25000 -> 0 | I25: =+I26 -> 0 | J25: =+J26 -> 0 | K25: =+K26 -> 0 | L25: =+H25 -> 0 | M25: =+M26 -> 0 | N25: =+N26 -> 0 | O25: =+O26 -> 0 | P25: =+L25+N25+O25 -> 0 | Q25: =+Q26 -> 0 | R25: =+R26 -> 0 | S25: =+P25 -> 0 | T25: =+T26 -> 0 | U25: =+U26 -> 0 | V25: =S25 -> 0
A26: 3.3 | C26: Lương công nhân khoán | G26: 0 | H26: =G26*25000 -> 0 | L26: =+H26 -> 0 | P26: =+L26+N26+O26 -> 0 | S26: =+P26 -> 0 | V26: =S26 -> 0
A27: 3.2 | C27: Lương công nhân khoán | G27: ='Tổ 3'!H24 -> 0 | H27: =G27*25000 -> 0 | L27: =+H27 -> 0 | P27: =+L27+N27+O27 -> 0 | S27: =+P27 -> 0 | V27: =S27 -> 0 | Y27: =1700000/25000 -> 68
A28: IV | C28: TẠP VỤ VĂN PHÒNG | F28: =+F29 -> 1 | G28: =+G29 -> 68 | H28: =G28*25000 -> 1700000 | I28: =+I29 -> 0 | J28: =+J29 -> 0 | K28: =+K29 -> 0 | L28: =+L29 -> 1700000 | M28: =+M29 -> 0 | N28: =+N29 -> 0 | O28: =+O29 -> 0 | P28: =+P29 -> 1700000 | ... U28: =+U29 -> 0 | V28: =S28 -> 1700000 | W28: =+SUM(W29:W29) -> 0 | Z28: =+'[5]TRạm Cán'!V26 -> 28133235 | AA28: =+Z28-V28 -> 26433235
A29: 1 | C29: Tạp vụ | F29: 1 | G29: 68 | H29: =G29*25000 -> 1700000 | L29: =+H29 -> 1700000 | P29: =+L29 -> 1700000 | S29: =+P29 -> 1700000 | V29: =S29 -> 1700000
A30: TỔNG CỘNG | F30: =+F28+F17+F16 -> 59 | G30: =+G28+G17+G16+G25 -> 484 | H30: =+H28+H17+H16+H25 -> 12100000 | I30: =+I28+I17+I16+I25 -> 0 | J30: =+J28+J17+J16+J25 -> 0 | K30: =+K28+K17+K16+K25 -> 0 | L30: =+L28+L17+L16+L25 -> 12100000 | M30: =+M28+M17+M16+M25 -> 0 | N30: =+N28+N17+N16+N25 -> #REF! | ... V30: =+V28+V17+V16+V25 -> #REF!
A31: (Số tiền bẳng chữ: ba trăm ba sáu triệu tám trăm bốn lăm nghìn chín trăm bốn lăm kíp)
Q32: Sepon, ngày 03 tháng 10 năm 2024
B33: PHÒNG TC- KT | S33: ĐỘI TRƯỞNG ĐỘI SEPON
AA34: 112

Sheet Tổ 1
A1: CỘNG HÒA DÂN CHỦ NHÂN DÂN LÀO
A2: Hòa bình - Độc lập - Dân chủ - Thống nhất - Thịnh vượng
A3: -----oOo-----
A4: CÔNG TY TNHH CỔ PHẦN QUASA - GERUCO LÀO
A5: ĐỘI SẢN XUẤT SEPON
A7: BẢNG LƯƠNG CÔNG NHÂN KHAI THÁC THÁNG 06 NĂM 2024
A8: TỔ 1
C9: Tỷ giá: USD qua Kíp: | E9: 21178
C10: Tỷ giá: Việt qua Kíp: | E10: 0.9892
C11: Tỷ giá Bath qua Kíp | E11: 653.07
A12: STT | B12: Họ và Tên | E12: Chức vụ | F12: Ký Nhận | G12: Bộ phận | H12: Lương | M12: Tổng lương | N12: BHXH | O12: Tiền lương còn lại
D13: MSNV | H13: Lương chăm sóc (25000kip[/công) | K13: Lương sản lượng | L13: Phụ cấp khai thác
H14: Công | J14: Thành tiền
A15: 1 | B15: 2 | C15: 2 | D15: 4 | E15: 3 | G15: 4 | H15: 5 | I15: 6 | J15: 6 | K15: 7 | L15: 8 | M15: 9 | N15: 10 | O15: 10 | S15: cvk | T15: ='CV KHAC'!M13 -> 500000 | V15: 648 | W15: 304 | X15: =+V15-W15 -> 344
A16: 1 | B16: ວັນມາ | C16: ='Chấm công công nhân'!L13 -> Vắt Đi | E16: CNKT | G16: Tổ 1 | H16: =VLOOKUP(C16,'BẢNG LƯƠNG KT'!C17:G53,5,0) -> 0 | J16: =H16*25000 -> 0 | K16: =+VLOOKUP(C16,'BẢNG LƯƠNG KT'!C17:L17,10,0) -> 5165366.8 | L16: =VLOOKUP(C16,'BẢNG LƯƠNG KT'!C17:S17,15,0) -> 30 | M16: =SUM(J16:L16) -> 5165396.8 | O16: =M16 -> 5165396.8 | S16: công an bản đen | T16: 1500000 | V16: =SUM(V15:V15) -> 648 | W16: =SUM(W15:W15) -> 304 | X16: =+V16-W16 -> 344
A17: 2 | B17: ທ ສຸກ | C17: ='Chấm công công nhân'!L14 -> T Ô Vên | E17: CNKT | G17: Tổ 1 | H17: =VLOOKUP(C17,'BẢNG LƯƠNG KT'!C18:G54,5,0) -> 0 | J17: =H17*25000 -> 0 | K17: =+VLOOKUP(C17,'BẢNG LƯƠNG KT'!C18:L18,10,0) -> 4297011.7 | L17: =VLOOKUP(C17,'BẢNG LƯƠNG KT'!C18:S18,15,0) -> 31 | M17: =SUM(J17:L17) -> 4297042.7 | O17: =M17 -> 4297042.7
A18: 3 | B18: ເພັງ | C18: ='Chấm công công nhân'!L15 -> Nàng Túc | E18: CNKT | G18: Tổ 1 | H18: =VLOOKUP(C18,'BẢNG LƯƠNG KT'!C19:G55,5,0) -> 0 | J18: =H18*25000 -> 0 | K18: =+VLOOKUP(C18,'BẢNG LƯƠNG KT'!C19:L19,10,0) -> 4189421.9 | L18: =VLOOKUP(C18,'BẢNG LƯƠNG KT'!C19:S19,15,0) -> 31 | M18: =SUM(J18:L18) -> 4189452.9 | O18: =M18 -> 4189452.9 | W18: =+V16-W16 -> 344
A19: 4 | B19: ທ ກອກ | C19: ='Chấm công công nhân'!L16 -> Thảo Say | E19: CNKT | G19: Tổ 1 | H19: =VLOOKUP(C19,'BẢNG LƯƠNG KT'!C20:G56,5,0) -> 0 | J19: =H19*25000 -> 0 | K19: =+VLOOKUP(C19,'BẢNG LƯƠNG KT'!C20:L20,10,0) -> 2394234.1 | L19: =VLOOKUP(C19,'BẢNG LƯƠNG KT'!C20:S20,15,0) -> 18 | M19: =SUM(J19:L19) -> 2394252.1 | O19: =M19 -> 2394252.1 | S19: tổng | T19: =SUM(T15:T16) -> 2000000
A20: 4 | C20: ='Chấm công công nhân'!L17 -> Thảo Pheng | E20: CNKT | G20: Tổ 1 | H20: =VLOOKUP(C20,'BẢNG LƯƠNG KT'!C21:G57,5,0) -> 0 | J20: =H20*25000 -> 0 | K20: =+VLOOKUP(C20,'BẢNG LƯƠNG KT'!C21:L21,10,0) -> 3421688.3 | L20: =VLOOKUP(C20,'BẢNG LƯƠNG KT'!C21:S21,15,0) -> 28 | M20: =SUM(J20:L20) -> 3421716.3 | O20: =M20 -> 3421716.3 | S20: tiền đón trực tết | T20: 6000000 | W20: =100*20 -> 2000
A21: 5 | C21: ='Chấm công công nhân'!L18 -> Nàng Chay | E21: CNKT | G21: Tổ 1 | H21: =VLOOKUP(C21,'BẢNG LƯƠNG KT'!C22:G58,5,0) -> 0 | J21: =H21*25000 -> 0 | K21: =+VLOOKUP(C21,'BẢNG LƯƠNG KT'!C22:L22,10,0) -> 3991468 | L21: =VLOOKUP(C21,'BẢNG LƯƠNG KT'!C22:S22,15,0) -> 31 | M21: =SUM(J21:L21) -> 3991499 | O21: =M21 -> 3991499 | W21: =100*20 -> 2000
A22: 6 | C22: ='Chấm công công nhân'!L19 -> Nàng Hđao | E22: CNKT | G22: Tổ 1 | H22: =VLOOKUP(C22,'BẢNG LƯƠNG KT'!C23:G59,5,0) -> 0 | J22: =H22*25000 -> 0 | K22: =+VLOOKUP(C22,'BẢNG LƯƠNG KT'!C23:L23,10,0) -> 3409479.9 | L22: =VLOOKUP(C22,'BẢNG LƯƠNG KT'!C23:S23,15,0) -> 25 | M22: =SUM(J22:L22) -> 3409504.9 | O22: =M22 -> 3409504.9 | W22: =40*20+200 -> 1000
A23: 7 | C23: ='Chấm công công nhân'!L20 -> Thảo Ken | E23: CNKT | G23: Tổ 1 | H23: =VLOOKUP(C23,'BẢNG LƯƠNG KT'!C24:G60,5,0) -> 0 | J23: =H23*25000 -> 0 | K23: =+VLOOKUP(C23,'BẢNG LƯƠNG KT'!C24:L24,10,0) -> 4218326.2 | L23: =VLOOKUP(C23,'BẢNG LƯƠNG KT'!C24:S24,15,0) -> 31 | M23: =SUM(J23:L23) -> 4218357.2 | O23: =M23 -> 4218357.2
A24: 8 | C24: ='Chấm công công nhân'!L21 -> Thảo Cợt | E24: CNKT | G24: Tổ 1 | H24: =VLOOKUP(C24,'BẢNG LƯƠNG KT'!C25:G61,5,0) -> 0 | J24: =H24*25000 -> 0 | K24: =+VLOOKUP(C24,'BẢNG LƯƠNG KT'!C25:L25,10,0) -> 3537194 | L24: =VLOOKUP(C24,'BẢNG LƯƠNG KT'!C25:S25,15,0) -> 23 | M24: =SUM(J24:L24) -> 3537217 | O24: =M24 -> 3537217 | T24: 244427
A25: 9 | C25: ='Chấm công công nhân'!L22 -> Thảo Mi | E25: CNKT | G25: Tổ 1 | H25: =VLOOKUP(C25,'BẢNG LƯƠNG KT'!C26:G62,5,0) -> 0 | J25: =H25*25000 -> 0 | K25: =+VLOOKUP(C25,'BẢNG LƯƠNG KT'!C26:L26,10,0) -> 2376451.2 | L25: =VLOOKUP(C25,'BẢNG LƯƠNG KT'!C26:S26,15,0) -> 19 | M25: =SUM(J25:L25) -> 2376470.2 | O25: =M25 -> 2376470.2 | T25: 14473
A26: 10 | C26: ='Chấm công công nhân'!L23 -> Thảo Phét | E26: CNKT | G26: Tổ 1 | H26: =VLOOKUP(C26,'BẢNG LƯƠNG KT'!C27:G63,5,0) -> 0 | J26: =H26*25000 -> 0 | K26: =+VLOOKUP(C26,'BẢNG LƯƠNG KT'!C27:L27,10,0) -> 3757557.8 | L26: =VLOOKUP(C26,'BẢNG LƯƠNG KT'!C27:S27,15,0) -> 28 | M26: =SUM(J26:L26) -> 3757585.8 | O26: =M26 -> 3757585.8 | T26: =+T24+T25 -> 258900 | V26: 3 | W26: 50 | X26: =+V26*W26 -> 150
A27: 11 | C27: ='Chấm công công nhân'!L24 -> Thảo Hăm | E27: CNKT | G27: Tổ 1 | H27: =VLOOKUP(C27,'BẢNG LƯƠNG KT'!C28:G64,5,0) -> 0 | J27: =H27*25000 -> 0 | K27: =+VLOOKUP(C27,'BẢNG LƯƠNG KT'!C28:L28,10,0) -> 4344144.9 | L27: =VLOOKUP(C27,'BẢNG LƯƠNG KT'!C28:S28,15,0) -> 28 | M27: =SUM(J27:L27) -> 4344172.9 | O27: =M27 -> 4344172.9 | T27: 850 | X27: 100
A28: 12 | B28: ຫວັດດີ | C28: ='Chấm công công nhân'!L25 -> Nang Lon | E28: CNKT | G28: Tổ 1 | H28: =VLOOKUP(C28,'BẢNG LƯƠNG KT'!C29:G65,5,0) -> 0 | J28: =H28*25000 -> 0 | K28: =+VLOOKUP(C28,'BẢNG LƯƠNG KT'!C29:L29,10,0) -> 4349245.7 | L28: =VLOOKUP(C28,'BẢNG LƯƠNG KT'!C29:S29,15,0) -> 29 | M28: =SUM(J28:L28) -> 4349274.7 | O28: =M28 -> 4349274.7 | T28: =+T26-T27 -> 258050
A29: 13 | B29: ສະຕອງ | C29: ='Chấm công công nhân'!L26 -> Thảo Phết | E29: CNKT | G29: Tổ 1 | H29: =VLOOKUP(C29,'BẢNG LƯƠNG KT'!C30:G66,5,0) -> 0 | J29: =H29*25000 -> 0 | K29: =+VLOOKUP(C29,'BẢNG LƯƠNG KT'!C30:L30,10,0) -> 3962368.6 | L29: =VLOOKUP(C29,'BẢNG LƯƠNG KT'!C30:S30,15,0) -> 23 | M29: =SUM(J29:L29) -> 3962391.6 | O29: =M29 -> 3962391.6
A30: 14 | B30: ມອນ | C30: ='Chấm công công nhân'!L27 -> Vĩ Lay | E30: CNKT | G30: Tổ 1 | H30: =VLOOKUP(C30,'BẢNG LƯƠNG KT'!C31:G67,5,0) -> 0 | J30: =H30*25000 -> 0 | K30: =+VLOOKUP(C30,'BẢNG LƯƠNG KT'!C31:L31,10,0) -> 5400001.7 | L30: =VLOOKUP(C30,'BẢNG LƯƠNG KT'!C31:S31,15,0) -> 31 | M30: =SUM(J30:L30) -> 5400032.7 | O30: =M30 -> 5400032.7
A31: 15 | B31: ເງິນ | C31: ='Chấm công công nhân'!L28 -> Pha Xúc | E31: CNKT | G31: Tổ 1 | H31: =VLOOKUP(C31,'BẢNG LƯƠNG KT'!C32:G68,5,0) -> 0 | J31: =H31*25000 -> 0 | K31: =+VLOOKUP(C31,'BẢNG LƯƠNG KT'!C32:L32,10,0) -> 3924182.6 | L31: =VLOOKUP(C31,'BẢNG LƯƠNG KT'!C32:S32,15,0) -> 29 | M31: =SUM(J31:L31) -> 3924211.6 | O31: =M31 -> 3924211.6
A32: 15 | B32: ລອນ | C32: ='Chấm công công nhân'!L29 -> Nàng Đao | E32: CNKT | G32: Tổ 1 | H32: =VLOOKUP(C32,'BẢNG LƯƠNG KT'!C33:G69,5,0) -> 0 | J32: =H32*25000 -> 0 | K32: =+VLOOKUP(C32,'BẢNG LƯƠNG KT'!C33:L33,10,0) -> 3734423.3 | L32: =VLOOKUP(C32,'BẢNG LƯƠNG KT'!C33:S33,15,0) -> 30 | M32: =SUM(J32:L32) -> 3734453.3 | O32: =M32 -> 3734453.3
A33: 16 | B33: ນ ນາ | C33: ='Chấm công công nhân'!L30 -> Nàng Kiên | E33: CNKT | G33: Tổ 1 | H33: =VLOOKUP(C33,'BẢNG LƯƠNG KT'!C34:G71,5,0) -> 0 | J33: =H33*25000 -> 0 | K33: =+VLOOKUP(C33,'BẢNG LƯƠNG KT'!C34:L34,10,0) -> 3619837.4 | L33: =VLOOKUP(C33,'BẢNG LƯƠNG KT'!C34:S34,15,0) -> 29 | M33: =SUM(J33:L33) -> 3619866.4 | O33: =M33 -> 3619866.4
A34: 17 | B34: ພົງ | C34: ='Chấm công công nhân'!L31 -> Nàng Túc 2 | E34: CNKT | G34: Tổ 1 | H34: =VLOOKUP(C34,'BẢNG LƯƠNG KT'!C35:G72,5,0) -> 0 | J34: =H34*25000 -> 0 | K34: =+VLOOKUP(C34,'BẢNG LƯƠNG KT'!C35:L35,10,0) -> 3737656.5 | L34: =VLOOKUP(C34,'BẢNG LƯƠNG KT'!C35:S35,15,0) -> 29 | M34: =SUM(J34:L34) -> 3737685.5 | O34: =M34 -> 3737685.5
A35: 18 | B35: ທອງລາ | C35: ='Chấm công công nhân'!L32 -> Nàng Phon | E35: CNKT | G35: Tổ 1 | H35: =VLOOKUP(C35,'BẢNG LƯƠNG KT'!C36:G73,5,0) -> 0 | J35: =H35*25000 -> 0 | K35: =+VLOOKUP(C35,'BẢNG LƯƠNG KT'!C36:L36,10,0) -> 3351169.6 | L35: =VLOOKUP(C35,'BẢNG LƯƠNG KT'!C36:S36,15,0) -> 29 | M35: =SUM(J35:L35) -> 3351198.6 | O35: =M35 -> 3351198.6
A36: 19 | B36: ຫຳ | C36: ='Chấm công công nhân'!L33 -> Thảo Chòi | E36: CNKT | G36: Tổ 1 | H36: =VLOOKUP(C36,'BẢNG LƯƠNG KT'!C37:G74,5,0) -> 0 | J36: =H36*25000 -> 0 | K36: =+VLOOKUP(C36,'BẢNG LƯƠNG KT'!C37:L37,10,0) -> 4119711.6 | L36: =VLOOKUP(C36,'BẢNG LƯƠNG KT'!C37:S37,15,0) -> 30 | M36: =SUM(J36:L36) -> 4119741.6 | O36: =M36 -> 4119741.6
A37: 20 | B37: ທ ຈາບ | C37: ='Chấm công công nhân'!L34 -> Thong La | E37: CNKT | G37: Tổ 1 | H37: =VLOOKUP(C37,'BẢNG LƯƠNG KT'!C38:G75,5,0) -> 0 | J37: =H37*25000 -> 0 | K37: =+VLOOKUP(C37,'BẢNG LƯƠNG KT'!C38:L38,10,0) -> 4847419.6 | L37: =VLOOKUP(C37,'BẢNG LƯƠNG KT'!C38:S38,15,0) -> 31 | M37: =SUM(J37:L37) -> 4847450.6 | O37: =M37 -> 4847450.6
A38: 21 | B38: ນ ກຸຫລາບ | C38: ='Chấm công công nhân'!L35 -> Thảo kok | E38: CNKT | G38: Tổ 1 | H38: =VLOOKUP(C38,'BẢNG LƯƠNG KT'!C39:G76,5,0) -> 0 | J38: =H38*25000 -> 0 | K38: =+VLOOKUP(C38,'BẢNG LƯƠNG KT'!C39:L39,10,0) -> 4573679 | L38: =VLOOKUP(C38,'BẢNG LƯƠNG KT'!C39:S39,15,0) -> 29 | M38: =SUM(J38:L38) -> 4573708 | O38: =M38 -> 4573708
A39: 22 | B39: ທ ປອນ | C39: ='Chấm công công nhân'!L36 -> Thảo Hôm | E39: CNKT | G39: Tổ 1 | H39: =VLOOKUP(C39,'BẢNG LƯƠNG KT'!C40:G77,5,0) -> 0 | J39: =H39*25000 -> 0 | K39: =+VLOOKUP(C39,'BẢNG LƯƠNG KT'!C40:L40,10,0) -> 2251998.3 | L39: =VLOOKUP(C39,'BẢNG LƯƠNG KT'!C40:S40,15,0) -> 19 | M39: =SUM(J39:L39) -> 2252017.3 | O39: =M39 -> 2252017.3
A40: 23 | B40: ທ ສຸກ | C40: ='Chấm công công nhân'!L37 -> Nàng Lam | E40: CNKT | G40: Tổ 1 | H40: =VLOOKUP(C40,'BẢNG LƯƠNG KT'!C41:G78,5,0) -> 0 | J40: =H40*25000 -> 0 | K40: =+VLOOKUP(C40,'BẢNG LƯƠNG KT'!C41:L41,10,0) -> 2402317.3 | L40: =VLOOKUP(C40,'BẢNG LƯƠNG KT'!C41:S41,15,0) -> 19 | M40: =SUM(J40:L40) -> 2402336.3 | O40: =M40 -> 2402336.3
A41: 24 | B41: ທ ກີ່ | C41: ='Chấm công công nhân'!L38 -> Thảo Hơ Phơ | E41: CNKT | G41: Tổ 1 | H41: =VLOOKUP(C41,'BẢNG LƯƠNG KT'!C42:G78,5,0) -> 0 | J41: =H41*25000 -> 0 | K41: =+VLOOKUP(C41,'BẢNG LƯƠNG KT'!C42:L42,10,0) -> 3507620.7 | L41: =VLOOKUP(C41,'BẢNG LƯƠNG KT'!C42:S42,15,0) -> 21 | M41: =SUM(J41:L41) -> 3507641.7 | O41: =M41 -> 3507641.7
...

Sheet Tổ 2
A1: CỘNG HÒA DÂN CHỦ NHÂN DÂN LÀO
A2: Hòa bình - Độc lập - Dân chủ - Thống nhất - Thịnh vượng
A3: -----oOo-----
A4: CÔNG TY TNHH CỔ PHẦN QUASA - GERUCO LÀO
A5: ĐỘI SẢN XUẤT SEPON
A7: BẢNG LƯƠNG CÔNG NHÂN TRỰC TIẾP NGƯỜI LÀO THÁNG 06 NĂM 2024
A8: TỔ 2
C9: Tỷ giá: USD qua Kíp: | E9: ='Tổ 1'!E9 -> 21178
C10: Tỷ giá: Việt qua Kíp: | E10: ='Tổ 1'!E10 -> 0.9892
C11: Tỷ giá Bath qua Kíp | E11: ='Tổ 1'!E11 -> 653.07
A12: STT | B12: Họ và Tên | E12: Chức vụ | F12: Ký nhận | G12: Bộ phận | H12: Lương | M12: Tổng lương | N12: BHXH | O12: Tiền lương còn lại
H13: Lương chăm sóc (25000kip[/công) | K13: Lương sản lượng | L13: Phụ cấp khai thác
D14: MSNV | H14: Công | I14: Thành tiền | J14: Thành tiền
A15: 1 | B15: ທ ສົມ | C15: ='Chấm công công nhân'!L50 -> Thảo tít | E15: CNKT | G15: Tổ 2 | H15: =+VLOOKUP(C15,'BẢNG LƯƠNG KT'!C55:G69,5,0) -> 0 | I15: =H15*25000 -> 0 | K15: =+VLOOKUP(C15,'BẢNG LƯƠNG KT'!C55:L55,10,0) -> 3773841.2 | L15: =+VLOOKUP(C15,'BẢNG LƯƠNG KT'!C55:S55,15,0) -> 30 | M15: =SUM(I15:L15) -> 3773871.2 | O15: =M15 -> 3773871.2
A16: 2 | B16: ທ ດິນ | C16: ='Chấm công công nhân'!L51 -> Thảo ớt | E16: CNKT | G16: Tổ 2 | H16: =+VLOOKUP(C16,'BẢNG LƯƠNG KT'!C56:G71,5,0) -> 0 | I16: =H16*25000 -> 0 | K16: =+VLOOKUP(C16,'BẢNG LƯƠNG KT'!C56:L56,10,0) -> 4434873.5 | L16: =+VLOOKUP(C16,'BẢNG LƯƠNG KT'!C56:S56,15,0) -> 31 | M16: =SUM(I16:L16) -> 4434904.5 | O16: =M16 -> 4434904.5 | S16: 244427
A17: 3 | B17: ທ ຫວ່າງ | C17: ='Chấm công công nhân'!L52 -> Nàng Ọt | E17: CNKT | G17: Tổ 2 | H17: =+VLOOKUP(C17,'BẢNG LƯƠNG KT'!C57:G72,5,0) -> 0 | I17: =H17*25000 -> 0 | K17: =+VLOOKUP(C17,'BẢNG LƯƠNG KT'!C57:L57,10,0) -> 3924206.5 | L17: =+VLOOKUP(C17,'BẢNG LƯƠNG KT'!C57:S57,15,0) -> 31 | M17: =SUM(I17:L17) -> 3924237.5 | O17: =M17 -> 3924237.5 | S17: 14473
A18: 4 | B18: ທ ຈັນ | C18: ='Chấm công công nhân'!L53 -> Thào Tòng | E18: CNKT | G18: Tổ 2 | H18: =+VLOOKUP(C18,'BẢNG LƯƠNG KT'!C58:G73,5,0) -> 0 | I18: =H18*25000 -> 0 | K18: =+VLOOKUP(C18,'BẢNG LƯƠNG KT'!C58:L58,10,0) -> 3912765.6 | L18: =+VLOOKUP(C18,'BẢNG LƯƠNG KT'!C58:S58,15,0) -> 31 | M18: =SUM(I18:L18) -> 3912796.6 | O18: =M18 -> 3912796.6 | S18: =+S16+S17 -> 258900 | U18: 3 | V18: 50 | W18: =+U18*V18 -> 150
A19: 5 | B19: ທ ກວັກ | C19: ='Chấm công công nhân'!L54 -> Nàng Nơm | E19: CNKT | G19: Tổ 2 | H19: =+VLOOKUP(C19,'BẢNG LƯƠNG KT'!C59:G74,5,0) -> 0 | I19: =H19*25000 -> 0 | K19: =+VLOOKUP(C19,'BẢNG LƯƠNG KT'!C59:L59,10,0) -> 4106555.3 | L19: =+VLOOKUP(C19,'BẢNG LƯƠNG KT'!C59:S59,15,0) -> 31 | M19: =SUM(I19:L19) -> 4106586.3 | O19: =M19 -> 4106586.3 | S19: 850 | W19: 100
A20: 6 | B20: ທ ຈັນດີ | C20: ='Chấm công công nhân'!L55 -> Thảo Ây | E20: CNKT | G20: Tổ 2 | H20: =+VLOOKUP(C20,'BẢNG LƯƠNG KT'!C60:G75,5,0) -> 0 | I20: =H20*25000 -> 0 | K20: =+VLOOKUP(C20,'BẢNG LƯƠNG KT'!C60:L60,10,0) -> 4087647 | L20: =+VLOOKUP(C20,'BẢNG LƯƠNG KT'!C60:S60,15,0) -> 31 | M20: =SUM(I20:L20) -> 4087678 | O20: =M20 -> 4087678 | S20: =+S18-S19 -> 258050
A21: 7 | B21: ນ ສະຫວັນ | C21: ='Chấm công công nhân'!L56 -> Thảo Âm Thong | E21: CNKT | G21: Tổ 2 | H21: =+VLOOKUP(C21,'BẢNG LƯƠNG KT'!C61:G76,5,0) -> 0 | I21: =H21*25000 -> 0 | K21: =+VLOOKUP(C21,'BẢNG LƯƠNG KT'!C61:L61,10,0) -> 3115232.3 | L21: =+VLOOKUP(C21,'BẢNG LƯƠNG KT'!C61:S61,15,0) -> 27 | M21: =SUM(I21:L21) -> 3115259.3 | O21: =M21 -> 3115259.3
A22: 8 | B22: ນ ລີ | C22: ='Chấm công công nhân'!L57 -> Nàng phon | E22: CNKT | G22: Tổ 2 | H22: =+VLOOKUP(C22,'BẢNG LƯƠNG KT'!C62:G77,5,0) -> 0 | I22: =H22*25000 -> 0 | K22: =+VLOOKUP(C22,'BẢNG LƯƠNG KT'!C62:L62,10,0) -> 3618572.7 | L22: =+VLOOKUP(C22,'BẢNG LƯƠNG KT'!C62:S62,15,0) -> 28 | M22: =SUM(I22:L22) -> 3618600.7 | O22: =M22 -> 3618600.7
A23: 9 | B23: ທ ວັນ | C23: ='Chấm công công nhân'!L58 -> Thảo phắt | E23: CNKT | G23: Tổ 2 | H23: =+VLOOKUP(C23,'BẢNG LƯƠNG KT'!C63:G78,5,0) -> 0 | I23: =H23*25000 -> 0 | K23: =+VLOOKUP(C23,'BẢNG LƯƠNG KT'!C63:L63,10,0) -> 4197152.1 | L23: =+VLOOKUP(C23,'BẢNG LƯƠNG KT'!C63:S63,15,0) -> 31 | M23: =SUM(I23:L23) -> 4197183.1 | O23: =M23 -> 4197183.1
A24: 10 | B24: ທ ວີລະ | C24: ='Chấm công công nhân'!L59 -> Thảo Phon Say | E24: CNKT | G24: Tổ 2 | H24: =+VLOOKUP(C24,'BẢNG LƯƠNG KT'!C64:G78,5,0) -> 0 | I24: =H24*25000 -> 0 | K24: =+VLOOKUP(C24,'BẢNG LƯƠNG KT'!C64:L64,10,0) -> 4352420.6 | L24: =+VLOOKUP(C24,'BẢNG LƯƠNG KT'!C64:S64,15,0) -> 31 | M24: =SUM(I24:L24) -> 4352451.6 | O24: =M24 -> 4352451.6
A25: 11 | C25: ='Chấm công công nhân'!L60 -> Nàng Pít | E25: CNKT | G25: Tổ 2 | H25: =+VLOOKUP(C25,'BẢNG LƯƠNG KT'!C65:G78,5,0) -> 0 | I25: =H25*25000 -> 0 | K25: =+VLOOKUP(C25,'BẢNG LƯƠNG KT'!C65:L65,10,0) -> 3547645.2 | L25: =+VLOOKUP(C25,'BẢNG LƯƠNG KT'!C65:S65,15,0) -> 30 | M25: =SUM(I25:L25) -> 3547675.2 | O25: =M25 -> 3547675.2
A26: 12 | C26: ='Chấm công công nhân'!L61 -> Thảo út | E26: CNKT | G26: Tổ 2 | H26: =+VLOOKUP(C26,'BẢNG LƯƠNG KT'!C66:G78,5,0) -> 0 | I26: =H26*25000 -> 0 | K26: =+VLOOKUP(C26,'BẢNG LƯƠNG KT'!C66:L66,10,0) -> 4501912.3 | L26: =+VLOOKUP(C26,'BẢNG LƯƠNG KT'!C66:S66,15,0) -> 31 | M26: =SUM(I26:L26) -> 4501943.3 | O26: =M26 -> 4501943.3
A27: 13 | C27: ='Chấm công công nhân'!L62 -> Nàng ăm | E27: CNKT | G27: Tổ 2 | H27: =+VLOOKUP(C27,'BẢNG LƯƠNG KT'!C67:G78,5,0) -> 0 | I27: =H27*25000 -> 0 | K27: =+VLOOKUP(C27,'BẢNG LƯƠNG KT'!C67:L67,10,0) -> 4515861.1 | L27: =+VLOOKUP(C27,'BẢNG LƯƠNG KT'!C67:S67,15,0) -> 27 | M27: =SUM(I27:L27) -> 4515888.1 | O27: =M27 -> 4515888.1
A28: 14 | C28: ='Chấm công công nhân'!L63 -> Nàng Phìn | E28: CNKT | G28: Tổ 2 | H28: =+VLOOKUP(C28,'BẢNG LƯƠNG KT'!C68:G78,5,0) -> 0 | I28: =H28*25000 -> 0 | K28: =+VLOOKUP(C28,'BẢNG LƯƠNG KT'!C68:L68,10,0) -> 4565513.2 | L28: =+VLOOKUP(C28,'BẢNG LƯƠNG KT'!C68:S68,15,0) -> 31 | M28: =SUM(I28:L28) -> 4565544.2 | O28: =M28 -> 4565544.2
A29: 15 | C29: ='Chấm công công nhân'!L64 -> May | E29: CNKT | G29: Tổ 2 | H29: =+VLOOKUP(C29,'BẢNG LƯƠNG KT'!C69:G78,5,0) -> 0 | I29: =H29*25000 -> 0 | K29: =+VLOOKUP(C29,'BẢNG LƯƠNG KT'!C69:L69,10,0) -> 4831949.4 | L29: =+VLOOKUP(C29,'BẢNG LƯƠNG KT'!C69:S69,15,0) -> 28 | M29: =SUM(I29:L29) -> 4831977.4 | O29: =M29 -> 4831977.4
A30: Tổng cộng | H30: =SUM(H15:H29) -> 0 | I30: =SUM(I15:I29) -> 0 | J30: =SUM(J15:J29) -> 0 | K30: =SUM(K15:K29) -> 61486148 | L30: =SUM(L15:L29) -> 449 | M30: =SUM(M15:M29) -> 61486597 | N30: =SUM(N15:N29) -> 0 | O30: =SUM(O15:O29) -> 61486597
A32: (Bằng chữ: Tám bốn triệu một trăm hai mươi nghìn tám trăm tám mốt kíp)
L33: Sepon, ngày 30 tháng 06 năm 2024
C34: PHÒNG TC-KT | H34: PHÒNG TC-HC | M34: ĐỘI TRƯỞNG ĐỘI SEPON

Sheet Tổ 3
A1: CỘNG HÒA DÂN CHỦ NHÂN DÂN LÀO
A2: Hòa bình - Độc lập - Dân chủ - Thống nhất - Thịnh vượng
A3: -----oOo-----
A4: CÔNG TY TNHH CỔ PHẦN QUASA - GERUCO LÀO
A5: ĐỘI SẢN XUẤT SEPON
A7: BẢNG LƯƠNG CÔNG NHÂN TRỰC TIẾP NGƯỜI LÀO THÁNG 06 NĂM 2024
A8: TỔ 3
C9: Tỷ giá: USD qua Kíp: | E9: 20939
C10: Tỷ giá: Việt qua Kíp: | E10: 0.9901
C11: Tỷ giá Bath qua Kíp | E11: 653.23
A12: STT | B12: Họ và Tên | E12: Chức vụ | F12: Ký nhận | G12: Bộ phận | H12: Lương | L12: Tổng lương | M12: BHXH | N12: Thực Nhận
D13: MSNV | H13: Lương chăm sóc (25000kip/công) | J13: Lương sản lượng | K13: Phụ cấp khai thác | U13: =20*100 -> 2000
H14: Công | I14: Thành tiền
A15: 1 | B15: 2 | C15: 3 | D15: 4 | E15: 5 | H15: 6 | I15: 9 | J15: 11 | K15: 12 | L15: 13 | M15: 14 | N15: 15 | Q15: =421.47*25000 -> 10536750
A16: 1 | B16: ທ ໂຈ້ | C16: ='Chấm công công nhân'!L66 -> Phò Đăm | E16: CNKT | G16: Tổ 3 | H16: =+VLOOKUP(C16,'BẢNG LƯƠNG KT'!C72:G88,5,0) -> 0 | I16: =+H16*25000 -> 0 | J16: =+VLOOKUP(C16,'BẢNG LƯƠNG KT'!C72:L72,10,0) -> 5352523.3 | K16: =+VLOOKUP(C16,'BẢNG LƯƠNG KT'!C72:S72,15,0) -> 0 | L16: =SUM(I16:K16) -> 5352523.3 | N16: =L16 -> 5352523.3
A17: 2 | B17: ນ ຄຳ | C17: ='Chấm công công nhân'!L67 -> Thảo Mai | E17: CNKT | G17: Tổ 3 | H17: =+VLOOKUP(C17,'BẢNG LƯƠNG KT'!C73:G88,5,0) -> 0 | I17: =+H17*25000 -> 0 | J17: =+VLOOKUP(C17,'BẢNG LƯƠNG KT'!C73:L73,10,0) -> 965101.5 | K17: =+VLOOKUP(C17,'BẢNG LƯƠNG KT'!C73:S73,15,0) -> 0 | L17: =SUM(I17:K17) -> 965101.5 | N17: =L17 -> 965101.5
A18: 3 | B18: ທ ວີ | C18: ='Chấm công công nhân'!L68 -> Thảo Tưng | E18: CNKT | G18: Tổ 3 | H18: =+VLOOKUP(C18,'BẢNG LƯƠNG KT'!C74:G89,5,0) -> 0 | I18: =+H18*25000 -> 0 | J18: =+VLOOKUP(C18,'BẢNG LƯƠNG KT'!C74:L74,10,0) -> 2090723 | K18: =+VLOOKUP(C18,'BẢNG LƯƠNG KT'!C74:S74,15,0) -> 0 | L18: =SUM(I18:K18) -> 2090723 | N18: =L18 -> 2090723
A19: 4 | B19: ນ ທອງ | C19: ='Chấm công công nhân'!L69 -> Thảo Xay | E19: CNKT | G19: Tổ 3 | H19: =+VLOOKUP(C19,'BẢNG LƯƠNG KT'!C75:G90,5,0) -> 0 | I19: =+H19*25000 -> 0 | J19: =+VLOOKUP(C19,'BẢNG LƯƠNG KT'!C75:L75,10,0) -> 3568348.9 | K19: =+VLOOKUP(C19,'BẢNG LƯƠNG KT'!C75:S75,15,0) -> 0 | L19: =SUM(I19:K19) -> 3568348.9 | N19: =L19 -> 3568348.9
A20: 5 | B20: ທ ຕາ | C20: ='Chấm công công nhân'!L70 -> Nàng Nọi | E20: CNKT | G20: Tổ 3 | H20: =+VLOOKUP(C20,'BẢNG LƯƠNG KT'!C76:G91,5,0) -> 0 | I20: =+H20*25000 -> 0 | J20: =+VLOOKUP(C20,'BẢNG LƯƠNG KT'!C76:L76,10,0) -> 2891341.1 | K20: =+VLOOKUP(C20,'BẢNG LƯƠNG KT'!C76:S76,15,0) -> 0 | L20: =SUM(I20:K20) -> 2891341.1 | N20: =L20 -> 2891341.1
A21: 6 | B21: ທ ຈື່ | C21: ='Chấm công công nhân'!L71 -> Thảo Đăm | E21: CNKT | G21: Tổ 3 | H21: =+VLOOKUP(C21,'BẢNG LƯƠNG KT'!C77:G92,5,0) -> 0 | I21: =+H21*25000 -> 0 | J21: =+VLOOKUP(C21,'BẢNG LƯƠNG KT'!C77:L77,10,0) -> 2954260.9 | K21: =+VLOOKUP(C21,'BẢNG LƯƠNG KT'!C77:S77,15,0) -> 0 | L21: =SUM(I21:K21) -> 2954260.9 | N21: =L21 -> 2954260.9
A22: 7 | B22: ທ ທອງ | C22: ='Chấm công công nhân'!L72 -> Thảo chăn | E22: CNKT | G22: Tổ 3 | H22: =+VLOOKUP(C22,'BẢNG LƯƠNG KT'!C78:G93,5,0) -> 0 | I22: =+H22*25000 -> 0 | J22: =+VLOOKUP(C22,'BẢNG LƯƠNG KT'!C78:L78,10,0) -> 4622256.5 | K22: =+VLOOKUP(C22,'BẢNG LƯƠNG KT'!C78:S78,15,0) -> 0 | L22: =SUM(I22:K22) -> 4622256.5 | N22: =L22 -> 4622256.5
A23: 8 | C23: ='Tong hop cong'!C77 -> Hồ Xa My | E23: CNK | H23: ='BẢNG LƯƠNG KT'!G88 -> 0 | I23: =+H23*25000 -> 0 | L23: =SUM(I23:K23) -> 0 | N23: =L23 -> 0
A24: Tổng cộng | H24: =SUM(H16:H23) -> 0 | I24: =SUM(I16:I23) -> 0 | J24: =SUM(J16:J23) -> 22444555 | K24: =SUM(K16:K23) -> 0 | L24: =SUM(L16:L23) -> 22444555 | M24: =SUM(M16:M23) -> 0 | N24: =SUM(N16:N23) -> 22444555
A26: (Bằng chữ: Hai mươi bảy triệu tám trăm năm chín nghìn chín trăm bảy lăm kíp)
K27: Sepon, Ngày 30 tháng 06 năm 2024
C28: PHÒNG TC-KT | H28: PHÒNG TC-HC | L28: ĐỘI TRƯỞNG ĐỘI SEPON

Sheet BN DRC CHUẨN
A1: CỘNG HÒA DÂN CHỦ NHÂN DÂN LÀO
A2: Hòa bình - Độc lập - Dân chủ - Thống nhất - Thịnh vượng
A3: -----oOo-----
A5: CÔNG TY TNHH CỔ PHẦN QUASA-GERUCO LÀO
A6: ĐỘI SẢN XUẤT SEPON
A8: BẢNG THEO DÕI SẢN LƯỢNG MỦ THÁNG 10 NĂM 2024
A10: STT | B10: STT | C10: TÊN CN | D10: NGÀY | AI10: TẠP | AJ10: Quy khô | AK10: Xếp hạng kỹ thuật | AL10: Ký tên
D11: 1 | E11: 2 | F11: 3 | G11: 4 | H11: 5 | I11: 6 | J11: 7 | K11: 8 | L11: 9 | M11: 10 | N11: 11 | O11: 12 | P11: 13 | Q11: 14 | R11: 15 | S11: 16 | T11: 17 | U11: 18 | V11: 19 | W11: 20 | X11: 21 | Y11: 22 | Z11: 23 | AA11: 24 | AB11: 25 | AC11: 26 | AD11: 27 | AE11: 28 | AF11: 29 | AG11: 30 | AH11: 31 | AN11: bôi kt
A12: 52 | B12: 1 | C12: ='[6]Chấm công công nhân'!L66 -> Phò Đăm | AB12: 167 | AC12: 206 | AG12: 0 | AI12: =SUM(D12:AH12) -> 373 | AJ12: =AI12*$AX$12/100 -> 195.54474 | AK12: ='[6]Kỷ thuật'!M64 -> A | AM12: =IF(AJ12>=2790,700000,IF(AJ12>=2425,500000,IF(AJ12>2110,300000,IF(AJ12>=2110,0,0)))) -> 0 | AN12: =+#REF!-#REF! -> #REF! | AT12: =+AI12+[2]Mủ!AI13 -> 1418 | AX12: 52.424863 | AZ12: 1335.9741
A13: 53 | B13: 2 | C13: ='[6]Chấm công công nhân'!L67 -> Thảo Mai | AB13: 147 | AC13: 187 | AG13: 0 | AI13: =SUM(D13:AH13) -> 334 | AJ13: =AI13*$AX$12/100 -> 175.09904 | AK13: ='[6]Kỷ thuật'!M65 -> B | AM13: =IF(AJ13>=2790,700000,IF(AJ13>=2425,500000,IF(AJ13>2110,300000,IF(AJ13>=2110,0,0)))) -> 0 | AT13: =+AI13+[2]Mủ!AI14 -> 1138 | AX13: =AX12/#REF!*100 -> #REF! | AZ13: 785.2036
A14: 54 | B14: 3 | C14: ='[6]Chấm công công nhân'!L68 -> Thảo Tưng | AB14: 0 | AC14: 0 | AG14: 91 | AI14: =SUM(D14:AH14) -> 91 | AJ14: =AI14*$AX$12/100 -> 47.706625 | AK14: ='[6]Kỷ thuật'!M66 -> B | AM14: =IF(AJ14>=2790,700000,IF(AJ14>=2425,500000,IF(AJ14>2110,300000,IF(AJ14>=2110,0,0)))) -> 0 | AT14: =+AI14+[2]Mủ!AI15 -> 1676 | AZ14: 832.28639
A15: 55 | B15: 4 | C15: ='[6]Chấm công công nhân'!L69 -> Thảo Xay | AB15: 66 | AC15: 77 | AG15: 151 | AI15: =SUM(D15:AH15) -> 294 | AJ15: =AI15*$AX$12/100 -> 154.1291 | AK15: ='[6]Kỷ thuật'!M67 -> A | AM15: =IF(AJ15>=2790,700000,IF(AJ15>=2425,500000,IF(AJ15>2110,300000,IF(AJ15>=2110,0,0)))) -> 0 | AT15: =+AI15+[2]Mủ!AI16 -> 1529 | AX15: =SUM(AI12:AI16) -> 1383 | AZ15: 1005.9042
A16: 56 | B16: 5 | C16: ='[6]Chấm công công nhân'!L70 -> Nàng Nọi | AB16: 64 | AC16: 78 | AG16: 149 | AI16: =SUM(D16:AH16) -> 291 | AJ16: =AI16*$AX$12/100 -> 152.55635 | AK16: ='[6]Kỷ thuật'!M68 -> B | AM16: =IF(AJ16>=2790,700000,IF(AJ16>=2425,500000,IF(AJ16>2110,300000,IF(AJ16>=2110,0,0)))) -> 0 | AT16: =+AI16+[2]Mủ!AI17 -> 1522 | AX16: =SUM(AJ12:AJ16) -> 725.03585 | AY16: =AX16/AX15*100 -> 52.424863 | AZ16: 851.41377
A17: 57 | B17: 6 | C17: ='[6]Chấm công công nhân'!L71 -> Thảo Đăm | AB17: 92 | AC17: 170 | AG17: 0 | AI17: =SUM(D17:AH17) -> 262 | AJ17: =AI17*$AX$12/100 -> 137.35314 | AK17: ='[6]Kỷ thuật'!M69 -> B | AM17: =IF(AJ17>=2790,700000,IF(AJ17>=2425,500000,IF(AJ17>2110,300000,IF(AJ17>=2110,0,0)))) -> 0 | AT17: =+AI17+[2]Mủ!AI18 -> 1035 | AX17: =AX16-523 -> 202.03585 | AY17: =AX17/AX15*100 -> 14.608522
A18: 58 | B18: 7 | C18: ='[6]Chấm công công nhân'!L72 -> Thảo Chăn | AB18: 112 | AC18: 165 | AG18: 0 | AI18: =SUM(D18:AH18) -> 277 | AJ18: =AI18*$AX$12/100 -> 145.21687 | AK18: ='[6]Kỷ thuật'!M70 -> A | AM18: =IF(AJ18>=2790,700000,IF(AJ18>=2425,500000,IF(AJ18>2110,300000,IF(AJ18>=2110,0,0)))) -> 0 | AT18: =+AI18+[2]Mủ!AI19 -> 1026 | AY18: 43.712734
A19: 59 | B19: 8 | C19: ='[6]Chấm công công nhân'!L73 -> Thảo Cô | AB19: 0 | AC19: 0 | AG19: 0 | AI19: =SUM(D19:AH19) -> 0 | AJ19: =AI19*$AX$12/100 -> 0 | AK19: ='[6]Kỷ thuật'!M71 -> B | AM19: =IF(AJ19>=2790,700000,IF(AJ19>=2425,500000,IF(AJ19>2110,300000,IF(AJ19>=2110,0,0)))) -> 0
A20: 60 | B20: 9 | C20: ='[6]Chấm công công nhân'!L74 -> Thảo Nha | AB20: 0 | AC20: 0 | AG20: 0 | AI20: =SUM(D20:AH20) -> 0 | AJ20: =AI20*$AX$12/100 -> 0 | AK20: ='[6]Kỷ thuật'!M72 -> A | AM20: =IF(AJ20>=2790,700000,IF(AJ20>=2425,500000,IF(AJ20>2110,300000,IF(AJ20>=2110,0,0)))) -> 0
A21: 61 | B21: 10 | C21: ='[6]Chấm công công nhân'!L75 -> Thảo Đăm 2 | AB21: 0 | AC21: 0 | AG21: 0 | AI21: =SUM(D21:AH21) -> 0 | AJ21: =AI21*$AX$12/100 -> 0 | AK21: ='[6]Kỷ thuật'!M73 -> B | AM21: =IF(AJ21>=2790,700000,IF(AJ21>=2425,500000,IF(AJ21>2110,300000,IF(AJ21>=2110,0,0)))) -> 0
A22: 62 | B22: 11 | C22: ='[6]Chấm công công nhân'!L76 -> Thảo Lay | AB22: 0 | AC22: 109 | AG22: 0 | AI22: =SUM(D22:AH22) -> 109 | AJ22: =AI22*$AX$12/100 -> 57.143101 | AK22: ='[6]Kỷ thuật'!M74 -> B | AM22: =IF(AJ22>=2790,700000,IF(AJ22>=2425,500000,IF(AJ22>2110,300000,IF(AJ22>=2110,0,0)))) -> 0
A23: 63 | B23: 12 | C23: ='[6]Chấm công công nhân'!L77 -> Thảo Khên | AB23: 135 | AC23: 193 | AG23: 0 | AI23: =SUM(D23:AH23) -> 328 | AJ23: =AI23*$AX$12/100 -> 171.95355 | AK23: ='[6]Kỷ thuật'!M75 -> A | AM23: =IF(AJ23>=2790,700000,IF(AJ23>=2425,500000,IF(AJ23>2110,300000,IF(AJ23>=2110,0,0)))) -> 0
A24: 64 | B24: 13 | C24: ='[6]Chấm công công nhân'!L78 -> Thảo Khon | AB24: 0 | AC24: 74 | AG24: 152 | AI24: =SUM(D24:AH24) -> 226 | AJ24: =AI24*$AX$12/100 -> 118.48019 | AK24: ='[6]Kỷ thuật'!M76 -> A | AM24: =IF(AJ24>=2790,700000,IF(AJ24>=2425,500000,IF(AJ24>2110,300000,IF(AJ24>=2110,0,0)))) -> 0
A25: 65 | B25: 14 | C25: ='[6]Chấm công công nhân'!L79 -> Thảo Nga | AB25: 0 | AC25: 0 | AG25: 150 | AI25: =SUM(D25:AH25) -> 150 | AJ25: =AI25*$AX$12/100 -> 78.637294 | AK25: ='[6]Kỷ thuật'!M77 -> B | AM25: =IF(AJ25>=2790,700000,IF(AJ25>=2425,500000,IF(AJ25>2110,300000,IF(AJ25>=2110,0,0)))) -> 0
A26: 62 | B26: 15 | C26: ='[6]Chấm công công nhân'!L80 -> 0 | AB26: 0 | AC26: 0 | AG26: 0 | AJ26: =AI26*$AX$12/100 -> 0 | AM26: =IF(AJ26>=2790,700000,IF(AJ26>=2425,500000,IF(AJ26>2110,300000,IF(AJ26>=2110,0,0)))) -> 0
A27: TỔNG CỘNG | D27: =SUM(D12:D26) -> 0 | E27: =SUM(E12:E26) -> 0 | F27: =SUM(F12:F26) -> 0 | G27: =SUM(G12:G26) -> 0 | H27: =SUM(H12:H26) -> 0 | I27: =SUM(I12:I26) -> 0 | J27: =SUM(J12:J26) -> 0 | K27: =SUM(K12:K26) -> 0 | ... AJ27: =SUM(AJ12:AJ26) -> 1433.82
A29: STT | D29: SỐ CÔNG NHÂN | G29: HẠNG KỸ THUẬT | J29: SẢN LƯỢNG MỦ TẠP (kg) | P29: SẢN LƯỢNG MỦ QUY KHÔ
A30: 1 | G30: A | J30: =SUMIF($AK$12:$AK$26,"A",$AI$12:$AI$26) -> 1498 | P30: =SUMIF($AK$12:$AK$26,"A",$AJ$12:$AJ$26) -> 785.32445
A31: 2 | G31: B | J31: =SUMIF($AK$12:$AK$26,"B",$AI$12:$AI$26) -> 1237 | P31: =SUMIF($AK$12:$AK$26,"B",$AJ$12:$AJ$26) -> 648.49555 | AP31: =97677*43.16 -> 4215739.3
A32: 3 | G32: C | J32: =SUMIF($AK$12:$AK$26,"C",$AI$12:$AI$26) -> 0 | P32: =SUMIF($AK$12:$AK$26,"C",$AJ$12:$AJ$26) -> 0
A33: 4 | D33: =SUM(COUNTIF(AK12:AK21,"D")) -> 0 | G33: D | J33: =SUMIF($AK$12:$AK$18,"D",$AI$12:$AI$18) -> 0 | P33: =SUMIF($AK$12:$AK$18,"D",$AJ$12:$AJ$18) -> 0
A34: TỔNG | D34: =SUM(D30:F33) -> 0 | J34: =SUM(J30:O33) -> 2735 | P34: =SUM(P30:V33) -> 1433.82
AE35: Sepon, ngày 31 tháng 10 năm 2024
C36: TỔNG GIÁM ĐỐC | O36: PHÒNG. KTNN | AE36: ĐỘI TRƯỞNG ĐỘI SEPON
AG37: Sepon, ngày 30 tháng 11 năm 2024
E38: TỔNG GIÁM ĐỐC | Q38: PHÒNG. KTNN | AG38: ĐỘI TRƯỞNG ĐỘI SEPON
AG44: Phạm Đắc Nhân

Sheet DANH SÁCH THUẾ
A1: CỘNG HÒA DÂN CHỦ NHÂN DÂN LÀO
A2: Hòa Bình -Độc Lập - Dân Chủ - Thống Nhất - Thịnh Vượng
A3: CÔNG TY TNHH CP QUASA - GERUCO LÀO
B4: ĐỘI SX SEPON
A6: DANH SÁCH CBCNV NỘP THUẾ TNCN THÁNG 01/2025
A8: STT | C8: HỌ VÀ TÊN | E8: CHỨC VỤ | F8: LƯƠNG | H8: THUẾ TNCN
A9: 1 | C9: Thảo Xúc | E9: Tạp vụ | F9: 1700000 | H9: 20000
A10: 2 | C10: ='Phụ cấp người Việt'!B12 -> Hồ Văn Tăng | E10: ='Phụ cấp người Việt'!C12 -> CNKT | F10: ='Phụ cấp người Việt'!F12 -> 1680000 | H10: ='Phụ cấp người Việt'!G12 -> 19000
A11: 3 | C11: ='Phụ cấp người Việt'!B13 -> Hồ Văn Khoa | E11: ='Phụ cấp người Việt'!C13 -> CNKT | F11: ='Phụ cấp người Việt'!F13 -> 1600000 | H11: ='Phụ cấp người Việt'!G13 -> 15000
A12: 4 | C12: ='Phụ cấp người Việt'!B14 -> Hồ Xa My | E12: ='Phụ cấp người Việt'!C14 -> CNKT | F12: ='Phụ cấp người Việt'!F14 -> 1680000 | H12: ='Phụ cấp người Việt'!G14 -> 19000
A13: TỔNG CỘNG | F13: =SUM(F9:G12) -> 6660000 | H13: =SUM(H9:I12) -> 73000
A15: Bằng chữ: Bảy mươi ba nghìn kíp.
F16: Sepon ngày 03 tháng 02 năm 2025
A18: TỔNG GIÁM ĐỐC | D18: PHÒNG TC-KT | F18: PHÒNG TC-HC | H18: ĐỘI TRƯỞNG

Sheet Chấm công công nhân
A1: CỘNG HÒA DÂN CHỦ NHÂN DÂN LÀO
A2: Hòa bình - Độc lập - Dân chủ - Thống nhất - Thịnh vượng
A3: -----oOo-----
J4: CÔNG TY TNHH CỔ PHẦN QUASA-GERUCO LÀO
A5: ĐỘI SẢN XUẤT SEPON | J5: ĐỘI SẢN XUẤT SEPON
J7: BẢNG CHẤM CÔNG CẠO MỦ HẰNG NGÀY CÔNG NHÂN THÁNG 01 NĂM 2025
A9: Lương ngày công | B9: Điểm ngày công | C9: Hạng kỹ thuật cạo | D9: Điểm kỹ thuật | E9: Tổng điểm | F9: Xếp hạng trong tháng | G9: Tổng mủ quy khô trong tháng | H9: Lương sản lượng trong tháng | I9: Tổng lương ngày công + sản lượng | J9: Stt | K9: Stt | L9: Họ và tên | M9: Ngày công | AR9: Ngày thường ( X) | AS9: Ngày chủ nhật ( CN) | AT9: Phụ cấp ngày công vườn cây năm nhất (X1) | AU9: Phụ cấp chủ nhật vườn cây năm nhất (CN1) | AV9: Tổng cộng | AW9: Ký tên | AY9: Ký tên
M10: 1 | N10: 2 | O10: 3 | P10: 4 | Q10: 5 | R10: 6 | S10: 7 | T10: 8 | U10: 9 | V10: 10 | W10: 11 | X10: 12 | Y10: 13 | Z10: 14 | AA10: 15 | AB10: 16 | AC10: 17 | AD10: 18 | AE10: 19 | AF10: 20 | AG10: 21 | AH10: 22 | AI10: 23 | AJ10: 24 | AK10: 25 | AL10: 26 | AM10: 27 | AN10: 28 | AO10: 29 | AP10: 30 | AQ10: 31
M11: D | N11: A | O11: B | P11: C | Q11: D | R11: A | S11: B | T11: C | U11: D | V11: A | W11: B | X11: C | Y11: D | Z11: A | AA11: B | AB11: C | AC11: D | AD11: A | AE11: B | AF11: C | AG11: D | AH11: A | AI11: B | AJ11: C | AK11: D | AL11: A | AM11: B | AN11: C | AO11: D | AP11: A | AQ11: B | BK11: 23
J12: A | K12: TỔ 1 | M12: =COUNTIF(M13:M48,"X")+COUNTIF(M13:M48,"CN")+COUNTIF(M13:M48,"X1")+COUNTIF(M13:M48,"CN1") -> 24 | N12: =COUNTIF(N13:N48,"X")+COUNTIF(N13:N48,"CN")+COUNTIF(N13:N48,"X1")+COUNTIF(N13:N48,"CN1") -> 19 | O12: =COUNTIF(O13:O48,"X")+COUNTIF(O13:O48,"CN")+COUNTIF(O13:O48,"X1")+COUNTIF(O13:O48,"CN1") -> 19 | P12: =COUNTIF(P13:P48,"X")+COUNTIF(P13:P48,"CN")+COUNTIF(P13:P48,"X1")+COUNTIF(P13:P48,"CN1") -> 36 | Q12: =COUNTIF(Q13:Q48,"X")+COUNTIF(Q13:Q48,"CN")+COUNTIF(Q13:Q48,"X1")+COUNTIF(Q13:Q48,"CN1") -> 36 | R12: =COUNTIF(R13:R48,"X")+COUNTIF(R13:R48,"CN")+COUNTIF(R13:R48,"X1")+COUNTIF(R13:R48,"CN1") -> 32 | S12: =COUNTIF(S13:S48,"X")+COUNTIF(S13:S48,"CN")+COUNTIF(S13:S48,"X1")+COUNTIF(S13:S48,"CN1") -> 36 | T12: =COUNTIF(T13:T48,"X")+COUNTIF(T13:T48,"CN")+COUNTIF(T13:T48,"X1")+COUNTIF(T13:T48,"CN1") -> 36 | ... AQ12: =COUNTIF(AQ13:AQ48,"X")+COUNTIF(AQ13:AQ48,"CN")+COUNTIF(AQ13:AQ48,"X1")+COUNTIF(AQ13:AQ48,"CN1") -> 32 | AR12: =SUM(AR13:AR48) -> 696 | AS12: =SUM(AS13:AS48) -> 111 | AT12: =SUM(AT13:AT48) -> 130 | AU12: =SUM(AU13:AU48) -> 22 | AV12: =SUM(AV13:AV48) -> 959 | AX12: =SUM(AX13:AX48) -> 180
J13: 1 | K13: 1 | L13: Vắt Đi | M13: x | N13: x1 | O13: x | P13: x | Q13: cn | R13: x1 | S13: x | T13: x | U13: x | V13: x1 | W13: x | X13: cn | Y13: x | Z13: x1 | AA13: x | AB13: x | AD13: x1 | AE13: cn | AF13: x | AG13: x | AH13: x1 | AI13: x | AJ13: x | AK13: x | AL13: cn1 | AM13: x | AN13: x | AO13: x | AP13: X1 | AQ13: x | AR13: =COUNTIF(M13:AQ13,"X") -> 19 | AS13: =+COUNTIF(M13:AQ13,"CN") -> 3 | AT13: =COUNTIF(M13:AQ13,"X1") -> 7 | AU13: =+COUNTIF(M13:AQ13,"CN1") -> 1 | AV13: =+SUM(AR13:AU13) -> 30
J14: 2 | K14: 2 | L14: T Ô Vên | M14: x1 | N14: x | O14: x | P14: x | Q14: cn1 | R14: x | S14: x | T14: x | U14: x1 | V14: x | W14: x | X14: cn | Y14: x1 | Z14: x | AA14: x | AB14: x | AC14: x1 | AD14: x | AE14: cn | AF14: x | AG14: x1 | AH14: x | AI14: x | AJ14: x | AK14: x1 | AL14: cn1 | AM14: x | AN14: x | AO14: x1 | AP14: x | AQ14: x | AR14: =COUNTIF(M14:AQ14,"X") -> 20 | AS14: =+COUNTIF(M14:AQ14,"CN") -> 2 | AT14: =COUNTIF(M14:AQ14,"X1") -> 7 | AU14: =+COUNTIF(M14:AQ14,"CN1") -> 2 | AV14: =+SUM(AR14:AU14) -> 31
J15: 3 | K15: 3 | L15: Nàng Túc | M15: x1 | N15: x | O15: x | P15: x | Q15: cn1 | R15: x | S15: x | T15: x | U15: x1 | V15: x | W15: x | X15: cn | Y15: x1 | Z15: x | AA15: x | AB15: x | AC15: x1 | AD15: x | AE15: cn | AF15: x | AG15: x1 | AH15: x | AI15: x | AJ15: x | AK15: x1 | AL15: cn1 | AM15: x | AN15: x | AO15: x1 | AP15: x | AQ15: x | AR15: =COUNTIF(M15:AQ15,"X") -> 20 | AS15: =+COUNTIF(M15:AQ15,"CN") -> 2 | AT15: =COUNTIF(M15:AQ15,"X1") -> 7 | AU15: =+COUNTIF(M15:AQ15,"CN1") -> 2 | AV15: =+SUM(AR15:AU15) -> 31
J16: 4 | K16: 4 | L16: Thảo Say | P16: x | Q16: cn1 | R16: x | S16: x | T16: x | U16: x1 | W16: x | X16: cn | Z16: x | AA16: x | AE16: cn | AF16: x | AH16: x | AI16: x | AL16: cn1 | AN16: x | AO16: x1 | AQ16: x | AR16: =COUNTIF(M16:AQ16,"X") -> 12 | AS16: =+COUNTIF(M16:AQ16,"CN") -> 2 | AT16: =COUNTIF(M16:AQ16,"X1") -> 2 | AU16: =+COUNTIF(M16:AQ16,"CN1") -> 2 | AV16: =+SUM(AR16:AU16) -> 18
J17: 5 | K17: 5 | L17: Thảo Pheng | M17: x1 | N17: x1 | O17: x | P17: x | Q17: cn1 | R17: x1 | S17: x | T17: x | U17: x1 | V17: x1 | W17: x | X17: cn | Z17: x1 | AA17: x | AD17: x1 | AE17: cn | AF17: x | AG17: x1 | AH17: x1 | AI17: x | AJ17: x | AK17: x1 | AL17: cn1 | AM17: x | AN17: x | AO17: x1 | AP17: x1 | AQ17: x | AR17: =COUNTIF(M17:AQ17,"X") -> 12 | AS17: =+COUNTIF(M17:AQ17,"CN") -> 2 | AT17: =COUNTIF(M17:AQ17,"X1") -> 12 | AU17: =+COUNTIF(M17:AQ17,"CN1") -> 2 | AV17: =+SUM(AR17:AU17) -> 28
J18: 6 | K18: 6 | L18: Nàng Chay | M18: x1 | N18: x1 | O18: x | P18: x | Q18: cn1 | R18: x1 | S18: x | T18: x | U18: x1 | V18: x1 | W18: x | X18: cn | Y18: x1 | Z18: x1 | AA18: x | AB18: x | AC18: x1 | AD18: x1 | AE18: cn | AF18: x | AG18: x1 | AH18: x1 | AI18: x | AJ18: x | AK18: x1 | AL18: cn1 | AM18: x | AN18: x | AO18: x1 | AP18: x1 | AQ18: x | AR18: =COUNTIF(M18:AQ18,"X") -> 13 | AS18: =+COUNTIF(M18:AQ18,"CN") -> 2 | AT18: =COUNTIF(M18:AQ18,"X1") -> 14 | AU18: =+COUNTIF(M18:AQ18,"CN1") -> 2 | AV18: =+SUM(AR18:AU18) -> 31
J19: 7 | K19: 7 | L19: Nàng Hđao | M19: x1 | P19: x | Q19: cn1 | R19: x1 | S19: x | T19: x | U19: x1 | V19: x1 | W19: x | X19: cn | Y19: x1 | Z19: x1 | AA19: x | AB19: x | AE19: cn | AF19: x | AG19: x1 | AH19: x1 | AI19: x | AK19: x1 | AL19: cn | AN19: x | AO19: x1 | AP19: x1 | AQ19: x | AR19: =COUNTIF(M19:AQ19,"X") -> 10 | AS19: =+COUNTIF(M19:AQ19,"CN") -> 3 | AT19: =COUNTIF(M19:AQ19,"X1") -> 11 | AU19: =+COUNTIF(M19:AQ19,"CN1") -> 1 | AV19: =+SUM(AR19:AU19) -> 25
J20: 8 | K20: 8 | L20: Thảo Ken | M20: x1 | N20: x1 | O20: x | P20: x | Q20: cn1 | R20: x1 | S20: x | T20: x | U20: x1 | V20: x1 | W20: x | X20: cn | Y20: x1 | Z20: x1 | AA20: x | AB20: x | AC20: x1 | AD20: x1 | AE20: cn | AF20: x | AG20: x1 | AH20: x1 | AI20: x | AJ20: x | AK20: x1 | AL20: cn | AM20: x | AN20: x | AO20: x1 | AP20: x1 | AQ20: x | AR20: =COUNTIF(M20:AQ20,"X") -> 13 | AS20: =+COUNTIF(M20:AQ20,"CN") -> 3 | AT20: =COUNTIF(M20:AQ20,"X1") -> 14 | AU20: =+COUNTIF(M20:AQ20,"CN1") -> 1 | AV20: =+SUM(AR20:AU20) -> 31
