Workbook
Name So_XN: [1]PHATSINH!$B$6:$B$2093
Name So_XN: [2]PHATSINH!$B$6:$B$2093

Sheet bcsx  t10 + cdc IN KÝ
A1: CỘNG HÒA DÂN CHỦ NHÂN DÂN LÀO
A2: Hoà Bình - Độc Lập - Dân Chủ - Thống Nhất - Thịnh Vượng
A3: -----oOo-----
A4: CÔNG TY TNHH MTV QUASA- GERUCO LÀO
A5: ĐỘI SẢN XUẤT SỐ 6
A7: BÁO CÁO SẢN XUẤT THÁNG 10 NĂM 2025
A8: ( Từ ngày 01 tháng 10 đến ngày 31 tháng 10 năm 2025 )
A10: STT | B10: DANH MỤC | C10: ĐVT | D10: Định mức | E10: Địa điểm và khối lượng thực hiện | M10: Tổng khối lượng | N10: số lần | O10: Tổng công | P10: Ghi chú
E11: Tên lô | F11: KL | G11: Tên lô | H11: KL | I11: Tên lô | J11: KL | K11: Tên lô | L11: KL | O11: 25.000 kíp
A12: A | B12: VƯỜN CÂY KINH DOANH | O12: =SUBTOTAL(9,O13:O58) -> 8706.6712
A13: I | B13: SẢN LƯỢNG | C13: Kg
A14: 1.1 | B14: Mủ tạp (Quy khô) | C14: kg | M14: 90.872 | N14: tấn
A15: 1.2 | B15: Mủ dây ( Quy khô ) | C15: Kg
A16: 1.3 | B16: Mủ Sirum ( Quy khô) | C16: Kg
A17: II | B17: PHỤ CẤP CẠO MỦ | C17: Công | O17: =SUBTOTAL(9,O18:O23) -> 5827.0392
A18: 2.1 | B18: Phụ cấp ngày công đi cạo | C18: Công | O18: 2452.187
A19: 2.2 | B19: Phụ cấp đi cạo ngày chủ nhật | C19: Công | O19: 357.28652
A20: 2.3 | B20: Phụ cấp ngày công cho công nhân vùng khó khăn | C20: Công | O20: 1876
A21: 2.4 | B21: Phụ cấp cạo cây non | C21: Công | O21: 150.74016
A22: 2.5 | B22: Phụ cấp cạo 2 lát ngày thường | C22: Công | O22: 374.8256
A23: 2.6 | B23: Phụ cấp thêm cạo 2 lát ngày thường | C23: Công | O23: 616
A24: III | B24: CHĂM SÓC | O24: =SUBTOTAL(9,O25:O58) -> 2879.632
A25: 1 | B25: Vườn cây kinh doanh năm 1 (2018) | O25: =+SUBTOTAL(9,O26:O34) -> 799.384
A26: 1.1 | B26: Bôi thuốc kích thích | C26: Phần | D26: =25/20 -> 1.25 | M26: =23+33-18 -> 38 | N26: 1 | O26: =+M26/D26 -> 30.4 | R26: =+O26+O36+O43 -> 216
A27: 1.2 | B27: Gom cành nhánh | C27: Phần | D27: =1/2 -> 0.5 | M27: 56 | O27: =+M27/D27 -> 112
A28: 1.3 | B28: Phát chồi đại trà | C28: Ha | D28: =1/16 -> 0.0625 | M28: =+SUM(E29:L29) -> 20.85 | O28: =+M28/D28 -> 333.6
E29: X33 | F29: 8.76 | G29: X32 | H29: =12.18*0.5 -> 6.09 | I29: X22 | J29: 6
B30: Phát chồi đại trà * | C30: Ha | D30: =1/20 -> 0.05 | M30: =+SUM(E31:L31) -> 7.966 | O30: =+M30/D30 -> 159.32
E31: X26 | F31: 7.966
A32: 1.4 | B32: Phun thuốc diệt cỏ đại trà (phun cục bộ) * | C32: Ha | D32: =1/4.8 -> 0.20833333 | M32: =+SUM(E33:L34) -> 34.18 | O32: =+M32/D32 -> 164.064 | R32: =+L33+L34 -> 20.2
E33: X24 | F33: 2.28 | G33: X29 | H33: 2 | I33: X26 | J33: 1.5 | K33: X25 | L33: =2+10.65 -> 12.65
E34: X28 | F34: 1.2 | G34: X22 | H34: 3 | I34: X27 | J34: 4 | K34: X30 | L34: 7.55
A35: 2 | B35: Vườn cây kinh doanh năm 4 (2017) | O35: =+SUBTOTAL(9,O36:O41) -> 510.68
A36: 2.1 | B36: Bôi thuốc kích thích | C36: Phần | D36: =25/20 -> 1.25 | M36: 64 | N36: 2 | O36: =+M36/D36*2 -> 102.4 | R36: =+M26+M36*2+M43*2 -> 270
A37: 2.2 | B37: Gom cành nhánh | C37: Phần | D37: =1/2 -> 0.5 | M37: 64 | O37: =+M37/D37 -> 128
A38: 2.3 | B38: Phát chồi đại trà | C38: Ha | D38: =1/16 -> 0.0625 | M38: =+SUM(E39:L39) -> 11 | O38: =+M38/D38 -> 176
B39: Phát chồi đại trà | E39: X31 | F39: 11 | S39: =+M28+M38+M40+#REF!+#REF! -> #REF!
C40: Ha | D40: =1/12 -> 0.083333333 | M40: =+SUM(E41:L41) -> 8.69 | O40: =+M40/D40 -> 104.28 | S40: =+O28+O38+O40+#REF!+#REF! -> #REF!
E41: X23 | F41: 3 | G41: X24 | H41: 5.69
A42: 3 | B42: Vườn cây kinh doanh năm 7 (2012) | O42: =+SUBTOTAL(9,O43:O47) -> 254.16
...

Sheet Thanh toán mủ dây
A1: CỘNG HÒA DÂN CHỦ NHÂN DÂN LÀO
A2: Hòa Bình -Độc Lập - Dân Chủ - thống Nhất - Thịnh Vượng
A3: -----oOo-----
A4: CÔNG TY TNHH MTV QUASA - GERUCO LÀO
A5: ĐỘI SẢN XUẤT SỐ 6
A7: BẢNG THANH TOÁN TIỀN LƯƠNG MỦ DÂY THÁNG 11 NĂM 2025
A9: Stt | B9: Họ và tên | C9: Ngày | AG9: Sản lượng mủ dây (kg) | AH9: Đơn giá ( Kíp) | AI9: Thành tiền | AJ9: Ký tên
C10: 1 | D10: 2 | E10: 3 | F10: 4 | G10: 5 | H10: 6 | I10: 7 | J10: 8 | K10: 9 | L10: 10 | M10: 11 | N10: 12 | O10: 13 | P10: 14 | Q10: 15 | R10: 16 | S10: 17 | T10: 18 | U10: 19 | V10: 20 | W10: 21 | X10: 22 | Y10: 23 | Z10: 24 | AA10: 25 | AB10: 26 | AC10: 27 | AD10: 28 | AE10: 29 | AF10: 30
A11: 1 | B11: =+'Biểu 2 TH MỦ dây'!B10 -> Phò Thưng | T11: 20 | AG11: =+VLOOKUP(B11,'Biểu 2 TH MỦ dây'!$B$10:$AH$43,33,0) -> 15 | AH11: 8000 | AI11: =+AG11*AH11 -> 120000
A12: 2 | B12: =+'Biểu 2 TH MỦ dây'!B11 -> A Nhợp | R12: 20 | AG12: =+VLOOKUP(B12,'Biểu 2 TH MỦ dây'!$B$10:$AH$43,33,0) -> 15 | AH12: 8000 | AI12: =+AG12*AH12 -> 120000
A13: 3 | B13: =+'Biểu 2 TH MỦ dây'!B12 -> Van | Q13: 15 | AG13: =+VLOOKUP(B13,'Biểu 2 TH MỦ dây'!$B$10:$AH$43,33,0) -> 15 | AH13: 8000 | AI13: =+AG13*AH13 -> 120000
A14: 4 | B14: =+'Biểu 2 TH MỦ dây'!B13 -> Thảo Khọt | Q14: 16 | AG14: =+VLOOKUP(B14,'Biểu 2 TH MỦ dây'!$B$10:$AH$43,33,0) -> 15 | AH14: 8000 | AI14: =+AG14*AH14 -> 120000
A15: 5 | B15: =+'Biểu 2 TH MỦ dây'!B14 -> A Cơ | S15: 20 | AG15: =+VLOOKUP(B15,'Biểu 2 TH MỦ dây'!$B$10:$AH$43,33,0) -> 15 | AH15: 8000 | AI15: =+AG15*AH15 -> 120000
A16: 6 | B16: =+'Biểu 2 TH MỦ dây'!B15 -> Phơ | S16: 12 | AG16: =+VLOOKUP(B16,'Biểu 2 TH MỦ dây'!$B$10:$AH$43,33,0) -> 15 | AH16: 8000 | AI16: =+AG16*AH16 -> 120000
A17: 7 | B17: =+'Biểu 2 TH MỦ dây'!B16 -> A phơ | S17: 21 | AG17: =+VLOOKUP(B17,'Biểu 2 TH MỦ dây'!$B$10:$AH$43,33,0) -> 15 | AH17: 8000 | AI17: =+AG17*AH17 -> 120000
A18: 8 | B18: =+'Biểu 2 TH MỦ dây'!B17 -> Nang Đăm | T18: 17 | AG18: =+VLOOKUP(B18,'Biểu 2 TH MỦ dây'!$B$10:$AH$43,33,0) -> 14 | AH18: 8000 | AI18: =+AG18*AH18 -> 112000
A19: 9 | B19: =+'Biểu 2 TH MỦ dây'!B18 -> Nang Sun | R19: 20 | AG19: =+VLOOKUP(B19,'Biểu 2 TH MỦ dây'!$B$10:$AH$43,33,0) -> 14 | AH19: 8000 | AI19: =+AG19*AH19 -> 112000
A20: 10 | B20: =+'Biểu 2 TH MỦ dây'!B19 -> A Nghen | S20: 10 | AG20: =+VLOOKUP(B20,'Biểu 2 TH MỦ dây'!$B$10:$AH$43,33,0) -> 14 | AH20: 8000 | AI20: =+AG20*AH20 -> 112000
A21: 11 | B21: =+'Biểu 2 TH MỦ dây'!B20 -> Nguyễn Thị Thanh Trà | R21: 18 | AG21: =+VLOOKUP(B21,'Biểu 2 TH MỦ dây'!$B$10:$AH$43,33,0) -> 14 | AH21: 8000 | AI21: =+AG21*AH21 -> 112000
A22: 12 | B22: =+'Biểu 2 TH MỦ dây'!B21 -> Phò Thít | O22: 13 | S22: 6 | AG22: =+VLOOKUP(B22,'Biểu 2 TH MỦ dây'!$B$10:$AH$43,33,0) -> 14 | AH22: 8000 | AI22: =+AG22*AH22 -> 112000
A23: 13 | B23: =+'Biểu 2 TH MỦ dây'!B22 -> A Bợp | O23: 12 | AG23: =+VLOOKUP(B23,'Biểu 2 TH MỦ dây'!$B$10:$AH$43,33,0) -> 14 | AH23: 8000 | AI23: =+AG23*AH23 -> 112000
A24: 14 | B24: =+'Biểu 2 TH MỦ dây'!B23 -> A Khai | AG24: =+VLOOKUP(B24,'Biểu 2 TH MỦ dây'!$B$10:$AH$43,33,0) -> 14 | AH24: 8000 | AI24: =+AG24*AH24 -> 112000
A25: 15 | B25: =+'Biểu 2 TH MỦ dây'!B24 -> Võ Thị Nguyên | AG25: =+VLOOKUP(B25,'Biểu 2 TH MỦ dây'!$B$10:$AH$43,33,0) -> 14 | AH25: 8000 | AI25: =+AG25*AH25 -> 112000
A26: 16 | B26: =+'Biểu 2 TH MỦ dây'!B25 -> Tà Lọt | AG26: =+VLOOKUP(B26,'Biểu 2 TH MỦ dây'!$B$10:$AH$43,33,0) -> 14 | AH26: 8000 | AI26: =+AG26*AH26 -> 112000
A27: 17 | B27: =+'Biểu 2 TH MỦ dây'!B26 -> A Han | AG27: =+VLOOKUP(B27,'Biểu 2 TH MỦ dây'!$B$10:$AH$43,33,0) -> 14 | AH27: 8000 | AI27: =+AG27*AH27 -> 112000
A28: 18 | B28: =+'Biểu 2 TH MỦ dây'!B27 -> A Nút | AG28: =+VLOOKUP(B28,'Biểu 2 TH MỦ dây'!$B$10:$AH$43,33,0) -> 14 | AH28: 8000 | AI28: =+AG28*AH28 -> 112000
A29: 19 | B29: =+'Biểu 2 TH MỦ dây'!B28 -> Thảo Buôn | AG29: =+VLOOKUP(B29,'Biểu 2 TH MỦ dây'!$B$10:$AH$43,33,0) -> 14 | AH29: 8000 | AI29: =+AG29*AH29 -> 112000
A30: 20 | B30: =+'Biểu 2 TH MỦ dây'!B29 -> Phò Lấp | AG30: =+VLOOKUP(B30,'Biểu 2 TH MỦ dây'!$B$10:$AH$43,33,0) -> 14 | AH30: 8000 | AI30: =+AG30*AH30 -> 112000
A31: 21 | B31: =+'Biểu 2 TH MỦ dây'!B30 -> Phò Nhạc | AG31: =+VLOOKUP(B31,'Biểu 2 TH MỦ dây'!$B$10:$AH$43,33,0) -> 14 | AH31: 8000 | AI31: =+AG31*AH31 -> 112000
A32: 22 | B32: =+'Biểu 2 TH MỦ dây'!B31 -> Nang Nọi | AG32: =+VLOOKUP(B32,'Biểu 2 TH MỦ dây'!$B$10:$AH$43,33,0) -> 14 | AH32: 8000 | AI32: =+AG32*AH32 -> 112000
A33: 23 | B33: =+'Biểu 2 TH MỦ dây'!B32 -> Húc | AG33: =+VLOOKUP(B33,'Biểu 2 TH MỦ dây'!$B$10:$AH$43,33,0) -> 14 | AH33: 8000 | AI33: =+AG33*AH33 -> 112000
A34: 24 | B34: =+'Biểu 2 TH MỦ dây'!B33 -> A Côm | AG34: =+VLOOKUP(B34,'Biểu 2 TH MỦ dây'!$B$10:$AH$43,33,0) -> 14 | AH34: 8000 | AI34: =+AG34*AH34 -> 112000
A35: 25 | B35: =+'Biểu 2 TH MỦ dây'!B34 -> Nang Phen | AG35: =+VLOOKUP(B35,'Biểu 2 TH MỦ dây'!$B$10:$AH$43,33,0) -> 14 | AH35: 8000 | AI35: =+AG35*AH35 -> 112000
... A44: 34 | B44: =+'Biểu 2 TH MỦ dây'!B43 -> Thảo Xen | AG44: =+VLOOKUP(B44,'Biểu 2 TH MỦ dây'!$B$10:$AH$43,33,0) -> 16 | AH44: 8000 | AI44: =+AG44*AH44 -> 128000
A45: 78 | B45: Trần Quang Thiện | AG45: =SUM(AG11:AG44) -> 490 | AH45: 700 | AI45: =+AG45*AH45 -> 343000
A46: 79 | B46: Hoàng Tấn Thảo | AG46: =+AG45 -> 490 | AH46: 300 | AI46: =+AG46*AH46 -> 147000 | AP46: PHÒNG TC - KT PHÒNG TC - HC P.P PHỤ TRÁCH ĐỘI TRƯỞNG NGƯỜI LẬP
A47: 80 | B47: Vương Thanh Long | AG47: =+AG45 -> 490 | AH47: 1000 | AI47: =+AG47*AH47 -> 490000
A48: Tổng | C48: =#REF!+#REF!+#REF!+#REF! -> #REF! | D48: =#REF!+#REF!+#REF!+#REF! -> #REF! | E48: =#REF!+#REF!+#REF!+#REF! -> #REF! | F48: =#REF!+#REF!+#REF!+#REF! -> #REF! | G48: =#REF!+#REF!+#REF!+#REF! -> #REF! | H48: =#REF!+#REF!+#REF!+#REF! -> #REF! | I48: =#REF!+#REF!+#REF!+#REF! -> #REF! | J48: =#REF!+#REF!+#REF!+#REF! -> #REF! | ... AF48: =#REF!+#REF!+#REF!+#REF! -> #REF! | AG48: =+SUM(AG11:AG44) -> 490 | AI48: =+SUM(AI11:AI47) -> 4900000 | AK48: =+AG48*9000 -> 4410000
A49: Số tiền bằng chữ: Bốn triệu, chín trăm nghìn kíp. | AM49: =+AG48*9000 -> 4410000
AD51: Huyện Noong, ngày 01 tháng 12 năm 2025
...

Sheet Biểu 2 TH MỦ dây
A1: CỘNG HÒA DÂN CHỦ NHÂN DÂN LÀO
A2: Hòa bình - Độc lập - Dân chủ - Thống nhất - Thịnh vượng
A3: ----oOo----
A4: CÔNG TY TNHH MTV QUASA-GERUCO LÀO
A5: ĐỘI SẢN XUẤT SỐ 6
A6: BẢNG THEO DÕI SẢN LƯỢNG MỦ DÂY THÁNG 11 NĂM 2025
AH7: Biểu 2
A8: Stt | B8: Họ và tên | C8: Ngày công | AH8: Tổng mủ dây | AI8: DRC bình quân | AJ8: Mủ dây quy khô (DRC công nhân) | AK8: Xếp hạng kỹ thuật | AL8: Ký tên CN
C9: 1 | D9: 2 | E9: 3 | F9: 4 | G9: 5 | H9: 6 | I9: 7 | J9: 8 | K9: 9 | L9: 10 | M9: 11 | N9: 12 | O9: 13 | P9: 14 | Q9: 15 | R9: 16 | S9: 17 | T9: 18 | U9: 19 | V9: 20 | W9: 21 | X9: 22 | Y9: 23 | Z9: 24 | AA9: 25 | AB9: 26 | AC9: 27 | AD9: 28 | AE9: 29 | AF9: 30 | AG9: 31
A10: 1 | B10: =+'Biểu 1 TH CÔNG'!C11 -> Phò Thưng | C10: - | D10: - | E10: - | F10: - | G10: - | H10: - | I10: - | J10: - | K10: - | L10: - | M10: 7 | N10: - | O10: - | P10: - | Q10: - | R10: - | S10: - | T10: - | U10: - | V10: - | W10: - | X10: - | Y10: - | Z10: - | AA10: 8 | AB10: - | AC10: - | AD10: - | AE10: - | AF10: - | AG10: - | AH10: =SUM(C10:AG10) -> 15 | AJ10: =AH10*AI10/100 -> 0
A11: 2 | B11: =+'Biểu 1 TH CÔNG'!C12 -> A Nhợp | C11: - | D11: - | E11: - | F11: - | G11: - | H11: - | I11: - | J11: - | K11: - | L11: - | M11: 7 | N11: - | O11: - | P11: - | Q11: - | R11: - | S11: - | T11: - | U11: - | V11: - | W11: - | X11: - | Y11: - | Z11: - | AA11: 8 | AB11: - | AC11: - | AD11: - | AE11: - | AF11: - | AG11: - | AH11: =SUM(C11:AG11) -> 15 | AJ11: =AH11*AI11/100 -> 0 | AN11: 46.656799
A12: 3 | B12: =+'Biểu 1 TH CÔNG'!C13 -> Van | C12: - | D12: - | E12: - | F12: - | G12: - | H12: - | I12: - | J12: - | K12: - | L12: - | M12: 7 | N12: - | O12: - | P12: - | Q12: - | R12: - | S12: - | T12: - | U12: - | V12: - | W12: - | X12: - | Y12: - | Z12: - | AA12: 8 | AB12: - | AC12: - | AD12: - | AE12: - | AF12: - | AG12: - | AH12: =SUM(C12:AG12) -> 15 | AJ12: =AH12*AI12/100 -> 0 | AN12: =AN11/100 -> 0.46656799
A13: 4 | B13: =+'Biểu 1 TH CÔNG'!C14 -> Thảo Khọt | C13: - | D13: - | E13: - | F13: - | G13: - | H13: - | I13: - | J13: - | K13: - | L13: - | M13: 7 | N13: - | O13: - | P13: - | Q13: - | R13: - | S13: - | T13: - | U13: - | V13: - | W13: - | X13: - | Y13: - | Z13: - | AA13: 8 | AB13: - | AC13: - | AD13: - | AE13: - | AF13: - | AG13: - | AH13: =SUM(C13:AG13) -> 15 | AJ13: =AH13*AI13/100 -> 0
A14: 5 | B14: =+'Biểu 1 TH CÔNG'!C15 -> A Cơ | C14: - | D14: - | E14: - | F14: - | G14: - | H14: - | I14: - | J14: - | K14: - | L14: - | M14: 7 | N14: - | O14: - | P14: - | Q14: - | R14: - | S14: - | T14: - | U14: - | V14: - | W14: - | X14: - | Y14: - | Z14: - | AA14: 8 | AB14: - | AC14: - | AD14: - | AE14: - | AF14: - | AG14: - | AH14: =SUM(C14:AG14) -> 15 | AJ14: =AH14*AI14/100 -> 0
A15: 6 | B15: =+'Biểu 1 TH CÔNG'!C16 -> Phơ | C15: - | D15: - | E15: - | F15: - | G15: - | H15: - | I15: - | J15: - | K15: - | L15: - | M15: 7 | N15: - | O15: - | P15: - | Q15: - | R15: - | S15: - | T15: - | U15: - | V15: - | W15: - | X15: - | Y15: - | Z15: - | AA15: 8 | AB15: - | AC15: - | AD15: - | AE15: - | AF15: - | AG15: - | AH15: =SUM(C15:AG15) -> 15 | AJ15: =AH15*AI15/100 -> 0
A16: 7 | B16: =+'Biểu 1 TH CÔNG'!C17 -> A phơ | C16: - | D16: - | E16: - | F16: - | G16: - | H16: - | I16: - | J16: - | K16: - | L16: - | M16: 7 | N16: - | O16: - | P16: - | Q16: - | R16: - | S16: - | T16: - | U16: - | V16: - | W16: - | X16: - | Y16: - | Z16: - | AA16: 8 | AB16: - | AC16: - | AD16: - | AE16: - | AF16: - | AG16: - | AH16: =SUM(C16:AG16) -> 15 | AJ16: =AH16*AI16/100 -> 0
A17: 8 | B17: =+'Biểu 1 TH CÔNG'!C18 -> Nang Đăm | C17: - | D17: - | E17: - | F17: - | G17: - | H17: - | I17: - | J17: - | K17: - | L17: - | M17: 7 | N17: - | O17: - | P17: - | Q17: - | R17: - | S17: - | T17: - | U17: - | V17: - | W17: - | X17: - | Y17: - | Z17: - | AA17: 7 | AB17: - | AC17: - | AD17: - | AE17: - | AF17: - | AG17: - | AH17: =SUM(C17:AG17) -> 14 | AJ17: =AH17*AI17/100 -> 0
A18: 9 | B18: =+'Biểu 1 TH CÔNG'!C19 -> Nang Sun | C18: - | D18: - | E18: - | F18: - | G18: - | H18: - | I18: - | J18: - | K18: - | L18: - | M18: 7 | N18: - | O18: - | P18: - | Q18: - | R18: - | S18: - | T18: - | U18: - | V18: - | W18: - | X18: - | Y18: - | Z18: - | AA18: 7 | AB18: - | AC18: - | AD18: - | AE18: - | AF18: - | AG18: - | AH18: =SUM(C18:AG18) -> 14 | AJ18: =AH18*AI18/100 -> 0
A19: 10 | B19: =+'Biểu 1 TH CÔNG'!C20 -> A Nghen | C19: - | D19: - | E19: - | F19: - | G19: - | H19: - | I19: - | J19: - | K19: - | L19: - | M19: 7 | N19: - | O19: - | P19: - | Q19: - | R19: - | S19: - | T19: - | U19: - | V19: - | W19: - | X19: - | Y19: - | Z19: - | AA19: 7 | AB19: - | AC19: - | AD19: - | AE19: - | AF19: - | AG19: - | AH19: =SUM(C19:AG19) -> 14 | AJ19: =AH19*AI19/100 -> 0
A20: 11 | B20: =+'Biểu 1 TH CÔNG'!C21 -> Nguyễn Thị Thanh Trà | C20: - | D20: - | E20: - | F20: - | G20: - | H20: - | I20: - | J20: - | K20: - | L20: - | M20: 7 | N20: - | O20: - | P20: - | Q20: - | R20: - | S20: - | T20: - | U20: - | V20: - | W20: - | X20: - | Y20: - | Z20: - | AA20: 7 | AB20: - | AC20: - | AD20: - | AE20: - | AF20: - | AG20: - | AH20: =SUM(C20:AG20) -> 14 | AJ20: =AH20*AI20/100 -> 0
A21: 12 | B21: =+'Biểu 1 TH CÔNG'!C22 -> Phò Thít | C21: - | D21: - | E21: - | F21: - | G21: - | H21: - | I21: - | J21: - | K21: - | L21: - | M21: 7 | N21: - | O21: - | P21: - | Q21: - | R21: - | S21: - | T21: - | U21: - | V21: - | W21: - | X21: - | Y21: - | Z21: - | AA21: 7 | AB21: - | AC21: - | AD21: - | AE21: - | AF21: - | AG21: - | AH21: =SUM(C21:AG21) -> 14 | AJ21: =AH21*AI21/100 -> 0
A22: 13 | B22: =+'Biểu 1 TH CÔNG'!C23 -> A Bợp | C22: - | D22: - | E22: - | F22: - | G22: - | H22: - | I22: - | J22: - | K22: - | L22: - | M22: 7 | N22: - | O22: - | P22: - | Q22: - | R22: - | S22: - | T22: - | U22: - | V22: - | W22: - | X22: - | Y22: - | Z22: - | AA22: 7 | AB22: - | AC22: - | AD22: - | AE22: - | AF22: - | AG22: - | AH22: =SUM(C22:AG22) -> 14 | AJ22: =AH22*AI22/100 -> 0
A23: 14 | B23: =+'Biểu 1 TH CÔNG'!C24 -> A Khai | C23: - | D23: - | E23: - | F23: - | G23: - | H23: - | I23: - | J23: - | K23: - | L23: - | M23: 7 | N23: - | O23: - | P23: - | Q23: - | R23: - | S23: - | T23: - | U23: - | V23: - | W23: - | X23: - | Y23: - | Z23: - | AA23: 7 | AB23: - | AC23: - | AD23: - | AE23: - | AF23: - | AG23: - | AH23: =SUM(C23:AG23) -> 14 | AJ23: =AH23*AI23/100 -> 0
A24: 15 | B24: =+'Biểu 1 TH CÔNG'!C25 -> Võ Thị Nguyên | C24: - | D24: - | E24: - | F24: - | G24: - | H24: - | I24: - | J24: - | K24: - | L24: - | M24: 7 | N24: - | O24: - | P24: - | Q24: - | R24: - | S24: - | T24: - | U24: - | V24: - | W24: - | X24: - | Y24: - | Z24: - | AA24: 7 | AB24: - | AC24: - | AD24: - | AE24: - | AF24: - | AG24: - | AH24: =SUM(C24:AG24) -> 14 | AJ24: =AH24*AI24/100 -> 0
... A42: 33 | B42: =+'Biểu 1 TH CÔNG'!C43 -> Nang Cung | C42: - | D42: - | E42: - | F42: - | G42: - | H42: - | I42: - | J42: - | K42: - | L42: - | M42: 8 | N42: - | O42: - | P42: - | Q42: - | R42: - | S42: - | T42: - | U42: - | V42: - | W42: - | X42: - | Y42: - | Z42: - | AA42: 8 | AB42: - | AC42: - | AD42: - | AE42: - | AF42: - | AG42: - | AH42: =SUM(C42:AG42) -> 16 | AJ42: =AH42*AI42/100 -> 0
A43: 34 | B43: =+'Biểu 1 TH CÔNG'!C44 -> Thảo Xen | C43: - | D43: - | E43: - | F43: - | G43: - | H43: - | I43: - | J43: - | K43: - | L43: - | M43: 8 | N43: - | O43: - | P43: - | Q43: - | R43: - | S43: - | T43: - | U43: - | V43: - | W43: - | X43: - | Y43: - | Z43: - | AA43: 8 | AB43: - | AC43: - | AD43: - | AE43: - | AF43: - | AG43: - | AH43: =SUM(C43:AG43) -> 16
B44: TỔNG | C44: - | D44: - | E44: - | F44: - | G44: - | H44: - | I44: - | J44: - | K44: - | L44: =SUM(L10:L43) -> 0 | M44: =SUM(M10:M43) -> 240 | N44: - | O44: - | P44: - | Q44: - | R44: - | S44: - | T44: - | U44: - | V44: - | W44: - | X44: - | Y44: - | Z44: - | AA44: =SUM(AA10:AA43) -> 250 | AB44: - | AC44: - | AD44: - | AE44: - | AF44: - | AG44: - | AH44: =SUM(AH10:AH43) -> 490
AA45: Huyện Noong, ngày 01 tháng 12 năm 2025
B47: TỔNG GIÁM ĐỐC | I47: P. TC-HC | P47: P. QLKT | U47: P.P PHỤ TRÁCH | AB47: ĐỘI TRƯỞNG | AG47: NGƯỜI LẬP | AH47: NGƯỜI LẬP
I62: Hồ Thị Thủy | U62: Hoàng Tấn Thảo | AB62: Trần Quang Thiện | AH62: Hồ Dũng Cảm

Sheet SẢN LƯỢNG  SERUM THÁNG 12
A1: CỘNG HÒA DÂN CHỦ NHÂN DÂN LÀO
A2: Hòa Bình - Độc Lập - Dân Chủ - Thống Nhất - Thịnh Vượng
A3: ----oOo----
A4: CÔNG TY TNHH MTV QUASA-GERUCO LÀO
A5: ĐỘI SẢN XUẤT SỐ 06
A7: BẢNG TỔNG HỢP SẢN LƯỢNG MỦ XIRUM THÁNG 12 NĂM 2025
A8: (Từ ngày 01/12 đến 31/12/2025)
A9: Nội dung | B9: Ngày | AG9: Tổng mủ Xirum | AH9: Mủ Xirum quy khô | AI9: Ghi chú | AJ9: DRC trạm 1 | AK9: 40.586752 | AL9: 102 | AM9: 57.369
B10: 1 | C10: 2 | D10: 3 | E10: 4 | F10: 5 | G10: 6 | H10: 7 | I10: 8 | J10: 9 | K10: 10 | L10: 11 | M10: 12 | N10: 13 | O10: 14 | P10: 15 | Q10: 16 | R10: 17 | S10: 18 | T10: 19 | U10: 20 | V10: 21 | W10: 22 | X10: 23 | Y10: 24 | Z10: 25 | AA10: 26 | AB10: 27 | AC10: 28 | AD10: 29 | AE10: 30 | AF10: 31 | AJ10: DRC trạm 2 | AK10: =AM10/AL10 -> 0.5467234 | AL10: 94 | AM10: 51.392
A12: Mủ sirum | F12: 137 | AD12: 97 | AG12: =SUM(B12:AF12) -> 234 | AH12: =AG12*$AK$9/100 -> 94.973
A13: Mủ serum trạm 2 | AG13: =SUM(B13:AF13) -> 0 | AH13: =AG13*$AK$10 -> 0
A14: TỔNG CỘNG | B14: =SUM(B12:B13) -> 0 | C14: =SUM(C12:C13) -> 0 | D14: =SUM(D12:D13) -> 0 | E14: =SUM(E12:E13) -> 0 | F14: =SUM(F12:F13) -> 137 | G14: =SUM(G12:G13) -> 0 | H14: =SUM(H12:H13) -> 0 | I14: =SUM(I12:I13) -> 0 | ... AH14: =SUM(AH12:AH13) -> 94.973 | AJ14: =SUM(#REF!,#REF!) -> #REF! | AK14: ='[4]TRUY LĨNH SL THÁNG 8'!AL73 -> 3355.984 | AL14: =AK14-AG14 -> 3121.984
Z16: Huyện Noong, ngày 31 tháng 12 năm 2025
B17: TỔNG GIÁM ĐỐC | J17: PHÒNG QLKT | O17: PHÒNG TC - HC | U17: P.PHÒNG PHỤ TRÁCH | AB17: ĐỘI TRƯỞNG | AH17: NGƯỜI LẬP
O23: Hồ Thị Thủy | U23: Hoàng Tấn Thảo | AB23: Trần Quang Thiện | AH23: Hồ Dũng Cảm

Sheet Phu cấp cây non
A1: CỘNG HÒA DÂN CHỦ NHÂN DÂN LÀO
A2: Hòa bình - Độc lập - Dân chủ - Thống nhất - Thịnh vượng
A3: ----oOo----
A4: CÔNG TY TNHH MTV QUASA-GERUCO LÀO
A5: ĐỘI SẢN XUẤT SỐ 6
A7: BẢNG CHẤM CÔNG PHỤ CẤP CÂY NON KHAI THÁC THÁNG 12 NĂM 2025
A9: Stt | B9: Họ và tên | C9: Ngày công | AH9: Tổng ngày công | AI9: Ký tên
C10: 1 | D10: 2 | E10: 3 | F10: 4 | G10: 5 | H10: 6 | I10: 7 | J10: 8 | K10: 9 | L10: 10 | M10: 11 | N10: 12 | O10: 13 | P10: 14 | Q10: 15 | R10: 16 | S10: 17 | T10: 18 | U10: 19 | V10: 20 | W10: 21 | X10: 22 | Y10: 23 | Z10: 24 | AA10: 25 | AB10: 26 | AC10: 27 | AD10: 28 | AE10: 29 | AF10: 30 | AG10: 31
A11: II | B11: TRẠM 2 | C11: =COUNTIF(C12:C17,"x")+COUNTIF(C12:C17,"cn")+COUNTIF(C12:C17,"cnđ")+COUNTIF(C12:C17,"đ") -> 6 | D11: =COUNTIF(D12:D17,"x")+COUNTIF(D12:D17,"cn")+COUNTIF(D12:D17,"cnđ")+COUNTIF(D12:D17,"đ") -> 6 | E11: =COUNTIF(E12:E17,"x")+COUNTIF(E12:E17,"cn")+COUNTIF(E12:E17,"cnđ")+COUNTIF(E12:E17,"đ") -> 6 | F11: =COUNTIF(F12:F17,"x")+COUNTIF(F12:F17,"cn")+COUNTIF(F12:F17,"cnđ")+COUNTIF(F12:F17,"đ") -> 6 | G11: =COUNTIF(G12:G17,"x")+COUNTIF(G12:G17,"cn")+COUNTIF(G12:G17,"cnđ")+COUNTIF(G12:G17,"đ") -> 6 | H11: =COUNTIF(H12:H17,"x")+COUNTIF(H12:H17,"cn")+COUNTIF(H12:H17,"cnđ")+COUNTIF(H12:H17,"đ") -> 6 | I11: =COUNTIF(I12:I17,"x")+COUNTIF(I12:I17,"cn")+COUNTIF(I12:I17,"cnđ")+COUNTIF(I12:I17,"đ") -> 6 | J11: =COUNTIF(J12:J17,"x")+COUNTIF(J12:J17,"cn")+COUNTIF(J12:J17,"cnđ")+COUNTIF(J12:J17,"đ") -> 6 | ... AG11: =COUNTIF(AG12:AG17,"x")+COUNTIF(AG12:AG17,"cn")+COUNTIF(AG12:AG17,"cnđ")+COUNTIF(AG12:AG17,"đ") -> 6 | AH11: =SUM(AH12:AH17) -> 186
A12: 1 | B12: =+'Biểu 1 TH CÔNG'!C83 -> Thảo Vong | C12: x | D12: x | E12: x | F12: x | G12: x | H12: x | I12: x | J12: x | K12: x | L12: x | M12: x | N12: x | O12: x | P12: x | Q12: x | R12: x | S12: x | T12: x | U12: x | V12: x | W12: x | X12: x | Y12: x | Z12: x | AA12: x | AB12: x | AC12: x | AD12: x | AE12: x | AF12: x | AG12: x | AH12: =COUNTIF(C12:AG12,"X") -> 31
A13: 2 | B13: =+'Biểu 1 TH CÔNG'!C84 -> Nàng Veng | C13: x | D13: x | E13: x | F13: x | G13: x | H13: x | I13: x | J13: x | K13: x | L13: x | M13: x | N13: x | O13: x | P13: x | Q13: x | R13: x | S13: x | T13: x | U13: x | V13: x | W13: x | X13: x | Y13: x | Z13: x | AA13: x | AB13: x | AC13: x | AD13: x | AE13: x | AF13: x | AG13: x | AH13: =COUNTIF(C13:AG13,"X") -> 31
A14: 3 | B14: =+'Biểu 1 TH CÔNG'!C85 -> Thảo Đuông Chăn | C14: x | D14: x | E14: x | F14: x | G14: x | H14: x | I14: x | J14: x | K14: x | L14: x | M14: x | N14: x | O14: x | P14: x | Q14: x | R14: x | S14: x | T14: x | U14: x | V14: x | W14: x | X14: x | Y14: x | Z14: x | AA14: x | AB14: x | AC14: x | AD14: x | AE14: x | AF14: x | AG14: x | AH14: =COUNTIF(C14:AG14,"X") -> 31
A15: 4 | B15: =+'Biểu 1 TH CÔNG'!C86 -> Nàng Peng | C15: x | D15: x | E15: x | F15: x | G15: x | H15: x | I15: x | J15: x | K15: x | L15: x | M15: x | N15: x | O15: x | P15: x | Q15: x | R15: x | S15: x | T15: x | U15: x | V15: x | W15: x | X15: x | Y15: x | Z15: x | AA15: x | AB15: x | AC15: x | AD15: x | AE15: x | AF15: x | AG15: x | AH15: =COUNTIF(C15:AG15,"X") -> 31
A16: 5 | B16: =+'Biểu 1 TH CÔNG'!C87 -> Thảo Xay Tho | C16: x | D16: x | E16: x | F16: x | G16: x | H16: x | I16: x | J16: x | K16: x | L16: x | M16: x | N16: x | O16: x | P16: x | Q16: x | R16: x | S16: x | T16: x | U16: x | V16: x | W16: x | X16: x | Y16: x | Z16: x | AA16: x | AB16: x | AC16: x | AD16: x | AE16: x | AF16: x | AG16: x | AH16: =COUNTIF(C16:AG16,"X") -> 31
A17: 6 | B17: =+'Biểu 1 TH CÔNG'!C88 -> Nàng Xia Lô | C17: x | D17: x | E17: x | F17: x | G17: x | H17: x | I17: x | J17: x | K17: x | L17: x | M17: x | N17: x | O17: x | P17: x | Q17: x | R17: x | S17: x | T17: x | U17: x | V17: x | W17: x | X17: x | Y17: x | Z17: x | AA17: x | AB17: x | AC17: x | AD17: x | AE17: x | AF17: x | AG17: x | AH17: =COUNTIF(C17:AG17,"X") -> 31
B18: TỔNG CỘNG | C18: =+C11 -> 6 | D18: =+D11 -> 6 | E18: =+E11 -> 6 | F18: =+F11 -> 6 | G18: =+G11 -> 6 | H18: =+H11 -> 6 | I18: =+I11 -> 6 | J18: =+J11 -> 6 | ... AH18: =+AH11 -> 186
B20: Ghi chú: | C20: x: Ngày công cạo thường | AA20: Huyện Noong, ngày 31 tháng 12 năm 2025
B22: TỔNG GIÁM ĐỐC | I22: PHÒNG TC-HC | O22: PHÒNG QLKT | U22: P.P PHỤ TRÁCH | AA22: ĐỘI TRƯỞNG | AG22: NGƯỜI LẬP
I32: Hồ Thị Thủy | U32: Hoàng Tấn Thảo | AA32: Trần Quang Thiện | AH32: Hồ Dũng Cảm

Sheet Biểu 1 TH CÔNG
A1: CỘNG HÒA DÂN CHỦ NHÂN DÂN LÀO
A2: Hòa bình - Độc lập - Dân chủ - Thống nhất - Thịnh vượng
A3: ----oOo----
A4: CÔNG TY TNHH MTV QUASA-GERUCO LÀO
A5: ĐỘI SẢN XUẤT SỐ 6
A7: BẢNG CHẤM CÔNG THEO DÕI CÔNG NHÂN KHAI THÁC THÁNG 12 NĂM 2025
AJ8: Biểu 1
A9: Stt | C9: Họ và tên | D9: Ngày công | AI9: Trong đó | AN9: Ký tên
D10: 1 | E10: 2 | F10: 3 | G10: 4 | H10: 5 | I10: 6 | J10: 7 | K10: 8 | L10: 9 | M10: 10 | N10: 11 | O10: 12 | P10: 13 | Q10: 14 | R10: 15 | S10: 16 | T10: 17 | U10: 18 | V10: 19 | W10: 20 | X10: 21 | Y10: 22 | Z10: 23 | AA10: 24 | AB10: 25 | AC10: 26 | AD10: 27 | AE10: 28 | AF10: 29 | AG10: 30 | AH10: 31 | AI10: Ngày công cạo thường (x) | AJ10: Ngày công chủ nhật (cn) | AK10: Cạo đúp ngày thường (đ) | AL10: Cạo đúp ngày chủ nhật (đcn) | AM10: Tổng ngày công đi cạo
A11: 1 | C11: =+'[5]TỔNG MỦ TẠP'!$B9 -> Phò Thưng | D11: x | E11: x | F11: x | G11: x | H11: x | I11: x | J11: cn | K11: x | L11: x | M11: x | N11: x | O11: x | P11: x | Q11: cn | R11: x | S11: x | T11: x | U11: x | V11: x | W11: x | X11: cn | Y11: x | Z11: x | AA11: x | AB11: x | AC11: x | AD11: x | AE11: cn | AF11: x | AG11: x | AH11: x | AI11: =COUNTIF(D11:AH11,"x") -> 27 | AJ11: =COUNTIF(D11:AH11,"cn") -> 4 | AK11: =COUNTIF(D11:AH11,"đ") -> 0 | AL11: =COUNTIF(D11:AH11,"đcn") -> 0 | AM11: =SUM(AI11:AL11) -> 31
A12: 2 | C12: =+'[5]TỔNG MỦ TẠP'!$B10 -> A Nhợp | D12: x | E12: x | F12: x | G12: x | H12: x | I12: x | J12: cn | K12: x | L12: x | M12: x | N12: x | O12: x | P12: x | Q12: cn | R12: x | S12: x | T12: x | U12: x | V12: x | X12: cn | Y12: x | Z12: x | AA12: x | AB12: x | AC12: x | AD12: x | AE12: cn | AF12: x | AG12: x | AH12: x | AI12: =COUNTIF(D12:AH12,"x") -> 26 | AJ12: =COUNTIF(D12:AH12,"cn") -> 4 | AK12: =COUNTIF(D12:AH12,"đ") -> 0 | AL12: =COUNTIF(D12:AH12,"đcn") -> 0 | AM12: =SUM(AI12:AL12) -> 30
A13: 3 | C13: =+'[5]TỔNG MỦ TẠP'!$B11 -> Van | F13: x | G13: x | H13: x | I13: x | J13: cn | K13: x | L13: x | M13: x | N13: x | O13: x | Q13: cn | R13: x | S13: x | T13: x | U13: x | V13: x | X13: cn | Y13: x | Z13: x | AA13: x | AB13: x | AC13: x | AD13: x | AE13: cn | AF13: x | AG13: x | AH13: x | AI13: =COUNTIF(D13:AH13,"x") -> 23 | AJ13: =COUNTIF(D13:AH13,"cn") -> 4 | AK13: =COUNTIF(D13:AH13,"đ") -> 0 | AL13: =COUNTIF(D13:AH13,"đcn") -> 0 | AM13: =SUM(AI13:AL13) -> 27
A14: 4 | C14: =+'[5]TỔNG MỦ TẠP'!$B12 -> Thảo Khọt | D14: x | E14: x | F14: x | G14: x | H14: x | I14: x | J14: cn | K14: x | L14: x | M14: x | N14: x | O14: x | P14: x | Q14: cn | R14: x | S14: x | T14: x | U14: x | V14: x | W14: x | X14: cn | Y14: x | Z14: x | AA14: x | AB14: x | AC14: x | AD14: x | AE14: cn | AF14: x | AG14: x | AH14: x | AI14: =COUNTIF(D14:AH14,"x") -> 27 | AJ14: =COUNTIF(D14:AH14,"cn") -> 4 | AK14: =COUNTIF(D14:AH14,"đ") -> 0 | AL14: =COUNTIF(D14:AH14,"đcn") -> 0 | AM14: =SUM(AI14:AL14) -> 31
A15: 5 | C15: =+'[5]TỔNG MỦ TẠP'!$B13 -> A Cơ | D15: x | E15: x | F15: x | G15: x | H15: x | I15: x | J15: cn | K15: x | L15: x | M15: x | N15: x | O15: x | P15: x | Q15: cn | R15: x | S15: x | T15: x | U15: x | V15: x | W15: x | X15: cn | Y15: x | Z15: x | AA15: x | AB15: x | AC15: x | AD15: x | AE15: cn | AF15: x | AG15: x | AH15: x | AI15: =COUNTIF(D15:AH15,"x") -> 27 | AJ15: =COUNTIF(D15:AH15,"cn") -> 4 | AK15: =COUNTIF(D15:AH15,"đ") -> 0 | AL15: =COUNTIF(D15:AH15,"đcn") -> 0 | AM15: =SUM(AI15:AL15) -> 31
A16: 6 | C16: =+'[5]TỔNG MỦ TẠP'!$B14 -> Phơ | D16: x | E16: x | F16: x | G16: x | H16: x | I16: x | J16: cn | K16: x | L16: x | M16: x | N16: x | O16: x | P16: x | R16: x | S16: x | T16: x | U16: x | V16: x | W16: x | Y16: x | Z16: x | AA16: x | AB16: x | AC16: x | AD16: x | AE16: cn | AF16: x | AG16: x | AH16: x | AI16: =COUNTIF(D16:AH16,"x") -> 27 | AJ16: =COUNTIF(D16:AH16,"cn") -> 2 | AK16: =COUNTIF(D16:AH16,"đ") -> 0 | AL16: =COUNTIF(D16:AH16,"đcn") -> 0 | AM16: =SUM(AI16:AL16) -> 29
A17: 7 | C17: =+'[5]TỔNG MỦ TẠP'!$B15 -> A phơ | D17: x | E17: x | F17: x | G17: x | H17: x | I17: x | J17: cn | K17: x | L17: x | M17: x | N17: x | O17: x | P17: x | Q17: cn | R17: x | S17: x | T17: x | U17: x | V17: x | W17: x | X17: cn | Y17: x | Z17: x | AA17: x | AB17: x | AC17: x | AD17: x | AE17: cn | AF17: x | AG17: x | AH17: x | AI17: =COUNTIF(D17:AH17,"x") -> 27 | AJ17: =COUNTIF(D17:AH17,"cn") -> 4 | AK17: =COUNTIF(D17:AH17,"đ") -> 0 | AL17: =COUNTIF(D17:AH17,"đcn") -> 0 | AM17: =SUM(AI17:AL17) -> 31
A18: 8 | C18: =+'[5]TỔNG MỦ TẠP'!$B16 -> Nang Đăm | D18: x | E18: x | F18: x | G18: x | H18: x | I18: x | J18: cn | K18: x | L18: x | M18: x | N18: x | O18: x | P18: x | Q18: cn | R18: x | S18: x | U18: x | V18: x | W18: x | X18: cn | Y18: x | Z18: x | AA18: x | AB18: x | AC18: x | AD18: x | AE18: cn | AF18: x | AG18: x | AH18: x | AI18: =COUNTIF(D18:AH18,"x") -> 26 | AJ18: =COUNTIF(D18:AH18,"cn") -> 4 | AK18: =COUNTIF(D18:AH18,"đ") -> 0 | AL18: =COUNTIF(D18:AH18,"đcn") -> 0 | AM18: =SUM(AI18:AL18) -> 30
A19: 9 | C19: =+'[5]TỔNG MỦ TẠP'!$B17 -> Nang Sun | D19: x | E19: x | F19: x | G19: x | H19: x | I19: x | J19: cn | K19: x | L19: x | M19: x | N19: x | O19: x | P19: x | Q19: cn | R19: x | S19: x | T19: x | U19: x | V19: x | W19: x | X19: cn | Y19: x | Z19: x | AA19: x | AB19: x | AC19: x | AD19: x | AE19: cn | AF19: x | AG19: x | AH19: x | AI19: =COUNTIF(D19:AH19,"x") -> 27 | AJ19: =COUNTIF(D19:AH19,"cn") -> 4 | AK19: =COUNTIF(D19:AH19,"đ") -> 0 | AL19: =COUNTIF(D19:AH19,"đcn") -> 0 | AM19: =SUM(AI19:AL19) -> 31
A20: 10 | C20: =+'[5]TỔNG MỦ TẠP'!$B18 -> A Nghen | D20: x | E20: x | F20: x | G20: x | I20: x | J20: cn | K20: x | L20: x | M20: x | N20: x | O20: x | P20: x | Q20: cn | R20: x | S20: x | T20: x | U20: x | X20: cn | Y20: x | Z20: x | AA20: x | AB20: x | AC20: x | AD20: x | AE20: cn | AF20: x | AG20: x | AH20: x | AI20: =COUNTIF(D20:AH20,"x") -> 24 | AJ20: =COUNTIF(D20:AH20,"cn") -> 4 | AK20: =COUNTIF(D20:AH20,"đ") -> 0 | AL20: =COUNTIF(D20:AH20,"đcn") -> 0 | AM20: =SUM(AI20:AL20) -> 28
A21: 11 | C21: =+'[5]TỔNG MỦ TẠP'!$B19 -> Nguyễn Thị Thanh Trà | D21: x | E21: x | F21: x | G21: x | H21: x | I21: x | J21: cn | K21: x | L21: x | M21: x | N21: x | O21: x | P21: x | Q21: cn | R21: x | S21: x | T21: x | U21: x | V21: x | W21: x | X21: cn | Y21: x | Z21: x | AA21: x | AB21: x | AC21: x | AD21: x | AE21: cn | AF21: x | AG21: x | AH21: x | AI21: =COUNTIF(D21:AH21,"x") -> 27 | AJ21: =COUNTIF(D21:AH21,"cn") -> 4 | AK21: =COUNTIF(D21:AH21,"đ") -> 0 | AL21: =COUNTIF(D21:AH21,"đcn") -> 0 | AM21: =SUM(AI21:AL21) -> 31
A22: 12 | C22: =+'[5]TỔNG MỦ TẠP'!$B20 -> Phò Thít | D22: x | E22: x | F22: x | G22: x | H22: x | I22: x | J22: cn | K22: x | L22: x | M22: x | N22: x | O22: x | P22: x | Q22: cn | R22: x | S22: x | T22: x | U22: x | V22: x | W22: x | X22: cn | Y22: x | Z22: x | AA22: x | AB22: x | AC22: x | AD22: x | AE22: cn | AF22: x | AG22: x | AH22: x | AI22: =COUNTIF(D22:AH22,"x") -> 27 | AJ22: =COUNTIF(D22:AH22,"cn") -> 4 | AK22: =COUNTIF(D22:AH22,"đ") -> 0 | AL22: =COUNTIF(D22:AH22,"đcn") -> 0 | AM22: =SUM(AI22:AL22) -> 31
A23: 13 | C23: =+'[5]TỔNG MỦ TẠP'!$B21 -> A Bợp | D23: x | E23: x | F23: x | G23: x | H23: x | I23: x | J23: cn | K23: x | L23: x | M23: x | N23: x | O23: x | P23: x | Q23: cn | R23: x | S23: x | T23: x | U23: x | V23: x | W23: x | X23: cn | Y23: x | Z23: x | AA23: x | AB23: x | AC23: x | AD23: x | AE23: cn | AF23: x | AG23: x | AH23: x | AI23: =COUNTIF(D23:AH23,"x") -> 27 | AJ23: =COUNTIF(D23:AH23,"cn") -> 4 | AK23: =COUNTIF(D23:AH23,"đ") -> 0 | AL23: =COUNTIF(D23:AH23,"đcn") -> 0 | AM23: =SUM(AI23:AL23) -> 31
A24: 14 | C24: =+'[5]TỔNG MỦ TẠP'!$B22 -> A Khai | D24: x | E24: x | F24: x | G24: x | H24: x | I24: x | J24: cn | K24: x | L24: x | M24: x | N24: x | O24: x | P24: x | Q24: cn | R24: x | S24: x | T24: x | U24: x | V24: x | W24: x | X24: cn | Y24: x | Z24: x | AA24: x | AB24: x | AC24: x | AD24: x | AE24: cn | AF24: x | AG24: x | AH24: x | AI24: =COUNTIF(D24:AH24,"x") -> 27 | AJ24: =COUNTIF(D24:AH24,"cn") -> 4 | AK24: =COUNTIF(D24:AH24,"đ") -> 0 | AL24: =COUNTIF(D24:AH24,"đcn") -> 0 | AM24: =SUM(AI24:AL24) -> 31
A25: 15 | C25: =+'[5]TỔNG MỦ TẠP'!$B23 -> Võ Thị Nguyên | D25: x | E25: x | F25: x | G25: x | H25: x | I25: x | J25: cn | K25: x | L25: x | M25: x | N25: x | O25: x | P25: x | Q25: cn | R25: x | S25: x | T25: x | U25: x | V25: x | W25: x | X25: cn | Y25: x | Z25: x | AA25: x | AB25: x | AC25: x | AD25: x | AE25: cn | AF25: x | AG25: x | AH25: x | AI25: =COUNTIF(D25:AH25,"x") -> 27 | AJ25: =COUNTIF(D25:AH25,"cn") -> 4 | AK25: =COUNTIF(D25:AH25,"đ") -> 0 | AL25: =COUNTIF(D25:AH25,"đcn") -> 0 | AM25: =SUM(AI25:AL25) -> 31
A26: 16 | C26: =+'[5]TỔNG MỦ TẠP'!$B24 -> Tà Lọt | D26: x | E26: x | F26: x | G26: x | H26: x | I26: x | J26: cn | K26: x | L26: x | M26: x | N26: x | O26: x | P26: x | Q26: cn | S26: x | T26: x | U26: x | V26: x | W26: x | X26: cn | Y26: x | Z26: x | AA26: x | AB26: x | AC26: x | AD26: x | AE26: cn | AF26: x | AG26: x | AH26: x | AI26: =COUNTIF(D26:AH26,"x") -> 26 | AJ26: =COUNTIF(D26:AH26,"cn") -> 4 | AK26: =COUNTIF(D26:AH26,"đ") -> 0 | AL26: =COUNTIF(D26:AH26,"đcn") -> 0 | AM26: =SUM(AI26:AL26) -> 30
A27: 17 | C27: =+'[5]TỔNG MỦ TẠP'!$B25 -> A Han | D27: x | E27: x | F27: x | H27: x | I27: x | J27: cn | K27: x | L27: x | M27: x | N27: x | O27: x | P27: x | Q27: cn | R27: x | S27: x | T27: x | U27: x | X27: cn | Y27: x | Z27: x | AA27: x | AB27: x | AC27: x | AD27: x | AE27: cn | AF27: x | AG27: x | AH27: x | AI27: =COUNTIF(D27:AH27,"x") -> 24 | AJ27: =COUNTIF(D27:AH27,"cn") -> 4 | AK27: =COUNTIF(D27:AH27,"đ") -> 0 | AL27: =COUNTIF(D27:AH27,"đcn") -> 0 | AM27: =SUM(AI27:AL27) -> 28
A28: 18 | C28: =+'[5]TỔNG MỦ TẠP'!$B26 -> A Nút | D28: x | E28: x | F28: x | G28: x | H28: x | I28: x | J28: cn | K28: x | L28: x | M28: x | N28: x | O28: x | P28: x | Q28: cn | R28: x | S28: x | T28: x | U28: x | V28: x | W28: x | X28: cn | Y28: x | Z28: x | AA28: x | AB28: x | AC28: x | AD28: x | AE28: cn | AF28: x | AG28: x | AH28: x | AI28: =COUNTIF(D28:AH28,"x") -> 27 | AJ28: =COUNTIF(D28:AH28,"cn") -> 4 | AK28: =COUNTIF(D28:AH28,"đ") -> 0 | AL28: =COUNTIF(D28:AH28,"đcn") -> 0 | AM28: =SUM(AI28:AL28) -> 31
A29: 19 | C29: =+'[5]TỔNG MỦ TẠP'!$B27 -> Thảo Buôn | D29: x | E29: x | F29: x | G29: x | H29: x | I29: x | J29: cn | K29: x | L29: x | M29: x | N29: x | O29: x | P29: x | Q29: cn | R29: x | S29: x | T29: x | U29: x | V29: x | X29: cn | Y29: x | Z29: x | AA29: x | AB29: x | AC29: x | AD29: x | AE29: cn | AF29: x | AG29: x | AH29: x | AI29: =COUNTIF(D29:AH29,"x") -> 26 | AJ29: =COUNTIF(D29:AH29,"cn") -> 4 | AK29: =COUNTIF(D29:AH29,"đ") -> 0 | AL29: =COUNTIF(D29:AH29,"đcn") -> 0 | AM29: =SUM(AI29:AL29) -> 30
A30: 20 | C30: =+'[5]TỔNG MỦ TẠP'!$B28 -> Phò Lấp | D30: x | E30: x | F30: x | G30: x | H30: x | I30: x | J30: cn | K30: x | L30: x | M30: x | N30: x | O30: x | P30: x | Q30: cn | R30: x | S30: x | T30: x | U30: x | W30: x | X30: cn | Y30: x | Z30: x | AA30: x | AB30: x | AC30: x | AD30: x | AE30: cn | AF30: x | AG30: x | AH30: x | AI30: =COUNTIF(D30:AH30,"x") -> 26 | AJ30: =COUNTIF(D30:AH30,"cn") -> 4 | AK30: =COUNTIF(D30:AH30,"đ") -> 0 | AL30: =COUNTIF(D30:AH30,"đcn") -> 0 | AM30: =SUM(AI30:AL30) -> 30
A31: 21 | C31: =+'[5]TỔNG MỦ TẠP'!$B29 -> Phò Nhạc | D31: x | E31: x | F31: x | G31: x | H31: x | I31: x | J31: cn | K31: x | L31: x | M31: x | N31: x | O31: x | P31: x | Q31: cn | R31: x | S31: x | T31: x | U31: x | V31: x | W31: x | X31: cn | Y31: x | Z31: x | AA31: x | AB31: x | AC31: x | AD31: x | AE31: cn | AF31: x | AG31: x | AH31: x | AI31: =COUNTIF(D31:AH31,"x") -> 27 | AJ31: =COUNTIF(D31:AH31,"cn") -> 4 | AK31: =COUNTIF(D31:AH31,"đ") -> 0 | AL31: =COUNTIF(D31:AH31,"đcn") -> 0 | AM31: =SUM(AI31:AL31) -> 31
A32: 22 | C32: =+'[5]TỔNG MỦ TẠP'!$B30 -> Nang Nọi | D32: x | E32: x | F32: x | G32: x | H32: x | I32: x | J32: cn | K32: x | L32: x | M32: x | O32: x | P32: x | Q32: cn | R32: x | S32: x | T32: x | U32: x | V32: x | W32: x | X32: cn | Z32: x | AA32: x | AB32: x | AC32: x | AD32: x | AE32: cn | AF32: x | AH32: x | AI32: =COUNTIF(D32:AH32,"x") -> 24 | AJ32: =COUNTIF(D32:AH32,"cn") -> 4 | AK32: =COUNTIF(D32:AH32,"đ") -> 0 | AL32: =COUNTIF(D32:AH32,"đcn") -> 0 | AM32: =SUM(AI32:AL32) -> 28
A33: 23 | C33: =+'[5]TỔNG MỦ TẠP'!$B31 -> Húc | D33: x | E33: x | F33: x | G33: x | H33: x | I33: x | J33: cn | K33: x | L33: x | M33: x | N33: x | O33: x | P33: x | Q33: cn | R33: x | S33: x | T33: x | U33: x | W33: x | X33: cn | Y33: x | Z33: x | AA33: x | AB33: x | AC33: x | AD33: x | AE33: cn | AF33: x | AG33: x | AH33: x | AI33: =COUNTIF(D33:AH33,"x") -> 26 | AJ33: =COUNTIF(D33:AH33,"cn") -> 4 | AK33: =COUNTIF(D33:AH33,"đ") -> 0 | AL33: =COUNTIF(D33:AH33,"đcn") -> 0 | AM33: =SUM(AI33:AL33) -> 30
A34: 24 | C34: =+'[5]TỔNG MỦ TẠP'!$B32 -> A Côm | D34: x | E34: x | F34: x | G34: x | H34: x | I34: x | J34: cn | K34: x | L34: x | M34: x | N34: x | O34: x | P34: x | Q34: cn | R34: x | S34: x | T34: x | U34: x | V34: x | W34: x | X34: cn | Y34: x | Z34: x | AA34: x | AB34: x | AC34: x | AD34: x | AE34: cn | AF34: x | AG34: x | AH34: x | AI34: =COUNTIF(D34:AH34,"x") -> 27 | AJ34: =COUNTIF(D34:AH34,"cn") -> 4 | AK34: =COUNTIF(D34:AH34,"đ") -> 0 | AL34: =COUNTIF(D34:AH34,"đcn") -> 0 | AM34: =SUM(AI34:AL34) -> 31
A35: 25 | C35: =+'[5]TỔNG MỦ TẠP'!$B33 -> Nang Phen | D35: x | E35: x | F35: x | G35: x | H35: x | I35: x | J35: cn | K35: x | L35: x | M35: x | N35: x | O35: x | P35: x | Q35: cn | R35: x | S35: x | T35: x | U35: x | V35: x | W35: x | X35: cn | Y35: x | Z35: x | AA35: x | AB35: x | AC35: x | AD35: x | AE35: cn | AF35: x | AG35: x | AH35: x | AI35: =COUNTIF(D35:AH35,"x") -> 27 | AJ35: =COUNTIF(D35:AH35,"cn") -> 4 | AK35: =COUNTIF(D35:AH35,"đ") -> 0 | AL35: =COUNTIF(D35:AH35,"đcn") -> 0 | AM35: =SUM(AI35:AL35) -> 31
A36: 26 | C36: =+'[5]TỔNG MỦ TẠP'!$B34 -> Thảo Đuôn | D36: x | E36: x | F36: x | G36: x | H36: x | I36: x | J36: cn | K36: x | L36: x | M36: x | N36: x | O36: x | P36: x | Q36: cn | R36: x | S36: x | T36: x | U36: x | V36: x | W36: x | X36: cn | Y36: x | Z36: x | AA36: x | AB36: x | AC36: x | AD36: x | AE36: cn | AF36: x | AG36: x | AH36: x | AI36: =COUNTIF(D36:AH36,"x") -> 27 | AJ36: =COUNTIF(D36:AH36,"cn") -> 4 | AK36: =COUNTIF(D36:AH36,"đ") -> 0 | AL36: =COUNTIF(D36:AH36,"đcn") -> 0 | AM36: =SUM(AI36:AL36) -> 31
A37: 27 | C37: =+'[5]TỔNG MỦ TẠP'!$B35 -> A Rơ | D37: x | E37: x | F37: x | G37: x | H37: x | I37: x | J37: cn | K37: x | L37: x | M37: x | N37: x | O37: x | P37: x | Q37: cn | R37: x | S37: x | T37: x | U37: x | V37: x | W37: x | X37: cn | Y37: x | Z37: x | AA37: x | AB37: x | AC37: x | AD37: x | AE37: cn | AF37: x | AG37: x | AH37: x | AI37: =COUNTIF(D37:AH37,"x") -> 27 | AJ37: =COUNTIF(D37:AH37,"cn") -> 4 | AK37: =COUNTIF(D37:AH37,"đ") -> 0 | AL37: =COUNTIF(D37:AH37,"đcn") -> 0 | AM37: =SUM(AI37:AL37) -> 31
A38: 28 | C38: =+'[5]TỔNG MỦ TẠP'!$B36 -> Thảo Xâm | D38: x | E38: x | F38: x | G38: x | H38: x | I38: x | J38: cn | K38: x | L38: x | M38: x | N38: x | O38: x | P38: x | Q38: cn | R38: x | S38: x | T38: x | U38: x | V38: x | W38: x | X38: cn | Y38: x | Z38: x | AA38: x | AB38: x | AC38: x | AD38: x | AE38: cn | AF38: x | AG38: x | AH38: x | AI38: =COUNTIF(D38:AH38,"x") -> 27 | AJ38: =COUNTIF(D38:AH38,"cn") -> 4 | AK38: =COUNTIF(D38:AH38,"đ") -> 0 | AL38: =COUNTIF(D38:AH38,"đcn") -> 0 | AM38: =SUM(AI38:AL38) -> 31
A39: 29 | C39: =+'[5]TỔNG MỦ TẠP'!$B37 -> Thảo Anh | D39: x | E39: x | F39: x | G39: x | H39: x | I39: x | J39: cn | K39: x | L39: x | M39: x | N39: x | O39: x | P39: x | Q39: cn | R39: x | S39: x | T39: x | U39: x | V39: x | W39: x | X39: cn | Y39: x | Z39: x | AA39: x | AB39: x | AC39: x | AD39: x | AE39: cn | AF39: x | AG39: x | AH39: x | AI39: =COUNTIF(D39:AH39,"x") -> 27 | AJ39: =COUNTIF(D39:AH39,"cn") -> 4 | AK39: =COUNTIF(D39:AH39,"đ") -> 0 | AL39: =COUNTIF(D39:AH39,"đcn") -> 0 | AM39: =SUM(AI39:AL39) -> 31
A40: 30 | C40: =+'[5]TỔNG MỦ TẠP'!$B38 -> Nang Banh | D40: x | E40: x | F40: x | G40: x | H40: x | I40: x | J40: cn | K40: x | L40: x | M40: x | N40: x | O40: x | P40: x | Q40: cn | R40: x | S40: x | T40: x | U40: x | V40: x | W40: x | X40: cn | Y40: x | Z40: x | AA40: x | AB40: x | AC40: x | AD40: x | AE40: cn | AF40: x | AG40: x | AH40: x | AI40: =COUNTIF(D40:AH40,"x") -> 27 | AJ40: =COUNTIF(D40:AH40,"cn") -> 4 | AK40: =COUNTIF(D40:AH40,"đ") -> 0 | AL40: =COUNTIF(D40:AH40,"đcn") -> 0 | AM40: =SUM(AI40:AL40) -> 31
A41: 31 | C41: =+'[5]TỔNG MỦ TẠP'!$B39 -> Thảo Boi | D41: x | E41: x | F41: x | G41: x | H41: x | I41: x | J41: cn | K41: x | L41: x | M41: x | N41: x | O41: x | P41: x | Q41: cn | R41: x | S41: x | T41: x | U41: x | V41: x | W41: x | X41: cn | Y41: x | Z41: x | AA41: x | AB41: x | AC41: x | AD41: x | AE41: cn | AF41: x | AG41: x | AH41: x | AI41: =COUNTIF(D41:AH41,"x") -> 27 | AJ41: =COUNTIF(D41:AH41,"cn") -> 4 | AK41: =COUNTIF(D41:AH41,"đ") -> 0 | AL41: =COUNTIF(D41:AH41,"đcn") -> 0 | AM41: =SUM(AI41:AL41) -> 31
...

Sheet Biểu 2 TH MỦ TẠP
A1: CỘNG HÒA DÂN CHỦ NHÂN DÂN LÀO
A2: Hòa bình - Độc lập - Dân chủ - Thống nhất - Thịnh vượng
A3: ----oOo----
A4: CÔNG TY TNHH MTV QUASA-GERUCO LÀO
A5: ĐỘI SẢN XUẤT SỐ 6
A7: BẢNG THEO DÕI SẢN LƯỢNG MỦ TẠP THÁNG 12 NĂM 2025
AI8: Biểu 2
A9: Stt | C9: Họ và tên | D9: Ngày công | AI9: Tổng mủ tạp T12 | AJ9: DRC bình quân | AK9: Mủ tạp quy khô T12 | AL9: Tổng mủ tạp T12 | AM9: DRC bình quân T8 | AN9: Mủ quy khô truy lĩnh T12 | AO9: Tổng mủ quy khô trả lương | AP9: Xếp hạng kỹ thuật | AQ9: Ký tên CN
D10: 1 | E10: 2 | F10: 3 | G10: 4 | H10: 5 | I10: 6 | J10: 7 | K10: 8 | L10: 9 | M10: 10 | N10: 11 | O10: 12 | P10: 13 | Q10: 14 | R10: 15 | S10: 16 | T10: 17 | U10: 18 | V10: 19 | W10: 20 | X10: 21 | Y10: 22 | Z10: 23 | AA10: 24 | AB10: 25 | AC10: 26 | AD10: 27 | AE10: 28 | AF10: 29 | AG10: 30 | AH10: 31
A11: 1 | C11: =+'Biểu 1 TH CÔNG'!C11 -> Phò Thưng | D11: 71 | E11: 30 | F11: 46 | G11: 149 | H11: 53 | I11: 47 | J11: 77 | K11: 120 | L11: 80 | M11: 80 | N11: 82 | O11: 149 | P11: 114 | Q11: 64 | R11: 64 | S11: 140 | T11: 91 | U11: 56 | V11: 68 | W11: 138 | X11: 74 | Y11: 48 | Z11: 57 | AA11: 113 | AB11: 74 | AC11: 53 | AD11: 59 | AE11: 111 | AF11: 80 | AG11: 84 | AH11: 80 | AI11: =SUM(D11:AH11) -> 2552 | AJ11: =$AU$11 -> 40.312391 | AK11: =+AI11*$AU$11/100 -> 1028.7722 | AL11: =+AI11 -> 2552 | AM11: =$AV$11 -> 3.9348778 | AN11: =+AL11*$AV$11/100 -> 100.41808 | AO11: =+AK11+AN11 -> 1129.1903 | AP11: A | AT11: DRC | AU11: 40.312391 | AV11: =+AV13/AV12*100 -> 3.9348778
A12: 2 | C12: =+'Biểu 1 TH CÔNG'!C12 -> A Nhợp | D12: 105 | E12: 80 | F12: 70 | G12: 105 | H12: 100 | I12: 80 | J12: 90 | K12: 118 | L12: 90 | M12: 100 | N12: 80 | O12: 118 | P12: 100 | Q12: 88 | R12: 66 | S12: 112 | T12: 80 | U12: 90 | V12: 90 | W12: 112 | X12: 70 | Y12: 70 | Z12: 0 | AA12: 110 | AB12: 70 | AC12: 80 | AD12: 70 | AE12: 100 | AF12: 100 | AG12: 100 | AH12: 90 | AI12: =SUM(D12:AH12) -> 2734 | AJ12: =$AU$11 -> 40.312391 | AK12: =+AI12*$AU$11/100 -> 1102.1408 | AL12: =+AI12 -> 2734 | AM12: =$AV$11 -> 3.9348778 | AN12: =+AL12*$AV$11/100 -> 107.57956 | AO12: =+AK12+AN12 -> 1209.7203 | AP12: C | AT12: MỦ TẠP | AU12: =+AI88 -> 198539 | AV12: =+AL88 -> 198539
A13: 3 | C13: =+'Biểu 1 TH CÔNG'!C13 -> Van | D13: 163 | E13: 0 | F13: 52 | G13: 0 | H13: 0 | I13: 96 | J13: 80 | K13: 132 | L13: 200 | M13: 62 | N13: 0 | O13: 126 | P13: 96 | Q13: 55 | R13: 94 | S13: 89 | T13: 0 | U13: 50 | V13: 73 | W13: 0 | X13: 200 | Y13: 125 | Z13: 0 | AA13: 0 | AB13: 123 | AC13: 86 | AD13: 108 | AE13: 173 | AF13: 145 | AG13: 68 | AH13: 97 | AI13: =SUM(D13:AH13) -> 2493 | AJ13: =$AU$11 -> 40.312391 | AK13: =+AI13*$AU$11/100 -> 1004.9879 | AL13: =+AI13 -> 2493 | AM13: =$AV$11 -> 3.9348778 | AN13: =+AL13*$AV$11/100 -> 98.096503 | AO13: =+AK13+AN13 -> 1103.0844 | AP13: B | AT13: QUY KHÔ | AU13: 80035.817 | AV13: 7812.267
A14: 4 | C14: =+'Biểu 1 TH CÔNG'!C14 -> Thảo Khọt | D14: 111 | E14: 77 | F14: 111 | G14: 189 | H14: 120 | I14: 74 | J14: 107 | K14: 83 | L14: 113 | M14: 100 | N14: 100 | O14: 107 | P14: 111 | Q14: 85 | R14: 90 | S14: 97 | T14: 145 | U14: 85 | V14: 112 | W14: 80 | X14: 110 | Y14: 73 | Z14: 100 | AA14: 127 | AB14: 110 | AC14: 67 | AD14: 78 | AE14: 78 | AF14: 141 | AG14: 83 | AH14: 110 | AI14: =SUM(D14:AH14) -> 3174 | AJ14: =$AU$11 -> 40.312391 | AK14: =+AI14*$AU$11/100 -> 1279.5153 | AL14: =+AI14 -> 3174 | AM14: =$AV$11 -> 3.9348778 | AN14: =+AL14*$AV$11/100 -> 124.89302 | AO14: =+AK14+AN14 -> 1404.4083 | AP14: A
A15: 5 | C15: =+'Biểu 1 TH CÔNG'!C15 -> A Cơ | D15: 59 | E15: 47 | F15: 56 | G15: 87 | H15: 67 | I15: 49 | J15: 63 | K15: 101 | L15: 71 | M15: 77 | N15: 67 | O15: 104 | P15: 97 | Q15: 79 | R15: 79 | S15: 98 | T15: 86 | U15: 70 | V15: 79 | W15: 101 | X15: 79 | Y15: 72 | Z15: 61 | AA15: 95 | AB15: 76 | AC15: 75 | AD15: 73 | AE15: 97 | AF15: 81 | AG15: 92 | AH15: 79 | AI15: =SUM(D15:AH15) -> 2417 | AJ15: =$AU$11 -> 40.312391 | AK15: =+AI15*$AU$11/100 -> 974.35048 | AL15: =+AI15 -> 2417 | AM15: =$AV$11 -> 3.9348778 | AN15: =+AL15*$AV$11/100 -> 95.105996 | AO15: =+AK15+AN15 -> 1069.4565 | AP15: B
A16: 6 | C16: =+'Biểu 1 TH CÔNG'!C16 -> Phơ | D16: 58 | E16: 78 | F16: 68 | G16: 134 | H16: 53 | I16: 76 | J16: 88 | K16: 100 | L16: 73 | M16: 72 | N16: 60 | O16: 100 | P16: 85 | Q16: 65 | R16: 74 | S16: 103 | T16: 64 | U16: 80 | V16: 95 | W16: 0 | X16: 60 | Y16: 0 | Z16: 0 | AA16: 160 | AB16: 59 | AC16: 65 | AD16: 85 | AE16: 98 | AF16: 0 | AG16: 77 | AH16: 71 | AI16: =SUM(D16:AH16) -> 2201 | AJ16: =$AU$11 -> 40.312391 | AK16: =+AI16*$AU$11/100 -> 887.27572 | AL16: =+AI16 -> 2201 | AM16: =$AV$11 -> 3.9348778 | AN16: =+AL16*$AV$11/100 -> 86.60666 | AO16: =+AK16+AN16 -> 973.88238 | AP16: A
A17: 7 | C17: =+'Biểu 1 TH CÔNG'!C17 -> A phơ | D17: 97 | E17: 80 | F17: 70 | G17: 105 | H17: 100 | I17: 80 | J17: 90 | K17: 119 | L17: 90 | M17: 100 | N17: 80 | O17: 118 | P17: 100 | Q17: 88 | R17: 66 | S17: 112 | T17: 80 | U17: 90 | V17: 90 | W17: 112 | X17: 70 | Y17: 70 | Z17: 0 | AA17: 110 | AB17: 70 | AC17: 80 | AD17: 70 | AE17: 100 | AF17: 100 | AG17: 100 | AH17: 90 | AI17: =SUM(D17:AH17) -> 2727 | AJ17: =$AU$11 -> 40.312391 | AK17: =+AI17*$AU$11/100 -> 1099.3189 | AL17: =+AI17 -> 2727 | AM17: =$AV$11 -> 3.9348778 | AN17: =+AL17*$AV$11/100 -> 107.30412 | AO17: =+AK17+AN17 -> 1206.623 | AP17: B
A18: 8 | C18: =+'Biểu 1 TH CÔNG'!C18 -> Nang Đăm | D18: 0 | E18: 28 | F18: 56 | G18: 0 | H18: 110 | I18: 64 | J18: 85 | K18: 114 | L18: 52 | M18: 65 | N18: 58 | O18: 64 | P18: 65 | Q18: 51 | R18: 72 | S18: 0 | T18: 61 | U18: 57 | V18: 76 | W18: 96 | X18: 61 | Y18: 45 | Z18: 63 | AA18: 52 | AB18: 53 | AC18: 37 | AD18: 80 | AE18: 47 | AF18: 59 | AG18: 61 | AH18: 92 | AI18: =SUM(D18:AH18) -> 1824 | AJ18: =$AU$11 -> 40.312391 | AK18: =+AI18*$AU$11/100 -> 735.298 | AL18: =+AI18 -> 1824 | AM18: =$AV$11 -> 3.9348778 | AN18: =+AL18*$AV$11/100 -> 71.772171 | AO18: =+AK18+AN18 -> 807.07017 | AP18: B
A19: 9 | C19: =+'Biểu 1 TH CÔNG'!C19 -> Nang Sun | D19: 55 | E19: 0 | F19: 0 | G19: 80 | H19: 50 | I19: 69 | J19: 100 | K19: 161 | L19: 50 | M19: 66 | N19: 64 | O19: 108 | P19: 81 | Q19: 0 | R19: 76 | S19: 98 | T19: 57 | U19: 100 | V19: 100 | W19: 100 | X19: 62 | Y19: 66 | Z19: 89 | AA19: 85 | AB19: 57 | AC19: 53 | AD19: 82 | AE19: 100 | AF19: 90 | AG19: 50 | AH19: 168 | AI19: =SUM(D19:AH19) -> 2317 | AJ19: =$AU$11 -> 40.312391 | AK19: =+AI19*$AU$11/100 -> 934.03809 | AL19: =+AI19 -> 2317 | AM19: =$AV$11 -> 3.9348778 | AN19: =+AL19*$AV$11/100 -> 91.171118 | AO19: =+AK19+AN19 -> 1025.2092 | AP19: A
A20: 10 | C20: =+'Biểu 1 TH CÔNG'!C20 -> A Nghen | D20: 0 | E20: 0 | F20: 69 | G20: 0 | H20: 64 | I20: 96 | J20: 69 | K20: 112 | L20: 78 | M20: 73 | N20: 85 | O20: 83 | P20: 102 | Q20: 60 | R20: 82 | S20: 0 | T20: 80 | U20: 69 | V20: 0 | W20: 133 | X20: 77 | Y20: 0 | Z20: 0 | AA20: 76 | AB20: 74 | AC20: 0 | AD20: 133 | AE20: 72 | AF20: 74 | AG20: 116 | AH20: 67 | AI20: =SUM(D20:AH20) -> 1944 | AJ20: =$AU$11 -> 40.312391 | AK20: =+AI20*$AU$11/100 -> 783.67287 | AL20: =+AI20 -> 1944 | AM20: =$AV$11 -> 3.9348778 | AN20: =+AL20*$AV$11/100 -> 76.494024 | AO20: =+AK20+AN20 -> 860.1669 | AP20: A
A21: 11 | C21: =+'Biểu 1 TH CÔNG'!C21 -> Nguyễn Thị Thanh Trà | D21: 100 | E21: 0 | F21: 126 | G21: 100 | H21: 70 | I21: 120 | J21: 100 | K21: 135 | L21: 85 | M21: 100 | N21: 100 | O21: 120 | P21: 90 | Q21: 60 | R21: 100 | S21: 120 | T21: 80 | U21: 90 | V21: 110 | W21: 130 | X21: 100 | Y21: 80 | Z21: 120 | AA21: 118 | AB21: 85 | AC21: 75 | AD21: 95 | AE21: 110 | AF21: 115 | AG21: 95 | AH21: 110 | AI21: =SUM(D21:AH21) -> 3039 | AJ21: =$AU$11 -> 40.312391 | AK21: =+AI21*$AU$11/100 -> 1225.0935 | AL21: =+AI21 -> 3039 | AM21: =$AV$11 -> 3.9348778 | AN21: =+AL21*$AV$11/100 -> 119.58094 | AO21: =+AK21+AN21 -> 1344.6745 | AP21: A
A22: 12 | C22: =+'Biểu 1 TH CÔNG'!C22 -> Phò Thít | D22: 73 | E22: 93 | F22: 73 | G22: 106 | H22: 58 | I22: 81 | J22: 54 | K22: 96 | L22: 53 | M22: 85 | N22: 58 | O22: 127 | P22: 60 | Q22: 110 | R22: 82 | S22: 110 | T22: 78 | U22: 97 | V22: 83 | W22: 118 | X22: 71 | Y22: 70 | Z22: 77 | AA22: 116 | AB22: 57 | AC22: 79 | AD22: 53 | AE22: 132 | AF22: 87 | AG22: 90 | AH22: 84 | AI22: =SUM(D22:AH22) -> 2611 | AJ22: =$AU$11 -> 40.312391 | AK22: =+AI22*$AU$11/100 -> 1052.5565 | AL22: =+AI22 -> 2611 | AM22: =$AV$11 -> 3.9348778 | AN22: =+AL22*$AV$11/100 -> 102.73966 | AO22: =+AK22+AN22 -> 1155.2962 | AP22: A
A23: 13 | C23: =+'Biểu 1 TH CÔNG'!C23 -> A Bợp | D23: 126 | E23: 63 | F23: 138 | G23: 104 | H23: 48 | I23: 86 | J23: 130 | K23: 99 | L23: 86 | M23: 100 | N23: 130 | O23: 137 | P23: 115 | Q23: 89 | R23: 123 | S23: 101 | T23: 95 | U23: 90 | V23: 88 | W23: 118 | X23: 83 | Y23: 70 | Z23: 145 | AA23: 112 | AB23: 98 | AC23: 78 | AD23: 112 | AE23: 107 | AF23: 145 | AG23: 78 | AH23: 159 | AI23: =SUM(D23:AH23) -> 3253 | AJ23: =$AU$11 -> 40.312391 | AK23: =+AI23*$AU$11/100 -> 1311.3621 | AL23: =+AI23 -> 3253 | AM23: =$AV$11 -> 3.9348778 | AN23: =+AL23*$AV$11/100 -> 128.00157 | AO23: =+AK23+AN23 -> 1439.3636 | AP23: B
A24: 14 | C24: =+'Biểu 1 TH CÔNG'!C24 -> A Khai | D24: 95 | E24: 73 | F24: 58 | G24: 95 | H24: 65 | I24: 64 | J24: 68 | K24: 119 | L24: 70 | M24: 70 | N24: 61 | O24: 118 | P24: 51 | Q24: 87 | R24: 67 | S24: 100 | T24: 54 | U24: 50 | V24: 51 | W24: 0 | X24: 66 | Y24: 60 | Z24: 0 | AA24: 89 | AB24: 68 | AC24: 45 | AD24: 58 | AE24: 78 | AF24: 73 | AG24: 66 | AH24: 70 | AI24: =SUM(D24:AH24) -> 2089 | AJ24: =$AU$11 -> 40.312391 | AK24: =+AI24*$AU$11/100 -> 842.12584 | AL24: =+AI24 -> 2089 | AM24: =$AV$11 -> 3.9348778 | AN24: =+AL24*$AV$11/100 -> 82.199597 | AO24: =+AK24+AN24 -> 924.32543 | AP24: A
A25: 15 | C25: =+'Biểu 1 TH CÔNG'!C25 -> Võ Thị Nguyên | D25: 100 | E25: 0 | F25: 125 | G25: 100 | H25: 70 | I25: 120 | J25: 100 | K25: 135 | L25: 85 | M25: 100 | N25: 100 | O25: 120 | P25: 90 | Q25: 60 | R25: 100 | S25: 120 | T25: 80 | U25: 90 | V25: 110 | W25: 130 | X25: 100 | Y25: 80 | Z25: 120 | AA25: 118 | AB25: 86 | AC25: 75 | AD25: 95 | AE25: 110 | AF25: 115 | AG25: 95 | AH25: 110 | AI25: =SUM(D25:AH25) -> 3039 | AJ25: =$AU$11 -> 40.312391 | AK25: =+AI25*$AU$11/100 -> 1225.0935 | AL25: =+AI25 -> 3039 | AM25: =$AV$11 -> 3.9348778 | AN25: =+AL25*$AV$11/100 -> 119.58094 | AO25: =+AK25+AN25 -> 1344.6745 | AP25: A
... A44: 34 | C44: =+'Biểu 1 TH CÔNG'!C44 -> Thảo Xen | D44: 90 | E44: 88 | F44: 0 | G44: 90 | H44: 72 | I44: 45 | J44: 60 | K44: 80 | L44: 65 | M44: 72 | N44: 0 | O44: 85 | P44: 71 | Q44: 57 | R44: 53 | S44: 86 | T44: 60 | U44: 50 | V44: 78 | W44: 103 | X44: 85 | Y44: 55 | Z44: 63 | AA44: 94 | AB44: 0 | AC44: 41 | AD44: 0 | AE44: 101 | AF44: 122 | AG44: 54 | AH44: 82 | AI44: =SUM(D44:AH44) -> 2002 | AJ44: =$AU$11 -> 40.312391 | AK44: =+AI44*$AU$11/100 -> 807.05406 | AL44: =+AI44 -> 2002 | AM44: =$AV$11 -> 3.9348778 | AN44: =+AL44*$AV$11/100 -> 78.776253 | AO44: =+AK44+AN44 -> 885.83031 | AP44: A
A45: 35 | B45: 1 | C45: =+'Biểu 1 TH CÔNG'!C46 -> Nàng Pong | D45: 72 | E45: 76 | F45: 77 | G45: 74 | H45: 92 | I45: 78 | J45: 130 | K45: 81 | L45: 84 | M45: 77 | N45: 92 | O45: 103 | P45: 172 | Q45: 87 | R45: 108 | S45: 63 | T45: 64 | U45: 86 | V45: 88 | W45: 86 | X45: 0 | Y45: 177 | Z45: 64 | AA45: 68 | AB45: 79 | AC45: 84 | AD45: 89 | AE45: 43 | AF45: 110 | AG45: 83 | AH45: 93 | AI45: =SUM(D45:AH45) -> 2680 | AJ45: =$AU$11 -> 40.312391 | AK45: =+AI45*$AU$11/100 -> 1080.3721 | AL45: =+AI45 -> 2680 | AM45: =$AV$11 -> 3.9348778 | AN45: =+AL45*$AV$11/100 -> 105.45472 | AO45: =+AK45+AN45 -> 1185.8268 | AP45: B
A46: 36 | B46: 2 | C46: =+'Biểu 1 TH CÔNG'!C47 -> Thảo Ơ | D46: 73 | E46: 81 | F46: 104 | G46: 142 | H46: 66 | I46: 78 | J46: 66 | K46: 0 | L46: 130 | M46: 77 | N46: 0 | O46: 144 | P46: 170 | Q46: 98 | R46: 130 | S46: 63 | T46: 52 | U46: 88 | V46: 151 | W46: 47 | X46: 71 | Y46: 121 | Z46: 75 | AA46: 46 | AB46: 60 | AC46: 132 | AD46: 77 | AE46: 71 | AF46: 75 | AG46: 73 | AH46: 65 | AI46: =SUM(D46:AH46) -> 2626 | AJ46: =$AU$11 -> 40.312391 | AK46: =+AI46*$AU$11/100 -> 1058.6034 | AL46: =+AI46 -> 2626 | AM46: =$AV$11 -> 3.9348778 | AN46: =+AL46*$AV$11/100 -> 103.32989 | AO46: =+AK46+AN46 -> 1161.9333 | AP46: B
A47: 37 | B47: 3 | C47: =+'Biểu 1 TH CÔNG'!C48 -> Thảo Ui | D47: 72 | E47: 76 | F47: 77 | G47: 74 | H47: 92 | I47: 78 | J47: 130 | K47: 81 | L47: 84 | M47: 77 | N47: 92 | O47: 103 | P47: 172 | Q47: 87 | R47: 108 | S47: 63 | T47: 64 | U47: 86 | V47: 88 | W47: 86 | X47: 46 | Y47: 178 | Z47: 64 | AA47: 68 | AB47: 78 | AC47: 84 | AD47: 89 | AE47: 43 | AF47: 110 | AG47: 84 | AH47: 92 | AI47: =SUM(D47:AH47) -> 2726 | AJ47: =$AU$11 -> 40.312391 | AK47: =+AI47*$AU$11/100 -> 1098.9158 | AL47: =+AI47 -> 2726 | AM47: =$AV$11 -> 3.9348778 | AN47: =+AL47*$AV$11/100 -> 107.26477 | AO47: =+AK47+AN47 -> 1206.1805 | AP47: A
A48: 38 | B48: 4 | C48: =+'Biểu 1 TH CÔNG'!C49 -> Thảo Xoan Chay | D48: 0 | E48: 50 | F48: 63 | G48: 62 | H48: 56 | I48: 58 | J48: 117 | K48: 69 | L48: 100 | M48: 85 | N48: 82 | O48: 197 | P48: 182 | Q48: 62 | R48: 153 | S48: 0 | T48: 85 | U48: 71 | V48: 111 | W48: 135 | X48: 52 | Y48: 190 | Z48: 58 | AA48: 66 | AB48: 89 | AC48: 52 | AD48: 46 | AE48: 90 | AF48: 107 | AG48: 130 | AH48: 78 | AI48: =SUM(D48:AH48) -> 2696 | AJ48: =$AU$11 -> 40.312391 | AK48: =+AI48*$AU$11/100 -> 1086.822 | AL48: =+AI48 -> 2696 | AM48: =$AV$11 -> 3.9348778 | AN48: =+AL48*$AV$11/100 -> 106.08431 | AO48: =+AK48+AN48 -> 1192.9064 | AP48: B
A49: 39 | B49: 5 | C49: =+'Biểu 1 TH CÔNG'!C50 -> Nàng Út | D49: 56 | E49: 77 | F49: 78 | G49: 76 | H49: 110 | I49: 70 | J49: 113 | K49: 93 | L49: 84 | M49: 75 | N49: 88 | O49: 127 | P49: 142 | Q49: 109 | R49: 57 | S49: 0 | T49: 77 | U49: 148 | V49: 116 | W49: 116 | X49: 43 | Y49: 88 | Z49: 0 | AA49: 118 | AB49: 87 | AC49: 57 | AD49: 113 | AE49: 57 | AF49: 147 | AG49: 129 | AH49: 85 | AI49: =SUM(D49:AH49) -> 2736 | AJ49: =$AU$11 -> 40.312391 | AK49: =+AI49*$AU$11/100 -> 1102.947 | AL49: =+AI49 -> 2736 | AM49: =$AV$11 -> 3.9348778 | AN49: =+AL49*$AV$11/100 -> 107.65826 | AO49: =+AK49+AN49 -> 1210.6053 | AP49: B
A50: 40 | B50: 6 | C50: =+'Biểu 1 TH CÔNG'!C51 -> Thảo Phôn Xay | D50: 64 | E50: 53 | F50: 110 | G50: 89 | H50: 129 | I50: 64 | J50: 79 | K50: 137 | L50: 102 | M50: 78 | N50: 83 | O50: 172 | P50: 150 | Q50: 79 | R50: 51 | S50: 0 | T50: 84 | U50: 78 | V50: 169 | W50: 155 | X50: 50 | Y50: 152 | Z50: 0 | AA50: 75 | AB50: 86 | AC50: 96 | AD50: 77 | AE50: 71 | AF50: 74 | AG50: 131 | AH50: 90 | AI50: =SUM(D50:AH50) -> 2828 | AJ50: =$AU$11 -> 40.312391 | AK50: =+AI50*$AU$11/100 -> 1140.0344 | AL50: =+AI50 -> 2828 | AM50: =$AV$11 -> 3.9348778 | AN50: =+AL50*$AV$11/100 -> 111.27834 | AO50: =+AK50+AN50 -> 1251.3127 | AP50: B
A51: 41 | B51: 7 | C51: =+'Biểu 1 TH CÔNG'!C52 -> Nàng Phêng | D51: 72 | E51: 50 | F51: 64 | G51: 111 | H51: 74 | I51: 70 | J51: 81 | K51: 119 | L51: 79 | M51: 59 | N51: 87 | O51: 153 | P51: 152 | Q51: 69 | R51: 128 | S51: 63 | T51: 77 | U51: 87 | V51: 120 | W51: 80 | X51: 51 | Y51: 76 | Z51: 130 | AA51: 51 | AB51: 75 | AC51: 99 | AD51: 83 | AE51: 43 | AF51: 70 | AG51: 114 | AH51: 65 | AI51: =SUM(D51:AH51) -> 2652 | AJ51: =$AU$11 -> 40.312391 | AK51: =+AI51*$AU$11/100 -> 1069.0846 | AL51: =+AI51 -> 2652 | AM51: =$AV$11 -> 3.9348778 | AN51: =+AL51*$AV$11/100 -> 104.35296 | AO51: =+AK51+AN51 -> 1173.4376 | AP51: A
A52: 42 | B52: 8 | C52: =+'Biểu 1 TH CÔNG'!C53 -> Thảo Phíc | D52: 0 | E52: 0 | F52: 0 | G52: 68 | H52: 32 | I52: 84 | J52: 64 | K52: 103 | L52: 92 | M52: 106 | N52: 56 | O52: 143 | P52: 60 | Q52: 0 | R52: 156 | S52: 70 | T52: 116 | U52: 53 | V52: 75 | W52: 112 | X52: 123 | Y52: 130 | Z52: 0 | AA52: 102 | AB52: 48 | AC52: 87 | AD52: 101 | AE52: 0 | AF52: 104 | AG52: 66 | AH52: 171 | AI52: =SUM(D52:AH52) -> 2322 | AJ52: =$AU$11 -> 40.312391 | AK52: =+AI52*$AU$11/100 -> 936.05371 | AL52: =+AI52 -> 2322 | AM52: =$AV$11 -> 3.9348778 | AN52: =+AL52*$AV$11/100 -> 91.367862 | AO52: =+AK52+AN52 -> 1027.4216 | AP52: B
A53: 43 | B53: 9 | C53: =+'Biểu 1 TH CÔNG'!C54 -> Nàng Chai | D53: 0 | E53: 0 | F53: 0 | G53: 142 | H53: 66 | I53: 79 | J53: 66 | K53: 0 | L53: 130 | M53: 77 | N53: 0 | O53: 141 | P53: 170 | Q53: 101 | R53: 130 | S53: 63 | T53: 53 | U53: 88 | V53: 152 | W53: 0 | X53: 71 | Y53: 61 | Z53: 75 | AA53: 0 | AB53: 61 | AC53: 133 | AD53: 77 | AE53: 71 | AF53: 76 | AG53: 74 | AH53: 65 | AI53: =SUM(D53:AH53) -> 2222 | AJ53: =$AU$11 -> 40.312391 | AK53: =+AI53*$AU$11/100 -> 895.74132 | AL53: =+AI53 -> 2222 | AM53: =$AV$11 -> 3.9348778 | AN53: =+AL53*$AV$11/100 -> 87.432984 | AO53: =+AK53+AN53 -> 983.1743 | AP53: A
A54: 44 | B54: 10 | C54: =+'Biểu 1 TH CÔNG'!C55 -> Thảo Viêng | D54: 72 | E54: 77 | F54: 77 | G54: 74 | H54: 92 | I54: 78 | J54: 129 | K54: 82 | L54: 84 | M54: 76 | N54: 92 | O54: 91 | P54: 172 | Q54: 87 | R54: 108 | S54: 63 | T54: 64 | U54: 86 | V54: 88 | W54: 86 | X54: 45 | Y54: 178 | Z54: 64 | AA54: 67 | AB54: 79 | AC54: 84 | AD54: 88 | AE54: 40 | AF54: 109 | AG54: 83 | AH54: 92 | AI54: =SUM(D54:AH54) -> 2707 | AJ54: =$AU$11 -> 40.312391 | AK54: =+AI54*$AU$11/100 -> 1091.2564 | AL54: =+AI54 -> 2707 | AM54: =$AV$11 -> 3.9348778 | AN54: =+AL54*$AV$11/100 -> 106.51714 | AO54: =+AK54+AN54 -> 1197.7736 | AP54: A
A55: 45 | B55: 11 | C55: =+'Biểu 1 TH CÔNG'!C56 -> Thảo Xượm | D55: 0 | E55: 0 | F55: 0 | G55: 112 | H55: 74 | I55: 70 | J55: 81 | K55: 119 | L55: 80 | M55: 59 | N55: 87 | O55: 153 | P55: 152 | Q55: 69 | R55: 128 | S55: 63 | T55: 77 | U55: 87 | V55: 120 | W55: 80 | X55: 51 | Y55: 152 | Z55: 131 | AA55: 51 | AB55: 76 | AC55: 99 | AD55: 83 | AE55: 39 | AF55: 71 | AG55: 114 | AH55: 65 | AI55: =SUM(D55:AH55) -> 2543 | AJ55: =$AU$11 -> 40.312391 | AK55: =+AI55*$AU$11/100 -> 1025.1441 | AL55: =+AI55 -> 2543 | AM55: =$AV$11 -> 3.9348778 | AN55: =+AL55*$AV$11/100 -> 100.06394 | AO55: =+AK55+AN55 -> 1125.208 | AP55: B
A56: 46 | B56: 12 | C56: =+'Biểu 1 TH CÔNG'!C57 -> Thảo Tích | D56: 0 | E56: 51 | F56: 63 | G56: 61 | H56: 57 | I56: 59 | J56: 58 | K56: 82 | L56: 85 | M56: 76 | N56: 93 | O56: 103 | P56: 176 | Q56: 87 | R56: 108 | S56: 62 | T56: 64 | U56: 86 | V56: 89 | W56: 85 | X56: 45 | Y56: 178 | Z56: 63 | AA56: 67 | AB56: 78 | AC56: 83 | AD56: 88 | AE56: 42 | AF56: 109 | AG56: 83 | AH56: 92 | AI56: =SUM(D56:AH56) -> 2473 | AJ56: =$AU$11 -> 40.312391 | AK56: =+AI56*$AU$11/100 -> 996.92542 | AL56: =+AI56 -> 2473 | AM56: =$AV$11 -> 3.9348778 | AN56: =+AL56*$AV$11/100 -> 97.309528 | AO56: =+AK56+AN56 -> 1094.2349 | AP56: B
... A84: 74 | B84: 40 | C84: =+'Biểu 1 TH CÔNG'!C85 -> Thảo Đuông Chăn | D84: 0 | E84: 66 | F84: 49 | G84: 37 | H84: 71 | I84: 79 | J84: 0 | K84: 0 | L84: 0 | M84: 47 | N84: 0 | O84: 0 | P84: 154 | Q84: 0 | R84: 0 | S84: 0 | T84: 0 | U84: 0 | V84: 0 | W84: 0 | X84: 0 | Y84: 115 | Z84: 200 | AA84: 0 | AB84: 0 | AC84: 0 | AD84: 0 | AE84: 0 | AF84: 0 | AG84: 0 | AH84: 0 | AI84: =SUM(D84:AH84) -> 818 | AJ84: =$AU$11 -> 40.312391 | AK84: =+AI84*$AU$11/100 -> 329.75535 | AL84: =+AI84 -> 818 | AM84: =$AV$11 -> 3.9348778 | AN84: =+AL84*$AV$11/100 -> 32.1873 | AO84: =+AK84+AN84 -> 361.94265 | AP84: B
A85: 75 | B85: 41 | C85: =+'Biểu 1 TH CÔNG'!C86 -> Nàng Peng | D85: 0 | E85: 0 | F85: 49 | G85: 37 | H85: 72 | I85: 78 | J85: 0 | K85: 0 | L85: 41 | M85: 0 | N85: 47 | O85: 0 | P85: 154 | Q85: 0 | R85: 0 | S85: 0 | T85: 0 | U85: 0 | V85: 0 | W85: 0 | X85: 0 | Y85: 115 | Z85: 201 | AA85: 0 | AB85: 0 | AC85: 0 | AD85: 0 | AE85: 0 | AF85: 0 | AG85: 0 | AH85: 0 | AI85: =SUM(D85:AH85) -> 794 | AJ85: =$AU$11 -> 40.312391 | AK85: =+AI85*$AU$11/100 -> 320.08038 | AL85: =+AI85 -> 794 | AM85: =$AV$11 -> 3.9348778 | AN85: =+AL85*$AV$11/100 -> 31.24293 | AO85: =+AK85+AN85 -> 351.32331 | AP85: C | AS85: sản lượng mủ | AU85: A | AV85: B | AW85: C | AX85: tổng
