Workbook
Name So_XN: [1]PHATSINH!$B$6:$B$2093

Sheet BẢNG PHÂN TOÁN
A1: CỘNG HÒA DÂN CHỦ NHÂN DÂN LÀO
A2: Hòa bình - Độc lập - Dân chủ - Thống nhất - Thịnh vượng
A3: -----oOo-----
A4: CÔNG TY TNHH CỔ PHẦN QUASA - GERUCO LÀO
A5: ĐỘI SẢN XUẤT SEPON
A8: BẢNG PHÂN TOÁN TIỀN LƯƠNG THÁNG 04 NĂM 2025
A9: Từ ngày 01/04/2025 đến ngày 30/04/2025
I10: Đvt: Kip
A11: STT | B11: Danh mục | C11: Đvt | D11: Số lượng | E11: Sản lượng thực hiện quy khô | F11: Đơn giá | G11: Tổng tiền lương | H11: Tổng tiền thực nhận | I11: Ghi chú
A12: I | B12: Tiền lương kinh doanh | G12: =G13+G32 -> 165503662 | K12: Tỷ giá: USD qua Kíp: | L12: 21754
A13: 1 | B13: Tiền lương công nhân trực tiếp | G13: =G14+G23+G31 -> 129103662
A14: 1.1 | B14: Sản lượng | E14: =+SUM(E15:E22) -> 5465.565 | G14: =SUM(G15:G20) -> 21440661 | K14: Tỷ giá Bath qua Kíp | L14: 646.2
B15: Xếp loại kỹ thuật A (đơn giá chuẩn) | C15: Kg | E15: =+SUMIF('BẢNG LƯƠNG KT'!$K$17:$K$74,"A",'BẢNG LƯƠNG KT'!$J$17:$J$74) -> 2944.8809 | F15: =6.1*$L$14 -> 3941.82 | G15: =ROUND((E15*F15),0) -> 11608190 | L15: 655.8
B16: Xếp loại kỹ thuật B (đơn giá chuẩn) | C16: Kg | E16: =+SUMIF('BẢNG LƯƠNG KT'!$K$17:$K$74,"B",'BẢNG LƯƠNG KT'!$J$17:$J$74) -> 1455.0998 | F16: =5.8*$L$14 -> 3747.96 | G16: =ROUND((E16*F16),0)-1 -> 5453655
B17: Xếp loại kỹ thuật C (đơn giá chuẩn) | C17: Kg | E17: =+SUMIF('BẢNG LƯƠNG KT'!$K$17:$K$74,"C",'BẢNG LƯƠNG KT'!$J$17:$J$74) -> 222.89625 | F17: =5.5*$L$14 -> 3554.1 | G17: =ROUND((E17*F17),0)-1 -> 792195
B18: Xếp loại kỹ thuật D (đơn giá chuẩn) | C18: Kg | E18: =+SUMIF('BẢNG LƯƠNG KT'!$K$17:$K$52,"D",'BẢNG LƯƠNG KT'!$J$17:$J$52) -> 0 | F18: =5.2*$L$14 -> 3360.24 | G18: =ROUND((E18*F18),0) -> 0
B19: Xếp loại kỹ thuật A (đơn giá phụ cấp ) | C19: Kg | E19: =+SUMIF('BẢNG LƯƠNG KT'!$K$77:$K$92,"A",'BẢNG LƯƠNG KT'!$J$77:$J$92) -> 523.74972 | F19: =+(6.1+0.6)*$L$14 -> 4329.54 | G19: =ROUND((E19*F19),0) -> 2267595
B20: Xếp loại kỹ thuật B (đơn giá phụ cấp ) | C20: Kg | E20: =+SUMIF('BẢNG LƯƠNG KT'!$K$77:$K$92,"B",'BẢNG LƯƠNG KT'!$J$77:$J$92) -> 318.93828 | F20: =+(5.8+0.6)*$L$14 -> 4135.68 | G20: =ROUND((E20*F20),0)-1 -> 1319026
B21: Xếp loại kỹ thuật C (đơn giá phụ cấp ) | C21: Kg | E21: =+SUMIF('BẢNG LƯƠNG KT'!$K$77:$K$92,"C",'BẢNG LƯƠNG KT'!$J$77:$J$92) -> 0 | F21: =+(5.5+0.6)*$L$14 -> 3941.82 | G21: =E21*F21 -> 0 | H21: =+E21*F21 -> 0
B22: Xếp loại kỹ thuật D (đơn giá phụ cấp ) | C22: Kg | E22: =+SUMIF('BẢNG LƯƠNG KT'!$K$77:$K$92,"D",'BẢNG LƯƠNG KT'!$J$77:$J$92) -> 0 | F22: =+(5.2+0.6)*$L$14 -> 3747.96 | G22: =E22*F22 -> 0 | H22: =+E22*F22 -> 0
A23: 1.2 | B23: Phụ cấp khai thác | C23: Công | D23: =+SUM(D24:D29) -> 2060 | G23: =SUM(G24:G30) -> 107663001
B24: Phụ cấp ngày công thường | C24: Ngày | D24: ='BẢNG LƯƠNG KT'!M16+'BẢNG LƯƠNG KT'!M55 -> 763 | F24: =46.1*'BẢNG PHÂN TOÁN'!$L$15 -> 30232.38 | G24: =ROUND((D24*F24),0) -> 23067306
B25: Phụ cấp ngày công chủ nhật | C25: Ngày | D25: ='BẢNG LƯƠNG KT'!N55+'BẢNG LƯƠNG KT'!N16 -> 135 | F25: =76.9*$L$15 -> 50431.02 | G25: =ROUND((D25*F25),0) -> 6808188
B26: Phụ cấp ngày công vườn cây non | C26: Ngày | D26: ='BẢNG LƯƠNG KT'!O94 -> 19 | F26: =76.8*'BẢNG PHÂN TOÁN'!$L$15 -> 50365.44 | G26: =ROUND((D26*F26),0) -> 956943
B27: Phụ cấp chủ nhật vườn cây non | C27: Ngày | D27: ='BẢNG LƯƠNG KT'!P94 -> 1 | F27: =107.6*'BẢNG PHÂN TOÁN'!$L$15 -> 70564.08 | G27: =ROUND((D27*F27),0) -> 70564
B28: Phụ cấp vùng khó khăn | C28: Ngày | D28: =SUM(D24:D27) -> 918 | F28: 20000 | G28: =ROUND((D28*F28),0) -> 18360000
B29: Phụ cấp ngày công tổ 3 | C29: Ngày | D29: ='BẢNG LƯƠNG KT'!M76+'BẢNG LƯƠNG KT'!N76 -> 224 | F29: 100000 | G29: =ROUND((D29*F29),0) -> 22400000
B30: Phụ cấp tiền nhận phần cây | C30: Công | D30: ='BẢNG LƯƠNG KT'!R94 -> 1440 | F30: 25000 | G30: =D30*F30 -> 36000000
A31: 1.3 | B31: Tiền lương chăm sóc vườn cây | C31: Công | D31: ='BẢNG LƯƠNG KT'!G94 -> 0 | F31: 25000 | G31: =D31*F31 -> 0 | K31: ='1'!U52+'2'!U39+'3'!S33 -> 129103662
A32: 2 | B32: Tiền lương bảo vệ vườn cây | C32: Công | D32: =G32/F32 -> 1456 | F32: 25000 | G32: =BV!U26 -> 36400000 | K32: ='Tạp vụ'!M14 -> 1700000
A33: II | B33: Tiền lương KTCB | C33: Công | D33: =D34 -> 0 | F33: 25000 | G33: =G34 -> 0
A34: 1 | B34: Vườn cây 2018 | C34: Công | F34: 25000 | G34: =D34*F34 -> 0
A35: II | B35: Tiền lương tạp vụ | C35: Ngày | D35: ='Tạp vụ'!G13 -> 30 | F35: =G35/D35 -> 56666.667 | G35: ='Tạp vụ'!M14 -> 1700000 | K35: =BV!U26 -> 36400000
A36: TỔNG CỘNG: | E36: =E14 -> 5465.565 | G36: =G12+G33+G35 -> 167203662 | K36: =SUM(K31:K35) -> 167203662
A37: Số tiền bằng chữ: Hai trăm năm mươi lăm triệu năm trăm lẻ ba nghìn sáu trăm sáu mươi hai kíp.
G39: Sepon, ngày 03 tháng 05 năm 2025
A40: TỔNG GIÁM ĐỐC PHÒNG TC - KT PHÒNG TC - HC ĐỘI SẢN XUẤT SEPON

Sheet Tính lương tổ
A1: CỘNG HÒA DÂN CHỦ NHÂN DÂN LÀO
A2: Hòa bình - Độc lập - Dân chủ - Thống nhất - Thịnh vượng
A3: -----oOo-----
A4: CÔNG TY TNHH CỔ PHẦN QUASA-GERUCO LÀO
A5: ĐỘI SẢN XUẤT SEPON
A8: BẢNG TÍNH LƯƠNG TỔ TRƯỞNG THỰC HIỆN TRONG THÁNG 04/2025
K9: Đvt: Usd
A10: STT | B10: Họ và tên | C10: Chức vụ | D10: Tổ/ Đội | E10: Sản lượng giao kế hoạch tháng (tấn) | F10: Sản lượng thực hiện trong tháng (tấn) | G10: Tỷ lệ hoàn thành công việc ( % ) | H10: Lương cơ bản | I10: Lương tính theo tỷ lệ hoành thành công việc | J10: Phụ cấp | K10: Lương thực hiện trong tháng | L10: GHI CHÚ
E11: (1) | F11: (2) | G11: (3)=(2)/(1)*100% | H11: (4) | I11: (5)=250*(3) | J11: (6) | K11: (7) = (4) +(5)+(6)
A12: 1 | B12: Trần Văn Sơn | C12: Tổ trưởng | D12: Tổ 1 | E12: 6 | F12: =Mủ!AJ12/1000 -> 3.295671 | G12: =(F12/E12)*100 -> 54.92785 | H12: 250 | I12: =250*G12/100 -> 137.31962 | K12: =+H12+I12+J12 -> 387.31962
A13: 2 | B13: Đoàn Nhật Nam | C13: Tổ trưởng | D13: Tổ 2 | E13: 2 | F13: =Mủ!AJ50/1000 -> 1.327206 | G13: =(F13/E13)*100 -> 66.3603 | H13: 250 | I13: =250*G13/100 -> 165.90075 | K13: =+H13+I13+J13 -> 415.90075
A14: 3 | B14: Dương Văn Việt | C14: Tổ trưởng | D14: Tổ 3 | E14: 2 | F14: =Mủ!AJ70/1000 -> 0.842688 | G14: =(F14/E14)*100 -> 42.1344 | H14: 330 | I14: =250*G14/100 -> 105.336 | J14: 50 | K14: =+H14+I14+J14 -> 485.336
B15: Tổng | E15: =SUM(E12:E14) -> 10 | F15: =SUM(F12:F14) -> 5.465565 | G15: =(F15/E15)*100 -> 54.65565 | H15: =SUM(H12:H14) -> 830 | I15: =SUM(I12:I14) -> 408.55637 | J15: =SUM(J12:J14) -> 50 | K15: =SUM(K12:K14) -> 1288.5564
K17: Sepon, ngày 03 tháng 05 năm 2025
A18: TỔNG GIÁM ĐỐC | D18: P.TC - KT | G18: P. TC - HC | H18: P.KT -NN | J18: ĐỘI TRƯỞNG ĐỘI SEPON

Sheet Mủ
A1: CỘNG HÒA DÂN CHỦ NHÂN DÂN LÀO
A2: Hòa bình - Độc lập - Dân chủ - Thống nhất - Thịnh vượng
A3: -----oOo-----
A5: CÔNG TY TNHH CỔ PHẦN QUASA-GERUCO LÀO
A6: ĐỘI SẢN XUẤT SEPON
A8: BẢNG THEO DÕI SẢN LƯỢNG MỦ THÁNG 04 NĂM 2025
A10: STT | B10: STT | C10: TÊN CN | D10: NGÀY | AI10: TẠP | AJ10: Quy khô | AK10: Xếp hạng kỹ thuật | AL10: Ký tên
D11: 1 | E11: 2 | F11: 3 | G11: 4 | H11: 5 | I11: 6 | J11: 7 | K11: 8 | L11: 9 | M11: 10 | N11: 11 | O11: 12 | P11: 13 | Q11: 14 | R11: 15 | S11: 16 | T11: 17 | U11: 18 | V11: 19 | W11: 20 | X11: 21 | Y11: 22 | Z11: 23 | AA11: 24 | AB11: 25 | AC11: 26 | AD11: 27 | AE11: 28 | AF11: 29 | AG11: 30 | AH11: 31 | AN11: bôi kt
A12: A | B12: TỔ 1 | D12: =SUM(D13:D49) -> 0 | E12: =SUM(E13:E49) -> 0 | F12: =SUM(F13:F49) -> 0 | G12: =SUM(G13:G49) -> 0 | H12: =SUM(H13:H49) -> 0 | I12: =SUM(I13:I49) -> 0 | J12: =SUM(J13:J49) -> 0 | K12: =SUM(K13:K49) -> 0 | ... AJ12: =SUM(AJ13:AJ49) -> 3295.671 | BA12: t2 | BB12: t1 | BC12: t4
A13: 1 | B13: 1 | C13: ='Chấm công công nhân'!L13 -> Vắt Đi | D13: 0 | E13: 0 | F13: 0 | G13: 0 | H13: 0 | I13: 0 | J13: 0 | K13: 0 | L13: 0 | M13: 0 | N13: 0 | O13: 0 | P13: 0 | Q13: 0 | R13: 0 | S13: 0 | T13: 0 | U13: 0 | V13: 0 | W13: 0 | X13: 0 | Y13: 0 | Z13: 0 | AA13: 0 | AB13: 0 | AC13: 0 | AD13: 0 | AE13: 0 | AF13: 0 | AG13: 0 | AH13: 0 | AI13: =SUM(D13:AH13) -> 0 | AJ13: =AI13*$AX$17/100 -> 0 | AK13: A | AM13: =IF(AJ13>=3175,700000,IF(AJ13>=2760,500000,IF(AJ13>2400,300000,IF(AJ13>=2400,0,0)))) -> 0 | AN13: 2 | AO13: =AN13/1.25 -> 1.6 | BA13: 24072.189 | BB13: 35751.784 | BC13: 3295.671 | BD13: =SUM(BA13:BC13) -> 63119.644
A14: 2 | B14: 2 | C14: ='Chấm công công nhân'!L14 -> Mẹ Leo | D14: 0 | E14: 0 | F14: 0 | G14: 0 | H14: 0 | I14: 0 | J14: 0 | K14: 0 | L14: 0 | M14: 0 | N14: 0 | O14: 0 | P14: 0 | Q14: 0 | R14: 0 | S14: 0 | T14: 0 | U14: 0 | V14: 0 | W14: 0 | X14: 0 | Y14: 0 | Z14: 0 | AA14: 0 | AB14: 0 | AC14: 74 | AD14: 61 | AE14: 111 | AF14: 100 | AG14: 0 | AH14: 0 | AI14: =SUM(D14:AH14) -> 346 | AJ14: =AI14*$AX$17/100 -> 187.61141 | AK14: B | AM14: =IF(AJ14>=3175,700000,IF(AJ14>=2760,500000,IF(AJ14>2400,300000,IF(AJ14>=2400,0,0)))) -> 0 | AN14: 2 | AO14: =AN14/1.25 -> 1.6 | BA14: 11104.175 | BB14: 15912.768 | BC14: 1327.206 | BD14: =SUM(BA14:BC14) -> 28344.149
A15: 3 | B15: 3 | C15: ='Chấm công công nhân'!L15 -> Thảo Ken | D15: 0 | E15: 0 | F15: 0 | G15: 0 | H15: 0 | I15: 0 | J15: 0 | K15: 0 | L15: 0 | M15: 0 | N15: 0 | O15: 0 | P15: 0 | Q15: 0 | R15: 0 | S15: 0 | T15: 0 | U15: 0 | V15: 0 | W15: 0 | X15: 0 | Y15: 0 | Z15: 0 | AA15: 0 | AB15: 0 | AC15: 0 | AD15: 0 | AE15: 0 | AF15: 0 | AG15: 0 | AH15: 0 | AI15: =SUM(D15:AH15) -> 0 | AJ15: =AI15*$AX$17/100 -> 0 | AK15: A | AM15: =IF(AJ15>=3175,700000,IF(AJ15>=2760,500000,IF(AJ15>2400,300000,IF(AJ15>=2400,0,0)))) -> 0 | AN15: 2 | AO15: =AN15/1.25 -> 1.6 | BA15: 5843.686 | BB15: 11489.906 | BC15: 842.688 | BD15: =SUM(BA15:BC15) -> 18176.28
A16: 4 | B16: 4 | C16: ='Chấm công công nhân'!L16 -> Thảo Phút | D16: 0 | E16: 0 | F16: 0 | G16: 0 | H16: 0 | I16: 0 | J16: 0 | K16: 0 | L16: 0 | M16: 0 | N16: 0 | O16: 0 | P16: 0 | Q16: 0 | R16: 0 | S16: 0 | T16: 0 | U16: 0 | V16: 0 | W16: 0 | X16: 0 | Y16: 0 | Z16: 0 | AA16: 156 | AB16: 87 | AC16: 0 | AD16: 75 | AE16: 0 | AF16: 0 | AG16: 0 | AH16: 0 | AI16: =SUM(D16:AH16) -> 318 | AJ16: =AI16*$AX$17/100 -> 172.42899 | AK16: A | AM16: =IF(AJ16>=3175,700000,IF(AJ16>=2760,500000,IF(AJ16>2400,300000,IF(AJ16>=2400,0,0)))) -> 0 | AO16: =AN16/1.25 -> 0 | BD16: =SUM(BD13:BD15) -> 109640.07
A17: 5 | B17: 5 | C17: ='Chấm công công nhân'!L17 -> Thảo Mằn | D17: 0 | E17: 0 | F17: 0 | G17: 0 | H17: 0 | I17: 0 | J17: 0 | K17: 0 | L17: 0 | M17: 0 | N17: 0 | O17: 0 | P17: 0 | Q17: 0 | R17: 0 | S17: 0 | T17: 0 | U17: 0 | V17: 0 | W17: 0 | X17: 0 | Y17: 0 | Z17: 0 | AA17: 40 | AB17: 0 | AC17: 0 | AD17: 0 | AE17: 0 | AF17: 0 | AG17: 0 | AH17: 0 | AI17: =SUM(D17:AH17) -> 40 | AJ17: =AI17*$AX$17/100 -> 21.689181 | AK17: B | AM17: =IF(AJ17>=3175,700000,IF(AJ17>=2760,500000,IF(AJ17>2400,300000,IF(AJ17>=2400,0,0)))) -> 0 | AO17: =AN17/1.25 -> 0 | AX17: 54.222952
A18: 6 | B18: 6 | C18: ='Chấm công công nhân'!L18 -> Nàng Chay | D18: 0 | E18: 0 | F18: 0 | G18: 0 | H18: 0 | I18: 0 | J18: 0 | K18: 0 | L18: 0 | M18: 0 | N18: 0 | O18: 0 | P18: 0 | Q18: 0 | R18: 0 | S18: 0 | T18: 0 | U18: 0 | V18: 0 | W18: 0 | X18: 0 | Y18: 0 | Z18: 0 | AA18: 0 | AB18: 0 | AC18: 0 | AD18: 0 | AE18: 0 | AF18: 0 | AG18: 0 | AH18: 0 | AI18: =SUM(D18:AH18) -> 0 | AJ18: =AI18*$AX$17/100 -> 0 | AK18: B | AM18: =IF(AJ18>=3175,700000,IF(AJ18>=2760,500000,IF(AJ18>2400,300000,IF(AJ18>=2400,0,0)))) -> 0 | AN18: 2 | AO18: =AN18/1.25 -> 1.6 | BD18: =BD16/700000*100 -> 15.662868
A19: 7 | B19: 7 | C19: ='Chấm công công nhân'!L19 -> Thảo Sắp | D19: 0 | E19: 0 | F19: 0 | G19: 0 | H19: 0 | I19: 0 | J19: 0 | K19: 0 | L19: 0 | M19: 0 | N19: 0 | O19: 0 | P19: 0 | Q19: 0 | R19: 0 | S19: 0 | T19: 0 | U19: 0 | V19: 0 | W19: 0 | X19: 0 | Y19: 0 | Z19: 0 | AA19: 86 | AB19: 52 | AC19: 60 | AD19: 64 | AE19: 0 | AF19: 0 | AG19: 0 | AH19: 0 | AI19: =SUM(D19:AH19) -> 262 | AJ19: =AI19*$AX$17/100 -> 142.06413 | AK19: A | AM19: =IF(AJ19>=3175,700000,IF(AJ19>=2760,500000,IF(AJ19>2400,300000,IF(AJ19>=2400,0,0)))) -> 0 | AN19: 4 | AO19: =AN19/1.25 -> 3.2
A20: 8 | B20: 8 | C20: ='Chấm công công nhân'!L20 -> Thảo Say | D20: 0 | E20: 0 | F20: 0 | G20: 0 | H20: 0 | I20: 0 | J20: 0 | K20: 0 | L20: 0 | M20: 0 | N20: 0 | O20: 0 | P20: 0 | Q20: 0 | R20: 0 | S20: 0 | T20: 0 | U20: 0 | V20: 0 | W20: 0 | X20: 0 | Y20: 0 | Z20: 0 | AA20: 0 | AB20: 83 | AC20: 80 | AD20: 78 | AE20: 203 | AF20: 0 | AG20: 0 | AH20: 0 | AI20: =SUM(D20:AH20) -> 444 | AJ20: =AI20*$AX$17/100 -> 240.74991 | AK20: A | AM20: =IF(AJ20>=3175,700000,IF(AJ20>=2760,500000,IF(AJ20>2400,300000,IF(AJ20>=2400,0,0)))) -> 0 | AN20: 4 | AO20: =AN20/1.25 -> 3.2
A21: 9 | B21: 9 | C21: ='Chấm công công nhân'!L21 -> Thảo Cợt | D21: 0 | E21: 0 | F21: 0 | G21: 0 | H21: 0 | I21: 0 | J21: 0 | K21: 0 | L21: 0 | M21: 0 | N21: 0 | O21: 0 | P21: 0 | Q21: 0 | R21: 0 | S21: 0 | T21: 0 | U21: 0 | V21: 0 | W21: 0 | X21: 0 | Y21: 0 | Z21: 0 | AA21: 62 | AB21: 0 | AC21: 0 | AD21: 0 | AE21: 0 | AF21: 0 | AG21: 137 | AH21: 0 | AI21: =SUM(D21:AH21) -> 199 | AJ21: =AI21*$AX$17/100 -> 107.90367 | AK21: C | AM21: =IF(AJ21>=3175,700000,IF(AJ21>=2760,500000,IF(AJ21>2400,300000,IF(AJ21>=2400,0,0)))) -> 0 | AN21: 4 | AO21: =AN21/1.25 -> 3.2 | AQ21: thiếu | AR21: k bôi
A22: 10 | B22: 10 | C22: ='Chấm công công nhân'!L22 -> Thảo Hôm | D22: 0 | E22: 0 | F22: 0 | G22: 0 | H22: 0 | I22: 0 | J22: 0 | K22: 0 | L22: 0 | M22: 0 | N22: 0 | O22: 0 | P22: 0 | Q22: 0 | R22: 0 | S22: 0 | T22: 0 | U22: 0 | V22: 0 | W22: 0 | X22: 0 | Y22: 0 | Z22: 0 | AA22: 107 | AB22: 79 | AC22: 92 | AD22: 94 | AE22: 0 | AF22: 0 | AG22: 0 | AH22: 0 | AI22: =SUM(D22:AH22) -> 372 | AJ22: =AI22*$AX$17/100 -> 201.70938 | AK22: A | AM22: =IF(AJ22>=3175,700000,IF(AJ22>=2760,500000,IF(AJ22>2400,300000,IF(AJ22>=2400,0,0)))) -> 0 | AO22: =AN22/1.25 -> 0 | AQ22: 8 | AR22: 4 | AS22: =12*4 -> 48
A23: 11 | B23: 11 | C23: ='Chấm công công nhân'!L23 -> Thảo Khăm | D23: 0 | E23: 0 | F23: 0 | G23: 0 | H23: 0 | I23: 0 | J23: 0 | K23: 0 | L23: 0 | M23: 0 | N23: 0 | O23: 0 | P23: 0 | Q23: 0 | R23: 0 | S23: 0 | T23: 0 | U23: 0 | V23: 0 | W23: 0 | X23: 0 | Y23: 0 | Z23: 0 | AA23: 0 | AB23: 0 | AC23: 0 | AD23: 0 | AE23: 0 | AF23: 0 | AG23: 0 | AH23: 0 | AI23: =SUM(D23:AH23) -> 0 | AJ23: =AI23*$AX$17/100 -> 0 | AK23: B | AM23: =IF(AJ23>=3175,700000,IF(AJ23>=2760,500000,IF(AJ23>2400,300000,IF(AJ23>=2400,0,0)))) -> 0 | AN23: 2 | AO23: =AN23/1.25 -> 1.6
A24: 12 | B24: 12 | C24: ='Chấm công công nhân'!L24 -> Thảo Hăm | D24: 0 | E24: 0 | F24: 0 | G24: 0 | H24: 0 | I24: 0 | J24: 0 | K24: 0 | L24: 0 | M24: 0 | N24: 0 | O24: 0 | P24: 0 | Q24: 0 | R24: 0 | S24: 0 | T24: 0 | U24: 0 | V24: 0 | W24: 0 | X24: 0 | Y24: 0 | Z24: 0 | AA24: 0 | AB24: 0 | AC24: 0 | AD24: 0 | AE24: 0 | AF24: 0 | AG24: 0 | AH24: 0 | AI24: =SUM(D24:AH24) -> 0 | AJ24: =AI24*$AX$17/100 -> 0 | AK24: A | AM24: =IF(AJ24>=3175,700000,IF(AJ24>=2760,500000,IF(AJ24>2400,300000,IF(AJ24>=2400,0,0)))) -> 0 | AN24: 4 | AO24: =AN24/1.25 -> 3.2
A25: 13 | B25: 13 | C25: ='Chấm công công nhân'!L25 -> Nang Lon | D25: 0 | E25: 0 | F25: 0 | G25: 0 | H25: 0 | I25: 0 | J25: 0 | K25: 0 | L25: 0 | M25: 0 | N25: 0 | O25: 0 | P25: 0 | Q25: 0 | R25: 0 | S25: 0 | T25: 0 | U25: 0 | V25: 0 | W25: 0 | X25: 0 | Y25: 0 | Z25: 0 | AA25: 0 | AB25: 0 | AC25: 0 | AD25: 0 | AE25: 0 | AF25: 0 | AG25: 0 | AH25: 0 | AI25: =SUM(D25:AH25) -> 0 | AJ25: =AI25*$AX$17/100 -> 0 | AK25: B | AN25: 2 | AO25: =AN25/1.25 -> 1.6
A26: 14 | B26: 14 | C26: ='Chấm công công nhân'!L26 -> Thảo Pheng | D26: 0 | E26: 0 | F26: 0 | G26: 0 | H26: 0 | I26: 0 | J26: 0 | K26: 0 | L26: 0 | M26: 0 | N26: 0 | O26: 0 | P26: 0 | Q26: 0 | R26: 0 | S26: 0 | T26: 0 | U26: 0 | V26: 0 | W26: 0 | X26: 0 | Y26: 0 | Z26: 0 | AA26: 0 | AB26: 49 | AC26: 53 | AD26: 0 | AE26: 0 | AF26: 0 | AG26: 0 | AH26: 0 | AI26: =SUM(D26:AH26) -> 102 | AJ26: =AI26*$AX$17/100 -> 55.307411 | AK26: B | AN26: 2 | AO26: =AN26/1.25 -> 1.6
A27: 15 | B27: 15 | C27: ='Chấm công công nhân'!L27 -> Thảo kok | D27: 0 | E27: 0 | F27: 0 | G27: 0 | H27: 0 | I27: 0 | J27: 0 | K27: 0 | L27: 0 | M27: 0 | N27: 0 | O27: 0 | P27: 0 | Q27: 0 | R27: 0 | S27: 0 | T27: 0 | U27: 0 | V27: 0 | W27: 0 | X27: 0 | Y27: 0 | Z27: 0 | AA27: 0 | AB27: 0 | AC27: 73 | AD27: 50 | AE27: 61 | AF27: 77 | AG27: 0 | AH27: 0 | AI27: =SUM(D27:AH27) -> 261 | AJ27: =AI27*$AX$17/100 -> 141.5219 | AK27: A | AN27: 2 | AO27: =AN27/1.25 -> 1.6
A28: 16 | B28: 16 | C28: ='Chấm công công nhân'!L28 -> Nàng Sút Chay | D28: 0 | E28: 0 | F28: 0 | G28: 0 | H28: 0 | I28: 0 | J28: 0 | K28: 0 | L28: 0 | M28: 0 | N28: 0 | O28: 0 | P28: 0 | Q28: 0 | R28: 0 | S28: 0 | T28: 0 | U28: 0 | V28: 0 | W28: 0 | X28: 0 | Y28: 0 | Z28: 0 | AA28: 0 | AB28: 34 | AC28: 36 | AD28: 0 | AE28: 0 | AF28: 0 | AG28: 0 | AH28: 0 | AI28: =SUM(D28:AH28) -> 70 | AJ28: =AI28*$AX$17/100 -> 37.956066 | AK28: A | AO28: =AN28/1.25 -> 0
A29: 17 | B29: 17 | C29: ='Chấm công công nhân'!L29 -> Thảo Khăm Phay | D29: 0 | E29: 0 | F29: 0 | G29: 0 | H29: 0 | I29: 0 | J29: 0 | K29: 0 | L29: 0 | M29: 0 | N29: 0 | O29: 0 | P29: 0 | Q29: 0 | R29: 0 | S29: 0 | T29: 0 | U29: 0 | V29: 0 | W29: 0 | X29: 0 | Y29: 0 | Z29: 0 | AA29: 0 | AB29: 34 | AC29: 36 | AD29: 0 | AE29: 0 | AF29: 0 | AG29: 0 | AH29: 0 | AI29: =SUM(D29:AH29) -> 70 | AJ29: =AI29*$AX$17/100 -> 37.956066 | AK29: B | AN29: 4 | AO29: =AN29/1.25 -> 3.2
A30: 18 | B30: 18 | C30: ='Chấm công công nhân'!L30 -> Thảo Sớm | D30: 0 | E30: 0 | F30: 0 | G30: 0 | H30: 0 | I30: 0 | J30: 0 | K30: 0 | L30: 0 | M30: 0 | N30: 0 | O30: 0 | P30: 0 | Q30: 0 | R30: 0 | S30: 0 | T30: 0 | U30: 0 | V30: 0 | W30: 0 | X30: 0 | Y30: 0 | Z30: 0 | AA30: 0 | AB30: 0 | AC30: 71 | AD30: 63 | AE30: 0 | AF30: 0 | AG30: 0 | AH30: 0 | AI30: =SUM(D30:AH30) -> 134 | AJ30: =AI30*$AX$17/100 -> 72.658755 | AK30: A | AN30: 4 | AO30: =AN30/1.25 -> 3.2
A31: 19 | B31: 19 | C31: ='Chấm công công nhân'!L31 -> Pha Xúc | D31: 0 | E31: 0 | F31: 0 | G31: 0 | H31: 0 | I31: 0 | J31: 0 | K31: 0 | L31: 0 | M31: 0 | N31: 0 | O31: 0 | P31: 0 | Q31: 0 | R31: 0 | S31: 0 | T31: 0 | U31: 0 | V31: 0 | W31: 0 | X31: 0 | Y31: 0 | Z31: 0 | AA31: 0 | AB31: 0 | AC31: 0 | AD31: 0 | AE31: 0 | AF31: 0 | AG31: 0 | AH31: 0 | AI31: =SUM(D31:AH31) -> 0 | AJ31: =AI31*$AX$17/100 -> 0 | AK31: B | AN31: 4 | AO31: =AN31/1.25 -> 3.2
A32: 20 | B32: 20 | C32: ='Chấm công công nhân'!L32 -> Nàng Phon | D32: 0 | E32: 0 | F32: 0 | G32: 0 | H32: 0 | I32: 0 | J32: 0 | K32: 0 | L32: 0 | M32: 0 | N32: 0 | O32: 0 | P32: 0 | Q32: 0 | R32: 0 | S32: 0 | T32: 0 | U32: 0 | V32: 0 | W32: 0 | X32: 0 | Y32: 0 | Z32: 0 | AA32: 40 | AB32: 0 | AC32: 0 | AD32: 0 | AE32: 0 | AF32: 0 | AG32: 0 | AH32: 0 | AI32: =SUM(D32:AH32) -> 40 | AJ32: =AI32*$AX$17/100 -> 21.689181 | AK32: A | AN32: 4 | AO32: =AN32/1.25 -> 3.2
A33: 21 | B33: 21 | C33: ='Chấm công công nhân'!L33 -> Thảo Chăn | D33: 0 | E33: 0 | F33: 0 | G33: 0 | H33: 0 | I33: 0 | J33: 0 | K33: 0 | L33: 0 | M33: 0 | N33: 0 | O33: 0 | P33: 0 | Q33: 0 | R33: 0 | S33: 0 | T33: 0 | U33: 0 | V33: 0 | W33: 0 | X33: 0 | Y33: 0 | Z33: 0 | AA33: 45 | AB33: 0 | AC33: 46 | AD33: 50 | AE33: 0 | AF33: 121 | AG33: 0 | AH33: 0 | AI33: =SUM(D33:AH33) -> 262 | AJ33: =AI33*$AX$17/100 -> 142.06413 | AK33: A | AO33: =AN33/1.25 -> 0
A34: 22 | B34: 22 | C34: ='Chấm công công nhân'!L34 -> Thong La | D34: 0 | E34: 0 | F34: 0 | G34: 0 | H34: 0 | I34: 0 | J34: 0 | K34: 0 | L34: 0 | M34: 0 | N34: 0 | O34: 0 | P34: 0 | Q34: 0 | R34: 0 | S34: 0 | T34: 0 | U34: 0 | V34: 0 | W34: 0 | X34: 0 | Y34: 0 | Z34: 0 | AA34: 58 | AB34: 0 | AC34: 75 | AD34: 0 | AE34: 0 | AF34: 0 | AG34: 0 | AH34: 0 | AI34: =SUM(D34:AH34) -> 133 | AJ34: =AI34*$AX$17/100 -> 72.116526 | AK34: A | AO34: =AN34/1.25 -> 0
A35: 23 | B35: 23 | C35: ='Chấm công công nhân'!L35 -> Thảo Cum Pha | D35: 0 | E35: 0 | F35: 0 | G35: 0 | H35: 0 | I35: 0 | J35: 0 | K35: 0 | L35: 0 | M35: 0 | N35: 0 | O35: 0 | P35: 0 | Q35: 0 | R35: 0 | S35: 0 | T35: 0 | U35: 0 | V35: 0 | W35: 0 | X35: 0 | Y35: 0 | Z35: 0 | AA35: 0 | AB35: 0 | AC35: 21 | AD35: 0 | AE35: 0 | AF35: 0 | AG35: 0 | AH35: 0 | AI35: =SUM(D35:AH35) -> 21 | AJ35: =AI35*$AX$17/100 -> 11.38682 | AK35: B | AN35: 4 | AO35: =AN35/1.25 -> 3.2
A36: 24 | B36: 24 | C36: ='Chấm công công nhân'!L36 -> T Ô Vên | D36: 0 | E36: 0 | F36: 0 | G36: 0 | H36: 0 | I36: 0 | J36: 0 | K36: 0 | L36: 0 | M36: 0 | N36: 0 | O36: 0 | P36: 0 | Q36: 0 | R36: 0 | S36: 0 | T36: 0 | U36: 0 | V36: 0 | W36: 0 | X36: 0 | Y36: 0 | Z36: 0 | AA36: 0 | AB36: 0 | AC36: 46 | AD36: 50 | AE36: 69 | AF36: 41 | AG36: 0 | AH36: 0 | AI36: =SUM(D36:AH36) -> 206 | AJ36: =AI36*$AX$17/100 -> 111.69928 | AK36: B | AN36: 4 | AO36: =AN36/1.25 -> 3.2
A37: 25 | B37: 25 | C37: ='Chấm công công nhân'!L37 -> Nàng Lam | D37: 0 | E37: 0 | F37: 0 | G37: 0 | H37: 0 | I37: 0 | J37: 0 | K37: 0 | L37: 0 | M37: 0 | N37: 0 | O37: 0 | P37: 0 | Q37: 0 | R37: 0 | S37: 0 | T37: 0 | U37: 0 | V37: 0 | W37: 0 | X37: 0 | Y37: 0 | Z37: 0 | AA37: 130 | AB37: 47 | AC37: 16 | AD37: 54 | AE37: 0 | AF37: 0 | AG37: 0 | AH37: 0 | AI37: =SUM(D37:AH37) -> 247 | AJ37: =AI37*$AX$17/100 -> 133.93069 | AK37: A | AN37: 4 | AO37: =AN37/1.25 -> 3.2
A38: 26 | B38: 26 | C38: ='Chấm công công nhân'!L38 -> Nàng Hđao | D38: 0 | E38: 0 | F38: 0 | G38: 0 | H38: 0 | I38: 0 | J38: 0 | K38: 0 | L38: 0 | M38: 0 | N38: 0 | O38: 0 | P38: 0 | Q38: 0 | R38: 0 | S38: 0 | T38: 0 | U38: 0 | V38: 0 | W38: 0 | X38: 0 | Y38: 0 | Z38: 0 | AA38: 25 | AB38: 23 | AC38: 0 | AD38: 0 | AE38: 0 | AF38: 0 | AG38: 0 | AH38: 0 | AI38: =SUM(D38:AH38) -> 48 | AJ38: =AI38*$AX$17/100 -> 26.027017 | AK38: B | AN38: 4 | AO38: =AN38/1.25 -> 3.2
A39: 27 | B39: 27 | C39: ='Chấm công công nhân'!L39 -> Thảo Tong | D39: 0 | E39: 0 | F39: 0 | G39: 0 | H39: 0 | I39: 0 | J39: 0 | K39: 0 | L39: 0 | M39: 0 | N39: 0 | O39: 0 | P39: 0 | Q39: 0 | R39: 0 | S39: 0 | T39: 0 | U39: 0 | V39: 0 | W39: 0 | X39: 0 | Y39: 0 | Z39: 0 | AA39: 0 | AB39: 0 | AC39: 61 | AD39: 57 | AE39: 0 | AF39: 0 | AG39: 0 | AH39: 0 | AI39: =SUM(D39:AH39) -> 118 | AJ39: =AI39*$AX$17/100 -> 63.983083 | AK39: B | AN39: 4 | AO39: =AN39/1.25 -> 3.2
A40: 28 | B40: 28 | C40: ='Chấm công công nhân'!L40 -> Thảo Khốc | D40: 0 | E40: 0 | F40: 0 | G40: 0 | H40: 0 | I40: 0 | J40: 0 | K40: 0 | L40: 0 | M40: 0 | N40: 0 | O40: 0 | P40: 0 | Q40: 0 | R40: 0 | S40: 0 | T40: 0 | U40: 0 | V40: 0 | W40: 0 | X40: 0 | Y40: 0 | Z40: 0 | AA40: 0 | AB40: 68 | AC40: 74 | AD40: 80 | AE40: 97 | AF40: 52 | AG40: 56 | AH40: 0 | AI40: =SUM(D40:AH40) -> 427 | AJ40: =AI40*$AX$17/100 -> 231.532 | AK40: A | AM40: =IF(AJ40>=3175,700000,IF(AJ40>=2760,500000,IF(AJ40>2400,300000,IF(AJ40>=2400,0,0)))) -> 0 | AN40: 4 | AO40: =AN40/1.25 -> 3.2
A41: 29 | B41: 29 | C41: ='Chấm công công nhân'!L41 -> Thảo Sợt | D41: 0 | E41: 0 | F41: 0 | G41: 0 | H41: 0 | I41: 0 | J41: 0 | K41: 0 | L41: 0 | M41: 0 | N41: 0 | O41: 0 | P41: 0 | Q41: 0 | R41: 0 | S41: 0 | T41: 0 | U41: 0 | V41: 0 | W41: 0 | X41: 0 | Y41: 0 | Z41: 0 | AA41: 0 | AB41: 69 | AC41: 74 | AD41: 81 | AE41: 98 | AF41: 52 | AG41: 56 | AH41: 0 | AI41: =SUM(D41:AH41) -> 430 | AJ41: =AI41*$AX$17/100 -> 233.15869 | AK41: B | AM41: =IF(AJ41>=3175,700000,IF(AJ41>=2760,500000,IF(AJ41>2400,300000,IF(AJ41>=2400,0,0)))) -> 0 | AN41: 4 | AO41: =AN41/1.25 -> 3.2
A42: 30 | B42: 30 | C42: ='Chấm công công nhân'!L42 -> Thảo Văn | D42: 0 | E42: 0 | F42: 0 | G42: 0 | H42: 0 | I42: 0 | J42: 0 | K42: 0 | L42: 0 | M42: 0 | N42: 0 | O42: 0 | P42: 0 | Q42: 0 | R42: 0 | S42: 0 | T42: 0 | U42: 0 | V42: 0 | W42: 0 | X42: 0 | Y42: 0 | Z42: 0 | AA42: 0 | AB42: 0 | AC42: 0 | AD42: 0 | AE42: 0 | AF42: 0 | AG42: 0 | AH42: 0 | AI42: =SUM(D42:AH42) -> 0 | AJ42: =AI42*$AX$17/100 -> 0 | AK42: C | AM42: =IF(AJ42>=3175,700000,IF(AJ42>=2760,500000,IF(AJ42>2400,300000,IF(AJ42>=2400,0,0)))) -> 0 | AO42: =AN42/1.25 -> 0
A43: 31 | B43: 31 | C43: ='Chấm công công nhân'!L43 -> Nàng Túc | D43: 0 | E43: 0 | F43: 0 | G43: 0 | H43: 0 | I43: 0 | J43: 0 | K43: 0 | L43: 0 | M43: 0 | N43: 0 | O43: 0 | P43: 0 | Q43: 0 | R43: 0 | S43: 0 | T43: 0 | U43: 0 | V43: 0 | W43: 0 | X43: 0 | Y43: 0 | Z43: 0 | AA43: 0 | AB43: 0 | AC43: 47 | AD43: 50 | AE43: 70 | AF43: 42 | AG43: 0 | AH43: 0 | AI43: =SUM(D43:AH43) -> 209 | AJ43: =AI43*$AX$17/100 -> 113.32597 | AK43: A | AM43: =IF(AJ43>=3175,700000,IF(AJ43>=2760,500000,IF(AJ43>2400,300000,IF(AJ43>=2400,0,0)))) -> 0 | AN43: 4 | AO43: =AN43/1.25 -> 3.2
...

Sheet Chấm công công nhân
A1: CỘNG HÒA DÂN CHỦ NHÂN DÂN LÀO
A2: Hòa bình - Độc lập - Dân chủ - Thống nhất - Thịnh vượng
A3: -----oOo-----
J4: CÔNG TY TNHH CỔ PHẦN QUASA-GERUCO LÀO
A5: ĐỘI SẢN XUẤT SEPON | J5: ĐỘI SẢN XUẤT SEPON
J7: BẢNG CHẤM CÔNG CẠO MỦ HẰNG NGÀY CÔNG NHÂN THÁNG 04 NĂM 2025
A9: Lương ngày công | B9: Điểm ngày công | C9: Hạng kỹ thuật cạo | D9: Điểm kỹ thuật | E9: Tổng điểm | F9: Xếp hạng trong tháng | G9: Tổng mủ quy khô trong tháng | H9: Lương sản lượng trong tháng | I9: Tổng lương ngày công + sản lượng | J9: Stt | K9: Stt | L9: Họ và tên | M9: Ngày công | AR9: Ngày thường (X) | AS9: Ngày chủ nhật ( CN) | AT9: Phụ cấp ngày công vườn cây năm nhất (X1) | AU9: Phụ cấp chủ nhật vườn cây năm nhất (CN1) | AV9: Tổng cộng | AW9: Ký tên | AY9: Ký tên
M10: 1 | N10: 2 | O10: 3 | P10: 4 | Q10: 5 | R10: 6 | S10: 7 | T10: 8 | U10: 9 | V10: 10 | W10: 11 | X10: 12 | Y10: 13 | Z10: 14 | AA10: 15 | AB10: 16 | AC10: 17 | AD10: 18 | AE10: 19 | AF10: 20 | AG10: 21 | AH10: 22 | AI10: 23 | AJ10: 24 | AK10: 25 | AL10: 26 | AM10: 27 | AN10: 28 | AO10: 29 | AP10: 30
M11: D | N11: A | O11: B | P11: C | Q11: D | R11: A | S11: B | T11: C | U11: D | V11: A | W11: B | X11: C | Y11: D | Z11: A | AA11: B | AB11: C | AC11: D | AD11: A | AE11: B | AF11: C | AG11: D | AH11: A | AI11: B | AJ11: C | AK11: D | AL11: A | AM11: B | AN11: C | BK11: 23
J12: A | K12: TỔ 1 | M12: =COUNTIF(M13:M49,"X")+COUNTIF(M13:M49,"CN")+COUNTIF(M13:M49,"X1")+COUNTIF(M13:M49,"CN1") -> 0 | N12: =COUNTIF(N13:N49,"X")+COUNTIF(N13:N49,"CN")+COUNTIF(N13:N49,"X1")+COUNTIF(N13:N49,"CN1") -> 0 | O12: =COUNTIF(O13:O49,"X")+COUNTIF(O13:O49,"CN")+COUNTIF(O13:O49,"X1")+COUNTIF(O13:O49,"CN1") -> 0 | P12: =COUNTIF(P13:P49,"X")+COUNTIF(P13:P49,"CN")+COUNTIF(P13:P49,"X1")+COUNTIF(P13:P49,"CN1") -> 0 | Q12: =COUNTIF(Q13:Q49,"X")+COUNTIF(Q13:Q49,"CN")+COUNTIF(Q13:Q49,"X1")+COUNTIF(Q13:Q49,"CN1") -> 11 | R12: =COUNTIF(R13:R49,"X")+COUNTIF(R13:R49,"CN")+COUNTIF(R13:R49,"X1")+COUNTIF(R13:R49,"CN1") -> 13 | S12: =COUNTIF(S13:S49,"X")+COUNTIF(S13:S49,"CN")+COUNTIF(S13:S49,"X1")+COUNTIF(S13:S49,"CN1") -> 10 | T12: =COUNTIF(T13:T49,"X")+COUNTIF(T13:T49,"CN")+COUNTIF(T13:T49,"X1")+COUNTIF(T13:T49,"CN1") -> 15 | ... AP12: =COUNTIF(AP13:AP49,"X")+COUNTIF(AP13:AP49,"CN")+COUNTIF(AP13:AP49,"X1")+COUNTIF(AP13:AP49,"CN1") -> 37 | AR12: =SUM(AR13:AR49) -> 531 | AS12: =SUM(AS13:AS49) -> 108 | AT12: =SUM(AT13:AT49) -> 5 | AU12: =SUM(AU13:AU49) -> 1 | AV12: =SUM(AV13:AV49) -> 645 | AX12: =SUM(AX13:AX48) -> 0
J13: 1 | K13: 1 | L13: Vắt Đi | T13: X | X13: X | Y13: CN | AD13: X | AE13: X | AF13: CN | AG13: X | AH13: X | AI13: X | AJ13: X | AL13: X | AM13: CN | AO13: X | AP13: X | AR13: =COUNTIF(M13:AQ13,"X") -> 11 | AS13: =+COUNTIF(M13:AQ13,"CN") -> 3 | AT13: =COUNTIF(M13:AQ13,"X1") -> 0 | AU13: =+COUNTIF(M13:AQ13,"CN1") -> 0 | AV13: =+SUM(AR13:AU13) -> 14
J14: 2 | K14: 2 | L14: Mẹ Leo | Q14: X | R14: CN | S14: X | T14: X | U14: X | V14: X | W14: X | X14: X | Y14: CN | AC14: X | AD14: X | AE14: X | AF14: CN | AG14: X | AH14: X | AI14: X | AJ14: X | AK14: X | AL14: X | AM14: CN | AN14: X | AO14: X | AP14: X | AR14: =COUNTIF(M14:AQ14,"X") -> 19 | AS14: =+COUNTIF(M14:AQ14,"CN") -> 4 | AT14: =COUNTIF(M14:AQ14,"X1") -> 0 | AU14: =+COUNTIF(M14:AQ14,"CN1") -> 0 | AV14: =+SUM(AR14:AU14) -> 23
J15: 3 | K15: 3 | L15: Thảo Ken | U15: X | V15: X | W15: X | X15: X | Y15: CN | AE15: X | AF15: CN | AG15: X | AH15: X | AI15: X | AL15: X | AM15: CN | AN15: X | AO15: X | AP15: X | AR15: =COUNTIF(M15:AQ15,"X") -> 12 | AS15: =+COUNTIF(M15:AQ15,"CN") -> 3 | AT15: =COUNTIF(M15:AQ15,"X1") -> 0 | AU15: =+COUNTIF(M15:AQ15,"CN1") -> 0 | AV15: =+SUM(AR15:AU15) -> 15
J16: 4 | K16: 4 | L16: Thảo Phút | Q16: X | R16: CN | S16: X | T16: X | U16: X | V16: X | W16: X | X16: X | Y16: CN | Z16: X | AA16: X | AC16: X | AD16: X | AE16: X | AF16: CN | AG16: X | AH16: X | AI16: X | AJ16: X | AK16: X | AL16: X | AM16: CN | AN16: X | AO16: X | AP16: X | AR16: =COUNTIF(M16:AQ16,"X") -> 21 | AS16: =+COUNTIF(M16:AQ16,"CN") -> 4 | AT16: =COUNTIF(M16:AQ16,"X1") -> 0 | AU16: =+COUNTIF(M16:AQ16,"CN1") -> 0 | AV16: =+SUM(AR16:AU16) -> 25
J17: 5 | K17: 5 | L17: Thảo Mằn | T17: X | U17: X | V17: X | X17: X | Y17: CN | AE17: X | AF17: CN | AG17: X | AH17: X | AI17: X | AJ17: X | AL17: X | AM17: CN | AO17: X | AP17: X | AR17: =COUNTIF(M17:AQ17,"X") -> 12 | AS17: =+COUNTIF(M17:AQ17,"CN") -> 3 | AT17: =COUNTIF(M17:AQ17,"X1") -> 0 | AU17: =+COUNTIF(M17:AQ17,"CN1") -> 0 | AV17: =+SUM(AR17:AU17) -> 15
J18: 6 | K18: 6 | L18: Nàng Chay | U18: X | V18: X | W18: X | X18: X | Y18: CN | AD18: X | AE18: X | AF18: CN | AG18: X | AH18: X | AI18: X | AL18: X | AM18: CN | AN18: X | AO18: X | AP18: X | AR18: =COUNTIF(M18:AQ18,"X") -> 13 | AS18: =+COUNTIF(M18:AQ18,"CN") -> 3 | AT18: =COUNTIF(M18:AQ18,"X1") -> 0 | AU18: =+COUNTIF(M18:AQ18,"CN1") -> 0 | AV18: =+SUM(AR18:AU18) -> 16
J19: 7 | K19: 7 | L19: Thảo Sắp | Q19: X | R19: CN | S19: X | T19: X | U19: X | V19: X | W19: X | X19: X | Y19: CN | Z19: X | AA19: X | AB19: X | AC19: X | AD19: X | AE19: X | AF19: CN | AG19: X | AH19: X | AI19: X | AJ19: X | AK19: X | AL19: X | AM19: CN | AN19: X | AO19: X | AP19: X | AR19: =COUNTIF(M19:AQ19,"X") -> 22 | AS19: =+COUNTIF(M19:AQ19,"CN") -> 4 | AT19: =COUNTIF(M19:AQ19,"X1") -> 0 | AU19: =+COUNTIF(M19:AQ19,"CN1") -> 0 | AV19: =+SUM(AR19:AU19) -> 26
J20: 8 | K20: 8 | L20: Thảo Say | Q20: X | R20: CN | S20: X | U20: X | V20: X | W20: X | X20: X | Y20: CN | Z20: X | AA20: X | AB20: X | AC20: X | AD20: X | AE20: X | AF20: CN | AG20: X | AH20: X | AI20: X | AJ20: X | AK20: X | AL20: X | AM20: CN | AN20: X | AO20: X | AP20: X | AR20: =COUNTIF(M20:AQ20,"X") -> 21 | AS20: =+COUNTIF(M20:AQ20,"CN") -> 4 | AT20: =COUNTIF(M20:AQ20,"X1") -> 0 | AU20: =+COUNTIF(M20:AQ20,"CN1") -> 0 | AV20: =+SUM(AR20:AU20) -> 25
J21: 9 | K21: 9 | L21: Thảo Cợt | V21: X | X21: X | AD21: X | AE21: X | AF21: CN | AH21: X | AI21: X | AK21: X | AL21: X | AM21: CN | AN21: X | AO21: X | AP21: X | AR21: =COUNTIF(M21:AQ21,"X") -> 11 | AS21: =+COUNTIF(M21:AQ21,"CN") -> 2 | AT21: =COUNTIF(M21:AQ21,"X1") -> 0 | AU21: =+COUNTIF(M21:AQ21,"CN1") -> 0 | AV21: =+SUM(AR21:AU21) -> 13
J22: 10 | K22: 10 | L22: Thảo Hôm | Q22: X | R22: CN | S22: X | T22: X | U22: X | V22: X | W22: X | X22: X | Y22: CN | AE22: X | AF22: CN | AG22: X | AH22: X | AI22: X | AJ22: X | AK22: X | AL22: X | AM22: CN | AN22: X | AO22: X | AP22: X | AR22: =COUNTIF(M22:AQ22,"X") -> 17 | AS22: =+COUNTIF(M22:AQ22,"CN") -> 4 | AT22: =COUNTIF(M22:AQ22,"X1") -> 0 | AU22: =+COUNTIF(M22:AQ22,"CN1") -> 0 | AV22: =+SUM(AR22:AU22) -> 21
J23: 11 | K23: 11 | L23: Thảo Khăm | AG23: X | AH23: X | AI23: X | AJ23: X | AK23: X | AL23: X | AM23: CN | AN23: X | AO23: X | AP23: X | AR23: =COUNTIF(M23:AQ23,"X") -> 9 | AS23: =+COUNTIF(M23:AQ23,"CN") -> 1 | AT23: =COUNTIF(M23:AQ23,"X1") -> 0 | AU23: =+COUNTIF(M23:AQ23,"CN1") -> 0 | AV23: =+SUM(AR23:AU23) -> 10
J24: 12 | K24: 12 | L24: Thảo Hăm | U24: X | V24: X | W24: X | X24: X | AD24: X | AE24: X | AF24: CN | AG24: X | AH24: X | AI24: X | AJ24: X | AL24: X | AM24: CN | AN24: X | AO24: X | AP24: X | AR24: =COUNTIF(M24:AQ24,"X") -> 14 | AS24: =+COUNTIF(M24:AQ24,"CN") -> 2 | AT24: =COUNTIF(M24:AQ24,"X1") -> 0 | AU24: =+COUNTIF(M24:AQ24,"CN1") -> 0 | AV24: =+SUM(AR24:AU24) -> 16
J25: 13 | K25: 13 | L25: Nang Lon | U25: X | V25: X | W25: X | X25: X | AD25: X | AE25: X | AF25: CN | AG25: X | AH25: X | AI25: X | AJ25: X | AL25: X | AM25: CN | AN25: X | AO25: X | AP25: X | AR25: =COUNTIF(M25:AQ25,"X") -> 14 | AS25: =+COUNTIF(M25:AQ25,"CN") -> 2 | AT25: =COUNTIF(M25:AQ25,"X1") -> 0 | AU25: =+COUNTIF(M25:AQ25,"CN1") -> 0 | AV25: =+SUM(AR25:AU25) -> 16
J26: 14 | K26: 14 | L26: Thảo Pheng | U26: X | V26: X | W26: X | X26: X | AE26: X | AF26: CN | AG26: X | AH26: X | AI26: X | AJ26: X | AK26: X | AL26: X | AM26: CN | AN26: X | AO26: X | AP26: X | AR26: =COUNTIF(M26:AQ26,"X") -> 14 | AS26: =+COUNTIF(M26:AQ26,"CN") -> 2 | AT26: =COUNTIF(M26:AQ26,"X1") -> 0 | AU26: =+COUNTIF(M26:AQ26,"CN1") -> 0 | AV26: =+SUM(AR26:AU26) -> 16
J27: 15 | K27: 15 | L27: Thảo kok | U27: X | V27: X | W27: X | X27: X | Y27: CN | AE27: X | AF27: CN | AG27: X | AH27: X | AI27: X | AL27: X | AM27: CN | AN27: X | AO27: X | AP27: X | AR27: =COUNTIF(M27:AQ27,"X") -> 12 | AS27: =+COUNTIF(M27:AQ27,"CN") -> 3 | AT27: =COUNTIF(M27:AQ27,"X1") -> 0 | AU27: =+COUNTIF(M27:AQ27,"CN1") -> 0 | AV27: =+SUM(AR27:AU27) -> 15
A28: =#REF!*#REF!+#REF!*#REF! -> #REF! | B28: =IF(#REF!>15,40,IF(#REF!>12,35,IF(#REF!>9,30,25))) -> #REF! | C28: B | D28: =IF(C28="A",60,IF(C28="B",50,IF(C28="C",45,40))) -> 50 | E28: =D28+B28 -> #REF! | F28: =IF(E28>94,"A",IF(E28>80,"B",IF(E28>69,"C","D"))) -> #REF! | G28: =('[8]LÁT A'!N11+'[8]LÁT D'!N11+'[8]LÁT C'!N11+'[8]LÁT B'!N11)*0.4+'[8]MỦ DÂY'!AH11*0.5 -> 16 | H28: =G28*IF(F28="A",#REF!,IF(F28="B",#REF!,IF(F28="C",#REF!,#REF!))) -> #REF! | I28: =A28+H28 -> #REF! | J28: 16 | K28: 16 | L28: Nàng Sút Chay | Q28: X | V28: X | Y28: CN | AE28: X | AF28: CN | AG28: X | AH28: X | AI28: X | AJ28: X | AL28: X | AM28: CN | AN28: X | AO28: X | AP28: X | AR28: =COUNTIF(M28:AQ28,"X") -> 11 | AS28: =+COUNTIF(M28:AQ28,"CN") -> 3 | AT28: =COUNTIF(M28:AQ28,"X1") -> 0 | AU28: =+COUNTIF(M28:AQ28,"CN1") -> 0 | AV28: =+SUM(AR28:AU28) -> 14 | AX28: =IF(AV28=31,20,IF(AV28>=25,10)) -> FALSE
A29: =#REF!*#REF!+#REF!*#REF! -> #REF! | B29: =IF(#REF!>15,40,IF(#REF!>12,35,IF(#REF!>9,30,25))) -> #REF! | C29: B | D29: =IF(C29="A",60,IF(C29="B",50,IF(C29="C",45,40))) -> 50 | E29: =D29+B29 -> #REF! | F29: =IF(E29>94,"A",IF(E29>80,"B",IF(E29>69,"C","D"))) -> #REF! | G29: =('[8]LÁT A'!N12+'[8]LÁT D'!N12+'[8]LÁT C'!N12+'[8]LÁT B'!N12)*0.4+'[8]MỦ DÂY'!AH12*0.5 -> 0 | H29: =G29*IF(F29="A",#REF!,IF(F29="B",#REF!,IF(F29="C",#REF!,#REF!))) -> #REF! | I29: =A29+H29 -> #REF! | J29: 17 | K29: 17 | L29: Thảo Khăm Phay | V29: X | W29: X | Y29: CN | AE29: X | AF29: CN | AG29: X | AH29: X | AI29: X | AJ29: X | AL29: X | AM29: CN | AN29: X | AO29: X | AP29: X | AR29: =COUNTIF(M29:AQ29,"X") -> 11 | AS29: =+COUNTIF(M29:AQ29,"CN") -> 3 | AT29: =COUNTIF(M29:AQ29,"X1") -> 0 | AU29: =+COUNTIF(M29:AQ29,"CN1") -> 0 | AV29: =+SUM(AR29:AU29) -> 14 | AX29: =IF(AV29=31,20,IF(AV29>=25,10)) -> FALSE
A30: =#REF!*#REF!+#REF!*#REF! -> #REF! | B30: =IF(#REF!>15,40,IF(#REF!>12,35,IF(#REF!>9,30,25))) -> #REF! | C30: B | D30: =IF(C30="A",60,IF(C30="B",50,IF(C30="C",45,40))) -> 50 | E30: =D30+B30 -> #REF! | F30: =IF(E30>94,"A",IF(E30>80,"B",IF(E30>69,"C","D"))) -> #REF! | G30: =('[8]LÁT A'!N13+'[8]LÁT D'!N13+'[8]LÁT C'!N13+'[8]LÁT B'!N13)*0.4+'[8]MỦ DÂY'!AH13*0.5 -> 16 | H30: =G30*IF(F30="A",#REF!,IF(F30="B",#REF!,IF(F30="C",#REF!,#REF!))) -> #REF! | I30: =A30+H30 -> #REF! | J30: 18 | K30: 18 | L30: Thảo Sớm | U30: X | W30: X | X30: X | Y30: CN | AE30: X | AF30: CN | AG30: X | AH30: X | AI30: X | AJ30: X | AL30: X | AM30: CN | AN30: X | AO30: X | AP30: X | AR30: =COUNTIF(M30:AQ30,"X") -> 12 | AS30: =+COUNTIF(M30:AQ30,"CN") -> 3 | AT30: =COUNTIF(M30:AQ30,"X1") -> 0 | AU30: =+COUNTIF(M30:AQ30,"CN1") -> 0 | AV30: =+SUM(AR30:AU30) -> 15 | AX30: =IF(AV30=31,20,IF(AV30>=25,10)) -> FALSE
A31: =#REF!*#REF!+#REF!*#REF! -> #REF! | B31: =IF(#REF!>15,40,IF(#REF!>12,35,IF(#REF!>9,30,25))) -> #REF! | C31: B | D31: =IF(C31="A",60,IF(C31="B",50,IF(C31="C",45,40))) -> 50 | E31: =D31+B31 -> #REF! | F31: =IF(E31>94,"A",IF(E31>80,"B",IF(E31>69,"C","D"))) -> #REF! | G31: =('[8]LÁT A'!N14+'[8]LÁT D'!N14+'[8]LÁT C'!N14+'[8]LÁT B'!N14)*0.4+'[8]MỦ DÂY'!AH14*0.5 -> 24 | H31: =G31*IF(F31="A",#REF!,IF(F31="B",#REF!,IF(F31="C",#REF!,#REF!))) -> #REF! | I31: =A31+H31 -> #REF! | J31: 19 | K31: 19 | L31: Pha Xúc | U31: X | W31: X | X31: X | AE31: X | AF31: CN | AG31: X | AH31: X | AI31: X | AL31: X | AM31: CN | AN31: X | AO31: X | AP31: X | AR31: =COUNTIF(M31:AQ31,"X") -> 11 | AS31: =+COUNTIF(M31:AQ31,"CN") -> 2 | AT31: =COUNTIF(M31:AQ31,"X1") -> 0 | AU31: =+COUNTIF(M31:AQ31,"CN1") -> 0 | AV31: =+SUM(AR31:AU31) -> 13 | AX31: =IF(AV31=31,20,IF(AV31>=25,10)) -> FALSE
A32: =#REF!*#REF!+#REF!*#REF! -> #REF! | B32: =IF(#REF!>15,40,IF(#REF!>12,35,IF(#REF!>9,30,25))) -> #REF! | C32: B | D32: =IF(C32="A",60,IF(C32="B",50,IF(C32="C",45,40))) -> 50 | E32: =D32+B32 -> #REF! | F32: =IF(E32>94,"A",IF(E32>80,"B",IF(E32>69,"C","D"))) -> #REF! | G32: =('[8]LÁT A'!N15+'[8]LÁT D'!N15+'[8]LÁT C'!N15+'[8]LÁT B'!N15)*0.4+'[8]MỦ DÂY'!AH15*0.5 -> 24 | H32: =G32*IF(F32="A",#REF!,IF(F32="B",#REF!,IF(F32="C",#REF!,#REF!))) -> #REF! | I32: =A32+H32 -> #REF! | J32: 20 | K32: 20 | L32: Nàng Phon | R32: CN | T32: X | U32: X | V32: X | X32: X | Y32: CN | AD32: X | AE32: X | AF32: CN | AG32: X | AH32: X | AI32: X | AJ32: X | AL32: X | AM32: CN | AO32: X | AP32: X | AR32: =COUNTIF(M32:AQ32,"X") -> 13 | AS32: =+COUNTIF(M32:AQ32,"CN") -> 4 | AT32: =COUNTIF(M32:AQ32,"X1") -> 0 | AU32: =+COUNTIF(M32:AQ32,"CN1") -> 0 | AV32: =+SUM(AR32:AU32) -> 17 | AX32: =IF(AV32=31,20,IF(AV32>=25,10)) -> FALSE
A33: =#REF!*#REF!+#REF!*#REF! -> #REF! | B33: =IF(#REF!>15,40,IF(#REF!>12,35,IF(#REF!>9,30,25))) -> #REF! | C33: B | D33: =IF(C33="A",60,IF(C33="B",50,IF(C33="C",45,40))) -> 50 | E33: =D33+B33 -> #REF! | F33: =IF(E33>94,"A",IF(E33>80,"B",IF(E33>69,"C","D"))) -> #REF! | G33: =('[8]LÁT A'!N16+'[8]LÁT D'!N16+'[8]LÁT C'!N16+'[8]LÁT B'!N16)*0.4+'[8]MỦ DÂY'!AH16*0.5 -> 0 | H33: =G33*IF(F33="A",#REF!,IF(F33="B",#REF!,IF(F33="C",#REF!,#REF!))) -> #REF! | I33: =A33+H33 -> #REF! | J33: 21 | K33: 21 | L33: Thảo Chăn | T33: X | U33: X | V33: X | W33: X | X33: X | Y33: CN | AD33: X | AF33: CN | AG33: X | AH33: X | AI33: X | AJ33: X | AL33: X | AM33: CN | AN33: X | AO33: X | AP33: X | AR33: =COUNTIF(M33:AQ33,"X") -> 14 | AS33: =+COUNTIF(M33:AQ33,"CN") -> 3 | AT33: =COUNTIF(M33:AQ33,"X1") -> 0 | AU33: =+COUNTIF(M33:AQ33,"CN1") -> 0 | AV33: =+SUM(AR33:AU33) -> 17 | AX33: =IF(AV33=31,20,IF(AV33>=25,10)) -> FALSE
A34: =#REF!*#REF!+#REF!*#REF! -> #REF! | B34: =IF(#REF!>15,40,IF(#REF!>12,35,IF(#REF!>9,30,25))) -> #REF! | C34: B | D34: =IF(C34="A",60,IF(C34="B",50,IF(C34="C",45,40))) -> 50 | E34: =D34+B34 -> #REF! | F34: =IF(E34>94,"A",IF(E34>80,"B",IF(E34>69,"C","D"))) -> #REF! | G34: =('[8]LÁT A'!N17+'[8]LÁT D'!N17+'[8]LÁT C'!N17+'[8]LÁT B'!N17)*0.4+'[8]MỦ DÂY'!AH17*0.5 -> 0 | H34: =G34*IF(F34="A",#REF!,IF(F34="B",#REF!,IF(F34="C",#REF!,#REF!))) -> #REF! | I34: =A34+H34 -> #REF! | J34: 22 | K34: 22 | L34: Thong La | U34: X | V34: X | W34: X | X34: X | Y34: CN | AD34: X | AE34: X | AF34: CN | AG34: X | AH34: X | AI34: X | AJ34: X | AL34: X | AM34: CN | AN34: X | AO34: X | AP34: X | AR34: =COUNTIF(M34:AQ34,"X") -> 14 | AS34: =+COUNTIF(M34:AQ34,"CN") -> 3 | AT34: =COUNTIF(M34:AQ34,"X1") -> 0 | AU34: =+COUNTIF(M34:AQ34,"CN1") -> 0 | AV34: =+SUM(AR34:AU34) -> 17 | AX34: =IF(AV34=31,20,IF(AV34>=25,10)) -> FALSE
A35: =#REF!*#REF!+#REF!*#REF! -> #REF! | B35: =IF(#REF!>15,40,IF(#REF!>12,35,IF(#REF!>9,30,25))) -> #REF! | C35: B | D35: =IF(C35="A",60,IF(C35="B",50,IF(C35="C",45,40))) -> 50 | E35: =D35+B35 -> #REF! | F35: =IF(E35>94,"A",IF(E35>80,"B",IF(E35>69,"C","D"))) -> #REF! | G35: =('[8]LÁT A'!N18+'[8]LÁT D'!N18+'[8]LÁT C'!N18+'[8]LÁT B'!N18)*0.4+'[8]MỦ DÂY'!AH18*0.5 -> 16 | H35: =G35*IF(F35="A",#REF!,IF(F35="B",#REF!,IF(F35="C",#REF!,#REF!))) -> #REF! | I35: =A35+H35 -> #REF! | J35: 23 | K35: 23 | L35: Thảo Cum Pha | V35: X | X35: X | AF35: CN | AG35: X | AI35: X | AJ35: X | AL35: X | AM35: CN | AO35: X | AP35: X | AR35: =COUNTIF(M35:AQ35,"X") -> 8 | AS35: =+COUNTIF(M35:AQ35,"CN") -> 2 | AT35: =COUNTIF(M35:AQ35,"X1") -> 0 | AU35: =+COUNTIF(M35:AQ35,"CN1") -> 0 | AV35: =+SUM(AR35:AU35) -> 10 | AX35: =IF(AV35=31,20,IF(AV35>=25,10)) -> FALSE
A36: =#REF!*#REF!+#REF!*#REF! -> #REF! | B36: =IF(#REF!>15,40,IF(#REF!>12,35,IF(#REF!>9,30,25))) -> #REF! | C36: B | D36: =IF(C36="A",60,IF(C36="B",50,IF(C36="C",45,40))) -> 50 | E36: =D36+B36 -> #REF! | F36: =IF(E36>94,"A",IF(E36>80,"B",IF(E36>69,"C","D"))) -> #REF! | G36: =('[8]LÁT A'!N19+'[8]LÁT D'!N19+'[8]LÁT C'!N19+'[8]LÁT B'!N19)*0.4+'[8]MỦ DÂY'!AH19*0.5 -> 0 | H36: =G36*IF(F36="A",#REF!,IF(F36="B",#REF!,IF(F36="C",#REF!,#REF!))) -> #REF! | I36: =A36+H36 -> #REF! | J36: 24 | K36: 24 | L36: T Ô Vên | W36: X | X36: X | Y36: CN | Z36: X | AD36: X | AE36: X | AF36: CN | AG36: X | AH36: X | AI36: X | AJ36: X | AK36: X | AL36: X | AM36: CN | AN36: X | AO36: X | AP36: X | AR36: =COUNTIF(M36:AQ36,"X") -> 14 | AS36: =+COUNTIF(M36:AQ36,"CN") -> 3 | AT36: =COUNTIF(M36:AQ36,"X1") -> 0 | AU36: =+COUNTIF(M36:AQ36,"CN1") -> 0 | AV36: =+SUM(AR36:AU36) -> 17 | AX36: =IF(AV36=31,20,IF(AV36>=25,10)) -> FALSE
A37: =#REF!*#REF!+#REF!*#REF! -> #REF! | B37: =IF(#REF!>15,40,IF(#REF!>12,35,IF(#REF!>9,30,25))) -> #REF! | C37: B | D37: =IF(C37="A",60,IF(C37="B",50,IF(C37="C",45,40))) -> 50 | E37: =D37+B37 -> #REF! | F37: =IF(E37>94,"A",IF(E37>80,"B",IF(E37>69,"C","D"))) -> #REF! | G37: =('[8]LÁT A'!N12+'[8]LÁT D'!N12+'[8]LÁT C'!N12+'[8]LÁT B'!N12)*0.4+'[8]MỦ DÂY'!AH12*0.5 -> 0 | H37: =G37*IF(F37="A",#REF!,IF(F37="B",#REF!,IF(F37="C",#REF!,#REF!))) -> #REF! | I37: =A37+H37 -> #REF! | J37: 25 | K37: 25 | L37: Nàng Lam | Q37: X | R37: CN | S37: X | T37: X | U37: X | V37: X | W37: X | X37: X | Y37: CN | AC37: X | AD37: X | AF37: CN | AG37: X | AH37: X | AI37: X | AJ37: X | AK37: X | AL37: X | AM37: CN | AN37: X | AO37: X | AP37: X | AR37: =COUNTIF(M37:AQ37,"X") -> 18 | AS37: =+COUNTIF(M37:AQ37,"CN") -> 4 | AT37: =COUNTIF(M37:AQ37,"X1") -> 0 | AU37: =+COUNTIF(M37:AQ37,"CN1") -> 0 | AV37: =+SUM(AR37:AU37) -> 22 | AX37: =IF(AV37=31,20,IF(AV37>=25,10)) -> FALSE
A38: =#REF!*#REF!+#REF!*#REF! -> #REF! | B38: =IF(#REF!>15,40,IF(#REF!>12,35,IF(#REF!>9,30,25))) -> #REF! | C38: B | D38: =IF(C38="A",60,IF(C38="B",50,IF(C38="C",45,40))) -> 50 | E38: =D38+B38 -> #REF! | F38: =IF(E38>94,"A",IF(E38>80,"B",IF(E38>69,"C","D"))) -> #REF! | G38: =('[8]LÁT A'!N13+'[8]LÁT D'!N13+'[8]LÁT C'!N13+'[8]LÁT B'!N13)*0.4+'[8]MỦ DÂY'!AH13*0.5 -> 16 | H38: =G38*IF(F38="A",#REF!,IF(F38="B",#REF!,IF(F38="C",#REF!,#REF!))) -> #REF! | I38: =A38+H38 -> #REF! | J38: 26 | K38: 26 | L38: Nàng Hđao | U38: X | Y38: CN | Z38: X | AA38: X | AD38: X | AE38: X | AF38: CN | AG38: X | AH38: X | AJ38: X | AK38: X | AL38: X | AM38: CN | AN38: X | AO38: X | AP38: X | AR38: =COUNTIF(M38:AQ38,"X") -> 13 | AS38: =+COUNTIF(M38:AQ38,"CN") -> 3 | AT38: =COUNTIF(M38:AQ38,"X1") -> 0 | AU38: =+COUNTIF(M38:AQ38,"CN1") -> 0 | AV38: =+SUM(AR38:AU38) -> 16 | AX38: =IF(AV38=31,20,IF(AV38>=25,10)) -> FALSE
A39: =#REF!*#REF!+#REF!*#REF! -> #REF! | B39: =IF(#REF!>15,40,IF(#REF!>12,35,IF(#REF!>9,30,25))) -> #REF! | C39: B | D39: =IF(C39="A",60,IF(C39="B",50,IF(C39="C",45,40))) -> 50 | E39: =D39+B39 -> #REF! | F39: =IF(E39>94,"A",IF(E39>80,"B",IF(E39>69,"C","D"))) -> #REF! | G39: =('[8]LÁT A'!N14+'[8]LÁT D'!N14+'[8]LÁT C'!N14+'[8]LÁT B'!N14)*0.4+'[8]MỦ DÂY'!AH14*0.5 -> 24 | H39: =G39*IF(F39="A",#REF!,IF(F39="B",#REF!,IF(F39="C",#REF!,#REF!))) -> #REF! | I39: =A39+H39 -> #REF! | J39: 27 | K39: 27 | L39: Thảo Tong | T39: X | V39: X | W39: X | X39: X | Y39: CN | AD39: X | AE39: X | AF39: CN | AG39: X | AH39: X | AI39: X | AJ39: X | AL39: X | AM39: CN | AN39: X | AO39: X | AP39: X | AR39: =COUNTIF(M39:AQ39,"X") -> 14 | AS39: =+COUNTIF(M39:AQ39,"CN") -> 3 | AT39: =COUNTIF(M39:AQ39,"X1") -> 0 | AU39: =+COUNTIF(M39:AQ39,"CN1") -> 0 | AV39: =+SUM(AR39:AU39) -> 17 | AX39: =IF(AV39=31,20,IF(AV39>=25,10)) -> FALSE
A40: =#REF!*#REF!+#REF!*#REF! -> #REF! | B40: =IF(#REF!>15,40,IF(#REF!>12,35,IF(#REF!>9,30,25))) -> #REF! | C40: B | D40: =IF(C40="A",60,IF(C40="B",50,IF(C40="C",45,40))) -> 50 | E40: =D40+B40 -> #REF! | F40: =IF(E40>94,"A",IF(E40>80,"B",IF(E40>69,"C","D"))) -> #REF! | G40: =('[8]LÁT A'!N15+'[8]LÁT D'!N15+'[8]LÁT C'!N15+'[8]LÁT B'!N15)*0.4+'[8]MỦ DÂY'!AH15*0.5 -> 24 | H40: =G40*IF(F40="A",#REF!,IF(F40="B",#REF!,IF(F40="C",#REF!,#REF!))) -> #REF! | I40: =A40+H40 -> #REF! | J40: 28 | K40: 28 | L40: Thảo Khốc | R40: CN | T40: X | U40: X | V40: X | W40: X | X40: X | Y40: CN | Z40: X | AA40: X | AB40: X | AC40: X | AD40: X | AE40: X | AH40: X | AI40: X | AJ40: X | AK40: X | AL40: X | AM40: CN | AN40: X | AO40: X | AP40: X | AR40: =COUNTIF(M40:AQ40,"X") -> 19 | AS40: =+COUNTIF(M40:AQ40,"CN") -> 3 | AT40: =COUNTIF(M40:AQ40,"X1") -> 0 | AU40: =+COUNTIF(M40:AQ40,"CN1") -> 0 | AV40: =+SUM(AR40:AU40) -> 22 | AX40: =IF(AV40=31,20,IF(AV40>=25,10)) -> FALSE
A41: =#REF!*#REF!+#REF!*#REF! -> #REF! | B41: =IF(#REF!>15,40,IF(#REF!>12,35,IF(#REF!>9,30,25))) -> #REF! | C41: B | D41: =IF(C41="A",60,IF(C41="B",50,IF(C41="C",45,40))) -> 50 | E41: =D41+B41 -> #REF! | F41: =IF(E41>94,"A",IF(E41>80,"B",IF(E41>69,"C","D"))) -> #REF! | G41: =('[8]LÁT A'!N16+'[8]LÁT D'!N16+'[8]LÁT C'!N16+'[8]LÁT B'!N16)*0.4+'[8]MỦ DÂY'!AH16*0.5 -> 0 | H41: =G41*IF(F41="A",#REF!,IF(F41="B",#REF!,IF(F41="C",#REF!,#REF!))) -> #REF! | I41: =A41+H41 -> #REF! | J41: 29 | K41: 29 | L41: Thảo Sợt | R41: CN | T41: X | U41: X | V41: X | W41: X | X41: X | Y41: CN | Z41: X | AA41: X | AB41: X | AC41: X | AD41: X | AE41: X | AH41: X | AI41: X | AJ41: X | AK41: X | AL41: X | AM41: CN | AN41: X | AO41: X | AP41: X | AR41: =COUNTIF(M41:AQ41,"X") -> 19 | AS41: =+COUNTIF(M41:AQ41,"CN") -> 3 | AT41: =COUNTIF(M41:AQ41,"X1") -> 0 | AU41: =+COUNTIF(M41:AQ41,"CN1") -> 0 | AV41: =+SUM(AR41:AU41) -> 22 | AX41: =IF(AV41=31,20,IF(AV41>=25,10)) -> FALSE | BK41: =106-23 -> 83
A42: =#REF!*#REF!+#REF!*#REF! -> #REF! | B42: =IF(#REF!>15,40,IF(#REF!>12,35,IF(#REF!>9,30,25))) -> #REF! | C42: B | D42: =IF(C42="A",60,IF(C42="B",50,IF(C42="C",45,40))) -> 50 | E42: =D42+B42 -> #REF! | F42: =IF(E42>94,"A",IF(E42>80,"B",IF(E42>69,"C","D"))) -> #REF! | G42: =('[8]LÁT A'!N17+'[8]LÁT D'!N17+'[8]LÁT C'!N17+'[8]LÁT B'!N17)*0.4+'[8]MỦ DÂY'!AH17*0.5 -> 0 | H42: =G42*IF(F42="A",#REF!,IF(F42="B",#REF!,IF(F42="C",#REF!,#REF!))) -> #REF! | I42: =A42+H42 -> #REF! | J42: 30 | K42: 30 | L42: Thảo Văn | W42: X | Z42: X | AA42: X | AB42: X | AE42: X | AF42: CN | AH42: X | AI42: X | AJ42: X | AK42: X | AL42: X | AM42: CN | AN42: X | AO42: X | AP42: X | AR42: =COUNTIF(M42:AQ42,"X") -> 13 | AS42: =+COUNTIF(M42:AQ42,"CN") -> 2 | AT42: =COUNTIF(M42:AQ42,"X1") -> 0 | AU42: =+COUNTIF(M42:AQ42,"CN1") -> 0 | AV42: =+SUM(AR42:AU42) -> 15 | AX42: =IF(AV42=31,20,IF(AV42>=25,10)) -> FALSE
...

Sheet LƯƠNG TT
B1: CỘNG HÒA DÂN CHỦ NHÂN DÂN LÀO
B2: Hòa Bình - Độc Lập - Dân Chủ - Thống Nhất - Thịnh Vượng
B3: -----o0o-----
A4: CÔNG TY TNHH CỔ PHẦN QUASA - GERUCO LÀO
A5: ĐỘI SX SEPON
B7: BẢNG LƯƠNG CÔNG NHÂN TRỰC TIẾP THÁNG 04 NĂM 2025
A9: STT | C9: Mã số nhân viên | D9: Họ và tên | E9: Chức vụ | F9: Tiền lương | J9: Phụ cấp nhận phần cây | K9: Tổng tiền lương | L9: Thuế TNCN | M9: Trích KP Công Đoàn | N9: Ghi chú
F10: Lương chăm sóc | G10: Lương sản lượng | H10: Phụ cấp khai thác | I10: Phụ cấp khó khăn
A11: TỔ 1 | F11: =SUM(F12:F49) -> 0 | G11: =SUM(G12:G49) -> 12771771 | H11: =SUM(H12:H49) -> 53222332 | I11: =SUM(I12:I49) -> 0 | J11: =SUM(J12:J49) -> 0 | K11: =SUM(K12:K49) -> 65994103 | L11: =SUM(L12:L49) -> 0 | M11: =SUM(M12:M49) -> 0
A12: 1 | B12: 1 | D12: ='Chấm công công nhân'!L13 -> Vắt Đi | E12: CNKT | F12: ='BẢNG LƯƠNG KT'!H17 -> 0 | G12: ='BẢNG LƯƠNG KT'!L17 -> 0 | H12: ='BẢNG LƯƠNG KT'!S17 -> 1263849 | K12: =SUM(F12:J12) -> 1263849
A13: 2 | B13: 2 | D13: ='Chấm công công nhân'!L14 -> Mẹ Leo | E13: CNKT | F13: ='BẢNG LƯƠNG KT'!H18 -> 0 | G13: ='BẢNG LƯƠNG KT'!L18 -> 703160 | H13: ='BẢNG LƯƠNG KT'!S18 -> 1736139 | K13: =SUM(F13:H13) -> 2439299
A14: 3 | B14: 3 | C14: =[9]CNKT!B18 -> 0 | D14: ='Chấm công công nhân'!L15 -> Thảo Ken | E14: CNKT | F14: ='BẢNG LƯƠNG KT'!H19 -> 0 | G14: ='BẢNG LƯƠNG KT'!L19 -> 0 | H14: ='BẢNG LƯƠNG KT'!S19 -> 1314082 | K14: =SUM(F14:H14) -> 1314082
A15: 4 | B15: 4 | C15: =[9]CNKT!B19 -> 0 | D15: ='Chấm công công nhân'!L16 -> Thảo Phút | E15: CNKT | F15: ='BẢNG LƯƠNG KT'!H20 -> 0 | G15: ='BẢNG LƯƠNG KT'!L20 -> 679684 | H15: ='BẢNG LƯƠNG KT'!S20 -> 1836604 | K15: =SUM(F15:H15) -> 2516288
A16: 5 | B16: 5 | C16: =[9]CNKT!B20 -> 0 | D16: ='Chấm công công nhân'!L17 -> Thảo Mằn | E16: CNKT | F16: ='BẢNG LƯƠNG KT'!H21 -> 0 | G16: ='BẢNG LƯƠNG KT'!L21 -> 81290 | H16: ='BẢNG LƯƠNG KT'!S21 -> 1314082 | K16: =SUM(F16:H16) -> 1395372
A17: 6 | B17: 6 | C17: =[9]CNKT!B21 -> 0 | D17: ='Chấm công công nhân'!L18 -> Nàng Chay | E17: CNKT | F17: ='BẢNG LƯƠNG KT'!H22 -> 0 | G17: ='BẢNG LƯƠNG KT'!L22 -> 0 | H17: ='BẢNG LƯƠNG KT'!S22 -> 1364314 | K17: =SUM(F17:H17) -> 1364314
A18: 7 | B18: 7 | C18: =[9]CNKT!B22 -> 0 | D18: ='Chấm công công nhân'!L19 -> Thảo Sắp | E18: CNKT | F18: ='BẢNG LƯƠNG KT'!H23 -> 0 | G18: ='BẢNG LƯƠNG KT'!L23 -> 559991 | H18: ='BẢNG LƯƠNG KT'!S23 -> 1886836 | K18: =SUM(F18:H18) -> 2446827
A19: 8 | B19: 8 | C19: =[9]CNKT!B23 -> 0 | D19: ='Chấm công công nhân'!L20 -> Thảo Say | E19: CNKT | F19: ='BẢNG LƯƠNG KT'!H24 -> 0 | G19: ='BẢNG LƯƠNG KT'!L24 -> 948993 | H19: ='BẢNG LƯƠNG KT'!S24 -> 1836604 | K19: =SUM(F19:H19) -> 2785597
A20: 9 | B20: 9 | C20: =[9]CNKT!B24 -> 0 | D20: ='Chấm công công nhân'!L21 -> Thảo Cợt | E20: CNKT | F20: ='BẢNG LƯƠNG KT'!H25 -> 0 | G20: ='BẢNG LƯƠNG KT'!L25 -> 383500 | H20: ='BẢNG LƯƠNG KT'!S25 -> 1193418 | K20: =SUM(F20:H20) -> 1576918
A21: 10 | B21: 10 | C21: =[9]CNKT!B25 -> 0 | D21: ='Chấm công công nhân'!L22 -> Thảo Hôm | E21: CNKT | F21: ='BẢNG LƯƠNG KT'!H26 -> 0 | G21: ='BẢNG LƯƠNG KT'!L26 -> 795102 | H21: ='BẢNG LƯƠNG KT'!S26 -> 1635675 | K21: =SUM(F21:H21) -> 2430777
A22: 11 | B22: 11 | C22: =[9]CNKT!B26 -> 0 | D22: ='Chấm công công nhân'!L23 -> Thảo Khăm | E22: CNKT | F22: ='BẢNG LƯƠNG KT'!H27 -> 0 | G22: ='BẢNG LƯƠNG KT'!L27 -> 0 | H22: ='BẢNG LƯƠNG KT'!S27 -> 1022522 | K22: =SUM(F22:H22) -> 1022522
A23: 12 | B23: 12 | C23: =[9]CNKT!B27 -> 0 | D23: ='Chấm công công nhân'!L24 -> Thảo Hăm | E23: CNKT | F23: ='BẢNG LƯƠNG KT'!H28 -> 0 | G23: ='BẢNG LƯƠNG KT'!L28 -> 0 | H23: ='BẢNG LƯƠNG KT'!S28 -> 1344115 | K23: =SUM(F23:H23) -> 1344115
A24: 13 | B24: 13 | C24: =[9]CNKT!B28 -> 0 | D24: ='Chấm công công nhân'!L25 -> Nang Lon | E24: CNKT | F24: ='BẢNG LƯƠNG KT'!H29 -> 0 | G24: ='BẢNG LƯƠNG KT'!L29 -> 0 | H24: ='BẢNG LƯƠNG KT'!S29 -> 1344115 | K24: =SUM(F24:H24) -> 1344115
A25: 14 | B25: 14 | C25: =[9]CNKT!B29 -> 0 | D25: ='Chấm công công nhân'!L26 -> Thảo Pheng | E25: CNKT | F25: ='BẢNG LƯƠNG KT'!H30 -> 0 | G25: ='BẢNG LƯƠNG KT'!L30 -> 207290 | H25: ='BẢNG LƯƠNG KT'!S30 -> 1344115 | K25: =SUM(F25:H25) -> 1551405
... A47: 36 | B47: 36 | C47: =[9]CNKT!B51 -> 0 | D47: ='Chấm công công nhân'!L48 -> Thảo Tuỳ | E47: CNKT | F47: ='BẢNG LƯƠNG KT'!H52 -> 0 | G47: ='BẢNG LƯƠNG KT'!L52 -> 743805 | H47: ='BẢNG LƯƠNG KT'!S52 -> 1736139 | K47: =SUM(F47:H47) -> 2479944
A48: 37 | B48: 37 | D48: ='Chấm công công nhân'!L49 -> Thảo Đa Văn | E48: CNKT | F48: ='BẢNG LƯƠNG KT'!H53 -> 0 | G48: ='BẢNG LƯƠNG KT'!L53 -> 0 | H48: ='BẢNG LƯƠNG KT'!S53 -> 942391 | K48: =SUM(F48:H48) -> 942391
A49: 38 | B49: 38 | C49: =[9]CNKT!B52 -> 0 | D49: ='BẢNG LƯƠNG KT'!C54 -> Thảo e | E49: CNK | F49: ='BẢNG LƯƠNG KT'!H54 -> 0 | G49: ='BẢNG LƯƠNG KT'!L54 -> 0 | H49: ='BẢNG LƯƠNG KT'!S54 -> 0 | K49: =SUM(F49:H49) -> 0
A50: TỔ 2 | F50: =SUM(F51:F70) -> 0 | G50: =SUM(G51:G70) -> 5082268 | H50: =SUM(H51:H70) -> 24040670 | K50: =SUM(K51:K70) -> 29122938 | L50: =SUM(L51:L70) -> 0 | M50: =SUM(M51:M70) -> 0 | O50: =K50-#REF!-#REF!-M50 -> #REF!
A51: 38 | B51: 1 | D51: ='Chấm công công nhân'!L51 -> Thảo Xa Đết | E51: CNKT | F51: ='BẢNG LƯƠNG KT'!H56 -> 0 | G51: ='BẢNG LƯƠNG KT'!L56 -> 157630 | H51: ='BẢNG LƯƠNG KT'!S56 -> 1173220 | K51: =SUM(F51:H51) -> 1330850
A52: 39 | B52: 2 | D52: ='Chấm công công nhân'!L52 -> Thảo Sột | E52: CNKT | F52: ='BẢNG LƯƠNG KT'!H57 -> 0 | G52: ='BẢNG LƯƠNG KT'!L57 -> 658935 | H52: ='BẢNG LƯƠNG KT'!S57 -> 1545045 | K52: =SUM(F52:H52) -> 2203980
A53: 40 | B53: 3 | D53: ='Chấm công công nhân'!L53 -> Stoong | E53: CNKT | F53: ='BẢNG LƯƠNG KT'!H58 -> 0 | G53: ='BẢNG LƯƠNG KT'!L58 -> 425999 | H53: ='BẢNG LƯƠNG KT'!S58 -> 1344115 | K53: =SUM(F53:H53) -> 1770114
A54: 41 | B54: 4 | D54: ='Chấm công công nhân'!L54 -> Nàng Phắt | E54: CNKT | F54: ='BẢNG LƯƠNG KT'!H59 -> 0 | G54: ='BẢNG LƯƠNG KT'!L59 -> 407044 | H54: ='BẢNG LƯƠNG KT'!S59 -> 1344115 | K54: =SUM(F54:H54) -> 1751159
A55: 42 | B55: 5 | D55: ='Chấm công công nhân'!L55 -> Nàng May | E55: CNKT | F55: ='BẢNG LƯƠNG KT'!H60 -> 0 | G55: ='BẢNG LƯƠNG KT'!L60 -> 167606 | H55: ='BẢNG LƯƠNG KT'!S60 -> 1394348 | K55: =SUM(F55:H55) -> 1561954
A56: 43 | B56: 6 | D56: ='Chấm công công nhân'!L56 -> Thảo Bênh | E56: CNKT | F56: ='BẢNG LƯƠNG KT'!H61 -> 0 | G56: ='BẢNG LƯƠNG KT'!L61 -> 178374 | H56: ='BẢNG LƯƠNG KT'!S61 -> 1394348 | K56: =SUM(F56:H56) -> 1572722
A57: 44 | B57: 7 | D57: ='Chấm công công nhân'!L57 -> Thảo Đinh | E57: CNKT | F57: ='BẢNG LƯƠNG KT'!H62 -> 0 | G57: ='BẢNG LƯƠNG KT'!L62 -> 533024 | H57: ='BẢNG LƯƠNG KT'!S62 -> 1786372 | K57: =SUM(F57:H57) -> 2319396
A58: 45 | B58: 8 | D58: ='Chấm công công nhân'!L58 -> Thảo Vi | E58: CNKT | F58: ='BẢNG LƯƠNG KT'!H63 -> 0 | G58: ='BẢNG LƯƠNG KT'!L63 -> 201527 | H58: ='BẢNG LƯƠNG KT'!S63 -> 1323917 | K58: =SUM(F58:H58) -> 1525444
A59: 46 | B59: 9 | D59: ='Chấm công công nhân'!L59 -> Thảo Văn | E59: CNKT | F59: ='BẢNG LƯƠNG KT'!H64 -> 0 | G59: ='BẢNG LƯƠNG KT'!L64 -> 482866 | H59: ='BẢNG LƯƠNG KT'!S64 -> 1645510 | K59: =SUM(F59:H59) -> 2128376
A60: 47 | B60: 10 | D60: ='Chấm công công nhân'!L60 -> Nàng Phìn | E60: CNKT | F60: ='BẢNG LƯƠNG KT'!H65 -> 0 | G60: ='BẢNG LƯƠNG KT'!L65 -> 486856 | H60: ='BẢNG LƯƠNG KT'!S65 -> 1494813 | K60: =SUM(F60:H60) -> 1981669
A61: 48 | B61: 11 | D61: ='Chấm công công nhân'!L61 -> Mẹ Sột | E61: CNKT | F61: ='BẢNG LƯƠNG KT'!H66 -> 0 | G61: ='BẢNG LƯƠNG KT'!L66 -> 408695 | H61: ='BẢNG LƯƠNG KT'!S66 -> 1494813 | K61: =SUM(F61:H61) -> 1903508
A62: 49 | B62: 12 | D62: ='Chấm công công nhân'!L62 -> Nàng Heo | E62: CNKT | F62: ='BẢNG LƯƠNG KT'!H67 -> 0 | G62: ='BẢNG LƯƠNG KT'!L67 -> 214049 | H62: ='BẢNG LƯƠNG KT'!S67 -> 1323917 | K62: =SUM(F62:H62) -> 1537966
... A69: 56 | B69: 19 | D69: ='Chấm công công nhân'!L69 -> Nàng Binh | E69: CNKT | F69: ='BẢNG LƯƠNG KT'!H74 -> 0 | G69: ='BẢNG LƯƠNG KT'!L74 -> 0 | H69: ='BẢNG LƯƠNG KT'!S74 -> 640731 | K69: =SUM(F69:H69) -> 640731
...

Sheet BẢNG LƯƠNG KT
A1: 1 | B1: 2 | C1: 3 | D1: 4 | E1: 5 | F1: 6 | G1: 7 | H1: 8 | I1: 9 | J1: 10 | K1: 11 | L1: 12 | M1: 13 | N1: 14 | O1: 15 | P1: 16 | S1: 17
A3: CỘNG HÒA DÂN CHỦ NHÂN DÂN LÀO
A4: Hòa bình - Độc lập - Dân chủ - Thống nhất - Thịnh vượng
A5: -----oOo-----
A6: CÔNG TY TNHH CỔ PHẦN QUASA-GERUCO LÀO
A7: ĐỘI SẢN XUẤT SEPON
A8: BẢNG LƯƠNG KHAI THÁC THÁNG 04 NĂM 2025
C10: Tỷ giá Bath qua Kíp | D10: Tỷ giá Bath qua Kíp | E10: ='BẢNG PHÂN TOÁN'!L14 -> 646.2 | H10: 655.8 | M10: =M16*655.8*46.1 -> 16053394 | N10: =N16*76.9*655.8 -> 5446550.2 | O10: =O16*655.8*76.8 -> 251827.2 | P10: =P16*107.6*655.8 -> 70564.08 | Q10: =Q16*20000 -> 12900000 | R10: =R16*25000 -> 18500000 | U10: ĐVT: kíp
A11: STT | C11: Họ và tên | D11: MSNV | E11: Chức vụ | F11: Ký nhận | G11: LƯƠNG | U11: Tổng lương | V11: Tiền lương còn lại
G12: Lương chăm sóc (25.000 kíp/công) | I12: Lương sản lượng | M12: Lương phụ cấp khai thác | T12: Phụ cấp khó khăn
G13: Công | H13: Thành tiền | I13: Mủ tạp (kg) | J13: Mủ tạp quy khô (kg) | K13: Hạng kỹ thuật | L13: Thành tiền | M13: Phụ cấp ngày công | N13: Phụ cấp chủ nhật | O13: Phụ cấp ngày công vườn cây non | P13: Phụ cấp chủ nhật vườn cây non | Q13: Phụ cấp khó khăn | R13: Phụ cấp nhận phần cây | S13: Thành tiền
A14: ì© | B14: §ˆ²¾¦¾ì¾¸ | C14: §ˆ²¾¦¾¹¸¼©­¾´ | E14: ª¿ÁÎÈ¤ | G14: ¸ñ­¤¾­ | H14: À¯ñ­À¤ò­ | J14: µ¾¤­Õ£ò© ª¾´ºñ©ª¾ Á¹É¤ | K14: §˜­Àªñ¡ ­ò¡ | L14: À¯ñ­À¤ò­ | M14: º÷©Îø­ ¸ñ­¤¾­ | N14: º÷©Îø­ ¸ñ­º¾êò© | O14: º÷©Îø­ ¸ñ­¤¾­ | P14: º÷©Îø­ ¸ñ­º¾êò© | S14: À¯ñ­À¤ò­ | U14: ì¸´À¤ò­ À©õº­ | V14: ì¸´À¤ò­»ñ® | Y14: PC
A15: (1) | C15: (2) | D15: (1) | E15: (1) | F15: (1) | G15: (3) | H15: (4) | I15: (5) | J15: (6) | K15: (7) | L15: (8) | M15: (9) | N15: (10) | O15: (11) | P15: (12) | Q15: (13) | R15: (14) | S15: (15) | T15: (15) | U15: (16)=(4)+(8)+(15) | V15: (17) | Y15: 20000
A16: A | B16: TỔ 1 | G16: =SUM(G17:G54) -> 0 | H16: =SUM(H17:H54) -> 0 | I16: =SUM(I17:I54) -> 6078 | J16: =SUM(J17:J54) -> 3295.671 | K16: =SUM(K17:K54) -> 0 | L16: =SUM(L17:L54) -> 12771771 | M16: =SUM(M17:M54) -> 531 | N16: =SUM(N17:N54) -> 108 | ... V16: =SUM(V17:V54) -> 65994103
A17: 1 | B17: 1 | C17: ='Chấm công công nhân'!L13 -> Vắt Đi | D17: =VLOOKUP(C17,'Mã số NV'!$B$6:$D$53,3,0) -> #N/A | E17: CNKT | H17: =G17*25000 -> 0 | I17: =+VLOOKUP(C17,'Tong hop cong'!C13:S13,17,0) -> 0 | J17: =+VLOOKUP(C17,'Tong hop cong'!C13:U13,19,0) -> 0 | K17: =VLOOKUP(C17,'Tong hop cong'!C13:AA13,25,0) -> A | L17: =VLOOKUP(C17,'1'!$C$14:$L$51,10,0) -> 0 | M17: =+VLOOKUP(C17,'Tong hop cong'!C13:V13,20,0) -> 11 | N17: =+VLOOKUP(C17,'Tong hop cong'!C13:W13,21,0) -> 3 | O17: =+VLOOKUP(C17,'Tong hop cong'!C13:X13,22,0) -> 0 | P17: =+VLOOKUP(C17,'Tong hop cong'!C13:Y13,23,0) -> 0 | Q17: =M17+N17+O17+P17 -> 14 | R17: =+VLOOKUP(C17,'1'!$C$14:$R$50,16,0) -> 20 | S17: =VLOOKUP(C17,'1'!$C$14:$S$51,17,0) -> 1263849 | U17: =H17+L17+S17 -> 1263849 | V17: =U17 -> 1263849 | W17: t1
A18: 2 | B18: 2 | C18: ='Chấm công công nhân'!L14 -> Mẹ Leo | D18: =VLOOKUP(C18,'Mã số NV'!$B$6:$D$53,3,0) -> #N/A | E18: CNKT | H18: =G18*25000 -> 0 | I18: =+VLOOKUP(C18,'Tong hop cong'!C14:S14,17,0) -> 346 | J18: =+VLOOKUP(C18,'Tong hop cong'!C14:U14,19,0) -> 187.61141 | K18: =VLOOKUP(C18,'Tong hop cong'!C14:AA14,25,0) -> B | L18: =VLOOKUP(C18,'1'!$C$14:$L$51,10,0) -> 703160 | M18: =+VLOOKUP(C18,'Tong hop cong'!C14:V14,20,0) -> 19 | N18: =+VLOOKUP(C18,'Tong hop cong'!C14:W14,21,0) -> 4 | O18: =+VLOOKUP(C18,'Tong hop cong'!C14:X14,22,0) -> 0 | P18: =+VLOOKUP(C18,'Tong hop cong'!C14:Y14,23,0) -> 0 | Q18: =M18+N18+O18+P18 -> 23 | R18: =+VLOOKUP(C18,'1'!$C$14:$R$50,16,0) -> 20 | S18: =VLOOKUP(C18,'1'!$C$14:$S$51,17,0) -> 1736139 | U18: =H18+L18+S18 -> 2439299 | V18: =U18 -> 2439299 | W18: t1
A19: 3 | B19: 3 | C19: ='Chấm công công nhân'!L15 -> Thảo Ken | D19: =VLOOKUP(C19,'Mã số NV'!$B$6:$D$53,3,0) -> #N/A | E19: CNKT | H19: =G19*25000 -> 0 | I19: =+VLOOKUP(C19,'Tong hop cong'!C15:S15,17,0) -> 0 | J19: =+VLOOKUP(C19,'Tong hop cong'!C15:U15,19,0) -> 0 | K19: =VLOOKUP(C19,'Tong hop cong'!C15:AA15,25,0) -> A | L19: =VLOOKUP(C19,'1'!$C$14:$L$51,10,0) -> 0 | M19: =+VLOOKUP(C19,'Tong hop cong'!C15:V15,20,0) -> 12 | N19: =+VLOOKUP(C19,'Tong hop cong'!C15:W15,21,0) -> 3 | O19: =+VLOOKUP(C19,'Tong hop cong'!C15:X15,22,0) -> 0 | P19: =+VLOOKUP(C19,'Tong hop cong'!C15:Y15,23,0) -> 0 | Q19: =M19+N19+O19+P19 -> 15 | R19: =+VLOOKUP(C19,'1'!$C$14:$R$50,16,0) -> 20 | S19: =VLOOKUP(C19,'1'!$C$14:$S$51,17,0) -> 1314082 | U19: =H19+L19+S19 -> 1314082 | V19: =U19 -> 1314082 | W19: t1
A20: 4 | B20: 4 | C20: ='Chấm công công nhân'!L16 -> Thảo Phút | D20: =VLOOKUP(C20,'Mã số NV'!$B$6:$D$53,3,0) -> #N/A | E20: CNKT | H20: =G20*25000 -> 0 | I20: =+VLOOKUP(C20,'Tong hop cong'!C16:S16,17,0) -> 318 | J20: =+VLOOKUP(C20,'Tong hop cong'!C16:U16,19,0) -> 172.42899 | K20: =VLOOKUP(C20,'Tong hop cong'!C16:AA16,25,0) -> A | L20: =VLOOKUP(C20,'1'!$C$14:$L$51,10,0) -> 679684 | M20: =+VLOOKUP(C20,'Tong hop cong'!C16:V16,20,0) -> 21 | N20: =+VLOOKUP(C20,'Tong hop cong'!C16:W16,21,0) -> 4 | O20: =+VLOOKUP(C20,'Tong hop cong'!C16:X16,22,0) -> 0 | P20: =+VLOOKUP(C20,'Tong hop cong'!C16:Y16,23,0) -> 0 | Q20: =M20+N20+O20+P20 -> 25 | R20: =+VLOOKUP(C20,'1'!$C$14:$R$50,16,0) -> 20 | S20: =VLOOKUP(C20,'1'!$C$14:$S$51,17,0) -> 1836604 | U20: =H20+L20+S20 -> 2516288 | V20: =U20 -> 2516288 | W20: t1
A21: 5 | B21: 5 | C21: ='Chấm công công nhân'!L17 -> Thảo Mằn | E21: CNKT | H21: =G21*25000 -> 0 | I21: =+VLOOKUP(C21,'Tong hop cong'!C17:S17,17,0) -> 40 | J21: =+VLOOKUP(C21,'Tong hop cong'!C17:U17,19,0) -> 21.689181 | K21: =VLOOKUP(C21,'Tong hop cong'!C17:AA17,25,0) -> B | L21: =VLOOKUP(C21,'1'!$C$14:$L$51,10,0) -> 81290 | M21: =+VLOOKUP(C21,'Tong hop cong'!C17:V17,20,0) -> 12 | N21: =+VLOOKUP(C21,'Tong hop cong'!C17:W17,21,0) -> 3 | O21: =+VLOOKUP(C21,'Tong hop cong'!C17:X17,22,0) -> 0 | P21: =+VLOOKUP(C21,'Tong hop cong'!C17:Y17,23,0) -> 0 | Q21: =M21+N21+O21+P21 -> 15 | R21: =+VLOOKUP(C21,'1'!$C$14:$R$50,16,0) -> 20 | S21: =VLOOKUP(C21,'1'!$C$14:$S$51,17,0) -> 1314082 | U21: =H21+L21+S21 -> 1395372 | V21: =U21 -> 1395372 | W21: t1
