Workbook

Sheet Chuyển đổi công t8
E1: CÔNG TY TNHH CỔ PHẦN QUASA- GERUCO | N1: CỘNG HÒA DÂN CHỦ NHÂN DÂN LÀO
E2: NÔNG TRƯỜNG CAO SU SỐ 3 | N2: Hoà Bình - Độc Lập - Dân Chủ - Thống Nhất - Thịnh Vượng
A5: KHỐI LƯỢNG THỰC TẾ | L5: KHỐI LƯỢNG CHUYỂN ĐỔI | V5: CÔNG CHÊNH LỆCH
A6: 1 | B6: Vườn cây kinh doanh năm 1
A7: 1.1 | B7: Phun cỏ đại trà | C7: ha | D7: =1/3 -> 0.33333333 | I7: =SUM(E8:H13) -> 46.62 | J7: 1 | K7: =ROUND(I7/D7*J7,2) -> 139.86 | L7: Phun cỏ đại trà | M7: ha | N7: =1/4 -> 0.25 | S7: =SUM(O8:R13) -> 46.62 | T7: 1 | U7: =ROUND(S7/N7*T7,2) -> 186.48 | V7: =U7-K7 -> 46.62
E8: A3 | F8: 4.87 | G8: A16 | H8: 6.55 | O8: A3 | P8: 4.87 | Q8: A16 | R8: 6.55
E9: A1 | F9: 3.1 | G9: A18 | H9: 0.93 | O9: A1 | P9: 3.1 | Q9: A18 | R9: 0.93
E10: A5 | F10: 8.55 | G10: A17 | H10: 5.96 | O10: A5 | P10: 8.55 | Q10: A17 | R10: 5.96
E11: A7 | F11: 2.57 | G11: A64 | H11: 2.55 | O11: A7 | P11: 2.57 | Q11: A64 | R11: 2.55
E12: A14 | F12: 5.64 | O12: A14 | P12: 5.64
E13: A15 | F13: 5.9 | O13: A15 | P13: 5.9
A14: 2 | B14: Vườn cây kinh doanh năm 2
A15: 2.1 | B15: Phun cỏ đại trà | C15: ha | D15: =1/3 -> 0.33333333 | I15: =SUM(E16:H27) -> 240.65 | J15: 1 | K15: =ROUND(I15/D15*J15,2) -> 721.95 | L15: Phun cỏ đại trà | M15: ha | N15: =1/4 -> 0.25 | S15: =SUM(O16:R27) -> 240.65 | T15: 1 | U15: =ROUND(S15/N15*T15,2) -> 962.6 | V15: =U15-K15 -> 240.65
E16: D1 | F16: 17.26 | G16: A47 | H16: 8.91 | O16: D1 | P16: 17.26 | Q16: A47 | R16: 8.91
E17: D2 | F17: 4.52 | G17: A48 | H17: 9.14 | O17: D2 | P17: 4.52 | Q17: A48 | R17: 9.14
E18: D4 | F18: 5.45 | G18: A49 | H18: 11.01 | O18: D4 | P18: 5.45 | Q18: A49 | R18: 11.01
E19: D5 | F19: 13.1 | G19: A50 | H19: 19.42 | O19: D5 | P19: 13.1 | Q19: A50 | R19: 19.42
E20: D8 | F20: 11.87 | G20: A51 | H20: 14.56 | O20: D8 | P20: 11.87 | Q20: A51 | R20: 14.56
E21: D9 | F21: 7.85 | G21: A52 | H21: 10.65 | O21: D9 | P21: 7.85 | Q21: A52 | R21: 10.65
E22: A41 | F22: 18.68 | G22: A53 | H22: 8.13 | O22: A41 | P22: 18.68 | Q22: A53 | R22: 8.13
E23: A42 | F23: 16.42 | G23: A54 | H23: 3.5 | O23: A42 | P23: 16.42 | Q23: A54 | R23: 3.5
E24: A43 | F24: 12.74 | G24: A55 | H24: 5.1 | O24: A43 | P24: 12.74 | Q24: A55 | R24: 5.1
E25: A44 | F25: 5.96 | G25: A56 | H25: 10.58 | O25: A44 | P25: 5.96 | Q25: A56 | R25: 10.58
E26: A45 | F26: 7.71 | G26: A57 | H26: 12.9 | O26: A45 | P26: 7.71 | Q26: A57 | R26: 12.9
E27: A46 | F27: 5.19 | O27: A46 | P27: 5.19
A28: 3 | B28: Vườn cây kinh doanh năm 3
A29: 3.1 | B29: Phun cỏ đại trà | C29: ha | D29: =1/3 -> 0.33333333 | I29: =SUM(E30:H35) -> 45.27 | J29: 1 | K29: =ROUND(I29/D29*J29,2) -> 135.81 | L29: Phun cỏ đại trà | M29: ha | N29: =1/4 -> 0.25 | S29: =SUM(O30:R35) -> 45.27 | T29: 1 | U29: =ROUND(S29/N29*T29,2) -> 181.08 | V29: =U29-K29 -> 45.27
E30: B21 | F30: 2.88 | G30: B23 | H30: 5.3 | O30: B21 | P30: 2.88 | Q30: B23 | R30: 5.3
E31: B33 | F31: 7.46 | G31: B39 | H31: 1.56 | O31: B33 | P31: 7.46 | Q31: B39 | R31: 1.56
E32: B35 | F32: 3.2 | G32: B26 | H32: 6.57 | O32: B35 | P32: 3.2 | Q32: B26 | R32: 6.57
E33: B24 | F33: 6.7 | G33: B32 | H33: 3 | O33: B24 | P33: 6.7 | Q33: B32 | R33: 3
E34: B34 | F34: 6 | O34: B34 | P34: 6
E35: B40 | F35: 2.6 | O35: B40 | P35: 2.6
A36: 3.2 | B36: Phát chồi đại trà | C36: ha | D36: =1/7 -> 0.14285714 | L36: Phát chồi đại trà | M36: ha | N36: =1/7 -> 0.14285714 | S36: =SUM(O37:R50) -> 165.27 | T36: 1 | U36: =ROUND(S36/N36*T36,2) -> 1156.89 | V36: =U36-K36 -> 1156.89
O37: B1 | P37: 9.9 | Q37: B22 | R37: 4.33
O38: B2 | P38: 15.01 | Q38: B23 | R38: 5.3
O39: B3 | P39: 7.6 | Q39: B24 | R39: 6.7
O40: B6 | P40: 6.7 | Q40: B26 | R40: 6.57
O41: B7 | P41: 4.5 | Q41: B31 | R41: 3.25
O42: B42 | P42: 9.4 | Q42: B21 | R42: 2.88
...

Sheet Mủ CN (TT)
B1: CỘNG HÒA DÂN CHỦ NHÂN DÂN LÀO
B2: Hòa bình - Độc lập - Dân chủ - Thống nhất - Thịnh vượng
B3: ----- o0o-----
B4: CÔNG TY TNHH CP QUASA - GERUCO LÀO
B5: NÔNG TRƯỜNG CAO SU SỐ 3
A7: BẢNG THEO DÕI SẢN LƯỢNG MỦ TẠP CÔNG NHÂN NÔNG TRƯỜNG THÁNG 04/2025
A9: Stt | B9: Stt | C9: Họ và tên | D9: Bộ phận | E9: Ngày | AI9: Tổng mủ tạp | AJ9: DRC bình quân | AK9: Mủ tạp quy khô DRC công nhân | AL9: Xếp hạng kỷ thuật | AM9: Ký tên CN
E10: 1 | F10: 2 | G10: 3 | H10: 4 | I10: 5 | J10: 6 | K10: 7 | L10: 8 | M10: 9 | N10: 10 | O10: 11 | P10: 12 | Q10: 13 | R10: 14 | S10: 15 | T10: 16 | U10: 17 | V10: 18 | W10: 19 | X10: 20 | Y10: 21 | Z10: 22 | AA10: 23 | AB10: 24 | AC10: 25 | AD10: 26 | AE10: 27 | AF10: 28 | AG10: 29 | AH10: 30 | AR10: Sản lương | AS10: Qui khô | AT10: DRC
A11: A | B11: ĐỘI 1 KX | E11: =+SUBTOTAL(9,E12:E45) -> 0 | F11: =+SUBTOTAL(9,F12:F45) -> 0 | G11: =+SUBTOTAL(9,G12:G45) -> 0 | H11: =+SUBTOTAL(9,H12:H45) -> 0 | I11: =+SUBTOTAL(9,I12:I45) -> 0 | J11: =+SUBTOTAL(9,J12:J45) -> 0 | K11: =+SUBTOTAL(9,K12:K45) -> 0 | L11: =+SUBTOTAL(9,L12:L45) -> 0 | ... AH11: =+SUBTOTAL(9,AH12:AH45) -> 0 | AI11: =SUM(AI12:AI45) -> 879 | AJ11: =+AJ12 -> 56.836924 | AK11: =+SUM(AK12:AK45) -> 499.59656 | AR11: 879 | AS11: 499.59656 | AT11: =+AS11/AR11 -> 0.56836924
A12: 1 | B12: 1 | C12: A Xiu | D12: Đội 1 | AD12: 0 | AE12: 0 | AI12: =+SUM(E12:AH12) -> 0 | AJ12: =$AT$11*100 -> 56.836924 | AK12: =+AI12*AJ12/100 -> 0 | AL12: A | AS12: =+AK11-AS11 -> 0
A13: 2 | B13: 2 | C13: A Nhợp | D13: Đội 1 | AD13: 33 | AE13: 28 | AI13: =+SUM(E13:AH13) -> 61 | AJ13: =$AT$11*100 -> 56.836924 | AK13: =+AI13*AJ13/100 -> 34.670523 | AL13: A
A14: 3 | B14: 3 | C14: A Chan | D14: Đội 1 | AD14: 6 | AE14: 0 | AI14: =+SUM(E14:AH14) -> 6 | AJ14: =$AT$11*100 -> 56.836924 | AK14: =+AI14*AJ14/100 -> 3.4102154 | AL14: A | AO14: A | AP14: =+COUNTIF($AL$12:$AL$45,"A") -> 34
A15: 4 | B15: 4 | C15: Phò Đùa | D15: Đội 1 | AD15: 18 | AE15: 7 | AI15: =+SUM(E15:AH15) -> 25 | AJ15: =$AT$11*100 -> 56.836924 | AK15: =+AI15*AJ15/100 -> 14.209231 | AL15: A | AO15: B | AP15: =+COUNTIF($AL$12:$AL$45,"B") -> 0
A16: 5 | B16: 5 | C16: Xúc | D16: Đội 1 | AD16: 0 | AE16: 0 | AI16: =+SUM(E16:AH16) -> 0 | AJ16: =$AT$11*100 -> 56.836924 | AK16: =+AI16*AJ16/100 -> 0 | AL16: A | AO16: C | AP16: =+COUNTIF($AL$12:$AL$45,"C") -> 0
A17: 6 | B17: 6 | C17: Phơ | D17: Đội 1 | AD17: 0 | AE17: 0 | AI17: =+SUM(E17:AH17) -> 0 | AJ17: =$AT$11*100 -> 56.836924 | AK17: =+AI17*AJ17/100 -> 0 | AL17: A
A18: 7 | B18: 7 | C18: A Phơ | D18: Đội 1 | AD18: 20 | AE18: 20 | AI18: =+SUM(E18:AH18) -> 40 | AJ18: =$AT$11*100 -> 56.836924 | AK18: =+AI18*AJ18/100 -> 22.734769 | AL18: A
A19: 8 | B19: 8 | C19: Nang Xây | D19: Đội 1 | AD19: 10 | AE19: 10 | AI19: =+SUM(E19:AH19) -> 20 | AJ19: =$AT$11*100 -> 56.836924 | AK19: =+AI19*AJ19/100 -> 11.367385 | AL19: A
A20: 9 | B20: 9 | C20: Nang Sun | D20: Đội 1 | AD20: 11 | AE20: 0 | AI20: =+SUM(E20:AH20) -> 11 | AJ20: =$AT$11*100 -> 56.836924 | AK20: =+AI20*AJ20/100 -> 6.2520616 | AL20: A
A21: 10 | B21: 10 | C21: Thảo Ben | D21: Đội 1 | AD21: 6 | AE21: 0 | AI21: =+SUM(E21:AH21) -> 6 | AJ21: =$AT$11*100 -> 56.836924 | AK21: =+AI21*AJ21/100 -> 3.4102154 | AL21: A
A22: 11 | B22: 11 | C22: Nang Nhăn | D22: Đội 1 | AD22: 12 | AE22: 12 | AI22: =+SUM(E22:AH22) -> 24 | AJ22: =$AT$11*100 -> 56.836924 | AK22: =+AI22*AJ22/100 -> 13.640862 | AL22: A
A23: 12 | B23: 12 | C23: Phò Thít | D23: Đội 1 | AD23: 15 | AE23: 45 | AI23: =+SUM(E23:AH23) -> 60 | AJ23: =$AT$11*100 -> 56.836924 | AK23: =+AI23*AJ23/100 -> 34.102154 | AL23: A
A24: 13 | B24: 13 | C24: A Bợp | D24: Đội 1 | AD24: 26 | AE24: 14 | AI24: =+SUM(E24:AH24) -> 40 | AJ24: =$AT$11*100 -> 56.836924 | AK24: =+AI24*AJ24/100 -> 22.734769 | AL24: A
A25: 14 | B25: 14 | C25: A Cơ | D25: Đội 1 | AD25: 0 | AE25: 0 | AI25: =+SUM(E25:AH25) -> 0 | AJ25: =$AT$11*100 -> 56.836924 | AK25: =+AI25*AJ25/100 -> 0 | AL25: A
A26: 15 | B26: 15 | C26: Xa Vạt Đi | D26: Đội 1 | AD26: 15 | AE26: 20 | AI26: =+SUM(E26:AH26) -> 35 | AJ26: =$AT$11*100 -> 56.836924 | AK26: =+AI26*AJ26/100 -> 19.892923 | AL26: A
A27: 16 | B27: 16 | C27: Nguyễn Thi Thanh Trà | D27: Đội 1 | AD27: 35 | AE27: 62 | AI27: =+SUM(E27:AH27) -> 97 | AJ27: =$AT$11*100 -> 56.836924 | AK27: =+AI27*AJ27/100 -> 55.131816 | AL27: A
A28: 17 | B28: 17 | C28: A Han | D28: Đội 1 | AD28: 0 | AE28: 7 | AI28: =+SUM(E28:AH28) -> 7 | AJ28: =$AT$11*100 -> 56.836924 | AK28: =+AI28*AJ28/100 -> 3.9785846 | AL28: A
... A45: 34 | B45: 34 | C45: Thảo Xen | D45: Đội 1 | AD45: 18 | AE45: 27 | AI45: =+SUM(E45:AH45) -> 45 | AJ45: =$AT$11*100 -> 56.836924 | AK45: =+AI45*AJ45/100 -> 25.576616 | AL45: A
A46: B | B46: Đội 1 XT | E46: =+SUBTOTAL(9,E47:E89) -> 0 | F46: =+SUBTOTAL(9,F47:F89) -> 0 | G46: =+SUBTOTAL(9,G47:G89) -> 0 | H46: =+SUBTOTAL(9,H47:H89) -> 0 | I46: =+SUBTOTAL(9,I47:I89) -> 0 | J46: =+SUBTOTAL(9,J47:J89) -> 0 | K46: =+SUBTOTAL(9,K47:K89) -> 0 | L46: =+SUBTOTAL(9,L47:L89) -> 0 | ... AI46: =+SUBTOTAL(9,AI47:AI89) -> 7475 | AJ46: =+AJ47 -> 57.563979 | AK46: =+SUBTOTAL(9,AK47:AK89) -> 4302.9074 | AR46: 7475 | AS46: 4302.9074 | AT46: =+AS46/AR46 -> 0.57563979 | BC46: 45.786725
A47: 35 | B47: 1 | C47: Nàng Ăn | D47: Đội 1 | AD47: 39 | AE47: 43 | AF47: 115 | AG47: 46 | AI47: =+SUM(E47:AH47) -> 243 | AJ47: =+$AT$46*100 -> 57.563979 | AK47: =+AI47*$AT$46 -> 139.88047 | AL47: A
A48: 36 | B48: 2 | C48: Thảo Ơ | D48: Đội 1 | AD48: 39 | AE48: 43 | AF48: 115 | AG48: 66 | AI48: =+SUM(E48:AH48) -> 263 | AJ48: =+$AT$46*100 -> 57.563979 | AK48: =+AI48*$AT$46 -> 151.39327 | AL48: A
A49: 37 | B49: 3 | C49: Thảo Ui | D49: Đội 1 | AD49: 38 | AE49: 42 | AF49: 115 | AG49: 53 | AI49: =+SUM(E49:AH49) -> 248 | AJ49: =+$AT$46*100 -> 57.563979 | AK49: =+AI49*$AT$46 -> 142.75867 | AL49: A
A50: 38 | B50: 4 | C50: Thảo Tin | D50: Đội 1 | AD50: 45 | AE50: 27 | AF50: 80 | AG50: 94 | AI50: =+SUM(E50:AH50) -> 246 | AJ50: =+$AT$46*100 -> 57.563979 | AK50: =+AI50*$AT$46 -> 141.60739 | AL50: A | AO50: A | AP50: =+COUNTIF($AL$47:$AL$89,"A") -> 43
A51: 39 | B51: 5 | C51: Nàng Xái | D51: Đội 1 | AD51: 45 | AE51: 27 | AF51: 86 | AG51: 68 | AI51: =+SUM(E51:AH51) -> 226 | AJ51: =+$AT$46*100 -> 57.563979 | AK51: =+AI51*$AT$46 -> 130.09459 | AL51: A | AO51: B | AP51: =+COUNTIF($AL$47:$AL$89,"B") -> 0
A52: 40 | B52: 6 | C52: Thảo Phôn Xay | D52: Đội 1 | AD52: 32 | AE52: 32 | AF52: 96 | AG52: 70 | AI52: =+SUM(E52:AH52) -> 230 | AJ52: =+$AT$46*100 -> 57.563979 | AK52: =+AI52*$AT$46 -> 132.39715 | AL52: A | AO52: C | AP52: =+COUNTIF($AL$47:$AL$89,"C") -> 0
A53: 41 | B53: 7 | C53: Nàng Phêng | D53: Đội 1 | AD53: 30 | AE53: 30 | AF53: 212 | AG53: 65 | AI53: =+SUM(E53:AH53) -> 337 | AJ53: =+$AT$46*100 -> 57.563979 | AK53: =+AI53*$AT$46 -> 193.99061 | AL53: A
A54: 42 | B54: 8 | C54: Thảo Phíc | D54: Đội 1 | AD54: 30 | AE54: 31 | AF54: 91 | AG54: 69 | AI54: =+SUM(E54:AH54) -> 221 | AJ54: =+$AT$46*100 -> 57.563979 | AK54: =+AI54*$AT$46 -> 127.21639 | AL54: A | AR54: =+MAX(AI51:AI79) -> 337
A55: 43 | B55: 9 | C55: Nàng Chai | D55: Đội 1 | AD55: 31 | AE55: 31 | AF55: 88 | AG55: 73 | AI55: =+SUM(E55:AH55) -> 223 | AJ55: =+$AT$46*100 -> 57.563979 | AK55: =+AI55*$AT$46 -> 128.36767 | AL55: A
A56: 44 | B56: 10 | C56: Nàng Xanh | D56: Đội 1 | AD56: 40 | AE56: 40 | AF56: 89 | AG56: 76 | AI56: =+SUM(E56:AH56) -> 245 | AJ56: =+$AT$46*100 -> 57.563979 | AK56: =+AI56*$AT$46 -> 141.03175 | AL56: A
A57: 45 | B57: 11 | C57: Thảo Xượm | D57: Đội 1 | AD57: 35 | AE57: 35 | AF57: 186 | AG57: 79 | AI57: =+SUM(E57:AH57) -> 335 | AJ57: =+$AT$46*100 -> 57.563979 | AK57: =+AI57*$AT$46 -> 192.83933 | AL57: A
A58: 46 | B58: 12 | C58: Thảo Tích | D58: Đội 1 | AD58: 27 | AE58: 27 | AF58: 66 | AG58: 105 | AI58: =+SUM(E58:AH58) -> 225 | AJ58: =+$AT$46*100 -> 57.563979 | AK58: =+AI58*$AT$46 -> 129.51895 | AL58: A
...

Sheet Serum
A1: CỘNG HÒA DÂN CHỦ NHÂN DÂN LÀO
A2: Hòa bình - Độc lập - Dân chủ - Thống nhất - Thịnh vượng
A3: ----- o0o-----
A4: CÔNG TY TNHH CP QUASA - GERUCO LÀO
A5: NÔNG TRƯỜNG CAO SU SỐ 3
A7: BẢNG THEO DÕI SẢN LƯỢNG MỦ SERUM CÔNG NHÂN NÔNG TRƯỜNG THÁNG 02/2025
A9: Stt | B9: Đội | C9: Ngày đi công | AE9: Tổng mủ serum | AF9: DRC (%) | AG9: Mủ serum quy khô | AH9: Ký tên
C10: 1 | D10: 2 | E10: 3 | F10: 4 | G10: 5 | H10: 6 | I10: 7 | J10: 8 | K10: 9 | L10: 10 | M10: 11 | N10: 12 | O10: 13 | P10: 14 | Q10: 15 | R10: 16 | S10: 17 | T10: 18 | U10: 19 | V10: 20 | W10: 21 | X10: 22 | Y10: 23 | Z10: 24 | AA10: 25 | AB10: 26 | AC10: 27 | AD10: 2/3
A11: 1 | B11: Đội 1 KX | AE11: =+SUM(C11:AD11) -> 0
A12: 2 | B12: Đội 2 TP | AE12: =+SUM(C12:AD12) -> 0
A13: 3 | B13: Đội 3 | AE13: =+SUM(C13:AD13) -> 0
A14: Tổng cộng | C14: =SUM(C13:C13) -> 0 | D14: =SUM(D13:D13) -> 0 | E14: =SUM(E13:E13) -> 0 | F14: =SUM(F13:F13) -> 0 | G14: =SUM(G13:G13) -> 0 | H14: =SUM(H13:H13) -> 0 | I14: =SUM(I13:I13) -> 0 | J14: =SUM(J13:J13) -> 0 | ... AD14: =SUM(AD13:AD13) -> 0 | AE14: =SUM(AE11:AE13) -> 0 | AG14: =SUM(AG11:AG13) -> 0
AC15: Huyện Noong, ngày 28 tháng 02 năm 2025
A16: TỔNG GIÁM ĐỐC | D16: PHÒNG TC - HC | J16: PHÒNG KT- NN | P16: GIÁM ĐỐC NT | U16: TL. TC - KT | Z16: TL.KH -NN | AE16: NGƯỜI LẬP

Sheet Mủ dây
B1: CỘNG HÒA DÂN CHỦ NHÂN DÂN LÀO
B2: Hòa bình - Độc lập - Dân chủ - Thống nhất - Thịnh vượng
B3: ----- o0o-----
B4: CÔNG TY TNHH CP QUASA - GERUCO LÀO
B5: NÔNG TRƯỜNG CAO SU SỐ 3
A7: BẢNG THEO DÕI SẢN LƯỢNG MỦ DÂY CÔNG NHÂN NÔNG TRƯỜNG THÁNG 04/2025
A9: Stt | C9: Họ và tên | D9: Bộ phận | E9: Ngày đi cạo | AI9: Tổng mủ dây | AJ9: Ký tên CN
E10: 1 | F10: 2 | G10: 3 | H10: 4 | I10: 5 | J10: 6 | K10: 7 | L10: 8 | M10: 9 | N10: 10 | O10: 11 | P10: 12 | Q10: 13 | R10: 14 | S10: 15 | T10: 16 | U10: 17 | V10: 18 | W10: 19 | X10: 20 | Y10: 21 | Z10: 22 | AA10: 23 | AB10: 24 | AC10: 25 | AD10: 26 | AE10: 27 | AF10: 28 | AG10: 29 | AH10: 30 | AO10: Sản lương | AP10: Qui khô | AQ10: DRC
A11: A | B11: ĐỘI 1 KX | E11: =SUM(E12:E45) -> 0 | F11: =SUM(F12:F45) -> 0 | G11: =SUM(G12:G45) -> 0 | H11: =SUM(H12:H45) -> 0 | I11: =SUM(I12:I45) -> 0 | J11: =SUM(J12:J45) -> 0 | K11: =SUM(K12:K45) -> 0 | L11: =SUM(L12:L45) -> 0 | ... AI11: =SUM(AI12:AI45) -> 235 | AO11: 93698 | AP11: 39822.7 | AQ11: =+AP11/AO11 -> 0.42501121
A12: 1 | B12: 1 | C12: A Xiu | D12: Đội 1 | AI12: =+SUM(E12:AH12) -> 0 | AP12: =+#REF!-AP11 -> #REF!
A13: 2 | B13: 2 | C13: A Nhợp | D13: Đội 1 | AE13: 8 | AI13: =+SUM(E13:AH13) -> 8
A14: 3 | B14: 3 | C14: A Chan | D14: Đội 1 | AE14: 6 | AI14: =+SUM(E14:AH14) -> 6
A15: 4 | B15: 4 | C15: Phò Đùa | D15: Đội 1 | AE15: 5 | AI15: =+SUM(E15:AH15) -> 5
A16: 5 | B16: 5 | C16: Xúc | D16: Đội 1 | AE16: 4 | AI16: =+SUM(E16:AH16) -> 4
A17: 6 | B17: 6 | C17: Phơ | D17: Đội 1 | AE17: 16 | AI17: =+SUM(E17:AH17) -> 16
A18: 7 | B18: 7 | C18: A Phơ | D18: Đội 1 | AE18: 15 | AI18: =+SUM(E18:AH18) -> 15
A19: 8 | B19: 8 | C19: Nang Xây | D19: Đội 1 | AE19: 8 | AI19: =+SUM(E19:AH19) -> 8
A20: 9 | B20: 9 | C20: Nang Sun | D20: Đội 1 | AE20: 9 | AI20: =+SUM(E20:AH20) -> 9
A21: 10 | B21: 10 | C21: Thảo Ben | D21: Đội 1 | AE21: 3 | AI21: =+SUM(E21:AH21) -> 3
A22: 11 | B22: 11 | C22: Nang Nhăn | D22: Đội 1 | AE22: 10 | AI22: =+SUM(E22:AH22) -> 10
A23: 12 | B23: 12 | C23: Phò Thít | D23: Đội 1 | AE23: 6 | AI23: =+SUM(E23:AH23) -> 6
A24: 13 | B24: 13 | C24: A Bợp | D24: Đội 1 | AE24: 5 | AI24: =+SUM(E24:AH24) -> 5
... A42: 31 | B42: 31 | C42: Nang Bun Ten | D42: Đội 1 | AE42: 7 | AI42: =+SUM(E42:AH42) -> 7
A43: 32 | B43: 32 | C43: Cha Lơ | D43: Đội 1 | AI43: =+SUM(E43:AH43) -> 0
A44: 33 | B44: 33 | C44: Dã Lay | D44: Đội 1 | AE44: 3 | AI44: =+SUM(E44:AH44) -> 3
A45: 34 | B45: 34 | C45: Thảo Xen | D45: Đội 1 | AE45: 4 | AI45: =+SUM(E45:AH45) -> 4
A46: C | B46: ĐỘI 1 KX | E46: =SUM(E47:E61) -> 0 | F46: =SUM(F47:F61) -> 0 | G46: =SUM(G47:G61) -> 0 | H46: =SUM(H47:H61) -> 0 | I46: =SUM(I47:I61) -> 0 | J46: =SUM(J47:J61) -> 0 | K46: =SUM(K47:K61) -> 0 | L46: =SUM(L47:L61) -> 0 | ... AI46: =SUM(AI47:AI61) -> 145 | AO46: 229163 | AP46: 100576.28 | AQ46: =+AP46/AO46 -> 0.43888532 | BA46: 42.747144
A47: 35 | B47: 1 | C47: Nàng Ăn | D47: Đội 1 | AF47: 5 | AI47: =+SUM(E47:AH47) -> 5
A48: 36 | B48: 2 | C48: Thảo Ơ | D48: Đội 1 | AF48: 7 | AI48: =+SUM(E48:AH48) -> 7
A49: 37 | B49: 3 | C49: Thảo Ui | D49: Đội 1 | AF49: 9 | AI49: =+SUM(E49:AH49) -> 9
A50: 38 | B50: 5 | C50: Thảo Tin | D50: Đội 1 | AF50: 10 | AI50: =+SUM(E50:AH50) -> 10
A51: 39 | B51: 6 | C51: Nàng Xái | D51: Đội 1 | AF51: 15 | AI51: =+SUM(E51:AH51) -> 15
A52: 40 | B52: 7 | C52: Thảo Phôn Xay | D52: Đội 1 | AF52: 13 | AI52: =+SUM(E52:AH52) -> 13
A53: 41 | B53: 8 | C53: Nàng Phêng | D53: Đội 1 | AF53: 7 | AI53: =+SUM(E53:AH53) -> 7
A54: 42 | B54: 9 | C54: Thảo Phíc | D54: Đội 1 | AF54: 9 | AI54: =+SUM(E54:AH54) -> 9
A55: 43 | B55: 10 | C55: Nàng Chai | D55: Đội 1 | AF55: 10 | AI55: =+SUM(E55:AH55) -> 10
A56: 44 | B56: 11 | C56: Nàng Xanh | D56: Đội 1 | AF56: 11 | AI56: =+SUM(E56:AH56) -> 11
A57: 45 | B57: 12 | C57: Thảo Xượm | D57: Đội 1 | AF57: 14 | AI57: =+SUM(E57:AH57) -> 14
A58: 46 | B58: 13 | C58: Thảo Tích | D58: Đội 1 | AF58: 13 | AI58: =+SUM(E58:AH58) -> 13
... A61: 49 | B61: 16 | C61: Nàng Út | D61: Đội 1 | AF61: 7 | AI61: =+SUM(E61:AH61) -> 7
...

Sheet Chấm công CN
A1: CỘNG HÒA DÂN CHỦ NHÂN DÂN LÀO
A2: Hòa bình - Độc lập - Dân chủ - Thống nhất - Thịnh vượng
A3: ----- o0o-----
A4: CÔNG TY TNHH CP QUASA - GERUCO LÀO
A5: NÔNG TRƯỜNG CAO SU SỐ 3
A8: BẢNG CHẤM CÔNG CÔNG NHÂN KHAI THÁC NÔNG TRƯỜNG 3 THÁNG 04 NĂM 2025
A10: Stt | B10: Họ và tên | C10: MSNV | D10: Bội phận | E10: Ngày đi làm | AI10: Ngày công đi cao (x) | AJ10: Ngày chủ nhật ( cn) | AK10: Ngày cạo đúp bình thường ( D) | AL10: Ngày cạo đúp chủ nhật | AM10: Tổng công | AP10: Ký tên CN
E11: 1 | F11: 2 | G11: 3 | H11: 4 | I11: 5 | J11: 6 | K11: 7 | L11: 8 | M11: 9 | N11: 10 | O11: 11 | P11: 12 | Q11: 13 | R11: 14 | S11: 15 | T11: 16 | U11: 17 | V11: 18 | W11: 19 | X11: 20 | Y11: 21 | Z11: 22 | AA11: 23 | AB11: 24 | AC11: 25 | AD11: 26 | AE11: 27 | AF11: 28 | AG11: 29 | AH11: 30
A12: 1 | B12: A Xiu | D12: Đội 1 | Q12: cn | V12: x | W12: x | X12: cn | Y12: x | AI12: =+COUNTIF(E12:AH12,"X") -> 3 | AJ12: =+COUNTIF(E12:AH12,"CN") -> 2 | AK12: =+COUNTIF(E12:AH12,"D") -> 0 | AL12: =+COUNTIF(E12:AH12,"DCN") -> 0 | AM12: =+SUM(AI12:AL12) -> 5 | AN12: =+VLOOKUP(C12,[1]Sheet1!$D$9:$E$122,2,0) -> #N/A | AO12: =+IF(AN12=B12,"0","1") -> #N/A | AR12: =+VLOOKUP(B12,'Hổ trợ xăng CN'!C10:E40,3,0) -> #REF!
A13: 2 | B13: A Nhợp | D13: Đội 1 | Q13: cn | U13: x | V13: x | W13: x | X13: cn | Y13: x | Z13: x | AA13: x | AB13: x | AC13: x | AD13: x | AE13: cn | AF13: x | AG13: x | AH13: x | AI13: =+COUNTIF(E13:AH13,"X") -> 12 | AJ13: =+COUNTIF(E13:AH13,"CN") -> 3 | AK13: =+COUNTIF(E13:AH13,"D") -> 0 | AL13: =+COUNTIF(E13:AH13,"DCN") -> 0 | AM13: =+SUM(AI13:AL13) -> 15 | AN13: =+VLOOKUP(C13,[1]Sheet1!$D$9:$E$122,2,0) -> #N/A | AO13: =+IF(AN13=B13,"0","1") -> #N/A | AR13: =+VLOOKUP(B13,'Hổ trợ xăng CN'!C11:E41,3,0) -> #N/A
A14: 3 | B14: A Chan | D14: Đội 1 | Q14: cn | U14: x | V14: x | W14: x | X14: cn | Y14: x | Z14: x | AA14: x | AB14: x | AC14: x | AD14: x | AE14: cn | AF14: x | AG14: x | AH14: x | AI14: =+COUNTIF(E14:AH14,"X") -> 12 | AJ14: =+COUNTIF(E14:AH14,"CN") -> 3 | AK14: =+COUNTIF(E14:AH14,"D") -> 0 | AL14: =+COUNTIF(E14:AH14,"DCN") -> 0 | AM14: =+SUM(AI14:AL14) -> 15 | AN14: =+VLOOKUP(C14,[1]Sheet1!$D$9:$E$122,2,0) -> #N/A | AO14: =+IF(AN14=B14,"0","1") -> #N/A | AR14: =+VLOOKUP(B14,'Hổ trợ xăng CN'!C12:E42,3,0) -> #N/A
A15: 4 | B15: Phò Đùa | D15: Đội 1 | Q15: cn | U15: x | V15: x | W15: x | X15: cn | Y15: x | Z15: x | AA15: x | AB15: x | AD15: x | AE15: cn | AF15: x | AH15: x | AI15: =+COUNTIF(E15:AH15,"X") -> 10 | AJ15: =+COUNTIF(E15:AH15,"CN") -> 3 | AK15: =+COUNTIF(E15:AH15,"D") -> 0 | AL15: =+COUNTIF(E15:AH15,"DCN") -> 0 | AM15: =+SUM(AI15:AL15) -> 13 | AN15: =+VLOOKUP(C15,[1]Sheet1!$D$9:$E$122,2,0) -> #N/A | AO15: =+IF(AN15=B15,"0","1") -> #N/A
A16: 5 | B16: Xúc | D16: Đội 1 | Q16: cn | U16: x | V16: x | W16: x | X16: cn | Y16: x | Z16: x | AA16: x | AB16: x | AC16: x | AD16: x | AF16: x | AG16: x | AH16: x | AI16: =+COUNTIF(E16:AH16,"X") -> 12 | AJ16: =+COUNTIF(E16:AH16,"CN") -> 2 | AK16: =+COUNTIF(E16:AH16,"D") -> 0 | AL16: =+COUNTIF(E16:AH16,"DCN") -> 0 | AM16: =+SUM(AI16:AL16) -> 14 | AN16: =+VLOOKUP(C16,[1]Sheet1!$D$9:$E$122,2,0) -> #N/A | AO16: =+IF(AN16=B16,"0","1") -> #N/A
A17: 6 | B17: Phơ | D17: Đội 1 | Q17: cn | U17: x | V17: x | W17: x | X17: cn | Y17: x | Z17: x | AA17: x | AB17: x | AC17: x | AD17: x | AE17: cn | AF17: x | AG17: x | AH17: x | AI17: =+COUNTIF(E17:AH17,"X") -> 12 | AJ17: =+COUNTIF(E17:AH17,"CN") -> 3 | AK17: =+COUNTIF(E17:AH17,"D") -> 0 | AL17: =+COUNTIF(E17:AH17,"DCN") -> 0 | AM17: =+SUM(AI17:AL17) -> 15 | AN17: =+VLOOKUP(C17,[1]Sheet1!$D$9:$E$122,2,0) -> #N/A | AO17: =+IF(AN17=B17,"0","1") -> #N/A
A18: 7 | B18: A Phơ | D18: Đội 1 | Q18: cn | U18: x | V18: x | W18: x | X18: cn | Y18: x | Z18: x | AA18: x | AB18: x | AC18: x | AD18: x | AE18: cn | AF18: x | AG18: x | AH18: x | AI18: =+COUNTIF(E18:AH18,"X") -> 12 | AJ18: =+COUNTIF(E18:AH18,"CN") -> 3 | AK18: =+COUNTIF(E18:AH18,"D") -> 0 | AL18: =+COUNTIF(E18:AH18,"DCN") -> 0 | AM18: =+SUM(AI18:AL18) -> 15 | AN18: =+VLOOKUP(C18,[1]Sheet1!$D$9:$E$122,2,0) -> #N/A | AO18: =+IF(AN18=B18,"0","1") -> #N/A
A19: 8 | B19: Nang Xây | D19: Đội 1 | Q19: cn | U19: x | V19: x | W19: x | X19: cn | Y19: x | Z19: x | AA19: x | AB19: x | AC19: x | AD19: x | AE19: cn | AF19: x | AG19: x | AH19: x | AI19: =+COUNTIF(E19:AH19,"X") -> 12 | AJ19: =+COUNTIF(E19:AH19,"CN") -> 3 | AK19: =+COUNTIF(E19:AH19,"D") -> 0 | AL19: =+COUNTIF(E19:AH19,"DCN") -> 0 | AM19: =+SUM(AI19:AL19) -> 15 | AN19: =+VLOOKUP(C19,[1]Sheet1!$D$9:$E$122,2,0) -> #N/A | AO19: =+IF(AN19=B19,"0","1") -> #N/A
A20: 9 | B20: Nang Sun | D20: Đội 1 | Q20: cn | U20: x | V20: x | W20: x | X20: cn | Y20: x | Z20: x | AA20: x | AB20: x | AC20: x | AD20: x | AE20: cn | AF20: x | AG20: x | AH20: x | AI20: =+COUNTIF(E20:AH20,"X") -> 12 | AJ20: =+COUNTIF(E20:AH20,"CN") -> 3 | AK20: =+COUNTIF(E20:AH20,"D") -> 0 | AL20: =+COUNTIF(E20:AH20,"DCN") -> 0 | AM20: =+SUM(AI20:AL20) -> 15 | AN20: =+VLOOKUP(C20,[1]Sheet1!$D$9:$E$122,2,0) -> #N/A | AO20: =+IF(AN20=B20,"0","1") -> #N/A
A21: 10 | B21: Thảo Ben | D21: Đội 1 | Q21: cn | U21: x | V21: x | W21: x | X21: cn | Y21: x | Z21: x | AA21: x | AB21: x | AC21: x | AD21: x | AE21: cn | AF21: x | AG21: x | AH21: x | AI21: =+COUNTIF(E21:AH21,"X") -> 12 | AJ21: =+COUNTIF(E21:AH21,"CN") -> 3 | AK21: =+COUNTIF(E21:AH21,"D") -> 0 | AL21: =+COUNTIF(E21:AH21,"DCN") -> 0 | AM21: =+SUM(AI21:AL21) -> 15 | AN21: =+VLOOKUP(C21,[1]Sheet1!$D$9:$E$122,2,0) -> #N/A | AO21: =+IF(AN21=B21,"0","1") -> #N/A
A22: 11 | B22: Nang Nhăn | D22: Đội 1 | Q22: cn | U22: x | V22: x | W22: x | X22: cn | Y22: x | Z22: x | AA22: x | AB22: x | AC22: x | AD22: x | AE22: cn | AF22: x | AG22: x | AH22: x | AI22: =+COUNTIF(E22:AH22,"X") -> 12 | AJ22: =+COUNTIF(E22:AH22,"CN") -> 3 | AK22: =+COUNTIF(E22:AH22,"D") -> 0 | AL22: =+COUNTIF(E22:AH22,"DCN") -> 0 | AM22: =+SUM(AI22:AL22) -> 15 | AN22: =+VLOOKUP(C22,[1]Sheet1!$D$9:$E$122,2,0) -> #N/A | AO22: =+IF(AN22=B22,"0","1") -> #N/A
A23: 12 | B23: Phò Thít | D23: Đội 1 | Q23: cn | U23: x | V23: x | W23: x | X23: cn | Y23: x | Z23: x | AA23: x | AB23: x | AC23: x | AD23: x | AE23: cn | AF23: x | AG23: x | AH23: x | AI23: =+COUNTIF(E23:AH23,"X") -> 12 | AJ23: =+COUNTIF(E23:AH23,"CN") -> 3 | AK23: =+COUNTIF(E23:AH23,"D") -> 0 | AL23: =+COUNTIF(E23:AH23,"DCN") -> 0 | AM23: =+SUM(AI23:AL23) -> 15 | AN23: =+VLOOKUP(C23,[1]Sheet1!$D$9:$E$122,2,0) -> #N/A | AO23: =+IF(AN23=B23,"0","1") -> #N/A
A24: 13 | B24: A Bợp | D24: Đội 1 | Q24: cn | U24: x | V24: x | W24: x | X24: cn | Z24: x | AA24: x | AB24: x | AC24: x | AD24: x | AE24: cn | AF24: x | AG24: x | AH24: x | AI24: =+COUNTIF(E24:AH24,"X") -> 11 | AJ24: =+COUNTIF(E24:AH24,"CN") -> 3 | AK24: =+COUNTIF(E24:AH24,"D") -> 0 | AL24: =+COUNTIF(E24:AH24,"DCN") -> 0 | AM24: =+SUM(AI24:AL24) -> 14 | AN24: =+VLOOKUP(C24,[1]Sheet1!$D$9:$E$122,2,0) -> #N/A | AO24: =+IF(AN24=B24,"0","1") -> #N/A
A25: 14 | B25: A Cơ | D25: Đội 1 | Q25: cn | U25: x | V25: x | W25: x | X25: cn | Y25: x | Z25: x | AA25: x | AB25: x | AC25: x | AD25: x | AE25: cn | AF25: x | AG25: x | AH25: x | AI25: =+COUNTIF(E25:AH25,"X") -> 12 | AJ25: =+COUNTIF(E25:AH25,"CN") -> 3 | AK25: =+COUNTIF(E25:AH25,"D") -> 0 | AL25: =+COUNTIF(E25:AH25,"DCN") -> 0 | AM25: =+SUM(AI25:AL25) -> 15
A26: 15 | B26: Xa Vạt Đi | D26: Đội 1 | Q26: cn | U26: x | V26: x | W26: x | X26: cn | Y26: x | Z26: x | AA26: x | AB26: x | AC26: x | AD26: x | AE26: cn | AF26: x | AG26: x | AH26: x | AI26: =+COUNTIF(E26:AH26,"X") -> 12 | AJ26: =+COUNTIF(E26:AH26,"CN") -> 3 | AK26: =+COUNTIF(E26:AH26,"D") -> 0 | AL26: =+COUNTIF(E26:AH26,"DCN") -> 0 | AM26: =+SUM(AI26:AL26) -> 15
A27: 16 | B27: Nguyễn Thi Thanh Trà | D27: Đội 1 | Q27: cn | U27: x | V27: x | W27: x | X27: cn | Y27: x | Z27: x | AA27: x | AB27: x | AC27: x | AD27: x | AE27: cn | AF27: x | AG27: x | AH27: x | AI27: =+COUNTIF(E27:AH27,"X") -> 12 | AJ27: =+COUNTIF(E27:AH27,"CN") -> 3 | AK27: =+COUNTIF(E27:AH27,"D") -> 0 | AL27: =+COUNTIF(E27:AH27,"DCN") -> 0 | AM27: =+SUM(AI27:AL27) -> 15
A28: 17 | B28: A Han | D28: Đội 1 | Q28: cn | U28: x | V28: x | W28: x | X28: cn | Y28: x | Z28: x | AA28: x | AB28: x | AC28: x | AD28: x | AE28: cn | AF28: x | AG28: x | AH28: x | AI28: =+COUNTIF(E28:AH28,"X") -> 12 | AJ28: =+COUNTIF(E28:AH28,"CN") -> 3 | AK28: =+COUNTIF(E28:AH28,"D") -> 0 | AL28: =+COUNTIF(E28:AH28,"DCN") -> 0 | AM28: =+SUM(AI28:AL28) -> 15
A29: 18 | B29: Thảo Bun Ten | D29: Đội 1 | Q29: cn | U29: x | V29: x | W29: x | X29: cn | Y29: x | Z29: x | AA29: x | AB29: x | AC29: x | AD29: x | AE29: cn | AF29: x | AG29: x | AH29: x | AI29: =+COUNTIF(E29:AH29,"X") -> 12 | AJ29: =+COUNTIF(E29:AH29,"CN") -> 3 | AK29: =+COUNTIF(E29:AH29,"D") -> 0 | AL29: =+COUNTIF(E29:AH29,"DCN") -> 0 | AM29: =+SUM(AI29:AL29) -> 15
A30: 19 | B30: Nang Đào | D30: Đội 1 | Q30: cn | U30: x | V30: x | W30: x | X30: cn | Y30: x | Z30: x | AA30: x | AB30: x | AC30: x | AD30: x | AE30: cn | AF30: x | AG30: x | AH30: x | AI30: =+COUNTIF(E30:AH30,"X") -> 12 | AJ30: =+COUNTIF(E30:AH30,"CN") -> 3 | AK30: =+COUNTIF(E30:AH30,"D") -> 0 | AL30: =+COUNTIF(E30:AH30,"DCN") -> 0 | AM30: =+SUM(AI30:AL30) -> 15
A31: 20 | B31: Phò Nhạc | D31: Đội 1 | Q31: cn | U31: x | V31: x | W31: x | X31: cn | Y31: x | Z31: x | AA31: x | AB31: x | AC31: x | AD31: x | AF31: x | AG31: x | AH31: x | AI31: =+COUNTIF(E31:AH31,"X") -> 12 | AJ31: =+COUNTIF(E31:AH31,"CN") -> 2 | AK31: =+COUNTIF(E31:AH31,"D") -> 0 | AL31: =+COUNTIF(E31:AH31,"DCN") -> 0 | AM31: =+SUM(AI31:AL31) -> 14
A32: 21 | B32: Van | D32: Đội 1 | Q32: cn | U32: x | V32: x | W32: x | X32: cn | Y32: x | Z32: x | AA32: x | AB32: x | AC32: x | AE32: cn | AI32: =+COUNTIF(E32:AH32,"X") -> 8 | AJ32: =+COUNTIF(E32:AH32,"CN") -> 3 | AK32: =+COUNTIF(E32:AH32,"D") -> 0 | AL32: =+COUNTIF(E32:AH32,"DCN") -> 0 | AM32: =+SUM(AI32:AL32) -> 11
A33: 22 | B33: Thảo Xi | D33: Đội 1 | Q33: cn | U33: x | V33: x | W33: x | X33: cn | Y33: x | Z33: x | AA33: x | AB33: x | AC33: x | AD33: x | AE33: cn | AF33: x | AG33: x | AH33: x | AI33: =+COUNTIF(E33:AH33,"X") -> 12 | AJ33: =+COUNTIF(E33:AH33,"CN") -> 3 | AK33: =+COUNTIF(E33:AH33,"D") -> 0 | AL33: =+COUNTIF(E33:AH33,"DCN") -> 0 | AM33: =+SUM(AI33:AL33) -> 15
A34: 23 | B34: Húc | D34: Đội 1 | Q34: cn | U34: x | V34: x | W34: x | X34: cn | Y34: x | Z34: x | AA34: x | AB34: x | AC34: x | AD34: x | AE34: cn | AF34: x | AG34: x | AH34: x | AI34: =+COUNTIF(E34:AH34,"X") -> 12 | AJ34: =+COUNTIF(E34:AH34,"CN") -> 3 | AK34: =+COUNTIF(E34:AH34,"D") -> 0 | AL34: =+COUNTIF(E34:AH34,"DCN") -> 0 | AM34: =+SUM(AI34:AL34) -> 15
A35: 24 | B35: Thảo Nét | D35: Đội 1 | Q35: cn | U35: x | V35: x | W35: x | X35: cn | Y35: x | Z35: x | AA35: x | AB35: x | AC35: x | AD35: x | AE35: cn | AF35: x | AG35: x | AH35: x | AI35: =+COUNTIF(E35:AH35,"X") -> 12 | AJ35: =+COUNTIF(E35:AH35,"CN") -> 3 | AK35: =+COUNTIF(E35:AH35,"D") -> 0 | AL35: =+COUNTIF(E35:AH35,"DCN") -> 0 | AM35: =+SUM(AI35:AL35) -> 15
A36: 25 | B36: Thảo út | D36: Đội 1 | Q36: cn | U36: x | V36: x | W36: x | X36: cn | Y36: x | Z36: x | AA36: x | AB36: x | AC36: x | AD36: x | AE36: cn | AF36: x | AG36: x | AH36: x | AI36: =+COUNTIF(E36:AH36,"X") -> 12 | AJ36: =+COUNTIF(E36:AH36,"CN") -> 3 | AK36: =+COUNTIF(E36:AH36,"D") -> 0 | AL36: =+COUNTIF(E36:AH36,"DCN") -> 0 | AM36: =+SUM(AI36:AL36) -> 15 | AN36: =+VLOOKUP(C36,[1]Sheet1!$D$9:$E$122,2,0) -> #N/A | AO36: =+IF(AN36=B36,"0","1") -> #N/A
A37: 26 | B37: Tà Lọt | D37: Đội 1 | Q37: cn | U37: x | V37: x | W37: x | X37: cn | Y37: x | Z37: x | AA37: x | AB37: x | AC37: x | AD37: x | AE37: cn | AF37: x | AG37: x | AH37: x | AI37: =+COUNTIF(E37:AH37,"X") -> 12 | AJ37: =+COUNTIF(E37:AH37,"CN") -> 3 | AK37: =+COUNTIF(E37:AH37,"D") -> 0 | AL37: =+COUNTIF(E37:AH37,"DCN") -> 0 | AM37: =+SUM(AI37:AL37) -> 15
A38: 27 | B38: A Nghen | D38: Đội 1 | Q38: cn | U38: x | V38: x | W38: x | X38: cn | Y38: x | Z38: x | AA38: x | AB38: x | AC38: x | AD38: x | AE38: cn | AG38: x | AH38: x | AI38: =+COUNTIF(E38:AH38,"X") -> 11 | AJ38: =+COUNTIF(E38:AH38,"CN") -> 3 | AK38: =+COUNTIF(E38:AH38,"D") -> 0 | AL38: =+COUNTIF(E38:AH38,"DCN") -> 0 | AM38: =+SUM(AI38:AL38) -> 14
A39: 28 | B39: Thảo Xâm | D39: Đội 1 | Q39: cn | U39: x | V39: x | W39: x | X39: cn | Y39: x | Z39: x | AA39: x | AB39: x | AC39: x | AD39: x | AE39: cn | AF39: x | AG39: x | AH39: x | AI39: =+COUNTIF(E39:AH39,"X") -> 12 | AJ39: =+COUNTIF(E39:AH39,"CN") -> 3 | AK39: =+COUNTIF(E39:AH39,"D") -> 0 | AL39: =+COUNTIF(E39:AH39,"DCN") -> 0 | AM39: =+SUM(AI39:AL39) -> 15
A40: 29 | B40: Thảo Von | D40: Đội 1 | Q40: cn | U40: x | V40: x | W40: x | X40: cn | Y40: x | Z40: x | AA40: x | AB40: x | AC40: x | AD40: x | AE40: cn | AF40: x | AG40: x | AH40: x | AI40: =+COUNTIF(E40:AH40,"X") -> 12 | AJ40: =+COUNTIF(E40:AH40,"CN") -> 3 | AK40: =+COUNTIF(E40:AH40,"D") -> 0 | AL40: =+COUNTIF(E40:AH40,"DCN") -> 0 | AM40: =+SUM(AI40:AL40) -> 15
A41: 30 | B41: Nang Phen | D41: Đội 1 | Q41: cn | U41: x | V41: x | W41: x | X41: cn | Y41: x | Z41: x | AA41: x | AB41: x | AC41: x | AD41: x | AE41: cn | AF41: x | AG41: x | AH41: x | AI41: =+COUNTIF(E41:AH41,"X") -> 12 | AJ41: =+COUNTIF(E41:AH41,"CN") -> 3 | AM41: =+SUM(AI41:AL41) -> 15
A42: 31 | B42: Nang Bun Ten | D42: Đội 1 | Q42: cn | U42: x | V42: x | W42: x | X42: cn | Y42: x | Z42: x | AA42: x | AB42: x | AC42: x | AD42: x | AE42: cn | AF42: x | AG42: x | AH42: x | AI42: =+COUNTIF(E42:AH42,"X") -> 12 | AJ42: =+COUNTIF(E42:AH42,"CN") -> 3 | AM42: =+SUM(AI42:AL42) -> 15
A43: 32 | B43: Cha Lơ | D43: Đội 1 | Q43: cn | U43: x | V43: x | W43: x | X43: cn | Y43: x | Z43: x | AC43: x | AI43: =+COUNTIF(E43:AH43,"X") -> 6 | AJ43: =+COUNTIF(E43:AH43,"CN") -> 2 | AM43: =+SUM(AI43:AL43) -> 8
...

Sheet Phụ cấp cây non
A1: CỘNG HÒA DÂN CHỦ NHÂN DÂN LÀO
A2: Hòa bình - Độc lập - Dân chủ - Thống nhất - Thịnh vượng
A3: ----- o0o-----
A4: CÔNG TY TNHH CP QUASA - GERUCO LÀO
A5: NÔNG TRƯỜNG CAO SU SỐ 3
A8: BẢNG CHẤM CÔNG PHỤ CẤP CÂY NON NÔNG TRƯỜNG 3 THÁNG 04 NĂM 2025
A10: Stt | B10: Họ và tên | C10: MSNV | D10: Bội phận | E10: Ngày đi làm | AI10: Ngày công đi cao (x) | AJ10: Ngày cạo đúp bình thường ( D) | AK10: Ngày cạo đúp chủ nhật | AL10: Tổng công | AO10: Ký tên CN
E11: 1 | F11: 2 | G11: 3 | H11: 4 | I11: 5 | J11: 6 | K11: 7 | L11: 8 | M11: 9 | N11: 10 | O11: 11 | P11: 12 | Q11: 13 | R11: 14 | S11: 15 | T11: 16 | U11: 17 | V11: 18 | W11: 19 | X11: 20 | Y11: 21 | Z11: 22 | AA11: 23 | AB11: 24 | AC11: 25 | AD11: 26 | AE11: 27 | AF11: 28 | AG11: 29 | AH11: 30
A12: 1 | B12: Thảo Vong | D12: Đội 1 | U12: x | V12: x | W12: x | X12: x | Y12: x | Z12: x | AA12: x | AB12: x | AC12: x | AD12: x | AE12: x | AF12: x | AG12: x | AH12: x | AI12: =+COUNTIF(E12:AH12,"X") -> 14 | AL12: =+SUM(AI12:AK12) -> 14
A13: 2 | B13: Nàng Veng | D13: Đội 1 | U13: x | V13: x | W13: x | X13: x | Y13: x | Z13: x | AA13: x | AB13: x | AC13: x | AD13: x | AE13: x | AF13: x | AG13: x | AH13: x | AI13: =+COUNTIF(E13:AH13,"X") -> 14 | AL13: =+SUM(AI13:AK13) -> 14
A14: 3 | B14: Thảo Đuông Chăn | D14: Đội 1 | U14: x | V14: x | W14: x | X14: x | Y14: x | Z14: x | AA14: x | AB14: x | AC14: x | AD14: x | AE14: x | AF14: x | AG14: x | AH14: x | AI14: =+COUNTIF(E14:AH14,"X") -> 14 | AL14: =+SUM(AI14:AK14) -> 14
A15: 4 | B15: Nàng Peng | D15: Đội 1 | U15: x | V15: x | W15: x | X15: x | Y15: x | Z15: x | AA15: x | AB15: x | AC15: x | AD15: x | AE15: x | AF15: x | AG15: x | AH15: x | AI15: =+COUNTIF(E15:AH15,"X") -> 14 | AL15: =+SUM(AI15:AK15) -> 14
A16: 5 | B16: Thảo Xay Tho | D16: Đội 1 | AC16: x | AD16: x | AE16: x | AF16: x | AG16: x | AH16: x | AI16: =+COUNTIF(E16:AH16,"X") -> 6 | AL16: =+SUM(AI16:AK16) -> 6
A17: 6 | B17: Nàng Xia Lô | D17: Đội 1 | AC17: x | AD17: x | AE17: x | AF17: x | AG17: x | AH17: x | AI17: =+COUNTIF(E17:AH17,"X") -> 6 | AJ17: =+COUNTIF(E17:AH17,"D") -> 0 | AK17: =+COUNTIF(E17:AH17,"DCN") -> 0 | AL17: =+SUM(AI17:AK17) -> 6
A18: Tổng cộng | E18: =COUNTIF(E12:E17,"x") -> 0 | F18: =COUNTIF(F12:F17,"x") -> 0 | G18: =COUNTIF(G12:G17,"x") -> 0 | H18: =COUNTIF(H12:H17,"x") -> 0 | I18: =COUNTIF(I12:I17,"x") -> 0 | J18: =COUNTIF(J12:J17,"x") -> 0 | K18: =COUNTIF(K12:K17,"x") -> 0 | L18: =COUNTIF(L12:L17,"x") -> 0 | ... AH18: =COUNTIF(AH12:AH17,"x") -> 6 | AI18: =+SUM(AI12:AI17) -> 68 | AJ18: =+SUM(AJ12:AJ17) -> 0 | AK18: =+SUM(AK12:AK17) -> 0 | AL18: =+SUM(AL12:AL17) -> 68 | AM18: =SUBTOTAL(9,AM12:AM17) -> 0 | AN18: =SUBTOTAL(9,AN12:AN17) -> 0
A19: Ghi chú | D19: x | E19: Ngày phụ cấp | AF19: Huyện Noong, ngày 30 tháng 04 năm 2025
A22: TỔNG GIÁM ĐỐC | G22: P. KT -NN | M22: P. TC -HC | R22: GIÁM ĐỐC NT | W22: TL. TC - KT | AB22: TL . KH -NN | AH22: NGƯỜI LẬP
AK34: =+AK18+AK31 -> 0

Sheet Thanh toán bốc mủ
A1: CỘNG HÒA DÂN CHỦ NHÂN DÂN LÀO
A2: Hòa Bình -Độc Lập - Dân Chủ - thống Nhất - Thịnh Vượng
A3: -----oOo-----
A4: CÔNG TY TNHH CP QUASA - GERUCO LÀO
A5: NÔNG TRƯỜNG CAO SU SỐ 3
A7: BẢNG THANH TOÁN TIỀN LƯƠNG MỦ DÂY THÁNG 04 NĂM 2025
A9: (Từ ngày 01 tháng 04 đến ngày 31 tháng 04 năm 2025)
A12: Stt | B12: Họ và tên | C12: Ngày | AG12: Sản lượng mủ dây mủ dây | AH12: Đơn giá | AI12: Thành tiền | AJ12: Ký tên
C13: 1 | D13: 2 | E13: 3 | F13: 4 | G13: 5 | H13: 6 | I13: 7 | J13: 8 | K13: 9 | L13: 10 | M13: 11 | N13: 12 | O13: 13 | P13: 14 | Q13: 15 | R13: 16 | S13: 17 | T13: 18 | U13: 19 | V13: 20 | W13: 21 | X13: 22 | Y13: 23 | Z13: 24 | AA13: 25 | AB13: 26 | AC13: 27 | AD13: 28 | AE13: 29 | AF13: 30
A14: Đội 1 | C14: =SUM(C15:C46) -> 0 | D14: =SUM(D15:D46) -> 0 | E14: =SUM(E15:E46) -> 0 | F14: =SUM(F15:F46) -> 0 | G14: =SUM(G15:G46) -> 0 | H14: =SUM(H15:H46) -> 0 | I14: =SUM(I15:I46) -> 0 | J14: =SUM(J15:J46) -> 0 | ... AF14: =SUM(AF15:AF46) -> 0 | AG14: =SUM(AG15:AG61) -> 380 | AI14: =SUM(AI15:AI63) -> 3800000
A15: 1 | B15: A Nhợp | AG15: =+VLOOKUP(B15,'[2]Mủ dây'!C13:AI46,33,0) -> 8 | AH15: 8000 | AI15: =+AG15*AH15 -> 64000
A16: 2 | B16: A Chan | AG16: =+VLOOKUP(B16,'[2]Mủ dây'!C14:AI47,33,0) -> 6 | AH16: 8000 | AI16: =+AG16*AH16 -> 48000
A17: 3 | B17: Phò Đùa | AG17: =+VLOOKUP(B17,'[2]Mủ dây'!C15:AI48,33,0) -> 5 | AH17: 8000 | AI17: =+AG17*AH17 -> 40000
A18: 4 | B18: Xúc | AG18: =+VLOOKUP(B18,'[2]Mủ dây'!C16:AI49,33,0) -> 4 | AH18: 8000 | AI18: =+AG18*AH18 -> 32000
A19: 5 | B19: Phơ | AG19: =+VLOOKUP(B19,'[2]Mủ dây'!C17:AI50,33,0) -> 16 | AH19: 8000 | AI19: =+AG19*AH19 -> 128000
A20: 6 | B20: A Phơ | AG20: =+VLOOKUP(B20,'[2]Mủ dây'!C18:AI51,33,0) -> 15 | AH20: 8000 | AI20: =+AG20*AH20 -> 120000
A21: 7 | B21: Nang Xây | AG21: =+VLOOKUP(B21,'[2]Mủ dây'!C19:AI52,33,0) -> 8 | AH21: 8000 | AI21: =+AG21*AH21 -> 64000
A22: 8 | B22: Nang Sun | AG22: =+VLOOKUP(B22,'[2]Mủ dây'!C20:AI53,33,0) -> 9 | AH22: 8000 | AI22: =+AG22*AH22 -> 72000
A23: 9 | B23: Thảo Ben | AG23: =+VLOOKUP(B23,'[2]Mủ dây'!C21:AI54,33,0) -> 3 | AH23: 8000 | AI23: =+AG23*AH23 -> 24000
A24: 10 | B24: Nang Nhăn | AG24: =+VLOOKUP(B24,'[2]Mủ dây'!C22:AI55,33,0) -> 10 | AH24: 8000 | AI24: =+AG24*AH24 -> 80000
A25: 11 | B25: Phò Thít | AG25: =+VLOOKUP(B25,'[2]Mủ dây'!C23:AI56,33,0) -> 6 | AH25: 8000 | AI25: =+AG25*AH25 -> 48000
A26: 12 | B26: A Bợp | AG26: =+VLOOKUP(B26,'[2]Mủ dây'!C24:AI57,33,0) -> 5 | AH26: 8000 | AI26: =+AG26*AH26 -> 40000
... A30: 16 | B30: A Han | AG30: =+VLOOKUP(B30,'[2]Mủ dây'!C28:AI61,33,0) -> 6 | AH30: 8000 | AI30: =+AG30*AH30 -> 48000
A31: 17 | B31: Thảo Bun Ten | AG31: =+VLOOKUP(B31,'[2]Mủ dây'!C29:AI61,33,0) -> 7 | AH31: 8000 | AI31: =+AG31*AH31 -> 56000
A32: 18 | B32: Nang Đào | AG32: =+VLOOKUP(B32,'[2]Mủ dây'!C30:AI61,33,0) -> 9 | AH32: 8000 | AI32: =+AG32*AH32 -> 72000
A33: 19 | B33: Phò Nhạc | AG33: =+VLOOKUP(B33,'[2]Mủ dây'!C31:AI61,33,0) -> 12 | AH33: 8000 | AI33: =+AG33*AH33 -> 96000
A34: 20 | B34: Van | AG34: =+VLOOKUP(B34,'[2]Mủ dây'!C32:AI61,33,0) -> 4 | AH34: 8000 | AI34: =+AG34*AH34 -> 32000
A35: 21 | B35: Thảo Xi | AG35: =+VLOOKUP(B35,'[2]Mủ dây'!C33:AI61,33,0) -> 10 | AH35: 8000 | AI35: =+AG35*AH35 -> 80000
A36: 22 | B36: Húc | AG36: =+VLOOKUP(B36,'[2]Mủ dây'!C34:AI61,33,0) -> 4 | AH36: 8000 | AI36: =+AG36*AH36 -> 32000
A37: 23 | B37: Thảo Nét | AG37: =+VLOOKUP(B37,'[2]Mủ dây'!C35:AI61,33,0) -> 9 | AH37: 8000 | AI37: =+AG37*AH37 -> 72000
A38: 24 | B38: Thảo út | AG38: =+VLOOKUP(B38,'[2]Mủ dây'!C36:AI61,33,0) -> 8 | AH38: 8000 | AI38: =+AG38*AH38 -> 64000
A39: 25 | B39: Tà Lọt | AG39: =+VLOOKUP(B39,'[2]Mủ dây'!C37:AI61,33,0) -> 4 | AH39: 8000 | AI39: =+AG39*AH39 -> 32000
A40: 26 | B40: A Nghen | AG40: =+VLOOKUP(B40,'[2]Mủ dây'!C38:AI61,33,0) -> 4 | AH40: 8000 | AI40: =+AG40*AH40 -> 32000
A41: 27 | B41: Thảo Xâm | AG41: =+VLOOKUP(B41,'[2]Mủ dây'!C39:AI61,33,0) -> 6 | AH41: 8000 | AI41: =+AG41*AH41 -> 48000
A42: 28 | B42: Thảo Von | AG42: =+VLOOKUP(B42,'[2]Mủ dây'!C40:AI61,33,0) -> 9 | AH42: 8000 | AI42: =+AG42*AH42 -> 72000
A43: 29 | B43: Nang Phen | AG43: =+VLOOKUP(B43,'[2]Mủ dây'!C41:AI61,33,0) -> 7 | AH43: 8000 | AI43: =+AG43*AH43 -> 56000
A44: 30 | B44: Nang Bun Ten | AG44: =+VLOOKUP(B44,'[2]Mủ dây'!C42:AI61,33,0) -> 7 | AH44: 8000 | AI44: =+AG44*AH44 -> 56000
A45: 31 | B45: Dã Lay | Q45: 15 | AG45: =+VLOOKUP(B45,'[2]Mủ dây'!C44:AI61,33,0) -> 3 | AH45: 8000 | AI45: =+AG45*AH45 -> 24000
A46: 32 | B46: Thảo Xen | Q46: 16 | AG46: =+VLOOKUP(B46,'[2]Mủ dây'!C45:AI61,33,0) -> 4 | AH46: 8000 | AI46: =+AG46*AH46 -> 32000
A47: 33 | B47: Nàng Ăn | AG47: =+VLOOKUP(B47,'[2]Mủ dây'!C46:AI62,33,0) -> 5 | AH47: 8000 | AI47: =+AG47*AH47 -> 40000
...

Sheet Chấm công đi làm thưởng
A1: CỘNG HÒA DÂN CHỦ NHÂN DÂN LÀO
A2: Hòa bình - Độc lập - Dân chủ - Thống nhất - Thịnh vượng
A3: ----- o0o-----
A4: CÔNG TY TNHH CP QUASA - GERUCO LÀO
A5: NÔNG TRƯỜNG CAO SU SỐ 3
A8: BẢNG CHẤM CÔNG CÔNG NHÂN NÔNG TRƯỜNG THỰC HIỆN CÔNG TÁC SAU KHI NGƯNG CẠO MỦ
A10: Stt | B10: Họ và tên | C10: MSNV | D10: Bội phận | E10: Ngày đi làm | L10: Ngày công đi làm các công tác sau nghĩ cạo | M10: Ngày công đi cạo thực tế | N10: Tổng công | Q10: Ký tên CN
E11: 26/2 | F11: 27/2 | G11: 28/2 | H11: 1/3 | I11: 2/3 | J11: 3/3 | K11: 4/3
A12: 1 | B12: A Ngan | D12: Đội 1 | M12: =+VLOOKUP(B12,#REF!,36,0) -> #REF! | N12: =+L12+M12 -> #REF! | O12: =+VLOOKUP(C12,[1]Sheet1!$D$9:$E$122,2,0) -> #N/A | P12: =+IF(O12=B12,"0","1") -> #N/A | R12: =IF(N12>=24,"100%","80%") -> #REF! | S12: =IF(N12>=18," THƯỞNG 100%"," THƯỞNG 80%") -> #REF! | T12: 22
A13: 2 | B13: Ang | D13: Đội 1 | M13: =+VLOOKUP(B13,#REF!,36,0) -> #REF! | N13: =+L13+M13 -> #REF! | O13: =+VLOOKUP(C13,[1]Sheet1!$D$9:$E$122,2,0) -> #N/A | P13: =+IF(O13=B13,"0","1") -> #N/A | R13: =IF(N13>=24,"100%","80%") -> #REF! | S13: =IF(N13>=18," THƯỞNG 100%"," THƯỞNG 80%") -> #REF! | T13: 21
A14: 3 | B14: Tà Lọt | D14: Đội 1 | M14: =+VLOOKUP(B14,#REF!,36,0) -> #REF! | N14: =+L14+M14 -> #REF! | O14: =+VLOOKUP(C14,[1]Sheet1!$D$9:$E$122,2,0) -> #N/A | P14: =+IF(O14=B14,"0","1") -> #N/A | R14: =IF(N14>=24,"100%","80%") -> #REF! | S14: =IF(N14>=18," THƯỞNG 100%"," THƯỞNG 80%") -> #REF! | T14: 23
A15: 4 | B15: Dã Lay | D15: Đội 1 | M15: =+VLOOKUP(B15,#REF!,36,0) -> #REF! | N15: =+L15+M15 -> #REF! | O15: =+VLOOKUP(C15,[1]Sheet1!$D$9:$E$122,2,0) -> #N/A | P15: =+IF(O15=B15,"0","1") -> #N/A | R15: =IF(N15>=24,"100%","80%") -> #REF! | S15: =IF(N15>=18," THƯỞNG 100%"," THƯỞNG 80%") -> #REF! | T15: 23
A16: 5 | B16: Tom | D16: Đội 1 | M16: =+VLOOKUP(B16,#REF!,36,0) -> #REF! | N16: =+L16+M16 -> #REF! | O16: =+VLOOKUP(C16,[1]Sheet1!$D$9:$E$122,2,0) -> #N/A | P16: =+IF(O16=B16,"0","1") -> #N/A | R16: =IF(N16>=24,"100%","80%") -> #REF! | S16: =IF(N16>=18," THƯỞNG 100%"," THƯỞNG 80%") -> #REF! | T16: 22
A17: 6 | B17: Van | D17: Đội 1 | M17: =+VLOOKUP(B17,#REF!,36,0) -> #REF! | N17: =+L17+M17 -> #REF! | R17: =IF(N17>=24,"100%","80%") -> #REF! | S17: =IF(N17>=18," THƯỞNG 100%"," THƯỞNG 80%") -> #REF! | T17: 22
A18: 7 | B18: A Han | D18: Đội 1 | M18: =+VLOOKUP(B18,#REF!,36,0) -> #REF! | N18: =+L18+M18 -> #REF! | R18: =IF(N18>=24,"100%","80%") -> #REF! | S18: =IF(N18>=18," THƯỞNG 100%"," THƯỞNG 80%") -> #REF! | T18: 20
A19: 8 | B19: A Xiu | D19: Đội 1 | M19: =+VLOOKUP(B19,#REF!,36,0) -> #REF! | N19: =+L19+M19 -> #REF! | R19: =IF(N19>=24,"100%","80%") -> #REF! | S19: =IF(N19>=18," THƯỞNG 100%"," THƯỞNG 80%") -> #REF! | T19: 20
A20: 10 | B20: Bun Ma | D20: Đội 1 | M20: =+VLOOKUP(B20,#REF!,36,0) -> #REF! | N20: =+L20+M20 -> #REF! | R20: =IF(N20>=24,"100%","80%") -> #REF! | S20: =IF(N20>=18," THƯỞNG 100%"," THƯỞNG 80%") -> #REF! | T20: 23
A21: 11 | B21: Lây | D21: Đội 1 | M21: =+VLOOKUP(B21,#REF!,36,0) -> #REF! | N21: =+L21+M21 -> #REF! | R21: =IF(N21>=24,"100%","80%") -> #REF! | S21: =IF(N21>=18," THƯỞNG 100%"," THƯỞNG 80%") -> #REF! | T21: 23
A22: 12 | B22: Phò Lấp | D22: Đội 1 | M22: =+VLOOKUP(B22,#REF!,36,0) -> #REF! | N22: =+L22+M22 -> #REF! | R22: =IF(N22>=24,"100%","80%") -> #REF! | S22: =IF(N22>=18," THƯỞNG 100%"," THƯỞNG 80%") -> #REF! | T22: 23
A23: 13 | B23: A mang | D23: Đội 1 | M23: =+VLOOKUP(B23,#REF!,36,0) -> #REF! | N23: =+L23+M23 -> #REF! | R23: =IF(N23>=24,"100%","80%") -> #REF! | S23: =IF(N23>=18," THƯỞNG 100%"," THƯỞNG 80%") -> #REF! | T23: 22
A24: 14 | B24: Măn | D24: Đội 1 | M24: =+VLOOKUP(B24,#REF!,36,0) -> #REF! | N24: =+L24+M24 -> #REF! | R24: =IF(N24>=24,"100%","80%") -> #REF! | S24: =IF(N24>=18," THƯỞNG 100%"," THƯỞNG 80%") -> #REF! | T24: 21
A25: 15 | B25: Ca Chốt | D25: Đội 1 | M25: =+VLOOKUP(B25,#REF!,36,0) -> #REF! | N25: =+L25+M25 -> #REF! | R25: =IF(N25>=24,"100%","80%") -> #REF! | S25: =IF(N25>=18," THƯỞNG 100%"," THƯỞNG 80%") -> #REF! | T25: 21
A26: Đội 1 KX | M26: =SUM(M12:M25) -> #REF! | N26: 303 | S26: =+L26+L38 -> 0 | T26: 22 | U26: =+#REF!+#REF! -> #REF! | V26: =+#REF!+#REF! -> #REF!
A27: 1 | B27: Thảo Bun | D27: Đội 1 | M27: =+VLOOKUP(B27,#REF!,36,0) -> #REF! | N27: =+L27+M27 -> #REF! | R27: =IF(N27>=24,"100%","80%") -> #REF! | S27: =IF(N27>=18," THƯỞNG 100%"," THƯỞNG 80%") -> #REF! | T27: 22
A28: 2 | B28: Thảo Lốt | D28: Đội 1 | M28: =+VLOOKUP(B28,#REF!,36,0) -> #REF! | N28: =+L28+M28 -> #REF! | R28: =IF(N28>=24,"100%","80%") -> #REF! | S28: =IF(N28>=18," THƯỞNG 100%"," THƯỞNG 80%") -> #REF! | T28: 22
A29: 3 | B29: Nang Pan | D29: Đội 1 | M29: =+VLOOKUP(B29,#REF!,36,0) -> #REF! | N29: =+L29+M29 -> #REF! | R29: =IF(N29>=24,"100%","80%") -> #REF! | S29: =IF(N29>=18," THƯỞNG 100%"," THƯỞNG 80%") -> #REF! | T29: 23
A30: 4 | B30: Thảo Bổn | D30: Đội 1 | M30: =+VLOOKUP(B30,#REF!,36,0) -> #REF! | N30: =+L30+M30 -> #REF! | R30: =IF(N30>=24,"100%","80%") -> #REF! | S30: =IF(N30>=18," THƯỞNG 100%"," THƯỞNG 80%") -> #REF! | T30: 20
A31: 5 | B31: Nàng Păn | D31: Đội 1 | M31: =+VLOOKUP(B31,#REF!,36,0) -> #REF! | N31: =+L31+M31 -> #REF! | R31: =IF(N31>=24,"100%","80%") -> #REF! | S31: =IF(N31>=18," THƯỞNG 100%"," THƯỞNG 80%") -> #REF! | T31: 23
A32: 6 | B32: Thảo Uổn | D32: Đội 1 | M32: =+VLOOKUP(B32,#REF!,36,0) -> #REF! | N32: =+L32+M32 -> #REF! | R32: =IF(N32>=24,"100%","80%") -> #REF! | S32: =IF(N32>=18," THƯỞNG 100%"," THƯỞNG 80%") -> #REF! | T32: 20
A33: 7 | B33: A Khò | D33: Đội 1 | M33: =+VLOOKUP(B33,#REF!,36,0) -> #REF! | N33: =+L33+M33 -> #REF! | R33: =IF(N33>=24,"100%","80%") -> #REF! | S33: =IF(N33>=18," THƯỞNG 100%"," THƯỞNG 80%") -> #REF!
A34: 8 | B34: Thảo hôm | D34: Đội 1 | M34: =+VLOOKUP(B34,#REF!,36,0) -> #REF! | N34: =+L34+M34 -> #REF! | R34: =IF(N34>=24,"100%","80%") -> #REF! | S34: =IF(N34>=18," THƯỞNG 100%"," THƯỞNG 80%") -> #REF!
A35: 9 | B35: Nàng Phét | D35: Đội 1 | M35: =+VLOOKUP(B35,#REF!,36,0) -> #REF! | N35: =+L35+M35 -> #REF! | R35: =IF(N35>=24,"100%","80%") -> #REF! | S35: =IF(N35>=18," THƯỞNG 100%"," THƯỞNG 80%") -> #REF!
A36: 10 | B36: A Bốt A | D36: Đội 1 | M36: =+VLOOKUP(B36,#REF!,36,0) -> #REF! | N36: =+L36+M36 -> #REF! | R36: =IF(N36>=24,"100%","80%") -> #REF! | S36: =IF(N36>=18," THƯỞNG 100%"," THƯỞNG 80%") -> #REF!
A37: 11 | B37: Bô li Phăn | D37: Đội 1 | M37: =+VLOOKUP(B37,#REF!,36,0) -> #REF! | N37: =+L37+M37 -> #REF! | R37: =IF(N37>=24,"100%","80%") -> #REF! | S37: =IF(N37>=18," THƯỞNG 100%"," THƯỞNG 80%") -> #REF!
A38: Đội 1 XT | M38: =+SUBTOTAL(9,M27:M37) -> #REF! | N38: 237 | O38: =+SUBTOTAL(9,O12:O37) -> #N/A | P38: =+SUBTOTAL(9,P12:P37) -> #N/A
A39: 1 | B39: A Lau | D39: Đội 2 | M39: =+VLOOKUP(B39,#REF!,36,0) -> #REF! | N39: =+L39+M39 -> #REF! | O39: =+VLOOKUP(C39,[1]Sheet1!$D$9:$E$122,2,0) -> #N/A | P39: =+IF(O39=B39,"0","1") -> #N/A | R39: =IF(N39>=24,"100%","80%") -> #REF! | S39: =IF(N39>=18," THƯỞNG 100%"," THƯỞNG 80%") -> #REF!
A40: 2 | B40: Thảo Phao | D40: Đội 2 | M40: =+VLOOKUP(B40,#REF!,36,0) -> #REF! | N40: =+L40+M40 -> #REF! | O40: =+VLOOKUP(C40,[1]Sheet1!$D$9:$E$122,2,0) -> #N/A | P40: =+IF(O40=B40,"0","1") -> #N/A | R40: =IF(N40>=24,"100%","80%") -> #REF! | S40: =IF(N40>=18," THƯỞNG 100%"," THƯỞNG 80%") -> #REF!
A41: 3 | B41: Thảo Săm Lết | D41: Đội 2 | M41: =+VLOOKUP(B41,#REF!,36,0) -> #REF! | N41: =+L41+M41 -> #REF! | R41: =IF(N41>=24,"100%","80%") -> #REF! | S41: =IF(N41>=18," THƯỞNG 100%"," THƯỞNG 80%") -> #REF!
A42: 4 | B42: A Beo | D42: Đội 2 | M42: =+VLOOKUP(B42,#REF!,36,0) -> #REF! | N42: =+L42+M42 -> #REF! | R42: =IF(N42>=24,"100%","80%") -> #REF! | S42: =IF(N42>=18," THƯỞNG 100%"," THƯỞNG 80%") -> #REF!
A43: 5 | B43: Tà Pệc | D43: Đội 2 | M43: =+VLOOKUP(B43,#REF!,36,0) -> #REF! | N43: =+L43+M43 -> #REF! | R43: =IF(N43>=24,"100%","80%") -> #REF! | S43: =IF(N43>=18," THƯỞNG 100%"," THƯỞNG 80%") -> #REF!
...

Sheet Đội 1
A2: CỘNG HÒA DÂN CHỦ NHÂN DÂN LÀO
A3: Hòa Bình - Độc Lập - Dân Chủ - Thống Nhất - Thịnh Vượng
A4: -----o0o-----
A6: CÔNG TY TNHH CỔ PHẦN QUASA - GERUCO LÀO
A7: NÔNG TRƯỜNG CAO SU SỐ 3
A9: BẢNG LƯƠNG KHAI THÁC ĐỘI 1 THÁNG 04 NĂM 2025
E10: 655.8
E11: =+VCKD!E8 -> 640.39 | Y11: ='[3]Bảng CC vn'!AK10 -> 25 | AA11: =306516-30 -> 306486
C12: Tỷ giá Bath qua Kip: | E12: 646.2 | W12: ĐVT: Kip
A13: STT/mã cn | B13: Mã số nhân viên | C13: Họ và tên | D13: Chức vụ | E13: Ký nhận | F13: LƯƠNG | T13: Tổng tiền lương | U13: Thuế TNCN | V13: Đã chi trả tiền lương hằng ngày | W13: Tiền lương còn lại | X13: Ghi chú | Y13: Tạp Đội 1 | Z13: Quy khô | AA13: DRC
F14: Lương chăm sóc (25.000 kíp/ công) | H14: Lương sản lượng | N14: Lương ngày công đi cạo | Y14: 879 | Z14: 499.59656 | AA14: =+Z14/Y14 -> 0.56836924
Y15: 7475 | Z15: 4302.9074 | AA15: =+Z15/Y15 -> 0.57563979 | AB15: 90 | AC15: 51.874396 | AD15: 46.686957
F16: Ngày công | G16: Thành tiền | H16: Mủ tạp (kg) | I16: Mủ serum | J16: Mủ quy khô ( Kg) | K16: Mủ quy khô ( Kg) | L16: Hạng kỹ thuật | M16: Thành tiền | N16: Phụ cấp ngày công | O16: Phụ cấp ngày công chủ nhật | P16: Phụ cấp khó khăn | Q16: Phụ cấp ngày công cây non | R16: Phụ cấp xã cạo | S16: Thành tiền | Y16: =+Y14+Y15 -> 8354 | Z16: =+Z14+Z15 -> 4802.504
Y17: 80k | Z17: hoc cạo | AA17: Xã cạo
A18: 1 | C18: A Xiu | D18: CNKT | G18: =ROUND(F18*25000,0) -> 0 | H18: =+VLOOKUP(C18,'Mủ CN (TT)'!C12:AI45,33,0) -> 0 | J18: =+VLOOKUP(C18,'Mủ CN (TT)'!C12:AK89,35,0) -> 0 | K18: 0 | L18: =+VLOOKUP(C18,'Mủ CN (TT)'!C12:AL89,36,0) -> A | M18: =ROUND(J18*IF(L18="A",(6.1*$E$12),IF(L18="B",(5.8*$E$12),IF(L18="C",(5.5*$E$12),IF(L18="D",(5.2*$E$12))))),0) -> 0 | N18: =+VLOOKUP(C18,'Chấm công CN'!B12:AJ45,34,0) -> 3 | O18: =+VLOOKUP(C18,'Chấm công CN'!$B$12:$AJ$45,35,0) -> 2 | P18: =+N18+O18 -> 5 | R18: 500000 | S18: =ROUND((N18*(46.1*$E$10))+(O18*(76.9*$E$10))+(P18*20000)+(Q18*30.7*$E$10),0)+R18+0.18 -> 791559.18 | T18: =+G18+M18+S18 -> 791559.18 | W18: =+T18-U18 -> 791559.18
A19: 2 | C19: A Nhợp | D19: CNKT | G19: =ROUND(F19*25000,0) -> 0 | H19: =+VLOOKUP(C19,'Mủ CN (TT)'!C13:AI46,33,0) -> 61 | J19: =+VLOOKUP(C19,'Mủ CN (TT)'!C13:AK90,35,0) -> 34.670523 | K19: 34.162995 | L19: =+VLOOKUP(C19,'Mủ CN (TT)'!C13:AL90,36,0) -> A | M19: =ROUND(J19*IF(L19="A",(6.1*$E$12),IF(L19="B",(5.8*$E$12),IF(L19="C",(5.5*$E$12),IF(L19="D",(5.2*$E$12))))),0) -> 136665 | N19: =+VLOOKUP(C19,'Chấm công CN'!B13:AJ46,34,0) -> 12 | O19: =+VLOOKUP(C19,'Chấm công CN'!$B$12:$AJ$45,35,0) -> 3 | P19: =+N19+O19 -> 15 | R19: 500000 | S19: =ROUND((N19*(46.1*$E$10))+(O19*(76.9*$E$10))+(P19*20000)+(Q19*30.7*$E$10),0)+R19-0.38 -> 1314081.6 | T19: =+G19+M19+S19 -> 1450746.6 | W19: =+T19-U19 -> 1450746.6
A20: 3 | C20: A Chan | D20: CNKT | G20: =ROUND(F20*25000,0) -> 0 | H20: =+VLOOKUP(C20,'Mủ CN (TT)'!C14:AI47,33,0) -> 6 | J20: =+VLOOKUP(C20,'Mủ CN (TT)'!C14:AK91,35,0) -> 3.4102154 | K20: 3.3602946 | L20: =+VLOOKUP(C20,'Mủ CN (TT)'!C14:AL91,36,0) -> A | M20: =ROUND(J20*IF(L20="A",(6.1*$E$12),IF(L20="B",(5.8*$E$12),IF(L20="C",(5.5*$E$12),IF(L20="D",(5.2*$E$12))))),0) -> 13442 | N20: =+VLOOKUP(C20,'Chấm công CN'!B14:AJ47,34,0) -> 12 | O20: =+VLOOKUP(C20,'Chấm công CN'!$B$12:$AJ$45,35,0) -> 3 | P20: =+N20+O20 -> 15 | R20: 500000 | S20: =ROUND((N20*(46.1*$E$10))+(O20*(76.9*$E$10))+(P20*20000)+(Q20*30.7*$E$10),0)+R20-0.38 -> 1314081.6 | T20: =+G20+M20+S20 -> 1327523.6 | W20: =+T20-U20 -> 1327523.6
A21: 4 | C21: Phò Đùa | D21: CNKT | G21: =ROUND(F21*25000,0) -> 0 | H21: =+VLOOKUP(C21,'Mủ CN (TT)'!C15:AI48,33,0) -> 25 | J21: =+VLOOKUP(C21,'Mủ CN (TT)'!C15:AK92,35,0) -> 14.209231 | K21: 14.001228 | L21: =+VLOOKUP(C21,'Mủ CN (TT)'!C15:AL92,36,0) -> A | M21: =ROUND(J21*IF(L21="A",(6.1*$E$12),IF(L21="B",(5.8*$E$12),IF(L21="C",(5.5*$E$12),IF(L21="D",(5.2*$E$12))))),0) -> 56010 | N21: =+VLOOKUP(C21,'Chấm công CN'!B15:AJ48,34,0) -> 10 | O21: =+VLOOKUP(C21,'Chấm công CN'!$B$12:$AJ$45,35,0) -> 3 | P21: =+N21+O21 -> 13 | R21: 500000 | S21: =ROUND((N21*(46.1*$E$10))+(O21*(76.9*$E$10))+(P21*20000)+(Q21*30.7*$E$10),0)+R21-0.14 -> 1213616.9 | T21: =+G21+M21+S21 -> 1269626.9 | W21: =+T21-U21 -> 1269626.9
A22: 5 | C22: Xúc | D22: CNKT | G22: =ROUND(F22*25000,0) -> 0 | H22: =+VLOOKUP(C22,'Mủ CN (TT)'!C16:AI49,33,0) -> 0 | J22: =+VLOOKUP(C22,'Mủ CN (TT)'!C16:AK93,35,0) -> 0 | K22: 0 | L22: =+VLOOKUP(C22,'Mủ CN (TT)'!C16:AL93,36,0) -> A | M22: =ROUND(J22*IF(L22="A",(6.1*$E$12),IF(L22="B",(5.8*$E$12),IF(L22="C",(5.5*$E$12),IF(L22="D",(5.2*$E$12))))),0) -> 0 | N22: =+VLOOKUP(C22,'Chấm công CN'!B16:AJ49,34,0) -> 12 | O22: =+VLOOKUP(C22,'Chấm công CN'!$B$12:$AJ$45,35,0) -> 2 | P22: =+N22+O22 -> 14 | R22: 500000 | S22: =ROUND((N22*(46.1*$E$10))+(O22*(76.9*$E$10))+(P22*20000)+(Q22*30.7*$E$10),0)+R22-0.4 -> 1243650.6 | T22: =+G22+M22+S22 -> 1243650.6 | W22: =+T22-U22 -> 1243650.6
A23: 6 | C23: Phơ | D23: CNKT | G23: =ROUND(F23*25000,0) -> 0 | H23: =+VLOOKUP(C23,'Mủ CN (TT)'!C17:AI50,33,0) -> 0 | J23: =+VLOOKUP(C23,'Mủ CN (TT)'!C17:AK94,35,0) -> 0 | K23: 0 | L23: =+VLOOKUP(C23,'Mủ CN (TT)'!C17:AL94,36,0) -> A | M23: =ROUND(J23*IF(L23="A",(6.1*$E$12),IF(L23="B",(5.8*$E$12),IF(L23="C",(5.5*$E$12),IF(L23="D",(5.2*$E$12))))),0) -> 0 | N23: =+VLOOKUP(C23,'Chấm công CN'!B17:AJ50,34,0) -> 12 | O23: =+VLOOKUP(C23,'Chấm công CN'!$B$12:$AJ$45,35,0) -> 3 | P23: =+N23+O23 -> 15 | R23: 500000 | S23: =ROUND((N23*(46.1*$E$10))+(O23*(76.9*$E$10))+(P23*20000)+(Q23*30.7*$E$10),0)+R23-0.38 -> 1314081.6 | T23: =+G23+M23+S23 -> 1314081.6 | W23: =+T23-U23 -> 1314081.6
A24: 7 | C24: A Phơ | D24: CNKT | G24: =ROUND(F24*25000,0) -> 0 | H24: =+VLOOKUP(C24,'Mủ CN (TT)'!C18:AI51,33,0) -> 40 | J24: =+VLOOKUP(C24,'Mủ CN (TT)'!C18:AK95,35,0) -> 22.734769 | K24: 22.401964 | L24: =+VLOOKUP(C24,'Mủ CN (TT)'!C18:AL95,36,0) -> A | M24: =ROUND(J24*IF(L24="A",(6.1*$E$12),IF(L24="B",(5.8*$E$12),IF(L24="C",(5.5*$E$12),IF(L24="D",(5.2*$E$12))))),0) -> 89616 | N24: =+VLOOKUP(C24,'Chấm công CN'!B18:AJ51,34,0) -> 12 | O24: =+VLOOKUP(C24,'Chấm công CN'!$B$12:$AJ$45,35,0) -> 3 | P24: =+N24+O24 -> 15 | R24: 500000 | S24: =ROUND((N24*(46.1*$E$10))+(O24*(76.9*$E$10))+(P24*20000)+(Q24*30.7*$E$10),0)+R24-0.38 -> 1314081.6 | T24: =+G24+M24+S24 -> 1403697.6 | W24: =+T24-U24 -> 1403697.6
A25: 8 | C25: Nang Xây | D25: CNKT | G25: =ROUND(F25*25000,0) -> 0 | H25: =+VLOOKUP(C25,'Mủ CN (TT)'!C19:AI52,33,0) -> 20 | J25: =+VLOOKUP(C25,'Mủ CN (TT)'!C19:AK96,35,0) -> 11.367385 | K25: 11.200982 | L25: =+VLOOKUP(C25,'Mủ CN (TT)'!C19:AL96,36,0) -> A | M25: =ROUND(J25*IF(L25="A",(6.1*$E$12),IF(L25="B",(5.8*$E$12),IF(L25="C",(5.5*$E$12),IF(L25="D",(5.2*$E$12))))),0) -> 44808 | N25: =+VLOOKUP(C25,'Chấm công CN'!B19:AJ52,34,0) -> 12 | O25: =+VLOOKUP(C25,'Chấm công CN'!$B$12:$AJ$45,35,0) -> 3 | P25: =+N25+O25 -> 15 | R25: 500000 | S25: =ROUND((N25*(46.1*$E$10))+(O25*(76.9*$E$10))+(P25*20000)+(Q25*30.7*$E$10),0)+R25-0.38 -> 1314081.6 | T25: =+G25+M25+S25 -> 1358889.6 | W25: =+T25-U25 -> 1358889.6
A26: 9 | C26: Nang Sun | D26: CNKT | G26: =ROUND(F26*25000,0) -> 0 | H26: =+VLOOKUP(C26,'Mủ CN (TT)'!C20:AI53,33,0) -> 11 | J26: =+VLOOKUP(C26,'Mủ CN (TT)'!C20:AK97,35,0) -> 6.2520616 | K26: 6.1605401 | L26: =+VLOOKUP(C26,'Mủ CN (TT)'!C20:AL97,36,0) -> A | M26: =ROUND(J26*IF(L26="A",(6.1*$E$12),IF(L26="B",(5.8*$E$12),IF(L26="C",(5.5*$E$12),IF(L26="D",(5.2*$E$12))))),0) -> 24645 | N26: =+VLOOKUP(C26,'Chấm công CN'!B20:AJ53,34,0) -> 12 | O26: =+VLOOKUP(C26,'Chấm công CN'!$B$12:$AJ$45,35,0) -> 3 | P26: =+N26+O26 -> 15 | R26: 500000 | S26: =ROUND((N26*(46.1*$E$10))+(O26*(76.9*$E$10))+(P26*20000)+(Q26*30.7*$E$10),0)+R26-0.38 -> 1314081.6 | T26: =+G26+M26+S26 -> 1338726.6 | W26: =+T26-U26 -> 1338726.6
A27: 10 | C27: Thảo Ben | D27: CNKT | G27: =ROUND(F27*25000,0) -> 0 | H27: =+VLOOKUP(C27,'Mủ CN (TT)'!C21:AI54,33,0) -> 6 | J27: =+VLOOKUP(C27,'Mủ CN (TT)'!C21:AK98,35,0) -> 3.4102154 | K27: 3.3602946 | L27: =+VLOOKUP(C27,'Mủ CN (TT)'!C21:AL98,36,0) -> A | M27: =ROUND(J27*IF(L27="A",(6.1*$E$12),IF(L27="B",(5.8*$E$12),IF(L27="C",(5.5*$E$12),IF(L27="D",(5.2*$E$12))))),0) -> 13442 | N27: =+VLOOKUP(C27,'Chấm công CN'!B21:AJ54,34,0) -> 12 | O27: =+VLOOKUP(C27,'Chấm công CN'!$B$12:$AJ$45,35,0) -> 3 | P27: =+N27+O27 -> 15 | R27: 500000 | S27: =ROUND((N27*(46.1*$E$10))+(O27*(76.9*$E$10))+(P27*20000)+(Q27*30.7*$E$10),0)+R27-0.38 -> 1314081.6 | T27: =+G27+M27+S27 -> 1327523.6 | W27: =+T27-U27 -> 1327523.6
A28: 11 | C28: Nang Nhăn | D28: CNKT | G28: =ROUND(F28*25000,0) -> 0 | H28: =+VLOOKUP(C28,'Mủ CN (TT)'!C22:AI55,33,0) -> 24 | J28: =+VLOOKUP(C28,'Mủ CN (TT)'!C22:AK99,35,0) -> 13.640862 | K28: 13.441178 | L28: =+VLOOKUP(C28,'Mủ CN (TT)'!C22:AL99,36,0) -> A | M28: =ROUND(J28*IF(L28="A",(6.1*$E$12),IF(L28="B",(5.8*$E$12),IF(L28="C",(5.5*$E$12),IF(L28="D",(5.2*$E$12))))),0) -> 53770 | N28: =+VLOOKUP(C28,'Chấm công CN'!B22:AJ55,34,0) -> 12 | O28: =+VLOOKUP(C28,'Chấm công CN'!$B$12:$AJ$45,35,0) -> 3 | P28: =+N28+O28 -> 15 | R28: 500000 | S28: =ROUND((N28*(46.1*$E$10))+(O28*(76.9*$E$10))+(P28*20000)+(Q28*30.7*$E$10),0)+R28-0.38 -> 1314081.6 | T28: =+G28+M28+S28 -> 1367851.6 | W28: =+T28-U28 -> 1367851.6
A29: 12 | C29: Phò Thít | D29: CNKT | G29: =ROUND(F29*25000,0) -> 0 | H29: =+VLOOKUP(C29,'Mủ CN (TT)'!C23:AI56,33,0) -> 60 | J29: =+VLOOKUP(C29,'Mủ CN (TT)'!C23:AK100,35,0) -> 34.102154 | K29: 33.602946 | L29: =+VLOOKUP(C29,'Mủ CN (TT)'!C23:AL100,36,0) -> A | M29: =ROUND(J29*IF(L29="A",(6.1*$E$12),IF(L29="B",(5.8*$E$12),IF(L29="C",(5.5*$E$12),IF(L29="D",(5.2*$E$12))))),0) -> 134425 | N29: =+VLOOKUP(C29,'Chấm công CN'!B23:AJ56,34,0) -> 12 | O29: =+VLOOKUP(C29,'Chấm công CN'!$B$12:$AJ$45,35,0) -> 3 | P29: =+N29+O29 -> 15 | R29: 500000 | S29: =ROUND((N29*(46.1*$E$10))+(O29*(76.9*$E$10))+(P29*20000)+(Q29*30.7*$E$10),0)+R29-0.38 -> 1314081.6 | T29: =+G29+M29+S29 -> 1448506.6 | W29: =+T29-U29 -> 1448506.6
A30: 13 | C30: A Bợp | D30: CNKT | G30: =ROUND(F30*25000,0) -> 0 | H30: =+VLOOKUP(C30,'Mủ CN (TT)'!C24:AI57,33,0) -> 40 | J30: =+VLOOKUP(C30,'Mủ CN (TT)'!C24:AK101,35,0) -> 22.734769 | K30: 22.401964 | L30: =+VLOOKUP(C30,'Mủ CN (TT)'!C24:AL101,36,0) -> A | M30: =ROUND(J30*IF(L30="A",(6.1*$E$12),IF(L30="B",(5.8*$E$12),IF(L30="C",(5.5*$E$12),IF(L30="D",(5.2*$E$12))))),0) -> 89616 | N30: =+VLOOKUP(C30,'Chấm công CN'!B24:AJ57,34,0) -> 11 | O30: =+VLOOKUP(C30,'Chấm công CN'!$B$12:$AJ$45,35,0) -> 3 | P30: =+N30+O30 -> 14 | R30: 500000 | S30: =ROUND((N30*(46.1*$E$10))+(O30*(76.9*$E$10))+(P30*20000)+(Q30*30.7*$E$10),0)+R30+0.24 -> 1263849.2 | T30: =+G30+M30+S30 -> 1353465.2 | W30: =+T30-U30 -> 1353465.2
A31: 14 | C31: A Cơ | D31: CNKT | G31: =ROUND(F31*25000,0) -> 0 | H31: =+VLOOKUP(C31,'Mủ CN (TT)'!C25:AI58,33,0) -> 0 | J31: =+VLOOKUP(C31,'Mủ CN (TT)'!C25:AK102,35,0) -> 0 | K31: 0 | L31: =+VLOOKUP(C31,'Mủ CN (TT)'!C25:AL102,36,0) -> A | M31: =ROUND(J31*IF(L31="A",(6.1*$E$12),IF(L31="B",(5.8*$E$12),IF(L31="C",(5.5*$E$12),IF(L31="D",(5.2*$E$12))))),0) -> 0 | N31: =+VLOOKUP(C31,'Chấm công CN'!B25:AJ58,34,0) -> 12 | O31: =+VLOOKUP(C31,'Chấm công CN'!$B$12:$AJ$45,35,0) -> 3 | P31: =+N31+O31 -> 15 | R31: 500000 | S31: =ROUND((N31*(46.1*$E$10))+(O31*(76.9*$E$10))+(P31*20000)+(Q31*30.7*$E$10),0)+R31-0.38 -> 1314081.6 | T31: =+G31+M31+S31 -> 1314081.6 | W31: =+T31-U31 -> 1314081.6
A32: 15 | C32: Xa Vạt Đi | D32: CNKT | G32: =ROUND(F32*25000,0) -> 0 | H32: =+VLOOKUP(C32,'Mủ CN (TT)'!C26:AI59,33,0) -> 35 | J32: =+VLOOKUP(C32,'Mủ CN (TT)'!C26:AK103,35,0) -> 19.892923 | K32: 19.601719 | L32: =+VLOOKUP(C32,'Mủ CN (TT)'!C26:AL103,36,0) -> A | M32: =ROUND(J32*IF(L32="A",(6.1*$E$12),IF(L32="B",(5.8*$E$12),IF(L32="C",(5.5*$E$12),IF(L32="D",(5.2*$E$12))))),0) -> 78414 | N32: =+VLOOKUP(C32,'Chấm công CN'!B26:AJ59,34,0) -> 12 | O32: =+VLOOKUP(C32,'Chấm công CN'!$B$12:$AJ$45,35,0) -> 3 | P32: =+N32+O32 -> 15 | R32: 500000 | S32: =ROUND((N32*(46.1*$E$10))+(O32*(76.9*$E$10))+(P32*20000)+(Q32*30.7*$E$10),0)+R32-0.38 -> 1314081.6 | T32: =+G32+M32+S32 -> 1392495.6 | W32: =+T32-U32 -> 1392495.6
A33: 16 | C33: Nguyễn Thi Thanh Trà | D33: CNKT | G33: =ROUND(F33*25000,0) -> 0 | H33: =+VLOOKUP(C33,'Mủ CN (TT)'!C27:AI60,33,0) -> 97 | J33: =+VLOOKUP(C33,'Mủ CN (TT)'!C27:AK104,35,0) -> 55.131816 | K33: 54.324763 | L33: =+VLOOKUP(C33,'Mủ CN (TT)'!C27:AL104,36,0) -> A | M33: =ROUND(J33*IF(L33="A",(6.1*$E$12),IF(L33="B",(5.8*$E$12),IF(L33="C",(5.5*$E$12),IF(L33="D",(5.2*$E$12))))),0) -> 217320 | N33: =+VLOOKUP(C33,'Chấm công CN'!B27:AJ60,34,0) -> 12 | O33: =+VLOOKUP(C33,'Chấm công CN'!$B$12:$AJ$45,35,0) -> 3 | P33: =+N33+O33 -> 15 | R33: 500000 | S33: =ROUND((N33*(46.1*$E$10))+(O33*(76.9*$E$10))+(P33*20000)+(Q33*30.7*$E$10),0)+R33-0.38 -> 1314081.6 | T33: =+G33+M33+S33 -> 1531401.6 | W33: =+T33-U33 -> 1531401.6
A34: 17 | C34: A Han | D34: CNKT | G34: =ROUND(F34*25000,0) -> 0 | H34: =+VLOOKUP(C34,'Mủ CN (TT)'!C28:AI61,33,0) -> 7 | J34: =+VLOOKUP(C34,'Mủ CN (TT)'!C28:AK105,35,0) -> 3.9785846 | K34: 3.9203437 | L34: =+VLOOKUP(C34,'Mủ CN (TT)'!C28:AL105,36,0) -> A | M34: =ROUND(J34*IF(L34="A",(6.1*$E$12),IF(L34="B",(5.8*$E$12),IF(L34="C",(5.5*$E$12),IF(L34="D",(5.2*$E$12))))),0) -> 15683 | N34: =+VLOOKUP(C34,'Chấm công CN'!B28:AJ61,34,0) -> 12 | O34: =+VLOOKUP(C34,'Chấm công CN'!$B$12:$AJ$45,35,0) -> 3 | P34: =+N34+O34 -> 15 | R34: 500000 | S34: =ROUND((N34*(46.1*$E$10))+(O34*(76.9*$E$10))+(P34*20000)+(Q34*30.7*$E$10),0)+R34-0.38 -> 1314081.6 | T34: =+G34+M34+S34 -> 1329764.6 | W34: =+T34-U34 -> 1329764.6
A35: 18 | C35: Thảo Bun Ten | D35: CNKT | G35: =ROUND(F35*25000,0) -> 0 | H35: =+VLOOKUP(C35,'Mủ CN (TT)'!C29:AI62,33,0) -> 44 | J35: =+VLOOKUP(C35,'Mủ CN (TT)'!C29:AK106,35,0) -> 25.008246 | K35: 24.64216 | L35: =+VLOOKUP(C35,'Mủ CN (TT)'!C29:AL106,36,0) -> A | M35: =ROUND(J35*IF(L35="A",(6.1*$E$12),IF(L35="B",(5.8*$E$12),IF(L35="C",(5.5*$E$12),IF(L35="D",(5.2*$E$12))))),0) -> 98578 | N35: =+VLOOKUP(C35,'Chấm công CN'!B29:AJ62,34,0) -> 12 | O35: =+VLOOKUP(C35,'Chấm công CN'!$B$12:$AJ$45,35,0) -> 3 | P35: =+N35+O35 -> 15 | R35: 500000 | S35: =ROUND((N35*(46.1*$E$10))+(O35*(76.9*$E$10))+(P35*20000)+(Q35*30.7*$E$10),0)+R35-0.38 -> 1314081.6 | T35: =+G35+M35+S35 -> 1412659.6 | W35: =+T35-U35 -> 1412659.6
