Workbook

Sheet Chấm công KT
B1: CỘNG HÒA DÂN CHỦ NHÂN DÂN LÀO
B2: Hòa Bình -Độc Lập - Dân Chủ - thống Nhất - Thịnh Vượng
B3: -----o0o-----
B5: CÔNG TY TNHH MTV QUASA - GERUCO LÀO
B6: ĐỘI SẢN XUẤT SỐ 04
B7: BẢNG CHẤM CÔNG PHỤ CẤP CHO CÔNG NHÂN KHAI THÁC THÁNG 09 NĂM 2025
A8: (Từ ngày 01/09 đến 30/09/2025)
A10: STT | C10: MSNV | D10: HỌ VÀ TÊN | E10: Kí tên | F10: Phụ cấp ngày cạo, ngày chủ nhật | AK10: Ngày công đi cạo thường | AL10: Ngày CN thường | AM10: Ngày công đi cạo 2 lát (đ) | AN10: Ngày công chủ nhật cạo 2 lát (đc) | AO10: Ngày công cạo gia tăng 2 miêng (gt) | AP10: Ngày chủ nhật cạo gia tăng 2 miệng (ct) | AQ10: Tổng công | AU10: Ngày công đi cạo thường (x) | AV10: Ngày CN thường (cn) | AW10: Ngày công đi cạo 2 lát (đ) | AX10: Ngày công chủ nhật cạo 2 lát (đc) | AY10: Ngày công cạo gia tăng 2 miêng (gt) | AZ10: Ngày chủ nhật cạo gia tăng 2 miệng (ct)
F11: 1 | G11: 2 | H11: 3 | I11: 4 | J11: 5 | K11: 6 | L11: 7 | M11: 8 | N11: 9 | O11: 10 | P11: 11 | Q11: 12 | R11: 13 | S11: 14 | T11: 15 | U11: 16 | V11: 17 | W11: 18 | X11: 19 | Y11: 20 | Z11: 21 | AA11: 22 | AB11: 23 | AC11: 24 | AD11: 25 | AE11: 26 | AF11: 27 | AG11: 28 | AH11: 29 | AI11: 30 | AJ11: 31
A12: Trạm 1 | F12: =SUM(COUNTIF(F13:F93,"x"))+(COUNTIF(F13:F93,"cn"))+(COUNTIF(F13:F93,"gt"))+(COUNTIF(F13:F93,"ct"))+(COUNTIF(F13:F93,"đ"))+(COUNTIF(F13:F93,"đc")) -> 73 | G12: =SUM(COUNTIF(G13:G93,"x"))+(COUNTIF(G13:G93,"cn"))+(COUNTIF(G13:G93,"gt"))+(COUNTIF(G13:G93,"ct"))+(COUNTIF(G13:G93,"đ"))+(COUNTIF(G13:G93,"đc")) -> 73 | H12: =SUM(COUNTIF(H13:H93,"x"))+(COUNTIF(H13:H93,"cn"))+(COUNTIF(H13:H93,"gt"))+(COUNTIF(H13:H93,"ct"))+(COUNTIF(H13:H93,"đ"))+(COUNTIF(H13:H93,"đc")) -> 73 | I12: =SUM(COUNTIF(I13:I93,"x"))+(COUNTIF(I13:I93,"cn"))+(COUNTIF(I13:I93,"gt"))+(COUNTIF(I13:I93,"ct"))+(COUNTIF(I13:I93,"đ"))+(COUNTIF(I13:I93,"đc")) -> 73 | J12: =SUM(COUNTIF(J13:J93,"x"))+(COUNTIF(J13:J93,"cn"))+(COUNTIF(J13:J93,"gt"))+(COUNTIF(J13:J93,"ct"))+(COUNTIF(J13:J93,"đ"))+(COUNTIF(J13:J93,"đc")) -> 73 | K12: =SUM(COUNTIF(K13:K93,"x"))+(COUNTIF(K13:K93,"cn"))+(COUNTIF(K13:K93,"gt"))+(COUNTIF(K13:K93,"ct"))+(COUNTIF(K13:K93,"đ"))+(COUNTIF(K13:K93,"đc")) -> 73 | L12: =SUM(COUNTIF(L13:L93,"x"))+(COUNTIF(L13:L93,"cn"))+(COUNTIF(L13:L93,"gt"))+(COUNTIF(L13:L93,"ct"))+(COUNTIF(L13:L93,"đ"))+(COUNTIF(L13:L93,"đc")) -> 73 | M12: =SUM(COUNTIF(M13:M93,"x"))+(COUNTIF(M13:M93,"cn"))+(COUNTIF(M13:M93,"gt"))+(COUNTIF(M13:M93,"ct"))+(COUNTIF(M13:M93,"đ"))+(COUNTIF(M13:M93,"đc")) -> 73 | ... AJ12: =SUM(COUNTIF(AJ13:AJ93,"x"))+(COUNTIF(AJ13:AJ93,"cn"))+(COUNTIF(AJ13:AJ93,"gt"))+(COUNTIF(AJ13:AJ93,"ct"))+(COUNTIF(AJ13:AJ93,"đ"))+(COUNTIF(AJ13:AJ93,"đc")) -> 0 | AK12: =SUM(AK13:AK93) -> 1865 | AL12: =SUM(AL13:AL93) -> 143 | AM12: =SUM(AM13:AM93) -> 0 | AN12: =SUM(AN13:AN93) -> 146 | AO12: =SUM(AO13:AO93) -> 0 | AP12: =SUM(AP13:AP93) -> 0 | AQ12: =SUM(AQ13:AQ93) -> 2154 | AS12: ='Mã số nhân viên'!I3 -> 03456 | AT12: =C13-AS12 -> -3456
A13: 1 | B13: 1 | D13: T. Lăm | F13: x | G13: x | H13: x | I13: x | J13: x | K13: x | L13: cn | M13: x | N13: x | O13: x | P13: x | Q13: x | R13: x | S13: đc | T13: x | U13: x | V13: x | W13: x | X13: x | Y13: x | Z13: đc | AA13: x | AB13: x | AC13: x | AD13: x | AE13: x | AI13: x | AK13: =SUM(COUNTIF(F13:AJ13,"x")) -> 24 | AL13: =SUM(COUNTIF(F13:AJ13,"cn")) -> 1 | AM13: =SUM(COUNTIF(F13:AJ13,"đ")) -> 0 | AN13: =SUM(COUNTIF(F13:AJ13,"đc")) -> 2 | AO13: =SUM(COUNTIF(F13:AJ13,"gt")) -> 0 | AP13: =SUM(COUNTIF(F13:AJ13,"ct")) -> 0 | AQ13: =AK13+AL13+AM13+AN13+AO13+AP13 -> 27 | AS13: ='Mã số nhân viên'!I4 -> 04052 | AT13: =C14-AS13 -> 0
A14: 2 | B14: 2 | C14: =VLOOKUP(D14,'Mã số nhân viên'!B4:I135,8,0) -> 04052 | D14: T. Feng | F14: x | G14: x | H14: x | I14: x | J14: x | K14: x | L14: cn | M14: x | N14: x | O14: x | P14: x | Q14: x | R14: x | S14: đc | T14: tt | U14: x | V14: x | W14: x | X14: x | Y14: x | Z14: đc | AA14: x | AB14: x | AC14: x | AD14: x | AF14: x | AH14: x | AI14: x | AK14: =SUM(COUNTIF(F14:AJ14,"x")) -> 24 | AL14: =SUM(COUNTIF(F14:AJ14,"cn")) -> 1 | AM14: =SUM(COUNTIF(F14:AJ14,"đ")) -> 0 | AN14: =SUM(COUNTIF(F14:AJ14,"đc")) -> 2 | AO14: =SUM(COUNTIF(F14:AJ14,"gt")) -> 0 | AP14: =SUM(COUNTIF(F14:AJ14,"ct")) -> 0 | AQ14: =AK14+AL14+AM14+AN14+AO14+AP14 -> 27 | AS14: ='Mã số nhân viên'!I5 -> 02725 | AT14: =C15-AS14 -> 0
A15: 3 | B15: 3 | C15: =VLOOKUP(D15,'Mã số nhân viên'!B5:I136,8,0) -> 02725 | D15: T. Sa Văn | F15: x | G15: x | H15: x | I15: x | J15: x | K15: x | L15: cn | M15: x | N15: x | O15: x | P15: x | Q15: x | R15: x | S15: đc | T15: x | U15: x | V15: x | W15: x | X15: x | Y15: x | Z15: đc | AA15: x | AB15: x | AC15: x | AE15: x | AG15: cn | AH15: x | AI15: x | AK15: =SUM(COUNTIF(F15:AJ15,"x")) -> 24 | AL15: =SUM(COUNTIF(F15:AJ15,"cn")) -> 2 | AM15: =SUM(COUNTIF(F15:AJ15,"đ")) -> 0 | AN15: =SUM(COUNTIF(F15:AJ15,"đc")) -> 2 | AO15: =SUM(COUNTIF(F15:AJ15,"gt")) -> 0 | AP15: =SUM(COUNTIF(F15:AJ15,"ct")) -> 0 | AQ15: =AK15+AL15+AM15+AN15+AO15+AP15 -> 28 | AS15: ='Mã số nhân viên'!I6 -> 04053 | AT15: =C16-AS15 -> 0
A16: 4 | B16: 4 | C16: =VLOOKUP(D16,'Mã số nhân viên'!B6:I137,8,0) -> 04053 | D16: Lăm Ma Thu | F16: x | G16: x | H16: x | I16: x | J16: x | K16: x | L16: cn | M16: x | N16: x | O16: x | P16: x | Q16: x | R16: x | S16: đc | T16: x | U16: x | V16: x | W16: x | X16: x | Y16: x | Z16: đc | AA16: x | AB16: x | AC16: x | AD16: x | AE16: x | AF16: x | AG16: cn | AH16: x | AI16: x | AK16: =SUM(COUNTIF(F16:AJ16,"x")) -> 26 | AL16: =SUM(COUNTIF(F16:AJ16,"cn")) -> 2 | AM16: =SUM(COUNTIF(F16:AJ16,"đ")) -> 0 | AN16: =SUM(COUNTIF(F16:AJ16,"đc")) -> 2 | AO16: =SUM(COUNTIF(F16:AJ16,"gt")) -> 0 | AP16: =SUM(COUNTIF(F16:AJ16,"ct")) -> 0 | AQ16: =AK16+AL16+AM16+AN16+AO16+AP16 -> 30 | AS16: ='Mã số nhân viên'!I7 -> 03459 | AT16: =C17-AS16 -> 0
A17: 5 | B17: 5 | C17: =VLOOKUP(D17,'Mã số nhân viên'!B7:I138,8,0) -> 03459 | D17: N. Vạt | F17: x | G17: x | H17: x | I17: x | J17: x | K17: x | L17: cn | M17: x | N17: x | O17: x | P17: x | Q17: x | R17: x | S17: đc | T17: x | U17: x | V17: x | W17: tt | X17: x | Y17: x | Z17: đc | AA17: x | AB17: x | AC17: x | AD17: x | AE17: x | AG17: cn | AH17: x | AI17: x | AK17: =SUM(COUNTIF(F17:AJ17,"x")) -> 24 | AL17: =SUM(COUNTIF(F17:AJ17,"cn")) -> 2 | AM17: =SUM(COUNTIF(F17:AJ17,"đ")) -> 0 | AN17: =SUM(COUNTIF(F17:AJ17,"đc")) -> 2 | AO17: =SUM(COUNTIF(F17:AJ17,"gt")) -> 0 | AP17: =SUM(COUNTIF(F17:AJ17,"ct")) -> 0 | AQ17: =AK17+AL17+AM17+AN17+AO17+AP17 -> 28 | AS17: ='Mã số nhân viên'!I8 -> 04054 | AT17: =C18-AS17 -> 0
A18: 6 | B18: 6 | C18: =VLOOKUP(D18,'Mã số nhân viên'!B8:I139,8,0) -> 04054 | D18: N. Kay Son | F18: x | G18: x | H18: x | I18: x | J18: x | K18: x | L18: cn | M18: x | N18: x | O18: x | P18: x | Q18: x | R18: x | S18: đc | T18: x | U18: x | V18: x | W18: x | X18: x | Y18: x | Z18: đc | AA18: x | AB18: x | AC18: x | AD18: x | AE18: x | AF18: x | AG18: cn | AH18: x | AK18: =SUM(COUNTIF(F18:AJ18,"x")) -> 25 | AL18: =SUM(COUNTIF(F18:AJ18,"cn")) -> 2 | AM18: =SUM(COUNTIF(F18:AJ18,"đ")) -> 0 | AN18: =SUM(COUNTIF(F18:AJ18,"đc")) -> 2 | AO18: =SUM(COUNTIF(F18:AJ18,"gt")) -> 0 | AP18: =SUM(COUNTIF(F18:AJ18,"ct")) -> 0 | AQ18: =AK18+AL18+AM18+AN18+AO18+AP18 -> 29 | AS18: ='Mã số nhân viên'!I9 -> 04055 | AT18: =C19-AS18 -> 0
A19: 7 | B19: 7 | C19: =VLOOKUP(D19,'Mã số nhân viên'!B9:I140,8,0) -> 04055 | D19: T. Đèng 1 | F19: x | G19: x | H19: x | I19: x | J19: x | K19: x | L19: cn | M19: x | N19: x | O19: x | P19: x | Q19: x | R19: x | S19: đc | T19: x | U19: x | V19: x | W19: x | X19: x | Y19: x | Z19: đc | AA19: x | AB19: x | AC19: x | AD19: x | AE19: x | AF19: x | AG19: cn | AH19: x | AI19: x | AK19: =SUM(COUNTIF(F19:AJ19,"x")) -> 26 | AL19: =SUM(COUNTIF(F19:AJ19,"cn")) -> 2 | AM19: =SUM(COUNTIF(F19:AJ19,"đ")) -> 0 | AN19: =SUM(COUNTIF(F19:AJ19,"đc")) -> 2 | AO19: =SUM(COUNTIF(F19:AJ19,"gt")) -> 0 | AP19: =SUM(COUNTIF(F19:AJ19,"ct")) -> 0 | AQ19: =AK19+AL19+AM19+AN19+AO19+AP19 -> 30 | AS19: ='Mã số nhân viên'!I10 -> 03462 | AT19: =C20-AS19 -> 0
A20: 8 | B20: 8 | C20: =VLOOKUP(D20,'Mã số nhân viên'!B10:I141,8,0) -> 03462 | D20: T . Bua Ngân | F20: x | G20: x | H20: x | I20: x | J20: x | K20: x | L20: cn | M20: x | N20: x | O20: x | P20: x | Q20: x | R20: x | S20: đc | T20: x | U20: x | V20: x | W20: x | X20: x | Y20: x | Z20: đc | AA20: x | AB20: x | AC20: x | AD20: x | AE20: x | AG20: cn | AH20: x | AI20: x | AK20: =SUM(COUNTIF(F20:AJ20,"x")) -> 25 | AL20: =SUM(COUNTIF(F20:AJ20,"cn")) -> 2 | AM20: =SUM(COUNTIF(F20:AJ20,"đ")) -> 0 | AN20: =SUM(COUNTIF(F20:AJ20,"đc")) -> 2 | AO20: =SUM(COUNTIF(F20:AJ20,"gt")) -> 0 | AP20: =SUM(COUNTIF(F20:AJ20,"ct")) -> 0 | AQ20: =AK20+AL20+AM20+AN20+AO20+AP20 -> 29 | AS20: ='Mã số nhân viên'!I11 -> 03463 | AT20: =C21-AS20 -> 0
A21: 9 | B21: 9 | C21: =VLOOKUP(D21,'Mã số nhân viên'!B11:I142,8,0) -> 03463 | D21: T Căng | F21: x | G21: x | H21: x | I21: x | J21: x | K21: x | L21: cn | M21: x | N21: x | O21: x | P21: x | Q21: x | R21: x | S21: đc | T21: x | U21: x | V21: x | W21: x | X21: x | Y21: x | Z21: đc | AA21: x | AB21: x | AC21: x | AD21: x | AE21: x | AG21: cn | AH21: x | AI21: x | AK21: =SUM(COUNTIF(F21:AJ21,"x")) -> 25 | AL21: =SUM(COUNTIF(F21:AJ21,"cn")) -> 2 | AM21: =SUM(COUNTIF(F21:AJ21,"đ")) -> 0 | AN21: =SUM(COUNTIF(F21:AJ21,"đc")) -> 2 | AO21: =SUM(COUNTIF(F21:AJ21,"gt")) -> 0 | AP21: =SUM(COUNTIF(F21:AJ21,"ct")) -> 0 | AQ21: =AK21+AL21+AM21+AN21+AO21+AP21 -> 29 | AS21: ='Mã số nhân viên'!I12 -> 03464 | AT21: =C22-AS21 -> 0
A22: 10 | B22: 10 | C22: =VLOOKUP(D22,'Mã số nhân viên'!B12:I143,8,0) -> 03464 | D22: N. Phôn 1 | F22: x | G22: x | H22: x | I22: x | J22: x | K22: x | L22: cn | M22: x | N22: x | O22: x | P22: x | Q22: x | R22: x | S22: đc | T22: x | U22: x | V22: x | W22: x | X22: x | Y22: x | Z22: đc | AA22: x | AB22: x | AC22: x | AD22: x | AE22: x | AG22: cn | AH22: x | AI22: x | AK22: =SUM(COUNTIF(F22:AJ22,"x")) -> 25 | AL22: =SUM(COUNTIF(F22:AJ22,"cn")) -> 2 | AM22: =SUM(COUNTIF(F22:AJ22,"đ")) -> 0 | AN22: =SUM(COUNTIF(F22:AJ22,"đc")) -> 2 | AO22: =SUM(COUNTIF(F22:AJ22,"gt")) -> 0 | AP22: =SUM(COUNTIF(F22:AJ22,"ct")) -> 0 | AQ22: =AK22+AL22+AM22+AN22+AO22+AP22 -> 29 | AS22: ='Mã số nhân viên'!I13 -> 03465 | AT22: =C23-AS22 -> 0
A23: 11 | B23: 11 | C23: =VLOOKUP(D23,'Mã số nhân viên'!B13:I144,8,0) -> 03465 | D23: T. In Păn | F23: x | G23: x | H23: x | I23: x | J23: x | K23: x | L23: cn | M23: x | N23: x | O23: x | P23: x | Q23: x | R23: x | S23: đc | T23: x | U23: x | V23: x | W23: x | X23: x | Y23: x | Z23: đc | AA23: x | AB23: x | AC23: x | AD23: x | AF23: x | AG23: cn | AH23: x | AI23: x | AK23: =SUM(COUNTIF(F23:AJ23,"x")) -> 25 | AL23: =SUM(COUNTIF(F23:AJ23,"cn")) -> 2 | AM23: =SUM(COUNTIF(F23:AJ23,"đ")) -> 0 | AN23: =SUM(COUNTIF(F23:AJ23,"đc")) -> 2 | AO23: =SUM(COUNTIF(F23:AJ23,"gt")) -> 0 | AP23: =SUM(COUNTIF(F23:AJ23,"ct")) -> 0 | AQ23: =AK23+AL23+AM23+AN23+AO23+AP23 -> 29 | AS23: ='Mã số nhân viên'!I14 -> 03466 | AT23: =C24-AS23 -> 0
A24: 12 | B24: 12 | C24: =VLOOKUP(D24,'Mã số nhân viên'!B14:I145,8,0) -> 03466 | D24: N. Keo | F24: x | G24: x | H24: x | I24: x | J24: x | K24: x | L24: cn | M24: x | N24: x | O24: x | P24: x | Q24: x | R24: x | S24: đc | T24: x | U24: x | V24: x | W24: x | X24: x | Y24: x | Z24: đc | AA24: x | AB24: x | AC24: x | AD24: x | AE24: x | AF24: x | AG24: cn | AH24: x | AI24: x | AK24: =SUM(COUNTIF(F24:AJ24,"x")) -> 26 | AL24: =SUM(COUNTIF(F24:AJ24,"cn")) -> 2 | AM24: =SUM(COUNTIF(F24:AJ24,"đ")) -> 0 | AN24: =SUM(COUNTIF(F24:AJ24,"đc")) -> 2 | AO24: =SUM(COUNTIF(F24:AJ24,"gt")) -> 0 | AP24: =SUM(COUNTIF(F24:AJ24,"ct")) -> 0 | AQ24: =AK24+AL24+AM24+AN24+AO24+AP24 -> 30 | AS24: ='Mã số nhân viên'!I15 -> 02727 | AT24: =C25-AS24 -> 0
A25: 13 | B25: 13 | C25: =VLOOKUP(D25,'Mã số nhân viên'!B15:I146,8,0) -> 02727 | D25: T. Thong Đon | F25: x | G25: x | H25: x | I25: x | J25: x | K25: x | L25: cn | M25: x | N25: x | O25: x | P25: x | Q25: x | R25: x | S25: đc | T25: x | U25: x | V25: x | W25: x | X25: x | Y25: x | Z25: đc | AA25: x | AB25: x | AC25: x | AD25: x | AF25: x | AG25: cn | AH25: x | AI25: x | AK25: =SUM(COUNTIF(F25:AJ25,"x")) -> 25 | AL25: =SUM(COUNTIF(F25:AJ25,"cn")) -> 2 | AM25: =SUM(COUNTIF(F25:AJ25,"đ")) -> 0 | AN25: =SUM(COUNTIF(F25:AJ25,"đc")) -> 2 | AO25: =SUM(COUNTIF(F25:AJ25,"gt")) -> 0 | AP25: =SUM(COUNTIF(F25:AJ25,"ct")) -> 0 | AQ25: =AK25+AL25+AM25+AN25+AO25+AP25 -> 29 | AS25: ='Mã số nhân viên'!I16 -> 03467 | AT25: =C26-AS25 -> 0
A26: 14 | B26: 14 | C26: =VLOOKUP(D26,'Mã số nhân viên'!B16:I147,8,0) -> 03467 | D26: T. Hin | F26: x | G26: x | H26: x | I26: x | J26: x | K26: x | L26: cn | M26: x | N26: x | O26: x | P26: x | Q26: x | R26: x | S26: đc | T26: x | U26: x | V26: x | W26: x | X26: x | Y26: x | Z26: đc | AA26: x | AB26: x | AC26: x | AD26: x | AE26: x | AF26: x | AG26: cn | AH26: x | AI26: x | AK26: =SUM(COUNTIF(F26:AJ26,"x")) -> 26 | AL26: =SUM(COUNTIF(F26:AJ26,"cn")) -> 2 | AM26: =SUM(COUNTIF(F26:AJ26,"đ")) -> 0 | AN26: =SUM(COUNTIF(F26:AJ26,"đc")) -> 2 | AO26: =SUM(COUNTIF(F26:AJ26,"gt")) -> 0 | AP26: =SUM(COUNTIF(F26:AJ26,"ct")) -> 0 | AQ26: =AK26+AL26+AM26+AN26+AO26+AP26 -> 30 | AS26: ='Mã số nhân viên'!I17 -> 04056 | AT26: =C27-AS26 -> 0
A27: 15 | B27: 15 | C27: =VLOOKUP(D27,'Mã số nhân viên'!B17:I148,8,0) -> 04056 | D27: N. Ly Phon | F27: x | G27: x | H27: x | I27: x | J27: x | K27: x | L27: cn | M27: x | N27: x | O27: x | P27: x | Q27: x | R27: x | S27: đc | T27: x | U27: x | V27: x | W27: x | X27: x | Y27: x | Z27: đc | AA27: x | AB27: x | AC27: x | AD27: x | AE27: x | AF27: x | AG27: cn | AH27: x | AI27: x | AK27: =SUM(COUNTIF(F27:AJ27,"x")) -> 26 | AL27: =SUM(COUNTIF(F27:AJ27,"cn")) -> 2 | AM27: =SUM(COUNTIF(F27:AJ27,"đ")) -> 0 | AN27: =SUM(COUNTIF(F27:AJ27,"đc")) -> 2 | AO27: =SUM(COUNTIF(F27:AJ27,"gt")) -> 0 | AP27: =SUM(COUNTIF(F27:AJ27,"ct")) -> 0 | AQ27: =AK27+AL27+AM27+AN27+AO27+AP27 -> 30 | AS27: ='Mã số nhân viên'!I18 -> 03469 | AT27: =C28-AS27 -> 0
A28: 16 | B28: 16 | C28: =VLOOKUP(D28,'Mã số nhân viên'!B18:I149,8,0) -> 03469 | D28: T. Xôm Va Nít | F28: x | G28: x | H28: x | I28: x | J28: x | K28: x | L28: cn | M28: x | N28: x | O28: x | P28: x | Q28: x | R28: x | S28: đc | T28: x | U28: x | V28: x | W28: x | X28: x | Y28: x | Z28: đc | AA28: x | AB28: x | AC28: x | AD28: x | AE28: x | AG28: cn | AH28: x | AI28: x | AK28: =SUM(COUNTIF(F28:AJ28,"x")) -> 25 | AL28: =SUM(COUNTIF(F28:AJ28,"cn")) -> 2 | AM28: =SUM(COUNTIF(F28:AJ28,"đ")) -> 0 | AN28: =SUM(COUNTIF(F28:AJ28,"đc")) -> 2 | AO28: =SUM(COUNTIF(F28:AJ28,"gt")) -> 0 | AP28: =SUM(COUNTIF(F28:AJ28,"ct")) -> 0 | AQ28: =AK28+AL28+AM28+AN28+AO28+AP28 -> 29 | AS28: ='Mã số nhân viên'!I19 -> 03470 | AT28: =C29-AS28 -> 0
A29: 17 | B29: 17 | C29: =VLOOKUP(D29,'Mã số nhân viên'!B19:I150,8,0) -> 03470 | D29: T. Lọi | F29: x | G29: x | H29: x | I29: x | J29: x | K29: x | L29: cn | M29: x | N29: x | O29: x | P29: x | Q29: x | R29: x | S29: đc | T29: x | U29: x | V29: x | W29: tt | X29: x | Y29: x | Z29: đc | AA29: x | AB29: x | AC29: x | AD29: x | AE29: x | AF29: x | AG29: cn | AH29: x | AI29: x | AK29: =SUM(COUNTIF(F29:AJ29,"x")) -> 25 | AL29: =SUM(COUNTIF(F29:AJ29,"cn")) -> 2 | AM29: =SUM(COUNTIF(F29:AJ29,"đ")) -> 0 | AN29: =SUM(COUNTIF(F29:AJ29,"đc")) -> 2 | AO29: =SUM(COUNTIF(F29:AJ29,"gt")) -> 0 | AP29: =SUM(COUNTIF(F29:AJ29,"ct")) -> 0 | AQ29: =AK29+AL29+AM29+AN29+AO29+AP29 -> 29 | AS29: ='Mã số nhân viên'!I20 -> 03471 | AT29: =C30-AS29 -> 0
A30: 18 | B30: 18 | C30: =VLOOKUP(D30,'Mã số nhân viên'!B20:I151,8,0) -> 03471 | D30: T. Phô Thong | F30: x | G30: x | H30: x | I30: x | J30: x | K30: x | L30: cn | M30: x | N30: x | O30: x | P30: x | Q30: x | R30: x | S30: đc | T30: x | U30: x | V30: x | W30: x | X30: x | Y30: x | Z30: đc | AA30: x | AB30: x | AC30: x | AD30: x | AE30: x | AF30: x | AG30: cn | AH30: x | AI30: x | AK30: =SUM(COUNTIF(F30:AJ30,"x")) -> 26 | AL30: =SUM(COUNTIF(F30:AJ30,"cn")) -> 2 | AM30: =SUM(COUNTIF(F30:AJ30,"đ")) -> 0 | AN30: =SUM(COUNTIF(F30:AJ30,"đc")) -> 2 | AO30: =SUM(COUNTIF(F30:AJ30,"gt")) -> 0 | AP30: =SUM(COUNTIF(F30:AJ30,"ct")) -> 0 | AQ30: =AK30+AL30+AM30+AN30+AO30+AP30 -> 30 | AS30: ='Mã số nhân viên'!I21 -> 03472 | AT30: =C31-AS30 -> 0
A31: 19 | B31: 19 | C31: =VLOOKUP(D31,'Mã số nhân viên'!B21:I152,8,0) -> 03472 | D31: N. Soi | F31: x | G31: x | H31: x | I31: x | J31: x | K31: x | L31: cn | M31: x | N31: x | O31: x | P31: x | Q31: x | R31: x | S31: đc | T31: x | U31: x | V31: x | W31: x | X31: x | Y31: x | Z31: đc | AA31: x | AB31: x | AC31: x | AD31: x | AF31: x | AG31: cn | AI31: x | AK31: =SUM(COUNTIF(F31:AJ31,"x")) -> 24 | AL31: =SUM(COUNTIF(F31:AJ31,"cn")) -> 2 | AM31: =SUM(COUNTIF(F31:AJ31,"đ")) -> 0 | AN31: =SUM(COUNTIF(F31:AJ31,"đc")) -> 2 | AO31: =SUM(COUNTIF(F31:AJ31,"gt")) -> 0 | AP31: =SUM(COUNTIF(F31:AJ31,"ct")) -> 0 | AQ31: =AK31+AL31+AM31+AN31+AO31+AP31 -> 28 | AS31: ='Mã số nhân viên'!I22 -> 03473 | AT31: =C32-AS31 -> 0
A32: 20 | B32: 20 | C32: =VLOOKUP(D32,'Mã số nhân viên'!B22:I153,8,0) -> 03473 | D32: N. Me Kha La | F32: x | G32: x | H32: x | I32: x | J32: x | K32: x | L32: cn | M32: x | N32: x | O32: x | P32: x | Q32: x | R32: x | S32: đc | T32: x | U32: x | V32: x | W32: x | X32: x | Y32: x | Z32: đc | AA32: x | AB32: x | AC32: x | AD32: x | AE32: x | AG32: cn | AH32: x | AI32: x | AK32: =SUM(COUNTIF(F32:AJ32,"x")) -> 25 | AL32: =SUM(COUNTIF(F32:AJ32,"cn")) -> 2 | AM32: =SUM(COUNTIF(F32:AJ32,"đ")) -> 0 | AN32: =SUM(COUNTIF(F32:AJ32,"đc")) -> 2 | AO32: =SUM(COUNTIF(F32:AJ32,"gt")) -> 0 | AP32: =SUM(COUNTIF(F32:AJ32,"ct")) -> 0 | AQ32: =AK32+AL32+AM32+AN32+AO32+AP32 -> 29 | AS32: ='Mã số nhân viên'!I23 -> 03474 | AT32: =C33-AS32 -> 0
A33: 21 | B33: 21 | C33: =VLOOKUP(D33,'Mã số nhân viên'!B23:I154,8,0) -> 03474 | D33: N. Mon Khăm | F33: x | G33: x | H33: x | I33: x | J33: x | K33: x | L33: cn | M33: x | N33: x | O33: x | P33: x | Q33: x | R33: x | S33: đc | T33: x | U33: x | V33: x | W33: x | X33: x | Y33: x | Z33: đc | AA33: x | AB33: x | AC33: x | AD33: x | AG33: cn | AH33: x | AI33: x | AK33: =SUM(COUNTIF(F33:AJ33,"x")) -> 24 | AL33: =SUM(COUNTIF(F33:AJ33,"cn")) -> 2 | AM33: =SUM(COUNTIF(F33:AJ33,"đ")) -> 0 | AN33: =SUM(COUNTIF(F33:AJ33,"đc")) -> 2 | AO33: =SUM(COUNTIF(F33:AJ33,"gt")) -> 0 | AP33: =SUM(COUNTIF(F33:AJ33,"ct")) -> 0 | AQ33: =AK33+AL33+AM33+AN33+AO33+AP33 -> 28 | AS33: ='Mã số nhân viên'!I24 -> 04057 | AT33: =C34-AS33 -> -4057
A34: 22 | B34: 22 | D34: N.Choi | F34: x | G34: x | H34: x | I34: x | J34: x | K34: x | L34: cn | M34: x | N34: x | O34: x | P34: x | Q34: x | R34: x | S34: đc | T34: x | U34: x | V34: x | W34: x | X34: x | Y34: x | Z34: đc | AA34: x | AB34: x | AC34: x | AD34: x | AE34: x | AF34: x | AG34: cn | AH34: x | AI34: x | AK34: =SUM(COUNTIF(F34:AJ34,"x")) -> 26 | AL34: =SUM(COUNTIF(F34:AJ34,"cn")) -> 2 | AM34: =SUM(COUNTIF(F34:AJ34,"đ")) -> 0 | AN34: =SUM(COUNTIF(F34:AJ34,"đc")) -> 2 | AO34: =SUM(COUNTIF(F34:AJ34,"gt")) -> 0 | AP34: =SUM(COUNTIF(F34:AJ34,"ct")) -> 0 | AQ34: =AK34+AL34+AM34+AN34+AO34+AP34 -> 30 | AS34: ='Mã số nhân viên'!I25 -> 03476 | AT34: =C35-AS34 -> 0
A35: 23 | B35: 23 | C35: =VLOOKUP(D35,'Mã số nhân viên'!B25:I156,8,0) -> 03476 | D35: T. Bin Ly. | F35: x | G35: x | H35: x | I35: x | J35: x | K35: x | L35: cn | M35: x | N35: x | O35: x | P35: x | Q35: x | R35: x | S35: đc | T35: x | U35: x | V35: x | W35: x | X35: x | Y35: x | Z35: đc | AA35: x | AB35: x | AC35: x | AD35: x | AE35: x | AF35: x | AG35: cn | AH35: x | AI35: x | AK35: =SUM(COUNTIF(F35:AJ35,"x")) -> 26 | AL35: =SUM(COUNTIF(F35:AJ35,"cn")) -> 2 | AM35: =SUM(COUNTIF(F35:AJ35,"đ")) -> 0 | AN35: =SUM(COUNTIF(F35:AJ35,"đc")) -> 2 | AO35: =SUM(COUNTIF(F35:AJ35,"gt")) -> 0 | AP35: =SUM(COUNTIF(F35:AJ35,"ct")) -> 0 | AQ35: =AK35+AL35+AM35+AN35+AO35+AP35 -> 30 | AS35: ='Mã số nhân viên'!I26 -> 03477 | AT35: =C36-AS35 -> -3477
A36: 24 | B36: 24 | D36: N. Tinh | F36: x | G36: x | H36: x | I36: x | J36: x | K36: x | L36: cn | M36: x | N36: x | O36: x | P36: x | Q36: x | R36: x | S36: đc | T36: x | U36: x | V36: x | W36: x | X36: x | Y36: x | Z36: đc | AA36: x | AB36: x | AC36: x | AD36: x | AE36: x | AF36: x | AG36: cn | AH36: x | AI36: x | AK36: =SUM(COUNTIF(F36:AJ36,"x")) -> 26 | AL36: =SUM(COUNTIF(F36:AJ36,"cn")) -> 2 | AM36: =SUM(COUNTIF(F36:AJ36,"đ")) -> 0 | AN36: =SUM(COUNTIF(F36:AJ36,"đc")) -> 2 | AO36: =SUM(COUNTIF(F36:AJ36,"gt")) -> 0 | AP36: =SUM(COUNTIF(F36:AJ36,"ct")) -> 0 | AQ36: =AK36+AL36+AM36+AN36+AO36+AP36 -> 30 | AS36: ='Mã số nhân viên'!I27 -> 03478 | AT36: =C37-AS36 -> 0
A37: 25 | B37: 25 | C37: =VLOOKUP(D37,'Mã số nhân viên'!B27:I158,8,0) -> 03478 | D37: N. Nong | F37: x | G37: x | H37: x | I37: x | J37: x | K37: x | L37: cn | M37: x | N37: x | O37: x | P37: x | Q37: x | R37: x | S37: đc | T37: x | U37: x | V37: x | W37: x | X37: x | Y37: x | Z37: đc | AA37: x | AB37: x | AC37: x | AD37: x | AE37: x | AF37: x | AG37: cn | AH37: x | AI37: x | AK37: =SUM(COUNTIF(F37:AJ37,"x")) -> 26 | AL37: =SUM(COUNTIF(F37:AJ37,"cn")) -> 2 | AM37: =SUM(COUNTIF(F37:AJ37,"đ")) -> 0 | AN37: =SUM(COUNTIF(F37:AJ37,"đc")) -> 2 | AO37: =SUM(COUNTIF(F37:AJ37,"gt")) -> 0 | AP37: =SUM(COUNTIF(F37:AJ37,"ct")) -> 0 | AQ37: =AK37+AL37+AM37+AN37+AO37+AP37 -> 30 | AS37: ='Mã số nhân viên'!I28 -> 03479 | AT37: =C38-AS37 -> 0
A38: 26 | B38: 26 | C38: =VLOOKUP(D38,'Mã số nhân viên'!B28:I159,8,0) -> 03479 | D38: N. Tun 1 | F38: x | G38: x | H38: x | I38: x | J38: x | K38: x | L38: cn | M38: x | N38: x | O38: x | P38: x | Q38: x | R38: x | S38: đc | T38: x | U38: x | V38: x | W38: x | X38: x | Y38: x | Z38: đc | AA38: x | AB38: x | AC38: x | AD38: x | AE38: x | AF38: x | AG38: cn | AH38: x | AI38: x | AK38: =SUM(COUNTIF(F38:AJ38,"x")) -> 26 | AL38: =SUM(COUNTIF(F38:AJ38,"cn")) -> 2 | AM38: =SUM(COUNTIF(F38:AJ38,"đ")) -> 0 | AN38: =SUM(COUNTIF(F38:AJ38,"đc")) -> 2 | AO38: =SUM(COUNTIF(F38:AJ38,"gt")) -> 0 | AP38: =SUM(COUNTIF(F38:AJ38,"ct")) -> 0 | AQ38: =AK38+AL38+AM38+AN38+AO38+AP38 -> 30 | AS38: ='Mã số nhân viên'!I29 -> 03480 | AT38: =C39-AS38 -> 0
A39: 27 | B39: 27 | C39: =VLOOKUP(D39,'Mã số nhân viên'!B29:I160,8,0) -> 03480 | D39: T . Lốc | F39: x | G39: x | H39: x | I39: x | J39: x | K39: x | L39: cn | M39: x | N39: x | O39: x | P39: x | Q39: x | R39: x | S39: đc | T39: x | U39: x | V39: x | W39: x | X39: x | Y39: x | Z39: đc | AA39: x | AB39: x | AC39: x | AD39: x | AE39: x | AF39: x | AG39: cn | AH39: x | AI39: x | AK39: =SUM(COUNTIF(F39:AJ39,"x")) -> 26 | AL39: =SUM(COUNTIF(F39:AJ39,"cn")) -> 2 | AM39: =SUM(COUNTIF(F39:AJ39,"đ")) -> 0 | AN39: =SUM(COUNTIF(F39:AJ39,"đc")) -> 2 | AO39: =SUM(COUNTIF(F39:AJ39,"gt")) -> 0 | AP39: =SUM(COUNTIF(F39:AJ39,"ct")) -> 0 | AQ39: =AK39+AL39+AM39+AN39+AO39+AP39 -> 30 | AS39: ='Mã số nhân viên'!I30 -> 03481 | AT39: =C40-AS39 -> 0
A40: 28 | B40: 28 | C40: =VLOOKUP(D40,'Mã số nhân viên'!B30:I161,8,0) -> 03481 | D40: N . Khâm (1) | F40: x | G40: x | H40: x | I40: x | J40: x | K40: x | L40: cn | M40: x | N40: x | O40: x | P40: x | Q40: x | R40: x | S40: đc | T40: x | U40: x | V40: x | W40: x | X40: tt | Y40: x | Z40: đc | AA40: x | AB40: x | AC40: x | AD40: x | AE40: x | AG40: cn | AH40: x | AI40: x | AK40: =SUM(COUNTIF(F40:AJ40,"x")) -> 24 | AL40: =SUM(COUNTIF(F40:AJ40,"cn")) -> 2 | AM40: =SUM(COUNTIF(F40:AJ40,"đ")) -> 0 | AN40: =SUM(COUNTIF(F40:AJ40,"đc")) -> 2 | AO40: =SUM(COUNTIF(F40:AJ40,"gt")) -> 0 | AP40: =SUM(COUNTIF(F40:AJ40,"ct")) -> 0 | AQ40: =AK40+AL40+AM40+AN40+AO40+AP40 -> 28 | AS40: ='Mã số nhân viên'!I31 -> 03482 | AT40: =C41-AS40 -> 0
A41: 29 | B41: 29 | C41: =VLOOKUP(D41,'Mã số nhân viên'!B31:I162,8,0) -> 03482 | D41: T . Phết | F41: x | G41: x | H41: x | I41: x | J41: x | K41: x | L41: cn | M41: x | N41: x | O41: x | P41: x | Q41: x | R41: x | S41: đc | T41: x | U41: x | V41: x | W41: x | X41: tt | Y41: x | Z41: đc | AA41: x | AB41: x | AC41: x | AD41: x | AE41: x | AG41: cn | AH41: x | AI41: x | AK41: =SUM(COUNTIF(F41:AJ41,"x")) -> 24 | AL41: =SUM(COUNTIF(F41:AJ41,"cn")) -> 2 | AM41: =SUM(COUNTIF(F41:AJ41,"đ")) -> 0 | AN41: =SUM(COUNTIF(F41:AJ41,"đc")) -> 2 | AO41: =SUM(COUNTIF(F41:AJ41,"gt")) -> 0 | AP41: =SUM(COUNTIF(F41:AJ41,"ct")) -> 0 | AQ41: =AK41+AL41+AM41+AN41+AO41+AP41 -> 28 | AS41: ='Mã số nhân viên'!I32 -> 03483 | AT41: =C42-AS41 -> 0
A42: 30 | B42: 30 | C42: =VLOOKUP(D42,'Mã số nhân viên'!B32:I163,8,0) -> 03483 | D42: T. Viêng Sa Văn | F42: x | G42: x | H42: x | I42: x | J42: x | K42: x | L42: cn | M42: x | N42: x | O42: x | P42: x | Q42: x | R42: x | S42: đc | T42: x | U42: x | V42: x | W42: x | X42: x | Y42: x | Z42: đc | AA42: x | AB42: x | AC42: x | AD42: x | AE42: x | AG42: cn | AH42: x | AI42: x | AK42: =SUM(COUNTIF(F42:AJ42,"x")) -> 25 | AL42: =SUM(COUNTIF(F42:AJ42,"cn")) -> 2 | AM42: =SUM(COUNTIF(F42:AJ42,"đ")) -> 0 | AN42: =SUM(COUNTIF(F42:AJ42,"đc")) -> 2 | AO42: =SUM(COUNTIF(F42:AJ42,"gt")) -> 0 | AP42: =SUM(COUNTIF(F42:AJ42,"ct")) -> 0 | AQ42: =AK42+AL42+AM42+AN42+AO42+AP42 -> 29 | AS42: ='Mã số nhân viên'!I33 -> 03484 | AT42: =C43-AS42 -> 0
...

Sheet BTH mủ tạp
A2: CỘNG HÒA DÂN CHỦ NHÂN DÂN LÀO
A3: Hòa Bình -Độc Lập - Dân Chủ - thống Nhất - Thịnh Vượng
A4: -----o0o-----
B6: CÔNG TY TNHH MTV QUASA - GERUCO LÀO
B7: ĐỘI SẢN XUẤT SỐ 04
A9: BẢNG THEO DÕI SẢN LƯỢNG MỦ TẠP THÁNG 09 NĂM 2025
A10: (Từ ngày 01 đến 30/09/2025)
A13: Stt | C13: MSNV | D13: Họ và tên | E13: Kí tên | F13: Ngày | AK13: Tổng mủ tạp | AL13: DRC bình quân | AM13: Quy khô | AN13: Xếp hạng kỹ thuật
F14: 1 | G14: 2 | H14: 3 | I14: 4 | J14: 5 | K14: 6 | L14: 7 | M14: 8 | N14: 9 | O14: 10 | P14: 11 | Q14: 12 | R14: 13 | S14: 14 | T14: 15 | U14: 16 | V14: 17 | W14: 18 | X14: 19 | Y14: 20 | Z14: 21 | AA14: 22 | AB14: 23 | AC14: 24 | AD14: 25 | AE14: 26 | AF14: 27 | AG14: 28 | AH14: 29 | AI14: 30 | AJ14: 31 | AP14: DRC bình quân
A15: Lát bốc | F15: A | G15: B | H15: C | I15: D | J15: A | K15: B | L15: C | M15: D | N15: A | O15: B | P15: C | Q15: D | R15: A | S15: BC | T15: D | U15: A | V15: B | W15: C | X15: D | Y15: A | Z15: BC | AA15: D | AB15: A | AC15: B | AD15: C | AE15: D | AF15: A | AG15: B | AH15: C | AI15: D
A16: Trạm 1 | F16: =SUM(F17:F97) -> 2849 | G16: =SUM(G17:G97) -> 5316 | H16: =SUM(H17:H97) -> 6174 | I16: =SUM(I17:I97) -> 7847 | J16: =SUM(J17:J97) -> 8883 | K16: =SUM(K17:K97) -> 6847 | L16: =SUM(L17:L97) -> 11140 | M16: =SUM(M17:M97) -> 13510 | ... AK16: =SUM(AK17:AK97) -> 291671 | AM16: =SUM(AM17:AM97) -> 124584.01
A17: 1 | B17: 1 | C17: ='Chấm công KT'!C13 -> 0 | D17: ='Chấm công KT'!D13 -> T. Lăm | F17: 112 | G17: 103 | H17: 123 | I17: 128 | J17: 133 | K17: 86 | L17: 237 | M17: 190 | N17: 223 | O17: 170 | P17: 208 | Q17: 182 | R17: 355 | S17: 180 | T17: 159 | U17: 157 | V17: 126 | W17: 159 | X17: 141 | Y17: 263 | Z17: 144 | AA17: 137 | AB17: 139 | AC17: 106 | AD17: 158 | AE17: 126 | AF17: 144 | AG17: 0 | AH17: 0 | AI17: 0 | AK17: =SUM(F17:AJ17) -> 4389 | AL17: 42.713883 | AM17: =AK17*AL17/100 -> 1874.7123 | AN17: A | AS17: =AM16/15*100 -> 830560.07
A18: 2 | B18: 2 | C18: ='Chấm công KT'!C14 -> 04052 | D18: ='Chấm công KT'!D14 -> T. Feng | F18: 81 | G18: 89 | H18: 0 | I18: 90 | J18: 103 | K18: 71 | L18: 120 | M18: 182 | N18: 210 | O18: 170 | P18: 143 | Q18: 182 | R18: 343 | S18: 130 | T18: 165 | U18: 182 | V18: 105 | W18: 0 | X18: 116 | Y18: 247 | Z18: 103 | AA18: 110 | AB18: 145 | AC18: 113 | AD18: 93 | AE18: 120 | AF18: 169 | AG18: 189 | AH18: 0 | AI18: 67 | AK18: =SUM(F18:AJ18) -> 3838 | AL18: 42.713883 | AM18: =AK18*AL18/100 -> 1639.3588 | AN18: A
A19: 3 | B19: 3 | C19: ='Chấm công KT'!C15 -> 02725 | D19: ='Chấm công KT'!D15 -> T. Sa Văn | F19: 0 | G19: 110 | H19: 132 | I19: 138 | J19: 136 | K19: 79 | L19: 149 | M19: 180 | N19: 142 | O19: 155 | P19: 120 | Q19: 120 | R19: 230 | S19: 100 | T19: 130 | U19: 127 | V19: 90 | W19: 93 | X19: 110 | Y19: 235 | Z19: 0 | AA19: 144 | AB19: 106 | AC19: 80 | AD19: 132 | AE19: 122 | AF19: 161 | AG19: 0 | AH19: 75 | AI19: 0 | AK19: =SUM(F19:AJ19) -> 3396 | AL19: 42.713883 | AM19: =AK19*AL19/100 -> 1450.5635 | AN19: A
A20: 4 | B20: 4 | C20: ='Chấm công KT'!C16 -> 04053 | D20: ='Chấm công KT'!D16 -> Lăm Ma Thu | F20: 0 | G20: 72 | H20: 55 | I20: 83 | J20: 164 | K20: 52 | L20: 126 | M20: 177 | N20: 201 | O20: 148 | P20: 106 | Q20: 137 | R20: 261 | S20: 93 | T20: 145 | U20: 164 | V20: 147 | W20: 96 | X20: 130 | Y20: 205 | Z20: 70 | AA20: 91 | AB20: 150 | AC20: 76 | AD20: 0 | AE20: 117 | AF20: 180 | AG20: 181 | AH20: 100 | AI20: 98 | AK20: =SUM(F20:AJ20) -> 3625 | AL20: 42.713883 | AM20: =AK20*AL20/100 -> 1548.3783 | AN20: A
A21: 5 | B21: 5 | C21: ='Chấm công KT'!C17 -> 03459 | D21: ='Chấm công KT'!D17 -> N. Vạt | F21: 74 | G21: 0 | H21: 0 | I21: 180 | J21: 67 | K21: 89 | L21: 275 | M21: 147 | N21: 128 | O21: 146 | P21: 160 | Q21: 103 | R21: 194 | S21: 124 | T21: 90 | U21: 92 | V21: 0 | W21: 173 | X21: 145 | Y21: 181 | Z21: 121 | AA21: 92 | AB21: 74 | AC21: 78 | AD21: 0 | AE21: 77 | AF21: 126 | AG21: 148 | AH21: 144 | AI21: 0 | AK21: =SUM(F21:AJ21) -> 3228 | AL21: 42.713883 | AM21: =AK21*AL21/100 -> 1378.8041 | AN21: A
A22: 6 | B22: 6 | C22: ='Chấm công KT'!C18 -> 04054 | D22: ='Chấm công KT'!D18 -> N. Kay Son | F22: 0 | G22: 78 | H22: 80 | I22: 90 | J22: 154 | K22: 67 | L22: 174 | M22: 180 | N22: 221 | O22: 158 | P22: 131 | Q22: 143 | R22: 282 | S22: 110 | T22: 146 | U22: 184 | V22: 121 | W22: 130 | X22: 141 | Y22: 290 | Z22: 127 | AA22: 140 | AB22: 125 | AC22: 123 | AD22: 84 | AE22: 96 | AF22: 220 | AG22: 189 | AH22: 0 | AI22: 109 | AK22: =SUM(F22:AJ22) -> 4093 | AL22: 42.713883 | AM22: =AK22*AL22/100 -> 1748.2792 | AN22: A
A23: 7 | B23: 7 | C23: ='Chấm công KT'!C19 -> 04055 | D23: ='Chấm công KT'!D19 -> T. Đèng 1 | F23: 0 | G23: 75 | H23: 79 | I23: 110 | J23: 134 | K23: 70 | L23: 137 | M23: 186 | N23: 155 | O23: 182 | P23: 103 | Q23: 153 | R23: 258 | S23: 96 | T23: 138 | U23: 127 | V23: 124 | W23: 80 | X23: 149 | Y23: 189 | Z23: 84 | AA23: 120 | AB23: 100 | AC23: 115 | AD23: 87 | AE23: 151 | AF23: 156 | AG23: 183 | AH23: 105 | AI23: 0 | AK23: =SUM(F23:AJ23) -> 3646 | AL23: 42.713883 | AM23: =AK23*AL23/100 -> 1557.3482 | AN23: A
A24: 8 | B24: 8 | C24: ='Chấm công KT'!C20 -> 03462 | D24: ='Chấm công KT'!D20 -> T . Bua Ngân | F24: 0 | G24: 84 | H24: 70 | I24: 88 | J24: 110 | K24: 84 | L24: 132 | M24: 126 | N24: 183 | O24: 188 | P24: 89 | Q24: 108 | R24: 307 | S24: 130 | T24: 160 | U24: 150 | V24: 160 | W24: 120 | X24: 143 | Y24: 251 | Z24: 82 | AA24: 116 | AB24: 101 | AC24: 117 | AD24: 113 | AE24: 120 | AF24: 172 | AG24: 170 | AH24: 0 | AI24: 0 | AK24: =SUM(F24:AJ24) -> 3674 | AL24: 42.713883 | AM24: =AK24*AL24/100 -> 1569.3081 | AN24: A
A25: 9 | B25: 9 | C25: ='Chấm công KT'!C21 -> 03463 | D25: ='Chấm công KT'!D21 -> T Căng | F25: 0 | G25: 122 | H25: 144 | I25: 0 | J25: 120 | K25: 91 | L25: 260 | M25: 245 | N25: 141 | O25: 208 | P25: 184 | Q25: 144 | R25: 254 | S25: 143 | T25: 176 | U25: 150 | V25: 190 | W25: 204 | X25: 120 | Y25: 210 | Z25: 196 | AA25: 166 | AB25: 138 | AC25: 152 | AD25: 124 | AE25: 114 | AF25: 161 | AG25: 219 | AH25: 140 | AI25: 64 | AK25: =SUM(F25:AJ25) -> 4580 | AL25: 42.713883 | AM25: =AK25*AL25/100 -> 1956.2958 | AN25: A
A26: 10 | B26: 10 | C26: ='Chấm công KT'!C22 -> 03464 | D26: ='Chấm công KT'!D22 -> N. Phôn 1 | F26: 0 | G26: 122 | H26: 138 | I26: 0 | J26: 136 | K26: 92 | L26: 245 | M26: 259 | N26: 141 | O26: 210 | P26: 211 | Q26: 148 | R26: 262 | S26: 133 | T26: 191 | U26: 130 | V26: 177 | W26: 189 | X26: 121 | Y26: 216 | Z26: 196 | AA26: 168 | AB26: 146 | AC26: 152 | AD26: 115 | AE26: 110 | AF26: 163 | AG26: 240 | AH26: 123 | AI26: 104 | AK26: =SUM(F26:AJ26) -> 4638 | AL26: 42.713883 | AM26: =AK26*AL26/100 -> 1981.0699 | AN26: A
A27: 11 | B27: 11 | C27: ='Chấm công KT'!C23 -> 03465 | D27: ='Chấm công KT'!D23 -> T. In Păn | F27: 73 | G27: 0 | H27: 116 | I27: 97 | J27: 80 | K27: 110 | L27: 88 | M27: 187 | N27: 182 | O27: 155 | P27: 172 | Q27: 168 | R27: 306 | S27: 160 | T27: 130 | U27: 105 | V27: 100 | W27: 137 | X27: 120 | Y27: 236 | Z27: 163 | AA27: 110 | AB27: 94 | AC27: 80 | AD27: 0 | AE27: 84 | AF27: 138 | AG27: 0 | AH27: 103 | AI27: 101 | AK27: =SUM(F27:AJ27) -> 3595 | AL27: 42.713883 | AM27: =AK27*AL27/100 -> 1535.5641 | AN27: A
A28: 12 | B28: 12 | C28: ='Chấm công KT'!C24 -> 03466 | D28: ='Chấm công KT'!D24 -> N. Keo | F28: 0 | G28: 91 | H28: 128 | I28: 100 | J28: 133 | K28: 82 | L28: 270 | M28: 181 | N28: 201 | O28: 211 | P28: 164 | Q28: 128 | R28: 290 | S28: 161 | T28: 106 | U28: 154 | V28: 138 | W28: 162 | X28: 126 | Y28: 296 | Z28: 164 | AA28: 92 | AB28: 127 | AC28: 120 | AD28: 120 | AE28: 93 | AF28: 183 | AG28: 185 | AH28: 0 | AI28: 145 | AK28: =SUM(F28:AJ28) -> 4351 | AL28: 42.713883 | AM28: =AK28*AL28/100 -> 1858.4811 | AN28: A
A29: 13 | B29: 13 | C29: ='Chấm công KT'!C25 -> 02727 | D29: ='Chấm công KT'!D25 -> T. Thong Đon | F29: 74 | G29: 96 | H29: 0 | I29: 90 | J29: 80 | K29: 72 | L29: 340 | M29: 172 | N29: 194 | O29: 193 | P29: 168 | Q29: 126 | R29: 360 | S29: 219 | T29: 103 | U29: 133 | V29: 148 | W29: 182 | X29: 115 | Y29: 237 | Z29: 202 | AA29: 130 | AB29: 87 | AC29: 152 | AD29: 0 | AE29: 103 | AF29: 168 | AG29: 168 | AH29: 0 | AI29: 148 | AK29: =SUM(F29:AJ29) -> 4260 | AL29: 42.713883 | AM29: =AK29*AL29/100 -> 1819.6114 | AN29: A
... A89: 73 | B89: 73 | C89: ='Chấm công KT'!C85 -> 04071 | D89: ='Chấm công KT'!D85 -> T. Ne | F89: 57 | G89: 63 | H89: 0 | I89: 108 | J89: 0 | K89: 131 | L89: 175 | M89: 135 | N89: 91 | O89: 80 | P89: 100 | Q89: 121 | R89: 220 | S89: 102 | T89: 102 | U89: 87 | V89: 93 | W89: 83 | X89: 83 | Y89: 165 | Z89: 78 | AA89: 78 | AB89: 74 | AC89: 81 | AD89: 71 | AE89: 71 | AF89: 109 | AG89: 0 | AH89: 0 | AI89: 63 | AK89: =SUM(F89:AJ89) -> 2621 | AL89: 42.713883 | AM89: =AK89*AL89/100 -> 1119.5309 | AN89: A
A90: 74 | B90: 74 | D90: ='Chấm công KT'!D86 -> T. Tý | F90: 0 | G90: 54 | H90: 0 | I90: 0 | J90: 0 | K90: 0 | L90: 0 | M90: 0 | N90: 0 | O90: 0 | P90: 0 | Q90: 0 | R90: 0 | S90: 0 | T90: 0 | U90: 0 | V90: 0 | W90: 83 | X90: 0 | Y90: 0 | Z90: 0 | AA90: 0 | AB90: 0 | AC90: 0 | AD90: 0 | AE90: 0 | AF90: 0 | AG90: 0 | AH90: 0 | AI90: 0 | AK90: =SUM(F90:AJ90) -> 137 | AL90: 42.713883 | AM90: =AK90*AL90/100 -> 58.51802 | AN90: C.
A91: 75 | B91: 75 | D91: ='Chấm công KT'!D87 -> T. Lã | F91: 0 | G91: 54 | H91: 0 | I91: 0 | J91: 0 | K91: 0 | L91: 0 | M91: 0 | N91: 0 | O91: 0 | P91: 0 | Q91: 0 | R91: 0 | S91: 0 | T91: 0 | U91: 0 | V91: 0 | W91: 83 | X91: 0 | Y91: 0 | Z91: 133 | AA91: 0 | AB91: 0 | AC91: 0 | AD91: 0 | AE91: 0 | AF91: 0 | AG91: 0 | AH91: 0 | AI91: 0 | AK91: =SUM(F91:AJ91) -> 270 | AL91: 42.713883 | AM91: =AK91*AL91/100 -> 115.32748 | AN91: C.
A92: 76 | B92: 76 | D92: ='Chấm công KT'!D88 -> N. Veo | F92: 0 | G92: 0 | H92: 0 | I92: 0 | J92: 0 | K92: 0 | L92: 0 | M92: 0 | N92: 0 | O92: 0 | P92: 0 | Q92: 0 | R92: 0 | S92: 0 | T92: 0 | U92: 0 | V92: 0 | W92: 0 | X92: 0 | Y92: 0 | Z92: 133 | AA92: 0 | AB92: 0 | AC92: 0 | AD92: 0 | AE92: 0 | AF92: 0 | AG92: 0 | AH92: 0 | AI92: 0 | AK92: =SUM(F92:AJ92) -> 133 | AL92: 42.713883 | AM92: =AK92*AL92/100 -> 56.809465 | AN92: C.
A93: 77 | B93: 77 | D93: ='Chấm công KT'!D89 -> T. Pu | F93: 0 | G93: 0 | H93: 59 | I93: 0 | J93: 0 | K93: 0 | L93: 0 | M93: 0 | N93: 0 | O93: 0 | P93: 0 | Q93: 0 | R93: 0 | S93: 0 | T93: 0 | U93: 0 | V93: 0 | W93: 83 | X93: 0 | Y93: 0 | Z93: 120 | AA93: 0 | AB93: 0 | AC93: 0 | AD93: 0 | AE93: 0 | AF93: 0 | AG93: 0 | AH93: 0 | AI93: 0 | AK93: =SUM(F93:AJ93) -> 262 | AL93: 42.713883 | AM93: =AK93*AL93/100 -> 111.91037 | AN93: C.
A94: 78 | B94: 78 | D94: ='Chấm công KT'!D90 -> T. Ta. | F94: 0 | G94: 0 | H94: 0 | I94: 0 | J94: 0 | K94: 0 | L94: 0 | M94: 0 | N94: 0 | O94: 0 | P94: 0 | Q94: 0 | R94: 0 | S94: 0 | T94: 0 | U94: 0 | V94: 0 | W94: 0 | X94: 0 | Y94: 0 | Z94: 0 | AA94: 0 | AB94: 0 | AC94: 0 | AD94: 0 | AE94: 0 | AF94: 0 | AG94: 0 | AH94: 0 | AI94: 0 | AK94: =SUM(F94:AJ94) -> 0 | AL94: 42.713883 | AM94: =AK94*AL94/100 -> 0 | AN94: C.
A95: 79 | B95: 79 | D95: ='Chấm công KT'!D91 -> N. Nang | F95: 0 | G95: 0 | H95: 0 | I95: 0 | J95: 0 | K95: 0 | L95: 0 | M95: 0 | N95: 0 | O95: 0 | P95: 0 | Q95: 0 | R95: 0 | S95: 0 | T95: 0 | U95: 0 | V95: 0 | W95: 0 | X95: 0 | Y95: 0 | Z95: 0 | AA95: 0 | AB95: 0 | AC95: 0 | AD95: 0 | AE95: 0 | AF95: 0 | AG95: 0 | AH95: 0 | AI95: 0 | AK95: =SUM(F95:AJ95) -> 0 | AL95: 42.713883 | AM95: =AK95*AL95/100 -> 0 | AN95: C.
A96: 80 | B96: 80 | D96: ='Chấm công KT'!D92 -> T. Tan | F96: 0 | G96: 0 | H96: 0 | I96: 0 | J96: 0 | K96: 0 | L96: 0 | M96: 0 | N96: 0 | O96: 0 | P96: 0 | Q96: 0 | R96: 0 | S96: 0 | T96: 0 | U96: 0 | V96: 0 | W96: 0 | X96: 0 | Y96: 0 | Z96: 0 | AA96: 0 | AB96: 0 | AC96: 0 | AD96: 0 | AE96: 0 | AF96: 0 | AG96: 0 | AH96: 0 | AI96: 0 | AK96: =SUM(F96:AJ96) -> 0 | AL96: 42.713883 | AM96: =AK96*AL96/100 -> 0 | AN96: C.
A97: 81 | B97: 81 | D97: ='Chấm công KT'!D93 -> 0 | AI97: 0 | AK97: =SUM(F97:AJ97) -> 0 | AL97: 42.713883 | AM97: =AK97*AL97/100 -> 0 | AN97: C.
A98: Tram 2 | F98: =SUM(F99:F160) -> 5872 | G98: =SUM(G99:G160) -> 8401 | H98: =SUM(H99:H160) -> 4677 | I98: =SUM(I99:I160) -> 5301 | J98: =SUM(J99:J160) -> 6882 | K98: =SUM(K99:K160) -> 12560 | L98: =SUM(L99:L160) -> 5688 | M98: =SUM(M99:M160) -> 8620 | ... AK98: =SUM(AK99:AK160) -> 248798 | AM98: =SUM(AM99:AM160) -> 107620.46
A99: 78 | B99: 1 | C99: ='Chấm công KT'!C95 -> 04072 | D99: ='Chấm công KT'!D95 -> T. Lun | F99: 134 | G99: 217 | H99: 156 | I99: 80 | J99: 88 | K99: 205 | L99: 157 | M99: 195 | N99: 207 | O99: 213 | P99: 140 | Q99: 360 | R99: 156 | S99: 115 | T99: 148 | U99: 101 | V99: 181 | W99: 133 | X99: 228 | Y99: 106 | Z99: 114 | AA99: 102 | AB99: 90 | AC99: 0 | AD99: 0 | AE99: 209 | AG99: 100 | AH99: 0 | AI99: 70 | AK99: =SUM(F99:AJ99) -> 4005 | AL99: 43.256159 | AM99: =AK99*AL99/100 -> 1732.4092 | AN99: A
A100: 79 | B100: 2 | C100: ='Chấm công KT'!C96 -> 03466 | D100: ='Chấm công KT'!D96 -> N. Keo | F100: 100 | G100: 126 | H100: 93 | I100: 97 | J100: 86 | K100: 164 | L100: 77 | M100: 202 | N100: 220 | O100: 150 | P100: 63 | Q100: 354 | R100: 122 | S100: 67 | T100: 180 | U100: 173 | V100: 179 | W100: 66 | X100: 318 | Y100: 114 | Z100: 64 | AA100: 147 | AB100: 124 | AC100: 121 | AD100: 61 | AE100: 0 | AG100: 177 | AH100: 0 | AI100: 0 | AK100: =SUM(F100:AJ100) -> 3645 | AL100: 43.256159 | AM100: =AK100*AL100/100 -> 1576.687 | AN100: A
A101: 80 | B101: 3 | C101: ='Chấm công KT'!C97 -> 03590 | D101: ='Chấm công KT'!D97 -> T .Nhum | F101: 54 | G101: 116 | H101: 103 | I101: 57 | J101: 66 | K101: 239 | L101: 108 | M101: 122 | N101: 145 | O101: 195 | P101: 83 | Q101: 0 | R101: 191 | S101: 0 | T101: 218 | U101: 221 | V101: 156 | W101: 124 | X101: 208 | Y101: 169 | Z101: 80 | AA101: 91 | AB101: 99 | AC101: 146 | AD101: 80 | AE101: 186 | AG101: 311 | AH101: 0 | AI101: 75 | AK101: =SUM(F101:AJ101) -> 3643 | AL101: 43.256159 | AM101: =AK101*AL101/100 -> 1575.8219 | AN101: A
A102: 81 | B102: 4 | C102: ='Chấm công KT'!C98 -> 03591 | D102: ='Chấm công KT'!D98 -> N.Vông Ma Ni | F102: 81 | G102: 186 | H102: 130 | I102: 97 | J102: 104 | K102: 100 | L102: 0 | M102: 173 | N102: 148 | O102: 206 | P102: 213 | Q102: 298 | R102: 182 | S102: 0 | T102: 117 | U102: 106 | V102: 164 | W102: 210 | X102: 278 | Y102: 137 | Z102: 102 | AA102: 98 | AB102: 104 | AC102: 125 | AD102: 100 | AE102: 274 | AG102: 211 | AH102: 0 | AI102: 125 | AK102: =SUM(F102:AJ102) -> 4069 | AL102: 43.256159 | AM102: =AK102*AL102/100 -> 1760.0931 | AN102: A
A103: 82 | B103: 5 | C103: ='Chấm công KT'!C99 -> 03592 | D103: ='Chấm công KT'!D99 -> Đao Hương | F103: 82 | G103: 186 | H103: 0 | I103: 93 | J103: 96 | K103: 98 | L103: 0 | M103: 132 | N103: 176 | O103: 200 | P103: 200 | Q103: 244 | R103: 161 | S103: 0 | T103: 125 | U103: 120 | V103: 170 | W103: 202 | X103: 239 | Y103: 141 | Z103: 110 | AA103: 112 | AB103: 105 | AC103: 105 | AD103: 104 | AE103: 217 | AG103: 198 | AH103: 0 | AI103: 122 | AK103: =SUM(F103:AJ103) -> 3738 | AL103: 43.256159 | AM103: =AK103*AL103/100 -> 1616.9152 | AN103: A
A104: 83 | B104: 6 | C104: ='Chấm công KT'!C100 -> 03593 | D104: ='Chấm công KT'!D100 -> T. Xi Nun | F104: 147 | G104: 145 | H104: 91 | I104: 115 | J104: 110 | K104: 205 | L104: 135 | M104: 193 | N104: 300 | O104: 242 | P104: 118 | Q104: 430 | R104: 161 | S104: 112 | T104: 143 | U104: 272 | V104: 179 | W104: 110 | X104: 341 | Y104: 153 | Z104: 114 | AA104: 147 | AB104: 192 | AC104: 147 | AD104: 96 | AE104: 316 | AG104: 219 | AH104: 74 | AI104: 0 | AK104: =SUM(F104:AJ104) -> 5007 | AL104: 43.256159 | AM104: =AK104*AL104/100 -> 2165.8359 | AN104: B
...

Sheet BTH mủ Sỉum
A1: CỘNG HÒA DÂN CHỦ NHÂN DÂN LÀO
A2: Hòa Bình -Độc Lập - Dân Chủ - thống Nhất - Thịnh Vượng
A3: -----o0o-----
A5: CÔNG TY TNHH MTV QUASA - GERUCO LÀO
A6: ĐỘI SẢN XUẤT SỐ 4
A12: BẢNG THEO DÕI SẢN LƯỢNG MỦ SERUM THÁNG 09 NĂM 2025
AK13: DRC
A14: Stt | B14: Họ và tên | C14: Ngày | AH14: Tổng mủ Xirum | AI14: DRC bình quân | AJ14: Quy khô | AK14: Xếp hạng kỹ thuật | AL14: Kí tên
C15: 1 | D15: 2 | E15: 3 | F15: 4 | G15: 5 | H15: 6 | I15: 7 | J15: 8 | K15: 9 | L15: 10 | M15: 11 | N15: 12 | O15: 13 | P15: 14 | Q15: 15 | R15: 16 | S15: 17 | T15: 18 | U15: 19 | V15: 20 | W15: 21 | X15: 22 | Y15: 23 | Z15: 24 | AA15: 25 | AB15: 26 | AC15: 27 | AD15: 28 | AE15: 29 | AF15: 30
A16: Trạm 1 | C16: =C17 -> 0 | D16: =D17 -> 0 | E16: =E17 -> 0 | F16: =F17 -> 0 | G16: =G17 -> 0 | H16: =H17 -> 0 | I16: =I17 -> 0 | J16: =J17 -> 0 | ... AF16: =AF17 -> 340 | AH16: =AH17 -> 340 | AJ16: =AJ17 -> 184.212 | AK16: =AK17 -> 0
A17: 1 | B17: Mủ Xirum | AF17: 340 | AH17: =SUM(C17:AG17) -> 340 | AI17: 54.18 | AJ17: =AH17*AI17/100 -> 184.212
A18: Trạm 2 | C18: =C19 -> 0 | D18: =D19 -> 0 | E18: =E19 -> 0 | F18: =F19 -> 0 | G18: =G19 -> 0 | H18: =H19 -> 0 | I18: =I19 -> 0 | J18: =J19 -> 0 | ... AF18: =AF19 -> 630 | AH18: =AH19 -> 630 | AJ18: =AJ19 -> 310.01
A19: 1 | B19: Mủ Xirum | AF19: 630 | AH19: =SUM(C19:AG19) -> 630 | AI19: 49.207937 | AJ19: =AH19*AI19/100 -> 310.01
A20: Tổng cộng | AE20: =AE16+AE18 -> 0 | AF20: =AF16+AF18 -> 970 | AG20: =AG16+AG18 -> 0 | AH20: =AH16+AH18 -> 970 | AI20: =AI16+AI18 -> 0 | AJ20: =AJ16+AJ18 -> 494.222 | AK20: =AK16+AK18+#REF!+#REF! -> #REF!
Y22: Mường phìn, ngày 02 tháng 10 năm 2025
A23: TỔNG GIÁM ĐỐC PHÒNG QL - KT P. PHÒNG PHỤ TRÁCH ĐỘI TRƯỞNG NGƯỜI LẬP

Sheet TONGHOPCONGDOI
A2: CÔNG TY TNHH CỔ PHẦN QUASA - GERUCO | R2: CỘNG HÒA DÂN CHỦ NHÂN DÂN LÀO
A3: NÔNG TRƯỜNG 2 | N3: =144/0.67 -> 214.92537 | R3: Hòa Bình - Độc Lập - Dân Chủ - Thống Nhất - Thịnh Vượng
A4: Đội: 1.2.3.4 | J4: =F11*25000 -> 0 | K4: =G11*25000 -> 0 | T4: =Q9-19035.02 -> -11682.29
A5: BẢNG TỔNG HỢP CÔNG THỰC HIỆN THÁNG 07 NĂM 2025
A6: STT | B6: Mã số nhân viên | C6: Họ và Tên Lào | D6: Chức vụ
E7: Bôi thuốc kích thích | F7: Bôi thuốc loét sọc | G7: Phun cỏ đại trà | H7: Phát chồi đại trà | I7: Thiết kế miệng cạo ngữa | J7: Bón Phân | K7: Phun Potry | L7: Xả miệng cạo ngữa | M7: Phát chồi đại trà | N7: Gom chén | P7: Thổi lá hàng 3m | Q7: Tổng công | R7: Sản lượng mủ | V7: Các khoản PC | AC7: Tổng cộng | AD7: Xếp loại KT tính lương | AE7: Xác Nhận
R8: Mủ tạp | S8: Mủ Xirum | T8: Quy khô DRC=50 | U8: Tổng sản lượng mủ tạp+mủ dây quy khô | V8: Ngày công đi cạo thường (x) | W8: Ngày CN thường (cn) | X8: Ngày công đi cạo 2 lát (đ) | Y8: Ngày công chủ nhật cạo 2 lát (đc) | Z8: Ngày công cạo gia tăng 2 miêng (gt) | AA8: Ngày chủ nhật cạo gia tăng 2 miệng (ct) | AB8: Phụ cấp nhỏ a xít | AI8: =5308.01-Q9 -> -2044.72
A9: I | B9: VC KINH DOANH NĂM | E9: =E10+E96 -> 419.2 | F9: =F10+F96 -> 0 | G9: =G10+G96 -> 645.05 | H9: =H10+H96 -> 6252.48 | I9: =I10+I96 -> 36 | J9: =J10+J96 -> 0 | K9: =K10+K96 -> 0 | L9: =L10+L96 -> 0 | ... AC9: =AC10+AC96 -> 7352.73 | AF9: 6716.8 | AG9: =6716.8-Q9 -> -635.93
A10: A | B10: Đội I | E10: =SUM(E11:E94) -> 233.6 | F10: =SUM(F11:F95) -> 0 | G10: =SUM(G11:G95) -> 214.46 | H10: =SUM(H11:H95) -> 4166.56 | I10: =SUM(I11:I95) -> 36 | J10: =SUM(J11:J95) -> 0 | K10: =SUM(K11:K95) -> 0 | L10: =SUM(L11:L95) -> 0 | M10: =SUM(M11:M95) -> 0 | ... AC10: =SUM(AC11:AC95) -> 4650.62 | AF10: 1618 | AG10: 194
A11: 1 | B11: ='Chấm công KT'!C13 -> 0 | C11: ='Chấm công KT'!D13 -> T. Lăm | D11: CN-KT | E11: =4/1.25 -> 3.2 | I11: =14+8+14 -> 36 | Q11: =SUM(E11:P11) -> 39.2 | R11: =VLOOKUP(C11,'BTH mủ tạp'!D17:AK97,34,0) -> 4389 | T11: =S11*50/100 -> 0 | U11: =R11 -> 4389 | V11: =VLOOKUP(C11,'Chấm công KT'!D13:AK93,34,0) -> 24 | W11: =VLOOKUP(C11,'Chấm công KT'!D13:AL93,35,0) -> 1 | Y11: =VLOOKUP(C11,'Chấm công KT'!D13:AN93,37,0) -> 2 | Z11: =VLOOKUP(C11,'Chấm công KT'!$D$13:$AO$92,38,0) -> 0 | AA11: =VLOOKUP(C11,'Chấm công KT'!$D$13:$AP$92,39,0) -> 0 | AC11: =Q11 -> 39.2 | AD11: =VLOOKUP(C11,'BTH mủ tạp'!$D$17:$AN$160,37,0) -> A
A12: 2 | B12: ='Chấm công KT'!C14 -> 04052 | C12: ='Chấm công KT'!D14 -> T. Feng | D12: CN-KT | E12: =4/1.25 -> 3.2 | Q12: =SUM(E12:P12) -> 3.2 | R12: =VLOOKUP(C12,'BTH mủ tạp'!D18:AK98,34,0) -> 3838 | T12: =S12*50/100 -> 0 | U12: =R12 -> 3838 | V12: =VLOOKUP(C12,'Chấm công KT'!D14:AK94,34,0) -> 24 | W12: =VLOOKUP(C12,'Chấm công KT'!D14:AL94,35,0) -> 1 | Y12: =VLOOKUP(C12,'Chấm công KT'!D14:AN94,37,0) -> 2 | Z12: =VLOOKUP(C12,'Chấm công KT'!$D$13:$AO$92,38,0) -> 0 | AA12: =VLOOKUP(C12,'Chấm công KT'!$D$13:$AP$92,39,0) -> 0 | AC12: =Q12 -> 3.2 | AD12: =VLOOKUP(C12,'BTH mủ tạp'!$D$17:$AN$160,37,0) -> A
A13: 3 | B13: ='Chấm công KT'!C15 -> 02725 | C13: ='Chấm công KT'!D15 -> T. Sa Văn | D13: CN-KT | E13: =4/1.25 -> 3.2 | Q13: =SUM(E13:P13) -> 3.2 | R13: =VLOOKUP(C13,'BTH mủ tạp'!D19:AK99,34,0) -> 3396 | T13: =S13*50/100 -> 0 | U13: =R13 -> 3396 | V13: =VLOOKUP(C13,'Chấm công KT'!D15:AK95,34,0) -> 24 | W13: =VLOOKUP(C13,'Chấm công KT'!D15:AL95,35,0) -> 2 | Y13: =VLOOKUP(C13,'Chấm công KT'!D15:AN95,37,0) -> 2 | Z13: =VLOOKUP(C13,'Chấm công KT'!$D$13:$AO$92,38,0) -> 0 | AA13: =VLOOKUP(C13,'Chấm công KT'!$D$13:$AP$92,39,0) -> 0 | AC13: =Q13 -> 3.2 | AD13: =VLOOKUP(C13,'BTH mủ tạp'!$D$17:$AN$160,37,0) -> A | AG13: 119657 | AH13: 197
A14: 4 | B14: ='Chấm công KT'!C16 -> 04053 | C14: ='Chấm công KT'!D16 -> Lăm Ma Thu | D14: CN-KT | E14: =4/1.25 -> 3.2 | Q14: =SUM(E14:P14) -> 3.2 | R14: =VLOOKUP(C14,'BTH mủ tạp'!D20:AK100,34,0) -> 3625 | T14: =S14*50/100 -> 0 | U14: =R14 -> 3625 | V14: =VLOOKUP(C14,'Chấm công KT'!D16:AK96,34,0) -> 26 | W14: =VLOOKUP(C14,'Chấm công KT'!D16:AL96,35,0) -> 2 | Y14: =VLOOKUP(C14,'Chấm công KT'!D16:AN96,37,0) -> 2 | Z14: =VLOOKUP(C14,'Chấm công KT'!$D$13:$AO$92,38,0) -> 0 | AA14: =VLOOKUP(C14,'Chấm công KT'!$D$13:$AP$92,39,0) -> 0 | AC14: =Q14 -> 3.2 | AD14: =VLOOKUP(C14,'BTH mủ tạp'!$D$17:$AN$160,37,0) -> A | AG14: 125408 | AH14: 554
A15: 5 | B15: ='Chấm công KT'!C17 -> 03459 | C15: ='Chấm công KT'!D17 -> N. Vạt | D15: CN-KT | E15: =4/1.25 -> 3.2 | Q15: =SUM(E15:P15) -> 3.2 | R15: =VLOOKUP(C15,'BTH mủ tạp'!D21:AK101,34,0) -> 3228 | T15: =S15*50/100 -> 0 | U15: =R15 -> 3228 | V15: =VLOOKUP(C15,'Chấm công KT'!D17:AK97,34,0) -> 24 | W15: =VLOOKUP(C15,'Chấm công KT'!D17:AL97,35,0) -> 2 | Y15: =VLOOKUP(C15,'Chấm công KT'!D17:AN97,37,0) -> 2 | Z15: =VLOOKUP(C15,'Chấm công KT'!$D$13:$AO$92,38,0) -> 0 | AA15: =VLOOKUP(C15,'Chấm công KT'!$D$13:$AP$92,39,0) -> 0 | AC15: =Q15 -> 3.2 | AD15: =VLOOKUP(C15,'BTH mủ tạp'!$D$17:$AN$160,37,0) -> A | AG15: 97048 | AH15: 92
A16: 6 | B16: ='Chấm công KT'!C18 -> 04054 | C16: ='Chấm công KT'!D18 -> N. Kay Son | D16: CN-KT | E16: =4/1.25 -> 3.2 | Q16: =SUM(E16:P16) -> 3.2 | R16: =VLOOKUP(C16,'BTH mủ tạp'!D22:AK102,34,0) -> 4093 | T16: =S16*50/100 -> 0 | U16: =R16 -> 4093 | V16: =VLOOKUP(C16,'Chấm công KT'!D18:AK98,34,0) -> 25 | W16: =VLOOKUP(C16,'Chấm công KT'!D18:AL98,35,0) -> 2 | Y16: =VLOOKUP(C16,'Chấm công KT'!D18:AN98,37,0) -> 2 | Z16: =VLOOKUP(C16,'Chấm công KT'!$D$13:$AO$92,38,0) -> 0 | AA16: =VLOOKUP(C16,'Chấm công KT'!$D$13:$AP$92,39,0) -> 0 | AC16: =Q16 -> 3.2 | AD16: =VLOOKUP(C16,'BTH mủ tạp'!$D$17:$AN$160,37,0) -> A | AG16: 46179
A17: 7 | B17: ='Chấm công KT'!C19 -> 04055 | C17: ='Chấm công KT'!D19 -> T. Đèng 1 | D17: CN-KT | E17: =4/1.25 -> 3.2 | Q17: =SUM(E17:P17) -> 3.2 | R17: =VLOOKUP(C17,'BTH mủ tạp'!D23:AK103,34,0) -> 3646 | T17: =S17*50/100 -> 0 | U17: =R17 -> 3646 | V17: =VLOOKUP(C17,'Chấm công KT'!D19:AK99,34,0) -> 26 | W17: =VLOOKUP(C17,'Chấm công KT'!D19:AL99,35,0) -> 2 | Y17: =VLOOKUP(C17,'Chấm công KT'!D19:AN99,37,0) -> 2 | Z17: =VLOOKUP(C17,'Chấm công KT'!$D$13:$AO$92,38,0) -> 0 | AA17: =VLOOKUP(C17,'Chấm công KT'!$D$13:$AP$92,39,0) -> 0 | AC17: =Q17 -> 3.2 | AD17: =VLOOKUP(C17,'BTH mủ tạp'!$D$17:$AN$160,37,0) -> A
A18: 8 | B18: ='Chấm công KT'!C20 -> 03462 | C18: ='Chấm công KT'!D20 -> T . Bua Ngân | D18: CN-KT | E18: =4/1.25 -> 3.2 | Q18: =SUM(E18:P18) -> 3.2 | R18: =VLOOKUP(C18,'BTH mủ tạp'!D24:AK104,34,0) -> 3674 | T18: =S18*50/100 -> 0 | U18: =R18 -> 3674 | V18: =VLOOKUP(C18,'Chấm công KT'!D20:AK100,34,0) -> 25 | W18: =VLOOKUP(C18,'Chấm công KT'!D20:AL100,35,0) -> 2 | Y18: =VLOOKUP(C18,'Chấm công KT'!D20:AN100,37,0) -> 2 | Z18: =VLOOKUP(C18,'Chấm công KT'!$D$13:$AO$92,38,0) -> 0 | AA18: =VLOOKUP(C18,'Chấm công KT'!$D$13:$AP$92,39,0) -> 0 | AC18: =Q18 -> 3.2 | AD18: =VLOOKUP(C18,'BTH mủ tạp'!$D$17:$AN$160,37,0) -> A | AI18: =1155.43-Q9 -> -6197.3
A19: 9 | B19: ='Chấm công KT'!C21 -> 03463 | C19: ='Chấm công KT'!D21 -> T Căng | D19: CN-KT | E19: =4/1.25 -> 3.2 | Q19: =SUM(E19:P19) -> 3.2 | R19: =VLOOKUP(C19,'BTH mủ tạp'!D25:AK105,34,0) -> 4580 | T19: =S19*50/100 -> 0 | U19: =R19 -> 4580 | V19: =VLOOKUP(C19,'Chấm công KT'!D21:AK101,34,0) -> 25 | W19: =VLOOKUP(C19,'Chấm công KT'!D21:AL101,35,0) -> 2 | Y19: =VLOOKUP(C19,'Chấm công KT'!D21:AN101,37,0) -> 2 | Z19: =VLOOKUP(C19,'Chấm công KT'!$D$13:$AO$92,38,0) -> 0 | AA19: =VLOOKUP(C19,'Chấm công KT'!$D$13:$AP$92,39,0) -> 0 | AC19: =Q19 -> 3.2 | AD19: =VLOOKUP(C19,'BTH mủ tạp'!$D$17:$AN$160,37,0) -> A
A20: 10 | B20: ='Chấm công KT'!C22 -> 03464 | C20: ='Chấm công KT'!D22 -> N. Phôn 1 | D20: CN-KT | E20: =4/1.25 -> 3.2 | Q20: =SUM(E20:P20) -> 3.2 | R20: =VLOOKUP(C20,'BTH mủ tạp'!D26:AK106,34,0) -> 4638 | T20: =S20*50/100 -> 0 | U20: =R20 -> 4638 | V20: =VLOOKUP(C20,'Chấm công KT'!D22:AK102,34,0) -> 25 | W20: =VLOOKUP(C20,'Chấm công KT'!D22:AL102,35,0) -> 2 | Y20: =VLOOKUP(C20,'Chấm công KT'!D22:AN102,37,0) -> 2 | Z20: =VLOOKUP(C20,'Chấm công KT'!$D$13:$AO$92,38,0) -> 0 | AA20: =VLOOKUP(C20,'Chấm công KT'!$D$13:$AP$92,39,0) -> 0 | AC20: =Q20 -> 3.2 | AD20: =VLOOKUP(C20,'BTH mủ tạp'!$D$17:$AN$160,37,0) -> A | AG20: =Q9 -> 7352.73
A21: 11 | B21: ='Chấm công KT'!C23 -> 03465 | C21: ='Chấm công KT'!D23 -> T. In Păn | D21: CN-KT | E21: =4/1.25 -> 3.2 | Q21: =SUM(E21:P21) -> 3.2 | R21: =VLOOKUP(C21,'BTH mủ tạp'!D27:AK107,34,0) -> 3595 | T21: =S21*50/100 -> 0 | U21: =R21 -> 3595 | V21: =VLOOKUP(C21,'Chấm công KT'!D23:AK103,34,0) -> 25 | W21: =VLOOKUP(C21,'Chấm công KT'!D23:AL103,35,0) -> 2 | Y21: =VLOOKUP(C21,'Chấm công KT'!D23:AN103,37,0) -> 2 | Z21: =VLOOKUP(C21,'Chấm công KT'!$D$13:$AO$92,38,0) -> 0 | AA21: =VLOOKUP(C21,'Chấm công KT'!$D$13:$AP$92,39,0) -> 0 | AC21: =Q21 -> 3.2 | AD21: =VLOOKUP(C21,'BTH mủ tạp'!$D$17:$AN$160,37,0) -> A | AG21: =AG20-2544.38 -> 4808.35
A22: 12 | B22: ='Chấm công KT'!C24 -> 03466 | C22: ='Chấm công KT'!D24 -> N. Keo | D22: CN-KT | E22: =4/1.25 -> 3.2 | Q22: =SUM(E22:P22) -> 3.2 | R22: =VLOOKUP(C22,'BTH mủ tạp'!D28:AK108,34,0) -> 4351 | T22: =S22*50/100 -> 0 | U22: =R22 -> 4351 | V22: =VLOOKUP(C22,'Chấm công KT'!D24:AK104,34,0) -> 26 | W22: =VLOOKUP(C22,'Chấm công KT'!D24:AL104,35,0) -> 2 | Y22: =VLOOKUP(C22,'Chấm công KT'!D24:AN104,37,0) -> 2 | Z22: =VLOOKUP(C22,'Chấm công KT'!$D$13:$AO$92,38,0) -> 0 | AA22: =VLOOKUP(C22,'Chấm công KT'!$D$13:$AP$92,39,0) -> 0 | AC22: =Q22 -> 3.2 | AD22: =VLOOKUP(C22,'BTH mủ tạp'!$D$17:$AN$160,37,0) -> A | AG22: =AG21-6.33 -> 4802.02
A23: 13 | B23: ='Chấm công KT'!C25 -> 02727 | C23: ='Chấm công KT'!D25 -> T. Thong Đon | D23: CN-KT | E23: =4/1.25 -> 3.2 | Q23: =SUM(E23:P23) -> 3.2 | R23: =VLOOKUP(C23,'BTH mủ tạp'!D29:AK109,34,0) -> 4260 | T23: =S23*50/100 -> 0 | U23: =R23 -> 4260 | V23: =VLOOKUP(C23,'Chấm công KT'!D25:AK105,34,0) -> 25 | W23: =VLOOKUP(C23,'Chấm công KT'!D25:AL105,35,0) -> 2 | Y23: =VLOOKUP(C23,'Chấm công KT'!D25:AN105,37,0) -> 2 | Z23: =VLOOKUP(C23,'Chấm công KT'!$D$13:$AO$92,38,0) -> 0 | AA23: =VLOOKUP(C23,'Chấm công KT'!$D$13:$AP$92,39,0) -> 0 | AC23: =Q23 -> 3.2 | AD23: =VLOOKUP(C23,'BTH mủ tạp'!$D$17:$AN$160,37,0) -> A
A24: 14 | B24: ='Chấm công KT'!C26 -> 03467 | C24: ='Chấm công KT'!D26 -> T. Hin | D24: CN-KT | E24: =4/1.25 -> 3.2 | Q24: =SUM(E24:P24) -> 3.2 | R24: =VLOOKUP(C24,'BTH mủ tạp'!D30:AK110,34,0) -> 4134 | T24: =S24*50/100 -> 0 | U24: =R24 -> 4134 | V24: =VLOOKUP(C24,'Chấm công KT'!D26:AK106,34,0) -> 26 | W24: =VLOOKUP(C24,'Chấm công KT'!D26:AL106,35,0) -> 2 | Y24: =VLOOKUP(C24,'Chấm công KT'!D26:AN106,37,0) -> 2 | Z24: =VLOOKUP(C24,'Chấm công KT'!$D$13:$AO$92,38,0) -> 0 | AA24: =VLOOKUP(C24,'Chấm công KT'!$D$13:$AP$92,39,0) -> 0 | AC24: =Q24 -> 3.2 | AD24: =VLOOKUP(C24,'BTH mủ tạp'!$D$17:$AN$160,37,0) -> A
A25: 15 | B25: ='Chấm công KT'!C27 -> 04056 | C25: ='Chấm công KT'!D27 -> N. Ly Phon | D25: CN-KT | E25: =4/1.25 -> 3.2 | Q25: =SUM(E25:P25) -> 3.2 | R25: =VLOOKUP(C25,'BTH mủ tạp'!D31:AK111,34,0) -> 4003 | T25: =S25*50/100 -> 0 | U25: =R25 -> 4003 | V25: =VLOOKUP(C25,'Chấm công KT'!D27:AK107,34,0) -> 26 | W25: =VLOOKUP(C25,'Chấm công KT'!D27:AL107,35,0) -> 2 | Y25: =VLOOKUP(C25,'Chấm công KT'!D27:AN107,37,0) -> 2 | Z25: =VLOOKUP(C25,'Chấm công KT'!$D$13:$AO$92,38,0) -> 0 | AA25: =VLOOKUP(C25,'Chấm công KT'!$D$13:$AP$92,39,0) -> 0 | AC25: =Q25 -> 3.2 | AD25: =VLOOKUP(C25,'BTH mủ tạp'!$D$17:$AN$160,37,0) -> B
A26: 16 | B26: ='Chấm công KT'!C28 -> 03469 | C26: ='Chấm công KT'!D28 -> T. Xôm Va Nít | D26: CN-KT | E26: =4/1.25 -> 3.2 | Q26: =SUM(E26:P26) -> 3.2 | R26: =VLOOKUP(C26,'BTH mủ tạp'!D32:AK112,34,0) -> 4506 | T26: =S26*50/100 -> 0 | U26: =R26 -> 4506 | V26: =VLOOKUP(C26,'Chấm công KT'!D28:AK108,34,0) -> 25 | W26: =VLOOKUP(C26,'Chấm công KT'!D28:AL108,35,0) -> 2 | Y26: =VLOOKUP(C26,'Chấm công KT'!D28:AN108,37,0) -> 2 | Z26: =VLOOKUP(C26,'Chấm công KT'!$D$13:$AO$92,38,0) -> 0 | AA26: =VLOOKUP(C26,'Chấm công KT'!$D$13:$AP$92,39,0) -> 0 | AC26: =Q26 -> 3.2 | AD26: =VLOOKUP(C26,'BTH mủ tạp'!$D$17:$AN$160,37,0) -> A
A27: 17 | B27: ='Chấm công KT'!C29 -> 03470 | C27: ='Chấm công KT'!D29 -> T. Lọi | D27: CN-KT | E27: =4/1.25 -> 3.2 | Q27: =SUM(E27:P27) -> 3.2 | R27: =VLOOKUP(C27,'BTH mủ tạp'!D33:AK113,34,0) -> 3459 | T27: =S27*50/100 -> 0 | U27: =R27 -> 3459 | V27: =VLOOKUP(C27,'Chấm công KT'!D29:AK109,34,0) -> 25 | W27: =VLOOKUP(C27,'Chấm công KT'!D29:AL109,35,0) -> 2 | Y27: =VLOOKUP(C27,'Chấm công KT'!D29:AN109,37,0) -> 2 | Z27: =VLOOKUP(C27,'Chấm công KT'!$D$13:$AO$92,38,0) -> 0 | AA27: =VLOOKUP(C27,'Chấm công KT'!$D$13:$AP$92,39,0) -> 0 | AC27: =Q27 -> 3.2 | AD27: =VLOOKUP(C27,'BTH mủ tạp'!$D$17:$AN$160,37,0) -> A
A28: 18 | B28: ='Chấm công KT'!C30 -> 03471 | C28: ='Chấm công KT'!D30 -> T. Phô Thong | D28: CN-KT | E28: =4/1.25 -> 3.2 | Q28: =SUM(E28:P28) -> 3.2 | R28: =VLOOKUP(C28,'BTH mủ tạp'!D34:AK114,34,0) -> 5064 | T28: =S28*50/100 -> 0 | U28: =R28 -> 5064 | V28: =VLOOKUP(C28,'Chấm công KT'!D30:AK110,34,0) -> 26 | W28: =VLOOKUP(C28,'Chấm công KT'!D30:AL110,35,0) -> 2 | Y28: =VLOOKUP(C28,'Chấm công KT'!D30:AN110,37,0) -> 2 | Z28: =VLOOKUP(C28,'Chấm công KT'!$D$13:$AO$92,38,0) -> 0 | AA28: =VLOOKUP(C28,'Chấm công KT'!$D$13:$AP$92,39,0) -> 0 | AC28: =Q28 -> 3.2 | AD28: =VLOOKUP(C28,'BTH mủ tạp'!$D$17:$AN$160,37,0) -> A | AF28: =Q9-3223.96 -> 4128.77
A29: 19 | B29: ='Chấm công KT'!C31 -> 03472 | C29: ='Chấm công KT'!D31 -> N. Soi | D29: CN-KT | E29: =4/1.25 -> 3.2 | Q29: =SUM(E29:P29) -> 3.2 | R29: =VLOOKUP(C29,'BTH mủ tạp'!D35:AK115,34,0) -> 4063 | T29: =S29*50/100 -> 0 | U29: =R29 -> 4063 | V29: =VLOOKUP(C29,'Chấm công KT'!D31:AK111,34,0) -> 24 | W29: =VLOOKUP(C29,'Chấm công KT'!D31:AL111,35,0) -> 2 | Y29: =VLOOKUP(C29,'Chấm công KT'!D31:AN111,37,0) -> 2 | Z29: =VLOOKUP(C29,'Chấm công KT'!$D$13:$AO$92,38,0) -> 0 | AA29: =VLOOKUP(C29,'Chấm công KT'!$D$13:$AP$92,39,0) -> 0 | AC29: =Q29 -> 3.2 | AD29: =VLOOKUP(C29,'BTH mủ tạp'!$D$17:$AN$160,37,0) -> A
A30: 20 | B30: ='Chấm công KT'!C32 -> 03473 | C30: ='Chấm công KT'!D32 -> N. Me Kha La | D30: CN-KT | E30: =4/1.25 -> 3.2 | Q30: =SUM(E30:P30) -> 3.2 | R30: =VLOOKUP(C30,'BTH mủ tạp'!D36:AK116,34,0) -> 3609 | T30: =S30*50/100 -> 0 | U30: =R30 -> 3609 | V30: =VLOOKUP(C30,'Chấm công KT'!D32:AK112,34,0) -> 25 | W30: =VLOOKUP(C30,'Chấm công KT'!D32:AL112,35,0) -> 2 | Y30: =VLOOKUP(C30,'Chấm công KT'!D32:AN112,37,0) -> 2 | Z30: =VLOOKUP(C30,'Chấm công KT'!$D$13:$AO$92,38,0) -> 0 | AA30: =VLOOKUP(C30,'Chấm công KT'!$D$13:$AP$92,39,0) -> 0 | AC30: =Q30 -> 3.2 | AD30: =VLOOKUP(C30,'BTH mủ tạp'!$D$17:$AN$160,37,0) -> A
A31: 21 | B31: ='Chấm công KT'!C33 -> 03474 | C31: ='Chấm công KT'!D33 -> N. Mon Khăm | D31: CN-KT | E31: =4/1.25 -> 3.2 | Q31: =SUM(E31:P31) -> 3.2 | R31: =VLOOKUP(C31,'BTH mủ tạp'!D37:AK117,34,0) -> 3808 | T31: =S31*50/100 -> 0 | U31: =R31 -> 3808 | V31: =VLOOKUP(C31,'Chấm công KT'!D33:AK113,34,0) -> 24 | W31: =VLOOKUP(C31,'Chấm công KT'!D33:AL113,35,0) -> 2 | Y31: =VLOOKUP(C31,'Chấm công KT'!D33:AN113,37,0) -> 2 | Z31: =VLOOKUP(C31,'Chấm công KT'!$D$13:$AO$92,38,0) -> 0 | AA31: =VLOOKUP(C31,'Chấm công KT'!$D$13:$AP$92,39,0) -> 0 | AC31: =Q31 -> 3.2 | AD31: =VLOOKUP(C31,'BTH mủ tạp'!$D$17:$AN$160,37,0) -> A
A32: 22 | B32: ='Chấm công KT'!C34 -> 0 | C32: ='Chấm công KT'!D34 -> N.Choi | D32: CN-KT | E32: =4/1.25 -> 3.2 | Q32: =SUM(E32:P32) -> 3.2 | R32: =VLOOKUP(C32,'BTH mủ tạp'!D38:AK118,34,0) -> 3490 | T32: =S32*50/100 -> 0 | U32: =R32 -> 3490 | V32: =VLOOKUP(C32,'Chấm công KT'!D34:AK114,34,0) -> 26 | W32: =VLOOKUP(C32,'Chấm công KT'!D34:AL114,35,0) -> 2 | Y32: =VLOOKUP(C32,'Chấm công KT'!D34:AN114,37,0) -> 2 | Z32: =VLOOKUP(C32,'Chấm công KT'!$D$13:$AO$92,38,0) -> 0 | AA32: =VLOOKUP(C32,'Chấm công KT'!$D$13:$AP$92,39,0) -> 0 | AC32: =Q32 -> 3.2 | AD32: =VLOOKUP(C32,'BTH mủ tạp'!$D$17:$AN$160,37,0) -> A
A33: 23 | B33: ='Chấm công KT'!C35 -> 03476 | C33: ='Chấm công KT'!D35 -> T. Bin Ly. | D33: CN-KT | E33: =4/1.25 -> 3.2 | Q33: =SUM(E33:P33) -> 3.2 | R33: =VLOOKUP(C33,'BTH mủ tạp'!D39:AK119,34,0) -> 4267 | T33: =S33*50/100 -> 0 | U33: =R33 -> 4267 | V33: =VLOOKUP(C33,'Chấm công KT'!D35:AK115,34,0) -> 26 | W33: =VLOOKUP(C33,'Chấm công KT'!D35:AL115,35,0) -> 2 | Y33: =VLOOKUP(C33,'Chấm công KT'!D35:AN115,37,0) -> 2 | Z33: =VLOOKUP(C33,'Chấm công KT'!$D$13:$AO$92,38,0) -> 0 | AA33: =VLOOKUP(C33,'Chấm công KT'!$D$13:$AP$92,39,0) -> 0 | AC33: =Q33 -> 3.2 | AD33: =VLOOKUP(C33,'BTH mủ tạp'!$D$17:$AN$160,37,0) -> A
A34: 24 | B34: ='Chấm công KT'!C36 -> 0 | C34: ='Chấm công KT'!D36 -> N. Tinh | D34: CN-KT | E34: =4/1.25 -> 3.2 | Q34: =SUM(E34:P34) -> 3.2 | R34: =VLOOKUP(C34,'BTH mủ tạp'!D40:AK120,34,0) -> 3721 | T34: =S34*50/100 -> 0 | U34: =R34 -> 3721 | V34: =VLOOKUP(C34,'Chấm công KT'!D36:AK116,34,0) -> 26 | W34: =VLOOKUP(C34,'Chấm công KT'!D36:AL116,35,0) -> 2 | Y34: =VLOOKUP(C34,'Chấm công KT'!D36:AN116,37,0) -> 2 | Z34: =VLOOKUP(C34,'Chấm công KT'!$D$13:$AO$92,38,0) -> 0 | AA34: =VLOOKUP(C34,'Chấm công KT'!$D$13:$AP$92,39,0) -> 0 | AC34: =Q34 -> 3.2 | AD34: =VLOOKUP(C34,'BTH mủ tạp'!$D$17:$AN$160,37,0) -> A
A35: 25 | B35: ='Chấm công KT'!C37 -> 03478 | C35: ='Chấm công KT'!D37 -> N. Nong | D35: CN-KT | E35: =4/1.25 -> 3.2 | Q35: =SUM(E35:P35) -> 3.2 | R35: =VLOOKUP(C35,'BTH mủ tạp'!D41:AK121,34,0) -> 4018 | T35: =S35*50/100 -> 0 | U35: =R35 -> 4018 | V35: =VLOOKUP(C35,'Chấm công KT'!D37:AK117,34,0) -> 26 | W35: =VLOOKUP(C35,'Chấm công KT'!D37:AL117,35,0) -> 2 | Y35: =VLOOKUP(C35,'Chấm công KT'!D37:AN117,37,0) -> 2 | Z35: =VLOOKUP(C35,'Chấm công KT'!$D$13:$AO$92,38,0) -> 0 | AA35: =VLOOKUP(C35,'Chấm công KT'!$D$13:$AP$92,39,0) -> 0 | AC35: =Q35 -> 3.2 | AD35: =VLOOKUP(C35,'BTH mủ tạp'!$D$17:$AN$160,37,0) -> B
A36: 26 | B36: ='Chấm công KT'!C38 -> 03479 | C36: ='Chấm công KT'!D38 -> N. Tun 1 | D36: CN-KT | E36: =4/1.25 -> 3.2 | Q36: =SUM(E36:P36) -> 3.2 | R36: =VLOOKUP(C36,'BTH mủ tạp'!D42:AK122,34,0) -> 4131 | T36: =S36*50/100 -> 0 | U36: =R36 -> 4131 | V36: =VLOOKUP(C36,'Chấm công KT'!D38:AK118,34,0) -> 26 | W36: =VLOOKUP(C36,'Chấm công KT'!D38:AL118,35,0) -> 2 | Y36: =VLOOKUP(C36,'Chấm công KT'!D38:AN118,37,0) -> 2 | Z36: =VLOOKUP(C36,'Chấm công KT'!$D$13:$AO$92,38,0) -> 0 | AA36: =VLOOKUP(C36,'Chấm công KT'!$D$13:$AP$92,39,0) -> 0 | AC36: =Q36 -> 3.2 | AD36: =VLOOKUP(C36,'BTH mủ tạp'!$D$17:$AN$160,37,0) -> A
